File: GB1_test 56.csv
Segment,Time On Sample,Displacement Into Surface,Load On Sample,Harmonic Contact Stiffness,Harmonic Displacement,Harmonic Load
Surface Marker,0,0,0,-139.8449641,0.42972645,2.19903999
,0.2,0.559122709,0.000619828,3003.922663,0.266997542,2.271355244
,0.4,0.742958604,0.001264278,8993.418898,0.189341393,2.353531639
,0.6,0.481609489,0.001937937,18220.93208,0.129572337,2.457621705
,0.79,0.71849628,0.002546081,24672.33234,0.10688627,2.551850641
,1,0.609630309,0.003242406,27366.95577,0.099905943,2.642792495
,1.2,1.057248744,0.003869399,28310.13049,0.099905941,2.733734397
,1.4,0.822527546,0.00454116,29632.29891,0.102523565,2.939723183
,1.6,0.824960975,0.005197361,30243.69695,0.112121516,3.283768309
,1.8,0.972183546,0.005844062,31894.32395,0.117356761,3.631100508
,2,0.989595163,0.006499281,33010.14915,0.123900818,3.976241321
,2.2,0.948758274,0.00715832,32969.89526,0.13437131,4.315903713
,2.4,1.081834779,0.00780595,33970.04634,0.147459423,4.899903906
,2.6,0.888719655,0.008474981,36665.8667,0.153567212,5.529922808
,2.8,0.948569468,0.009127415,39093.5099,0.159674998,6.173089998
,3,1.018404739,0.009779193,40775.32036,0.165782784,6.703401612
,3.2,1.074926066,0.010431845,43865.92213,0.168836677,7.347664472
,3.4,0.851854568,0.011102842,46105.02084,0.176689548,8.100400105
,3.6,1.188800841,0.011737095,46485.40372,0.196321716,9.062411728
,3.8,1.082226354,0.012400448,44651.81605,0.225988111,9.967447615
,4,1.180353756,0.01305037,42517.07426,0.258708396,10.82646477
,4.2,1.310933895,0.013698164,40969.77448,0.29142868,11.71287409
,4.4,1.478127378,0.014343555,40718.73869,0.317604906,12.65406769
,4.6,1.235084969,0.015015861,40915.87628,0.344217409,13.76070958
,4.8,1.281620838,0.015669168,41145.20001,0.370393637,14.87721276
,5,1.032753575,0.016341856,40774.03338,0.401805117,15.98823737
,5.2,1.11007794,0.016993144,38863.58751,0.448922328,17.02913828
,5.4,1.080890752,0.017651419,37136.57471,0.498220893,18.06017795
,5.6,0.767118009,0.018328367,34878.43971,0.561043853,19.09669592
,5.8,0.348081887,0.01901222,32001.74858,0.640008826,19.99515748
,6,-0.252356743,0.019707975,28919.025,0.73555209,20.7982943
,6.2,-0.023170191,0.0203493,25957.65776,0.835458028,21.30888367
,6.4,0.168154829,0.020993109,21754.58437,1.002985894,21.66826851
,6.6,0.971089163,0.021596791,17451.33472,1.231591586,21.70990502
,6.8,1.484861251,0.022219443,14008.60575,1.490736215,21.47762011
,7,2.053969401,0.022838465,12213.77553,1.672660953,21.21465601
,7.2,1.828817611,0.023509597,11221.49737,1.798306868,21.05139879
,7.4,1.989353858,0.024157064,11515.85488,1.771694355,21.28149277
,7.6,2.112029099,0.024803735,13375.25255,1.591950914,22.0583336
,7.8,2.321244709,0.025446368,16201.82388,1.386903782,23.00391004
,8,1.830230114,0.026134943,20632.95609,1.165932826,24.20751982
,8.2,1.427004324,0.026817759,25755.71243,0.993824148,25.42537362
,8.4,1.361203791,0.027478436,29488.0248,0.908751408,26.45750892
,8.6,1.571667592,0.028120988,30487.77757,0.902643612,27.1938095
,8.8,1.5287504,0.028780165,29043.11706,0.965902833,27.89504796
,9,1.702184794,0.029425146,26901.18601,1.051848107,28.31031276
,9.2,1.591865763,0.030088744,24202.0765,1.177930281,28.68722837
,9.4,1.551860736,0.03074937,22415.23825,1.281762657,28.97320216
,9.6,1.9237561,0.03138133,21174.19628,1.365526561,29.19343513
,9.8,1.745619171,0.032049378,20218.14646,1.441437636,29.47064337
,10,1.586620773,0.03271781,19960.76938,1.472849123,29.72703353
,10.2,1.85200511,0.033353478,19914.71129,1.495971437,30.09956674
,10.4,1.775387,0.034014865,20047.90611,1.503824312,30.4479945
,10.6,1.805280438,0.034669264,20366.87315,1.499461605,30.82162317
,10.8,1.639209268,0.03533652,20658.43403,1.498589078,31.19634734
,11,1.820548815,0.035980983,20847.85719,1.502733633,31.54696674
,11.2,2.142932948,0.036616191,21213.18785,1.494662604,31.93264816
,11.4,2.090862422,0.037275968,21573.16312,1.488118552,32.319425
,11.6,2.022565527,0.037936808,22141.13307,1.472849091,32.76975154
,11.8,2.150649297,0.038584765,22825.56343,1.449290476,33.17077244
,12,2.388573098,0.039225514,24052.74094,1.405663413,33.74052893
,12.2,2.377276523,0.039882615,25221.65851,1.367271613,34.23906562
,12.4,2.476652101,0.040532455,26584.8826,1.325389643,34.8099177
,12.6,2.181602113,0.041208173,27967.50872,1.288306675,35.4333623
,12.8,2.638373852,0.041834564,29064.94831,1.26605685,36.06557309
,13,2.300885672,0.042513066,29560.85568,1.26213044,36.5126123
,13.2,2.177668762,0.04317751,29832.20793,1.270855857,37.07031593
,13.4,2.183430677,0.043833492,29868.63213,1.285689053,37.53488643
,13.6,2.635625749,0.044460183,29921.30826,1.301831029,38.07286829
,13.8,2.58646765,0.045119768,30139.4617,1.310120171,38.59551008
,14,2.253556136,0.04579797,30299.07323,1.317536793,39.01296578
,14.2,2.335873225,0.046448929,30586.51978,1.323644574,39.54437315
,14.4,2.537183681,0.047092081,31000.0618,1.323644561,40.05167563
,14.6,2.500923463,0.047750819,31375.65562,1.327134726,40.61047498
,14.8,2.547043269,0.048404153,31687.1453,1.332369969,41.16160467
,15,2.773317365,0.049045667,31978.47871,1.334551305,41.61302722
,15.2,2.870196577,0.04969567,32325.40282,1.337168921,42.16634831
,15.4,2.523139003,0.0503748,32537.58394,1.343713003,42.68131999
,15.6,2.499776668,0.051032692,32703.92943,1.351565872,43.20615311
,15.8,2.616210736,0.051681413,32742.17766,1.362472628,43.62141792
,16,2.452219876,0.052348532,32806.27881,1.375997023,44.14844227
,16.2,2.474624221,0.053003422,32907.0331,1.387340052,44.65903158
,16.4,2.616021932,0.053650504,32830.25415,1.403918322,45.10716699
,16.6,2.936325749,0.054285849,32749.31114,1.419187762,45.48627446
,16.8,2.638363341,0.054961757,32580.41086,1.439692494,45.94646184
,17,3.034390208,0.055592134,32370.44733,1.461942262,46.38144937
,17.2,3.060955159,0.05624675,32194.58243,1.479829343,46.69700673
,17.4,2.65731333,0.056929592,32249.06548,1.491608678,47.10679245
,17.6,3.275516616,0.057545392,32528.24272,1.495098794,47.57684216
,17.8,3.313731266,0.058199243,33022.49019,1.489427277,48.06661354
,18,3.525027169,0.058841739,33589.67394,1.481574391,48.59473408
,18.2,3.112232015,0.059525182,33987.03567,1.47721172,49.00123266
,18.4,3.237819414,0.060173301,34305.64904,1.477211711,49.46032492
,18.6,3.291844372,0.060826116,34399.76836,1.486809656,49.92270418
,18.8,2.904844976,0.061507866,34254.86628,1.506005587,50.35111653
,19,3.285893653,0.062139225,34073.38532,1.523020104,50.66886578
,19.2,3.70771627,0.062767908,33828.79557,1.544833591,51.06002597
,19.4,3.094379858,0.063464508,33607.51632,1.564465812,51.40407026
,19.6,3.298186671,0.064107495,33508.7254,1.579735261,51.78098627
,19.8,3.32974435,0.064761784,33446.76894,1.59064202,52.07353417
,20,3.224001996,0.065425081,33440.7968,1.602421331,52.44716269
,20.2,3.426976686,0.066068123,33468.06452,1.610274182,52.74190234
,20.4,3.346197975,0.066729782,33601.56794,1.616818246,53.15826253
,20.6,3.718925429,0.067361686,33733.73662,1.618999566,53.45081106
,20.8,3.728015569,0.06801909,33965.09968,1.618999565,53.82334405
,21,3.683848922,0.068686392,34309.59502,1.614636865,54.23203459
,21.2,3.762003076,0.06935224,34780.40433,1.60547518,54.66592606
,21.4,3.790228867,0.07002815,35332.74107,1.592387065,55.08009506
,21.6,3.711942049,0.070717779,35893.58751,1.579298959,55.48002003
,21.8,3.849173587,0.071400098,36632.31042,1.562284401,55.98074838
,22,3.926491276,0.072093319,37354.30153,1.54657866,56.49243353
,22.2,4.076202405,0.072788833,38090.97295,1.531745453,57.02822378
,22.4,3.865603878,0.07351489,38661.01662,1.522583792,57.5201861
,22.6,4.289080694,0.074206579,39180.63477,1.516475972,58.04940273
,22.8,4.283181738,0.074933612,39633.55547,1.510368187,58.48658114
,23,4.284770717,0.075667433,40363.50732,1.497716345,59.06948563
,23.2,4.389125521,0.07640183,41002.27358,1.488554658,59.63595504
,23.4,4.200572436,0.07716279,41675.29531,1.478520454,60.20899813
,23.6,4.265815167,0.07791466,42303.34807,1.470231311,60.76286705
,23.8,4.139668759,0.078686778,42678.06604,1.470231321,61.27619542
,24,3.995214474,0.079467681,42739.00871,1.481574364,61.80650681
,24.2,4.417849669,0.080219176,42620.98783,1.497716336,62.29080038
,24.4,4.726066963,0.080985763,42337.22748,1.518657291,62.72030955
,24.6,4.191344063,0.081815532,42203.28896,1.535235611,63.21007989
,24.8,4.288616038,0.082612042,42373.22893,1.538725767,63.6264404
,25,4.265645187,0.083424535,42722.85537,1.538289499,64.17209154
,25.2,4.694098906,0.084215406,43445.59585,1.526073892,64.78567612
,25.4,4.572935179,0.08505042,44249.40396,1.511240708,65.39049407
,25.6,4.428470716,0.085895376,44691.2516,1.507314287,65.88245649
,25.8,4.403830383,0.08674094,44980.0571,1.510804452,66.46864797
,26,4.72285484,0.087572339,45226.73093,1.515603401,67.04278756
,26.2,4.716102424,0.08843367,45201.04285,1.526073892,67.46133938
,26.4,4.812531696,0.089296781,45143.19083,1.540252673,67.98233793
,26.6,4.881083519,0.090170431,45417.75219,1.542652155,68.50004929
,26.8,4.761157743,0.091069736,45686.64321,1.546142328,69.05227441
,27,4.745247144,0.091962162,45813.25008,1.553995197,69.57710758
,27.2,4.805057442,0.092863126,46024.88449,1.556612815,70.01209473
,27.4,4.729230518,0.093782059,46166.83826,1.562720607,70.51720545
,27.6,4.801103294,0.094702875,45939.25403,1.580607688,70.9861589
,27.8,4.932472016,0.095624383,45773.72766,1.596749683,71.46606926
,28,4.883684624,0.096569299,45699.74365,1.607220177,71.83202809
,28.2,5.491023422,0.0974805,45521.04978,1.623362129,72.27687742
,28.4,5.615314286,0.098432808,45568.76174,1.631214986,72.69214243
,28.6,5.306068427,0.099423081,46009.13658,1.62728858,73.21259228
,28.8,5.505247123,0.10038991,46511.80963,1.618999425,73.65524948
,29,5.716906095,0.101365615,47341.01608,1.602857403,74.25897251
,29.2,5.579904667,0.102374056,48538.24307,1.576681192,74.91309633
,29.4,5.785319564,0.103370078,49653.83677,1.553995115,75.5650295
,29.6,6.123456231,0.104367303,50736.73768,1.53479919,76.29475659
,29.8,6.19323216,0.105392302,51591.49946,1.521274803,76.89628793
,30,6.221400383,0.106430354,52543.89359,1.50818669,77.62053592
,30.2,6.236253017,0.107479653,53190.65773,1.502951444,78.33601849
,30.4,6.214490637,0.108541905,53973.65643,1.494226039,79.04930961
,30.6,6.41781537,0.109600059,54992.1283,1.481574182,79.85792575
,30.8,6.522532038,0.110675323,55655.33159,1.475466389,80.48904063
,31,6.576903649,0.111764702,56213.5509,1.474157574,81.22424556
,31.2,6.757755952,0.11285674,56733.79372,1.475030101,81.99999131
,31.4,6.576217691,0.113983559,57083.4677,1.478956549,82.69684662
,31.6,6.507430063,0.115114296,57241.58095,1.48550061,83.2874207
,31.8,6.786051291,0.116233422,57409.70465,1.493789725,84.00399966
,32,6.775508554,0.117382983,57701.71858,1.499024971,84.74687422
,32.2,6.586057905,0.118555839,58041.77038,1.502951419,85.45359076
,32.4,6.809337574,0.119713157,58120.36464,1.512985622,86.12195926
,32.6,6.829993839,0.120895549,58228.63157,1.520838485,86.70924656
,32.8,6.739976077,0.122097154,58322.28835,1.531308982,87.41048486
,33,6.88295035,0.123295545,58273.57758,1.544397082,88.0437913
,33.2,6.762140264,0.124523309,58095.34776,1.559666557,88.64093958
,33.4,6.973344615,0.125741545,58223.32424,1.566646859,89.25014098
,33.6,6.867508826,0.126992775,58518.44198,1.570573307,89.94590104
,33.8,7.281746819,0.128222491,59012.05881,1.568828189,90.64056656
,34,7.184228232,0.129498417,59650.45893,1.561847873,91.25415007
,34.2,7.232328861,0.130777382,60544.94118,1.551813651,92.05400045
,34.4,7.43936261,0.13205875,61195.60836,1.547450929,92.77715328
,34.6,7.317706395,0.133374709,61583.88311,1.55006856,93.53974992
,34.8,7.518079028,0.134682582,61626.47494,1.558793953,94.13032483
,35,7.420550144,0.136023294,61520.91896,1.572754613,94.77787457
,35.2,7.410391852,0.137371722,61527.8059,1.583661375,95.43747709
,35.4,7.511735679,0.13872622,61574.91035,1.591950504,96.0302431
,35.6,7.534025814,0.140099585,61758.9069,1.596313203,96.57479875
,35.8,7.583773763,0.141484897,62142.98821,1.59805828,97.28261158
,36,7.572774646,0.142888141,62672.15621,1.59587693,98.01343373
,36.2,7.683262986,0.144297524,62814.83988,1.600675895,98.55031973
,36.4,7.591543606,0.145734387,63060.26484,1.605038606,99.19129538
,36.6,7.739472864,0.147169863,63121.88814,1.613764001,99.82021917
,36.8,7.709325876,0.1486315,63172.32341,1.623361951,100.457908
,37,7.853089886,0.150096441,63133.72492,1.634704968,101.0671094
,37.2,7.901989725,0.151582391,63288.90331,1.639067668,101.5645506
,37.4,7.909281139,0.153085944,63471.94373,1.643866641,102.1540291
,37.6,8.106293802,0.154592079,63974.97506,1.641685272,102.8410246
,37.8,7.918864042,0.156138664,64553.28148,1.637322586,103.5499323
,38,7.801329998,0.157696163,65140.56791,1.631214812,104.1514632
,38.2,8.256292882,0.159231661,65661.90711,1.62816088,104.8537988
,38.4,7.962344187,0.16083191,66050.04825,1.628160906,105.4991567
,38.6,7.990423856,0.162427054,66057.7936,1.638195122,106.1423239
,38.8,8.291436753,0.164020203,65907.07859,1.649974394,106.6233308
,39,8.334489516,0.165646372,65569.53461,1.667861474,107.1613122
,39.2,8.230254215,0.167298616,65275.74333,1.684439757,107.6894324
,39.4,8.512952638,0.168942067,65494.1051,1.687493624,108.2263191
,39.6,8.451150261,0.170624614,66228.13301,1.679640764,108.8913998
,39.8,8.398498529,0.172323465,67066.24937,1.668297741,109.4951224
,40,8.468165907,0.174031325,68207.61205,1.652592003,110.2763461
,40.2,8.181682681,0.175779709,69119.32019,1.64081273,110.928278
,40.4,8.451885771,0.177509007,69638.01555,1.639067625,111.6130821
,40.6,8.454975183,0.179273255,69702.2493,1.647356761,112.2945983
,40.8,8.707282088,0.181038805,69636.8192,1.657827227,112.9410536
,41,8.984965863,0.18282045,69499.68131,1.66742515,113.4286343
,41.2,9.503129832,0.184604039,69233.88637,1.681385753,114.0203062
,41.4,9.399280347,0.18644657,69335.15314,1.685748466,114.580201
,41.6,9.493056697,0.188294637,69686.14856,1.684003377,115.1236611
,41.8,9.794444343,0.190147509,70226.44916,1.680076917,115.8259965
,42,9.460504482,0.192060998,70849.01118,1.673532893,116.4198568
,42.2,9.658703096,0.193958451,71896.04313,1.660008496,117.1923157
,42.4,9.749555024,0.195882181,72719.32509,1.651719353,117.9088942
,42.6,9.817104495,0.197826715,73550.97671,1.645611563,118.7207974
,42.8,10.08602416,0.199777649,74103.08821,1.643430188,119.3683482
,43,10.4227586,0.201743613,74713.01356,1.641685078,120.1594342
,43.2,11.17846286,0.20370186,74930.25503,1.645611444,120.7653509
,43.4,11.27554014,0.205723033,75377.81898,1.645611436,121.476451
,43.6,11.31353359,0.207768365,76036.96893,1.641685,122.2839712
,43.8,11.6411019,0.209815316,76838.04657,1.633832107,123.0071248
,44,11.91873967,0.211886139,78067.90489,1.620307706,123.9625635
,44.2,11.62013028,0.214015676,79562.34412,1.60067557,124.8237711
,44.4,11.60069413,0.216148114,81528.28031,1.574935627,125.8526197
,44.6,11.66446667,0.21829659,83506.68672,1.552685839,127.0611608
,44.8,11.75195123,0.220465124,84776.69018,1.540470265,127.9913981
,45,12.16437473,0.222639518,86137.64914,1.529999745,129.1725486
,45.2,12.10747846,0.22486676,86950.08583,1.527382129,130.1466127
,45.4,12.27275671,0.227090707,87500.79205,1.529999737,131.143687
,45.6,12.27659902,0.229353292,88238.45757,1.529999737,132.1615789
,45.8,12.24881804,0.231634891,89059.76239,1.529127199,133.2139846
,46,12.52475669,0.233925146,89481.57986,1.53392615,134.1918847
,46.2,12.58184386,0.236252779,89616.68715,1.543960361,135.2492216
,46.4,12.43380946,0.238617324,89196.0337,1.560974912,136.1224823
,46.6,12.41516611,0.240997084,88536.36456,1.580170805,136.8204337
,46.8,12.46350471,0.243396359,87740.44287,1.603293124,137.6509634
,47,12.60711734,0.24581341,87283.04089,1.61856257,138.2996098
,47.2,12.85474123,0.248247973,86963.63313,1.633395736,139.0939827
,47.4,12.57562861,0.250741653,87004.17626,1.641684896,139.8664398
,47.6,12.81991617,0.253225781,87395.88342,1.643866226,140.6964227
,47.8,12.90068794,0.255745889,87877.67963,1.644302489,141.517639
,48,13.02555813,0.258288247,88037.29265,1.650410262,142.3109159
,48.2,13.25402329,0.260849472,88164.12399,1.656954295,143.0855664
,48.4,13.09097143,0.263462219,88429.92811,1.660880742,143.8514498
,48.6,13.27074926,0.266078559,88622.40641,1.666334104,144.6310307
,48.8,13.29949297,0.268731024,88611.60035,1.675277641,145.359114
,49,13.46844483,0.271400893,89210.58817,1.674405086,146.2400457
,49.2,13.47804125,0.274108143,89557.8813,1.675713896,146.9423801
,49.4,13.61952452,0.276833915,90063.43151,1.675277613,147.7257958
,49.6,13.73645587,0.279588697,90686.7261,1.674405063,148.6461722
,49.8,13.94782858,0.282364771,91124.93658,1.674405045,149.357273
,50,14.11509441,0.285171778,91196.54546,1.682257893,150.1856118
,50.2,14.15296092,0.288015687,91291.80447,1.687929398,150.8189178
,50.4,15.10365964,0.290827765,90789.2532,1.704071313,151.4325061
,50.6,15.39947463,0.293711389,90229.99454,1.721085826,152.0723876
,50.8,15.51637899,0.296635855,90239.48163,1.726757324,152.6487187
,51,15.34037212,0.299608961,90986.26151,1.721085829,153.4726737
,51.2,15.3474271,0.302599919,92146.50748,1.707125183,154.241845
,51.4,15.38609791,0.305618796,94400.79459,1.677458808,155.2969903
,51.6,15.50131903,0.30866294,97382.59628,1.640812102,156.6512581
,51.8,15.82872612,0.311723682,99605.25702,1.615944675,157.7633804
,52,15.50457761,0.314858268,101667.0959,1.59762136,159.0913498
,52.2,15.57901005,0.317997858,102624.4978,1.593258646,160.0533621
,52.4,15.91472343,0.32115193,102956.6611,1.598930132,161.0635856
,52.6,16.04739427,0.324351025,103346.3744,1.605037906,162.2020035
,52.8,16.00198611,0.327594087,103262.4868,1.615508395,163.0369157
,53,15.89666006,0.330873697,103312.5944,1.625542617,164.0526157
,53.2,16.06176809,0.334168353,103308.0573,1.63383173,164.8360316
,53.4,16.16862238,0.33749996,103683.5484,1.637758158,165.7892786
,53.6,16.22720836,0.340868171,103900.8996,1.644738475,166.836754
,53.8,16.58535246,0.344250514,104274.7547,1.646919791,167.6705726
,54,16.64559188,0.347686516,104946.5747,1.64648352,168.7542056
,54.2,17.18429531,0.351125552,105739.782,1.643865852,169.8400326
,54.4,17.10555957,0.35463976,105907.7546,1.649101101,170.7615038
,54.6,17.65673372,0.358147625,105762.2954,1.658262725,171.5262949
,54.8,18.62229839,0.361663618,105830.3988,1.666551771,172.5189908
,55,18.71662694,0.365272336,105612.0708,1.676585975,173.2070819
,55.2,18.28588152,0.368951838,105520.3095,1.686183956,174.1044465
,55.4,18.24872336,0.372642324,106080.1924,1.68574769,175.0149611
,55.6,18.41626102,0.376356505,107120.5625,1.677894813,175.9397204
,55.8,18.63288787,0.38010475,108132.0668,1.671787013,177.0617035
,56,18.5241495,0.383912091,108642.5636,1.671350753,177.932773
,56.2,19.11438651,0.387711722,108878.7741,1.677022211,178.9210845
,56.4,18.56960469,0.391624277,108339.9458,1.692291714,179.6891574
,56.6,18.83280593,0.395522822,107126.8183,1.715850276,180.2249487
,56.8,18.93789797,0.399471058,105650.2213,1.744644092,180.8034716
,57,18.78169779,0.403476064,104961.089,1.760349831,181.2943378
,57.2,19.10063218,0.407490066,104442.4376,1.774310444,181.9188803
,57.4,18.99351432,0.411572475,104309.658,1.782163316,182.5006887
,57.6,19.36402728,0.415664332,105045.5911,1.7760555,183.1581021
,57.8,19.57892716,0.419807267,106242.0801,1.765584998,184.0675222
,58,19.74722166,0.423994873,107225.1785,1.757732121,184.8114937
,58.2,19.56518662,0.428247758,108224.7706,1.751624357,185.7044765
,58.4,19.81210301,0.43251525,109238.9556,1.744644013,186.5580169
,58.6,20.04237017,0.436826734,109644.4942,1.745952802,187.2537786
,58.8,19.94519094,0.44120299,109521.1642,1.755550753,187.9878875
,59,19.99986674,0.445613399,109135.9878,1.7664575,188.5083384
,59.2,20.24550722,0.450055361,108833.6068,1.776927958,189.162464
,59.4,20.36590644,0.45455021,108061.3604,1.793069939,189.6610018
,59.6,20.11600476,0.459114594,107593.7271,1.803976715,190.2088432
,59.8,20.20601709,0.463702594,107497.3875,1.808339408,190.6723185
,60,20.33762813,0.468333863,107493.6694,1.813138366,191.2826163
,60.2,20.35689549,0.473019059,107504.7394,1.817064795,191.7274647
,60.4,20.74436875,0.477727216,108244.9268,1.811829517,192.3706341
,60.6,20.91215462,0.482497155,109418.2393,1.80266783,193.1518592
,60.8,21.03915895,0.487317755,110850.4531,1.789579717,193.945684
,61,22.90154325,0.492072131,112389.5137,1.774746358,194.8205991
,61.2,22.94989691,0.496993916,114317.1325,1.754677934,195.7963079
,61.4,22.94665122,0.5019686,115903.783,1.739844755,196.7840685
,61.6,23.09817203,0.50698307,117273.11,1.728065451,197.7942915
,61.8,23.34163414,0.512041856,118100.6997,1.723702729,198.7924626
,62,23.42199254,0.517162247,119240.4461,1.714977322,199.7084566
,62.2,23.59928482,0.522327615,120463.4524,1.707124446,200.8249614
,62.4,23.93674996,0.527547564,121936.6875,1.696217666,201.9294148
,62.6,23.76911376,0.532826838,123517.6887,1.683565852,202.9757933
,62.8,24.08284877,0.538140737,126086.3134,1.662188596,204.4505883
,63,23.88939565,0.543555059,127606.5194,1.651718134,205.5966744
,63.2,24.3096249,0.548970052,128682.129,1.648227937,206.9060213
,63.4,24.50434305,0.554440356,129182.0318,1.65084554,208.0543012
,63.6,25.24824982,0.559943151,128999.8216,1.660443413,208.9823513
,63.8,25.77371614,0.56551571,128682.0976,1.672658925,210.0681792
,64,25.61766686,0.571189211,128639.7822,1.680075528,210.9337701
,64.2,26.1023413,0.576877486,128977.8814,1.684874454,212.082052
,64.4,26.0581941,0.582657703,129854.1642,1.682693109,213.2292348
,64.6,26.44590817,0.588467597,131425.9615,1.671786326,214.3621763
,64.8,26.57357532,0.594353024,132918.5287,1.664369726,215.7690376
,65,26.90094196,0.60028447,133488.3422,1.665242237,216.8121325
,65.2,27.00653904,0.606290116,134319.485,1.664805958,218.1061381
,65.4,27.12044772,0.612355549,134407.8713,1.671786267,219.2007293
,65.6,27.38912113,0.618471693,133953.1264,1.68356553,220.0575571
,65.8,27.37527988,0.624667881,133558.7337,1.696217359,221.1094156
,66,27.66140813,0.630906643,134094.3379,1.697089873,222.0528027
,66.2,27.79025567,0.637218417,134859.6987,1.697089861,223.2525797
,66.4,27.99440002,0.643588651,135989.5571,1.692727144,224.4556441
,66.6,27.93475204,0.650040211,137255.619,1.686183101,225.5776259
,66.8,28.24247492,0.656532306,138841.0534,1.677893946,226.9910629
,67,28.58055982,0.663087622,139370.9284,1.679202726,228.0440192
,67.2,28.68480845,0.669724055,140157.9384,1.679638986,229.3708953
,67.4,29.57748049,0.676375277,140472.8982,1.684001605,230.5038406
,67.6,29.86394226,0.683133062,140390.4114,1.691418166,231.4066877
,67.8,30.39378845,0.689942532,140823.1038,1.695344547,232.6283806
,68,30.46845397,0.696850352,142020.6105,1.690981842,233.9443004
,68.2,30.77526999,0.703812443,142522.4158,1.692290623,234.9523334
,68.4,30.86655577,0.710858504,143573.5756,1.689236727,236.1849813
,68.6,30.92371336,0.717977631,145358.3826,1.680075053,237.7057932
,68.8,31.17723994,0.725155474,146030.3957,1.680511302,238.8222995
,69,31.11954209,0.732425852,146489.6364,1.684874009,240.1163043
,69.2,31.43795098,0.739744515,147590.4395,1.680947548,241.2832121
,69.4,31.60240596,0.747146726,148638.9737,1.678329917,242.5870796
,69.6,31.676148,0.75462932,149371.343,1.679638715,243.9775056
,69.8,32.09021526,0.762164668,150485.0738,1.675712253,245.1959114
,70,32.02413709,0.76980756,151577.1042,1.673530912,246.6630345
,70.2,31.96720006,0.777526485,151530.8608,1.680947501,247.6842135
,70.4,32.00927301,0.785316386,151267.0051,1.691417973,248.7963351
,70.6,32.34007924,0.793165539,151555.5976,1.697089451,250.0914383
,70.8,32.73661041,0.801089256,151992.3447,1.699270766,251.1443951
,71,32.72455791,0.809119533,152887.2163,1.698398228,252.51729
,71.2,32.96296075,0.817214023,154246.6297,1.69141789,253.7532255
,71.4,33.22465002,0.825388355,155960.9525,1.682256202,255.2356901
,71.6,33.99641588,0.833611153,156902.4365,1.681819863,256.7532212
,71.8,34.9470744,0.841904737,157300.0587,1.68487366,257.8719239
,72,35.39844761,0.850314464,157697.0619,1.690108861,259.2393429
,72.2,35.51279874,0.858831058,157453.6484,1.701451863,260.4730866
,72.4,35.90423224,0.867414944,157585.9123,1.707995873,261.602742
,72.6,36.36804647,0.876080277,157953.6835,1.711049719,262.619542
,72.8,36.63213803,0.884845884,158190.3326,1.716721201,263.8576693
,73,36.72895949,0.893710522,158386.7985,1.721083889,264.8799448
,73.2,36.59194107,0.902679636,159108.4406,1.721520172,266.1936717
,73.4,36.8318587,0.911713909,159660.6309,1.723265228,267.4120766
,73.6,36.9178197,0.92084914,160224.8483,1.72413776,268.494615
,73.8,37.80426552,0.930023386,161196.3606,1.722828869,269.8620382
,74,37.88187606,0.939343216,162216.7426,1.719774975,270.9905961
,74.2,37.94282933,0.948757635,163080.257,1.720211239,272.381022
,74.4,38.19515516,0.958254017,163917.8825,1.719774946,273.6399675
,74.6,38.38089621,0.967850324,164756.4288,1.718466121,274.7750997
,74.8,38.43681124,0.977551458,165564.7887,1.718902385,276.1655263
,75,38.55345553,0.987346108,166416.0747,1.718466105,277.5701966
,75.2,38.66425932,0.997239616,167603.2333,1.713667129,278.7721656
,75.4,39.2601732,1.007200624,169315.881,1.705377952,280.2392937
,75.6,39.99961185,1.017252172,170975.2926,1.69883384,281.8959776
,75.8,40.3833031,1.027428702,172621.8966,1.690980953,283.2633972
,76,40.72453999,1.037710193,174553.4446,1.68312807,284.9902017
,76.2,41.23842531,1.048083575,175723.374,1.680074136,286.3280382
,76.4,41.66450543,1.058566943,176785.1781,1.679201559,287.8400896
,76.6,42.20664946,1.069148194,177995.073,1.678328971,289.5690865
,76.8,42.2956874,1.079865486,178925.4102,1.677892694,290.9474607
,77,42.53448978,1.090680589,179624.4412,1.68094656,292.5975665
,77.2,42.4162955,1.101627959,179874.038,1.685745536,293.8619875
,77.4,43.3228392,1.112617715,180060.9152,1.691853227,295.2820045
,77.6,43.30113576,1.123779245,180767.3854,1.694034577,296.8488358
,77.8,43.71710947,1.135023979,180653.8631,1.701451121,297.9982145
,78,43.98286763,1.14639151,181335.4786,1.704068714,299.5365602
,78.2,44.31600931,1.157868848,181567.6227,1.708867649,300.6979909
,78.4,45.03606827,1.169436125,181642.848,1.715847895,301.9876193
,78.6,45.16988046,1.18115828,181407.0848,1.725882081,303.3309324
,78.8,45.21796562,1.19300374,182043.9691,1.726754615,304.5077001
,79,45.19738201,1.204972679,182799.9654,1.728063426,305.9824939
,79.2,45.94108114,1.217011519,184522.4619,1.721083046,307.6172644
,79.4,47.38415747,1.22912538,186426.3736,1.712357524,309.1797258
,79.6,47.5440861,1.241445388,187876.6345,1.707122276,310.5701538
,79.8,47.53382662,1.253900371,189039.1251,1.706249739,312.2684674
,80,47.7440589,1.26646605,190282.1089,1.703195834,313.6764264
,80.2,48.32997307,1.27913317,191000.0471,1.706249666,315.2750386
,80.4,48.2410181,1.291971997,191017.9305,1.713666254,316.6293063
,80.6,48.77446798,1.304898955,191684.2506,1.714975014,317.9408475
,80.8,49.37778996,1.317984342,192164.0405,1.719337652,319.5120677
,81,49.60331925,1.331160364,191854.083,1.728063019,320.6362439
,81.2,49.74602636,1.34450729,192147.1627,1.732861969,322.0474899
,81.4,50.17828968,1.35796938,193250.203,1.731116852,323.50147
,81.6,50.40666225,1.371580132,193933.2413,1.73198937,324.7330239
,81.8,50.47150161,1.385338408,195844.4125,1.725009054,326.4631139
,82,50.99273648,1.399204912,197775.9872,1.718028696,328.198686
,82.2,51.21022561,1.413230751,198991.7314,1.714974791,329.5430954
,82.4,51.72392683,1.427378031,200130.4479,1.713665936,331.1055495
,82.6,52.38489056,1.441657754,200951.5905,1.715410953,332.7863385
,82.8,52.7092392,1.456103143,200897.267,1.721954963,333.9915974
,83,53.75917276,1.470645853,201085.4688,1.728062636,335.5113245
,83.2,53.96364993,1.485390296,201758.3651,1.730243963,337.0902116
,83.4,54.79968203,1.500241292,202100.5324,1.734170309,338.4905064
,83.6,55.50047099,1.515250536,202858.5035,1.734170244,339.781232
,83.8,55.3412408,1.530467247,204005.7903,1.732425182,341.4477702
,84,55.92673299,1.545787605,204851.8544,1.731552589,342.8075234
,84.2,56.65948579,1.561252092,205684.2161,1.731988791,344.3984674
,84.4,56.97282586,1.5768995,207348.7952,1.726317262,346.0452877
,84.6,57.83492345,1.592668038,208573.4826,1.723263298,347.5168035
,84.8,58.49895152,1.60860785,210624.4005,1.71628293,349.4156359
,85,58.88044971,1.624726373,212390.7258,1.710175127,350.9704191
,85.2,59.33847724,1.641000947,214294.7671,1.704939855,352.8725357
,85.4,59.8701213,1.657434138,214910.5695,1.70799369,354.4503298
,85.6,60.58896589,1.674019928,216297.5433,1.707121081,356.3842258
,85.8,61.3177694,1.690771668,217378.4783,1.706248481,357.8918973
,86,61.29763913,1.707740998,218149.1622,1.709302366,359.7370343
,86.2,62.07548376,1.724828374,219101.0042,1.709302294,361.255665
,86.4,62.34737282,1.742120688,220638.2911,1.706248386,363.0438283
,86.6,62.4761098,1.759596289,220821.6081,1.713228678,364.7476235
,86.8,62.93100946,1.777225869,220929.9239,1.719336402,366.1325765
,87,63.32014357,1.795036996,221980.3429,1.720645174,367.93389
,87.2,64.05873912,1.813003975,222685.3818,1.722390185,369.3462383
,87.4,64.22564034,1.83118925,223508.0964,1.724135239,370.9733352
,87.6,64.36838109,1.849558721,225627.0603,1.717591195,372.992688
,87.8,65.12020343,1.868072581,227204.5824,1.713228439,374.613217
,88,65.66479859,1.886786271,229012.8764,1.708865693,376.6961239
,88.2,66.26178735,1.905684394,230856.8402,1.702757874,378.451421
,88.4,66.54337291,1.924793296,233030.863,1.695341278,380.4817323
,88.6,66.87152662,1.944090908,234281.3229,1.69534125,382.6270912
,88.8,67.15388298,1.96358551,235600.7028,1.693159879,384.3473219
,89,67.72079276,1.983257224,236625.0723,1.694468631,386.4236563
,89.2,68.1129262,2.003138169,237059.3979,1.69839502,387.9893967
,89.4,68.77297006,2.023201183,236874.4449,1.709301683,390.0295733
,89.6,69.39137596,2.043468333,238046.6929,1.708429089,391.6314749
,89.8,70.34758956,2.063917004,239009.2286,1.710610346,393.5807134
,90,70.62143329,2.084616169,240063.5967,1.711046589,395.1913764
,90.2,71.47606266,2.105484956,241858.9178,1.707992629,397.2622342
,90.4,72.0926728,2.126579116,244100.2591,1.701884808,399.3221336
,90.6,72.64933669,2.147889214,244400.5979,1.70842879,401.29876
,90.8,73.10694444,2.169419945,244835.7805,1.712355168,402.8612152
,91,73.4005905,2.191177605,244150.733,1.724134399,404.6011704
,91.2,74.14604206,2.213124226,243799.5306,1.732423438,405.9992755
,91.4,74.65846542,2.235306681,243789.6364,1.738967422,407.5442007
,91.6,75.17501392,2.25771175,245192.9117,1.737658567,409.4605638
,91.8,75.48016858,2.280355874,246675.9962,1.736349733,411.4755366
,92,75.96169616,2.303215766,248345.4567,1.732423269,413.1387955
,92.2,76.58381518,2.3262962,249393.7999,1.733732017,415.0792649
,92.4,77.09688984,2.349615691,249496.3002,1.739839732,416.6680179
,92.6,78.33886278,2.373121298,250254.5576,1.74202096,418.425515
,92.8,78.82440271,2.396913055,251346.1553,1.741148377,419.995641
,93,79.15097009,2.420954267,252939.2087,1.738967003,422.0380065
,93.2,79.72755043,2.445221272,255458.4498,1.729805307,423.8623332
,93.4,80.25416482,2.469736004,258182.3192,1.720643616,425.9583896
,93.6,80.32182696,2.494527056,260742.8164,1.71409958,428.3601377
,93.8,81.23737778,2.519511451,262327.3986,1.711481884,430.2337743
,94,82.27604212,2.544738738,263775.9846,1.71104552,432.4788508
,94.2,83.14533011,2.570230657,263363.2569,1.719770812,434.038025
,94.4,83.81278874,2.595992052,263715.1089,1.725005973,435.9105639
,94.6,84.36495788,2.622019911,263589.8996,1.733295025,437.8137795
,94.8,85.14383757,2.648294205,263600.1601,1.739402712,439.2995413
,95,85.58400329,2.674854918,263845.5826,1.74551043,441.1052408
,95.2,86.19304649,2.701671366,265130.1211,1.744201568,442.784937
,95.4,86.88442651,2.728751798,265522.8241,1.748564188,444.5435254
,95.6,87.49379966,2.75610975,266030.3868,1.752490547,446.395245
,95.8,88.20589562,2.783735826,266635.6892,1.755108091,448.0919263
,96,88.68370631,2.811654878,267585.5791,1.755544314,449.8444851
,96.2,89.63411524,2.839823284,268929.4819,1.754671688,451.8244053
,96.4,90.39558842,2.868287164,270836.0223,1.750308932,453.7298159
,96.6,91.39500174,2.897021423,272771.5295,1.745509885,455.547575
,96.8,92.18093096,2.926058435,274509.1347,1.742892201,457.7192384
,97,92.71052159,2.955404048,275228.8827,1.744637225,459.3868825
,97.2,93.43145235,2.98503192,274189.1201,1.756852671,461.0852084
,97.4,94.36327755,3.014943524,273075.805,1.768631828,462.5819299
,97.6,94.84945605,3.045185125,272705.2892,1.775175807,463.9033365
,97.8,95.42961549,3.075724406,273447.6519,1.777357093,465.7331425
,98,96.16990873,3.106560009,274893.5511,1.774303144,467.3021775
,98.2,96.92887536,3.137704004,279325.4366,1.756416073,469.7609117
,98.4,97.68319034,3.169319961,283670.266,1.73940154,472.1297991
,98.6,98.60516412,3.201005376,287942.4291,1.724568333,474.7824724
,98.8,98.98495015,3.233124961,290685.8642,1.716279202,476.9124953
,99,100.0653405,3.265439433,292592.8629,1.714097761,479.3942439
,99.2,101.1111334,3.298162685,292561.4747,1.720641687,481.1681773
,99.4,101.4712094,3.331259889,291811.1401,1.732857163,483.3190178
,99.6,102.3999846,3.364652144,292261.003,1.736783489,485.0315912
,99.8,103.3794656,3.398376583,293361.2367,1.739401007,487.1703881
,100,104.0168925,3.432462503,295351.151,1.735910802,489.1283916
,100.2,104.846068,3.466878156,298832.3847,1.726312827,491.7416199
,100.4,105.8395315,3.501628927,301873.4974,1.718459909,494.2014541
,100.6,106.5117424,3.536749976,303337.16,1.717587311,496.2766967
,100.8,107.4131453,3.572208805,303478.4829,1.72369498,498.5677941
,101,108.5008858,3.608011664,302451.8659,1.734165311,500.2190123
,101.2,108.8330069,3.644224057,299991.5329,1.752924804,501.9754054
,101.4,109.8669607,3.680754071,298046.0454,1.767321549,503.1510935
,101.6,110.8089072,3.717657177,297089.9492,1.778228158,504.8636678
,101.8,111.8048823,3.754927474,297335.8656,1.783463278,506.6836211
,102,112.1513308,3.792614651,298193.3811,1.783899513,508.1847199
,102.2,112.9116972,3.830653017,301171.2429,1.775174082,510.4878676
,102.4,113.665762,3.869073748,304668.3113,1.763831045,512.7647191
,102.6,114.7929698,3.90785491,307741.3783,1.754669313,514.865171
,102.8,115.5889335,3.947046135,312087.3032,1.741144934,517.615361
,103,116.3149368,3.98663545,315488.0965,1.731110706,519.8659165
,103.2,117.5010373,4.026592016,319110.9108,1.72238524,522.715819
,103.4,118.8593219,4.066938705,321094.9495,1.720203775,525.0934836
,103.6,119.4494987,4.107741368,322125.3979,1.721512519,527.141337
,103.8,120.523902,4.148922027,323089.9631,1.724566294,529.703071
,104,121.5766044,4.190517862,324025.869,1.726311268,531.753123
,104.2,122.6001163,4.232533741,324924.1456,1.729365042,534.2107685
,104.4,123.54451,4.274976645,325994.9915,1.731546296,536.4744746
,104.6,124.6710692,4.317834119,327109.2573,1.732854994,538.4806975
,104.8,125.6577645,4.361131294,328179.9455,1.735908778,540.9394406
,105,126.8757188,4.404848402,328682.3782,1.740707604,543.1878131
,105.2,127.7299685,4.449028609,328804.1593,1.745942731,544.9814692
,105.4,128.6806731,4.493646359,330126.5213,1.746378912,547.2605171
,105.6,129.1852923,4.5387417,333429.4873,1.738526049,550.0008432
,105.8,130.3363935,4.584247417,337280.3143,1.728928057,552.8825235
,106,131.5123854,4.630208776,340309.0817,1.721947665,555.2054029
,106.2,132.3296619,4.676655583,343784.7363,1.71496731,558.2108911
,106.4,133.5828929,4.723540319,345079.1353,1.716712271,560.7342799
,106.6,134.5223412,4.770916818,343944.9876,1.727618865,562.5871085
,106.8,135.786239,4.818747894,342664.6673,1.740270504,564.8924571
,107,136.7080608,4.867082088,341562.9042,1.750304562,566.6422895
,107.2,137.9143889,4.915883104,341347.9519,1.757720997,568.8577909
,107.4,139.200522,4.965169193,343060.91,1.756412073,571.198203
,107.6,140.355102,5.014959237,346049.5242,1.74899542,573.4816393
,107.8,141.0702456,5.065278425,348449.7678,1.745941482,576.1869087
,108,142.0757171,5.11608403,350354.4958,1.743760051,578.3531028
,108.2,143.4264352,5.167377286,351993.9029,1.744196191,580.9181338
,108.4,144.385145,5.219211785,351287.1244,1.754230246,582.9966722
,108.6,145.4893921,5.271557485,349861.221,1.767318155,585.0248123
,108.8,146.4337895,5.324439586,349947.2921,1.772117003,586.7658794
,109,147.9838821,5.377813166,351622.9942,1.770808054,589.1972398
,109.2,149.0479342,5.43175504,353140.4159,1.768626617,591.2461985
,109.4,150.0078857,5.486245704,356170.3946,1.760337451,593.7465775
,109.6,151.4703476,5.541250721,360677.5887,1.747249303,596.8506912
,109.8,152.7197,5.596822461,362720.7503,1.74506785,599.5209087
,110,154.1878099,5.652938089,363156.2929,1.748994114,601.4679744
,110.2,155.3462833,5.709637836,363502.5293,1.755101741,603.8292065
,110.4,156.4289437,5.766912316,364394.3991,1.758155507,606.1027808
,110.6,157.5023592,5.82476335,365168.6976,1.762081806,608.5034557
,110.8,158.824068,5.883181572,367859.14,1.756846479,610.7682702
,111,160.1153113,5.942188804,372174.9861,1.746375953,613.8614252
,111.2,161.18595,6.00180345,375610.8816,1.738523051,616.3826272
,111.4,162.4557847,6.062003918,377684.6822,1.737214131,618.996965
,111.6,163.8628221,6.12280022,378304.4088,1.742449199,621.6869093
,111.8,164.7783988,6.184239767,378515.2464,1.748993113,624.2661804
,112,165.786242,6.24629046,379577.3252,1.750738084,626.4049856
,112.2,167.5428888,6.308915273,381392.1683,1.750737918,629.1705395
,112.4,168.6990651,6.372208979,385107.5392,1.74288501,632.0544164
,112.6,170.3473357,6.436106164,390256.2404,1.729360592,634.9591211
,112.8,171.9771976,6.50064673,394828.1598,1.720198843,638.4357764
,113,173.4230591,6.565847769,396626.6814,1.719762442,640.9821866
,113.2,174.9807356,6.631696569,398789.9931,1.719326031,644.1082205
,113.4,176.6036278,6.698202811,400231.5804,1.721070946,647.0359353
,113.6,177.6326736,6.765585397,400331.0613,1.726960446,649.7099863
,113.8,179.0602482,6.833278836,402082.173,1.726305913,652.5440169
,114,180.4227826,6.901827497,404615.2734,1.723688188,655.8387836
,114.2,182.141352,6.971041456,406548.6196,1.72237923,658.5177792
,114.4,183.6430451,7.040965109,409221.9592,1.719325226,661.6208035
,114.6,184.9557367,7.111603782,412460.3019,1.715834974,665.1127952
,114.8,186.5087961,7.182936307,413510.4085,1.718888693,667.737003
,115,188.2452225,7.254973573,415863.1616,1.718888532,671.0668405
,115.2,189.5334407,7.327764152,418650.0917,1.715834549,673.8641648
,115.4,191.3062484,7.401254102,421211.154,1.714961853,677.0888176
,115.6,193.2033395,7.475474239,423000.7828,1.717143007,680.4581039
,115.8,194.0897106,7.550506914,424390.801,1.718887988,683.1929651
,116,195.7935128,7.626239433,423098.4476,1.73066701,685.988107
,116.2,197.3061932,7.702939813,421031.6145,1.74331858,687.930797
,116.4,198.9997656,7.780208545,419385.9563,1.755097599,690.3106705
,116.6,200.2509467,7.858282567,419064.8544,1.762513999,692.9206324
,116.8,202.1103089,7.936902662,420293.789,1.764695151,695.7617966
,117,203.4515236,8.01654537,423644.6541,1.758151036,698.3246459
,117.2,204.9856612,8.096975623,428550.9058,1.748116778,701.828697
,117.4,206.607458,8.17820823,432159.2088,1.742445171,704.9152916
,117.6,208.3909708,8.260246372,435303.0552,1.738082346,708.0588662
,117.8,209.8648067,8.343129289,439343.331,1.730665692,711.3985646
,118,211.7662157,8.426816779,443134.6898,1.724557796,715.0472557
,118.2,213.2131576,8.511375191,445284.0663,1.722812598,717.9158072
,118.4,215.0706116,8.596756185,448334.474,1.719322301,721.4023354
,118.6,216.8484624,8.683000271,451191.2485,1.718013339,725.111288
,118.8,218.7152113,8.770105018,451869.3316,1.72237582,727.7256472
,119,220.1274878,8.858115018,451535.3759,1.731973526,730.8385369
,119.2,221.8799573,8.946986821,452116.161,1.738517341,734.0478551
,119.4,223.7184083,9.036746023,453602.5304,1.740698495,736.986539
,119.6,225.3853008,9.127418049,454941.071,1.742443398,739.6304794
,119.8,227.3129153,9.218983743,456745.8563,1.744188277,743.0249742
,120,229.2104276,9.311470057,460434.8323,1.738080386,746.023923
,120.2,231.2105585,9.404873717,464909.0588,1.731099956,749.8643666
,120.4,232.798229,9.499242495,468369.4747,1.727173421,753.4407386
,120.6,234.8858475,9.594525852,471790.2186,1.722810575,756.681842
,120.8,236.6471262,9.690787371,476832.7353,1.714957641,760.847703
,121,238.5588631,9.788006098,479392.2654,1.713648669,763.9869029
,121.2,240.3481243,9.886209476,482465.0215,1.712775973,767.9040428
,121.4,242.1147615,9.985400939,484080.7293,1.715829662,771.4278299
,121.6,243.8155033,10.08559345,484789.7567,1.720192147,774.2416054
,121.8,245.7673824,10.18677584,485380.1612,1.726735941,777.8486688
,122,247.7332456,10.28897401,484921.3556,1.734152253,780.4728983
,122.2,249.4077066,10.39221829,484078.1811,1.743313654,783.4882821
,122.4,251.175199,10.49649352,486398.0455,1.742440953,786.8794889
End Of Loading Marker,122.582,253.2773381,10.59226171,488929.7632,1.739823176,789.9211814
,122.8,254.7252087,10.5948141,491844.3426,1.737641712,793.8185935
,123,256.3353832,10.59470873,494898.3912,1.734151446,797.0454454
,123.2,257.2915191,10.59464628,499446.8069,1.728043653,801.1565072
,123.4,258.2360055,10.59458458,499780.3212,1.734587533,804.4271723
,123.6,258.9649753,10.59453703,500088.8286,1.742003959,807.8610909
,123.8,259.4850854,10.59450318,499850.2909,1.748984145,810.4403642
,124,260.4570312,10.59443969,499907.8291,1.755964288,813.5861183
,124.2,261.0778267,10.59439924,499013.2093,1.764253248,815.9374931
,124.4,261.4381716,10.59437587,500964.1606,1.76425322,819.0678938
,124.6,261.9482964,10.59434268,503735.9788,1.762508114,822.6464389
,124.8,262.3935166,10.59431374,507461.8536,1.757709164,826.2742898
,125,262.8062845,10.59428694,509039.4638,1.75814539,829.0946141
,125.2,262.9860616,10.59427542,511458.7205,1.757709109,832.6895867
,125.4,263.3314286,10.59425303,511570.8989,1.764253036,835.761922
,125.6,263.7125763,10.5942283,510348.4227,1.772978293,838.0815111
,125.8,263.8682222,10.59421837,507169.6883,1.788683794,840.4865621
,126,264.2368883,10.59419445,505596.2345,1.798717839,842.4325208
,126.2,264.4840663,10.59417851,503150.0419,1.812242009,844.6633571
,126.4,264.7911562,10.59415864,501193.9477,1.823148588,846.6136983
,126.6,265.1523332,10.59413522,501086.4132,1.82794746,848.5224063
,126.8,265.5709258,10.59410803,505305.0786,1.820530926,851.5859735
,127,265.9753726,10.59408177,509253.7458,1.813986922,854.7152834
,127.2,266.1817772,10.59406851,512637.9742,1.808315467,857.3526227
,127.4,266.6985587,10.59403488,519008.5023,1.795227489,860.8610442
,127.6,266.5679589,10.59404372,523435.9458,1.788683538,864.3628776
,127.8,266.7136195,10.59403444,524152.3187,1.791737374,866.8468173
,128,267.0490011,10.59401271,523582.691,1.799153834,869.5257955
,128.2,267.2379314,10.59400059,523057.2869,1.805261516,871.6339154
,128.4,267.3798475,10.59399156,520265.1642,1.818349431,873.6598564
,128.6,267.5596246,10.59398004,518068.4323,1.829692284,875.7887914
,128.8,267.6487017,10.59397447,516958.2221,1.836672504,877.4772567
,129,267.8563545,10.59396112,517606.0744,1.839290069,879.9283281
,129.2,267.8672133,10.59396068,517853.125,1.841907654,881.7099256
,129.4,268.1089826,10.5939451,518695.6259,1.843216423,883.9396674
,129.6,268.2870955,10.59393369,518233.8594,1.848887841,886.119007
,129.8,268.2925456,10.5939336,517695.5057,1.853686747,887.7274844
,130,268.6221024,10.59391226,515891.631,1.863284528,889.4334876
,130.2,268.8630395,10.59389673,514489.2298,1.87113726,890.8398157
,130.4,268.8547598,10.59389754,512153.626,1.882480131,892.2001182
,130.6,269.0570039,10.59388455,510956.0394,1.889024074,893.2749984
,130.8,269.282963,10.59387,509361.2543,1.897313072,894.5142342
,131,269.0949477,10.59388261,508209.0066,1.903420791,895.4806304
,131.2,269.5251897,10.59385466,505603.1192,1.914327352,896.329803
,131.4,269.7711195,10.5938388,504053.2984,1.921307554,897.0935081
,131.6,269.4487185,10.59386023,502667.1891,1.928287816,897.8889725
,131.8,269.4899493,10.5938578,501624.6047,1.933959246,898.5978882
,132,269.6951057,10.59384462,501564.2172,1.936140547,899.2684569
,132.2,269.6801692,10.59384587,503963.4432,1.930905378,900.5263125
,132.4,269.9577191,10.59382794,506417.6224,1.925670179,901.8532043
Unloading Marker,132.588,269.8293635,10.59383662,508188.4466,1.922180083,903.001492
,133.4,270.1118711,10.45506738,1.7977E+308,1.8022074,0
,133.6,270.0747038,10.34888788,1.7977E+308,1.619412706,0
,133.8,269.7134299,10.24272964,1.7977E+308,1.363107517,0
,134,269.7360903,10.1370758,1.7977E+308,1.040053871,0
,134.2,269.3032549,10.03092226,1.7977E+308,0.681444709,0
,134.4,269.2651292,9.925537198,1.7977E+308,0.409870235,0
,134.6,268.9229516,9.819642501,1.7977E+308,0.223803549,0
,134.8,268.8129327,9.713732573,1.7977E+308,0.126080363,0
,135,268.5864183,9.607830287,1.7977E+308,0.078091298,0
,135.2,268.2201096,9.501937173,1.7977E+308,0.02879344,0
,135.4,268.1479516,9.396024761,1.7977E+308,0.019195627,0
,135.6,267.8552846,9.290126815,1.7977E+308,0.013524192,0
,135.8,267.6429161,9.184223602,1.7977E+308,0.016141778,0
,136,267.6148599,9.078308296,1.7977E+308,0.022685742,0
,136.2,266.8940724,8.972438439,1.7977E+308,0.022685743,0
,136.4,267.0628101,8.866510221,1.7977E+308,0.023122007,0
,136.6,266.9931485,8.760597645,1.7977E+308,0.020068157,0
,136.8,266.6480585,8.654703139,1.7977E+308,0.0122154,0
,137,266.3133699,8.548807951,1.7977E+308,0.010470343,0
,137.2,266.1821321,8.442899414,1.7977E+308,0.017886836,0
,137.4,265.8474434,8.337004226,1.7977E+308,0.023122008,0
,137.6,265.7690446,8.231092223,1.7977E+308,0.02530333,0
,137.8,265.4589032,8.125195424,1.7977E+308,0.017014308,0
,138,265.1629077,8.019297697,1.7977E+308,0.017014309,0
,138.2,265.0191882,7.91338998,1.7977E+308,0.024430802,0
,138.4,264.4053267,7.807513108,1.7977E+308,0.027484654,0
,138.6,264.3922485,7.701596819,1.7977E+308,0.027048389,0
,138.8,264.2551859,7.595688665,1.7977E+308,0.024867068,0
,139,264.1039775,7.489781438,1.7977E+308,0.020940689,0
,139.2,264.0118488,7.383870336,1.7977E+308,0.01003408,0
,139.4,263.819867,7.277965785,1.7977E+308,0.008289023,0
,139.6,263.5163824,7.172068549,1.7977E+308,0.009597816,0
,139.8,263.3635097,7.066161432,1.7977E+308,0.014832989,0
,140,263.043383,6.960265289,1.7977E+308,0.017450575,0
,140.2,262.9479259,6.854354404,1.7977E+308,0.019195633,0
,140.4,262.4172753,6.748472073,1.7977E+308,0.023122013,0
,140.6,262.2427678,6.642566376,1.7977E+308,0.027048393,0
,140.8,262.1564639,6.536654891,1.7977E+308,0.032283566,0
,141,262.1999691,6.43073489,1.7977E+308,0.037082474,0
,141.2,261.8049524,6.32484366,1.7977E+308,0.035337417,0
,141.4,261.6038173,6.218939709,1.7977E+308,0.033156096,0
,141.6,261.3311208,6.113040453,1.7977E+308,0.028793452,0
,141.8,260.8703674,6.007153536,1.7977E+308,0.024430808,0
,142,260.7699176,5.90124298,1.7977E+308,0.021813222,0
,142.2,260.7060807,5.795330021,1.7977E+308,0.020504429,0
,142.4,260.212875,5.689445233,1.7977E+308,0.017014314,0
,142.6,260.3171243,5.583521246,1.7977E+308,0.01570552,0
,142.8,259.9295965,5.477629525,1.7977E+308,0.012215405,0
,143,259.6360972,5.371731634,1.7977E+308,0.00785276,0
,143.2,259.7170474,5.265809176,1.7977E+308,0.010034083,0
,143.4,259.1239885,5.15993094,1.7977E+308,0.010470348,0
,143.6,258.6956873,5.054041893,1.7977E+308,0.009161554,0
,143.8,258.6717917,4.948126314,1.7977E+308,0.010906612,0
,144,258.4257226,4.842225311,1.7977E+308,0.017886844,0
,144.2,258.1896389,4.736323654,1.7977E+308,0.023122019,0
,144.4,258.0484157,4.630415772,1.7977E+308,0.028357193,0
,144.6,258.160154,4.524491294,1.7977E+308,0.027920928,0
,144.8,257.453928,4.418620483,1.7977E+308,0.022249491,0
,145,257.0331158,4.312730945,1.7977E+308,0.019195639,0
,145.2,256.8286522,4.206827213,1.7977E+308,0.016578052,0
,145.4,256.6391666,4.100922498,1.7977E+308,0.020068169,0
,145.6,256.6098622,3.995007273,1.7977E+308,0.029229725,0
,145.8,256.3063775,3.889110038,1.7977E+308,0.034901164,0
,146,255.9691924,3.783215013,1.7977E+308,0.033156107,0
,146.2,255.4476948,3.677332082,1.7977E+308,0.034028637,0
,146.4,255.5423748,3.571408723,1.7977E+308,0.034901166,0
,146.6,255.3978232,3.46550106,1.7977E+308,0.029665991,0
,146.8,254.9632811,3.359612423,1.7977E+308,0.027048404,0
,147,254.7467519,3.253709482,1.7977E+308,0.029229728,0
,147.2,254.4661502,3.147810745,1.7977E+308,0.022685759,0
,147.4,254.2113439,3.041910316,1.7977E+308,0.020504436,0
,147.6,254.0035518,2.936006802,1.7977E+308,0.015705526,0
,147.8,253.8648249,2.830098757,1.7977E+308,0.01134288,0
,148,253.2896562,2.724219347,1.7977E+308,0.004798911,0
,148.2,253.1530095,2.618311165,1.7977E+308,0.005235176,0
,148.4,252.7184674,2.512422528,1.7977E+308,0.01788685,0
,148.6,252.4844638,2.406520734,1.7977E+308,0.019195645,0
,148.8,252.0715566,2.300630678,1.7977E+308,0.01963191,0
,149,251.9365741,2.194722387,1.7977E+308,0.017886851,0
,149.2,251.3680622,2.088842539,1.7977E+308,0.020068175,0
,149.4,251.3716261,1.982925159,1.7977E+308,0.017886852,0
,149.6,251.0248716,1.877030762,1.7977E+308,0.012215411,0
,149.8,250.8104647,1.770862889,1.7977E+308,0.005671441,0
,150,250.425807,1.665235772,1.7977E+308,0.001745059,0
,150.2,250.0586658,1.559342713,1.7977E+308,0.005671441,0
,150.4,249.8837841,1.453172247,1.7977E+308,0.007852765,0
,150.6,249.3892879,1.347552337,1.7977E+308,0.013524207,0
,150.8,248.8478194,1.241670715,1.7977E+308,0.013960472,0
,151,248.7640118,1.135759067,1.7977E+308,0.010906619,0
,151.142,248.4057473,1.060581398,1.7977E+308,0.004362648,0
,226.4,247.950387,0.929377408,1.7977E+308,0.020504446,0
,226.6,247.4089185,0.823495787,1.7977E+308,0.025739624,0
,226.8,247.3009796,0.717585722,1.7977E+308,0.025739624,0
,227,246.819423,0.611700169,1.7977E+308,0.020504447,0
,227.2,246.1348314,0.505827938,1.7977E+308,0.015705534,0
,227.4,245.714851,0.399938346,1.7977E+308,0.010470357,0
,227.6,245.0061281,0.294067698,1.7977E+308,0.011342887,0
,227.8,244.0610857,0.188212554,1.7977E+308,0.014833006,0
,228,242.9978835,0.082365163,1.7977E+308,0.012651683,0
,228.154,241.4056126,0.000913428,1.7977E+308,0.012651684,0
END,,,,,,