File: GB1_test36.csv
Segment,Time On Sample,Displacement Into Surface,Load On Sample,Harmonic Contact Stiffness,Harmonic Displacement,Harmonic Load
Surface Marker,0,0,0,286.7727031,0.462787239,2.242006146
,0.2,0.128802327,0.000647681,2455.415539,0.302709087,2.32309533
,0.4,0.203111969,0.001298932,7564.588768,0.209802695,2.399801313
,0.6,0.363944345,0.001944515,14136.31122,0.164439949,2.472124102
,0.8,0.36296257,0.002600698,18736.88096,0.137832954,2.536776283
,1,0.481781502,0.003249033,23032.56286,0.121694285,2.725253838
,1.2,0.217487753,0.003922465,27177.59111,0.110353601,2.906060768
,1.4,0.27890218,0.00457456,30512.09685,0.104247077,3.081388718
,1.6,0.270016885,0.005231261,31384.87727,0.106864158,3.253429269
,1.8,0.227437677,0.005889939,30535.87252,0.114715403,3.398074825
,2,0.807572598,0.006507612,30714.64033,0.129981707,3.887897343
,2.2,0.653512213,0.00717338,29829.39108,0.148301278,4.333887806
,2.4,0.588886383,0.007833289,29076.55365,0.167493209,4.797411065
,2.6,0.708537334,0.008481127,29518.05991,0.180578615,5.251072154
,2.8,0.885592789,0.009125205,30691.27767,0.191919299,5.807738427
,3,0.935359994,0.009777621,33652.9009,0.197153461,6.507954451
,3.2,0.859918823,0.010438239,36329.11188,0.203259985,7.204883047
,3.4,0.799036765,0.011097903,38353.26609,0.21154741,7.895236839
,3.6,0.682830075,0.011761192,40114.67097,0.219834836,8.58230322
,3.8,0.707638799,0.012415242,41349.76726,0.22768608,9.169651862
,4,0.837689117,0.013062399,42767.4126,0.243824747,10.16135062
,4.2,0.757672224,0.013723317,44100.32695,0.258218696,11.09716356
,4.4,0.776241328,0.014377776,44648.6054,0.276102085,12.0176353
,4.6,1.016108959,0.01501774,43664.22204,0.304017616,12.95125673
,4.8,0.981433306,0.015675687,42853.50313,0.328007529,13.7216039
,5,0.646423936,0.016353308,43152.99312,0.354178349,14.96533643
,5.2,0.745692129,0.017002482,42407.76647,0.385583324,16.05017817
,5.4,0.73015131,0.017659175,41852.67898,0.416552121,17.11310383
,5.6,0.807788819,0.018309766,40720.13636,0.45537216,18.21657417
,5.8,0.644992964,0.018976106,38775.04553,0.500298729,19.05595666
,6,0.620300702,0.019633399,35970.16737,0.573140829,20.21531271
,6.2,0.440033908,0.020300884,33187.9542,0.650780918,21.16427515
,6.4,-0.102962821,0.020992129,30917.96206,0.720133599,21.82723363
,6.6,0.537072472,0.021605879,27843.47622,0.82481683,22.57785677
,6.8,0.596407096,0.022257668,25416.69999,0.919904119,23.12904406
,7,0.363727491,0.022928585,22507.3282,1.054247647,23.7273506
,7.2,-0.538671388,0.023643374,20654.74138,1.156313885,24.09444291
,7.4,0.167919874,0.024252763,18216.96497,1.306796024,24.34099823
,7.6,1.048388522,0.024850763,16655.4085,1.425000799,24.44838718
,7.8,0.977939047,0.025511054,15464.43016,1.537099124,24.56344609
,8,1.021466632,0.026163879,14950.26452,1.597728173,24.70918747
,8.2,0.847023487,0.026830982,14735.89564,1.63654823,24.93820948
,8.4,1.4238306,0.027448874,15476.53865,1.591621614,25.34694316
,8.6,1.442399705,0.028103333,17353.78201,1.476906216,26.12496097
,8.8,1.276276057,0.028769892,19341.45753,1.373967699,26.87558364
,9,1.253247695,0.029427076,21377.25939,1.287604017,27.59661982
,9.2,1.099603286,0.030092817,23789.48933,1.204729786,28.4633973
,9.4,1.182231969,0.030746355,25047.24679,1.178995148,29.21402012
,9.6,1.095975977,0.031404406,24926.27551,1.202985067,29.69945933
,9.8,1.467291601,0.032035759,24074.53971,1.257943749,30.08408534
,10,1.616476749,0.032681663,22759.02406,1.339509439,30.47309431
,10.2,1.904597432,0.033318465,21772.06102,1.404064088,30.7152663
,10.4,1.950620863,0.033971127,20920.521,1.467310215,31.00127005
,10.6,2.016611078,0.03462248,20730.81938,1.491736302,31.28179481
,10.8,2.343001422,0.035256776,21195.34866,1.478650868,31.67409143
,11,1.975545531,0.035939799,22645.35383,1.418458032,32.31732557
,11.2,2.125562625,0.036585648,24257.70137,1.355648071,32.89809952
,11.4,2.296378971,0.03722686,26472.42111,1.279752704,33.6629679
,11.6,2.216777537,0.037891026,27982.92043,1.237007051,34.2623703
,11.8,2.028191786,0.03855578,29048.22458,1.214761875,34.85519773
,12,2.216478548,0.039199123,28881.82438,1.243113575,35.45679192
,12.2,2.081137031,0.039863665,28267.65835,1.281933624,35.82936371
,12.4,2.508193239,0.040491367,27302.5023,1.340817919,36.2424806
,12.6,2.638243546,0.041138524,26910.40966,1.373095244,36.5821787
,12.8,2.234182411,0.041820669,26883.03545,1.389670125,36.96022915
,13,2.493184861,0.042459379,27958.13986,1.361318392,37.59141008
,13.2,2.411088101,0.043120434,29158.5238,1.325987803,38.13492664
,13.4,2.669258599,0.043759198,30898.11734,1.277571782,38.87897495
,13.6,1.620436745,0.044483579,32269.69009,1.246603065,39.59562683
,13.8,2.449324478,0.045084958,32277.88355,1.260124592,40.07668377
,14,2.658409968,0.045726938,31361.52317,1.307232038,40.46788455
,14.2,2.856680116,0.046369627,29966.76604,1.377020854,40.83716924
,14.4,2.703035719,0.047035369,28758.34323,1.440266995,41.07276605
,14.6,2.88549883,0.047679093,27450.73775,1.513545252,41.31055474
,14.8,2.898244289,0.048333934,27380.97178,1.528375378,41.62614505
,15,3.083203246,0.048977495,28161.89514,1.503513092,42.07980633
,15.2,3.156681001,0.049628359,29362.11801,1.46425687,42.6671551
,15.4,2.963103042,0.050296716,30556.99501,1.426309211,43.19533037
,15.6,3.052387834,0.050946544,32191.20294,1.378329387,43.88458851
,15.8,3.272288658,0.051587816,33075.31441,1.359573622,44.43796766
,16,2.989692129,0.052262005,33409.95514,1.360882189,44.94751409
,16.2,3.020740471,0.052915647,33574.65817,1.370914326,45.49103086
,16.4,3.076747292,0.053567655,33564.47401,1.387489171,46.01591904
,16.6,3.325766341,0.05420702,33454.76631,1.404064,46.41040726
,16.8,3.228694498,0.054869055,33303.80463,1.422819755,46.82023612
,17,3.014317807,0.055538775,33225.92419,1.442884064,47.34183651
,17.2,3.133552772,0.056186641,33215.95238,1.45422474,47.72974976
,17.4,3.087229833,0.056845352,33322.58548,1.463384527,48.22395538
,17.6,3.028011679,0.057504908,33452.12265,1.469054876,48.61625159
,17.8,3.337763026,0.058140294,33675.11141,1.472108115,49.0501887
,18,2.987778604,0.058818897,33804.64148,1.481267927,49.56630989
,18.2,3.168577816,0.05946273,33853.69413,1.491300057,49.95312744
,18.4,3.216681118,0.060115256,33799.946,1.507438721,50.3980222
,18.6,3.272271964,0.060767291,33763.60994,1.519651757,50.75415718
,18.8,3.472621981,0.061409844,33640.70768,1.534918051,51.10043017
,19,3.494102906,0.062064114,33672.05498,1.546694915,51.56504929
,19.2,3.388711571,0.062726694,33699.17012,1.554109984,51.90693874
,19.4,3.418096015,0.063380446,33490.43279,1.57330191,52.2992351
,19.6,3.667115061,0.064019811,33271.36785,1.590749095,52.59071815
,19.8,3.441923034,0.064690239,33010.48953,1.610813405,52.87562575
,20,3.544103037,0.065339222,32583.98407,1.640037468,53.1824498
,20.2,3.521906627,0.065996353,32308.22742,1.6614103,53.39722651
,20.4,3.6294943,0.066644983,32394.49046,1.670133894,53.71610447
,20.6,3.874353598,0.06728462,32519.81909,1.675804213,53.97580934
,20.8,3.820543118,0.067943822,32991.73669,1.667734886,54.34125846
,21,4.038780037,0.068585203,33780.51462,1.645707768,54.76040218
,21.2,3.804020598,0.069256258,34886.04893,1.612121918,55.2589907
,21.4,4.144554055,0.069889628,36161.48539,1.573301852,55.82223232
,21.6,4.096983168,0.070548587,37508.32061,1.531864742,56.34164125
,21.8,4.065634558,0.071211097,39097.41617,1.488682909,57.04733622
,22,4.232288821,0.071867197,40103.5191,1.465565347,57.58756586
,22.2,4.082801323,0.072550641,41209.66651,1.442447811,58.24394967
,22.4,4.380069486,0.07321157,42018.84833,1.430234743,58.87732247
,22.6,4.08914845,0.073917934,42310.99965,1.434160389,59.45371262
,22.8,4.506215138,0.074584615,42585.03881,1.438085977,59.9939426
,23,4.0730286,0.075314047,42881.62229,1.439830734,60.48705174
,23.2,4.529194662,0.075992263,43033.98325,1.44899048,61.08974241
,23.4,4.67587451,0.076697676,43220.54222,1.45378845,61.5576491
,23.6,4.221885865,0.077449729,43670.30047,1.453788489,62.17239189
,23.8,4.746268353,0.078144902,44157.89353,1.450735185,62.71481369
,24,4.672478195,0.078886562,44876.72476,1.444192489,63.44242467
,24.2,4.542946261,0.079639282,45428.40971,1.438958339,63.98813268
,24.4,4.799437595,0.080374049,45786.01629,1.44201158,64.6543794
,24.6,4.867907209,0.081128671,46175.00508,1.442883935,65.31185947
,24.8,4.690950599,0.081906977,46561.76461,1.44157541,65.8718128
,25,4.685374273,0.082681929,47072.5968,1.441139231,66.62133973
,25.2,5.056669724,0.083439813,47488.52484,1.43939448,67.165953
,25.4,4.929626353,0.084238218,48229.42219,1.432415609,67.88479739
,25.6,4.920718512,0.085036787,48579.25556,1.436341232,68.543373
,25.8,4.696334547,0.085857519,48714.50264,1.444628675,69.10990114
,26,4.788921954,0.086665505,48605.55065,1.462075874,69.78381811
,26.2,4.85405374,0.087483454,48428.33889,1.477778355,70.2637785
,26.4,5.102213026,0.08829774,48330.68874,1.493480819,70.86866045
,26.6,5.21393135,0.08912909,48457.37022,1.503076774,71.48450022
,26.8,5.518660555,0.089956144,48340.272,1.517034512,71.94473661
,27,5.403254099,0.090819071,48497.54002,1.526194306,72.60331215
,27.2,5.366049462,0.091685698,48607.80175,1.532737012,73.08327232
,27.4,5.592571365,0.092543536,48435.67743,1.549311838,73.63446012
,27.6,5.299123637,0.093444213,48320.07338,1.56283345,74.17797616
,27.8,5.378387724,0.094329386,48682.65796,1.560652543,74.7061518
,28,5.433523851,0.095225167,48969.76622,1.561524899,75.23871054
,28.2,5.216611171,0.096147721,49463.05006,1.557599298,75.8676992
,28.4,5.339132309,0.097057157,50248.32876,1.546694784,76.55805338
,28.6,5.530703024,0.09797594,50726.18608,1.546258588,77.2210126
,28.8,5.3437361,0.098924313,50791.51945,1.554546028,77.7141221
,29,5.428815837,0.099859403,50843.7314,1.563269624,78.21161536
,29.2,5.681947047,0.100797699,50677.72133,1.580280627,78.76718635
,29.4,5.38848612,0.101781415,50400.62508,1.599908761,79.26796632
,29.6,5.674060298,0.102736773,50505.27778,1.605579077,79.69861617
,29.8,5.816537656,0.103711323,50771.65635,1.607323786,80.18624744
,30,5.564669546,0.104721525,51292.52198,1.604270549,80.83715196
,30.2,6.07985699,0.105691415,51806.23003,1.600781061,81.45299245
,30.4,5.943626661,0.1067139,52316.05836,1.595110733,81.96144342
,30.6,6.140174375,0.10772477,52930.86094,1.589440374,82.62111532
,30.8,6.183641809,0.108755959,53502.64776,1.583770029,83.17230269
,31,6.308638617,0.109792138,54298.57159,1.575482596,83.91306361
,31.2,6.00767578,0.110866793,55052.17381,1.565450482,84.49383676
,31.4,6.196729312,0.111919924,56013.32999,1.553237422,85.2433644
,31.6,5.897426988,0.113015752,56791.7042,1.546258567,85.97974099
,31.8,6.063182526,0.114091922,57194.82267,1.546258553,86.56928172
,32,6.342913384,0.115171393,57508.99833,1.55105651,87.30237254
,32.2,6.729131995,0.116254777,57631.59569,1.557162998,87.83493212
,32.4,6.770089967,0.117371772,57759.61822,1.565014237,88.49350784
,32.6,6.659631418,0.118509888,57972.51489,1.569812229,89.14550854
,32.8,6.791268247,0.119643573,58423.80945,1.567195137,89.73943226
,33,6.705764539,0.120802908,59322.31567,1.557163004,90.57662312
,33.2,6.710109482,0.121968024,60107.09855,1.547567041,91.22314511
,33.4,7.081342139,0.123120729,61034.95102,1.537534867,92.0439
,33.6,6.930108895,0.124319332,61728.1838,1.531428365,92.6926132
,33.8,6.877043746,0.125523448,62196.56709,1.531864546,93.38077525
,34,7.203345477,0.12671478,62639.66361,1.534917782,94.22673358
,34.2,7.257597919,0.12793606,62864.24869,1.54189666,94.98283558
,34.4,6.881730709,0.12919785,62930.32301,1.549747939,95.55703351
,34.6,7.31867582,0.13041874,62943.88215,1.56021622,96.24519696
,34.8,7.105034735,0.131694773,63192.45196,1.566322762,97.04293865
,35,7.42966272,0.132948145,63222.47704,1.574610155,97.60289323
,35.2,7.219761364,0.134249371,63261.41748,1.584206135,98.28009694
,35.4,7.323086809,0.135542894,63746.71995,1.583769949,99.0120915
,35.6,7.408107304,0.136850634,64368.51368,1.578971959,99.65423042
,35.8,7.38247647,0.138178821,65273.2228,1.571556901,100.542924
,36,7.515329834,0.139509872,66040.16673,1.564141829,101.2267035
,36.2,7.618646866,0.140856313,67023.80354,1.554545858,102.0912898
,36.4,7.422460071,0.142235908,67651.4408,1.552364974,102.9164267
,36.6,7.553227087,0.143607833,68039.61539,1.553237324,103.5881524
,36.8,7.70229478,0.144992415,68403.14862,1.55607248,104.3727454
,37,7.815170483,0.146393229,68778.92604,1.558471462,105.1419972
,37.2,7.772469456,0.147818393,69278.44668,1.559343825,105.9868588
,37.4,7.915290812,0.14924564,70092.72432,1.554109652,106.8788405
,37.6,8.056445978,0.150687403,70629.80308,1.55236492,107.5724819
,37.8,7.756249839,0.152172666,70971.79426,1.555418208,108.2946133
,38,7.811709598,0.153649319,71322.38053,1.561088545,109.2019358
,38.2,7.957017489,0.155134984,71262.42501,1.574173936,109.9788582
,38.4,8.228363283,0.15662737,70601.62176,1.597291456,110.5125137
,38.6,8.075828626,0.158162609,69929.3743,1.622589916,111.1513644
,38.8,8.186187441,0.15969594,69771.55865,1.634366769,111.675157
,39,8.162184007,0.16125364,69751.81576,1.643962734,112.2646973
,39.2,8.412721285,0.162808959,69974.62297,1.649633052,112.9857343
,39.4,8.26475246,0.164406116,70680.29222,1.642654185,113.6322557
,39.6,8.60097544,0.165987586,71580.70978,1.634366733,114.4749269
,39.8,8.373134415,0.167622,71854.32565,1.637420016,115.1203524
,40,8.510516442,0.169248752,71954.16549,1.643962705,115.7449587
,40.2,8.632920774,0.170892919,72164.26898,1.649196855,116.4911988
,40.4,8.495754374,0.172570606,72350.68471,1.652686309,117.0664932
,40.6,8.504176393,0.174255532,72820.17978,1.651813949,117.8258825
,40.8,8.544209776,0.175955369,73652.21009,1.642654165,118.5534937
,41,8.384572667,0.177685383,74595.82865,1.632185859,119.3282236
,41.2,8.535249813,0.179412343,75252.16714,1.629568765,120.1687028
,41.4,8.885591967,0.181143593,75470.99765,1.633494353,120.8097466
,41.6,8.856562584,0.182917129,75139.86163,1.6500692,121.4990046
,41.8,9.914887794,0.184636898,74716.14093,1.666207761,122.0151301
,42,10.31430659,0.186417287,74407.31981,1.680165484,122.5487858
,42.2,10.31937869,0.188241627,74474.97175,1.687144365,123.2128407
,42.4,10.14141908,0.190096374,74921.45801,1.684963483,123.7979973
,42.6,10.73633715,0.191918866,76195.88106,1.668824765,124.6571064
,42.8,10.19480995,0.193834488,77585.75904,1.650069077,125.4559428
,43,10.09670853,0.1957401,79102.25868,1.630440985,126.3347738
,43.2,10.53105144,0.197629808,80973.05819,1.606887223,127.4119467
,43.4,10.59933375,0.19956269,82585.75757,1.589003837,128.5143215
,43.6,10.70005898,0.201512869,83450.13014,1.582024948,129.3405551
,43.8,10.55036444,0.203499089,83779.04955,1.585078223,130.154734
,44,10.65025145,0.205488792,83879.11101,1.594237995,131.1168466
,44.2,10.63948606,0.207505793,83396.19713,1.611249018,131.738165
,44.4,10.84585614,0.209528739,82696.82476,1.634802721,132.4526271
,44.6,10.67784592,0.211596721,82170.81783,1.652686118,132.9676526
,44.8,10.97572384,0.213654852,81984.14297,1.664899131,133.5758227
,45,10.79023612,0.215765371,81962.71234,1.675803651,134.3571273
,45.2,10.73452907,0.217888601,82186.13652,1.679293097,134.9817329
,45.4,10.76284547,0.220027663,82639.37585,1.679729275,135.7718049
,45.6,10.96753163,0.222176623,83133.36475,1.677548356,136.4259983
,45.8,10.72212998,0.224376696,83578.16263,1.678856921,137.2949667
,46,10.63479512,0.226588463,83667.76477,1.684091091,137.9108059
,46.2,11.11567788,0.228785117,83756.33219,1.690633745,138.648281
,46.4,10.88274311,0.231062082,83930.09112,1.694123209,139.2411078
,46.6,11.08158802,0.233322235,83864.03108,1.703719151,139.9216003
,46.8,10.940164,0.235616054,83801.99728,1.712006586,140.4903199
,47,11.20638949,0.2379176,83983.07178,1.715496,141.0831487
,47.2,11.05414094,0.240269939,84390.65873,1.716368377,141.8293879
,47.4,11.08491744,0.242633707,84667.92658,1.717676914,142.4189281
,47.6,11.30038284,0.245009097,85007.40549,1.718985434,143.1553065
,47.8,11.2229984,0.247427627,85259.93177,1.720293983,143.7558046
,48,11.26707464,0.249862528,85448.98506,1.723347239,144.3639738
,48.2,11.53743715,0.252306736,85398.59836,1.731198453,145.01488
,48.4,11.52243724,0.254794397,85250.13579,1.739485876,145.5123731
,48.6,11.5756532,0.257302444,85128.10998,1.748209472,146.1095842
,48.8,11.68876547,0.259831752,85040.33942,1.755624521,146.6092695
,49,13.3210124,0.262286726,85057.69746,1.760858515,147.1210147
,49.2,13.51647965,0.264860638,85258.17289,1.763911756,147.7302802
,49.4,13.70445522,0.267461037,85617.53645,1.763039377,148.2584566
,49.6,13.63868224,0.270104242,86508.02765,1.754315786,148.9696304
,49.8,14.02548521,0.272744287,87619.88339,1.741230349,149.676423
,50,14.48216769,0.275406094,89189.46323,1.722474571,150.6155253
,50.2,14.56696478,0.278119083,90758.3276,1.702846462,151.4395675
,50.4,14.49202337,0.28086984,93018.43105,1.674494774,152.5342715
,50.6,14.73405007,0.283627318,94486.60595,1.658356094,153.4109124
,50.8,14.7739088,0.28642589,95958.46886,1.643089794,154.3554919
,51,15.19812341,0.289227247,97592.17355,1.628695817,155.5849817
,51.2,14.90436174,0.292103891,98401.64655,1.624334046,156.4583329
,51.4,15.44254425,0.294954857,98597.83543,1.631312875,157.4598967
,51.6,15.20368203,0.297885595,98841.08021,1.635238521,158.2379133
,51.8,15.18944131,0.300830979,98938.24178,1.642217402,159.0455181
,52,15.09532881,0.30381116,99621.25013,1.642653592,160.1457007
,52.2,15.22334189,0.306806633,100162.0407,1.642653583,160.9697428
,52.4,15.07680707,0.309850286,101093.3121,1.638727973,162.0480094
,52.6,15.58334719,0.31288158,102177.0209,1.630876693,162.9925913
,52.8,15.3594314,0.315991635,103196.2379,1.624334015,163.9919599
,53,15.4628825,0.319111299,103735.9843,1.626514904,165.1425504
,53.2,15.15950565,0.322289087,104029.8414,1.630658643,166.1095926
,53.4,15.69722397,0.325443416,104042.7148,1.638727921,167.0218486
,53.6,15.42420314,0.32868287,103561.2208,1.654866603,167.9160202
,53.8,15.50683526,0.331931367,103317.5827,1.666207272,168.6513023
,54,15.77498675,0.335200417,103342.9443,1.674058488,169.4512376
,54.2,15.69745831,0.338524992,103456.7579,1.681473558,170.3476017
,54.4,15.9148504,0.341863568,103650.1189,1.686271512,171.0971299
,54.6,16.01326848,0.345243537,103825.4196,1.692814202,171.98692
,54.8,15.85003327,0.348674715,104079.0188,1.696739837,172.7638414
,55,15.99544559,0.352119942,103779.1218,1.708516681,173.4509091
,55.2,16.96198578,0.355545935,103455.1049,1.721165802,174.1982494
,55.4,17.97261376,0.359003298,102922.9887,1.735777727,174.8102584
,55.6,18.1546153,0.362549954,102862.5237,1.742974677,175.4748622
,55.8,18.09201826,0.366148361,102955.5291,1.747336483,176.104947
,56,18.10096306,0.36977822,104114.7495,1.737304346,177.0834965
,56.2,17.78835392,0.373465633,105386.4036,1.724655163,177.9305486
,56.4,18.09013299,0.377149625,107501.0364,1.702409961,179.1030561
,56.6,18.27210557,0.380878454,108963.3285,1.688888369,180.0574988
,56.8,18.55640189,0.384637914,110110.7402,1.680164745,181.013038
,57,18.81989348,0.38843658,111159.9293,1.675366742,182.1789706
,57.2,19.06174834,0.392274848,111944.5138,1.67231346,183.0928693
,57.4,18.76948604,0.3961868,112480.5982,1.674058209,184.1283988
,57.6,18.99468955,0.400103998,112943.5571,1.677111447,185.163931
,57.8,19.35133467,0.40405198,113820.6445,1.673185794,186.1096085
,58,20.03742514,0.408017824,114625.6985,1.67056865,187.1035025
,58.2,20.1403133,0.41206196,114925.8736,1.675366618,188.1335553
,58.4,20.06099825,0.416158766,115454.9805,1.675366627,189.0310152
,58.6,20.07735075,0.420290414,116999.9903,1.664025951,190.2813235
,58.8,20.19602633,0.424456766,117978.3615,1.659227963,191.3037055
,59,20.41785688,0.428658217,118577.7929,1.659664122,192.3249926
,59.2,20.59641939,0.432904772,119794.9398,1.653993768,193.6147502
,59.4,20.72921794,0.43719699,120405.3694,1.654429936,194.5987798
,59.6,21.01841597,0.441522028,120061.8797,1.668387662,195.6167797
,59.8,20.93572609,0.445914977,119917.4198,1.677983626,196.4594493
,60,20.83139854,0.450353461,120303.4307,1.681473076,197.4073157
,60.2,21.07981009,0.454813246,120545.746,1.688015749,198.4855843
,60.4,21.30159213,0.459319795,121061.8209,1.690196627,199.548512
,60.6,21.46263474,0.463875583,121903.6097,1.686707174,200.507338
,60.8,21.49887778,0.468485423,122494.9036,1.686270991,201.434385
,61,21.53511347,0.473141547,122841.8503,1.690632786,202.5816886
,61.2,21.61377109,0.477841662,123275.3334,1.691941319,203.4944904
,61.4,21.9461655,0.482572271,123212.4001,1.700664882,204.4796165
,61.6,21.88836853,0.487375987,123021.1133,1.709824664,205.2510598
,61.8,22.39296106,0.492190998,122764.3171,1.719856749,206.0071647
,62,22.43581447,0.497084839,122585.3157,1.730325059,206.9769481
,62.2,23.38298805,0.501968218,122508.7394,1.73730384,207.7067565
,62.4,23.56226539,0.506951317,123229.4424,1.735122925,208.7258516
,62.6,24.03521257,0.511965103,124091.7799,1.729452542,209.6244107
,62.8,23.85507222,0.517072355,125431.3142,1.718111888,210.6676118
,63,23.82800223,0.522220785,127340.6182,1.702409422,212.0636608
,63.2,23.95483447,0.527410789,128757.2616,1.691941097,213.152887
,63.4,24.25886345,0.532641231,130042.5579,1.685398373,214.4338796
,63.6,24.44807518,0.537931803,130646.6858,1.685834535,215.4157176
,63.8,24.4434345,0.543288222,130630.3514,1.69412195,216.3361898
,64,24.71665601,0.548680273,130216.2555,1.708515854,217.4232254
,64.2,24.89585435,0.554160229,129983.5305,1.717675611,218.1968616
,64.4,25.2164795,0.559658674,129458.4898,1.732069509,219.1118566
,64.6,25.84242536,0.565164162,129152.0292,1.742101579,219.7978314
,64.8,26.07484641,0.570778897,129539.1431,1.744282455,220.6394076
,65,26.20825665,0.576456539,130613.6549,1.740356825,221.7998608
,65.2,26.32335495,0.582192443,131249.3275,1.739484455,222.620616
,65.4,26.3078282,0.587994631,132305.6891,1.735122661,223.7306619
,65.6,26.74986374,0.59382501,134005.0161,1.723345775,224.9820681
,65.8,26.8308244,0.599737771,134844.7816,1.720292502,225.9660976
,66,27.00744969,0.605703532,135586.5111,1.718547767,226.9819057
,66.2,27.36459821,0.611717445,136743.9975,1.712877397,228.2267372
,66.4,26.95967253,0.617841857,137985.5609,1.705026204,229.2874694
,66.6,27.22944711,0.623983343,138565.1471,1.706334717,230.5038093
,66.8,27.71302256,0.630172594,139399.1234,1.703717593,231.5568766
,67,27.58344228,0.636464369,139907.7896,1.705026145,232.5847366
,67.2,27.94054165,0.642787324,139871.0091,1.714185882,233.6980719
,67.4,28.05137426,0.649190001,139452.3043,1.725526542,234.4695162
,67.6,28.11061585,0.655660444,139453.1263,1.73337777,235.4623118
,67.8,28.43107883,0.662178736,139376.967,1.740792792,236.3093676
,68,28.5219137,0.668777595,139821.2286,1.743846041,237.4413302
,68.2,29.15683218,0.675406715,140514.5411,1.741665079,238.3267408
,68.4,29.22351944,0.682139952,141336.3419,1.739920355,239.4915769
,68.6,29.37255883,0.688935337,141795.6793,1.7407927,240.3901348
,68.8,29.5199235,0.695798949,142432.086,1.740356506,241.3566314
,69,29.75712759,0.702725684,143248.6592,1.739484124,242.5839295
,69.2,29.85538526,0.709731272,143718.075,1.740356474,243.4759116
,69.4,30.15745906,0.716793676,144662.3966,1.737303193,244.6626658
,69.6,30.10511168,0.723950341,145138.3408,1.737739375,245.5940954
,69.8,30.63844434,0.731140331,145844.9493,1.735558426,246.5967564
,70,31.50537666,0.738380718,146641.428,1.734249803,247.8536459
,70.2,31.58361059,0.74574606,147351.3687,1.732505076,248.8519204
,70.4,31.67847172,0.753184273,148324.4464,1.730324169,250.0814091
,70.6,31.9954511,0.760682591,149490.0903,1.725089985,251.1279008
,70.8,32.22048824,0.768262368,150379.7697,1.723345244,252.2171281
,71,32.68095454,0.775902879,151392.6128,1.722036659,253.6153728
,71.2,33.51661719,0.783595226,152045.9272,1.722036579,254.6235151
,71.4,33.81274928,0.791400442,152844.9296,1.721600369,255.9231367
,71.6,34.28316196,0.799272767,153296.5664,1.722472679,256.9159354
,71.8,34.40414397,0.807246942,153909.3626,1.722472666,258.0073541
,72,35.05547999,0.815266582,154852.677,1.721164066,259.4110788
,72.2,34.93766738,0.823417364,155447.4704,1.721164081,260.4433221
,72.4,35.30777919,0.831617912,156290.9566,1.720727861,261.7495198
,72.6,35.20824333,0.839931699,157107.9231,1.719855516,262.828882
,72.8,35.79713104,0.848283794,157803.6989,1.720291635,263.9487948
,73,36.07444095,0.856740194,158991.1007,1.717674531,265.4204575
,73.2,36.31138787,0.86528428,160030.6351,1.714185073,266.5546127
,73.4,36.67269734,0.873906009,161203.7841,1.711567961,267.9999764
,73.6,36.85470828,0.882626201,161774.5327,1.712440303,269.0771498
,73.8,37.25176381,0.89141975,162519.209,1.712004085,270.2376055
,74,37.2740128,0.9003264,163189.8569,1.71418498,271.6972123
,74.2,37.40772864,0.909314727,163699.0047,1.715929685,272.8050678
,74.4,37.56888438,0.918391714,164875.8287,1.712440235,274.2559089
,74.6,37.98626555,0.927542955,165759.0008,1.710259297,275.4470475
,74.8,38.49015465,0.936780447,166865.1174,1.706333634,276.7094137
,75,38.50983541,0.946142608,167936.1922,1.704588915,278.3125705
,75.2,38.75329516,0.955584114,168893.5368,1.703716533,279.8105317
,75.4,39.23384494,0.965104785,169356.4929,1.706333563,280.9392102
,75.6,39.61038602,0.97472809,170998.4476,1.700663195,282.5182616
,75.8,40.81885937,0.984393217,172025.5377,1.699354538,283.8036457
,76,41.09470397,0.994216776,173708.6687,1.692811822,285.2643504
,76.2,41.52111537,1.004129291,174919.6112,1.691503243,286.9069593
,76.4,42.08727812,1.014132204,175397.5287,1.694120264,288.1156318
,76.6,42.40883232,1.024251614,174992.4672,1.705460894,289.4229251
,76.8,42.6388561,1.034478822,174974.2427,1.711567381,290.5735173
,77,42.87801499,1.044808091,174331.403,1.722908019,291.6572663
,77.2,43.50567685,1.055215599,174566.5262,1.727269749,293.0577052
,77.4,43.7131886,1.065755295,175535.7027,1.724652653,294.4800564
,77.6,43.73183144,1.0764133,176543.0524,1.721163219,295.7347487
,77.8,44.36193866,1.08713809,177772.0924,1.716801364,297.0245112
,78,44.51199503,1.098002377,180248.3724,1.705024511,298.9355889
,78.2,44.42659294,1.108991244,181978.265,1.698045653,300.3393095
,78.4,44.69059123,1.120067512,184802.092,1.684960252,302.2744959
,78.6,45.03027904,1.13125003,187225.8348,1.673183381,303.8666973
,78.8,45.08542297,1.142563687,189629.9333,1.662278897,305.571764
,79,45.44171377,1.153971271,191783.099,1.656172355,307.7041957
,79.2,45.8528949,1.165489771,192940.0302,1.655299957,309.279961
,79.4,46.18419066,1.177129307,192868.7267,1.665332047,311.015712
,79.6,46.61030982,1.188879546,192139.149,1.677981202,312.2189054
,79.8,47.3001375,1.200730488,191326.3147,1.691502689,313.471412
,80,47.62721722,1.212724354,191046.8649,1.702843314,315.1315534
,80.2,48.14562566,1.224826053,191137.6909,1.708513592,316.3511846
,80.4,48.12324905,1.237084913,192092.2486,1.709385954,318.0255685
,80.6,48.73479666,1.249425246,192818.0836,1.710694431,319.3525887
,80.8,48.81803804,1.261924435,193372.213,1.713747677,320.6697424
,81,49.59177565,1.274503745,193789.6976,1.719417929,322.2783851
,81.2,49.7490203,1.287249917,194565.9359,1.719854093,323.5692404
,81.4,50.03935612,1.300115447,195789.0003,1.718545527,325.2644468
,81.6,50.63582794,1.313090141,197813.9528,1.710694245,327.0418415
,81.8,50.74059825,1.326227619,199680.7059,1.702843013,328.6351373
,82,50.86280782,1.339562979,201047.715,1.699353569,330.2919895
,82.2,51.20049168,1.352884197,201338.7894,1.705023864,331.9565146
,82.4,51.55228666,1.366405682,200993.782,1.71374741,333.201348
,82.6,52.11121485,1.380049426,200026.2689,1.728141263,334.6116491
,82.8,52.5120513,1.393840629,199663.6623,1.735556267,335.4773353
,83,53.05180087,1.407761247,199524.3828,1.744715972,336.973109
,83.2,53.45841664,1.421830639,200505.5749,1.743843573,338.4765521
,83.4,53.86916967,1.436041133,201375.5308,1.742534995,339.7465898
,83.6,54.10685503,1.450405749,202494.4322,1.741226435,341.3815271
,83.8,54.72471721,1.464889706,203187.3139,1.741662552,342.6964936
,84,54.94654949,1.47954519,203875.1249,1.742098709,344.0739186
,84.2,55.69997244,1.494312999,204236.8238,1.746460423,345.610239
,84.4,56.18548489,1.509246738,204329.0899,1.7521307,346.7268651
,84.6,56.78994188,1.524322665,204984.9086,1.755183892,348.1579874
,84.8,57.20801867,1.539562447,206216.6377,1.753002955,349.5244558
,85,57.54038059,1.55496096,207283.4955,1.75387528,351.1385741
,85.2,57.80449827,1.570518678,208023.0475,1.754747611,352.3549159
,85.4,58.32982239,1.58621554,209718.6969,1.749513412,354.003006
,85.6,58.81186019,1.602072928,210621.8677,1.748641006,355.2872906
,85.8,59.48022877,1.618077097,210957.9272,1.752130369,356.5397976
,86,59.88817249,1.634258946,211593.1524,1.754747402,358.1769291
,86.2,60.77695554,1.650571717,213245.5906,1.749513166,359.8885796
,86.4,61.37702701,1.667067367,214550.555,1.745587496,361.2714871
,86.6,61.63930182,1.683750819,216760.7385,1.736863895,363.1277767
,86.8,62.00304747,1.700595163,218750.718,1.728576467,364.7177889
,87,62.12134197,1.71762491,221034.4801,1.719416703,366.4907965
,87.2,62.86606504,1.734784529,223012.9072,1.713746301,368.4895457
,87.4,63.05086066,1.752153376,224088.8387,1.712873926,370.0499687
,87.6,63.30384808,1.769692705,225248.1075,1.712873898,371.9402289
,87.8,64.09549278,1.787373261,225540.6149,1.717671788,373.4118984
,88,64.60882311,1.805249811,224739.2935,1.731193282,375.0862884
,88.2,64.87462081,1.82332222,223709.9017,1.744278615,376.190859
,88.4,65.49063909,1.841553169,222499.1036,1.759980987,377.4608994
,88.6,66.06711079,1.85996988,221320.6621,1.773938647,378.3857619
,88.8,66.69887747,1.878568037,221048.9298,1.781353615,379.4684204
,89,67.45291056,1.897344957,221659.0461,1.783970609,381.0255624
,89.2,68.16947604,1.916313007,223143.9191,1.778300216,382.3164242
,89.4,68.36271697,1.935506082,225874.6621,1.765214838,384.190247
,89.6,69.07048602,1.954858182,228946.2494,1.750384693,386.1572185
,89.8,69.34103638,1.974433529,231360.6626,1.73991638,387.8776299
,90,69.66064031,1.994202281,234547.8023,1.725522458,389.8314477
,90.2,70.29468832,2.014148981,237463.1799,1.714181747,392.0131958
,90.4,71.22487729,2.034276576,240038.6518,1.705458084,394.0886546
,90.6,71.35969355,2.05465885,241659.1457,1.702404822,396.0227457
,90.8,71.74156528,2.075229511,243845.0006,1.695862107,397.942595
,91,72.28646556,2.095996263,245160.9357,1.69673441,400.2503594
,91.2,73.04930255,2.11695725,245666.5099,1.700659942,401.8710587
,91.4,73.39197328,2.138156401,246603.266,1.703713158,403.9234993
,91.6,74.24168136,2.159534534,247580.2215,1.70502161,405.6241926
,91.8,74.93994115,2.181137027,247644.5442,1.711564218,407.2229754
,92,75.64731779,2.202956138,248502.3441,1.715053576,409.3334977
,92.2,76.09093272,2.225011672,249330.85,1.716362067,411.0078883
,92.4,76.78409617,2.247272507,249490.1752,1.722468496,412.8740462
,92.6,77.44311426,2.269759216,249953.231,1.725085501,414.4695415
,92.8,78.16532431,2.292467591,249771.7037,1.73293664,416.459526
,93,78.85754802,2.315406123,249328.5081,1.740351602,417.7964121
,93.2,79.58550873,2.338572765,248986.9656,1.748638917,419.5025844
,93.4,79.94737629,2.361996228,249428.464,1.751255951,420.9698671
,93.6,80.2775925,2.385657092,249921.8789,1.755181523,422.6354902
,93.8,80.88480882,2.409537559,252134.297,1.748638787,424.4139838
,94,81.47451613,2.43365907,254986.4606,1.739915162,426.6943554
,94.2,82.01177232,2.458026377,257107.5045,1.733808612,428.4147702
,94.4,82.6405036,2.482632499,259101.051,1.730319123,430.5658376
,94.6,83.26337192,2.507486262,260263.751,1.729882883,432.2226973
,94.8,83.91615058,2.532587736,260260.5462,1.736425491,433.7710735
,95,84.45740845,2.557948641,260178.7345,1.745149001,435.7062667
,95.2,85.31642896,2.583543482,260288.0729,1.750383053,437.1790345
,95.4,85.95827079,2.609409818,261169.8169,1.7521277,439.0703971
,95.6,86.35464738,2.635552171,263502.898,1.745584988,441.2105038
,95.8,87.10871875,2.661933541,265897.1357,1.737733706,443.0788554
,96,87.97672447,2.688572497,268587.4285,1.729010056,445.1576024
,96.2,88.33803292,2.715512326,270574.9163,1.725956773,447.4774208
,96.4,89.48215885,2.742671418,271658.6574,1.726392837,449.2098987
,96.6,90.06551022,2.770140354,271714.4115,1.733807806,451.1593382
,96.8,90.94083048,2.797866061,272088.5288,1.737733321,452.8271594
,97,91.86935091,2.825866789,273610.1727,1.735552337,454.7448252
,97.2,92.18135523,2.854189374,276089.1808,1.729009636,457.1062835
,97.4,92.77035203,2.882778318,279321.3213,1.718541305,459.6562235
,97.6,93.57727276,2.911640214,282226.8535,1.70894531,461.7919522
,97.8,94.01809154,2.940816184,283655.5276,1.70807291,463.8257668
,98,94.3257525,2.970294015,282670.1022,1.721594397,465.9866935
,98.2,95.15250009,3.00003383,281427.7271,1.734679652,467.4243969
,98.4,95.8069875,3.030083905,278965.6579,1.755616127,468.9530496
,98.6,96.78422156,3.060414527,276666.9758,1.773935499,470.0313314
,98.8,97.73145712,3.091051819,275519.9456,1.785712204,471.2728889
,99,98.95152159,3.121979045,275920.5646,1.790073856,473.0338593
,99.2,99.61496551,3.153253667,276907.8728,1.789201432,474.4792319
,99.4,100.5187915,3.184826767,278700.4307,1.785275738,476.4012811
,99.6,101.2994136,3.216886049,280385.3265,1.781350057,478.0307497
,99.8,101.8454014,3.2491235,281590.8801,1.780477646,479.6284375
,100,102.718318,3.281499573,282933.5351,1.780477556,481.6074689
,100.2,103.5420721,3.314367858,284601.9086,1.778296582,483.5832118
,100.4,104.1777542,3.347578764,286099.1874,1.775679451,485.1929545
,100.6,105.0779416,3.381106001,289052.6082,1.766519626,487.4360748
,100.8,105.7035337,3.41498813,291091.1744,1.761285431,489.3099061
,101,106.4488716,3.449202822,292684.8085,1.758232111,491.1366196
,101.2,107.1716924,3.483762825,293837.6813,1.759104393,493.2811149
,101.4,107.9011135,3.518669702,294203.7964,1.763902272,495.2327496
,101.6,108.6612608,3.553925217,294052.5699,1.770008681,496.6299087
,101.8,110.1060419,3.589489928,294918.2278,1.771317065,498.32404
,102,110.6464427,3.625471412,297372.3286,1.765646701,500.6109881
,102.2,111.5203956,3.661792438,299599.5921,1.759540127,502.484823
,102.4,112.3036086,3.698484346,302797.9268,1.749944142,504.9273789
,102.6,113.2473281,3.735534445,305592.5885,1.742529029,507.3787034
,102.8,114.4147814,3.772942025,306732.0604,1.742965088,509.3654106
,103,115.3084653,3.810743529,307460.2826,1.745582062,511.2995157
,103.2,115.9333709,3.848942362,308600.9587,1.747326709,513.5579749
,103.4,116.7021418,3.887515043,309620.6144,1.748198986,515.3605818
,103.6,117.5074567,3.926472523,310509.2916,1.751252146,517.4985047
,103.8,118.8335062,3.965787176,312054.9321,1.749943479,519.5049388
,104,119.5247197,4.005538419,313525.2887,1.750379586,521.9365377
,104.2,120.7058846,4.045656172,313635.9578,1.755613593,523.6602524
,104.4,121.569183,4.086197883,313207.0787,1.764337051,525.5614841
,104.6,122.3101208,4.127154967,313860.195,1.766081685,527.1975282
,104.8,123.1774486,4.168515116,315056.2762,1.767390124,529.5414646
,105,124.4215807,4.21026633,317512.2974,1.760847341,531.5314618
,105.2,125.1140672,4.252475128,322136.1741,1.74558107,534.3663152
,105.4,126.2902614,4.295076295,327117.6851,1.728133866,536.985302
,105.6,127.4019119,4.338109672,332738.9487,1.709814313,540.2551968
,105.8,128.2501834,4.381592805,336592.8877,1.698909801,543.0418376
,106,129.2934763,4.425499921,339419.8569,1.6932394,545.7912242
,106.2,130.4490112,4.469840859,341333.269,1.693239286,548.8551083
,106.4,131.2292689,4.514652068,341601.3128,1.698473332,550.9711168
,106.6,132.2627817,4.559896714,340982.3217,1.709377654,553.5528458
,106.8,133.1186022,4.605607688,340837.5502,1.717228753,555.6984424
,107,134.1199398,4.651768311,340401.7207,1.725952192,557.7388441
,107.2,135.2730333,4.698382784,340184.1822,1.734675617,560.0707322
,107.4,136.5067506,4.745460467,339596.9796,1.744707562,562.3248195
,107.6,137.4928897,4.793027348,339821.1794,1.749505405,564.1153784
,107.8,138.4989193,4.841070835,340647.9223,1.751686186,566.1985169
,108,139.8551201,4.88957395,341844.6584,1.753430757,568.7232701
,108.2,140.4649907,4.93861356,342393.5084,1.756047754,570.6212124
,108.4,141.4329342,4.988122297,345176.9269,1.750813534,573.2599238
,108.6,142.4577867,5.038124817,348524.5772,1.743398425,576.0432808
,108.8,143.675986,5.088616892,350656.2173,1.740781241,578.4102372
,109,144.9515087,5.139612083,353082.8103,1.736855522,580.7760972
,109.2,145.9861028,5.191133467,356359.6881,1.730748944,583.6427381
,109.4,147.5106286,5.243140296,358022.1618,1.731184967,586.5017152
,109.6,148.53341,5.295702726,358767.7199,1.733801923,588.6911478
,109.8,149.3339788,5.348807659,360754.9703,1.73162096,591.172062
,110,150.7467722,5.402405965,363426.0298,1.728131405,594.3707367
,110.2,151.8408461,5.456563651,365833.3876,1.72376953,596.849464
,110.4,153.1236843,5.511253105,369314.4441,1.717226754,600.0623836
,110.6,154.2234078,5.566504074,372432.1282,1.711120174,602.7723255
,110.8,155.4461704,5.622302034,374271.1319,1.710683876,605.521719
,111,156.5432206,5.678668904,376439.0697,1.710683766,608.8190126
,111.2,157.5802808,5.735606003,377009.4795,1.715481603,611.2067871
,111.4,158.5814766,5.79311758,376658.9935,1.725077382,613.8334479
,111.6,160.2481339,5.851163135,375824.0038,1.735109269,615.8015408
,111.8,161.3797598,5.909827144,376048.6193,1.741215622,617.9712541
,112,162.4405769,5.969085143,375664.1857,1.751247568,620.4839512
,112.2,163.6651919,6.028927609,377548.8726,1.751247443,623.1818437
,112.4,165.2249836,6.08934928,380860.4379,1.744268465,625.7427649
,112.6,166.5766933,6.150391767,386057.0933,1.731183044,629.1638914
,112.8,168.1321311,6.212034262,391221.5519,1.717661428,632.3275059
,113,169.4894682,6.27430912,396415.5231,1.704139835,635.6993201
,113.2,170.7784866,6.337214105,400697.0896,1.695416186,639.5489062
,113.4,172.0274712,6.400753687,402325.6013,1.695416062,642.3103565
,113.6,173.1149577,6.464942291,403974.2421,1.697160659,645.7018915
,113.8,174.7747171,6.529738186,404081.9794,1.703703133,648.4074634
,114,176.1323783,6.59520494,405304.7366,1.707192405,651.2401438
,114.2,177.4849431,6.6613297,407450.7098,1.708500798,654.5944261
,114.4,178.8923104,6.728115228,410106.7137,1.705883603,657.4972399
,114.6,179.9659625,6.795593825,410700.1356,1.711989957,660.6663272
,114.8,181.2965766,6.863733415,411517.7353,1.715915406,663.3938112
,115,182.6387289,6.932556854,411453.1826,1.722894083,666.0949942
,115.2,183.9591407,7.002073161,410234.4303,1.734670693,668.7885081
,115.4,185.2952483,7.072286717,409535.1981,1.743394071,670.916588
,115.6,187.1645176,7.143170767,410985.2359,1.74644711,673.9081701
,115.8,188.2192037,7.214820639,411309.3242,1.752117285,676.202806
,116,189.6864177,7.28716322,411244.6106,1.759095943,678.4919714
,116.2,191.0428681,7.360239992,411921.8926,1.763893734,681.2775332
,116.4,192.3700837,7.434052761,412102.4204,1.768691528,683.4121877
,116.6,194.0407726,7.508584699,412351.8695,1.77392546,685.9818837
,116.8,195.2803973,7.58389369,414513.357,1.770872104,688.4463735
,117,197.1763024,7.65991632,419141.9923,1.760403699,691.9354551
,117.2,198.9664295,7.736709719,423563.5606,1.749935308,694.8032128
,117.4,200.0517184,7.814712548,428675.3775,1.739030815,698.5169186
,117.6,201.7825924,7.892674495,433704.3872,1.727253908,701.6564348
,117.8,203.2795038,7.971829491,440213.3069,1.71155145,705.2627616
,118,204.95266,8.051767985,446086.42,1.700646904,709.730394
,118.2,206.6523104,8.132508017,450123.5686,1.694104108,713.1493422
,118.4,208.3393526,8.214060231,455857.4557,1.68450809,717.5150663
,118.6,209.9472301,8.296436871,457137.7113,1.687561157,720.5559604
,118.8,211.3711173,8.379653294,455819.8893,1.699337741,723.3185153
,119,212.898032,8.463699081,455382.7609,1.710241962,726.8492331
,119.2,214.6760579,8.548572849,454538.3598,1.721582332,729.9712205
,119.4,215.9198431,8.634334518,453390.2924,1.731614229,732.3513366
,119.6,217.6385286,8.720926642,454399.8049,1.735975803,735.6201612
,119.8,219.1715531,8.808400923,455652.3146,1.737720346,738.3432725
,120,221.2884589,8.896715769,456392.3632,1.742518053,741.7589427
,120.2,222.840337,8.985955158,457299.1953,1.744698768,744.3790485
,120.4,224.3063827,9.076096881,457889.1001,1.749060365,747.4802105
,120.6,225.8937473,9.167136183,458510.6659,1.752113424,749.9808746
,120.8,227.6864553,9.259076696,459920.9848,1.753421764,752.7741225
,121,229.7668671,9.351920896,462158.8847,1.753421551,756.2040403
,121.2,231.2448071,9.445736831,465949.4787,1.74862348,759.8147541
,121.4,233.0969695,9.540470093,470249.9434,1.74077215,762.8666152
,121.6,234.6802644,9.636172096,473302.3146,1.739027291,766.5792407
,121.8,236.7226363,9.732805034,475019.394,1.739899432,769.4371488
,122,238.2781699,9.830440494,476612.7737,1.741643969,772.5405072
,122.2,240.3651559,9.929021627,475120.5809,1.753420462,775.4959416
,122.4,242.105898,10.02861589,471947.5866,1.769558729,777.8804569
,122.6,243.9151152,10.12921,471654.1064,1.775228807,780.1773073
,122.8,245.808613,10.23081069,472279.8594,1.778281826,782.7075671
,123,247.9140924,10.33341817,473767.3685,1.779590131,785.8262801
,123.2,250.0185757,10.4370567,478267.0807,1.770430256,788.8595204
,123.4,251.6715672,10.54176615,485842.3412,1.754291646,793.0049954
,123.6,253.5348715,10.64751389,490038.5492,1.747748848,796.1302789
,123.8,255.5806168,10.75431212,493783.5363,1.742950724,799.4725366
,124,257.4681913,10.80157831,496147.537,1.743386709,803.4098143
,124.2,258.5692146,10.80150681,495529.5884,1.750801551,805.9433454
,124.4,260.010084,10.80141305,493470.1,1.763450443,808.7968601
,124.6,260.7009621,10.80136842,493996.0422,1.767594024,811.6169359
,124.8,261.2820246,10.80133098,495820.2246,1.7686844,814.7076739
,125,262.0194912,10.80128329,499704.7695,1.763886413,817.8997776
,125.2,262.647974,10.80124275,505345.7432,1.755162873,821.8545611
,125.4,263.3592345,10.80119678,509995.7011,1.747747852,825.1299459
,125.6,263.7888844,10.80116926,513377.7573,1.74556694,828.8754264
,125.8,264.1786013,10.80114435,515504.0964,1.745566901,831.9228755
,126,264.6415286,10.80111465,516916.2743,1.749056244,835.7089008
,126.2,264.9097827,10.8010977,516233.7418,1.756034996,838.2183064
,126.4,265.1260408,10.80108416,513926.0778,1.769556356,841.1561723
,126.6,265.7008636,10.80104713,511458.4139,1.781769159,843.2634214
,126.8,265.6538137,10.80105084,509851.806,1.791364984,845.5218799
,127,266.1283881,10.80102037,509099.1687,1.799652233,848.4652313
,127.2,266.1245989,10.80102125,512526.2773,1.794418152,851.2617315
,127.4,266.7913506,10.80097819,517723.1536,1.784822264,854.8822943
,127.6,266.8616038,10.80097421,523839.7608,1.772173224,858.2267028
,127.8,267.4102205,10.8009389,530012.9599,1.76126883,861.9524615
,128,267.660172,10.80092315,535784.3002,1.753417681,866.3006319
,128.2,267.7869968,10.80091547,535768.3206,1.759524099,868.9755016
,128.4,268.2066634,10.8008886,534188.9294,1.771300742,871.9747351
,128.6,268.4532871,10.80087307,528881.3296,1.792673221,874.1433464
,128.8,268.4644727,10.80087296,525135.4116,1.807066947,875.4144825
,129,268.8699963,10.80084702,519628.265,1.828439408,877.3858516
,129.2,268.8171229,10.80085111,516477.5742,1.841088447,878.7654701
,129.4,269.2367894,10.80082424,513530.8764,1.853737434,880.5439761
,129.6,269.5017157,10.80080751,513448.6784,1.857662968,882.4780833
,129.8,269.6135657,10.80080081,513076.087,1.862460866,884.1196068
,130,269.7420544,10.80079301,511226.0627,1.871620496,885.3008901
,130.2,270.1900067,10.80076429,510348.6906,1.878599224,886.9511861
,130.4,269.9915444,10.80077792,509987.1675,1.882960982,888.2135511
,130.6,270.4253538,10.80075012,509047.5676,1.889503538,889.6720828
,130.8,270.5771367,10.8007408,507688.5001,1.896046124,890.7777558
,131,270.4718512,10.80074833,508623.5142,1.896046137,892.5014603
,131.2,270.7401053,10.80073138,508943.3436,1.897354629,893.7287716
,131.4,270.7571145,10.80073089,510582.3961,1.89517376,895.4480931
,131.6,270.8215441,10.80072729,512994.9348,1.890375846,897.1005746
,131.8,270.9392176,10.80072021,516720.3617,1.882524712,899.0478261
,132,271.0885047,10.80071105,519561.5348,1.878162962,901.2777976
,132.2,271.4091707,10.80069067,522334.5146,1.873801193,903.5011987
,132.4,271.5077097,10.80068484,523831.5187,1.872056489,905.1657343
,132.6,271.7235518,10.80067132,523711.2746,1.875982028,906.9990251
,132.8,271.5334088,10.8006844,523592.6774,1.879035264,908.5572597
,133,272.0678825,10.80065001,523302.3959,1.882524594,909.9752478
,133.2,271.9076892,10.80066113,523530.0042,1.88470548,911.6715548
,133.4,271.8739503,10.80066396,524194.5912,1.885577831,913.1300733
,133.6,272.0848007,10.80065078,526311.8847,1.882960768,915.1222552
,133.8,272.3039705,10.80063704,527813.1876,1.881652225,916.8207632
,134.6,272.0588965,10.70835294,1.7977E+308,1.824513536,0
,134.8,272.1730179,10.59985,1.7977E+308,1.681884811,0
,135,271.8228329,10.49191725,1.7977E+308,1.49302174,0
,135.2,271.4826311,10.38398384,1.7977E+308,1.209072846,0
,135.4,271.6232886,10.27601894,1.7977E+308,0.899825853,0
,135.6,271.3013036,10.16862412,1.7977E+308,0.570078727,0
,135.8,271.0384719,10.06068565,1.7977E+308,0.35111965,0
,136,270.9694814,9.952734482,1.7977E+308,0.209363271,0
,136.2,270.4520771,9.844812685,1.7977E+308,0.123000926,0
,136.4,270.5819195,9.736848491,1.7977E+308,0.049287605,0
,136.6,270.0636832,9.628926749,1.7977E+308,0.031840666,0
,136.8,270.1727271,9.520963916,1.7977E+308,0.035330054,0
,137,269.8924248,9.413026589,1.7977E+308,0.025298064,0
,137.2,269.6978118,9.305083648,1.7977E+308,0.013957553,0
,137.4,269.3592739,9.197150134,1.7977E+308,0.005670256,0
,137.6,269.2387033,9.089202343,1.7977E+308,0.008287297,0
,137.8,268.9875187,8.981263108,1.7977E+308,0.021808677,0
,138,269.0175286,8.873305453,1.7977E+308,0.022681024,0
,138.2,268.6590242,8.765373247,1.7977E+308,0.022681024,0
,138.4,268.348772,8.657437881,1.7977E+308,0.018755463,0
,138.6,268.2506637,8.549488619,1.7977E+308,0.012649033,0
,138.8,268.1825052,8.441537394,1.7977E+308,0.022244852,0
,139,267.6875631,8.333614126,1.7977E+308,0.037510927,0
,139.2,267.6102532,8.225663501,1.7977E+308,0.050159961,0
,139.4,267.1893535,8.117735383,1.7977E+308,0.059755782,0
,139.6,267.1977331,8.009779145,1.7977E+308,0.055394046,0
,139.8,267.1204232,7.90182852,1.7977E+308,0.049287616,0
,140,266.6042667,7.793906642,1.7977E+308,0.03751093,0
,140.2,266.6076546,7.685950731,1.7977E+308,0.025298069,0
,140.4,266.4034744,7.578008416,1.7977E+308,0.011776688,0
,140.6,265.8706791,7.470087628,1.7977E+308,0.00959582,0
,140.8,265.8699074,7.362131989,1.7977E+308,0.018755466,0
,141,265.575046,7.254195615,1.7977E+308,0.028351286,0
,141.2,265.2023986,7.146264336,1.7977E+308,0.039691802,0
,141.4,265.0988827,7.038315428,1.7977E+308,0.042526931,0
,141.6,264.5652554,6.930394694,1.7977E+308,0.034893893,0
,141.8,264.666396,6.82243238,1.7977E+308,0.024425725,0
,142,264.5524808,6.714484152,1.7977E+308,0.023117204,0
,142.2,264.1353247,6.606555789,1.7977E+308,0.029877897,0
,142.4,263.8404633,6.498619415,1.7977E+308,0.041000326,0
,142.6,263.7465147,6.39066988,1.7977E+308,0.047542932,0
,142.8,263.5681244,6.282725876,1.7977E+308,0.046670585,0
,143,263.1389052,6.174798303,1.7977E+308,0.044925892,0
,143.2,262.9064391,6.066857842,1.7977E+308,0.041000329,0
,143.4,262.7692297,5.95891114,1.7977E+308,0.033585376,0
,143.6,262.3491617,5.850982968,1.7977E+308,0.024425729,0
,143.8,262.5430633,5.743014577,1.7977E+308,0.01526608,0
,144,261.9462087,5.635097985,1.7977E+308,0.004361737,0
,144.2,262.0402778,5.527136134,1.7977E+308,0.015266081,0
,144.4,261.5095622,5.419215209,1.7977E+308,0.022244861,0
,144.6,261.4114539,5.311265947,1.7977E+308,0.026606599,0
,144.8,261.1719162,5.203325948,1.7977E+308,0.032276858,0
,145,260.6686545,5.095403226,1.7977E+308,0.036638597,0
,145.2,260.5181341,4.987457396,1.7977E+308,0.032713033,0
,145.4,260.3825886,4.879510586,1.7977E+308,0.031840686,0
,145.6,260.1338996,4.771571187,1.7977E+308,0.030968339,0
,145.8,259.9151604,4.663629826,1.7977E+308,0.026170428,0
,146,259.7263709,4.555686504,1.7977E+308,0.0183193,0
,146.2,259.449396,4.447748958,1.7977E+308,0.011340519,0
,146.4,259.1849002,4.339810595,1.7977E+308,0.006106433,0
,146.6,259.0610018,4.231863021,1.7977E+308,0.007414955,0
,146.8,258.836439,4.123922042,1.7977E+308,0.008287303,0
,147,258.4005641,4.015994905,1.7977E+308,0.014829911,0
,147.2,257.7733437,3.908080303,1.7977E+308,0.020063997,0
,147.4,257.7609249,3.800125427,1.7977E+308,0.016138433,0
,147.6,257.7626489,3.692169624,1.7977E+308,0.009159651,0
,147.8,257.5430777,3.584228318,1.7977E+308,0.003489391,0
,148,257.1587829,3.476297803,1.7977E+308,0.012649042,0
,148.2,257.0523552,3.368349085,1.7977E+308,0.020063998,0
,148.4,256.5391101,3.260427016,1.7977E+308,0.020063999,0
,148.6,256.2504881,3.152490233,1.7977E+308,0.017446956,0
,148.8,255.949387,3.044554268,1.7977E+308,0.018755478,0
,149,255.7414629,2.936612199,1.7977E+308,0.016138435,0
,149.2,255.6708084,2.828661137,1.7977E+308,0.016574609,0
,149.4,255.30648,2.720729314,1.7977E+308,0.018319305,0
,149.6,254.9097061,2.612799615,1.7977E+308,0.018755479,0
,149.8,254.7525302,2.504854222,1.7977E+308,0.011340522,0
,150,254.2916971,2.39692872,1.7977E+308,0.013085219,0
,150.2,254.1070672,2.288985125,1.7977E+308,0.01875548,0
,150.4,253.6978142,2.181056244,1.7977E+308,0.019191655,0
,150.6,253.3617717,2.073122567,1.7977E+308,0.015266089,0
,150.8,253.2062596,1.965177065,1.7977E+308,0.01090435,0
,151,252.9833605,1.857235977,1.7977E+308,0.007414958,0
,151.2,252.6140405,1.74930448,1.7977E+308,0.006978784,0
,151.4,252.4360661,1.641360449,1.7977E+308,0.01090435,0
,151.6,251.8712407,1.533441759,1.7977E+308,0.012212873,0
,151.8,251.5618201,1.425506339,1.7977E+308,0.016138439,0
,152,251.2657106,1.317570046,1.7977E+308,0.013521395,0
,152.2,250.9230125,1.209636806,1.7977E+308,0.013521395,0
,152.4,250.4605154,1.101711413,1.7977E+308,0.013521396,0
,227.6,250.0190285,1.000495922,1.7977E+308,0.012649051,0
,227.8,249.6255821,0.892566006,1.7977E+308,0.013085225,0
,228,249.3906199,0.784625708,1.7977E+308,0.015266096,0
,228.2,249.0337788,0.676693394,1.7977E+308,0.016574619,0
,228.4,248.6361727,0.56876375,1.7977E+308,0.018755491,0
,228.6,248.2527095,0.460833179,1.7977E+308,0.018537404,0
,228.8,247.6225767,0.352918768,1.7977E+308,0.020064014,0
,229,246.964574,0.245006181,1.7977E+308,0.02050019,0
,229.2,246.4654714,0.137083186,1.7977E+308,0.023117236,0
,229.4,245.7721113,0.029172916,1.7977E+308,0.024861934,0
,229.446,245.5012128,0.004360853,1.7977E+308,0.024861934,0
END,,,,,,