File: GB1_test 20.csv
Segment,Time On Sample,Displacement Into Surface,Load On Sample,Harmonic Contact Stiffness,Harmonic Displacement,Harmonic Load
Surface Marker,0,0,0,-119.9631023,0.572343279,2.160776328
,0.2,-0.064151986,0.000661284,1913.695782,0.364694347,2.242955948
,0.4,-0.133296322,0.001322896,6678.919634,0.254762559,2.314178287
,0.6,0.324252131,0.001949972,11174.09091,0.211575065,2.378826292
,0.8,0.329993027,0.002606673,13820.05233,0.183655882,2.444569993
,0.988,0.284384307,0.003227317,16497.54745,0.162280257,2.56400438
,1.2,0.395558715,0.003915782,18798.22788,0.15050185,2.716310631
,1.4,0.615138657,0.004557739,20590.8438,0.144394527,2.868616889
,1.6,0.654161992,0.005211535,22126.69568,0.140904629,3.019827411
,1.8,0.667391526,0.005867022,23200.70322,0.140468392,3.169942198
,2,0.782132147,0.006515853,24861.52309,0.143522052,3.488799166
,2.2,0.680537664,0.00717887,26589.35101,0.147448188,3.861346802
,2.4,0.639683421,0.007837903,27618.94339,0.153991747,4.221841431
,2.6,1.211223929,0.008456782,28642.68332,0.157917877,4.518783898
,2.8,0.889134057,0.009134255,30105.01706,0.162716489,4.896810147
,3,0.78088311,0.009797708,32577.12512,0.165333914,5.357016051
,3.2,0.916425183,0.010445175,35810.10146,0.170132522,5.998017173
,3.4,0.952952343,0.011099135,38454.81159,0.176239844,6.605050704
,3.6,0.838044932,0.011763024,39275.06383,0.188454487,7.201126918
,3.8,0.862923279,0.012417747,38923.89065,0.20546774,7.785150151
,4,0.956862447,0.013067942,38534.42617,0.229460787,8.605850725
,4.2,0.997549897,0.013721629,38324.84398,0.253453834,9.451753057
,4.4,1.118946982,0.014370023,37327.64421,0.283117965,10.27354938
,4.6,1.033993662,0.015031948,36437.51312,0.312345861,11.05918657
,4.8,1.107963436,0.015683452,36376.7765,0.331104061,11.70347491
,5,1.040483335,0.016344231,36624.83062,0.361640669,12.87152134
,5.2,0.987148222,0.017004083,36933.16224,0.385633718,13.84343238
,5.4,1.029499789,0.01765766,37206.37043,0.409190528,14.80109901
,5.6,0.825146133,0.018327414,37058.02039,0.432747344,15.59550199
,5.8,1.029332998,0.01897038,36202.13133,0.46895503,16.5148182
,6,0.788784814,0.019642507,35477.56879,0.504290253,17.41441108
,6.2,0.729625293,0.020302741,34465.30658,0.548350217,18.40604521
,6.4,0.751174887,0.020960962,33599.707,0.591537704,19.36590329
,6.6,0.690351771,0.021618027,32739.16606,0.636470143,20.31261255
,6.8,0.396551862,0.022293646,31409.10614,0.692744759,21.21439682
,7,0.463032594,0.022948921,30066.60298,0.749891837,21.9726409
,7.2,0.534506196,0.02360059,28558.7039,0.817944846,22.76046964
,7.4,0.001074063,0.024288645,26783.28609,0.899521239,23.47159697
,7.6,0.202348735,0.024931803,25197.01084,0.974990275,23.94276029
,7.8,0.583347957,0.025563176,23384.35521,1.073579874,24.48076319
,8,0.401043834,0.026231485,22088.99499,1.156464964,24.93768174
,8.2,0.519944748,0.026880045,20856.81122,1.244584882,25.3770689
,8.4,0.329320043,0.0275489,20075.87056,1.307403061,25.69483002
,8.6,0.611304349,0.028186765,19769.38676,1.350590529,26.15503608
,8.8,0.492236642,0.028850928,19739.98734,1.371093689,26.54073245
,9,0.79419034,0.029487484,19720.38178,1.392905529,26.9603966
,9.2,0.980487959,0.030131623,20087.33569,1.394650465,27.47538909
,9.4,0.447887374,0.030822902,20599.87855,1.384180813,27.925733
,9.6,0.53517008,0.031473534,21132.58526,1.377201011,28.4571613
,9.8,0.718971527,0.032117838,21626.96701,1.369784964,28.90860153
,10,0.610720576,0.032781291,22494.47437,1.348845585,29.54521959
,10.2,0.865246962,0.033420957,22838.25368,1.347536855,29.95940515
,10.4,0.687103131,0.034088993,23174.49938,1.350154292,30.47001446
,10.6,0.678699154,0.034745899,23341.44908,1.35713409,30.86885956
,10.8,0.656982247,0.035403679,23377.3459,1.372838633,31.33125688
,11,0.728455848,0.036055347,23241.52333,1.395086728,31.72133621
,11.2,0.721715987,0.036712144,23176.58271,1.414281169,32.13771303
,11.4,0.815655158,0.03736234,22991.42762,1.436529262,32.444517
,11.6,1.129257666,0.037998131,22690.60365,1.467502082,32.79953327
,11.8,0.854595097,0.038672496,22500.65033,1.49018644,33.08003951
,12,0.822893493,0.03933093,22392.76174,1.508944647,33.38355626
,12.2,0.916000605,0.03998118,22308.57816,1.528139079,33.72323204
,12.4,0.991634497,0.040632575,22470.57696,1.529884023,34.01688735
,12.6,1.057283691,0.041284625,22944.59882,1.518105609,34.4277855
,12.8,1.305985665,0.041924672,23445.08551,1.505890951,34.84964116
,13,1.246826145,0.042584906,23997.92753,1.491058889,35.24191185
,13.2,1.302490642,0.043237611,24616.51939,1.473173159,35.61774673
,13.4,1.377292474,0.04388906,25216.70911,1.461830982,36.08014418
,13.6,1.581895367,0.044531998,25607.9708,1.455723648,36.42749027
,13.8,1.349667766,0.04520358,26248.68823,1.441327835,36.89317459
,14,1.693224358,0.045837407,26782.99605,1.430421879,37.31174318
,14.2,1.562507845,0.046502332,27482.21528,1.413844877,37.82016097
,14.4,1.752133691,0.047146252,28550.91415,1.380690835,38.38336559
,14.6,1.434204109,0.047823453,29403.26361,1.356697813,38.84028397
,14.8,1.48321214,0.048476593,30404.1189,1.331396048,39.41334996
,15,1.716937065,0.049117622,31293.84141,1.311329119,39.96231015
,15.2,1.576235855,0.049783202,31793.93381,1.309584181,40.55729048
,15.4,1.871533076,0.050420193,31683.63589,1.327033649,40.94846581
,15.6,1.66426722,0.051090138,31283.74324,1.358878983,41.39333133
,15.8,1.76153462,0.051740114,30738.99728,1.396395379,41.7932723
,16,1.720680379,0.052399147,30225.72653,1.432166836,42.13733098
,16.2,1.763031945,0.053052724,30044.97827,1.452233746,42.45399651
,16.4,1.955153965,0.05369648,30049.0362,1.467502034,42.880235
,16.6,1.815284813,0.054362005,30438.61077,1.464448386,43.33605782
,16.8,1.888422528,0.055013563,30777.14111,1.460958483,43.70970135
,17,1.838415649,0.055673196,31311.35617,1.453978692,44.25975695
,17.2,2.022217087,0.056317497,31573.97467,1.453978678,44.6410706
,17.4,1.998004008,0.056975439,31911.47815,1.453106206,45.12757395
,17.6,2.106920219,0.057624651,31929.94771,1.464884603,45.56915268
,17.8,1.946249617,0.05829154,32036.77806,1.469683227,45.91540266
,18,2.008570577,0.058943807,32214.58712,1.474045595,46.34383248
,18.2,1.872029658,0.059609114,32388.71502,1.479280453,46.80622968
,18.4,2.293799702,0.060237812,32443.05265,1.49018635,47.24233011
,18.6,1.898488726,0.060920086,32502.03152,1.498038654,47.57214387
,18.8,1.92003884,0.061575026,32336.3526,1.51897804,47.96660608
,19,2.084702943,0.062220583,32118.98788,1.539481177,48.28655897
,19.2,2.168657413,0.062871431,32068.89029,1.554313236,48.65472384
,19.4,2.320840642,0.063517806,32229.79418,1.559984308,49.06343074
,19.6,2.221742338,0.064180657,32456.40156,1.559984317,49.40091489
,19.8,2.258269498,0.064834615,33026.42782,1.547769673,49.86221658
,20,2.066812748,0.065503523,33571.62326,1.535991285,50.2895504
,20.2,2.248118011,0.066147988,33969.25203,1.532065135,50.75523521
,20.4,2.277156648,0.066802437,34151.62405,1.53424632,51.10477254
,20.6,2.328660853,0.067455414,34228.34,1.543407298,51.53210665
,20.8,2.116402651,0.068125685,34063.49447,1.56172928,51.90355845
,21,2.340142479,0.068769858,33890.42893,1.579178751,52.22789424
,21.2,2.440736674,0.069428642,33851.78342,1.591393385,52.5894847
,21.4,2.708573504,0.070082958,33854.22511,1.600118107,52.87766175
,21.6,2.520441442,0.070773967,33902.71258,1.609279106,53.24801765
,21.8,2.599398937,0.071454235,34099.98237,1.6092791,53.5559174
,22,2.501126968,0.072153041,34537.46143,1.603608025,54.02927188
,22.2,2.58840284,0.072846631,34908.66464,1.597500697,54.37223483
,22.4,2.832104529,0.073536853,35545.0957,1.582668612,54.83244125
,22.6,2.561593207,0.074267952,36453.33024,1.558239352,55.35839049
,22.8,2.482454085,0.074993737,37323.34197,1.534682549,55.81859634
,23,2.404145584,0.075728505,38234.38957,1.511998221,56.34783303
,23.2,2.605407997,0.076448674,39147.6824,1.491058819,56.9373351
,23.4,2.765898112,0.077180646,39852.00906,1.478407927,57.52574154
,23.6,2.97464643,0.07791677,40034.36143,1.48320652,58.04292569
,23.8,2.698303694,0.078692345,39844.0405,1.498474846,58.40999438
,24,2.870438441,0.079449858,39585.02154,1.51766927,58.81870135
,24.2,2.856192181,0.080219617,39222.47396,1.542534793,59.23946104
,24.4,2.834455556,0.081001462,38687.64933,1.574380113,59.602147
,24.6,2.8127177,0.081791045,38520.64441,1.590520893,59.91223816
,24.8,3.008145079,0.082578436,38550.34292,1.600990569,60.31656216
,25,2.857436319,0.083388481,38687.21769,1.60622543,60.69677961
,25.2,2.990457449,0.084191888,39084.9906,1.602299284,61.16136864
,25.4,3.155927541,0.085001351,39682.26454,1.588775917,61.58979874
,25.6,3.381304489,0.085815189,40367.14981,1.57438007,62.11136584
,25.8,2.84950732,0.086686906,41036.6115,1.561729238,62.65265477
,26,3.059904557,0.087518523,41639.86881,1.551259528,63.16216881
,26.2,3.029003644,0.088374258,42202.0241,1.54209855,63.63114054
,26.4,3.303466672,0.08921851,42671.1355,1.53860863,64.17023945
,26.6,3.495554583,0.090076776,43081.83377,1.53773614,64.72906119
,26.8,3.117681351,0.090981189,43330.56141,1.539481122,65.16077753
,27,3.327239678,0.091855958,43527.85924,1.546024663,65.73274804
,27.2,3.532636307,0.092739839,43402.75656,1.559111762,66.10639185
,27.4,3.504223215,0.093647967,43435.9446,1.569145221,66.59289524
,27.6,3.522403913,0.09456221,43607.53698,1.574380067,67.09035586
,27.8,3.528102291,0.0954864,43732.41848,1.579178676,67.48810535
,28,3.586218837,0.096416506,43993.1222,1.580923621,67.95159856
,28.2,3.301525996,0.097378407,44429.90814,1.578306223,68.49288791
,28.4,3.423708012,0.09832318,44634.97109,1.582668586,68.97719995
,28.6,3.705643661,0.099266953,44710.60169,1.589648357,69.37056713
,28.8,3.642273704,0.100242973,44866.28612,1.595319447,69.84611305
,29,3.463246134,0.101236312,44943.53407,1.602299259,70.26906384
,29.2,3.66529956,0.102214594,45077.99877,1.608406563,70.75337624
,29.4,3.928923735,0.103198535,45199.58959,1.614513861,71.23111435
,29.6,3.969554739,0.104207312,45357.12173,1.618439999,71.70008604
,29.8,3.442720563,0.10526345,45485.56357,1.621493703,72.07591993
,30,3.546584715,0.106288605,45838.8088,1.618440033,72.54489194
,30.2,3.84265264,0.107311405,46237.27569,1.614950109,73.07412918
,30.4,4.101276301,0.108347038,46786.43058,1.60709782,73.62856828
,30.6,3.749167723,0.109433169,47226.54796,1.601426767,74.074529
,30.8,3.670804497,0.110512241,47748.81405,1.596191927,74.64869052
,31,3.815431112,0.111587439,47940.80014,1.600118056,75.13738568
,31.2,4.0116436,0.112670089,48000.93508,1.608842781,75.62827241
,31.4,3.998175722,0.113777481,47985.10575,1.617567525,75.99534139
,31.6,4.022980761,0.114893381,47786.53805,1.634144536,76.43034561
,31.8,4.077738102,0.116018553,47602.68867,1.649412834,76.83795668
,32,4.183249176,0.117151755,47562.31697,1.65944628,77.22694049
,32.2,4.606604598,0.118275456,47587.5669,1.667734747,77.6509883
,32.4,6.020939297,0.119344989,47799.24897,1.668170856,78.01915614
,32.6,5.731217514,0.120537664,48461.86696,1.656392484,78.55496671
,32.8,6.097155516,0.121699036,49532.22209,1.632835643,79.16309681
,33,6.216802492,0.122888383,50816.3326,1.604480218,79.80081104
,33.2,6.060204329,0.124107868,52677.82569,1.563473941,80.59740529
,33.4,6.176519235,0.125321581,54848.81772,1.518541506,81.49371155
,33.6,6.13890147,0.126557701,56418.58067,1.489313621,82.21250923
,33.8,6.37003646,0.127788462,58245.12223,1.458340765,83.11648576
,34,6.319101827,0.129050257,59802.3855,1.434783965,83.98539833
,34.2,7.012024977,0.130275678,61063.05089,1.420388085,84.93430092
,34.4,6.940284918,0.131563874,61984.93825,1.412972061,85.84156399
,34.6,7.151442496,0.132846363,62723.90711,1.407737199,86.59980851
,34.8,7.184537641,0.134153405,63588.70464,1.402938589,87.53117781
,35,6.996303296,0.135488152,64393.97937,1.398576233,88.39022851
,35.2,7.333927411,0.136801718,65339.76276,1.3937776,89.4004911
,35.4,7.072467749,0.138167846,66035.5144,1.391596435,90.19379787
,35.6,7.051470635,0.139531891,66726.46035,1.392468911,91.15584736
,35.8,7.198547046,0.140898541,67435.50629,1.393341375,92.16282219
,36,7.375575351,0.142276993,67936.83123,1.396831259,93.0788518
,36.2,7.26054912,0.143688594,68385.15104,1.402066114,94.04090103
,36.4,7.377664808,0.145098974,68888.98316,1.406428477,95.02376992
,36.6,7.420725066,0.146528552,69466.80379,1.406864712,95.83460893
,36.8,7.264921217,0.147985491,69899.54757,1.412972044,96.82076429
,37,7.659105314,0.149420845,70383.08748,1.417334385,97.74556028
,37.2,7.582342337,0.15090171,70806.32781,1.423877949,98.74924728
,37.4,7.431523852,0.152402266,71153.63362,1.43173023,99.75731706
,37.6,7.453771014,0.153906499,71131.55169,1.442636157,100.484881
,37.8,7.5683742,0.155419755,71176.53637,1.454850788,101.4009103
,38,7.469968155,0.156962203,70999.29772,1.470119096,102.2270894
,38.2,7.75181009,0.158495196,70535.93068,1.491930929,103.0675138
,38.4,7.73577285,0.160063213,69858.29148,1.517232684,103.8137048
,38.6,7.774648927,0.161643363,69453.24931,1.535118403,104.4218343
,38.8,7.615492702,0.163252434,69221.19227,1.551695428,105.1976096
,39,7.857385813,0.164851249,68795.15232,1.570889841,105.8550474
,39.2,7.902910706,0.166479069,68872.2966,1.580487054,106.640685
,39.4,7.741250589,0.168136869,69669.46117,1.575688461,107.5435647
,39.6,7.854998983,0.169793199,70308.73959,1.571326081,108.2360655
,39.8,7.776539369,0.171478767,70806.3312,1.5726348,109.0710103
,40,8.18566297,0.17314924,72151.72307,1.557366466,110.0078595
,40.2,7.822634203,0.17488726,73283.1807,1.547769282,111.0082586
,40.4,8.052027885,0.176603652,73646.97543,1.550822923,111.7730778
,40.6,8.122495754,0.178347845,73882.69704,1.558238949,112.6628094
,40.8,8.094778008,0.180116037,74366.13948,1.558238952,113.4309152
,41,8.257598694,0.181889423,74313.92111,1.569581103,114.2034043
,41.2,8.136684794,0.183699433,74463.18842,1.578305857,115.0712208
,41.4,8.154721686,0.185518364,74856.76087,1.580050805,115.8119335
,41.6,9.578933443,0.187262872,75164.20849,1.585721763,116.7071486
,41.8,9.613605785,0.189116601,75291.9385,1.592265317,117.3941703
,42,10.32057637,0.190954091,75455.03202,1.598372574,118.1677569
,42.2,10.38519839,0.192833524,75699.39982,1.604043651,119.0432442
,42.4,10.23098318,0.194765327,76020.90483,1.606224851,119.7346484
,42.6,10.49445942,0.196679441,77230.81688,1.594446428,120.7460068
,42.8,10.57404937,0.19861517,78266.46163,1.58441297,121.5601335
,43,10.37073505,0.200598733,79577.63122,1.571762114,122.5156081
,43.2,10.26809653,0.20259567,80799.2829,1.562601145,123.6146235
,43.4,10.57898754,0.204585387,81546.19726,1.558674986,124.4342295
,43.6,10.66688388,0.206609874,81960.56543,1.563037349,125.4412043
,43.8,10.6957009,0.208658461,82248.08846,1.569144666,126.3747652
,44,10.99992576,0.210709577,82806.95524,1.570017115,127.2973698
,44.2,10.72919543,0.212819167,83686.8048,1.564346058,128.1695689
,44.4,10.84453653,0.214924522,84816.04866,1.557366256,129.281734
,44.6,11.12628582,0.217040051,85614.85025,1.553440099,130.1396902
,44.8,11.14510147,0.219194256,86660.17014,1.547769017,131.2639079
,45,11.06157058,0.221376814,87286.50341,1.547769025,132.2708823
,45.2,11.11366162,0.223572306,87318.55661,1.556057525,133.0893915
,45.4,11.04343668,0.225797849,87254.04705,1.568272169,134.099653
,45.6,10.9532388,0.228047087,87374.88739,1.57525197,134.9126834
,45.8,11.32150114,0.230288759,87395.36156,1.586157865,135.8648729
,46,11.11397592,0.232590926,87147.58442,1.600553706,136.676807
,46.2,11.40568171,0.234883192,86887.66159,1.616258215,137.5468167
,46.4,11.12159986,0.237236462,86578.69083,1.630217826,138.1965827
,46.6,11.56140449,0.239565723,86113.876,1.648539743,138.9646901
,46.8,12.44219598,0.24188934,85843.16895,1.661190537,139.5804929
,47,12.59909356,0.244283839,86131.80514,1.664680419,140.3288762
,47.2,12.76014758,0.246702231,87052.3259,1.658573087,141.2964052
,47.4,12.66159576,0.24916196,88170.39426,1.647230936,142.1291585
,47.6,12.60464288,0.251643712,89939.61628,1.628036516,143.2829605
,47.8,12.95206607,0.254123772,91490.51243,1.611459476,144.257065
,48,12.92339522,0.256653604,92821.73591,1.600117318,145.2980068
,48.2,12.79154519,0.259215551,93622.74259,1.598808622,146.4233194
,48.4,12.73540833,0.261798189,93847.51153,1.60404347,147.2593601
,48.6,13.35573021,0.264362321,93801.3173,1.61494934,148.2389441
,48.8,13.74307185,0.266967484,93835.7098,1.622365339,149.0136259
,49,13.87912791,0.269615422,94138.82904,1.626291459,149.9154111
,49.2,13.81382178,0.272303308,94911.06784,1.623674044,150.989225
,49.4,13.87831238,0.275009472,95842.24695,1.616694248,151.8756697
,49.6,13.75475362,0.277755279,97295.11094,1.604915858,153.0776835
,49.8,14.22361551,0.280489665,97975.96618,1.602734636,153.9816617
,50,14.10004799,0.283290587,98576.23962,1.603607121,154.9952102
,50.2,14.19281098,0.286105431,99222.94682,1.605352061,156.1172368
,50.4,14.18239434,0.288955216,99329.14805,1.614949273,157.1483174
,50.6,14.19360664,0.291832323,99178.19107,1.6258552,157.9098489
,50.8,14.41116462,0.294724823,99278.73802,1.635452392,158.9014845
,51,14.22350594,0.297672934,99522.55603,1.641123491,159.8120342
,51.2,14.33039093,0.300631337,99838.77885,1.644613378,160.6195867
,51.4,14.3432487,0.303625631,100683.5408,1.642432192,161.7196984
,51.6,14.63816922,0.3066314,101847.2896,1.633707427,162.6883241
,51.8,14.97801604,0.309664425,103375.0595,1.622365237,163.9089672
,52,14.90349333,0.312755235,104117.5623,1.62149277,164.9619621
,52.2,15.0544533,0.315862189,104176.9093,1.628908786,165.82211
,52.4,15.12802694,0.319005519,103710.2246,1.645485784,166.7578624
,52.6,15.21657262,0.322179332,102918.5237,1.664680203,167.419683
,52.8,15.47568501,0.325373953,101706.2686,1.691290633,168.1439611
,53,15.17148931,0.328637786,101251.4834,1.706122719,168.8375559
,53.2,15.57037706,0.331888033,101243.2379,1.71353871,169.5004737
,53.4,15.49249063,0.335202395,101412.3627,1.719209799,170.3080251
,53.6,15.6242774,0.338536245,101723.734,1.720954735,170.9851861
,53.8,15.38828942,0.341927792,102144.3358,1.722699706,171.8595765
,54,15.70811049,0.345316689,102218.3939,1.728370757,172.5882379
,54.2,15.90228542,0.348748086,102419.3177,1.730988161,173.24458
,54.4,17.38614402,0.35212895,103024.7665,1.728806835,174.1080218
,54.6,17.83658177,0.355611842,103679.0876,1.724880661,174.8618855
,54.8,18.01160293,0.359147883,104880.8484,1.71441096,175.866669
,55,18.50030408,0.362698862,106556.6655,1.697397676,176.9339116
,55.2,18.33333834,0.366328391,108107.9234,1.682129402,177.9277367
,55.4,18.57657115,0.369967233,109616.9277,1.669478511,179.0957848
,55.6,18.71412686,0.373649544,110982.9812,1.660317525,180.3109492
,55.8,18.36409103,0.37740099,111548.5892,1.660317558,181.1875302
,56,18.84028225,0.381135636,111780.2838,1.665988594,182.1068491
,56.2,18.81889714,0.384940695,111401.7666,1.681256888,183.0458886
,56.4,18.71929255,0.388789196,111282.3625,1.690417872,183.7723562
,56.6,19.49750236,0.392618623,110966.8317,1.703504906,184.6314115
,56.8,20.07767641,0.396499414,111051.0227,1.709175931,185.3644573
,57,19.50294859,0.40049538,111511.0018,1.71004846,186.2213143
,57.2,20.06563685,0.404456434,112884.2916,1.699142486,187.3301948
,57.4,20.02674129,0.408496979,113719.9235,1.694343886,188.2319792
,57.6,20.37308183,0.412552793,114981.9835,1.685182881,189.3704432
,57.8,20.41821111,0.416669333,115901.4666,1.680384272,190.4228911
,58,20.43795607,0.420828857,116509.6605,1.679075561,191.3559043
,58.2,20.65738814,0.425017024,116533.5155,1.686927804,192.3913695
,58.4,20.76656594,0.429254492,117052.3608,1.686927795,193.284389
,58.6,20.74177574,0.433543319,117748.9321,1.686927798,194.3998408
,58.8,21.13300737,0.437847769,118601.7965,1.683437868,195.337787
,59,21.29541636,0.442210524,119495.9408,1.680820433,196.3907833
,59.2,21.39374998,0.446621234,120526.6434,1.677766767,197.6037558
,59.4,21.46295453,0.451078333,120995.2536,1.679511708,198.4978709
,59.6,21.74931533,0.455588493,121390.6475,1.683874051,199.6100373
,59.8,21.98242447,0.46010203,121414.3273,1.690417582,200.4219736
,60,21.79450179,0.46471152,121476.0624,1.697397389,201.3697784
,60.2,21.88447516,0.469372375,122053.3488,1.698706092,202.4589332
,60.4,22.11090589,0.474024454,122896.747,1.695216177,203.4122185
,60.6,22.36977571,0.478744534,123920.6227,1.691290023,204.5868414
,60.8,22.52379876,0.483518969,124687.5577,1.688672588,205.497393
,61,22.3000602,0.488366211,125861.863,1.682565295,206.6347584
,61.2,22.83348601,0.49321224,126653.2528,1.682129009,207.865265
,61.4,23.21713376,0.498116919,126719.4814,1.688236289,208.7276059
,61.6,23.36446939,0.503086523,126885.2805,1.694779828,209.8003253
,61.8,23.50763682,0.508106254,127438.7287,1.696524765,210.9201608
,62,23.87295548,0.513161908,127694.9607,1.699578386,211.7189498
,62.2,23.58177294,0.518311552,128414.679,1.699142178,212.8530274
,62.4,23.58679455,0.523493373,129343.898,1.696524758,214.080244
,62.6,23.5992964,0.528726734,129853.5733,1.696960994,215.0050394
,62.8,23.7865219,0.534001225,130195.1358,1.701323345,216.1117267
,63,23.8797165,0.539334986,130201.2243,1.708739362,217.0409053
,63.2,24.0486198,0.544717208,129895.3951,1.718772792,217.8046296
,63.4,24.23748388,0.550152226,129714.7238,1.729242457,218.7699681
,63.6,24.58193398,0.555631494,129831.889,1.734041029,219.5446504
,63.8,24.95965761,0.561163653,130144.8828,1.737530887,220.5373828
,64,25.03866389,0.56677101,131010.0945,1.73360475,221.5454544
,64.2,25.45963669,0.572412228,132085.9231,1.726624923,222.5031239
,64.4,25.83982968,0.578112741,133413.2989,1.71833639,223.7402042
,64.6,26.42053933,0.583857289,134072.9229,1.716591392,224.6956832
,64.8,26.66176051,0.589681798,134867.5444,1.715282657,225.8582539
,65,26.9454073,0.595562075,135530.4881,1.715718873,226.9320695
,65.2,26.95696203,0.601519373,136142.8876,1.716155109,227.8820673
,65.4,27.24891049,0.607517987,136676.1037,1.719208738,229.0216274
,65.6,27.36278914,0.61358867,137785.7435,1.715282596,230.2115892
,65.8,27.88353398,0.619693536,138558.2015,1.713537598,231.1977492
,66,28.10472856,0.62587938,139218.0106,1.713537578,232.2814268
,66.2,28.11207458,0.632141601,140033.7614,1.712228869,233.5053556
,66.4,28.44807312,0.638445046,141100.8645,1.706994001,234.5791723
,66.6,28.39965127,0.644837104,141693.826,1.706994003,235.586147
,66.8,28.53260763,0.65128141,142734.5888,1.703940338,236.863768
,67,28.51411934,0.657800423,144002.7582,1.698269267,238.1030375
,67.2,29.05975527,0.664347751,144854.8595,1.696524268,239.1943873
,67.4,29.58374724,0.670962351,145340.6412,1.700014111,240.472011
,67.6,30.08859131,0.677644725,145931.4068,1.700450301,241.5184357
,67.8,30.81308774,0.684379616,146557.4972,1.701758942,242.7861993
,68,31.09741529,0.691211249,147305.0013,1.700886447,244.009035
,68.2,31.1895268,0.69812411,148739.7071,1.693470412,245.455399
,68.4,31.81331159,0.705071519,150257.6835,1.684309391,246.6848106
,68.6,31.46191464,0.712152967,151998.4087,1.675148452,248.2363611
,68.8,32.36025577,0.719223207,153414.0162,1.668168585,249.4975517
,69,32.88083176,0.726389479,154649.9908,1.664678645,250.8770783
,69.2,32.64339258,0.7336775,155204.8271,1.669041034,252.3212482
,69.4,33.02832025,0.740997754,155436.3361,1.674275837,253.4246494
,69.6,33.45567113,0.748388714,155712.739,1.680819346,254.8162292
,69.8,33.7998045,0.755859565,155922.002,1.685617917,255.9163438
,70,33.4283571,0.763452676,156390.1927,1.689107845,257.2016313
,70.2,33.79409989,0.771073392,157248.6992,1.689980284,258.6348479
,70.4,33.6655888,0.778803205,158051.7308,1.689544061,259.7952245
,70.6,34.10036777,0.786573674,158491.4991,1.694778859,261.1813254
,70.8,34.36289857,0.794433605,158490.4553,1.702194856,262.1817275
,71,34.82261426,0.802359474,158419.1747,1.710919543,263.3015665
,71.2,35.21741689,0.810369052,158454.3391,1.718771764,264.5320734
,71.4,35.45245181,0.818469803,158438.883,1.725315289,265.5094658
,71.6,35.70993932,0.826650477,159130.6926,1.726187738,266.8374912
,71.8,35.53141607,0.834942041,160077.5335,1.722697865,267.9419855
,72,35.94447188,0.843277931,161337.6362,1.717026752,269.2645334
,72.2,36.11788204,0.851713371,162706.6297,1.711791899,270.7492481
,72.4,36.43522455,0.860223977,163660.8123,1.709610687,271.9414041
,72.6,36.47547859,0.868838423,164437.861,1.710483157,273.3099701
,72.8,37.05073128,0.877504168,165109.6115,1.712664286,274.6818281
,73,37.16667488,0.886287219,165512.402,1.716590403,275.9046627
,73.2,37.63706055,0.895135226,165761.2637,1.720516487,276.9543749
,73.4,37.80123526,0.904092253,166712.6817,1.719207763,278.3711544
,73.6,38.30487474,0.913116975,168087.7804,1.713100406,279.634534
,73.8,38.54140963,0.922249998,169701.9368,1.706556839,281.2003334
,74,38.63315213,0.931484148,171130.6155,1.701321994,282.6565585
,74.2,38.79061236,0.940806661,173056.2047,1.691288542,284.0656679
,74.4,39.0911714,0.950213552,175139.1294,1.682563787,285.8593791
,74.6,39.19618212,0.95972786,176076.7226,1.681691305,287.1698721
,74.8,39.57908452,0.969319491,177388.6338,1.679510089,288.833193
,75,40.37883191,0.978979884,178453.5593,1.679073779,290.3913267
,75.2,41.02005701,0.988748251,178544.6913,1.685617265,291.6021125
,75.4,41.4403555,0.998629388,178083.3069,1.698268081,292.988214
,75.6,41.58314739,1.008628032,178079.034,1.705247849,294.1387312
,75.8,41.90855977,1.018714694,178243.9694,1.712227601,295.5785225
,76,41.84538568,1.028928315,178782.4986,1.714845026,296.8802485
,76.2,41.984385,1.03923119,179849.952,1.712227595,298.1523919
,76.4,42.53773193,1.04961036,181247.969,1.708737653,299.8124267
,76.6,42.31808191,1.060144685,181830.2215,1.710046384,301.0319717
,76.8,42.88803659,1.070732721,182175.2182,1.71484493,302.5287428
,77,43.34897494,1.081434414,182011.8432,1.72269714,303.7767828
,77.2,43.98296387,1.092232362,181377.5082,1.733602988,304.7969124
,77.4,44.25915137,1.103162203,180958.3746,1.744072632,306.064674
,77.6,44.58690887,1.114198592,181059.1863,1.748871201,307.0848009
,77.8,44.94043357,1.125400316,181186.5497,1.754978475,308.2999677
,78,45.08593514,1.136672663,182066.6758,1.754542225,309.5732072
,78.2,45.51016665,1.147982661,183911.8343,1.746689932,311.1225724
,78.4,46.19314048,1.159446441,184658.7163,1.746253631,312.2632326
,78.6,46.06733735,1.171078753,185999.8399,1.742327518,313.7983488
,78.8,46.18281194,1.18281203,187529.6548,1.735347728,315.0978854
,79,46.47466371,1.194651512,188622.4633,1.732730283,316.5201445
,79.2,46.77232096,1.20660956,189652.2017,1.731421547,318.0738925
,79.4,46.87026563,1.218700922,191204.9086,1.724877995,319.4008216
,79.6,47.28187616,1.230893167,192964.1794,1.718770649,321.1123554
,79.8,47.51790335,1.243219472,193597.9067,1.720079336,322.3625848
,80,48.41040315,1.255626271,194001.6058,1.724441614,323.7706051
,80.2,49.10651785,1.268170767,193244.0218,1.737964869,325.0679555
,80.4,49.36744717,1.280869961,192113.6635,1.753669346,326.2403889
,80.6,50.21745188,1.293657956,190899.2997,1.768501293,327.0523321
,80.8,50.59732448,1.306605424,189859.7604,1.782460813,328.0472585
,81,51.38488384,1.319656076,189961.9992,1.786386861,329.1210811
,81.2,51.52841102,1.332880252,190853.4903,1.783769431,330.2222906
,81.4,52.06048721,1.346211671,192648.7462,1.775480893,331.6960525
,81.6,52.64163338,1.359673866,194800.3052,1.763702463,333.025178
,81.8,52.65696003,1.373308561,198100.3828,1.745816783,334.8791528
,82,52.97263715,1.387060044,201003.1692,1.730984727,336.5764411
,82.2,53.56203868,1.400931678,203361.4157,1.72007877,338.1564893
,82.4,53.60974968,1.414978336,206352.4502,1.706555448,340.1693452
,82.6,54.15833589,1.429133066,208662.8667,1.696521968,341.8107542
,82.8,54.38239773,1.443451212,211047.9407,1.687797234,343.9003131
,83,55.26126461,1.457870108,212461.1003,1.685179734,345.6995092
,83.2,55.20820597,1.4724952,213548.1605,1.684307263,347.3189989
,83.4,55.52788495,1.487242785,213789.8931,1.690414543,349.1762644
,83.6,56.0330888,1.502126294,212877.4819,1.702629103,350.4144425
,83.8,56.06316503,1.51719071,211372.6282,1.720951011,351.8104027
,84,56.69063325,1.532367016,210138.1846,1.736655447,353.0222862
,84.2,57.58183886,1.547678457,209131.0944,1.751487383,354.2900546
,84.4,57.83150504,1.563186045,208973.4372,1.758903373,355.3649682
,84.6,58.64444813,1.578812361,210563.8839,1.75541341,357.0206243
,84.8,58.92401858,1.594630759,212084.6946,1.750614789,358.4132999
,85,59.53971424,1.610585934,213599.7099,1.746688607,359.968147
,85.2,59.73020398,1.626729507,215656.8909,1.739272577,361.7629547
,85.4,59.86575229,1.64303875,216909.3341,1.736218909,363.1841192
,85.6,60.54294272,1.659476165,217203.0702,1.741017442,364.7356786
,85.8,60.98047489,1.676094529,218383.2515,1.739708694,366.4406391
,86,61.67092536,1.692863291,220020.7154,1.73491003,368.1236876
,86.2,62.15915956,1.709813799,221210.8677,1.732728805,369.5733442
,86.4,62.88783069,1.72691885,222835.7144,1.729238849,371.3922636
,86.6,63.06315761,1.744232165,224487.9117,1.725312711,373.247337
,86.8,63.41235647,1.761707957,224983.2624,1.727930093,374.629056
,87,63.65585638,1.779366274,225110.9699,1.733601136,376.0940492
,87.2,64.08820468,1.797189507,225493.2673,1.737963453,377.7420327
,87.4,64.75183588,1.815176609,225689.6625,1.743198219,379.3319446
,87.6,65.57852119,1.833333633,226427.6786,1.744070612,380.7290093
,87.8,66.12394276,1.851691724,227514.6973,1.743634324,382.4328757
,88,66.63854894,1.87023632,228437.9288,1.744070511,384.0271683
,88.2,67.62323671,1.888936229,228843.3455,1.747560302,385.3804058
,88.4,68.08869211,1.907858246,229671.9756,1.749305201,387.0349635
,88.6,67.79944323,1.927019919,229937.823,1.753231351,388.307104
,88.8,68.63177417,1.94630028,231411.1328,1.750613856,390.0756216
,89,68.91658198,1.9658104,233294.3885,1.74450653,391.8156446
,89.2,69.25877042,1.985512848,235969.1178,1.732728134,393.6060707
,89.4,69.81393351,2.005399236,238956.5404,1.720949718,395.813974
,89.6,70.40650731,2.025482841,241834.9353,1.710480007,398.0733767
,89.8,71.0048734,2.045767901,242732.2392,1.710916186,399.6884898
,90,71.50336047,2.066263362,243539.0103,1.713097318,401.5052162
,90.2,72.02012001,2.086963467,243460.7265,1.721821982,403.3263262
,90.4,72.36461109,2.107882842,243294.3457,1.729237955,404.7168124
,90.6,73.16669899,2.128982386,243558.8903,1.735345177,406.4513626
,90.8,74.01285207,2.150290978,244179.7746,1.73796251,407.9382785
,91,74.41465374,2.171843063,244772.3012,1.741452356,409.5785915
,91.2,75.00030513,2.193599482,245730.2503,1.743197242,411.4325742
,91.4,75.29220638,2.21559379,247048.849,1.742324744,413.3533934
,91.6,75.85449033,2.237791332,247567.0989,1.744505868,414.7986684
,91.8,76.53738677,2.260203886,248749.7871,1.743633331,416.6636087
,92,76.82086108,2.282867959,249673.6946,1.743633305,418.4518451
,92.2,77.36473235,2.305742554,251118.2846,1.739707133,420.0998304
,92.4,77.91688759,2.328846543,252288.2168,1.73883461,422.0831089
,92.6,78.61503149,2.352173342,253318.869,1.737962072,423.6708313
,92.8,78.87755732,2.375764026,254443.4359,1.738398283,425.6267134
,93,79.44166532,2.399571837,255761.4533,1.737961994,427.4916536
,93.2,80.14094421,2.423609582,255986.5856,1.742760517,428.954463
,93.4,80.92588644,2.44788238,256518.805,1.747559031,430.7766716
,93.6,81.55020334,2.472409648,257130.7098,1.750176383,432.2427666
,93.8,81.99891751,2.49719503,257532.5142,1.755411165,434.0496327
,94,83.09077025,2.522187007,257644.9952,1.761082119,435.5628502
,94.2,83.1932702,2.547495349,258659.8217,1.762390816,437.3872427
,94.4,83.63354389,2.573035547,259751.7284,1.761518303,438.8982616
,94.6,83.98641106,2.59883812,260443.7864,1.764571916,440.6711585
,94.8,84.91668282,2.624861816,261406.3932,1.764571826,442.1799907
,95,85.9792096,2.651138373,262430.8257,1.764571722,443.8718127
,95.2,86.33111995,2.677725631,264265.0238,1.760209336,445.8397494
,95.4,87.10151115,2.704552571,265483.5495,1.75846432,447.4548664
,95.6,88.05322557,2.731773828,267908.2303,1.750611994,449.6693503
,95.8,88.8393392,2.759144112,270127.0222,1.743195919,451.4773168
,96,89.54888221,2.78665525,273412.7696,1.731417501,453.7213821
,96.2,90.71598895,2.814551828,275509.0682,1.727491273,456.0410596
,96.4,91.11922535,2.842778954,276607.8516,1.729236176,458.1492509
,96.6,92.12648796,2.871249947,277387.3449,1.731853491,459.8739447
,96.8,92.41231417,2.900054423,278040.0836,1.736215815,461.9120087
,97,93.2297769,2.929113414,277857.9149,1.744067969,463.5983489
,97.2,93.6686086,2.958489293,279034.6782,1.743631692,465.2485259
,97.4,94.73809033,2.988118711,281661.39,1.737088063,467.5890213
,97.6,95.35072703,3.018076045,283914.2046,1.732289419,469.8812988
,97.8,95.9050721,3.04833815,284877.3085,1.733161836,471.6804971
,98,96.53841394,3.078899082,285888.2692,1.734470481,473.6769275
,98.2,97.00196796,3.109778279,286246.2185,1.739705257,475.7160892
,98.4,97.66266943,3.14095465,285738.8313,1.747993659,477.2095795
,98.6,98.61620404,3.172424947,285615.1616,1.755409562,479.0504212
,98.8,99.54805491,3.204213031,287503.2783,1.752355827,481.1739605
,99,100.0580037,3.236348205,289058.369,1.749302133,482.8219471
,99.2,101.2218954,3.268763122,291552.073,1.743630967,485.2413373
,99.4,101.6893064,3.301549266,294462.2953,1.735778694,487.7264636
,99.6,102.3821516,3.334649888,296638.2138,1.730107574,489.7404263
,99.8,103.2571637,3.368070727,298038.0222,1.729671256,492.0984525
,100,103.892491,3.401842883,299033.8706,1.7309799,494.2230842
,100.2,104.5477337,3.435952826,300018.1578,1.731416072,496.1592507
,100.4,105.608964,3.470378496,300118.4386,1.737959493,498.3748343
,100.6,106.0943582,3.505188058,299738.1725,1.746247911,499.9921413
,100.8,106.6895279,3.540340083,299084.8437,1.757153724,501.8614661
,101,107.5816845,3.575825594,299251.0355,1.762824684,503.597119
,101.2,108.1176656,3.61169116,299394.4618,1.768059458,505.1223838
,101.4,109.256828,3.647877389,301389.7616,1.765005701,507.3193412
,101.6,109.8900442,3.684460397,303521.1559,1.759770825,509.189764
,101.8,110.8011077,3.721392667,306354.892,1.752354747,511.5708018
,102,111.8527292,3.758686785,308269.4354,1.749737231,513.7776204
,102.2,112.8901462,3.796356543,308243.1468,1.756716893,515.7850158
,102.4,113.7918783,3.834413737,306745.6013,1.769367607,517.074705
,102.6,114.3182936,3.872878081,304407.4899,1.787253175,518.5451846
,102.8,115.229056,3.91170342,303143.9377,1.798595181,519.7461198
,103,116.0282612,3.950926227,302815.7023,1.806011091,521.504781
,103.2,116.9655246,3.99053396,304154.9132,1.803393585,522.996087
,103.4,117.8386565,4.030543915,308030.0618,1.789433998,525.3464433
,103.6,118.8881198,4.070944285,311287.9696,1.7780918,527.3253505
,103.8,119.914221,4.111752053,314513.5067,1.768494534,529.7578926
,104,120.7147706,4.152984703,318416.4457,1.755843657,532.2682253
,104.2,121.3937746,4.194639635,321365.0872,1.747555137,534.4213483
,104.4,122.2316342,4.236702604,323363.0834,1.745373884,536.8484074
,104.6,123.43969,4.279163715,325462.8479,1.741447658,538.9149762
,104.8,124.4180314,4.32206667,328443.0373,1.734904048,541.6236417
,105,125.3505413,4.365403671,328714.696,1.740138771,543.750472
,105.2,126.520117,4.409160362,329038.1593,1.74537347,546.0690588
,105.4,127.5248763,4.453367555,330464.8222,1.74406467,548.086316
,105.6,128.2749569,4.498035784,331795.398,1.744500832,550.4991298
,105.8,129.371932,4.543129839,332528.2813,1.747118132,552.43421
,106,130.2832873,4.588689187,334119.2603,1.747118044,554.6903365
,106.2,131.1271735,4.634710762,335794.1175,1.747117962,557.1447912
,106.4,132.1606942,4.681182178,336650.3819,1.750607736,559.5236407
,106.6,133.1408892,4.728123978,337215.8785,1.75366128,561.380922
,106.8,134.1226734,4.775537334,339877.8905,1.748426375,564.019462
,107,135.4055846,4.823407176,343667.4908,1.737520399,566.7522383
,107.2,136.0901738,4.871797517,346960.5158,1.728795651,569.2713381
,107.4,137.7115763,4.920612236,350776.7113,1.720070815,572.430361
,107.6,138.5549322,4.969968767,353654.7009,1.714399693,574.9768575
,107.8,139.5030477,5.019814264,354045.5783,1.720506879,577.6395015
,108,140.6557683,5.070147017,353053.6808,1.731848852,579.8737189
,108.2,141.5388236,5.121003249,351797.972,1.74319085,581.6367677
,108.4,142.4401029,5.172369196,350124.3735,1.757586482,583.7635986
,108.6,144.0901466,5.224201828,350132.5003,1.762821128,585.4970749
,108.8,145.1834649,5.276591903,352391.0575,1.760203618,588.1180855
,109,146.3124776,5.329506,355420.0132,1.754532469,590.6952682
,109.2,147.170989,5.382969514,359434.3482,1.74362654,593.2045106
,109.4,148.3838689,5.436947014,364571.3239,1.730539409,596.5355569
,109.6,149.6399293,5.491463861,366743.4102,1.72835812,598.8946913
,109.8,150.7419729,5.546538671,368688.6294,1.728358014,601.704169
,110,151.9096606,5.602162489,369712.3725,1.730975305,604.2528637
,110.2,153.1488154,5.658342747,369830.423,1.736646224,606.3292978
,110.4,154.2389431,5.715097811,370550.9392,1.741008455,608.9864689
,110.6,155.4304904,5.772416491,372842.8114,1.737082237,611.3762827
,110.8,156.6061375,5.830309128,375627.9801,1.732719788,614.4060052
,111,157.6044653,5.888795141,379548.043,1.723995021,617.3666939
,111.2,159.0253815,5.947840929,383519.7798,1.715706448,620.7897885
,111.4,160.1741226,6.00749787,386315.7631,1.710907771,623.4940776
,111.6,161.5648952,6.067738068,388105.4272,1.711780106,626.5862609
,111.8,163.160256,6.128570158,389347.8308,1.714397355,629.6696819
,112,164.2795864,6.190044856,388916.6401,1.722249449,632.1855037
,112.2,165.7507761,6.252113777,388976.1356,1.727920342,634.4427438
,112.4,166.9814039,6.314822196,390332.1356,1.730101391,637.4406912
,112.6,168.3700211,6.378150463,390724.5186,1.734463591,639.7527136
,112.8,169.759369,6.442114899,392497.2631,1.735335923,642.6498578
,113,170.9439303,6.506735717,394971.4779,1.733590876,645.4220855
,113.2,172.2373868,6.57199884,396146.0668,1.736208151,647.8382006
,113.4,173.3925656,6.638260261,397132.1432,1.741006605,650.7408201
,113.6,174.9712047,6.704828922,399458.8796,1.740133986,653.7190521
,113.8,176.2893595,6.771744987,401216.2921,1.739697625,656.1406494
,114,177.8361673,6.839656775,402184.871,1.742751107,658.8482341
,114.2,179.0167644,6.908275064,403533.3589,1.744495925,661.8242694
,114.4,180.5142629,6.977561918,403562.9292,1.749730576,664.0015189
,114.6,181.5382142,7.047576048,402542.9458,1.760200068,666.4910466
,114.8,182.8416224,7.118275288,401429.3962,1.769360832,668.3329989
,115,184.1299407,7.189685847,402043.3293,1.772850569,670.7293938
,115.2,185.6552791,7.261798276,404757.7777,1.768924323,673.5860011
,115.4,187.2096238,7.334633453,408357.9722,1.761071979,676.2289397
,115.6,188.3278581,7.408229184,414030.9302,1.747112419,679.7627028
,115.8,190.2663757,7.482510422,419384.0017,1.734025248,682.8658591
,116,191.5807373,7.557578969,423354.023,1.72748163,686.1235028
,116.2,193.0663811,7.633390502,427106.4016,1.72311916,689.6134445
,116.4,194.2806556,7.709981671,429903.9362,1.721810346,693.0737965
,116.6,195.7810327,7.787323602,432383.382,1.720065272,695.9610857
,116.8,197.0666174,7.865456557,434795.1877,1.720065149,699.4071946
,117,198.7073623,7.944351059,436051.0675,1.722682387,702.3898166
,117.2,200.1873957,8.024047965,437060.3006,1.724863408,705.1401391
,117.4,201.7979335,8.104536146,437650.8542,1.729661811,708.2980775
,117.6,203.6629497,8.185815834,436497.0065,1.738822516,710.489582
,117.8,204.8388995,8.267957118,435134.5972,1.749728209,713.304549
,118,206.6187855,8.350883172,435906.6749,1.752781668,716.0472069
,118.2,208.0956733,8.434661967,436027.4785,1.758888771,718.8556067
,118.4,209.775447,8.519269158,437749.4025,1.758452374,721.418564
,118.6,211.8960713,8.604697239,440909.652,1.754526083,724.6499266
,118.8,213.2269448,8.691035776,443824.4721,1.75059986,727.3608016
,119,214.7523796,8.778228881,445799.3337,1.751035942,730.364242
,119.2,216.6404482,8.866274212,449068.3609,1.747982137,733.707368
,119.4,218.1181761,8.95523111,450198.7612,1.751908082,736.81819
,119.6,219.7904611,9.045068962,450066.6713,1.758015165,739.0261307
,119.8,221.3352992,9.135817857,451468.0227,1.760632407,742.1281887
,120,223.1795295,9.227458598,453380.962,1.759323533,744.5037809
,120.2,224.6317186,9.320045887,455416.7194,1.759323384,747.731847
,120.4,225.9223425,9.413574128,460586.7089,1.749289928,751.4650439
,120.6,228.0240635,9.507988556,466356.1117,1.736638994,754.7873576
,120.8,229.3118908,9.603405304,470304.289,1.73140409,758.6695751
,121,231.2102887,9.699740353,473386.9807,1.728786515,762.1277564
,121.2,233.5786394,9.797012357,476862.2329,1.723987736,765.3273546
,121.4,235.3577448,9.895300558,478280.7296,1.726604959,768.8830545
,121.6,237.1017471,9.994578506,478110.4513,1.733584493,772.2316646
,121.8,238.9379479,10.09484784,479189.6047,1.735765474,775.0072014
,122,240.8447124,10.19611998,480480.2383,1.737946447,778.2867776
,122.2,242.4925483,10.29842667,482355.6218,1.739691213,781.7613905
,122.4,243.8881104,10.40177766,485495.9827,1.736637457,784.9007051
,122.6,246.0464944,10.50611691,491139.169,1.72791262,788.9692208
,122.8,248.0865609,10.61151222,494680.7176,1.723986341,792.3003029
,123,249.6888022,10.7179954,498018.7032,1.721368799,795.9075013
,123.2,251.4930606,10.82553501,497712.6807,1.729220788,799.364589
,123.4,253.4311067,10.9341462,495781.9492,1.741871307,802.5170644
,123.6,255.403093,11.04384645,492205.5303,1.757575438,804.5102539
,123.8,257.1828772,11.09074078,490423.3794,1.769353505,807.3668792
,124,258.8677922,11.09063095,492053.4042,1.770225802,810.342934
,124.2,259.7655911,11.09057274,496765.8432,1.761501093,813.4077295
,124.4,260.9288129,11.09049712,505229.8483,1.744051738,817.8684977
,124.6,261.2167218,11.0904789,516797.7674,1.719186542,822.9242324
,124.8,261.9472794,11.09043165,524730.9127,1.704354618,827.0255894
,125,262.7277598,11.09038113,530598.8436,1.696502387,831.4436155
,125.2,263.164605,11.09035314,532831.0663,1.699119733,835.8221889
,125.4,263.4841317,11.09033285,531597.9912,1.709153016,838.8245122
,125.6,264.1489575,11.09028991,526540.1051,1.730964503,841.8925909
,125.8,264.337853,11.09027818,521649.6199,1.750594879,844.0391422
,126,265.0010147,11.09023535,517771.9133,1.768480285,846.4968939
,126.2,265.2822673,11.09021757,515774.1017,1.781130955,849.1825512
,126.4,265.3563404,11.09021336,515519.5082,1.787238182,851.5449593
,126.6,265.6667145,11.09019367,516959.5121,1.788983076,854.5976891
,126.8,266.126857,11.09016415,518513.1237,1.790291724,857.6723357
,127,266.2042582,11.09015973,519810.0911,1.790727948,859.9952995
,127.2,266.5861883,11.09013535,520372.7531,1.79509022,863.0392637
,127.4,266.9614621,11.0901114,519570.4966,1.80294234,865.7358791
,127.6,266.797154,11.09012283,518680.1452,1.809922052,867.7498389
,127.8,267.4361863,11.09008158,517261.2894,1.819082838,870.1330809
,128,267.450768,11.09008128,515568.9647,1.828679917,872.1832039
,128.2,267.9866266,11.0900468,514904.7645,1.834350865,873.9111933
,128.4,268.084829,11.09004102,515282.2512,1.838276934,876.2538802
,128.6,268.3452804,11.09002459,514711.6333,1.84394791,877.8624281
,128.8,268.4334982,11.09001947,514927.236,1.848746441,880.0604773
,129,268.4851061,11.09001674,516714.0855,1.848310206,882.2431862
,129.2,268.9277755,11.08998837,516564.0135,1.853544932,884.267021
,129.4,268.9069953,11.08999039,515600.9582,1.860088398,885.7583184
,129.6,269.4827921,11.08995329,514502.5966,1.867504264,887.4161799
,129.8,269.3605023,11.08996196,512948.9682,1.875356433,888.6423051
,130,269.6026486,11.08994674,512246.1255,1.880154948,890.0908776
,130.2,269.4903434,11.08995476,512829.7276,1.881463654,891.8977423
,130.4,269.8972348,11.08992874,514744.9087,1.878846227,893.9018537
,130.6,269.7832655,11.08993687,518038.0453,1.871430316,895.9169107
,130.8,269.9580161,11.08992606,522946.4114,1.860524528,898.6507781
,131,270.0304251,11.08992197,524500.2607,1.86008829,900.6998072
,131.2,270.0703843,11.08992001,525733.3586,1.860088287,902.5340715
,131.4,270.5446714,11.08988956,526896.7855,1.860960701,904.712406
,131.6,270.4914415,11.08989371,527356.2944,1.863141861,906.3527235
,131.8,270.5996284,11.08988727,527542.1196,1.866631698,908.3634032
,132,270.6137942,11.089887,527521.42,1.870121544,910.0990486
,132.2,270.7860486,11.08987636,526978.3705,1.874483835,911.4446171
,132.4,270.9258533,11.08986785,524693.5306,1.884953361,912.8427793
,132.6,270.7245192,11.08988171,521224.0277,1.898476539,913.75881
,132.8,271.2037986,11.08985094,518618.8579,1.908946029,914.4053066
,133,271.2895203,11.08984597,517909.5918,1.91374456,915.4243441
,133.2,271.3502806,11.08984264,519122.2241,1.912872093,916.8915366
,133.4,271.3253402,11.08984494,521229.4373,1.908509788,918.2842159
,133.6,271.4410156,11.08983801,524075.7158,1.902402546,920.154641
,134.4,271.7260149,10.99336431,1.7977E+308,1.893677906,0
,134.6,271.587235,10.88250322,1.7977E+308,1.789854992,0
,134.8,271.1405981,10.77166231,1.7977E+308,1.620597482,0
,135,270.9735286,10.66080308,1.7977E+308,1.370201009,0
,135.2,271.0078142,10.54993064,1.7977E+308,1.068765511,0
,135.4,270.6244128,10.43908559,1.7977E+308,0.717163486,0
,135.6,270.5056019,10.32822319,1.7977E+308,0.461532223,0
,135.8,270.058965,10.21738229,1.7977E+308,0.2630472,0
,136,269.9692757,10.10651798,1.7977E+308,0.131305485,0
,136.2,269.6823916,9.995666597,1.7977E+308,0.055401319,0
,136.4,269.4479264,9.88481178,1.7977E+308,0.028791237,0
,136.6,269.5129977,9.773937323,1.7977E+308,0.023556467,0
,136.8,269.1395807,9.663091618,1.7977E+308,0.011778234,0
,137,268.8801541,9.552238439,1.7977E+308,0.003926078,0
,137.2,268.7863046,9.441374402,1.7977E+308,0.012650696,0
,137.4,268.4062313,9.330529134,1.7977E+308,0.01963039,0
,137.6,268.3489919,9.219662697,1.7977E+308,0.028791239,0
,137.8,267.9547738,9.108818356,1.7977E+308,0.026610085,0
,138,267.6196309,8.997970141,1.7977E+308,0.01919416,0
,138.2,267.6497563,8.887097975,1.7977E+308,0.014831851,0
,138.4,267.2630266,8.776253143,1.7977E+308,0.008724618,0
,138.6,267.1533682,8.665390143,1.7977E+308,0.003926078,0
,138.8,266.9397041,8.554533963,1.7977E+308,0.008724619,0
,139,266.5970728,8.443686239,1.7977E+308,0.006107233,0
,139.2,266.4533005,8.332825476,1.7977E+308,0.012650697,0
,139.4,266.2396364,8.221969296,1.7977E+308,0.021811548,0
,139.6,266.2248313,8.111100076,1.7977E+308,0.027918781,0
,139.8,265.9429393,8.00024837,1.7977E+308,0.030972398,0
,140,265.5595378,7.88940332,1.7977E+308,0.042750635,0
,140.2,265.3550261,7.778546539,1.7977E+308,0.046240483,0
,140.4,265.0964315,7.667693305,1.7977E+308,0.043623098,0
,140.6,264.949331,7.55683276,1.7977E+308,0.036643403,0
,140.8,264.7764371,7.445973907,1.7977E+308,0.022247781,0
,141,264.7449911,7.335105779,1.7977E+308,0.015268085,0
,141.2,264.100327,7.224277859,1.7977E+308,0.017885471,0
,141.4,264.0480797,7.113411095,1.7977E+308,0.021811551,0
,141.6,263.9201163,7.002549295,1.7977E+308,0.024865168,0
,141.8,263.6282398,6.891698244,1.7977E+308,0.022247782,0
,142,263.3555003,6.780845937,1.7977E+308,0.019194165,0
,142.2,263.210896,6.669985229,1.7977E+308,0.020502859,0
,142.4,262.9206835,6.559134068,1.7977E+308,0.018757935,0
,142.6,262.4474209,6.44829491,1.7977E+308,0.014831856,0
,142.8,262.2354208,6.33743862,1.7977E+308,0.010469545,0
,143,262.0242527,6.226582276,1.7977E+308,0.006979697,0
,143.2,261.7798028,6.115728115,1.7977E+308,0.007415928,0
,143.4,261.4729494,6.004878045,1.7977E+308,0.016576781,0
,143.6,261.470625,5.894008007,1.7977E+308,0.020939092,0
,143.8,261.027316,5.783166885,1.7977E+308,0.021811555,0
,144,260.7237907,5.672316597,1.7977E+308,0.019630399,0
,144.2,260.5500647,5.561457798,1.7977E+308,0.0196304,0
,144.4,260.3938117,5.450597854,1.7977E+308,0.02748256,0
,144.6,260.1909641,5.339740964,1.7977E+308,0.030536178,0
,144.8,259.926545,5.228888112,1.7977E+308,0.034026028,0
,145,259.9125719,5.118018838,1.7977E+308,0.044059343,0
,145.2,259.6677059,5.007164704,1.7977E+308,0.05016658,0
,145.4,259.2427019,4.896322381,1.7977E+308,0.044059345,0
,145.6,258.8464034,4.785478176,1.7977E+308,0.04187819,0
,145.8,258.3639882,4.674639618,1.7977E+308,0.037079649,0
,146,258.3383664,4.563771108,1.7977E+308,0.027918795,0
,146.2,258.2711423,4.452905326,1.7977E+308,0.024428945,0
,146.4,257.9701132,4.342054874,1.7977E+308,0.021811559,0
,146.6,258.0484972,4.231179544,1.7977E+308,0.01875794,0
,146.8,257.620165,4.12033744,1.7977E+308,0.013959398,0
,147,257.2775335,4.009489716,1.7977E+308,0.020066635,0
,147.2,256.9956414,3.89863801,1.7977E+308,0.028355028,0
,147.4,256.7204056,3.787785867,1.7977E+308,0.034462265,0
,147.6,256.426953,3.676380564,1.7977E+308,0.036643422,0
,147.8,256.3363435,3.56607067,1.7977E+308,0.035334729,0
,148,256.0211695,3.455221146,1.7977E+308,0.030099955,0
,148.2,255.5761962,3.344380132,1.7977E+308,0.026173874,0
,148.4,254.9015781,3.233554177,1.7977E+308,0.022247794,0
,148.6,255.153116,3.122113139,1.7977E+308,0.01744925,0
,148.8,254.8311975,3.011818412,1.7977E+308,0.013523169,0
,149,254.2481044,2.900986455,1.7977E+308,0.018757945,0
,149.2,254.1700637,2.790121382,1.7977E+308,0.02748257,0
,149.4,253.6743356,2.679283697,1.7977E+308,0.031408653,0
,149.6,253.3666499,2.568433682,1.7977E+308,0.025301415,0
,149.8,253.249503,2.457571173,1.7977E+308,0.02355649,0
,150,253.1107229,2.346710083,1.7977E+308,0.020939103,0
,150.2,252.5118209,2.235879163,1.7977E+308,0.012650708,0
,150.4,252.2099596,2.125028766,1.7977E+308,0.010033321,0
,150.6,251.9014419,2.014178805,1.7977E+308,0.015268097,0
,150.8,251.5762833,1.903329936,1.7977E+308,0.026173881,0
,151,251.3160243,1.792476811,1.7977E+308,0.036207202,0
,151.2,250.9251339,1.681632252,1.7977E+308,0.037952128,0
,151.4,250.5442281,1.570787037,1.7977E+308,0.037079667,0
,151.6,250.2606718,1.45993544,1.7977E+308,0.033153585,0
,151.8,249.8955749,1.34908919,1.7977E+308,0.030536197,0
,152,249.5063486,1.238244521,1.7977E+308,0.023120264,0
,152.2,249.0422381,1.127404763,1.7977E+308,0.022684033,0
,227.4,248.4577166,1.022916822,1.7977E+308,0.008288399,0
,227.6,248.1650077,0.912065825,1.7977E+308,0.010469557,0
,227.8,247.7699569,0.801221539,1.7977E+308,0.016576798,0
,228,247.5038735,0.690368796,1.7977E+308,0.018321725,0
,228.2,247.3126743,0.579511143,1.7977E+308,0.020939114,0
,228.4,246.7520461,0.468677713,1.7977E+308,0.019194189,0
,228.6,246.368644,0.357832663,1.7977E+308,0.023120273,0
,228.8,245.8146721,0.246998797,1.7977E+308,0.031844906,0
,229,244.8546612,0.136191555,1.7977E+308,0.037079687,0
,229.2,244.2699036,0.025359708,1.7977E+308,0.039697078,0
,229.242,243.9770007,0.002096174,1.7977E+308,0.039697078,0
END,,,,,,