File: GB1_test 30.csv
Segment,Time On Sample,Displacement Into Surface,Load On Sample,Harmonic Contact Stiffness,Harmonic Displacement,Harmonic Load
Surface Marker,0,0,0,8.086050036,0.361686048,2.254861072
,0.2,0.428977012,0.000629711,3867.69642,0.24868642,2.316217862
,0.4,0.35324748,0.001292559,10998.22558,0.195895094,2.41811391
,0.6,0.265451592,0.001956199,13618.15113,0.190659591,2.504670767
,0.8,0.611628434,0.002591347,15093.58626,0.179752288,2.594514624
,1,0.280841105,0.003270941,15661.59602,0.178879708,2.681071464
,1.2,0.605381723,0.003907509,16509.16237,0.174516785,2.759958756
,1.4,0.609539838,0.004564801,18916.69377,0.164918362,3.008672784
,1.6,0.69899465,0.005216217,21914.47021,0.152702187,3.249717224
,1.8,0.463073937,0.005888995,25983.86415,0.13743197,3.492952945
,2,0.942812944,0.006514787,31023.10512,0.123034332,3.744953992
,2.2,0.564592452,0.007196908,34459.61381,0.120416582,4.090085751
,2.4,0.938646826,0.007829639,37445.61165,0.123470624,4.572174663
,2.6,1.271925233,0.008465046,38124.43782,0.131760169,4.964419743
,2.8,0.653209795,0.009162957,37377.69546,0.147902976,5.442125893
,3,0.99064902,0.009798092,36333.96034,0.16491836,5.902301682
,3.2,1.032670571,0.010452622,36586.358,0.177134534,6.407399355
,3.4,1.234467312,0.011096662,38557.32533,0.189786999,7.292689855
,3.6,0.820463838,0.011781133,40479.39289,0.199821718,8.093614669
,3.8,1.128777375,0.012418179,42269.11604,0.205929802,8.754295631
,4,1.166638114,0.013072983,44144.00718,0.214655641,9.570559749
,4.2,1.286882934,0.013722377,45180.79326,0.23036215,10.51392006
,4.4,0.976899768,0.014400018,45367.95352,0.250431584,11.42879314
,4.6,1.540687172,0.015020292,44653.62166,0.279663137,12.49815412
,4.8,1.130012354,0.015704544,42771.73359,0.317620544,13.52587978
,5,0.919888681,0.016375628,40101.97167,0.366048955,14.5240228
,5.2,1.015168629,0.017026662,38100.5191,0.408805565,15.32933038
,5.4,0.916554724,0.017690426,36556.59037,0.461160603,16.52469157
,5.6,0.875360029,0.018350419,35262.96509,0.509589012,17.591861
,5.8,0.659411215,0.019021887,34349.76504,0.547982711,18.42455984
,6,0.94525637,0.019660409,33323.39961,0.594665943,19.429277
,6.2,1.129577702,0.020305596,32196.73945,0.640040301,20.23787162
,6.4,0.710581247,0.020990395,30582.17686,0.706356695,21.28641466
,6.6,1.127075908,0.021620339,28284.75507,0.791869903,22.14869663
,6.8,1.337194274,0.022263833,25953.08147,0.881309746,22.72172511
,7,1.571445349,0.022905742,23075.80838,1.009143276,23.2914666
,7.2,1.476992259,0.023569232,20867.0384,1.125633233,23.66727676
,7.4,1.598901404,0.024218517,19167.44734,1.232524753,23.96639104
,7.6,1.585168071,0.024876708,18093.2256,1.318474269,24.37287955
,7.8,1.440785234,0.025543476,18001.82215,1.345524381,24.78922897
,8,1.546883293,0.026193799,18478.92113,1.344215498,25.3830749
,8.2,1.647988377,0.02684445,19163.40123,1.330254149,25.95391197
,8.4,1.781547795,0.02749297,20109.72523,1.309312127,26.65074958
,8.6,1.673780107,0.028157335,20510.03212,1.311057303,27.11092526
,8.8,1.505264559,0.028825688,20638.15394,1.330690454,27.6445098
,9,1.5098388,0.029482676,20564.75237,1.352941344,28.03346794
,9.2,1.445343557,0.0301442,20548.08296,1.371265611,28.44543474
,9.4,1.443260498,0.030801625,20513.39242,1.391771334,28.9395759
,9.6,1.75823133,0.031438235,20514.56988,1.405296362,29.31319499
,9.8,1.685414464,0.032100305,20449.6948,1.425365798,29.74597923
,10,1.614261922,0.032762265,20302.66247,1.448925569,30.06481522
,10.2,2.163070394,0.033383522,19971.07098,1.484265176,30.33982543
,10.4,2.479705539,0.034020022,19770.38625,1.518732214,30.67509659
,10.6,2.257099442,0.034691926,19903.04168,1.527894364,30.96434974
,10.8,2.575398911,0.035328317,20495.32882,1.513060413,31.39275176
,11,2.388575799,0.035997871,21451.02269,1.474230447,31.83539675
,11.2,2.428933023,0.03665251,23642.63356,1.383045431,32.60126072
,11.4,2.545017027,0.037302177,25426.37139,1.316729049,33.19072403
,11.6,2.631143183,0.037953811,27538.68818,1.249103795,33.9445358
,11.8,2.272062451,0.038634676,29187.45478,1.203293166,34.57125103
,12,2.432251063,0.039281447,30359.38527,1.178424516,35.165097
,12.2,2.411028269,0.039940129,30763.74425,1.185405189,35.84878665
,12.4,1.817277725,0.040636401,30339.75657,1.215509371,36.30348353
,12.6,2.674818448,0.041237388,29224.58069,1.273972436,36.74612967
,12.8,2.832510049,0.041887606,28074.21595,1.33374442,37.03428747
,13,2.856224547,0.042540055,26788.39617,1.405296295,37.36188887
,13.2,3.049699651,0.043184641,26173.10606,1.445435139,37.64347274
,13.4,2.668982702,0.043866925,26303.96644,1.451106963,38.03133471
,13.6,2.968974595,0.044504518,27553.14276,1.410531792,38.64490277
,13.8,2.986031272,0.045160687,28849.27749,1.368211475,39.18067883
,14,2.876599265,0.04582516,30757.27031,1.311057241,39.91148159
,14.2,2.772160231,0.046489306,32274.80687,1.27266356,40.54696225
,14.4,2.676042821,0.047152905,33380.5296,1.256084473,41.28762591
,14.6,2.723889507,0.047807052,33565.42021,1.263937726,41.76533225
,14.8,2.889071092,0.048453496,33462.99369,1.284879728,42.32521296
,15,2.922771017,0.049108572,33168.01951,1.312366118,42.84455417
,15.2,2.918191472,0.049766161,32932.85476,1.333308132,43.25432974
,15.4,2.737193497,0.050435333,32716.58031,1.354250158,43.70026176
,15.6,2.64606906,0.051098604,32589.60275,1.374319594,44.22617674
,15.8,2.839544168,0.05174319,32565.76918,1.386972047,44.64252646
,16,3.14286471,0.052380564,32572.02967,1.401369659,45.17172896
,16.2,2.832881564,0.053058205,32607.1398,1.413585857,45.59465195
,16.4,3.028853158,0.053702627,32677.86273,1.425365725,46.0394888
,16.6,3.188209604,0.054349453,32750.19963,1.439327056,46.54020401
,16.8,3.105406794,0.055012178,32899.7259,1.447180317,46.95217075
,17,3.158246454,0.055665997,33045.04272,1.45765132,47.4452162
,17.2,3.03633201,0.05633129,33093.95578,1.467686045,47.84841775
,17.4,2.847844574,0.057000954,33135.42097,1.48121111,48.36008902
,17.6,2.975578851,0.057649856,33185.77619,1.490373232,48.74685602
,17.8,3.234794785,0.058290126,33148.41196,1.504770848,49.19717115
,18,2.986807739,0.058963696,33161.05304,1.51436929,49.55106794
,18.2,3.087912818,0.059614347,33207.09624,1.524403996,49.92906946
,18.4,3.174871137,0.060265926,33214.29289,1.53792904,50.38157573
,18.6,3.158225236,0.060924308,33072.29415,1.554508138,50.70260312
,18.8,2.94893374,0.061595337,32907.60951,1.575013878,51.08279556
,19,2.819529833,0.062261122,32739.86357,1.592029269,51.37095303
,19.2,3.291779344,0.062887405,32580.31239,1.608172032,51.66678098
,19.4,2.971810249,0.063565701,32498.08978,1.623442283,52.03820806
,19.6,3.464863817,0.064190618,32593.61612,1.626932575,52.33403605
,19.8,3.109943904,0.064871209,32866.23424,1.624314852,52.73285449
,20,3.494816359,0.065503229,33093.50233,1.623442237,53.04621283
,20.2,3.670816051,0.066148962,33481.33601,1.61646155,53.40230147
,20.4,3.589677567,0.066811578,34163.98121,1.599882467,53.90192072
,20.6,3.588426671,0.067468948,35083.34849,1.575013829,54.42454898
,20.8,3.758601226,0.068115064,35869.20208,1.554944388,54.86062045
,21,3.62420435,0.068781176,37139.62432,1.520041043,55.45008346
,21.2,3.677876129,0.069435211,38280.17381,1.491245776,55.99243364
,21.4,3.886329353,0.070083842,39606.42682,1.461577911,56.68269752
,21.6,3.898391209,0.070751957,40368.96413,1.448052861,57.18998649
,21.8,3.568433229,0.07144943,41052.28578,1.440199633,57.80903197
,22,3.762736472,0.072119262,41129.31976,1.451106917,58.35576491
,22.2,3.709054214,0.072812364,40904.95033,1.46899489,58.76882726
,22.4,3.109472317,0.073548267,40470.18774,1.49429987,59.16764522
,22.6,3.87047485,0.074201658,39621.6053,1.534874959,59.5379785
,22.8,4.090570726,0.074897467,38877.59319,1.572396047,59.88749344
,23,4.025233779,0.07561912,38592.86845,1.593774357,60.2654946
,23.2,3.969049481,0.076347322,38657.29023,1.600318741,60.60405247
,23.4,4.120904618,0.077069147,38991.23526,1.597700978,61.01054127
,23.6,4.109654757,0.077809065,40141.81089,1.56803313,61.60876972
,23.8,4.05013831,0.078559505,41497.38349,1.533566074,62.25301573
,24,4.266066418,0.07929934,42682.77935,1.504770792,62.8194706
,24.2,3.941919925,0.080082332,44051.71422,1.475975552,63.61053393
,24.4,3.975602023,0.080849551,44909.43637,1.460269041,64.1616492
,24.6,4.084177508,0.081619573,45516.91749,1.455469823,64.82671288
,24.8,3.794978148,0.082423442,45779.91408,1.460705349,65.45014105
,25,4.043354421,0.083199967,45696.34686,1.473357796,65.89936061
,25.2,3.936396098,0.084007748,45557.98451,1.488628022,66.3661101
,25.4,4.173119567,0.084800948,45336.82453,1.508697433,66.93585188
,25.6,4.045354638,0.085626118,44996.79024,1.531384623,67.43656676
,25.8,3.984161361,0.086455335,44771.982,1.547963722,67.81895074
,26,4.283293088,0.087269097,44593.96099,1.565415375,68.28350966
,26.2,4.053168223,0.088125934,44469.91245,1.578940444,68.67246731
,26.4,4.625246539,0.088938529,44435.60945,1.592465447,69.17208793
,26.6,4.276951948,0.089819942,44491.22441,1.602063899,69.63883684
,26.8,4.316443627,0.090684647,44718.57599,1.605554232,70.13516932
,27,3.844154056,0.091591679,45098.88513,1.601627645,70.55809185
,27.2,4.307213613,0.092446014,45603.55601,1.594646936,71.039086
,27.4,4.330057862,0.093338119,46083.11473,1.590720308,71.62416655
,27.6,4.439445583,0.094233443,46502.45771,1.588102549,72.18295172
,27.8,4.52469915,0.095139432,46760.60841,1.590284002,72.70777135
,28,4.353645246,0.096071462,46609.78651,1.602936483,73.07372016
,28.2,4.342365043,0.097002265,46561.68253,1.612534907,73.46596525
,28.4,4.41097094,0.097937179,46719.56207,1.617770405,73.99297619
,28.6,4.372226403,0.098888509,46988.76777,1.619079285,74.50903032
,28.8,4.821127511,0.099817239,47366.07025,1.615588912,74.9527722
,29,4.600136394,0.100799565,48013.52627,1.606863094,75.54004367
,29.2,4.535590251,0.101781352,48393.16575,1.605117933,76.01336709
,29.4,4.758970717,0.102754103,48577.14173,1.609480834,76.48121287
,29.6,4.947398811,0.103738905,48584.53265,1.620388116,76.96987625
,29.8,4.877855001,0.104750553,48591.898,1.630422837,77.43443436
,30,4.74007225,0.105776925,48838.72849,1.632604309,77.94172321
,30.2,4.936817131,0.106791607,49187.7128,1.629986542,78.38875128
,30.4,4.987099831,0.107826011,49774.21973,1.6212607,78.8982318
,30.6,4.657081825,0.108901182,50689.10547,1.604681637,79.54028565
,30.8,4.957842864,0.109935065,51672.51767,1.587229937,80.21521078
,31,4.881631856,0.11100943,52261.83091,1.57937669,80.73126506
,31.2,4.966858626,0.112083999,52872.63446,1.573704889,81.3886591
,31.4,5.042097718,0.113170105,53176.57748,1.574577467,81.9321049
,31.6,4.861861235,0.11428389,53326.29429,1.581121862,82.54567208
,31.8,5.030299018,0.115385852,53281.88508,1.590283978,82.98612652
,32,5.167112873,0.116500948,53455.98013,1.595519471,83.57997255
,32.2,5.20739411,0.117633615,53699.29041,1.597264636,84.09054858
,32.4,5.560566571,0.118757143,54237.17801,1.593774272,84.7490391
,32.6,5.066595941,0.119947826,54890.84824,1.587666228,85.42834511
,32.8,5.272471987,0.121104208,55434.53725,1.582430709,85.96412149
,33,6.242271187,0.122222061,55868.87342,1.582866921,86.60836992
,33.2,6.357437887,0.123407324,56207.3791,1.583739496,87.14305073
,33.4,6.48258864,0.124603849,56425.99,1.589847573,87.80044493
,33.6,6.441305021,0.12582334,56823.39012,1.588974993,88.35484694
,33.8,6.647171646,0.127038899,57466.10386,1.583303183,89.03305906
,34,6.449437608,0.128293257,58397.92684,1.570650736,89.77920074
,34.2,6.235890482,0.129561245,59313.14744,1.557125706,90.43768983
,34.4,6.46588387,0.130812629,60876.61256,1.532257052,91.37009397
,34.6,6.325563017,0.132101031,61948.92548,1.516986848,92.10199234
,34.8,6.703677246,0.133368142,62762.62061,1.510442441,92.9478403
,35,6.765567763,0.134668851,63542.61164,1.505206935,93.77506107
,35.2,7.025510834,0.135969558,64148.81185,1.502589164,94.47956913
,35.4,7.061184085,0.137298123,64329.53353,1.509569832,95.17750245
,35.6,6.917108145,0.138651952,64193.84554,1.525276353,95.92035713
,35.8,7.122122138,0.139996325,64486.34138,1.531384424,96.70265652
,36,7.401196432,0.141349282,64678.27796,1.536619904,97.31184245
,36.2,7.097754949,0.142754293,64594.68531,1.549708684,98.0190878
,36.4,7.316909151,0.144138927,64938.43923,1.55276271,98.7274305
,36.6,7.141616203,0.145563536,65763.78121,1.546218348,99.58423333
,36.8,7.282542654,0.146981608,66660.45446,1.537928791,100.4465155
,37,7.416809533,0.148414415,67360.48792,1.532256989,101.1499274
,37.2,7.913064724,0.149837691,68377.84258,1.523531111,102.1020545
,37.4,8.158004625,0.151291861,69019.22363,1.520913344,102.8964062
,37.6,8.024308378,0.152785569,69522.2927,1.523094812,103.786079
,37.8,8.215985178,0.15427291,69647.92773,1.533129512,104.6341179
,38,8.30780013,0.155781784,69772.18132,1.539673884,105.263025
,38.2,8.202390236,0.1573187,70119.84329,1.542291642,105.9719146
,38.4,8.23012383,0.158862405,70605.48017,1.545345683,106.9108925
,38.6,8.195442792,0.160425708,71153.96774,1.546654562,107.8170003
,38.8,8.347163606,0.161992417,71576.49089,1.547527136,108.5160297
,39,8.672803824,0.163563412,72007.35352,1.551017443,109.4210431
,39.2,8.440892828,0.165186939,72411.94888,1.552762631,110.189098
,39.4,8.637542811,0.166798437,72627.39117,1.55843441,110.9516754
,39.6,8.621988827,0.168440247,72985.76164,1.561924746,111.8260097
,39.8,8.503244108,0.17010531,73410.26298,1.562361048,112.5513338
,40,8.725683262,0.171764546,74152.65342,1.559306988,113.4925037
,40.2,8.792505432,0.173450673,74394.68183,1.564542486,114.2265938
,40.4,8.571396771,0.175172728,74844.77706,1.568469131,115.1820056
,40.6,8.853743516,0.176878909,74945.22976,1.576322362,115.8613138
,40.8,8.848159382,0.178621322,74757.1687,1.592028869,116.6677169
,41,8.940767598,0.180374842,74462.18045,1.606862784,117.2484154
,41.2,9.156533029,0.182137817,74324.54942,1.618642646,117.8674619
,41.4,9.34982728,0.183919881,74283.77002,1.631295093,118.6651007
,41.6,9.507335692,0.185722312,74548.7003,1.634349123,119.2753821
,41.8,9.599932596,0.187546975,75158.61181,1.633040241,120.1212292
,42,9.726645229,0.189387769,75905.34137,1.626932145,120.8432675
,42.2,10.12796843,0.191229058,76646.46704,1.621696611,121.6102286
,42.4,9.784503523,0.193137947,77675.27111,1.612970805,122.5963184
,42.6,9.941997212,0.195032984,78235.07321,1.610789333,123.3413657
,42.8,10.0578798,0.196949598,78815.75518,1.610353033,124.2595264
,43,10.45586226,0.198867099,79052.51265,1.614279626,124.9563653
,43.2,10.50017274,0.200827138,79440.21655,1.615588498,125.688264
,43.4,10.66264712,0.202799094,79942.12336,1.617769945,126.6371034
,43.6,10.3774151,0.204820371,80592.60877,1.614715927,127.4018708
,43.8,10.54154744,0.206832256,81547.06594,1.608171537,128.3682406
,44,10.65075385,0.208868034,82481.15861,1.600318277,129.1965572
,44.2,10.8989281,0.210915041,83335.27279,1.594210172,130.0456922
,44.4,10.85334582,0.213002126,84325.3528,1.588102092,131.1369662
,44.6,10.70124347,0.215117039,84717.24498,1.589847273,131.9422733
,44.8,10.99101586,0.217223976,84667.11389,1.601190836,132.856052
,45,11.06691919,0.219366373,84313.428,1.617333626,133.6514992
,45.2,11.13782611,0.221530663,83931.79263,1.633040125,134.3077978
,45.4,11.03647201,0.223728118,83425.3707,1.650928098,134.9136954
,45.6,11.43690817,0.225914549,83055.21708,1.667507151,135.6061519
,45.8,11.34886164,0.228155243,82952.93982,1.677105579,136.1791803
,46,10.99784832,0.230435664,83113.48878,1.683213696,136.9275125
,46.2,11.14113568,0.232706344,83328.48727,1.686267726,137.5498458
,46.4,11.23698618,0.23500293,83887.53246,1.685395135,138.4176065
,46.6,11.51674082,0.237310579,84409.79794,1.683213653,139.1023929
,46.8,11.74240123,0.239645031,84972.4886,1.681904758,139.9318059
,47,11.737549,0.242018124,85237.15752,1.68452251,140.5749562
,47.2,11.98983109,0.244398018,85529.3959,1.686703948,141.2159165
,47.4,11.99745375,0.246817791,86028.51235,1.68714024,142.0705292
,47.6,12.62004032,0.249221413,86641.32667,1.68321356,142.7805173
,47.8,12.52030633,0.251696904,87790.12247,1.671869984,143.74579
,48,12.6793708,0.254180175,89065.11116,1.657472344,144.5938291
,48.2,12.88003739,0.256698416,90521.15173,1.641329533,145.5339036
,48.4,13.05740142,0.259230836,92563.64349,1.619514931,146.7939095
,48.6,12.81202511,0.261803762,93723.80927,1.610352827,147.7263125
,48.8,13.07675801,0.264381652,94801.65225,1.605117304,148.8307358
,49,12.89045494,0.267015263,95212.64263,1.607735071,149.6732952
,49.2,13.20261275,0.269642481,95674.12579,1.609916505,150.5596825
,49.4,13.04459478,0.272327121,95917.82712,1.617333479,151.6137035
,49.6,13.24856307,0.275014635,96193.39224,1.621260088,152.4179165
,49.8,13.02396361,0.27775734,96376.51164,1.628240776,153.3941459
,50,13.41183104,0.280487236,96750.12878,1.630422202,154.2136986
,50.2,13.25712445,0.28328034,96843.28053,1.636966592,155.0091447
,50.4,13.60171065,0.286068532,96966.01955,1.645256106,156.0270114
,50.6,14.49551932,0.288848544,96966.20587,1.653109281,156.7720623
,50.8,14.38407179,0.291722886,97119.22585,1.660526251,157.7033698
,51,14.39661184,0.294617829,97393.07766,1.663580292,158.4221208
,51.2,14.79360611,0.297516448,97671.84401,1.668815759,159.3709614
,51.4,14.77285039,0.300471982,97613.89801,1.677541596,160.1160078
,51.6,14.70465674,0.303460177,97887.72956,1.68190452,161.0133505
,51.8,14.53992752,0.306484835,98100.03316,1.685394869,161.7222396
,52,14.85451879,0.309508194,98022.67919,1.69499326,162.5593231
,52.2,15.10669307,0.312566143,98419.48394,1.695865822,163.3043708
,52.4,15.08008819,0.315673184,98918.26045,1.695429533,164.0800954
,52.6,14.98024811,0.318816195,99374.4696,1.69717471,164.978534
,52.8,15.31978453,0.321961864,99774.47593,1.698047264,165.7137212
,53,15.16667603,0.325171628,100694.213,1.692375487,166.6713244
,53.2,15.85903897,0.328357944,100899.0732,1.696302051,167.4065135
,53.4,15.63851512,0.331636558,101434.5488,1.695865781,168.2392116
,53.6,15.58774708,0.334936847,102411.1075,1.690193996,169.266937
,53.8,15.62227039,0.338264576,103147.2335,1.686703661,170.0908715
,54,15.78494135,0.341617187,103577.4587,1.689321399,171.0232759
,54.2,15.94303007,0.345003685,104291.7078,1.68626734,171.839541
,54.4,16.28086036,0.348412398,105025.1601,1.684958438,172.8957559
,54.6,16.26751284,0.351878631,104807.3691,1.694993149,173.5662978
,54.8,16.06941986,0.355391733,104445.4833,1.708518209,174.3584567
,55,16.28074495,0.358913122,104313.7652,1.716807736,174.9884604
,55.2,16.4329809,0.362473863,104253.9522,1.724224684,175.672151
,55.4,16.57688954,0.366070981,103679.2706,1.741240043,176.4226767
,55.6,16.82398052,0.369697332,103932.526,1.743421482,177.0570632
,55.8,16.66164202,0.373387269,104176.9558,1.746911825,177.8382657
,56,16.80802973,0.377093787,104262.5464,1.751274733,178.4343038
,56.2,17.37465326,0.380809964,104146.4047,1.75912793,179.0281526
,56.4,17.86055117,0.384568601,104613.8276,1.75912789,179.8520891
,56.6,18.05019344,0.388384521,104894.5961,1.761309326,180.596042
,56.8,18.63510649,0.392212748,105410.2268,1.759127815,181.2457686
,57,18.35706155,0.396136498,106352.4483,1.752147175,182.1222928
,57.2,18.57081801,0.400067213,107577.0398,1.740367283,182.9714285
,57.4,18.62146448,0.404048139,108669.7335,1.731205155,183.8359016
,57.6,19.01578745,0.408046249,110129.8773,1.718552663,184.8965
,57.8,19.50164181,0.41207856,111156.1425,1.710699372,185.7609757
,58,19.42994131,0.416188224,112394.4461,1.701537255,186.84458
,58.2,19.81425891,0.420309102,113028.6366,1.699792056,187.7013859
,58.4,20.06958485,0.424479911,114208.0594,1.692811368,188.8605923
,58.6,19.99370375,0.428714317,115038.174,1.68844846,189.7513609
,58.8,20.1175347,0.432978197,115861.8993,1.686266992,190.8656446
,59,20.2005829,0.437287705,116701.6053,1.682340361,191.7903796
,59.2,20.42342743,0.441631113,117834.9306,1.674923386,192.7983855
,59.4,20.31256811,0.446040367,118716.6491,1.671433064,193.8545979
,59.6,20.12847154,0.450498545,119647.7904,1.668815331,195.0609158
,59.8,20.42119655,0.454970126,120842.2791,1.660962058,196.0875475
,60,20.45178347,0.459503824,121458.3083,1.662707223,197.2796226
,60.2,20.7120398,0.464067959,121365.384,1.671433032,198.1802543
,60.4,20.72929757,0.468694106,121226.647,1.680595155,199.075406
,60.6,20.53018591,0.47338092,120805.3341,1.694556504,200.056018
,60.8,20.82370654,0.478082338,120101.5626,1.710262976,200.7134135
,61,21.05813617,0.482834867,119841.1679,1.722042828,201.5866534
,61.2,21.21683147,0.487640241,119930.1639,1.728150896,202.3656665
,61.4,20.99688551,0.492518763,120434.1956,1.729023501,203.2399994
,61.6,21.25542476,0.497414839,121323.254,1.725533146,204.2633445
,61.8,21.26347551,0.502376552,122289.1603,1.72117023,205.3414712
,62,21.92226881,0.507345243,122847.4941,1.720297588,206.1960872
,62.2,22.08425362,0.512396621,123245.4657,1.721606449,207.0441268
,62.4,22.19713282,0.517501967,123342.8631,1.728587105,208.0608973
,62.6,22.42567435,0.522650899,123758.5417,1.72989596,208.8793543
,62.8,22.60427794,0.527854955,124184.0902,1.732513694,209.8533947
,63,22.52739958,0.533128106,124890.7903,1.730332244,210.7080067
,63.2,22.76590208,0.538433526,125851.8043,1.725096725,211.6152123
,63.4,22.83796375,0.543803233,126976.6526,1.719861221,212.7985219
,63.6,22.91500984,0.54922645,127020.0856,1.725533005,213.5709611
,63.8,23.17512284,0.554692089,127203.9163,1.73076848,214.5450013
,64,23.43439494,0.560212702,127356.4995,1.734695081,215.3338762
,64.2,23.84511164,0.565778815,126813.8828,1.746911207,216.0077076
,64.4,24.22835809,0.571402736,126529.1785,1.757818461,216.9214883
,64.6,24.5699875,0.577085756,126708.3869,1.76087247,217.6501021
,64.8,24.74683982,0.582836779,126911.8495,1.764799079,218.5277246
,65,25.00939562,0.588639851,127012.7935,1.768725679,219.2201815
,65.2,25.00148961,0.594519133,127893.0898,1.763490182,220.0835589
,65.4,25.39301177,0.600431244,129042.4915,1.756073192,221.1836012
,65.6,26.25802439,0.606371536,129960.5921,1.750401324,222.0645153
,65.8,26.9133228,0.612385252,131151.3268,1.74298431,223.1536025
,66,27.35557332,0.618504423,132398.7593,1.736003608,224.2876103
,66.2,27.41752605,0.624648572,132990.0734,1.735567312,225.1783802
,66.4,27.58098773,0.630878807,133922.624,1.732076967,226.1841941
,66.6,27.41157488,0.63719354,135180.3809,1.725968903,227.3718858
,66.8,27.68735836,0.643542171,136200.6151,1.721169673,228.3590748
,67,27.97644626,0.649953893,137211.4316,1.717679317,229.54896
,67.2,28.21975506,0.656432867,138482.387,1.710262342,230.6566711
,67.4,28.74432406,0.66295852,139291.5416,1.708080838,231.7337056
,67.6,28.7146631,0.669586335,140191.8345,1.706335676,233.0046677
,67.8,29.0403245,0.676257252,141220.1112,1.701536443,234.078414
,68,29.19621431,0.683006438,142978.3279,1.690629145,235.4709954
,68.2,29.59674879,0.689807306,144349.3694,1.683648448,236.6937518
,68.4,29.80421095,0.696689267,145697.371,1.677540351,237.9921065
,68.6,30.04328425,0.703638271,147075.2886,1.671868543,239.4613845
,68.8,30.19746599,0.710662721,147629.2338,1.673177405,240.588817
,69,30.56883065,0.717743284,147326.4057,1.684520948,241.7622687
,69.2,30.58984404,0.724918216,147444.5025,1.690192735,242.8020478
,69.4,30.77311746,0.732154376,147726.7975,1.694991925,243.927289
,69.6,31.21102069,0.739446495,148476.8783,1.696300761,245.247559
,69.8,31.57152126,0.746816955,149800.4264,1.690192651,246.410054
,70,31.63576065,0.754280903,152020.5248,1.677540197,248.0206706
,70.2,31.78570073,0.761814183,153679.7179,1.669250649,249.3891475
,70.4,31.96808303,0.769421252,155285.2315,1.661833682,250.8058335
,70.6,32.16876072,0.777103643,156664.0867,1.657907043,252.4087819
,70.8,32.20174564,0.784874221,156907.2917,1.662269954,253.5263526
,71,32.56550228,0.792700982,157489.6099,1.665323968,255.0306921
,71.2,32.89887251,0.800608474,157861.679,1.668814268,256.2413967
,71.4,32.85567715,0.808620163,157650.9503,1.677976391,257.4115582
,71.6,33.08458577,0.816694088,157162.2938,1.691065113,258.7000528
,71.8,33.08879797,0.824863907,157386.1064,1.696300609,259.7836574
,72,33.56899336,0.833084389,156892.3684,1.709825596,260.9198576
,72.2,33.54072507,0.841421133,156432.4732,1.721605462,261.8730793
,72.4,33.55571586,0.849838787,156700.6158,1.726404669,262.9292931
,72.6,33.88691448,0.858320082,157088.5472,1.731203842,264.1739623
,72.8,33.93516475,0.866905206,156962.4853,1.739929666,265.2641417
,73,34.36702762,0.875551308,157219.5375,1.743419956,266.2173669
,73.2,34.96364458,0.884273434,157629.3693,1.745165069,267.1574454
,73.4,35.46787769,0.893089381,158251.9851,1.746473895,268.4273162
,73.6,35.83562231,0.902002755,159233.2963,1.742547242,269.5065415
,73.8,36.21916374,0.911004668,160340.452,1.73905688,270.825716
,74,36.3646927,0.920112761,161673.7105,1.733821368,272.2204902
,74.2,36.26305529,0.929328541,162667.6058,1.73120363,273.4541985
,74.4,36.64738522,0.93860502,163455.4642,1.729894722,274.5367118
,74.6,37.08662297,0.94797104,164227.4067,1.730330975,275.8690343
,74.8,37.57827189,0.957427719,165099.9948,1.728149475,276.9723655
,75,37.56644827,0.967012573,166457.4472,1.722913982,278.4219209
,75.2,37.98400446,0.976665298,167701.0773,1.717678451,279.6742599
,75.4,37.92721343,0.986446343,168763.1479,1.714624419,280.9375528
,75.6,38.28482297,0.996298354,169554.9583,1.71549697,282.3958758
,75.8,38.78638064,1.006239827,170230.6943,1.715496925,283.5419377
,76,39.11400075,1.016292731,170789.2567,1.718550935,284.9553384
,76.2,39.41747214,1.026448191,171221.9126,1.721168655,286.0707203
,76.4,39.30567897,1.03673311,172106.1619,1.720296084,287.3668824
,76.6,40.00855497,1.047067655,173768.4385,1.713751654,288.9807916
,76.8,40.57910085,1.05751477,175188.6317,1.708079819,290.2747676
,77,41.10635765,1.068069747,176510.4553,1.705025734,291.8141714
,77.2,41.36480964,1.078748337,177387.3176,1.704589421,293.1103362
,77.4,41.38191789,1.089550235,177712.4482,1.710697496,294.6574048
,77.6,42.1654291,1.100409925,177901.9825,1.71593292,295.8100427
,77.8,42.37639624,1.111416656,178103.404,1.722477268,297.2113914
,78,43.12492171,1.122498493,178510.4551,1.725094948,298.3300637
,78.2,43.30589578,1.133729139,179462.2068,1.723349768,299.5922629
,78.4,43.76562576,1.145054313,180776.382,1.720731981,301.2554753
,78.6,44.12880702,1.156499543,181333.9294,1.722040822,302.4333101
,78.8,44.0758896,1.168087168,181806.3967,1.725531156,303.9014911
,79,44.35082502,1.179769614,182342.5724,1.727276296,305.0848036
,79.2,44.55167947,1.191574358,182622.5641,1.73163919,306.2703066
,79.4,44.96804471,1.203483435,183140.2162,1.735565772,307.7702655
,79.6,45.46927133,1.21550647,184459.4129,1.730766526,309.0379466
,79.8,45.83566871,1.227659131,186427.7741,1.722476964,310.7121147
,80,46.35516421,1.239923984,187507.679,1.719859172,311.990752
,80.2,46.50266428,1.252336663,189234.0275,1.712442212,313.4567431
,80.4,46.61436163,1.264876285,191631.5226,1.701971219,315.4355023
,80.6,47.00314847,1.277523573,192428.3411,1.702407476,316.8127475
,80.8,47.28789501,1.29030486,192862.4756,1.707206652,318.3915934
,81,47.40119603,1.303225934,193090.7322,1.713314716,319.8816885
,81.2,47.61267137,1.316270322,192531.9429,1.725094555,321.1482706
,81.4,48.41079911,1.329407133,191704.4437,1.737746921,322.1365617
,81.6,48.78616827,1.342703716,191359.6156,1.74778158,323.4239629
,81.8,49.08412528,1.356138909,191393.3845,1.753017045,324.4725109
,82,49.57595422,1.369696375,191559.5282,1.758252492,325.7522429
,82.2,50.23252928,1.383379155,192374.3293,1.75737985,326.9804817
,82.4,50.62861622,1.397216696,193603.9059,1.753453196,328.3128055
,82.6,51.40331405,1.411168398,195262.2983,1.747345053,329.9497251
,82.8,51.44485623,1.425308513,196602.1095,1.74254585,331.2831413
,83,51.4489286,1.43959313,199177.1888,1.729457124,333.0778288
,83.2,51.80082124,1.45399833,200643.4471,1.724221602,334.5471097
,83.4,52.56960323,1.468520837,202025.5783,1.720294915,336.0766553
,83.6,52.71256562,1.483304505,203497.8347,1.717240867,337.8384749
,83.8,53.18338725,1.498141716,204511.241,1.718113407,339.5301752
,84,53.69830166,1.513049755,204707.998,1.723348851,340.724447
,84.2,54.01928688,1.528195802,205169.7803,1.72683915,342.0458133
,84.4,54.78628587,1.54346455,206339.5674,1.726839081,343.8865271
,84.6,55.18877423,1.558910713,206990.1264,1.728147918,345.1969381
,84.8,55.75350915,1.574501497,208035.2017,1.727711577,346.9247956
,85,55.88466365,1.590277508,209073.7048,1.725093821,348.3272396
,85.2,56.03243618,1.606210782,209832.3895,1.724657517,349.7318747
,85.4,57.27364182,1.62223217,209975.6056,1.730329186,351.4509749
,85.6,57.74757009,1.638465124,209769.8087,1.7373098,352.9827082
,85.8,58.43616976,1.654846975,209809.1247,1.742108931,354.1857487
,86,58.92502479,1.671406659,210184.301,1.747344376,355.6846136
,86.2,59.24326055,1.688143909,210687.3546,1.750398383,356.9840674
,86.4,59.83941106,1.705030959,211794.3145,1.749525747,358.3558376
,86.6,60.15592877,1.722106188,213962.9081,1.742545068,360.1088943
,86.8,60.65299796,1.739341023,216258.9862,1.734691791,361.9660392
,87,60.92618854,1.756763845,218314.5152,1.726402244,363.4922944
,87.2,61.25344172,1.774358027,221122.3489,1.713749785,365.2913684
,87.4,61.78537819,1.792115283,224649.1685,1.698479565,367.7062046
,87.6,61.89371686,1.810078773,226814.2749,1.690626324,369.4844594
,87.8,62.70020901,1.828177155,229341.7259,1.682336731,371.7393327
,88,63.05106462,1.846487583,230268.9963,1.682772991,373.3455711
,88.2,63.62823848,1.864967061,231301.3949,1.685390686,375.6245458
,88.4,64.04727244,1.883642584,231564.6293,1.690626135,377.1825768
,88.6,64.92313235,1.902475601,231759.5859,1.698042998,379.131763
,88.8,65.66373618,1.921506688,231356.2933,1.707205039,380.521065
,89,66.0980749,1.940748312,230845.8246,1.718548557,382.2029046
,89.2,66.99173511,1.960152963,230094.8566,1.730328321,383.4968868
,89.4,67.0240789,1.979809354,229454.8858,1.741235584,384.8270164
,89.6,67.64805692,1.999624193,229212.8251,1.750397627,386.3729972
,89.8,67.76188933,2.019671836,229489.9686,1.754324232,387.6450578
,90,68.31507009,2.039891812,230354.5473,1.755633051,389.3181343
,90.2,68.58861286,2.06033348,231424.9359,1.753887866,390.7523542
,90.4,69.32646811,2.080949815,233246.7948,1.749088602,392.7453651
,90.6,69.69564365,2.101797706,234379.4625,1.746907112,394.2168386
,90.8,70.38683168,2.122833842,236235.2171,1.74123528,396.1660228
,91,70.31239922,2.144131819,238314.7641,1.732945764,397.8456664
,91.2,70.88868161,2.165600716,240528.6838,1.724656197,399.664466
,91.4,71.77698955,2.187264734,243540.1508,1.71374886,402.1439513
,91.6,72.30160912,2.209170422,245789.2762,1.705895585,404.0054812
,91.8,72.97348593,2.231286462,247682.3963,1.702841486,406.2198149
,92,73.75933325,2.253617219,247964.2581,1.708076901,407.7833288
,92.2,74.30215429,2.276188427,247770.6547,1.71636637,409.3249278
,92.4,75.0596364,2.298972329,246765.5088,1.731636466,411.0768949
,92.6,75.64232865,2.321996429,246223.7025,1.743416253,412.7587371
,92.8,76.39058382,2.345241,247168.5424,1.743852475,414.254321
,93,76.92327256,2.368733349,249419.672,1.738180653,416.3141651
,93.2,77.34940738,2.392468716,251976.1384,1.729454808,418.1877468
,93.4,77.70809936,2.416447041,255277.5094,1.716802357,420.3188063
,93.6,78.53276227,2.440635531,258631.9565,1.705458736,422.7522745
,93.8,78.79567898,2.465104136,261076.0485,1.69978694,425.1506746
,94,79.55202706,2.489786091,263043.1718,1.69498768,427.0943828
,94.2,80.42899878,2.514708065,264016.8592,1.696296473,429.0008401
,94.4,81.25932975,2.539883472,263449.1539,1.708076236,431.1582022
,94.6,81.92984592,2.565322375,262776.4683,1.718110851,432.7107587
,94.8,82.65441179,2.591013206,261071.9408,1.735126104,434.3761694
,95,82.84718692,2.616997345,259527.6223,1.749523663,435.5824919
,95.2,83.7530809,2.643195473,259675.2395,1.753886482,437.0769814
,95.4,83.62039851,2.669725152,261995.3355,1.747342143,439.359238
,95.6,84.73508019,2.696439131,264139.0003,1.740361398,441.1605148
,95.8,85.31796953,2.723456629,267511.2458,1.728581512,443.6334244
,96,85.75934867,2.750754924,269796.3975,1.722037121,445.5409727
,96.2,86.22980975,2.778325667,271167.0433,1.721600789,447.4561899
,96.4,87.41505134,2.806126194,271625.252,1.727272453,449.5302884
,96.6,87.80304023,2.834258628,271257.688,1.73730709,451.4192088
,96.8,88.92078753,2.862625519,271753.716,1.740797309,452.9947811
,97,89.64654265,2.891303327,273201.5984,1.740360953,455.0579163
,97.2,90.46628587,2.920263116,273530.7823,1.745160069,456.6751202
,97.4,91.05131406,2.94952924,274934.7379,1.745596306,458.8511065
,97.6,91.97914488,2.979066824,276521.8825,1.742978482,460.6556699
,97.8,92.47420597,3.008929715,277094.6132,1.745596177,462.3145036
,98,93.4751718,3.039059379,277568.7263,1.749522695,464.2801294
,98.2,94.10744321,3.069515961,279631.9203,1.743414578,466.2106891
,98.4,95.20151396,3.10024826,281772.2023,1.738179,468.6003367
,98.6,95.54659287,3.131338632,283775.298,1.73294349,470.5122664
,98.8,96.63723619,3.162692165,288036.8664,1.718545825,473.2360905
,99,97.01799816,3.194407609,290981.1125,1.712001443,475.8284254
,99.2,97.97539532,3.226403541,292677.2099,1.710692488,477.9156687
,99.4,98.29281151,3.258763041,293457.4479,1.714182779,479.9525047
,99.6,99.31002124,3.291401616,292828.2082,1.725526223,482.0452273
,99.8,99.93856082,3.324393768,291934.9962,1.735997122,483.5791595
,100,101.136244,3.357679756,292247.1433,1.74166878,485.7113296
,100.2,101.6689794,3.391344325,292991.7732,1.74385018,487.5597134
,100.4,102.5012381,3.425327126,294453.2382,1.742541235,489.551634
,100.6,103.3167993,3.459652534,296818.9658,1.737741974,491.9851052
,100.8,103.855197,3.494340937,297921.5645,1.738178215,493.864169
,101,104.9652319,3.529340261,297405.1873,1.747776487,495.8889635
,101.2,106.0818681,3.564691023,296965.2012,1.755629599,497.4897379
,101.4,106.5318891,3.600441035,296338.4274,1.763919062,499.0006589
,101.6,107.4112175,3.636704775,295701.2268,1.773081063,500.7920749
,101.8,108.6134233,3.672946721,296361.7768,1.774826109,502.398329
,102,109.5184615,3.709755811,298913.4483,1.768717971,504.6356796
,102.2,110.4650488,3.746932036,300683.4701,1.765663857,506.5421408
,102.4,111.4323807,3.784480417,302366.2705,1.76348232,508.4650373
,102.6,111.8096526,3.822444971,305280.7578,1.756501653,510.8776863
,102.8,113.0589653,3.86073338,307195.4215,1.752574932,512.830169
,103,114.0635623,3.89942268,309190.4613,1.749520814,515.2504971
,103.2,114.8708762,3.938513789,311076.2468,1.746030424,517.3465059
,103.4,115.9818651,3.977977559,313357.0176,1.740794849,519.522503
,103.6,116.9363453,4.017848208,314608.8999,1.741667341,521.9559766
,103.8,117.4846688,4.058146296,315620.9646,1.74297616,523.8218953
,104,118.5064257,4.09881797,316063.8221,1.748647828,526.0099433
,104.2,119.3541966,4.139909832,316074.8161,1.755192091,527.7991689
,104.4,120.2651458,4.18141036,315485.4866,1.765662952,529.8382049
,104.6,120.8980881,4.223346177,315509.754,1.770898365,531.4170614
,104.8,121.9279025,4.265677189,315672.283,1.776133741,533.3958391
,105,123.3279592,4.308409116,316768.1191,1.775261032,535.1138547
,105.2,123.9702683,4.351620643,318746.8719,1.770461791,537.0772875
,105.4,125.4696303,4.395210982,322053.3518,1.760863289,539.8066006
,105.6,126.7525617,4.439252784,324974.5185,1.752137386,541.9661654
,105.8,127.6197602,4.483764309,328365.5034,1.743411523,544.6373988
,106,128.5056112,4.528721607,331729.1799,1.735994527,547.4587376
,106.2,129.1700365,4.574145088,333113.5905,1.735121891,549.2337187
,106.4,130.4892971,4.619980552,334958.2203,1.735558061,552.0167157
,106.6,131.6749234,4.666284237,334558.5561,1.745156312,554.252977
,106.8,132.5717172,4.713072228,334104.066,1.753009434,555.9545528
,107,133.5266872,4.760326468,333385.2001,1.763043995,558.004547
,107.2,134.568126,4.808049803,333478.7609,1.768715655,559.9756567
,107.4,135.2816187,4.856274246,334299.3737,1.770024458,561.7703599
,107.6,136.6291379,4.904941369,336864.7758,1.764788863,564.2827311
,107.8,137.8500914,4.954105831,339348.9205,1.759116994,566.4433933
,108,139.1358746,5.003759937,342190.7493,1.75344512,569.0346514
,108.2,140.4124246,5.053913503,344072.7647,1.751263558,571.2698198
,108.4,141.4658765,5.104585748,345786.6722,1.749954595,573.462254
,108.6,142.2787542,5.155782899,347613.3642,1.749518227,576.1093836
,108.8,143.1697728,5.207489336,348777.7876,1.749954438,578.1265096
,109,144.8537538,5.259662956,350905.999,1.747772836,580.8404891
,109.2,145.2627879,5.31244473,353018.2932,1.74428249,583.1512446
,109.4,146.6320461,5.365693442,355252.893,1.741664629,586.0690122
,109.6,147.6783425,5.41949853,356590.1969,1.741228245,588.1726999
,109.8,148.8435512,5.473836263,357474.4732,1.744718448,590.8154522
,110,150.1992369,5.528707521,356901.1035,1.752571519,592.6244112
,110.2,151.4000538,5.58414027,356949.5844,1.75867945,594.6700322
,110.4,152.8188069,5.64011564,357759.4747,1.763042204,597.1188588
,110.6,153.9969775,5.696669112,358854.8156,1.764350961,599.0790161
,110.8,155.2591055,5.753785273,361019.6976,1.762169401,601.619876
,111,156.3688576,5.811485367,364314.8145,1.754316105,604.0259666
,111.2,157.4685316,5.869765898,366335.8908,1.752134561,606.3893259
,111.4,158.4749111,5.928638007,368383.4451,1.750825603,609.2062892
,111.6,159.9338892,5.98807177,369439.3092,1.753443199,611.8085113
,111.8,161.1905584,6.048116106,370218.9536,1.756060814,613.895767
,112,162.2465822,6.10877684,371648.7741,1.757369582,616.4804506
,112.2,163.7269084,6.170019132,374317.4542,1.752570273,618.9665321
,112.4,164.8734422,6.231898749,376525.5157,1.749952437,621.455894
,112.6,165.9924161,6.294401896,380114.8837,1.742535433,624.5588281
,112.8,167.3376363,6.357518046,382278.9397,1.739481292,627.0284725
,113,168.6727698,6.421268962,384028.8984,1.73948117,629.933095
,113.2,170.1034993,6.48565409,385201.801,1.741226192,632.4257509
,113.4,171.4858608,6.550689192,386560.6057,1.742098641,634.9184062
,113.6,173.2068055,6.616355437,388422.5684,1.742534772,637.8208448
,113.8,174.2219777,6.682727936,391019.7669,1.738608085,640.3244509
,114,175.8495099,6.749726976,393485.119,1.736426496,643.4580732
,114.2,177.4619562,6.817400128,395316.2307,1.735117485,645.9605928
,114.4,178.7514182,6.88577449,397948.7812,1.731627063,648.7709906
,114.6,180.3120533,6.954818026,400083.4143,1.731190632,651.9133781
,114.8,181.7286153,7.024564743,402088.3646,1.731190503,654.9538664
,115,182.9128947,7.09502746,405162.2764,1.726391228,657.6415477
,115.2,184.4007978,7.166178052,408727.976,1.720719351,660.7203853
,115.4,185.7179956,7.23805481,410125.1995,1.724209534,664.0336924
,115.6,187.6483764,7.310613194,411479.5955,1.725518222,666.498969
,115.8,189.1134667,7.383931434,413398.879,1.726826952,669.6972341
,116,190.6566623,7.457981184,413082.8761,1.734243703,671.9499455
,116.2,191.9892045,7.532788807,412054.8833,1.744714485,674.1862175
,116.4,193.4714149,7.60833808,414020.0862,1.745586924,677.3746228
,116.6,194.9543367,7.684646296,415680.4713,1.746895651,680.4107323
,116.8,196.5186876,7.761715851,417218.2832,1.746895507,682.8540892
,117,198.0221681,7.839563842,421435.0034,1.738605905,686.2397152
,117.2,199.3149892,7.918207672,426439.2279,1.726826023,689.5376858
,117.4,200.9355532,7.997619962,429948.4844,1.72071785,692.7600607
,117.6,202.7432249,8.077817894,433780.8677,1.714609662,696.5193149
,117.8,204.1604882,8.158847296,436248.1887,1.711991809,699.5422756
,118,205.7623601,8.240678768,438164.6604,1.712864239,703.0802027
,118.2,207.2026634,8.323342922,437837.5469,1.720280994,705.7996672
,118.4,208.7285463,8.406832069,439305.2473,1.722026004,708.779901
,118.6,210.439034,8.491147682,442891.4605,1.718971838,712.4712227
,118.8,212.2692168,8.576302734,446171.429,1.715481374,715.4788549
,119,213.4876308,8.662353712,449998.7153,1.711990966,719.2611089
,119.2,215.3540848,8.749666217,453410.5954,1.708936787,722.6587982
,119.4,216.831923,8.837004685,454009.3229,1.714172099,725.5908229
,119.6,218.6673773,8.925638333,452773.6383,1.725515397,728.7266489
,119.8,220.5101793,9.015162199,451344.0732,1.736858692,731.6444372
,120,222.123996,9.105600615,449773.4478,1.747329432,733.8445621
,120.2,223.8749734,9.196938496,449874.253,1.752564714,736.4117387
,120.4,225.6432799,9.289193183,453651.0925,1.748201681,740.0723863
,120.6,227.0419631,9.382399054,456475.2466,1.74558383,742.9441496
,120.8,229.027165,9.47650269,458770.7504,1.746019934,746.2311822
,121,230.590315,9.571579677,460481.2993,1.746456077,748.8991565
,121.2,232.725834,9.667574127,460058.4628,1.755617901,752.2026278
,121.4,234.9127929,9.76452995,458156.7866,1.766524866,754.1978768
,121.6,236.8524475,9.86247613,457984.8549,1.773068985,757.0148706
,121.8,238.7578271,9.961408846,460168.5202,1.770451086,759.590817
,122,240.6330911,10.06133736,465066.0971,1.760852606,763.205453
,122.2,242.2668712,10.16228575,470916.5119,1.748200144,766.6666914
,122.4,244.1900789,10.2642287,477274.7901,1.734675085,770.2298303
,122.6,246.3219937,10.36718289,482519.459,1.725949161,774.3758702
,122.8,247.8100738,10.47121732,485013.0531,1.725512738,778.1055434
,123,249.8076806,10.5762634,485624.1865,1.729439133,781.0036188
,123.2,251.7847318,10.68236549,486003.8059,1.734238102,783.8918336
,123.4,253.7882423,10.78953146,487358.5763,1.737728208,787.6861633
,123.6,255.8802058,10.89776724,491516.0395,1.731183722,791.0641434
End Of Loading Marker,123.792,257.6422942,11.00271152,497785.4149,1.720276406,795.5542113
,124,259.4685686,11.00534165,502974.3284,1.711114232,799.0998255
,124.2,260.4926327,11.00527516,506547.1138,1.707187566,802.8426395
,124.4,261.2836944,11.00522397,510823.2417,1.703697211,807.5803093
,124.6,262.5099711,11.0051442,509344.1294,1.716349394,811.0601692
,124.8,263.2852218,11.00509404,507187.6739,1.729437909,813.5999355
,125,264.0429973,11.00504504,504092.0738,1.746452995,816.5418121
,125.2,264.2573781,11.00503171,503247.2871,1.755178698,819.1319678
,125.4,264.7338865,11.00500116,502537.7593,1.76346809,821.7856782
,125.6,265.3859788,11.0049591,504922.4597,1.763031746,825.3016808
,125.8,265.7226857,11.00493773,507691.0464,1.759977713,828.2621742
,126,266.0069672,11.00491981,511493.5037,1.755614828,831.9907273
,126.2,266.6598916,11.00487769,513859.3572,1.755178479,835.1407782
,126.4,267.0781493,11.00485097,515418.2889,1.756923586,838.142909
,126.6,267.324984,11.00483551,516140.943,1.762595283,841.549336
,126.8,267.7016342,11.00481153,516769.0536,1.768266969,844.7125286
,127,268.1548422,11.00478252,516960.2057,1.773502353,847.18655
,127.2,268.1337243,11.00478465,516827.2017,1.779610364,849.7021953
,127.4,268.5062137,11.00476093,517574.9813,1.78440947,852.9344171
,127.6,268.5982682,11.00475563,517695.0473,1.79008118,855.8291661
,127.8,268.8193062,11.00474187,517692.196,1.794880305,858.1716991
,128,269.3365898,11.00470865,519232.8663,1.796189115,861.2242342
,128.2,269.4269801,11.00470346,521881.8951,1.793571392,864.0039392
,128.4,269.6788076,11.00468767,524129.9121,1.792262512,866.8515774
,128.6,269.715108,11.00468603,528820.9677,1.784845649,870.4519323
,128.8,270.0559757,11.00466439,533329.8789,1.776992471,873.5789677
,129,270.097269,11.00466243,538277.5487,1.769575608,877.5847188
,129.2,270.4239901,11.00464172,539892.2642,1.770448151,880.550691
,129.4,270.7423897,11.00462156,539936.3586,1.776119838,883.3435468
,129.6,270.7204396,11.00462375,537006.8834,1.790517276,885.8372811
,129.8,270.9572884,11.00460894,531357.4852,1.812767834,887.7799011
,130,271.0834611,11.0046014,525258.7942,1.834582117,888.748471
,130.2,271.2886881,11.00458867,520211.7007,1.854214963,890.4029285
,130.4,271.3141706,11.00458774,518569.0661,1.862068107,891.7714127
,130.6,271.3812606,11.00458408,516319.3326,1.872102677,893.3064404
,130.8,271.7470928,11.00456081,515797.349,1.876029215,894.6311105
,131,272.0288777,11.00454305,515867.5678,1.879083189,896.375415
,131.2,272.1334145,11.00453693,515888.7953,1.882573466,897.8195022
,131.4,272.2895446,11.00452742,516355.0463,1.885191167,899.5725709
,131.6,272.3208522,11.00452611,518690.8771,1.881264592,901.3135819
,131.8,272.6475732,11.00450541,522078.518,1.874720273,903.5520342
,132,272.5773583,11.00451076,526094.6393,1.865558279,905.7170657
,132.2,272.4513894,11.00451978,530730.1252,1.855087432,908.3039252
,132.4,273.0468951,11.00448142,532810.9356,1.852905945,910.8842325
,132.6,273.0565667,11.00448153,533976.3024,1.85246966,912.8093153
,132.8,273.5072782,11.00445268,533787.4337,1.856832475,914.9677839
,133,273.1982361,11.00447372,531237.3929,1.868175938,916.5718319
,133.2,273.45256,11.00445776,528809.8171,1.878210488,917.681748
,133.4,273.5862221,11.00444973,527106.4512,1.886499907,918.833292
,133.6,273.6549764,11.00444596,524250.7322,1.898715904,919.8413062
,133.798,273.776875,11.0044387,523148.0213,1.904823895,920.8164494
,134.5,273.8247407,10.91698221,1.7977E+308,1.922275328,0
,134.7,273.7470477,10.80698057,1.7977E+308,1.864249324,0
,134.9,273.2216577,10.69700832,1.7977E+308,1.720711339,0
,135.1,272.9384235,10.58702018,1.7977E+308,1.511294162,0
,135.3,272.7808441,10.47702378,1.7977E+308,1.24297838,0
,135.5,272.7788769,10.36701716,1.7977E+308,0.87649827,0
,135.7,272.3292125,10.25703994,1.7977E+308,0.548411325,0
,135.9,272.2456945,10.14703868,1.7977E+308,0.304527532,0
,136.1,272.1147439,10.03704054,1.7977E+308,0.128268045,0
,136.3,271.9629895,9.927043758,1.7977E+308,0.015706291,0
,136.5,271.8437765,9.816494805,1.7977E+308,0.022686865,0
,136.7,271.324124,9.707072217,1.7977E+308,0.02225058,0
,136.9,270.9144903,9.596542331,1.7977E+308,0.019632865,0
,137.1,270.8516886,9.487089748,1.7977E+308,0.012216005,0
,137.3,270.6566624,9.377095809,1.7977E+308,0.008289432,0
,137.5,270.4691255,9.267101379,1.7977E+308,0.00959829,0
,137.7,270.3573143,9.157101977,1.7977E+308,0.014397435,0
,137.9,269.9650683,9.047120986,1.7977E+308,0.010034576,0
,138.1,269.598619,8.937138302,1.7977E+308,0.005671717,0
,138.3,269.3178812,8.827149991,1.7977E+308,0.010034577,0
,138.5,269.1985807,8.71715108,1.7977E+308,0.017015152,0
,138.7,269.0984196,8.607150913,1.7977E+308,0.026613443,0
,138.9,268.8027031,8.497163585,1.7977E+308,0.028358587,0
,139.1,268.6908919,8.387164183,1.7977E+308,0.024432013,0
,139.3,268.5541162,8.27716642,1.7977E+308,0.023559442,0
,139.5,268.2467496,8.167179857,1.7977E+308,0.02704973,0
,139.7,267.8986075,8.057195971,1.7977E+308,0.028794874,0
,139.9,267.9082904,7.947188592,1.7977E+308,0.032285162,0
,140.1,267.6658315,7.837197767,1.7977E+308,0.036211736,0
,140.3,267.4375192,7.727206014,1.7977E+308,0.028794875,0
,140.5,267.2853487,7.617209261,1.7977E+308,0.020723585,0
,140.7,267.1693768,7.507210132,1.7977E+308,0.024868302,0
,140.9,266.7542466,7.397230644,1.7977E+308,0.028794876,0
,141.1,266.6382746,7.287231515,1.7977E+308,0.032285165,0
,141.3,266.3783405,7.177241838,1.7977E+308,0.031848879,0
,141.5,265.961962,7.067262432,1.7977E+308,0.030540022,0
,141.7,266.0132525,6.957252322,1.7977E+308,0.024432017,0
,141.9,265.6642782,6.84726849,1.7977E+308,0.014397439,0
,142.1,265.5042023,6.737272257,1.7977E+308,0.006544291,0
,142.3,265.0753415,6.62729367,1.7977E+308,0.006108005,0
,142.5,264.5291474,6.517322788,1.7977E+308,0.017887729,0
,142.7,264.7219035,6.407303389,1.7977E+308,0.025740877,0
,142.9,264.5143949,6.29731027,1.7977E+308,0.032721455,0
,143.1,264.1080022,6.187330208,1.7977E+308,0.039265747,0
,143.3,263.743217,6.077347415,1.7977E+308,0.047118897,0
,143.5,263.8219685,5.967335501,1.7977E+308,0.053663188,0
,143.7,263.3847861,5.857357461,1.7977E+308,0.055408334,0
,143.9,262.9942042,5.747376362,1.7977E+308,0.050172902,0
,144.1,262.7916885,5.637382915,1.7977E+308,0.040574608,0
,144.3,262.7214849,5.527380781,1.7977E+308,0.035775461,0
,144.5,262.204416,5.417407986,1.7977E+308,0.032721459,0
,144.7,262.1275551,5.307406289,1.7977E+308,0.037084321,0
,144.9,262.0606801,5.197403936,1.7977E+308,0.036211749,0
,145.1,261.8822968,5.087408905,1.7977E+308,0.033594032,0
,145.3,261.2695304,4.977442393,1.7977E+308,0.026613455,0
,145.5,260.9005844,4.867459873,1.7977E+308,0.023559452,0
,145.7,260.6290001,4.75747096,1.7977E+308,0.024432025,0
,145.9,260.6012362,4.64746604,1.7977E+308,0.030103745,0
,146.1,260.3130089,4.53747822,1.7977E+308,0.02966746,0
,146.3,260.0663891,4.427487669,1.7977E+308,0.024868312,0
,146.5,259.8039585,4.317498156,1.7977E+308,0.019196592,0
,146.7,259.4241945,4.207516346,1.7977E+308,0.016142589,0
,146.9,258.9953335,4.09753776,1.7977E+308,0.022686883,0
,147.1,259.1190212,3.987522896,1.7977E+308,0.029231176,0
,147.3,258.8515976,3.87753371,1.7977E+308,0.036648042,0
,147.5,258.4402118,3.767553976,1.7977E+308,0.038829473,0
,147.7,258.1453272,3.657566594,1.7977E+308,0.040138333,0
,147.9,257.7222913,3.547587625,1.7977E+308,0.041883479,0
,148.1,257.5580545,3.437591665,1.7977E+308,0.041447193,0
,148.3,257.027671,3.327619744,1.7977E+308,0.0349029,0
,148.5,257.0198787,3.217613512,1.7977E+308,0.034466614,0
,148.7,256.4861666,3.10764181,1.7977E+308,0.029667466,0
,148.9,256.5216462,2.997632737,1.7977E+308,0.020941741,0
,149.1,256.1452107,2.887650709,1.7977E+308,0.011779729,0
,149.3,255.7687752,2.777668681,1.7977E+308,0.003926577,0
,149.5,255.2209165,2.667697907,1.7977E+308,0.004799149,0
,149.7,255.3421077,2.557683207,1.7977E+308,0.004362863,0
,149.9,254.7767737,2.447713581,1.7977E+308,0.003054004,0
,150.1,254.744849,2.337708934,1.7977E+308,0.003054004,0
,150.3,254.5256902,2.227716579,1.7977E+308,0.004362863,0
,150.5,254.1933587,2.117731655,1.7977E+308,0.010470872,0
,150.7,253.7853014,2.007751703,1.7977E+308,0.023123176,0
,150.9,253.4804309,1.897764976,1.7977E+308,0.030103758,0
,151.1,252.9800048,1.787791089,1.7977E+308,0.032721477,0
,151.3,252.8756828,1.677791195,1.7977E+308,0.029667472,0
,151.5,252.7164389,1.567794907,1.7977E+308,0.023123177,0
,151.7,251.9039558,1.457841507,1.7977E+308,0.011343446,0
,151.9,251.9544141,1.347831451,1.7977E+308,0.002617718,0
,152.1,251.306697,1.237867234,1.7977E+308,0.003926578,0
,152.3,251.0792166,1.127875426,1.7977E+308,0.009162014,0
,227.5,250.6588785,1.024225789,1.7977E+308,0.014833741,0
,227.7,250.2982537,0.914242723,1.7977E+308,0.014397455,0
,227.9,250.0674446,0.804251134,1.7977E+308,0.012216023,0
,228.1,249.8849003,0.694256375,1.7977E+308,0.003490292,0
,228.3,249.2176274,0.584293442,1.7977E+308,0.014397456,0
,228.5,248.8665723,0.474309747,1.7977E+308,0.027486053,0
,228.7,248.1015215,0.364353234,1.7977E+308,0.037084359,0
,228.9,247.5561588,0.254382296,1.7977E+308,0.046246378,0
,229.1,246.5955522,0.144438622,1.7977E+308,0.047555241,0
,229.3,245.4768366,0.034505328,1.7977E+308,0.043192377,0
,229.358,245.1623199,0.002624022,1.7977E+308,0.041883518,0
END,,,,,,