File: GB1_test 14.csv
Segment,Time On Sample,Displacement Into Surface,Load On Sample,Harmonic Contact Stiffness,Harmonic Displacement,Harmonic Load
Surface Marker,0,0,0,-304.1713677,0.352453406,2.217838711
,0.3,0.251039571,0.000967672,8657.936399,0.177535315,2.316458036
,0.6,0.536190975,0.001933111,16466.9769,0.153980258,2.409598511
,0.9,0.737310778,0.002904051,19280.39816,0.144819958,2.664912966
,1.2,0.542400478,0.003900916,22416.45579,0.133914842,2.882971209
,1.5,0.806751978,0.004867716,26437.76064,0.122573518,3.133902594
,1.8,0.499522215,0.005871934,33550.31906,0.111232198,3.626999129
,2.1,0.94857683,0.006826643,40448.32482,0.105997739,4.181458856
,2.4,0.981633437,0.007808585,40743.96657,0.120392494,4.806047841
,2.7,1.132833642,0.00878175,42788.16959,0.133914838,5.628971241
,3,1.31564977,0.009752361,46023.74035,0.146564773,6.67433599
,3.3,1.063331995,0.010751458,49809.26953,0.156597482,7.753669533
,3.6,1.350979618,0.011715207,51081.08448,0.173173258,8.884504389
,3.9,1.077861943,0.012715666,48063.77341,0.218102343,10.49747797
,4.2,1.375909516,0.013678734,43411.87693,0.280697711,12.10716441
,4.5,1.30663086,0.014665849,40530.73645,0.341548265,13.65877491
,4.8,1.047241117,0.015665408,39850.88891,0.387785967,15.25202459
,5.1,0.693835821,0.016671122,39010.52797,0.441439154,16.95594699
,5.4,0.771820456,0.017648596,34536.21839,0.549181711,18.61384723
,5.7,0.217904108,0.018667436,29801.14127,0.676553505,19.74029863
,6,0.443152044,0.019635269,23977.76402,0.878516274,20.65636253
,6.3,-0.144460155,0.020656314,19438.82749,1.106215167,21.27437656
,6.6,0.778832458,0.021578452,16025.02527,1.341765645,21.52969151
,6.9,1.00990436,0.022545904,14541.09136,1.486149381,21.83760312
,7.2,1.047953186,0.023525993,14566.01827,1.511013046,22.30768843
,7.5,1.089329997,0.024505863,16291.72197,1.416356626,23.28621128
,7.8,1.066643115,0.025489927,19187.54945,1.2741539,24.46635559
,8.1,1.288563057,0.026457979,22076.03974,1.173390602,25.68266065
,8.4,1.168532643,0.027448416,23349.30789,1.157687242,26.72583372
,8.7,1.462836236,0.028411729,22993.13397,1.206105943,27.49287307
,9,1.368597699,0.029400478,21798.55411,1.290729658,28.11198303
,9.3,1.393334589,0.030381438,20983.84174,1.356596564,28.70698632
,9.6,1.070297151,0.031385164,20295.38638,1.411994586,29.19241218
,9.9,1.765622811,0.032322226,19847.30385,1.458232226,29.72605289
,10.2,1.417625499,0.033327586,19610.57807,1.496618268,30.22462795
,10.5,1.870008324,0.034280552,19549.93689,1.526716353,30.68594761
,10.8,2.225879607,0.035239835,20009.77544,1.525843913,31.17575711
,11.1,2.197368755,0.036224281,21117.4599,1.489202725,31.80472919
,11.4,2.392664815,0.037194077,23137.88915,1.409813461,32.61121614
,11.7,2.358329992,0.038178904,25553.45051,1.322136328,33.47577883
,12,2.303195269,0.039165094,28137.12162,1.242310879,34.47402538
,12.3,2.208956737,0.040153843,30005.24796,1.19869042,35.43172845
,12.6,2.034846591,0.04114782,30755.45833,1.195200795,36.20753344
,12.9,2.35827003,0.042109228,30871.81416,1.22006444,37.07757542
,13.2,1.975328898,0.043116876,30670.80964,1.25583325,37.82489019
,13.5,2.14816107,0.044088142,29901.33691,1.310358822,38.46810755
,13.8,2.333473179,0.045058591,29000.30993,1.368810234,39.02256724
,14.1,2.711808345,0.046016404,27737.08982,1.44514602,39.50251513
,14.4,2.65750562,0.047002539,27474.0794,1.477425169,40.04492116
,14.7,2.752130168,0.047978925,27848.86314,1.479606185,40.62896693
,15,2.534756237,0.048975735,29435.1224,1.429006464,41.44860266
,15.3,2.715075848,0.049949784,31182.97535,1.379715324,42.32302761
,15.6,2.397030927,0.050949911,32724.30967,1.343946568,43.21936705
,15.9,2.920133385,0.051898248,33455.53471,1.3413293,44.08393047
,16.2,2.503912426,0.052908075,33585.08783,1.357468905,44.82467044
,16.5,2.917191419,0.053863601,33512.52349,1.379279107,45.52377248
,16.8,2.815464926,0.05485284,33457.33013,1.400216939,46.1713724
,17.1,2.950857274,0.055826558,33523.65479,1.419409934,46.91211324
,17.4,2.557932201,0.05683486,33825.74528,1.429878878,47.63641675
,17.7,2.828939889,0.057799699,34205.06586,1.435549517,48.31469902
,18,2.626541886,0.058795529,34495.77016,1.446454651,49.03133219
,18.3,2.850125805,0.059763473,34627.34392,1.46390282,49.81699991
,18.6,2.622767923,0.060760936,34708.10696,1.476988979,50.39008718
,18.9,3.107598565,0.061711778,34746.47,1.49400092,51.07384864
,19.2,2.801201072,0.062714416,34628.14521,1.51581118,51.70172435
,19.5,3.127120489,0.063675661,34379.66974,1.541983432,52.28029154
,19.8,2.74417937,0.064683309,33823.7704,1.579060862,52.75366356
,20.1,3.813071138,0.065595917,33094.59024,1.625298458,53.18759026
,20.4,3.099827652,0.066625189,32692.53559,1.65714146,53.61384378
,20.7,3.652049951,0.06757162,32939.56991,1.659322436,54.07735539
,21,3.418036112,0.06856952,34349.14107,1.614393375,54.78083948
,21.3,3.36955736,0.069555274,36076.88139,1.560304016,55.51062235
,21.6,3.35103046,0.070539067,38132.5627,1.504906022,56.42011156
,21.9,3.555478466,0.071508264,38959.80243,1.496181917,57.23755644
,22.2,3.471639888,0.072496333,38804.5345,1.51886456,57.86324107
,22.5,3.645719722,0.073469531,38420.72695,1.54809026,58.44728693
,22.8,3.960404805,0.074446463,39023.61257,1.541110957,59.13214374
,23.1,4.10120038,0.07544964,39954.95426,1.525843787,59.9254816
,23.4,3.775659815,0.076498709,41385.48277,1.497272406,60.8349703
,23.7,3.886914613,0.077534802,42439.79472,1.482223342,61.70610789
,24,3.878359501,0.078594471,43198.16065,1.476988888,62.5651916
,24.3,4.15933642,0.079651154,43804.62106,1.476988865,63.4111268
,24.6,3.829625774,0.080764054,43906.28291,1.489638828,64.0959824
,24.9,4.160517232,0.081850279,43907.03885,1.509268009,64.90027845
,25.2,4.174415611,0.082973893,43440.07457,1.541547151,65.56321925
,25.5,4.152535472,0.084116795,43352.38697,1.560303953,66.23930962
,25.8,3.883549802,0.08529318,43453.07927,1.573826322,66.99100723
,26.1,4.102110967,0.086455008,43902.32559,1.574262508,67.74380201
,26.4,4.328157281,0.087634031,44400.74523,1.573826284,68.48125564
,26.7,4.477657145,0.088835855,44886.31636,1.572953862,69.18912354
,27,4.429139066,0.09006903,45553.03726,1.570336639,70.07669715
,27.3,4.595272964,0.091306773,46000.51697,1.572081444,70.82949176
,27.6,4.522621076,0.092578829,46401.43134,1.57382627,71.50448587
,27.9,4.564781554,0.093862651,46503.36119,1.587784815,72.27371689
,28.2,4.331548318,0.095183869,46607.89802,1.599562361,72.96295563
,28.5,4.67155711,0.096487255,46593.4547,1.614393288,73.63795101
,28.8,4.692908294,0.097831557,46755.53916,1.621808766,74.2910299
,29.1,4.857359565,0.099186627,46739.07759,1.63489489,74.94191779
,29.4,4.534257972,0.100594291,46546.14495,1.653215515,75.52596252
,29.7,4.930829497,0.101975646,46339.17441,1.673717095,76.12973301
,30,4.715880703,0.103418166,46476.36124,1.683313618,76.71158634
,30.3,4.960190173,0.10485233,46901.54788,1.682441187,77.32631396
,30.6,4.924945571,0.106326583,47911.04912,1.663248188,78.06157548
,30.9,5.714205349,0.107768867,48903.99503,1.647108544,78.87683052
,31.2,5.09073263,0.109326045,50531.0201,1.613084644,79.78631834
,31.5,5.311732029,0.110850964,52239.80535,1.579933075,80.74950098
,31.8,5.526071809,0.112399279,54050.38305,1.545909098,81.75870565
,32.1,5.553208791,0.113983347,55509.07339,1.524098866,82.83475228
,32.4,5.474678484,0.115598343,55787.49045,1.532822966,83.76286938
,32.7,5.783022377,0.117212307,55516.24958,1.556377988,84.66030611
,33,5.432420758,0.1188997,54963.13397,1.586912342,85.43391859
,33.3,5.912148774,0.12054659,54763.26186,1.606541506,86.18013964
,33.6,5.813634753,0.122262396,54682.65241,1.621808677,86.87266594
,33.9,5.859883919,0.123994433,54691.32226,1.635331016,87.65066323
,34.2,5.970192616,0.12574836,55140.16279,1.636203415,88.45605427
,34.5,6.318447891,0.127513266,55692.54342,1.634458565,89.29322389
,34.8,6.414604166,0.129321537,56212.51195,1.633586148,90.07341229
,35.1,6.938401989,0.131128753,56506.00737,1.639692964,90.88647532
,35.4,7.712626217,0.132946611,56708.78687,1.64710837,91.65789933
,35.7,7.728897851,0.134842171,57888.97951,1.630096392,92.67367871
,36,7.671117312,0.13677122,59796.58512,1.595636239,93.79903435
,36.3,7.903698666,0.138710308,62380.61866,1.550270946,95.0679371
,36.6,7.578838209,0.140715268,64602.24216,1.515374612,96.22945279
,36.9,7.821394084,0.142713024,66752.71474,1.489202319,97.66820003
,37.2,7.771082622,0.144760391,68226.80321,1.477424801,98.98312384
,37.5,8.262395529,0.14680279,68807.59394,1.483531624,100.2377824
,37.8,8.309417754,0.148905515,69167.37261,1.496181552,101.5625686
,38.1,8.410514627,0.151036611,69682.13267,1.500979799,102.6506691
,38.4,8.372663123,0.153208852,70616.38273,1.50054359,103.9568272
,38.7,8.681748619,0.155391134,72349.26501,1.487021232,105.4777574
,39,8.440463693,0.157642581,73918.47651,1.476552337,106.9318438
,39.3,8.744546597,0.159891991,75271.75326,1.470881661,108.3968896
,39.6,8.734961697,0.162196062,75964.66971,1.477860929,109.8860414
,39.9,8.670459524,0.164538699,75846.87498,1.496181529,111.0683774
,40.2,8.873022381,0.166898987,75420.18645,1.521481373,112.3350885
,40.5,9.081403526,0.169294635,74681.19437,1.552015675,113.4549666
,40.8,8.894996952,0.171752411,74783.30905,1.565538026,114.6044289
,41.1,8.967751139,0.174230304,75142.07314,1.575134524,115.8667567
,41.4,8.656117345,0.176770929,76206.75395,1.570336302,117.1904461
,41.7,9.364504221,0.179282773,76784.89121,1.573825876,118.3881254
,42,8.890619104,0.181910591,77657.9931,1.573389715,119.721676
,42.3,9.603153619,0.184499737,77849.08947,1.585603381,120.9598991
,42.6,9.387174639,0.187189478,78306.8248,1.590837853,122.0732009
,42.9,9.857585666,0.189874611,78657.20111,1.60043431,123.3859357
,43.2,9.515962425,0.192653856,78758.50085,1.611339455,124.4225329
,43.5,9.805817264,0.195433413,78636.65346,1.6279152,125.5577521
,43.8,9.80862689,0.198273992,77710.18504,1.658013311,126.4256022
,44.1,10.16918787,0.201133775,77052.17279,1.683749343,127.3350932
,44.4,9.788433837,0.204085427,77224.09977,1.692037266,128.2982735
,44.7,10.3519878,0.207019671,78089.98677,1.687238963,129.3129593
,45,10.28321798,0.210039935,79305.01306,1.677642472,130.4810498
,45.3,10.583015,0.21308151,79823.19251,1.681568285,131.5483317
,45.6,10.57413432,0.216189439,80288.29212,1.684185513,132.4895981
,45.9,10.71833337,0.219334234,80695.25157,1.689419954,133.5700284
,46.2,10.6811498,0.222538587,81376.51998,1.689419959,134.6548404
,46.5,10.89438926,0.225774601,81811.54134,1.692473371,135.5555648
,46.8,10.88547812,0.22907414,82521.34577,1.692909577,136.7105065
,47.1,11.22017325,0.232400919,82817.0312,1.697707795,137.6123271
,47.4,11.3243976,0.235793059,83354.38483,1.699016399,138.6565964
,47.7,11.9993628,0.239198934,84283.38181,1.694218085,139.8772876
,48,12.29076977,0.24268186,85364.3199,1.685057765,140.9204617
,48.3,12.52642468,0.246220957,86929.21845,1.669790588,142.2047059
,48.6,12.50165647,0.249830753,87725.32254,1.669354387,143.4308727
,48.9,13.49940212,0.253427814,87893.5726,1.679823199,144.5880105
,49.2,13.67346356,0.257133264,88067.45664,1.687674862,145.5446184
,49.5,13.70690886,0.260903906,88996.18881,1.68374902,146.7412002
,49.8,13.71621724,0.264733065,90667.72844,1.666737048,148.0462627
,50.1,14.09076244,0.268596103,92206.47198,1.654523291,149.4565211
,50.4,13.75643608,0.272577446,93396.55506,1.648852666,150.8393818
,50.7,14.1026746,0.276560848,94192.19936,1.649288838,152.0786999
,51,13.97966021,0.280621973,95754.70768,1.639256149,153.587575
,51.3,14.53887021,0.284713136,97107.71179,1.631840624,155.065772
,51.6,14.58140122,0.288899942,98004.89975,1.630532007,156.3817923
,51.9,14.83691301,0.293135966,98678.90477,1.635330233,157.8961484
,52.2,14.78124829,0.297456673,99434.25906,1.636202647,159.1409431
,52.5,15.2031386,0.301811135,101340.1181,1.622680273,160.7966546
,52.8,14.97107007,0.30627415,103040.4279,1.613083799,162.5750889
,53.1,15.68829762,0.310742156,103881.4386,1.61264753,163.9404221
,53.4,15.33972826,0.315347923,103038.1141,1.637075008,165.2630155
,53.7,15.88387896,0.3199644,101766.732,1.666736854,166.3324904
,54,15.6001831,0.324705208,100894.5506,1.691600531,167.4096308
,54.3,16.2973985,0.329452852,100865.0302,1.705122799,168.5645769
,54.6,16.39972577,0.334311336,101636.9924,1.706867608,169.8334795
,54.9,17.29160503,0.339191023,102570.5099,1.703814092,171.0202033
,55.2,17.08191063,0.344217305,103781.4888,1.697271048,172.3899154
,55.5,17.42964111,0.349282472,104533.6822,1.697271017,173.750864
,55.8,17.63924818,0.35443335,104812.8535,1.704250265,174.929914
,56.1,18.06266568,0.359647947,105354.3341,1.708176064,176.2075847
,56.4,17.75058676,0.364989857,107199.7713,1.694217554,177.6978311
,56.7,17.98303593,0.370376838,109356.5428,1.675024546,179.227528
,57,18.00913732,0.375858746,111579.6074,1.658012574,180.9632288
,57.3,18.4137834,0.381398696,112153.8069,1.663246993,182.4742984
,57.6,18.20149163,0.387063034,111942.8259,1.677641753,183.6588253
,57.9,18.73215809,0.39276393,111762.5467,1.693345059,185.039499
,58.2,18.41375963,0.398606962,112019.4595,1.701196762,186.3346981
,58.5,18.57540847,0.404506403,112293.0716,1.707739817,187.4775877
,58.8,19.03822543,0.410475142,113037.8584,1.710356995,188.9404439
,59.1,19.62624336,0.416525697,113854.8394,1.71122935,190.3287884
,59.4,19.3040439,0.422727776,115088.3811,1.706431135,191.7773954
,59.7,19.72147338,0.428974641,115664.5719,1.709484525,193.0528747
,60,19.75533804,0.435341072,116503.6965,1.709484523,194.4729934
,60.3,20.54796704,0.441753885,116473.9503,1.719517144,195.5873968
,60.6,20.5626651,0.44831482,116163.9769,1.733911884,196.8442454
,60.9,20.85772979,0.454956349,114753.9931,1.761392723,197.6638838
,61.2,20.94810773,0.461711617,113357.3946,1.789309786,198.4714669
,61.5,21.6158741,0.468530925,112514.1319,1.808938909,199.2220739
,61.8,21.61885993,0.475497067,113619.2418,1.801087233,200.2433318
,62.1,22.39475255,0.482517473,116474.3485,1.77055286,201.7116692
,62.4,21.92429956,0.489726065,120656.4766,1.726496283,203.5700934
,62.7,23.13778743,0.496932558,124111.2069,1.693780851,205.3540157
,63,22.79376309,0.504350717,126523.2498,1.677205125,207.2201106
,63.3,23.41982723,0.511816973,126598.6553,1.686801558,208.517507
,63.6,22.99007166,0.519465645,126312.1555,1.70337736,209.975975
,63.9,23.56035584,0.527163873,125641.5162,1.722570289,211.135304
,64.2,23.24870674,0.535036495,126718.0051,1.720825504,212.6606148
,64.5,23.81146557,0.542970411,128271.6882,1.712973774,214.3086576
,64.8,24.0056315,0.551048601,130034.0159,1.702504856,215.9358781
,65.1,24.58332776,0.559223426,131686.4834,1.694653126,217.6671997
,65.4,25.52458618,0.567497912,132593.6174,1.694653036,219.1201972
,65.7,25.78442078,0.575942438,134343.4117,1.687237542,221.0673835
,66,25.83623634,0.584528279,135399.1851,1.685492721,222.6288571
,66.3,26.65346666,0.593193345,136047.4768,1.689854685,224.2988176
,66.6,26.84168796,0.602030835,135786.3992,1.704685607,225.8011206
,66.9,27.23289482,0.610988336,135553.3658,1.719516508,227.2738387
,67.2,27.23221054,0.620107144,135865.1529,1.725187162,228.581093
,67.5,27.82138877,0.629324673,137557.602,1.716899228,230.3310433
,67.8,27.78072469,0.638723154,140061.2136,1.69945107,232.1511185
,68.1,28.44722859,0.648249105,142846.7301,1.68156664,234.2341828
,68.4,28.12364074,0.657952559,143955.3568,1.682875284,236.1287687
,68.7,28.56547013,0.667719084,143888.8998,1.694652752,237.6091585
,69,28.32586704,0.677711018,143652.6291,1.709483714,239.2232265
,69.3,29.17948115,0.687782029,143605.119,1.72126114,240.7353966
,69.6,28.84331846,0.69808359,144381.1191,1.72300599,242.2256429
,69.9,29.44395722,0.708478931,145063.528,1.727367973,243.9569647
,70.2,29.27747179,0.719081857,144956.2622,1.738709295,245.4417332
,70.5,30.11101866,0.72977907,144606.8429,1.752231538,246.7643345
,70.8,29.91120226,0.740706208,144608.2964,1.761828047,248.0639171
,71.1,30.94603987,0.75171697,145626.3817,1.76139174,249.6001954
,71.4,30.75116276,0.762975295,147545.8574,1.750922864,251.2526165
,71.7,30.93315225,0.774378709,149204.489,1.743071175,252.8842208
,72,30.69578904,0.785981821,150483.3815,1.740017771,254.5936219
,72.3,31.89691685,0.797665478,151851.4354,1.735219409,256.1430504
,72.6,32.62045163,0.80955687,153435.7549,1.729984891,257.9773765
,72.9,33.3614297,0.821626812,155128.2812,1.722569357,259.6911677
,73.2,33.31115187,0.833931269,156266.9779,1.721260742,261.5123384
,73.5,34.02627957,0.846371056,156094.0617,1.732165777,263.1636709
,73.8,33.80787943,0.859060271,155807.1943,1.743943301,264.5837888
,74.1,34.53126663,0.871879633,155934.53,1.752667311,266.0981496
,74.4,35.05161632,0.88490616,156153.0068,1.761827541,267.6026469
,74.7,36.18303467,0.898089352,156739.0684,1.765317062,269.055648
,75,35.97199818,0.911560239,158334.7009,1.759210226,270.7869648
,75.3,37.08796059,0.925146942,160154.0664,1.750922245,272.5928041
,75.6,37.1210495,0.939010617,162385.0834,1.738272326,274.3526128
,75.9,37.38664756,0.953068414,164041.6907,1.733910267,276.3271944
,76.2,37.56235647,0.96734446,166333.7264,1.72387756,278.413544
,76.5,38.1731643,0.981806715,168199.0012,1.716462036,280.1744531
,76.8,38.17491747,0.996527697,170157.9452,1.71122759,282.4503696
,77.1,38.63007224,1.011441154,170528.8561,1.7173344,284.1269033
,77.4,38.91213635,1.02659137,169274.2651,1.739144563,285.719061
,77.7,39.73579235,1.041935009,168378.8359,1.75615643,287.1227502
,78,39.897144,1.057554067,167757.3991,1.770987343,288.5702657
,78.3,40.32053636,1.073391773,169483.0964,1.763571837,290.3607593
,78.6,40.82875413,1.089462968,171668.2138,1.751794285,292.1622113
,78.9,41.77955423,1.105747742,175628.614,1.727802986,294.6211296
,79.2,42.43745316,1.122298214,177916.7842,1.719515051,296.8280187
,79.5,43.23175937,1.139089664,178906.0649,1.721259789,298.5724931
,79.8,43.45194929,1.156172483,179440.2822,1.728675231,300.6413113
,80.1,44.67215513,1.173447441,181387.2169,1.721695853,302.5797402
,80.4,44.95299808,1.191045358,183809.6159,1.712099345,304.9104492
,80.7,45.79872272,1.208872058,186485.462,1.699885562,307.2455454
,81,45.60274798,1.227036676,187038.4928,1.705992432,309.4568101
,81.3,46.82111949,1.24538242,187348.9576,1.71384398,311.5190628
,81.6,46.494434,1.264107383,188343.6134,1.717769845,313.6963578
,81.9,47.84833144,1.28300429,190342.5607,1.71253527,315.8057298
,82.2,48.01492804,1.302265135,192522.2807,1.707300811,318.2350566
,82.5,48.77718606,1.321777509,193557.9185,1.710354163,320.4277019
,82.8,49.13005619,1.341611748,193792.839,1.7190782,322.4285844
,83.1,50.48127128,1.361679973,194534.8116,1.724312511,324.5500097
,83.4,50.39808077,1.382145861,195737.6111,1.726493537,326.7941487
,83.7,51.01205195,1.402874904,197047.7803,1.726493477,328.861876
,84,51.2549041,1.423941626,198020.0893,1.729983082,331.0786236
,84.3,51.94947826,1.445296853,197297.0511,1.74568634,332.9129517
,84.6,52.07990939,1.467011693,198207.5513,1.747431141,334.7604244
,84.9,53.11549754,1.488994985,198581.044,1.754846497,336.8369208
,85.2,53.0320013,1.511384383,200776.4342,1.747431048,339.0668153
,85.5,53.90441208,1.534048781,203109.7487,1.740015503,341.4128709
,85.8,54.25178034,1.557090532,205656.3419,1.730855197,343.7402927
,86.1,55.32957107,1.580511507,208341.5387,1.72169482,346.2890682
,86.4,55.52458543,1.604186422,209977.9972,1.719949988,348.7940043
,86.7,56.77782604,1.628229193,210984.3374,1.721694679,351.056785
,87,56.79549846,1.652716682,212133.0252,1.723003288,353.4499507
,87.3,57.81649625,1.677507978,213866.7318,1.719513562,355.6469832
,87.6,58.29747066,1.70270959,215782.9151,1.717768702,358.2614999
,87.9,58.96807905,1.728279438,218325.1855,1.712534197,361.0612032
,88.2,59.59369838,1.754238446,219561.2833,1.716023763,363.5431328
,88.5,60.75006712,1.780554565,220519.5162,1.719077073,365.6788043
,88.8,61.45792819,1.807297923,220422.7904,1.731290696,368.1201912
,89.1,62.83631157,1.834401108,221039.3341,1.735652592,370.1386172
,89.4,63.01323153,1.861993138,222682.9525,1.734343966,372.5920522
,89.7,64.16767729,1.889937347,225727.151,1.725183585,375.558318
,90,64.86529168,1.918333561,227767.1163,1.720821486,377.9230023
,90.3,66.13275316,1.947121013,228699.4359,1.725619596,380.404938
,90.6,66.36015414,1.976411582,229189.5181,1.733907434,382.8211188
,90.9,67.27471107,2.006099249,230729.3664,1.733907344,385.1211544
,91.2,67.81812776,2.036259974,233208.4368,1.729109057,387.8562074
,91.5,69.11109756,2.066827659,234780.8761,1.729545135,390.488266
,91.8,69.09651685,2.097944083,235224.2921,1.736524382,392.7970576
,92.1,70.74043928,2.129421459,235251.1428,1.745684485,395.0576536
,92.4,70.77978778,2.161480107,236876.2739,1.744812074,397.5746427
,92.7,71.5774208,2.193972967,240791.7145,1.730417297,400.684453
,93,72.46275096,2.226951139,244338.1166,1.71863973,403.729614
,93.3,73.35632181,2.260426983,246888.6526,1.712969007,406.659719
,93.6,74.02143022,2.294423698,247428.0009,1.718639577,409.0430313
,93.9,75.82545509,2.328857851,248405.6007,1.723873838,411.9534232
,94.2,76.20086587,2.363906026,249448.2975,1.729108235,414.6205373
,94.5,77.51800808,2.399421609,251135.5503,1.729980511,417.3084809
,94.8,78.19942261,2.435515711,253258.2704,1.728235633,420.0380595
,95.1,79.38992985,2.472121465,256055.6272,1.72256488,423.118289
,95.4,79.75334862,2.509334793,257462.1904,1.72343725,425.6582945
,95.7,80.99110204,2.54705274,258735.0699,1.726490548,428.6793531
,96,81.44918795,2.585391931,258391.8782,1.738267978,431.2840108
,96.3,82.61936724,2.624263266,259526.517,1.740012673,433.6629464
,96.6,82.80021426,2.663787145,260648.271,1.74393848,436.4451159
,96.9,84.45858464,2.703810684,260558.2596,1.753970977,438.6542126
,97.2,84.67668023,2.74453408,261495.8823,1.758769185,441.2369526
,97.5,86.14765825,2.785790134,261185.8028,1.769674104,443.5216553
,97.8,87.35978753,2.827686559,262570.2631,1.770546387,446.1767278
,98.1,88.27313095,2.870235718,265570.3059,1.762258446,449.0158862
,98.4,89.39769815,2.913413543,269116.2011,1.750480864,451.6457555
,98.7,90.5271535,2.957243632,272850.9783,1.740884296,455.1029322
,99,91.25381945,3.001762414,274091.9418,1.742629034,457.5991124
,99.3,92.66593974,3.046908622,275185.2529,1.746118514,460.3988299
,99.6,93.47475744,3.092776715,278339.1308,1.739139195,463.6006891
,99.9,94.4714951,3.139325273,280926.1253,1.734777072,466.5198399
,100.2,95.54300019,3.186572093,283566.7576,1.731287347,469.7118411
,100.5,97.25502529,3.234490663,284605.9424,1.735649201,472.7405794
,100.8,97.6473965,3.283220226,284896.5674,1.743064603,475.3923568
,101.1,99.03637654,3.332620419,285333.044,1.750479904,478.2183723
,101.4,99.24048197,3.382844908,285364.8196,1.760512537,480.8580934
,101.7,100.8979559,3.433732469,286323.0281,1.764438192,483.3772976
,102,101.5527578,3.485455119,288280.5063,1.763129519,486.3063089
,102.3,102.7107902,3.537925859,291863.4647,1.753096751,489.5629606
,102.6,103.5508759,3.59121026,294705.7124,1.746989837,492.5204653
,102.9,105.3351437,3.645237398,297830.6664,1.741755233,495.974366
,103.2,106.7565334,3.700104914,299698.7169,1.7434999,499.1422674
,103.5,109.0031264,3.755746743,300335.2985,1.750042708,501.6592893
,103.8,108.8342851,3.812580193,298332.1867,1.771416627,504.2880484
,104.1,110.9699832,3.869738304,296893.5339,1.787555886,506.496061
,104.4,111.9740053,3.928027879,295643.0633,1.802386651,508.5900983
,104.7,113.6434802,3.987154349,298695.5908,1.794971047,511.2583297
,105,114.3227438,4.047239136,302488.3691,1.785374534,514.2914426
,105.3,115.7822704,4.108180642,304923.5149,1.781012367,516.8073577
,105.6,117.1700994,4.170047355,311608.8937,1.757457325,520.6195749
,105.9,118.9463193,4.232823399,318413.848,1.733029845,524.3704328
,106.2,120.0792595,4.296590515,328662.6706,1.69595258,529.3003367
,106.5,122.215427,4.361254835,335277.8642,1.677195698,534.071367
,106.8,123.3447306,4.426962733,336790.2929,1.681993809,538.0161694
,107.1,125.3208425,4.493607036,337372.1478,1.691153854,541.8886625
,107.4,126.5346912,4.561307716,336897.5534,1.705112189,545.4937786
,107.7,127.9205993,4.630019408,338925.366,1.706856861,549.1712159
,108,129.2605829,4.699771713,343838.3424,1.697260296,553.6310381
,108.3,130.7135496,4.770569826,347318.7919,1.693770542,557.9221098
,108.6,131.9442049,4.842451885,348035.9655,1.701622051,561.4680556
,108.9,133.9197343,4.915371914,343166.9863,1.733900764,564.5252952
,109.2,135.0589382,4.98945135,339192.3193,1.762253746,567.1683212
,109.5,136.7441654,5.064613923,338947.9764,1.770977603,569.650276
,109.8,138.7041844,5.140893971,343090.3983,1.762253377,573.5194864
,110.1,140.594133,5.218331385,347269.3294,1.752656759,577.1405029
,110.4,141.9426861,5.296974343,349432.5498,1.751784222,580.5171534
,110.7,143.3322338,5.376802727,352396.9421,1.750039276,584.4663469
,111,144.8592839,5.457828393,354879.7363,1.74873052,587.8966946
,111.3,146.7975583,5.540048896,358278.7889,1.744368313,591.5209998
,111.6,148.3916078,5.623532372,362330.6607,1.738261339,595.6915442
,111.9,150.3082685,5.708255785,365691.7088,1.733899138,599.4413169
,112.2,151.9776247,5.794275568,370866.38,1.724302553,603.8332106
,112.5,154.2225105,5.881557015,374553.1867,1.721248925,608.0738947
,112.8,155.5927662,5.970214928,376859.8044,1.723429794,611.9792608
,113.1,157.8472129,6.06015389,378174.3373,1.728663982,615.8671078
,113.4,159.3385097,6.151502024,382813.9303,1.72081222,620.4025473
,113.7,161.478538,6.244187626,386454.7898,1.7155776,624.6465179
,114,163.3146678,6.338293467,386462.5408,1.725173835,628.8181684
,114.3,165.533286,6.433795994,382126.2561,1.750473255,631.8732266
,114.6,167.0178609,6.530789679,376343.4349,1.782315751,634.6203624
,114.9,169.047155,6.629212879,379198.1933,1.777953538,637.7882828
,115.2,171.0670607,6.729123484,388741.8118,1.7504727,642.5538476
,115.5,173.7514846,6.8305,400859.9654,1.717321196,648.1565934
,115.8,175.4755506,6.93347145,407762.1324,1.704671214,653.2114382
,116.1,177.6328348,7.037970059,405552.9879,1.724300019,657.2033851
,116.4,179.0602145,7.144095505,402882.0303,1.743928893,660.7307151
,116.7,181.4374691,7.251761735,402296.8831,1.754397461,664.1802585
,117,183.2354015,7.361092957,407520.9558,1.744800876,668.7080392
,117.3,185.6121344,7.472037771,411148.4687,1.742183437,673.0177667
,117.6,187.3604502,7.584700086,413169.0461,1.744364263,676.7828876
,117.9,189.8007085,7.699019013,411265.2238,1.762248221,680.4329626
,118.2,191.5875821,7.815108242,410573.9738,1.77402544,683.8890746
,118.5,193.7202833,7.932928627,414331.0675,1.769663224,688.0037525
,118.8,196.0315785,8.052517259,418373.6777,1.76399239,692.1107672
,119.1,198.3675458,8.173911058,423782.3092,1.754395757,696.6111633
,119.4,200.5384878,8.29714995,425476.625,1.758321337,700.581204
,119.7,203.1317828,8.422222778,430502.4578,1.749597081,704.9271017
,120,204.8120879,8.549245338,434397.7,1.745671114,709.683901
,120.3,207.517095,8.678119516,440323.824,1.734329653,714.7332914
,120.6,209.7883273,8.808969231,444967.1713,1.728222633,719.3608035
,120.9,212.6965466,8.941753891,446728.3064,1.733892938,724.0716025
,121.2,214.7841082,9.076598931,446927.8235,1.744361516,728.3616128
,121.5,217.5343649,9.213900005,445496.4836,1.757011022,731.6829643
,121.8,219.7278397,9.352389366,446908.7642,1.760936594,736.2151456
,122.1,222.3427241,9.493410559,452720.8698,1.74915895,740.694733
,122.4,224.7966962,9.636573054,460497.5994,1.734327932,746.0805292
,122.7,227.598926,9.781875579,469927.2886,1.716443489,751.7128792
,123,229.8342244,9.929411023,476735.2246,1.708155486,757.597251
,123.3,233.0850221,10.07910842,478691.7379,1.713389555,762.8515688
,123.6,235.8196289,10.23110178,477915.1005,1.726911447,767.8922053
,123.9,238.681164,10.38538322,478963.0947,1.732145553,771.9608864
,124.2,241.3784271,10.54200638,484370.2351,1.7264747,777.4814749
,124.5,244.4064434,10.70097429,494743.4818,1.70640926,783.86225
,124.8,246.6728118,10.86239347,501726.4129,1.696812668,789.8551102
,125.1,250.0311878,11.02617853,504536.7665,1.700301928,795.6025363
,125.4,252.2859591,11.19250865,502682.9441,1.717313448,800.6037187
End Of Loading Marker,125.68,255.2711231,11.34995732,501108.5662,1.733016296,805.0778431
,126,257.4618807,11.35264979,501010.3124,1.744357237,809.759058
,126.3,258.9747766,11.3525514,501701.614,1.752208655,814.4917564
,126.6,259.9672666,11.35248708,504140.3854,1.753517153,819.0085766
,126.9,261.4052838,11.35239359,508254.0842,1.750899818,824.3735374
,127.2,262.1032514,11.35234855,514020.8912,1.744356778,829.9675002
,127.5,262.9805114,11.35229177,519360.2241,1.740430904,835.4749009
,127.8,263.2504233,11.35227475,521971.1557,1.74348427,840.4628888
,128.1,264.1218594,11.35221836,522122.9257,1.753952938,845.2492678
,128.4,264.3318686,11.35220526,519268.1859,1.77140085,849.2214682
,128.7,265.030668,11.35216016,518195.2816,1.782741926,853.0895813
,129,265.2144696,11.35214878,520687.9852,1.783614311,857.7356848
,129.3,265.6087631,11.35212362,522538.2472,1.784486665,861.746242
,129.6,265.9872488,11.35209949,526173.7797,1.781433242,866.7539571
,129.9,266.3723904,11.35207493,528666.2264,1.781869401,871.0702348
,130.2,266.2475262,11.35208375,530319.9274,1.786231396,875.5081361
,130.5,267.0836028,11.35202967,531520.0523,1.791901887,879.7696338
,130.8,266.7598945,11.35205151,529315.1214,1.805860261,883.2629718
,131.1,267.1924591,11.35202384,525147.9363,1.825052935,886.1919938
,131.4,267.2414794,11.35202128,519495.9846,1.849043827,888.5216228
,131.7,267.9011755,11.35197874,514930.7716,1.869981268,890.6178575
,132,267.6839611,11.35199361,514098.3866,1.877832858,892.6121725
,132.3,268.2255156,11.35195881,514033.9427,1.883067178,894.9867328
,132.6,267.8976473,11.35198092,514586.0926,1.885684403,897.239649
,132.9,268.5199042,11.35194084,511430.6714,1.899642676,899.0367356
,133.2,268.2352991,11.35196012,508604.0503,1.912728651,900.3933063
,133.5,268.9856814,11.35191164,506184.6396,1.924069719,901.5669008
,133.8,268.9240479,11.35191633,506080.7019,1.92799551,902.9081333
,134.1,269.1744081,11.35190059,507674.8482,1.926250691,904.5868683
,134.4,269.3498899,11.35188975,510406.7622,1.921016296,906.5439368
,134.7,269.5919303,11.35187455,516294.0802,1.906185536,909.1507964
,135,269.419643,11.35188648,528919.0277,1.873034503,913.389266
,135.3,269.6824829,11.35186992,537839.7612,1.852533167,917.5554161
,135.6,269.6033778,11.35187575,542592.6297,1.84511781,921.5517237
,136.5,270.003668,11.19813716,1.7977E+308,1.914909462,0
,136.8,269.7011845,11.02799414,1.7977E+308,1.767038355,0
,137.1,269.1840493,10.85786517,1.7977E+308,1.458646371,0
,137.4,268.9888916,10.68771512,1.7977E+308,0.945241246,0
,137.7,268.6331611,10.51757558,1.7977E+308,0.438379083,0
,138,268.3198618,10.34743327,1.7977E+308,0.11253911,0
,138.3,267.932516,10.1772958,1.7977E+308,0.068046906,0
,138.6,267.7373583,10.00714575,1.7977E+308,0.056705755,0
,138.9,267.1927676,9.83701858,1.7977E+308,0.035768247,0
,139.2,267.1599369,9.666290694,1.7977E+308,0.021809907,0
,139.5,266.6551911,9.496728124,1.7977E+308,0.01177735,0
,139.8,266.1530315,9.326598173,1.7977E+308,0.017447926,0
,140.1,265.9320823,9.156449814,1.7977E+308,0.027044286,0
,140.4,265.3425644,8.986325582,1.7977E+308,0.030533873,0
,140.7,265.2389249,8.816169543,1.7977E+308,0.026171891,0
,141,264.6843503,8.646043023,1.7977E+308,0.012649748,0
,141.3,264.5416075,8.475889544,1.7977E+308,0.006106775,0
,141.6,264.1609175,8.305751642,1.7977E+308,0.020501316,0
,141.9,263.8168347,8.135611343,1.7977E+308,0.029661479,0
,142.2,263.9719421,7.965438366,1.7977E+308,0.023118506,0
,142.5,263.0521265,7.795335756,1.7977E+308,0.012649749,0
,142.8,262.7746024,7.6251911,1.7977E+308,0.027044292,0
,143.1,262.3980722,7.455052925,1.7977E+308,0.04274743,0
,143.4,262.2644812,7.284898847,1.7977E+308,0.050162801,0
,143.7,261.9104146,7.114759201,1.7977E+308,0.046673216,0
,144,261.4544299,6.944626228,1.7977E+308,0.031406277,0
,144.3,260.905263,6.774499354,1.7977E+308,0.019192725,0
,144.6,260.4967014,6.604363277,1.7977E+308,0.019192726,0
,144.9,260.0282369,6.43423112,1.7977E+308,0.025735701,0
,145.2,259.9815883,6.26407135,1.7977E+308,0.036204462,0
,145.5,259.7835185,6.093921493,1.7977E+308,0.027480495,0
,145.8,259.2730388,5.923792087,1.7977E+308,0.019192727,0
,146.1,258.9023324,5.753653531,1.7977E+308,0.007851571,0
,146.4,258.1339377,5.583541009,1.7977E+308,0.005670579,0
,146.7,257.9812111,5.413388183,1.7977E+308,0.011777356,0
,147,257.4624115,5.243259322,1.7977E+308,0.013085952,0
,147.3,257.2015269,5.073113576,1.7977E+308,0.006542976,0
,147.6,257.0421444,4.902961187,1.7977E+308,0.005234381,0
,147.9,256.3877314,4.732841203,1.7977E+308,0.012213556,0
,148.2,256.1726059,4.562692462,1.7977E+308,0.007415373,0
,148.5,255.6787658,4.392561967,1.7977E+308,0.002180992,0
,148.8,255.3380107,4.22242145,1.7977E+308,0.006542977,0
,149.1,254.8899297,4.052287959,1.7977E+308,0.006542977,0
,149.4,254.7962739,3.882131267,1.7977E+308,0.013085954,0
,149.7,254.127717,3.712012209,1.7977E+308,0.01439455,0
,150,253.6563404,3.541880243,1.7977E+308,0.019192734,0
,150.3,253.3779841,3.371735641,1.7977E+308,0.031406293,0
,150.6,253.0730043,3.201592783,1.7977E+308,0.030970095,0
,150.9,252.3977915,3.03147416,1.7977E+308,0.026608111,0
,151.2,251.914767,2.861342957,1.7977E+308,0.023118523,0
,151.5,251.5615321,2.691203257,1.7977E+308,0.019628935,0
,151.8,251.0859955,2.521071564,1.7977E+308,0.019628936,0
,152.1,250.6670338,2.350936167,1.7977E+308,0.020501334,0
,152.4,250.1191145,2.180809211,1.7977E+308,0.025735717,0
,152.7,249.7775273,2.010668749,1.7977E+308,0.031842499,0
,153,249.0315957,1.840554756,1.7977E+308,0.031406301,0
,153.3,248.6675449,1.670415765,1.7977E+308,0.023990925,0
,153.6,247.9906679,1.500297251,1.7977E+308,0.01962894,0
,153.9,247.5925057,1.330160493,1.7977E+308,0.027044317,0
,154.2,247.1094811,1.160029289,1.7977E+308,0.034459696,0
,229.5,246.0872984,0.995200584,1.7977E+308,0.044056076,0
,229.8,245.9054521,0.825049665,1.7977E+308,0.041438884,0
,230.1,245.3949719,0.654920259,1.7977E+308,0.044492276,0
,230.4,244.5658415,0.484811712,1.7977E+308,0.042311285,0
,230.7,243.7558467,0.314701913,1.7977E+308,0.041438889,0
,231,242.93254,0.144592986,1.7977E+308,0.050162868,0
,231.242,241.8574831,0.007398684,1.7977E+308,0.045364684,0
END,,,,,,