File: GB1_test 50.csv
Segment,Time On Sample,Displacement Into Surface,Load On Sample,Harmonic Contact Stiffness,Harmonic Displacement,Harmonic Load
Surface Marker,0,0,0,89.23319357,0.736367955,2.130097945
,0.2,0.052995249,0.000653191,790.1489357,0.570597915,2.188171606
,0.4,-0.083718617,0.00131882,2537.204865,0.408317778,2.260489737
,0.6,0.197260391,0.001957063,5563.966632,0.291406273,2.329520707
,0.788,0.046999374,0.00258418,10162.18089,0.204595124,2.399647378
,1,-0.116105975,0.003290151,15331.63113,0.161843906,2.492784365
,1.2,-0.053125915,0.003941926,18566.31462,0.143085717,2.626463356
,1.4,0.296081929,0.004574934,20501.54427,0.135669686,2.75685518
,1.6,0.558755787,0.005213615,22171.0347,0.131307315,2.890534188
,1.8,0.403736782,0.005879682,25022.92693,0.121710104,3.023117435
,2,0.158855563,0.006551641,30438.92568,0.109931708,3.291571115
,2.2,0.612902648,0.007177775,34704.56904,0.107750521,3.636725922
,2.4,0.72414204,0.007826384,37465.83031,0.109495468,3.988455082
,2.6,0.569955093,0.008492397,39504.51108,0.112549127,4.330322631
,2.8,0.72279736,0.009138279,39375.0569,0.121710102,4.665615855
,3,0.754991291,0.009792071,38627.6008,0.136542157,5.1323966
,3.2,0.368660302,0.010473304,39177.83876,0.151810452,5.810653036
,3.4,0.781104508,0.011102165,40110.32363,0.164897557,6.486718154
,3.6,0.615268757,0.011768941,41335.91786,0.176675955,7.160591716
,3.8,0.751469874,0.012415914,41693.7615,0.191508009,7.824603754
,4,0.699625998,0.013075216,43203.98143,0.207648776,8.791037103
,4.2,0.984765404,0.013712423,43920.12574,0.22640696,9.749800417
,4.4,0.867188988,0.014376035,42940.83653,0.253017414,10.67897894
,4.6,0.949306368,0.015026553,41973.81401,0.279627865,11.59172156
,4.8,0.847123015,0.015689156,41232.4379,0.3060202,12.46720935
,5,0.511963564,0.016367033,40803.30765,0.337211147,13.57499165
,5.2,0.717225454,0.017009478,40314.34545,0.370801386,14.7287948
,5.4,0.818064127,0.01765877,40230.76322,0.395230652,15.62400578
,5.6,0.892692989,0.018309779,39230.82406,0.435364447,16.71425659
,5.8,0.641571346,0.018982147,37510.34517,0.482478041,17.69712575
,6,0.494456886,0.019647696,35955.84159,0.530900345,18.66136756
,6.2,0.500857035,0.020303179,34429.67165,0.585429961,19.71326779
,6.4,-0.042316804,0.020994696,32778.52719,0.644321966,20.67531791
,6.6,-0.535983235,0.021682967,30263.19128,0.725462057,21.56504988
,6.8,1.073791738,0.022233326,27178.51283,0.831467564,22.29590238
,7,0.536858348,0.022924433,24284.98413,0.94925156,22.86787278
,7.2,0.720902772,0.023568269,21888.46811,1.065290573,23.24151659
,7.4,1.347185741,0.02418311,19265.46592,1.220154639,23.5680444
,7.6,1.415990199,0.024834501,18091.39159,1.310455675,23.84307253
,7.8,1.453592503,0.025487938,17793.75161,1.357133022,24.30437465
,8,1.248650056,0.026157277,18190.28951,1.357569274,24.83689902
,8.2,1.318286572,0.026808613,19083.67886,1.326596449,25.41106126
,8.4,1.348400358,0.027462541,20648.03215,1.267704464,26.20656086
,8.6,1.329422755,0.028119687,21974.24596,1.229751854,26.99658176
,8.8,1.407379845,0.028770478,22598.37034,1.221463348,27.59046717
,9,1.529435981,0.029418378,22887.41877,1.228006893,28.17449101
,9.2,1.539996417,0.030073587,22747.72224,1.254617344,28.74974905
,9.4,1.461110676,0.030734661,22336.27547,1.289080066,29.15955174
,9.6,1.608544564,0.031380896,21696.67257,1.335757404,29.62742832
,9.8,1.47515906,0.032045543,21072.67586,1.378944869,29.95176414
,10,1.930038173,0.03267162,20322.51844,1.432165736,30.24432429
,10.2,1.89150722,0.033330048,19518.88643,1.493238905,30.50949078
,10.4,2.14086814,0.033969599,19039.62672,1.535117626,30.72206252
,10.6,2.147268289,0.034625081,19018.38346,1.554312049,31.04749414
,10.8,2.577185664,0.035252793,19440.40525,1.545151038,31.381692
,11,2.488731268,0.035914493,20803.41714,1.487567777,31.96571569
,11.2,2.434390705,0.036577234,22454.80299,1.41646117,32.51686762
,11.4,2.336783676,0.037239534,25170.44786,1.314381746,33.31675004
,11.6,2.220039326,0.037903089,27295.91741,1.24763751,33.96761323
,11.8,1.573274384,0.038601395,29372.39387,1.193107942,34.72804881
,12,2.005688466,0.039225667,29619.47443,1.203141362,35.30001996
,12.2,2.04620297,0.039878912,27826.39902,1.288643791,35.68462109
,12.4,2.691623217,0.040492496,25500.88836,1.400320387,35.8117264
,12.6,2.988411398,0.041128937,22908.10086,1.54602348,35.8435028
,12.8,3.063040253,0.041779943,21475.59085,1.641123112,35.84569431
,13,3.090241837,0.042434058,21135.89977,1.672095928,36.00457511
,13.2,3.118275478,0.043088119,21935.5646,1.630217186,36.35740005
,13.4,3.084736872,0.043746218,24544.19595,1.497164943,37.09373024
,13.6,2.935542289,0.044411899,27462.98197,1.375018631,37.82567737
,13.8,3.080896023,0.045058268,31447.25905,1.242402611,38.78115363
,14,3.056510048,0.045715766,34407.00581,1.16606116,39.59199341
,14.2,3.300878609,0.046355644,36390.33077,1.128108537,40.42146092
,14.4,3.139203167,0.047022143,36598.29932,1.139450706,41.08656852
,14.6,3.089023413,0.047681333,36478.76238,1.156027711,41.59279542
,14.8,3.059645095,0.048339158,35969.76071,1.188309242,42.21297828
,15,3.289036623,0.048980017,35464.68021,1.220154518,42.76632195
,15.2,2.991735826,0.049655408,34971.05479,1.251127357,43.2418682
,15.4,3.240264674,0.050295013,34347.63871,1.289516184,43.78863757
,15.6,3.246664823,0.050950493,33787.60294,1.32354266,44.20172757
,15.8,3.198149185,0.051609573,33453.26793,1.351461825,44.70466724
,16,3.158786178,0.052268052,33316.45827,1.370220012,45.19774555
,16.2,3.396498279,0.052908366,33310.71626,1.382870863,45.64809068
,16.4,3.568477845,0.053552989,33464.04819,1.391595591,46.19595558
,16.6,3.158017248,0.054235799,33760.66782,1.391595623,46.66273576
,16.8,3.182722659,0.054890079,34031.10715,1.3972667,47.24456825
,17,3.270664432,0.055540212,34177.59828,1.406863904,47.73435933
,17.2,3.294537786,0.056194546,34330.67319,1.418206059,48.29756433
,17.4,3.138686745,0.056860663,34446.05341,1.426930811,48.71503703
,17.6,3.250758182,0.057509214,34546.88752,1.440017905,49.25084894
,17.8,3.316234405,0.05816082,34633.5436,1.448306404,49.66613046
,18,3.449107276,0.058808007,34615.19903,1.462265976,50.12304983
,18.2,3.48878972,0.059461305,34482.23548,1.481460392,50.60188367
,18.4,3.538456852,0.060113947,34215.77011,1.502835996,50.95690009
,18.6,3.508246477,0.060771826,33661.82663,1.537298711,51.33273526
,18.8,3.635294944,0.061419395,33323.23525,1.55954678,51.62529521
,19,3.609244856,0.062077002,32989.13605,1.580922388,51.95839694
,19.2,3.395149801,0.062746937,32520.84624,1.607096618,52.30355141
,19.4,3.854189158,0.063372739,32039.87312,1.632834551,52.59392039
,19.6,3.886383085,0.064026526,31651.90818,1.654210159,52.82621509
,19.8,3.490067469,0.064708409,31051.91577,1.689545377,53.05412627
,20,3.888366638,0.065338193,30771.24957,1.711357183,53.24807094
,20.2,4.272520823,0.065968904,30929.65033,1.713102095,53.4913235
,20.4,4.641697968,0.066600596,31905.24979,1.679948061,53.93399894
,20.6,4.595678506,0.06725951,33214.08401,1.633270723,54.39530087
,20.8,4.548826797,0.067919669,35915.26358,1.540352281,55.18422607
,21,4.474516226,0.06858773,38942.01636,1.448742551,56.01698034
,21.2,4.040755793,0.069286217,41660.05098,1.377635979,56.79933059
,21.4,4.027183226,0.069964015,43690.29038,1.335321006,57.63756366
,21.6,4.164211968,0.070638678,43874.58389,1.34448197,58.30486303
,21.8,4.579978875,0.07130161,42751.80999,1.386360676,58.68069895
,22,4.830997367,0.071982001,41000.46165,1.450487471,59.01489684
,22.2,4.260358078,0.07272363,39067.14969,1.525956492,59.29211557
,22.4,4.8466934,0.073396348,37850.76366,1.580486047,59.5474215
,22.6,4.956258759,0.074107325,37982.40888,1.587465827,59.94517152
,22.8,4.953079219,0.074832822,39341.78689,1.552566881,60.57631172
,23,5.029776026,0.075560344,40761.21401,1.517667929,61.21402641
,23.2,4.815667637,0.076314268,42214.7002,1.483205237,61.82434734
,23.4,4.965999166,0.077051748,44600.3776,1.427366911,62.66805935
,23.6,4.835926181,0.077815163,46319.10499,1.395085396,63.48437764
,23.8,4.623478314,0.078591558,47204.92469,1.383743254,64.10675167
,24,4.439735156,0.079374046,47855.61394,1.380689611,64.78829503
,24.2,4.307578313,0.080160943,47657.24734,1.400756516,65.43258369
,24.4,4.868107979,0.080910084,45937.33411,1.460957156,65.85663208
,24.6,5.065859441,0.081690587,44340.49146,1.517667928,66.12070328
,24.8,5.041034331,0.082493503,42480.15165,1.587465823,66.36724236
,25,5.388553576,0.083280092,41402.63874,1.631961949,66.62473947
,25.2,5.129501771,0.084114504,41377.13458,1.641122946,67.04330765
,25.4,5.213256265,0.084934665,42577.94355,1.608405177,67.57692812
,25.6,5.29409722,0.085763437,44535.75104,1.556492988,68.34284322
,25.8,5.220590222,0.086610659,46651.41037,1.505453286,69.17231036
,26,5.234031872,0.087460611,48239.15014,1.474044234,69.93493813
,26.2,5.371864722,0.088310998,49136.36022,1.460957118,70.54745116
,26.4,5.198506777,0.089190377,49238.77764,1.471863053,71.23118604
,26.6,5.149540004,0.090070373,48943.31006,1.493238662,71.80973111
,26.8,5.149663204,0.090956006,48735.82197,1.509379425,72.25131017
,27,5.250463934,0.091843865,48610.94557,1.524211469,72.76959041
,27.2,5.436133084,0.092735118,48672.24331,1.535117374,73.36128469
,27.4,5.269424513,0.093658638,48698.66728,1.54733202,73.94640399
,27.6,5.189248441,0.094585656,48709.43042,1.556493,74.40222726
,27.8,5.422756506,0.095501327,48655.9559,1.568707612,74.92927368
,28,5.403317666,0.096442938,48342.81368,1.587902034,75.38509698
,28.2,5.457098386,0.097389063,47875.97546,1.611895055,75.81900615
,28.4,5.559968963,0.098341556,47787.17327,1.62236473,76.20799015
,28.6,5.60542606,0.099307416,48019.60844,1.624982147,76.72627044
,28.8,5.560186598,0.10029378,48549.71248,1.618874836,77.2916668
,29,5.329398357,0.101292329,49376.62473,1.603606568,77.88774324
,29.2,5.575376586,0.102274461,50341.22121,1.583975889,78.45423584
,29.4,5.520979733,0.10329138,51412.75047,1.564345238,79.15769425
,29.6,5.599711224,0.104304738,52341.21379,1.550385653,79.87210994
,29.8,5.873975368,0.105310359,52959.78869,1.543842078,80.44079415
,30,5.737200779,0.106358262,53595.40322,1.541224669,81.17931553
,30.2,5.652844129,0.107413225,53854.92429,1.545150808,81.71731872
,30.4,6.031941714,0.108448294,54018.18009,1.553875512,82.33202365
,30.6,5.820276936,0.109532785,53912.8788,1.569580055,82.92371717
,30.8,5.928952525,0.110606861,53867.52666,1.58004973,83.37296653
,31,5.839596753,0.1117048,53945.91643,1.587902001,83.90768232
,31.2,5.858406683,0.112806619,54158.46061,1.592700604,84.504855
,31.4,6.066091849,0.11390715,54581.83318,1.591391876,85.1447615
,31.6,6.211370953,0.115022884,55212.12132,1.582667127,85.69920107
,31.8,6.335014791,0.116151208,56146.52607,1.569143776,86.44868047
,32,6.42454248,0.117293094,56675.99013,1.565653874,87.08968247
,32.2,6.381771213,0.118455317,57153.54741,1.565653878,87.7887577
,32.4,6.632714337,0.119609715,57408.35649,1.571324935,88.43414312
,32.6,6.330337518,0.120812178,57407.47128,1.580922171,88.93489077
,32.8,6.31668267,0.122007626,57276.84081,1.594445514,89.49042562
,33,6.560131604,0.123198221,57528.82189,1.597935387,90.08431156
,33.2,6.541480582,0.124418094,57904.94093,1.597935389,90.73627054
,33.4,6.770780702,0.125633761,58386.94774,1.593573001,91.30824215
,33.6,7.067475501,0.1268573,59230.25743,1.583103297,92.06977479
,33.8,7.087925328,0.128111356,60450.22127,1.564781346,92.86746615
,34,6.895366498,0.129392008,61545.33399,1.550385549,93.65310376
,34.2,6.964903652,0.130668319,62824.05593,1.534244785,94.5362618
,34.4,7.151758853,0.131949657,63564.13351,1.528137455,95.21013601
,34.6,7.133925924,0.13325733,64391.83064,1.522466379,96.05932636
,34.8,7.32077699,0.134564666,64769.81466,1.525956254,96.83619925
,35,7.264665238,0.135901219,64998.02987,1.532063574,97.55609342
,35.2,7.304237941,0.137244862,64820.71031,1.547331864,98.26503048
,35.4,7.222328135,0.138610027,64907.0793,1.554311656,98.85672422
,35.6,7.137919971,0.139989114,64955.25526,1.564345111,99.58209697
,35.8,7.298134457,0.141365827,64820.04752,1.578740914,100.27679
,36,7.118867379,0.142778751,64889.56672,1.587029424,100.9024511
,36.2,7.274085069,0.144183804,65294.567,1.588774357,101.622346
,36.4,7.588223437,0.145592571,65518.26681,1.592700463,102.1987005
,36.6,7.83662702,0.147019874,65766.92429,1.597935283,102.8999681
,36.8,7.966044155,0.148469248,66256.3694,1.59793527,103.6472561
,37,8.114596278,0.149931999,66721.21842,1.597499023,104.3452363
,37.2,7.92449878,0.151431733,66936.21712,1.60142517,104.9632272
,37.4,7.954894045,0.152932041,67309.65448,1.603606354,105.7291423
,37.6,7.981126643,0.154447601,67655.79,1.605351294,106.4588984
,37.8,8.169607967,0.155967778,67934.25801,1.606223751,107.0166254
,38,8.25907206,0.157509706,68143.5972,1.61233106,107.8460928
,38.2,8.165481083,0.159079309,68413.86204,1.614076014,108.4224466
,38.4,8.304031583,0.16064926,68859.60659,1.614512239,109.1817876
,38.6,8.250374348,0.162247718,69592.60366,1.609713639,110.0002975
,38.8,8.371446572,0.16385074,70123.51388,1.607096208,110.6675971
,39,8.556584643,0.165465626,70853.12921,1.601425115,111.4291297
,39.2,8.358141765,0.167122003,71380.56549,1.601861369,112.2761281
,39.4,8.537450221,0.16877008,71693.93012,1.604042537,112.9017902
,39.6,8.646863236,0.170439333,71653.91157,1.616257157,113.6479824
,39.8,8.646442044,0.172132542,71668.88644,1.624981892,114.2341979
,40,8.510808866,0.173851585,71670.28337,1.63501535,114.8741036
,40.2,8.625206129,0.175571449,71891.27049,1.640686418,115.5939983
,40.4,8.588582269,0.177318499,71725.05885,1.652028577,116.1330972
,40.6,8.649306298,0.179076773,71619.22433,1.662934491,116.7719077
,40.8,8.916377694,0.180839169,71506.41962,1.672095438,117.272657
,41,9.098992483,0.182624741,71471.48568,1.681256393,117.9163988
,41.2,9.969715671,0.184383003,71444.28051,1.689108573,118.4790589
,41.4,10.01503537,0.186213191,72044.80178,1.684091847,119.1496454
,41.6,10.40024748,0.188039371,73093.88786,1.670350355,119.9057003
,41.8,10.36568383,0.189911692,74387.60538,1.652900891,120.7061306
,42,10.57699008,0.191786571,75988.39887,1.631525273,121.6764
,42.2,10.25702487,0.193715256,77535.03882,1.61058594,122.5157279
,42.4,10.52615303,0.195624447,79324.54292,1.588774081,123.585161
,42.6,10.50821844,0.197571727,80400.37935,1.578740639,124.4310643
,42.8,10.81145476,0.199517555,81355.23414,1.573069536,125.4511896
,43,10.85134189,0.201500264,82006.97818,1.572197059,126.3573582
,43.2,10.83214979,0.203506904,82170.09099,1.578304375,127.0728698
,43.4,10.75055024,0.205537573,81891.28659,1.594881377,127.9264428
,43.6,10.75631343,0.207582958,81640.08581,1.607968478,128.5586788
,43.8,10.95136634,0.209636465,81328.44599,1.624109218,129.3443177
,44,10.92716892,0.211725068,80921.90361,1.640249979,130.0105211
,44.2,11.06147504,0.213824173,80628.42849,1.653337068,130.5978328
,44.4,11.59433314,0.215918187,80639.47734,1.661625516,131.3341652
,44.6,11.6242094,0.218066325,80900.0315,1.663806697,131.9806457
,44.8,12.0197713,0.220211976,81455.86561,1.662061714,132.7871042
,45,11.89362997,0.222413797,82294.92807,1.655518176,133.5990395
,45.2,12.24258973,0.224606172,83072.38117,1.649410831,134.3539987
,45.4,12.139739,0.226850459,84185.51643,1.639813634,135.3346764
,45.6,12.51115717,0.229086173,85005.86644,1.633706288,136.1016884
,45.8,12.47153562,0.231371301,85593.02166,1.634578765,137.0242928
,46,12.70399307,0.23366146,85964.99179,1.637632401,137.8274638
,46.2,12.6627001,0.235992671,86637.36309,1.634578748,138.5911871
,46.4,12.73206697,0.238340072,87055.55893,1.638068636,139.5083133
,46.6,12.67495554,0.240731323,87185.86149,1.643739718,140.205197
,46.8,12.76262202,0.243113072,87685.79093,1.644175947,141.1026
,47,12.81783256,0.245532936,88480.24125,1.638941102,141.991237
,47.2,13.02613575,0.247979451,88741.40317,1.641558503,142.7385254
,47.4,13.10713423,0.250434254,89410.97455,1.638941077,143.7027683
,47.6,12.92686092,0.252943331,90283.15521,1.632397543,144.5410008
,47.8,12.94960552,0.255464216,91424.94419,1.624545282,145.6104331
,48,13.03475038,0.25800624,92107.52564,1.623672801,146.5275591
,48.2,13.24386766,0.260565676,92544.42529,1.625853966,147.3121026
,48.4,13.03861648,0.26317813,92785.99733,1.632833771,148.247855
,48.6,12.99727634,0.265806043,92745.16768,1.641558508,148.9699406
,48.8,13.1223434,0.268449459,92315.99397,1.657699253,149.7654409
,49,13.21828425,0.271121345,92040.60286,1.669913871,150.4667081
,49.2,13.33502224,0.273818757,91962.23514,1.679511066,151.2775488
,49.4,13.57490036,0.276535157,92062.96432,1.685182121,151.9437537
,49.6,13.51523362,0.279298612,92398.00357,1.689108256,152.7534976
,49.8,13.47137156,0.282088695,92544.36821,1.6943431,153.3846379
,50,13.41169596,0.284907873,92825.87813,1.698269236,154.1231594
,50.2,13.60745737,0.287738493,93022.80774,1.703940294,154.9175644
,50.4,13.93218306,0.29058914,92850.59209,1.713101233,155.488441
,50.6,14.17037029,0.293474064,92622.71141,1.724007126,156.1787515
,50.8,14.0432799,0.29641206,92951.03408,1.724007139,156.8197532
,51,13.98274939,0.299375095,93216.97147,1.725315855,157.5243069
,51.2,14.33574646,0.302340631,93796.81053,1.723134638,158.3592548
,51.4,14.40750352,0.305354622,94970.55425,1.712228717,159.2851467
,51.6,15.2455802,0.308348352,95637.44225,1.708302511,159.9940876
,51.8,15.35477023,0.311420148,96041.49523,1.710047447,160.8191727
,52,15.00798818,0.314552823,96235.02861,1.71484608,161.5598845
,52.2,15.55732641,0.317657994,96266.69192,1.720953343,162.1800699
,52.4,15.71143263,0.32082047,96208.88121,1.728369348,162.7695733
,52.6,16.2516082,0.323989159,96841.06381,1.726188118,163.5935646
,52.8,16.19436188,0.327229073,97711.95001,1.720953284,164.4800098
,53,16.50571157,0.330477262,98655.79392,1.713537234,165.3061915
,53.2,16.52167589,0.333777552,99724.76451,1.70350379,166.1060744
,53.4,16.49187182,0.337113979,101138.519,1.690416698,167.1766023
,53.6,16.63263407,0.340472686,101852.31,1.686490555,167.9852516
,53.8,16.74759719,0.343866839,102875.1252,1.679074523,168.9933236
,54,16.95491319,0.347289074,104299.9775,1.665987408,170.0397466
,54.2,17.48173354,0.350724669,105684.2608,1.653772733,171.0028957
,54.4,17.50515402,0.354227947,107060.669,1.644611766,172.1819012
,54.6,17.70995728,0.357754537,108103.9636,1.638504436,173.1505274
,54.8,17.66596993,0.361332937,108710.2425,1.640685624,174.2648845
,55,17.61282426,0.364947736,108304.9567,1.655081434,175.093256
,55.2,17.606268,0.368595797,107534.1238,1.672967131,175.7485024
,55.4,17.8809411,0.37226208,106925.0622,1.689980331,176.5976945
,55.6,17.8810296,0.375983237,106973.2643,1.697396352,177.4666084
,55.8,18.23390426,0.379718395,107569.875,1.695651373,178.2752587
,56,18.09585947,0.383523297,108717.39,1.686926656,179.2537448
,56.2,18.18912041,0.387351122,110462.0945,1.672094606,180.4897289
,56.4,18.14924615,0.391226121,111837.3353,1.66075246,181.4594496
,56.6,18.28742586,0.395128323,113275.3856,1.651155244,182.718444
,56.8,18.44556866,0.399068608,113736.8417,1.652463939,183.6103689
,57,18.36407283,0.403064197,114156.0125,1.655517603,184.6184401
,57.2,18.48559248,0.407086543,114090.1761,1.665987268,185.6659584
,57.4,18.77726129,0.411138157,113635.3207,1.679074337,186.3902376
,57.6,18.7198758,0.415253637,112792.3852,1.698704986,187.2306619
,57.8,19.20165652,0.419374879,112470.7082,1.709174617,187.9220702
,58,19.37806582,0.423557682,111958.9387,1.722697932,188.6233382
,58.2,19.5993995,0.427779578,111646.6324,1.73404006,189.4429455
,58.4,19.37432801,0.43207328,111658.0836,1.739711157,190.1179139
,58.6,19.8802115,0.436361821,111731.8986,1.746254656,190.9243739
,58.8,19.94759426,0.440722371,111871.1864,1.750617014,191.5807164
,59,20.15267543,0.445117713,112265.6418,1.751925704,192.3488243
,59.2,19.92924036,0.449585538,112508.4461,1.756288091,193.1782905
,59.4,20.10726553,0.454071698,112785.8438,1.75803302,193.8324422
,59.6,20.34935189,0.458598763,113739.0389,1.751925686,194.7649096
,59.8,21.02202036,0.46314282,114377.424,1.748871966,195.4979569
,60,21.15717296,0.467767948,115166.8001,1.744945825,196.3789245
,60.2,21.38842071,0.472433265,116346.981,1.73665731,197.4012419
,60.4,21.53895149,0.477150877,117191.1408,1.731858695,198.2142743
,60.6,21.65827264,0.481917815,118203.6131,1.726623847,199.2585058
,60.8,21.69770873,0.486737972,119398.3632,1.717462878,200.1570046
,61,21.95347183,0.491592356,120642.2754,1.709174362,201.1990449
,61.2,21.83022541,0.496520411,122133.627,1.699140936,202.4240706
,61.4,21.91082497,0.501484595,123400.0488,1.6904162,203.439813
,61.6,22.0721261,0.50649333,124187.7591,1.689543712,204.5826601
,61.8,22.32910574,0.511546019,124228.881,1.697395944,205.575393
,62,23.25879502,0.516605306,124506.1648,1.700013275,206.352271
,62.2,23.65387989,0.521750442,124746.165,1.705248075,207.3943125
,62.4,23.88337732,0.526958022,124924.5333,1.710919127,208.3859494
,62.6,24.05046219,0.532221971,125272.4798,1.712664057,209.1924078
,62.8,24.22003482,0.537538722,125887.2329,1.712664041,210.2629371
,63,23.92863965,0.542939285,126555.9383,1.711791596,211.2896347
,63.2,24.11234013,0.548362734,126882.9776,1.713972761,212.1344439
,63.4,24.33846683,0.553837878,127198.8688,1.717462631,213.1962073
,63.6,24.80754525,0.559352166,127602.6959,1.717898823,214.0486879
,63.8,24.51029085,0.564972265,127929.2626,1.720952506,215.0830558
,64,25.31799847,0.570576104,127891.8052,1.727495975,215.991421
,64.2,25.43176205,0.576281826,128082.5117,1.730985855,216.8088363
,64.4,25.93658302,0.582019308,128402.098,1.735348171,217.8169105
,64.6,25.9654632,0.587816474,128590.4695,1.739710532,218.5740603
,64.8,25.93192054,0.593734888,129120.8352,1.74145548,219.5624088
,65,26.30191571,0.59968658,129635.4429,1.742764154,220.4477609
,65.2,26.66691859,0.605638308,130399.9237,1.740146701,221.3276346
,65.4,26.88879346,0.611689476,131762.3573,1.731421954,222.5011629
,65.6,27.16058202,0.617798245,133261.2639,1.721388493,223.7305739
,65.8,27.48062009,0.623965243,134348.3091,1.714844918,224.7397437
,66,27.51774913,0.63021301,135999.5432,1.703066535,225.9954505
,66.2,27.91015627,0.636499936,136998.8575,1.698267899,227.0331098
,66.4,27.93728063,0.642874122,137643.8726,1.700012841,228.2636146
,66.6,27.96023454,0.649312609,137894.6827,1.704375203,229.1938898
,66.8,28.28854285,0.655795589,138356.9762,1.708301298,230.3367387
,67,28.48787205,0.662352314,138474.8469,1.71528106,231.3426199
,67.2,28.55156559,0.668983889,138892.8429,1.717462236,232.2520769
,67.4,28.7342326,0.675674238,140002.4085,1.713536092,233.5198378
,67.6,28.6980581,0.682446291,141156.4897,1.708737497,234.7700658
,67.8,29.18690032,0.689251739,142270.6733,1.70306638,235.8548419
,68,29.54260267,0.696134175,143891.4857,1.693032913,237.1620503
,68.2,29.88331701,0.703086788,145276.8972,1.686925573,238.5799279
,68.4,30.13831846,0.710114871,146089.8297,1.685616841,239.6986701
,68.6,30.38498812,0.71721405,147207.5949,1.682999401,241.0847705
,68.8,31.00107939,0.724360206,148160.2487,1.680381926,242.2078981
,69,30.9989415,0.73161889,148789.957,1.682126872,243.4362117
,69.2,30.8511822,0.738959912,149657.849,1.682126886,244.8288843
,69.4,31.27836199,0.746336953,150690.439,1.679073193,246.0232329
,69.6,31.47089016,0.75380351,151455.8316,1.680381884,247.4159076
,69.8,31.46704115,0.761357999,151579.0753,1.686052956,248.4371284
,70,31.71612515,0.768971692,151700.5202,1.692596475,249.5975082
,70.2,31.96602907,0.776661705,151292.6561,1.705247303,250.7951432
,70.4,31.98211291,0.78444446,150661.2194,1.717898153,251.6640574
,70.6,32.5373567,0.792269887,149952.9715,1.732293892,252.6798033
,70.8,32.47021,0.80021494,149893.5144,1.738401206,253.5355683
,71,32.64933923,0.808223607,149681.6335,1.747125915,254.4921421
,71.2,32.80266191,0.81631448,149540.3474,1.755414385,255.5341828
,71.4,32.95181139,0.824486943,149297.2019,1.763266626,256.2913335
,71.6,33.38717511,0.832722693,149623.9606,1.766320233,257.2994086
,71.8,33.48970324,0.84106305,150039.91,1.767192697,258.1639406
,72,34.27367197,0.849442282,151127.5901,1.761521552,259.2498151
,72.2,34.37284517,0.857950873,152894.8573,1.750179402,260.5756496
,72.4,34.39379152,0.866550035,155107.6053,1.734911135,262.0318755
,72.6,34.81660721,0.875209088,156075.0704,1.730984968,263.0947371
,72.8,35.01725011,0.883969762,156668.4101,1.732729893,264.3307227
,73,35.26114592,0.892815621,156846.696,1.737964703,265.3913913
,73.2,35.69806457,0.901737741,156204.7922,1.750179273,266.1649803
,73.4,36.17074738,0.910747066,155470.5032,1.765011254,267.1029294
,73.6,36.92049042,0.919828654,155725.6107,1.768064834,267.9367854
,73.8,36.98377279,0.929046793,156193.1112,1.770246008,269.027038
,74,37.07533035,0.938355559,156905.0433,1.769373528,270.0767481
,74.2,37.46641318,0.947738109,158504.512,1.758903824,271.1626208
,74.4,37.80173324,0.957218765,160424.3859,1.747125418,272.5618708
,74.6,38.2373009,0.966788048,161239.6319,1.744944196,273.5809035
,74.8,38.4003549,0.97647182,162240.8591,1.742326764,274.8125061
,75,38.67696905,0.986245466,163523.6085,1.737091905,276.0660237
,75.2,39.12663521,0.996105888,164033.1249,1.740145514,277.3129688
,75.4,39.00549531,1.006103006,164128.4095,1.745380358,278.2662531
,75.6,39.21216947,1.016178822,164827.3429,1.745380339,279.4299206
,75.8,39.70671881,1.026337051,165122.079,1.748870179,280.5311339
,76,39.95371533,1.036613605,165497.926,1.751487572,281.6520681
,76.2,40.27641249,1.046988565,165870.4621,1.753232485,282.6196004
,76.4,40.07032164,1.057502587,167073.8762,1.748870145,283.9804966
,76.6,40.48617569,1.068081196,168749.2748,1.740581621,285.3830352
,76.8,40.68775847,1.078780299,170618.0849,1.729675702,286.6069676
,77,41.2208984,1.089564904,172258.1013,1.722259639,288.0127942
,77.2,42.32439523,1.100420469,174404.8835,1.711353636,289.6662605
,77.4,42.52426225,1.111444472,175960.2298,1.704373842,291.0238726
,77.6,42.90133951,1.122567648,177361.674,1.700447683,292.6345994
,77.8,43.49098921,1.133788553,178363.2227,1.698702684,293.9330456
,78,43.94166767,1.14513139,179539.8984,1.696957698,295.4407745
,78.2,44.29414545,1.156594662,180102.4031,1.700883788,296.9309712
,78.4,44.36162589,1.168191865,180020.6663,1.708736028,298.0672447
,78.6,44.64167801,1.179891531,179729.9799,1.719205664,299.3591133
,78.8,44.9017421,1.191710167,179430.3389,1.728584711,300.5189465
,79,45.27328275,1.203640143,180192.6858,1.728584675,301.8250605
,79.2,45.85365027,1.215676306,181646.3244,1.723131672,303.2960842
,79.4,45.98676874,1.227862738,183535.4001,1.71353447,304.7282054
,79.6,46.43938688,1.240088724,186042.1998,1.700883588,306.5558879
,79.8,46.68520001,1.252575024,188126.1125,1.692595084,308.3649417
,80,46.80037043,1.265132847,188831.6604,1.694340016,309.8387005
,80.2,47.02868035,1.277809335,189430.4554,1.696084938,311.1941214
,80.4,47.36264106,1.2906062,189133.2711,1.706118331,312.6733609
,80.6,48.2216083,1.303497064,188884.1545,1.713970495,313.8063545
,80.8,48.78101497,1.31653719,189032.225,1.720077743,315.2954572
,81,48.88109569,1.329804933,189674.6884,1.722258913,316.6881323
,81.2,49.34145639,1.343048909,190065.4063,1.725748755,317.872621
,81.4,49.91910506,1.356485306,191416.9313,1.723567521,319.5184135
,81.6,50.15309343,1.370079247,192730.0009,1.720077613,320.8847927
,81.8,50.31550333,1.383814488,194381.6,1.715279005,322.5886553
,82,50.77992736,1.397667844,195727.3599,1.71222531,324.1960968
,82.2,50.94061788,1.411750833,196521.5319,1.712661531,325.5635708
,82.4,51.68789602,1.425866548,196970.6247,1.717023818,327.0986966
,82.6,52.09900119,1.440146699,197135.0292,1.722258607,328.3357809
,82.8,52.46682824,1.4545005,196025.0587,1.738399294,329.5498542
,83,52.63908785,1.46908392,195395.6835,1.750177641,330.6861288
,83.2,53.26313013,1.483784136,195677.5723,1.753667466,331.8202161
,83.4,53.60425015,1.498650707,196827.9043,1.751486255,333.3454767
,83.6,54.27733644,1.51364471,198288.7952,1.745815126,334.6866579
,83.8,54.98784124,1.528786857,201283.864,1.730110574,336.5778961
,84,55.12503584,1.544119164,203465.0368,1.720513377,338.2839503
,84.2,55.40947972,1.559595715,204270.3228,1.720949586,339.6722444
,84.4,55.53331225,1.575238375,204229.6825,1.728801816,341.2216096
,84.6,56.04152922,1.591012915,203630.2241,1.738835186,342.3031006
,84.8,56.57052236,1.606944542,202472.1137,1.754539617,343.511697
,85,56.76666805,1.623058127,202452.9931,1.760646897,344.7422056
,85.2,56.97610087,1.639332808,203319.3437,1.760646877,346.2291139
,85.4,57.3835368,1.655757847,203990.0545,1.761083073,347.3697744
,85.6,57.83005307,1.672345387,204817.5811,1.7619555,348.8665472
,85.8,58.49537327,1.689085213,205251.4643,1.763700378,350.003922
,86,58.8253486,1.706015255,205154.6022,1.770243879,351.1588267
,86.2,59.14115196,1.723116269,204736.5492,1.77984103,352.3718041
,86.4,60.02688563,1.740351318,204918.6511,1.784203298,353.6231379
,86.6,60.70624217,1.757772924,205438.8426,1.785075702,354.7166847
,86.8,61.15425962,1.775384782,207351.3206,1.777223419,356.3000205
,87,61.42668538,1.793185138,209512.6708,1.767189976,357.807749
,87.2,62.067683,1.811139902,211583.7294,1.757592733,359.2322063
,87.4,62.34254785,1.829299059,214358.9885,1.744941878,361.1015268
,87.6,62.83205382,1.847626497,216660.9998,1.734472179,362.6256943
,87.8,63.08522696,1.866153705,218554.9096,1.728801094,364.4807699
,88,64.01732714,1.884822294,219525.9155,1.728801004,366.080547
,88.2,64.3761118,1.903716241,220848.2426,1.725747321,367.5729369
,88.4,65.0460547,1.922779606,222279.1344,1.724002318,369.466367
,88.6,65.29910778,1.942061918,222929.5899,1.725747235,370.9061613
,88.8,65.49222215,1.961541823,223758.6842,1.727492159,372.6155042
,89,66.16124062,1.98118612,224926.0774,1.726619624,374.2854058
,89.2,66.67047321,2.001038356,225404.2591,1.730545696,375.9772204
,89.4,67.03739274,2.02109956,225832.5749,1.734035544,377.6076727
,89.6,67.74875081,2.041339512,225991.9435,1.738834063,378.9455683
,89.8,68.3311081,2.061791184,226923.5354,1.739706474,380.6746387
,90,68.73204483,2.082460327,228186.3848,1.737961497,382.3730268
,90.2,69.01895709,2.103344618,229648.0921,1.734035352,383.8204911
,90.4,69.672772,2.124414523,231141.9022,1.732290347,385.7325496
,90.6,70.02368544,2.145716099,233048.261,1.725746784,387.3619061
,90.8,70.59422722,2.167217132,234706.9417,1.722256847,389.2991662
,91,71.09068178,2.188939188,235502.3944,1.724001741,391.0063208
,91.2,71.75767277,2.210868346,235482.7483,1.730108971,392.4318752
,91.4,72.42546077,2.233017684,235942.9471,1.734471259,394.1598511
,91.6,73.12649553,2.255387477,235476.9792,1.745377072,395.7278505
,91.8,73.32410175,2.278015039,235362.8049,1.752356816,396.9956143
,92,74.3562222,2.300814998,236217.4927,1.753665422,398.5548512
,92.2,74.78423473,2.323884643,237697.2491,1.751047969,400.2505015
,92.4,75.39151801,2.347174651,238739.928,1.75104791,401.9001322
,92.6,75.94135234,2.370702493,240676.9883,1.7453768,403.8023287
,92.8,76.60805267,2.394459055,242168.6991,1.741450619,405.4064877
,93,77.11371257,2.418464921,243409.3609,1.73970563,407.1585688
,93.2,78.13395954,2.442678046,244618.6806,1.739269297,409.072823
,93.4,78.74812544,2.467161161,245917.1264,1.737088062,410.6890349
,93.6,79.53531946,2.491878836,247816.5694,1.733161871,412.7227216
,93.8,80.04956027,2.516862855,249061.7908,1.731853116,414.2677096
,94,80.60078755,2.542095525,250327.731,1.731416828,416.0833437
,94.2,81.1116199,2.567584408,251577.8787,1.731416779,418.1345598
,94.4,82.10417071,2.593297623,252362.4161,1.733161624,419.8411739
,94.6,82.7517941,2.619291885,253520.0301,1.732725327,421.6924207
,94.8,83.3989599,2.645547477,253582.4853,1.737960084,423.3343828
,95,83.86677616,2.672078717,253679.905,1.743631094,424.9949691
,95.2,84.33371801,2.698876411,254354.3533,1.745812223,426.6637753
,95.4,85.07977107,2.725925002,255166.3603,1.747557091,428.5122838
,95.6,85.734671,2.753251453,254620.4972,1.756281725,429.7877234
,95.8,86.30840204,2.780857738,255570.5371,1.758462844,431.5770616
,96,86.82925357,2.80874487,256339.3508,1.760643967,433.2053255
,96.2,87.63379083,2.836893509,256020.1098,1.768496116,434.4566608
,96.4,88.62091884,2.865312983,255394.7703,1.77940189,435.9698787
,96.6,89.13539501,2.894049134,254874.7888,1.788562771,437.4118688
,96.8,89.59990205,2.923077371,254799.0685,1.792925073,438.5919783
,97,90.61726227,2.952360711,256251.2288,1.788562624,440.1950467
,97.2,90.99722289,2.981979371,259480.3864,1.774166838,442.2725591
,97.4,91.94501273,3.011857638,262288.1432,1.762388407,444.0432747
,97.6,92.53830007,3.042059495,266972.0247,1.742321551,446.4977221
,97.8,93.31708704,3.072552606,270536.6513,1.728798199,448.5346974
,98,93.74969111,3.103374892,273569.2262,1.721382167,451.197332
,98.2,94.57996742,3.134480588,274334.9265,1.723563261,452.8661426
,98.4,95.24877567,3.165909553,276169.3938,1.721382024,455.2110184
,98.6,95.7611077,3.197664535,277343.1454,1.72094574,456.959814
,98.8,96.82587233,3.229702076,278780.0626,1.720945639,459.2575787
,99,97.70087761,3.262074103,279419.4072,1.723999197,461.2397695
,99.2,98.3104062,3.294788877,280686.0341,1.72312667,463.0773198
,99.4,98.99726349,3.327827122,281910.9989,1.724435308,465.2742728
,99.6,99.89707353,3.361183401,282867.9866,1.725743925,467.0942963
,99.8,100.7943341,3.394874935,285211.8047,1.721381494,469.5498451
,100,101.8496309,3.428894837,287609.6881,1.716582814,471.8278867
,100.2,102.4996909,3.463110258,290016.513,1.712656641,474.3612278
,100.4,103.3942367,3.498176904,291433.1412,1.711784087,476.3236976
,100.6,104.2696727,3.533071483,291793.0855,1.717891286,478.5732486
,100.8,104.9603092,3.568505115,290222.1494,1.731850722,480.0196245
,101,105.6558814,3.604294634,289158.1897,1.743628985,481.6566592
,101.2,106.1791615,3.640455064,288578.1592,1.753226091,483.5029745
,101.4,107.1816462,3.67694725,288431.327,1.760641978,485.3898397
,101.6,108.1973853,3.713805266,289933.8581,1.758024472,487.1200156
,101.8,109.0632961,3.751043475,294181.4933,1.74319242,489.7223919
,102,109.9100102,3.788657041,296978.7961,1.735776355,492.0311137
,102.2,110.9031053,3.826639021,298162.3522,1.735776259,493.8314166
,102.4,111.8611936,3.865004776,299439.4989,1.737084869,496.1269896
,102.6,112.8341975,3.903755196,298105.8853,1.749735569,497.5481691
,102.8,113.594134,3.942908892,294858.9661,1.773292143,498.9419518
,103,114.1434987,3.982469782,292912.9681,1.788996521,500.1878078
,103.2,115.2594279,4.022390861,291694.3638,1.801210967,501.6550101
,103.4,116.1190211,4.062730062,291370.4308,1.807318159,502.899774
,103.6,116.9502601,4.103476395,293927.1184,1.799029627,504.9279881
,103.8,117.6083671,4.144643471,296856.1212,1.788123708,506.7447225
,104,118.4918945,4.1862092,300404.7636,1.77547283,508.936201
,104.2,119.7372983,4.228167938,304266.5775,1.762385685,511.4038091
,104.4,120.5599525,4.27057599,308929.71,1.746681178,514.1442502
,104.6,121.5223238,4.31340055,311992.1793,1.737956404,516.2875187
,104.8,122.4987715,4.356654159,316330.3131,1.725305523,519.1353425
,105,123.5566912,4.400336848,319433.4201,1.718325678,521.7004693
,105.2,124.4656039,4.444468069,321278.3264,1.716144421,523.805386
,105.4,125.0840599,4.489061837,322602.1484,1.717889295,526.327773
,105.6,126.2657438,4.534066444,322469.4659,1.725741393,528.6156817
,105.8,127.0637798,4.57954858,322320.146,1.731848592,530.4302283
,106,127.8675676,4.625487061,321650.298,1.74057319,532.4091343
,106.2,129.0199116,4.671864259,322412.7138,1.743626719,534.8285301
,106.4,130.2246007,4.718703999,323419.2243,1.744062837,536.7581357
,106.6,130.898366,4.766049248,325765.2532,1.740572899,539.3287364
,106.8,132.2576662,4.813824896,327117.4243,1.741009001,541.3416194
,107,133.3123591,4.862100831,330060.8125,1.73533786,543.8815456
,107.2,134.0250017,4.910884206,331830.8452,1.734901555,546.4740619
,107.4,135.2184921,4.960126065,332759.2954,1.736646376,548.523102
,107.6,135.6946755,5.009909832,334531.988,1.73577386,551.1210936
,107.8,136.9296102,5.060143888,336527.0688,1.732283873,553.3607922
,108,138.2767915,5.110875333,337262.5249,1.735337383,555.7056831
,108.2,139.1928892,5.162144828,338929.3113,1.735337294,558.3409369
,108.4,140.3834818,5.213911329,341121.0522,1.731847308,560.5696779
,108.6,141.9018198,5.266176345,342234.7142,1.734464564,563.1446761
,108.8,143.0040487,5.318993874,343278.0601,1.737518092,565.6111893
,109,144.1869021,5.372336803,345752.8089,1.733591876,568.1850872
,109.2,145.3322279,5.426218024,347550.646,1.731846831,570.417115
,109.4,146.5931227,5.480633068,348282.2682,1.735772811,572.9329404
,109.6,147.9396316,5.535589698,349844.3865,1.734900214,575.1660685
,109.8,149.3426318,5.59109704,351297.773,1.735336312,577.8561179
,110,150.0761584,5.647206217,352140.6679,1.738389874,580.2831802
,110.2,151.2418457,5.703850658,352726.6101,1.741443394,582.3234557
,110.4,152.2464407,5.761074827,354074.9152,1.742751996,584.9543299
,110.6,153.642424,5.818848177,354554.0377,1.746241727,586.8872278
,110.8,154.6638922,5.87722665,354963.9926,1.751912659,589.3592207
,111,155.684019,5.936191826,354759.0116,1.758892291,591.3918257
,111.2,157.0206468,5.995728614,355420.1849,1.762818258,593.6720698
,111.4,158.26815,6.055869515,356292.9657,1.764563068,595.6093494
,111.6,159.183569,6.116636444,357423.3538,1.766307911,597.9838205
,111.8,160.6784138,6.177975803,360441.4831,1.760636733,600.7582453
,112,161.5403865,6.239973152,363555.7265,1.75365692,603.3365223
,112.2,162.916051,6.302559408,365704.6103,1.749730688,605.6178646
,112.4,164.516269,6.365759819,368610.0897,1.744495736,608.6070557
,112.6,165.8314088,6.429614127,371380.632,1.738388346,611.0538532
,112.8,167.0956914,6.494113337,374704.8987,1.731408497,614.1854843
,113,168.5316893,6.559249218,377079.7017,1.728790961,616.9774413
,113.2,169.4138539,6.625076043,378964.1143,1.728354643,619.4472422
,113.4,170.7947271,6.691531409,380261.7668,1.731408139,622.3148037
,113.6,172.2541228,6.758649471,380414.863,1.737515258,624.4208311
,113.8,173.2645203,6.826471372,378910.1915,1.751474609,626.7109338
,114,174.6667049,6.894948871,378712.9586,1.758890428,628.9725558
,114.2,176.4261452,6.964090869,379487.1229,1.761725768,631.26322
,114.4,177.8651359,7.03394873,380183.923,1.764561139,633.4651254
,114.6,179.1334449,7.104519128,382111.0146,1.762816083,636.1924329
,114.8,180.5131362,7.175788267,383772.7713,1.761071017,638.4014579
,115,181.9717582,7.247768256,385213.929,1.761507106,640.9205783
,115.2,183.5950109,7.320460561,386361.6852,1.763251877,643.5810528
,115.4,185.042585,7.393894971,388094.5974,1.761506804,645.7572079
,115.6,186.2445872,7.4680832,391124.5566,1.756708129,648.6510667
,115.8,187.4448068,7.543016914,396249.3355,1.744929735,652.0489645
,116,189.0151683,7.618679144,401366.9663,1.733151308,655.215667
,116.2,190.7135445,7.69509311,406200.12,1.722681567,658.2454066
,116.4,191.960828,7.772304349,412049.6377,1.710903174,662.0487274
,116.6,193.8320246,7.850250531,415276.7324,1.706976905,665.0028646
,116.8,195.0973651,7.929019647,418800.9539,1.703486926,668.5968999
,117,196.8684653,8.008546808,421568.4396,1.701305597,671.8315439
,117.2,198.3166035,8.088894248,421904.106,1.706540245,674.4492823
,117.4,199.7130263,8.170052331,420898.1565,1.717445915,677.4592953
,117.6,201.4604437,8.252002765,419769.827,1.727042853,679.7943419
,117.8,203.0962355,8.334784226,416684.7241,1.744055746,682.2773098
,118,204.5454493,8.418830895,413554.0951,1.761068653,684.3088321
,118.2,206.1684931,8.503292974,412798.7122,1.770229365,686.7271522
,118.4,208.1650597,8.588150066,415281.3127,1.766739312,689.1378091
,118.6,209.6047822,8.67432569,418674.5949,1.761504387,692.253014
,118.8,211.1650139,8.761359061,422427.4681,1.754088292,694.8674703
,119,212.943103,8.849252584,428834.3853,1.738820004,698.3716695
,119.2,214.2476164,8.938060294,435274.3202,1.724424228,702.3634611
,119.4,216.0661933,9.027726576,438114.9479,1.720934199,705.3603349
,119.6,217.5326707,9.118316999,443333.629,1.71133696,709.3302146
,119.8,219.2436253,9.209801426,447227.0679,1.704793322,712.6141714
,120,220.7663908,9.30221742,450908.4971,1.701303323,716.9018176
,120.2,222.7541231,9.39553141,452591.3876,1.702175597,719.8241869
,120.4,224.1942191,9.489818899,454057.1162,1.705665312,723.4828787
,120.6,226.0235624,9.585028246,452353.523,1.717443388,725.9132586
,120.8,227.6705352,9.681206321,450431.5163,1.731402636,728.821377
,121,229.52703,9.778336854,450189.9371,1.739254622,731.5936279
,121.2,230.7302127,9.876486253,451266.4506,1.741871893,734.1916456
,121.4,232.9391832,9.975555566,454200.0127,1.739690521,737.6870899
,121.6,234.553914,10.0756589,460705.7152,1.726167194,741.8103797
,121.8,236.6069734,10.17673792,465306.7265,1.717878602,745.1063991
,122,238.1889331,10.27886245,468329.2406,1.715697294,748.7289383
,122.2,240.1135327,10.38199015,471137.529,1.714824647,752.6035039
,122.4,242.0155022,10.4861548,472300.0188,1.717878082,755.5017691
,122.6,243.5603574,10.59138905,472245.6287,1.726166323,758.7802466
,122.8,245.5543495,10.69765044,471878.9864,1.733582058,761.3300683
,123,247.3468164,10.80499281,471911.3698,1.740561577,764.2568203
,123.2,249.5684475,10.91338526,472091.5987,1.747541055,767.4498464
,123.4,251.4520946,11.02288903,472826.3575,1.752339411,770.5990375
End Of Loading Marker,123.532,252.5747256,11.09577147,472560.6187,1.757137837,772.362103
,123.8,254.9376737,11.09838983,472980.786,1.763244842,775.8959043
,124,255.8236504,11.098332,475166.2602,1.762372295,779.0056281
,124.2,256.835266,11.09826594,477935.8069,1.759318581,781.8951094
,124.4,257.2827545,11.09823686,482723.7445,1.751466377,785.6896573
,124.6,258.1196404,11.09818226,490670.6783,1.735325766,790.0813909
,124.8,258.5787776,11.09815241,498280.1222,1.719621413,793.8803223
,125,259.0029688,11.09812487,506485.4671,1.703917071,798.3586101
,125.2,259.3614284,11.09810163,514168.8349,1.690830118,803.2510839
,125.4,259.9661735,11.09806224,517982.5034,1.687340216,807.0686479
,125.6,260.2655579,11.09804287,519919.4895,1.6903938,811.3749025
,125.8,260.5632781,11.09802362,520025.779,1.696501002,814.5755581
,126,260.5814311,11.09802269,516662.692,1.713077763,817.6633464
,126.2,261.1320932,11.09798685,512727.5532,1.731835633,820.7927837
,126.4,261.4680875,11.09796508,509760.5927,1.746231212,823.1245218
,126.6,261.9255605,11.09793535,506412.3834,1.762807932,825.893458
,126.8,261.9487058,11.09793409,503080.7899,1.778948463,828.4388579
,127,261.9327449,11.0979354,501496.3165,1.788981769,830.8472897
,127.2,262.3186619,11.09791036,500733.25,1.795961421,832.9620711
,127.4,262.5631313,11.0978946,501009.9362,1.801196164,835.7671648
,127.6,262.9461361,11.09786975,502400.7043,1.801632356,838.1054771
,127.8,263.109481,11.0978593,504617.4439,1.800759879,841.0606843
,128,262.9529045,11.09786983,507189.1216,1.798578742,843.9293214
,128.2,263.2552009,11.09785027,508791.6265,1.798578713,846.3607698
,128.4,263.4996702,11.09783451,508993.6067,1.803377225,849.0694389
,128.6,263.5294719,11.09783282,507300.2687,1.813846756,851.4329448
,128.8,263.9241254,11.0978072,506048.527,1.821698867,853.2146234
,129,264.083726,11.097797,507088.1756,1.823443774,855.5803239
,129.2,263.808583,11.09781531,508353.3684,1.824752494,858.1487264
,129.4,264.4120799,11.097776,511878.5009,1.81886332,860.9078083
,129.6,264.4639307,11.09777286,515371.9822,1.812974203,863.758918
,129.8,264.012394,11.09780273,516958.6096,1.812974249,866.5837181
,130,264.4303448,11.09777559,515201.2814,1.822135049,868.6557675
,130.2,264.7405457,11.09775552,513570.7198,1.830423398,870.3552635
,130.4,265.059483,11.09773487,510930.1839,1.843074052,872.2815788
,130.6,264.7743555,11.09775382,509460.5389,1.851362462,873.7104138
,130.8,264.931044,11.09774381,508020.951,1.860523288,875.4416824
,131,265.1622006,11.09772892,506983.4401,1.867502953,876.9055934
,131.2,265.1903381,11.09772734,504815.7587,1.877972484,878.2380108
,131.4,264.9264277,11.0977449,502384.0674,1.888442045,879.1233594
,131.6,265.3402182,11.09771804,498834.5271,1.90327384,879.9594174
,131.8,265.3837485,11.09771545,495864.1548,1.915488291,880.4590745
,132,265.4039816,11.09771438,493086.9564,1.927484629,881.0463912
,132.2,265.6771565,11.09769673,491323.015,1.935554865,881.5263294
,132.4,265.4956186,11.0977089,490702.6684,1.93991719,882.2330758
,132.6,265.486314,11.09770977,490372.0996,1.942534575,882.8192947
,132.8,265.6841888,11.09769706,491703.99,1.939917171,883.8547717
,133,265.8745751,11.09768484,493533.8406,1.935554845,884.9669513
,133.2,265.9542994,11.09767988,495603.5835,1.930320071,886.2401989
,133.4,265.9033926,11.09768348,497020.3292,1.926830233,887.3381259
Unloading Marker,133.538,265.9086544,11.09768331,498459.1919,1.922904158,888.266219
,134.3,265.9718807,10.97396432,1.7977E+308,1.978741662,0
,134.5,265.8063159,10.86301953,1.7977E+308,1.948205545,0
,134.7,265.4044503,10.75209022,1.7977E+308,1.836966804,0
,134.9,265.0733085,10.64115628,1.7977E+308,1.64677032,0
,135.1,265.1041064,10.5301986,1.7977E+308,1.351006008,0
,135.3,264.6231964,10.41927448,1.7977E+308,0.925681249,0
,135.5,264.3694348,10.30833547,1.7977E+308,0.568408429,0
,135.7,264.0375491,10.19684679,1.7977E+308,0.302307789,0
,135.9,264.1573759,10.08588328,1.7977E+308,0.095098265,0
,136.1,264.0342454,9.974935702,1.7977E+308,0.018757915,0
,136.3,263.5574074,9.864566092,1.7977E+308,0.017449224,0
,136.5,263.306974,9.753626858,1.7977E+308,0.012214457,0
,136.7,262.8385446,9.642701917,1.7977E+308,0.008724612,0
,136.9,262.9342421,9.531739989,1.7977E+308,0.004362306,0
,137.1,262.6763202,9.420801246,1.7977E+308,0.016140533,0
,137.3,262.4333752,9.309861521,1.7977E+308,0.02791876,0
,137.5,262.4117543,9.198907285,1.7977E+308,0.036207141,0
,137.7,261.9008906,9.087985126,1.7977E+308,0.042314371,0
,137.9,261.6987157,8.977042728,1.7977E+308,0.043186833,0
,138.1,261.4782359,8.86610153,1.7977E+308,0.037952066,0
,138.3,261.4923929,8.755144949,1.7977E+308,0.029663684,0
,138.5,261.1021758,8.64421488,1.7977E+308,0.021375302,0
,138.7,260.6528834,8.533288684,1.7977E+308,0.018757919,0
,138.9,260.4914788,8.422343613,1.7977E+308,0.014395612,0
,139.1,260.4074544,8.311393468,1.7977E+308,0.01265069,0
,139.3,260.0696562,8.200459962,1.7977E+308,0.017885458,0
,139.5,259.9132438,8.089514564,1.7977E+308,0.024865149,0
,139.7,259.4622873,7.978588477,1.7977E+308,0.023120227,0
,139.9,259.3807591,7.867638169,1.7977E+308,0.023556458,0
,140.1,259.1303256,7.756698935,1.7977E+308,0.029663688,0
,140.3,258.9264866,7.645756646,1.7977E+308,0.032717303,0
,140.5,258.765082,7.534811575,1.7977E+308,0.034462227,0
,140.7,258.2974846,7.423886579,1.7977E+308,0.032717305,0
,140.9,258.174354,7.312938999,1.7977E+308,0.028791228,0
,141.1,257.8473723,7.202004784,1.7977E+308,0.021811537,0
,141.3,257.3132112,7.091084152,1.7977E+308,0.017012999,0
,141.5,257.1984011,6.980136026,1.7977E+308,0.01177823,0
,141.7,257.3257163,6.869172025,1.7977E+308,0.007852154,0
,141.9,256.8705995,6.758246211,1.7977E+308,0.004362308,0
,142.1,256.9704572,6.64728401,1.7977E+308,0.007415923,0
,142.3,256.4487768,6.536362561,1.7977E+308,0.014395616,0
,142.5,256.1292834,6.425427855,1.7977E+308,0.016140539,0
,142.7,256.099342,6.314474164,1.7977E+308,0.017013001,0
,142.9,255.5477078,6.203554678,1.7977E+308,0.01614054,0
,143.1,255.382975,6.092609826,1.7977E+308,0.017013001,0
,143.3,255.3155915,5.98165859,1.7977E+308,0.019630386,0
,143.5,255.1300575,5.870715101,1.7977E+308,0.023120233,0
,143.7,254.8039078,5.759780831,1.7977E+308,0.028355003,0
,143.9,254.4361557,5.648849289,1.7977E+308,0.03140862,0
,144.1,254.3146892,5.5379016,1.7977E+308,0.029663697,0
,144.3,254.252298,5.426950037,1.7977E+308,0.025301388,0
,144.5,253.7073202,5.316030114,1.7977E+308,0.027046313,0
,144.7,253.5242823,5.205086462,1.7977E+308,0.034026007,0
,144.9,253.2181016,5.094150883,1.7977E+308,0.042314394,0
,145.1,252.8965281,4.983216313,1.7977E+308,0.046240472,0
,145.3,252.5707943,4.872282016,1.7977E+308,0.041005703,0
,145.5,252.2849987,4.761345101,1.7977E+308,0.030536162,0
,145.7,252.0657668,4.650403821,1.7977E+308,0.01963039,0
,145.9,251.7263043,4.539470424,1.7977E+308,0.009160849,0
,146.1,251.6239748,4.42852148,1.7977E+308,0.008724618,0
,146.3,251.2932488,4.31758751,1.7977E+308,0.013959389,0
,146.5,250.9525381,4.206654195,1.7977E+308,0.02355647,0
,146.7,250.4491625,4.095731546,1.7977E+308,0.030972396,0
,146.9,250.5065859,3.984772127,1.7977E+308,0.04187817,0
,147.1,250.3705586,3.873825392,1.7977E+308,0.049730327,0
,147.3,249.8409734,3.762904461,1.7977E+308,0.054092638,0
,147.5,249.4561643,3.651974037,1.7977E+308,0.053220177,0
,147.7,249.3954372,3.541022365,1.7977E+308,0.052783946,0
,147.9,249.0713674,3.430087959,1.7977E+308,0.054528871,0
,148.1,248.681566,3.319157863,1.7977E+308,0.054528873,0
,148.3,248.5001922,3.208214101,1.7977E+308,0.05322018,0
,148.5,248.204828,3.097277813,1.7977E+308,0.048857871,0
,148.7,247.9148721,2.98634117,1.7977E+308,0.044059331,0
,148.9,247.6973042,2.875399781,1.7977E+308,0.040569484,0
,149.1,247.059137,2.764485969,1.7977E+308,0.034898482,0
,149.3,246.7829099,2.653548426,1.7977E+308,0.025737631,0
,149.5,246.8985765,2.542585189,1.7977E+308,0.020066627,0
,149.7,246.6169411,2.431648001,1.7977E+308,0.013959393,0
,149.9,246.2666618,2.320715313,1.7977E+308,0.005671004,0
,150.1,245.6659366,2.209799046,1.7977E+308,0.004362311,0
,150.3,245.3913735,2.098861394,1.7977E+308,0.010905777,0
,150.5,244.928768,1.987936071,1.7977E+308,0.01614055,0
,150.7,244.6192589,1.87700071,1.7977E+308,0.026610096,0
,150.9,244.1841109,1.766073587,1.7977E+308,0.037515874,0
,151.1,243.9619667,1.655132498,1.7977E+308,0.047985421,0
,151.3,243.6782511,1.544195447,1.7977E+308,0.049730347,0
,151.5,243.1798675,1.43327247,1.7977E+308,0.048857886,0
,151.7,242.64737,1.322351729,1.7977E+308,0.04231442,0
,151.9,242.3836235,1.211413368,1.7977E+308,0.032281105,0
,152.082,241.8133998,1.11048111,1.7977E+308,0.019194171,0
,227.3,241.1441576,0.99578445,1.7977E+308,0.026173873,0
,227.5,241.1641389,0.884827487,1.7977E+308,0.035770959,0
,227.7,240.6932127,0.773902709,1.7977E+308,0.03926081,0
,227.9,240.2996669,0.662972858,1.7977E+308,0.047112973,0
,228.1,239.6198969,0.552061774,1.7977E+308,0.049730363,0
,228.3,239.0715904,0.44114207,1.7977E+308,0.04842167,0
,228.5,238.1738242,0.330245278,1.7977E+308,0.044495591,0
,228.7,237.4524518,0.219336921,1.7977E+308,0.035770967,0
,228.9,236.4498476,0.108447003,1.7977E+308,0.027046342,0
,229.094,235.2086286,0.000901399,1.7977E+308,0.023120262,0
END,,,,,,