File: GB1_test45.csv
Segment,Time On Sample,Displacement Into Surface,Load On Sample,Harmonic Contact Stiffness,Harmonic Displacement,Harmonic Load
Surface Marker,0,0,0,-192.5884729,0.475916699,2.211222309
,0.3,0.130548448,0.000976155,4813.348112,0.24690087,2.316414255
,0.6,0.364268167,0.001945558,14534.64656,0.169253598,2.462148943
,0.9,0.323419308,0.002932126,18744.69372,0.145697685,2.611170863
,1.2,0.575443967,0.00389805,22594.26009,0.126067756,2.741565059
,1.5,0.397310991,0.004892128,28497.2296,0.111672477,3.082343113
,1.8,0.412208134,0.005873572,31391.05657,0.115162242,3.529408872
,2.1,0.543588969,0.006847392,31638.94307,0.125631536,3.930453175
,2.4,0.814750233,0.007812062,33164.92757,0.137845711,4.583519873
,2.7,1.044310175,0.008779455,38707.42538,0.139590592,5.414097972
,3,0.877825572,0.00977277,45122.35068,0.140463034,6.261112264
,3.3,0.836976949,0.010757862,46534.01063,0.156166976,7.094977556
,3.6,1.068200944,0.011725146,46744.20156,0.188883519,8.609303316
,3.9,1.061049388,0.012708031,45752.41372,0.220291403,9.839829943
,4.2,1.146252757,0.013684872,43970.15283,0.255189049,11.04077136
,4.5,0.793394251,0.014690385,41175.65462,0.308407968,12.68987413
,4.8,0.866533239,0.015668016,38610.10804,0.369478852,14.26775332
,5.1,1.023706889,0.016640147,36186.8884,0.438837924,15.75249387
,5.4,1.118478561,0.017616362,35130.8332,0.505579675,17.38406482
,5.7,0.789748818,0.018620296,34243.00423,0.565778127,18.8775711
,6,1.346295117,0.019566287,33147.71651,0.630338759,20.31409893
,6.3,-0.108166318,0.020643902,30957.25114,0.716710495,21.59941214
,6.6,0.311095654,0.021598881,26482.94901,0.87200502,22.7061193
,6.9,1.216261012,0.022522055,21241.66281,1.093168816,23.3208353
,7.2,1.455805267,0.023488793,17398.02653,1.320439733,23.58491107
,7.5,1.280168378,0.024482705,15391.06058,1.480532702,23.80844383
,7.8,2.070514058,0.025413392,15936.27991,1.468318464,24.50972402
,8.1,1.280841741,0.026447494,18193.41798,1.354028734,25.6098559
,8.4,1.873165159,0.027391142,21168.62615,1.23494047,26.78449977
,8.7,1.558579876,0.028394149,22722.21474,1.202223949,27.81779118
,9,1.503586807,0.029380165,22152.91717,1.254134204,28.47085785
,9.3,1.537620555,0.030360355,20601.40356,1.360572026,29.01434957
,9.6,1.773836702,0.03132731,19409.55354,1.449561009,29.38690461
,9.9,1.279533726,0.03234208,19076.19591,1.496236654,29.85588492
,10.2,1.985012726,0.033278322,19212.48492,1.515430301,30.37636653
,10.5,1.835168657,0.034270545,19745.27679,1.514121653,30.95601782
,10.8,2.631338501,0.03520085,20449.53701,1.50190741,31.47321232
,11.1,2.13453947,0.036215781,22159.20236,1.443017675,32.23256616
,11.4,2.622859578,0.037166234,24700.48608,1.348793993,33.1113577
,11.7,2.403957332,0.038162976,27807.90952,1.247154617,34.15122372
,12,2.273249872,0.039153946,30295.96444,1.182593982,35.20314313
,12.3,1.586748824,0.040181294,31236.47453,1.172124734,36.0293375
,12.6,1.95692121,0.041139482,30428.6814,1.226216063,36.85553294
,12.9,2.601662268,0.042079697,28034.74841,1.343123131,37.36724852
,13.2,2.886135927,0.043043492,26178.79208,1.447816045,37.76938898
,13.5,2.797029785,0.044031738,25521.47042,1.496672757,38.20001829
,13.8,3.038238076,0.044998364,27183.5437,1.4364743,39.00210727
,14.1,3.039822798,0.045980674,29732.45947,1.347921527,39.89733453
,14.4,3.167043488,0.046954761,32911.45463,1.259368746,41.05992497
,14.7,2.328281659,0.047992073,34474.62809,1.230578248,41.95734271
,15,2.666837033,0.048952328,34143.952,1.26547587,42.7923043
,15.3,2.905549247,0.049919117,33696.83196,1.299937279,43.47057339
,15.6,3.14176538,0.05088607,32918.499,1.352283729,44.22664097
,15.9,2.837164431,0.051888421,32879.38633,1.377584546,44.97175012
,16.2,2.965216629,0.052865726,33148.08877,1.391979815,45.73987071
,16.5,2.837837797,0.053853204,33828.02833,1.385872738,46.51785255
,16.8,2.964226462,0.054827345,34144.22042,1.39416092,47.33747348
,17.1,2.920881765,0.055812596,34057.61343,1.411609746,47.97410373
,17.4,3.463283044,0.056762781,33655.66595,1.44781601,48.69510773
,17.7,3.087127841,0.057769814,33143.07053,1.488384553,49.30763106
,18,3.347473254,0.058731915,32892.85176,1.51804753,49.8051018
,18.3,3.206781485,0.059723537,32518.88283,1.554253849,50.3573592
,18.6,3.561145344,0.060682756,32357.50131,1.577809729,50.84277679
,18.9,3.202462694,0.061688645,32295.72236,1.595694805,51.36983166
,19.2,3.537689949,0.062649117,32445.25668,1.605291628,51.91441977
,19.5,3.198975929,0.063653699,32633.09724,1.613143629,52.41408086
,19.8,4.198992154,0.064570659,32694.30281,1.627975038,52.90826549
,20.1,4.15564746,0.065555907,33520.89375,1.608345118,53.51969347
,20.4,4.129775318,0.066540011,35149.343,1.55861598,54.26918627
,20.7,4.082270477,0.067525638,38570.15367,1.454795497,55.38027607
,21,4.5043047,0.068487258,42389.81549,1.360281015,56.66486046
,21.3,3.720175113,0.069547432,44498.62239,1.321748261,57.69668988
,21.6,4.156903258,0.070540914,43476.15943,1.369296268,58.57767335
,21.9,3.619742231,0.071613565,38902.90993,1.525027047,58.93379092
,22.2,4.69920575,0.072595724,34922.82157,1.679885242,58.82421783
,22.5,4.492770278,0.073677469,32048.34524,1.815113623,58.69711046
,22.8,4.912847999,0.074734206,32698.64363,1.794611225,59.08391072
,23.1,4.968495659,0.075831039,36333.02423,1.654148206,60.03392565
,23.4,5.039949176,0.076943442,43052.32335,1.449997002,61.65125207
,23.7,4.711195397,0.078098986,47969.58138,1.33919701,63.07572587
,24,5.172031774,0.079219889,50476.2539,1.300373357,64.32926415
,24.3,4.660226748,0.080421908,50571.38101,1.316077335,65.2628418
,24.6,5.092768636,0.081579896,50000.46508,1.351411166,66.29942164
,24.9,4.702433781,0.082809531,48718.11715,1.404193875,67.14314803
,25.2,5.32467194,0.08399096,47383.3385,1.460030054,67.89373773
,25.5,5.267973821,0.085235071,46683.87037,1.499726126,68.72431556
,25.8,5.417615235,0.08648431,46923.84495,1.508014304,69.48586186
,26.1,5.119623506,0.087782057,47819.52218,1.49972614,70.4468335
,26.4,5.317516339,0.089066521,49096.11871,1.484022186,71.56011562
,26.7,5.137666156,0.090395365,49844.19091,1.481841099,72.5375236
,27,5.381314143,0.091716379,50044.50575,1.494491474,73.46671988
,27.3,5.406136029,0.093071924,50041.55261,1.510195412,74.22826556
,27.6,5.464235694,0.094445857,49867.73114,1.533315095,75.10815285
,27.9,5.075534,0.095869763,50008.0716,1.547710406,75.95845338
,28.2,5.384066895,0.097269163,50235.15095,1.557743452,76.76273444
,28.5,5.295719901,0.098715906,50628.15587,1.564286768,77.7061744
,28.8,5.525203461,0.100163544,50730.83432,1.576064703,78.50935952
,29.1,5.436017508,0.10165396,50854.51898,1.586970224,79.3092563
,29.4,5.895133232,0.103130965,50871.54583,1.60049302,80.02039887
,29.7,5.79429177,0.104667087,51251.04871,1.605727676,80.82358301
,30,5.849035505,0.106216284,51889.57137,1.603546569,81.65306568
,30.3,5.640855237,0.107806171,52674.04874,1.597439502,82.53733485
,30.6,6.166518296,0.109371632,53616.69892,1.587406384,83.51364915
,30.9,5.829366382,0.111017736,54269.44491,1.584789092,84.40558815
,31.2,6.247690345,0.112638779,55533.13256,1.567776456,85.40929596
,31.5,5.84812863,0.114338279,57044.27963,1.545965467,86.44149105
,31.8,6.290573386,0.116007856,58539.4726,1.527644169,87.5920292
,32.1,6.197189218,0.117738155,59148.83959,1.530261501,88.63408655
,32.4,6.675402893,0.119456954,58179.73144,1.570829966,89.5095918
,32.7,6.428085608,0.121249441,57368.72005,1.606163848,90.25470067
,33,6.847217012,0.123025015,56998.25652,1.629719717,90.98008816
,33.3,6.681429724,0.124866056,57936.64987,1.618378,91.80956993
,33.6,6.870081166,0.126711589,59710.51287,1.592204755,93.09488481
,33.9,6.834081099,0.128599843,61334.87157,1.566903971,94.11173998
,34.2,7.017731422,0.130502072,62871.19135,1.547274035,95.28528856
,34.5,7.257954944,0.132429378,64143.05945,1.536804723,96.55635853
,34.8,7.672067288,0.134374425,65493.62163,1.524590516,97.80880173
,35.1,7.414729816,0.136393331,66062.42931,1.528516523,98.95057185
,35.4,7.951972485,0.138390279,66722.88384,1.529388918,100.0452272
,35.7,7.601438481,0.140475765,66946.90721,1.53985824,101.1749439
,36,7.914024314,0.142549014,67302.38305,1.548146403,102.2893225
,36.3,7.873826045,0.144677065,67721.06688,1.555125934,103.4387634
,36.6,8.300389337,0.146806443,68112.64889,1.563850307,104.6177913
,36.9,8.061326608,0.149011873,68321.12747,1.57475584,105.6795717
,37.2,8.184189954,0.151226736,68544.1406,1.586097562,106.7051942
,37.5,7.989213992,0.153496049,68623.27666,1.600056635,107.669453
,37.8,8.28596004,0.155767141,69001.93656,1.608344798,108.7049374
,38.1,8.02357905,0.158109547,69547.57001,1.612707027,109.7732923
,38.4,8.644804185,0.160429071,70256.50321,1.61183453,110.8208308
,38.7,8.224743075,0.162852166,71727.42648,1.596566854,112.0973778
,39,8.477785338,0.165267125,72316.57684,1.598747934,113.2851713
,39.3,8.761606731,0.167716749,72894.51006,1.59962035,114.3294214
,39.6,9.201011094,0.170193266,72527.71576,1.621867553,115.3868213
,39.9,8.867041258,0.172758148,72474.90198,1.637135299,116.411346
,40.2,9.615531199,0.175290451,71972.65225,1.660254912,117.2912354
,40.5,9.219979193,0.177936438,71635.11335,1.679012428,118.1053761
,40.8,9.509178298,0.180577248,71555.16345,1.691662799,118.8603485
,41.1,9.368213565,0.183286396,72345.7036,1.689045487,119.8520014
,41.4,9.585013556,0.186012777,73885.14043,1.670287991,120.9181666
,41.7,9.505605712,0.188799907,75937.796,1.643678552,122.2111508
,42,9.858012696,0.191600735,77496.02697,1.62753837,123.4767429
,42.3,9.46075748,0.194493203,78060.35774,1.628847064,124.5166079
,42.6,10.08272726,0.197362105,78557.89268,1.634081655,125.7394667
,42.9,9.806101967,0.200333832,78649.09098,1.645859628,126.8001513
,43.2,10.30658189,0.203299122,79141.96447,1.65022179,127.9101475
,43.5,10.27622208,0.206344139,79405.37557,1.65763754,128.9270031
,43.8,10.57200918,0.209413534,79549.35612,1.667234362,129.9822111
,44.1,10.65229414,0.212543664,79639.74081,1.677267425,130.985918
,44.4,10.88150425,0.215711239,79436.73064,1.691662677,131.8647102
,44.7,10.87441135,0.218942333,79592.67921,1.700823307,132.8300656
,45,11.48633802,0.222181479,79809.37166,1.706930335,133.6628375
,45.3,11.3103283,0.225521494,80617.80684,1.703440589,134.7355757
,45.6,12.2342489,0.228839451,81264.70272,1.70169562,135.6899775
,45.9,11.88100165,0.232291814,81875.86679,1.701695655,136.7342255
,46.2,12.35894005,0.235741498,82395.22877,1.703876712,137.7576576
,46.5,12.15044877,0.239288469,83174.08013,1.70038697,138.7756081
,46.8,12.680788,0.242840411,84223.53511,1.692098734,139.9151899
,47.1,12.2459686,0.246509629,84967.41213,1.689045233,141.0131293
,47.4,12.80125127,0.250168985,85843.73114,1.685119199,142.2348924
,47.7,12.71752924,0.253925645,86491.9435,1.685991648,143.3591313
,48,13.11221307,0.25770769,87151.26907,1.685991612,144.3431163
,48.3,12.97106314,0.261582131,87592.94908,1.692971151,145.4717378
,48.6,13.74430034,0.265455037,88038.17192,1.697333282,146.4502454
,48.9,13.54988213,0.269450142,88339.26181,1.704749047,147.4999728
,49.2,13.8946071,0.273470065,89542.6911,1.696024608,148.6855756
,49.5,13.35987108,0.277608523,90486.98108,1.691226237,149.8207703
,49.8,14.04487508,0.281729128,92165.68366,1.675086021,151.1871731
,50.1,13.80715246,0.285972876,93407.70326,1.666797858,152.5283697
,50.4,14.44055072,0.290223434,94798.46124,1.656328512,153.8093038
,50.7,14.469888,0.294577918,96006.76308,1.651093866,155.2272042
,51,14.70139712,0.29898482,97388.52764,1.643678101,156.6867437
,51.3,14.3687821,0.303495633,97953.6201,1.646295454,157.8811098
,51.6,14.6102541,0.308036688,97902.63434,1.659382042,159.2365534
,51.9,14.88250015,0.312644267,97335.31087,1.679884371,160.3827086
,52.2,15.84698057,0.317276083,96724.0686,1.700822854,161.4269625
,52.5,15.52597253,0.32204663,97075.31027,1.70736619,162.5018918
,52.8,15.94212275,0.326872954,98702.57597,1.694279543,163.8792512
,53.1,16.07870329,0.33177443,100574.315,1.67726694,165.1930555
,53.4,16.38999747,0.336738436,102816.6117,1.658945661,166.8958525
,53.7,16.50408959,0.341790617,104175.8436,1.651093686,168.2403376
,54,16.7962231,0.346907315,105152.4342,1.65109366,169.7568573
,54.3,16.7264131,0.352125305,105871.7077,1.652402328,171.0849054
,54.6,16.95195976,0.357402329,106136.4618,1.661562933,172.528009
,54.9,17.02024093,0.36276908,106102.9002,1.674213315,173.8757816
,55.2,17.25907451,0.368205625,106727.8735,1.677703056,175.2191723
,55.5,16.92712537,0.373761901,107031.2448,1.685555052,176.422304
,55.8,17.58610555,0.379336736,107510.2909,1.691662074,177.7448773
,56.1,18.02583349,0.385010659,107601.1099,1.702131319,178.9797897
,56.4,18.7030911,0.390754737,107568.8743,1.71303676,180.2563414
,56.7,18.51378019,0.396642627,107993.7108,1.71521788,181.358665
,57,19.12860799,0.402566117,109470.7732,1.704312317,182.8269729
,57.3,18.98045406,0.408629294,111062.5205,1.693406827,184.208713
,57.6,19.67013538,0.414728873,112972.0099,1.681192596,185.90165
,57.9,19.26652037,0.420992705,114322.8468,1.676394217,187.4784323
,58.2,19.74317343,0.427293099,115011.6218,1.67813905,188.78676
,58.5,19.87535276,0.433711351,115751.956,1.682065021,190.4117578
,58.8,20.39607261,0.440201117,115706.6107,1.69515158,191.7792565
,59.1,20.11636828,0.44684138,115623.0104,1.706493329,192.8859624
,59.4,21.24942744,0.453488973,115850.0453,1.716090068,194.2786667
,59.7,20.66184173,0.460350473,116355.4602,1.720888541,195.595755
,60,21.30064524,0.467234703,117465.5331,1.716526288,196.8701157
,60.3,21.52757953,0.474250213,117492.6,1.727867982,198.1631019
,60.6,21.82438712,0.481367121,117302.9436,1.739209685,199.2237895
,60.9,21.62612246,0.48862401,117032.3063,1.751860084,200.3644643
,61.2,22.10926927,0.495945647,117585.4073,1.752296258,201.5500683
,61.5,22.02495707,0.503415399,119259.057,1.739645883,202.9252343
,61.8,22.66781723,0.510950073,121813.2662,1.718271035,204.5721501
,62.1,22.43287237,0.518656561,123957.314,1.704312015,206.2705611
,62.4,23.39103358,0.526400598,125011.717,1.702567044,207.7432549
,62.7,23.10113796,0.534343996,124912.0168,1.715217455,209.1030791
,63,23.94610597,0.542332735,125190.9494,1.722196896,210.4727709
,63.3,23.84753789,0.550504612,125505.5498,1.727431548,211.7175426
,63.6,24.30807133,0.558762741,126014.9184,1.731793705,213.1672229
,63.9,24.93665409,0.567134373,126229.2291,1.739209385,214.4569244
,64.2,25.40546781,0.575643251,126609.2271,1.745316421,215.7466246
,64.5,25.08300499,0.584332709,127519.6833,1.744444013,217.0396082
,64.8,26.13669123,0.593062846,129005.1072,1.737464391,218.5375048
,65.1,25.64861353,0.602026473,130863.9802,1.726122718,220.1471591
,65.4,26.1847375,0.611057982,131886.8651,1.725250227,221.7929785
,65.7,26.0543875,0.620269835,132071.2386,1.731357321,223.0169307
,66,26.56134675,0.629578943,132009.2101,1.741390333,224.3658023
,66.3,26.84862896,0.639043208,132129.117,1.748369826,225.5656507
,66.6,27.58684612,0.648620778,133460.8559,1.743135114,227.1435354
,66.9,27.64277956,0.658388004,135125.3497,1.734846929,228.7893528
,67.2,28.06810876,0.668278343,137095.3873,1.721760289,230.3299799
,67.5,27.97090234,0.678352632,138892.8945,1.71390834,232.2037122
,67.8,28.7007048,0.688524687,139611.5124,1.71696181,233.8309061
,68.1,28.33636967,0.698922427,139929.0938,1.723068926,235.1556655
,68.4,28.97959212,0.7094108,139503.3445,1.739645223,236.6349323
,68.7,29.28165904,0.720080062,139750.5061,1.746188494,237.8851854
,69,29.9963848,0.73088347,139481.0121,1.759711242,239.1683137
,69.3,30.29340795,0.741877672,139814.9188,1.764509633,240.3615876
,69.6,30.90407818,0.753017252,140907.4503,1.761892254,241.913174
,69.9,31.00469028,0.764358591,143113.4983,1.746624548,243.6104923
,70.2,31.88322471,0.7757815,145339.4321,1.732665426,245.4130073
,70.5,32.10524522,0.787537894,146940.5819,1.726558326,247.1015602
,70.8,32.56604744,0.799338066,148708.8191,1.720014984,248.9270831
,71.1,32.4211008,0.811396055,150567.5734,1.712599261,250.8051981
,71.4,33.52915487,0.823553681,153272.1052,1.696022801,252.7359179
,71.7,33.46818459,0.835972125,155733.4721,1.683372431,254.8912589
,72,34.40145432,0.848512704,158401.4565,1.669849529,257.1638519
,72.3,34.15321848,0.861320532,159356.217,1.672030652,259.0331999
,72.6,34.84597211,0.874259853,159607.0129,1.683372303,261.0811622
,72.9,34.68503706,0.887450978,158781.9198,1.702129772,262.5505621
,73.2,35.26873265,0.900792272,158031.8168,1.720450949,264.1131061
,73.5,35.48297708,0.914359792,157927.6552,1.731356424,265.6449674
,73.8,36.05163146,0.928109354,159126.2844,1.730047711,267.4781616
,74.1,36.16971132,0.942096452,160729.0644,1.725249282,269.4012051
,74.4,37.09814985,0.956241078,161671.7233,1.726121632,271.1029116
,74.7,37.1949457,0.970653385,161611.7721,1.737027118,272.7443474
,75,37.63200511,0.985260871,161790.3816,1.744879032,274.4230398
,75.3,37.77449268,1.00010832,162724.7675,1.744442799,275.9603794
,75.6,38.82135551,1.015120516,164780.5621,1.735282085,277.9678021
,75.9,39.22253105,1.030402081,166541.7429,1.730047404,279.9390604
,76.2,39.9240308,1.045894686,168208.1053,1.726121364,281.9508639
,76.5,39.65285643,1.061685653,169354.6512,1.726557612,283.8059673
,76.8,40.82271091,1.077620124,171623.2463,1.716960664,285.9010517
,77.1,40.81937229,1.093872851,173668.4812,1.709981149,288.0804995
,77.4,41.26861608,1.110341083,175961.7124,1.700820492,290.2358445
,77.7,42.04647003,1.127036477,178079.3202,1.694713346,292.5796614
,78,42.81929171,1.143984361,180067.052,1.689914854,294.9322443
,78.3,42.83992247,1.161237885,181108.8269,1.691659734,296.9199361
,78.6,43.6742318,1.178698398,181495.4012,1.699075386,298.8616131
,78.9,43.86451217,1.196465348,180936.5578,1.715215497,300.8219123
,79.2,44.79025954,1.214452177,180178.9284,1.73222797,302.599228
,79.5,44.91888424,1.232763218,179507.2074,1.747059426,304.1869721
,79.8,45.60076123,1.251314452,180494.8537,1.748368019,306.0990627
,80.1,45.76174636,1.270180272,183279.4726,1.734845197,308.3486406
,80.4,46.76968702,1.289275287,186982.2894,1.71521522,310.7220451
,80.7,46.8839876,1.308717732,188745.334,1.712597893,313.0548994
,81,48.11981031,1.328380076,188314.1233,1.727429238,314.9812396
,81.3,48.15414261,1.348418759,187826.2156,1.74095204,316.5810372
,81.6,48.64770421,1.36872989,188348.6947,1.747931504,318.5851687
,81.9,48.75266168,1.389373461,190856.2456,1.737026007,320.6090219
,82.2,49.92172862,1.410258763,193144.0241,1.729173943,322.8903851
,82.5,50.24873681,1.431515188,194993.5868,1.725684157,325.2966575
,82.8,51.02831512,1.453062895,195407.8439,1.731354934,327.1287595
,83.1,51.21544045,1.474975183,196285.5057,1.734844672,329.2578056
,83.4,52.47249619,1.497148087,197683.2113,1.733535892,331.3474142
,83.7,52.27761653,1.519751713,198113.4657,1.740515422,333.4129027
,84,53.28828555,1.542617236,197809.6658,1.752293247,335.303082
,84.3,53.33208764,1.565892016,197146.3214,1.765379825,336.8382299
,84.6,54.01649237,1.58947615,196785.0858,1.7775939,338.6484167
,84.9,54.39964774,1.613436411,198234.9684,1.775412765,340.6032404
,85.2,55.42090795,1.637716722,200243.6788,1.768433155,342.4101428
,85.5,55.96785615,1.662395112,203880.2608,1.751420548,344.954483
,85.8,56.59711543,1.68744095,205075.6945,1.752292925,347.1076392
,86.1,56.95174663,1.712883392,205387.9465,1.757963741,348.809344
,86.4,58.14333276,1.738654979,205153.7325,1.768869106,350.7817073
,86.7,58.89388432,1.76484489,206299.7742,1.769305251,352.8033764
,87,59.60443579,1.791433168,209478.1694,1.754473727,355.1986945
,87.3,59.76494124,1.818550205,212190.9414,1.743132012,357.4307415
,87.6,60.49867503,1.845856149,213622.7629,1.741823283,359.6014317
,87.9,60.88620667,1.873689706,214102.6506,1.748366534,361.6943208
,88.2,62.08571143,1.901985696,214733.2455,1.754037266,363.7411954
,88.5,62.52885361,1.930664971,217559.4998,1.74487662,366.3764822
,88.8,63.60844054,1.959637698,220923.6485,1.731353722,369.0621789
,89.1,64.35014065,1.98916859,222995.5486,1.726119021,371.324914
,89.4,65.15583563,2.01914136,223933.4789,1.731353572,373.9503413
,89.7,65.46474059,2.049599558,223697.4994,1.742695239,375.807644
,90,66.54402613,2.080467202,224377.671,1.7488022,378.0144976
,90.3,66.790382,2.111856193,225433.6431,1.752291929,380.3594093
,90.6,67.66317614,2.143678095,228204.0763,1.744003682,383.0571577
,90.9,68.20974067,2.176002116,230939.134,1.733970592,385.4064556
,91.2,69.31950712,2.208778875,234461.9723,1.720883914,388.3255481
,91.5,69.76149605,2.242095119,237374.3029,1.711723273,391.1460181
,91.8,71.37863783,2.275837256,239148.2018,1.71085068,393.978552
,92.1,71.75972829,2.310168642,239921.008,1.71652149,396.6138404
,92.4,72.95986319,2.344964239,240572.0887,1.723500877,399.0475162
,92.7,73.49679207,2.380328949,241321.3875,1.730916547,401.6214444
,93,74.74751187,2.416180617,242814.2341,1.733097515,404.2698892
,93.3,75.37828829,2.452614943,243452.1292,1.738332084,406.467974
,93.6,76.30101731,2.489580266,244480.6419,1.742257964,409.2183212
,93.9,76.80681398,2.527131601,245377.9886,1.745747667,411.69363
,94.2,78.17948838,2.565193117,246170.36,1.750545937,414.1689489
,94.5,78.52119488,2.603897765,247943.8432,1.749237251,416.644256
,94.8,79.81214655,2.6431244,249406.6687,1.750545775,419.2455857
,95.1,80.63540708,2.682974708,250881.5077,1.751418136,421.8436228
,95.4,81.44442749,2.723427928,252167.9023,1.752290492,424.2455203
,95.7,81.96131074,2.764511587,253485.474,1.754035317,426.8413625
,96,82.9398679,2.806185594,256721.216,1.744874629,429.7253922
,96.3,83.63377318,2.848507896,259066.8516,1.740512375,432.2543968
,96.6,85.05726066,2.891421435,261801.9545,1.735277612,435.3049871
,96.9,85.49469821,2.93504839,263564.1102,1.734841351,438.2306506
,97.2,86.9970198,2.979264502,263985.6701,1.741384483,440.9251225
,97.5,87.50746429,3.024213978,263121.7295,1.75447099,443.1692302
,97.8,89.13354296,3.069768795,260638.5607,1.777590411,445.1459856
,98.1,90.20122504,3.116048874,259642.6992,1.792421733,447.0460335
,98.4,91.01170102,3.163045101,260187.0567,1.798092491,449.0359287
,98.7,92.01010116,3.210738808,264504.4607,1.782388527,451.8070997
,99,93.28128996,3.259135329,269393.561,1.764067227,454.9059013
,99.3,93.64046612,3.308323204,273241.1492,1.750544421,457.6781604
,99.6,95.09612939,3.358181755,277068.8829,1.739638819,461.0410417
,99.9,95.27451888,3.408877781,280034.2116,1.733095526,464.2198227
,100.2,96.89634495,3.460244516,283785.1422,1.723934784,467.6287271
,100.5,97.78919622,3.512435503,286791.6895,1.718700078,470.8458699
,100.8,99.38830874,3.565368461,289798.7618,1.714337741,474.2810723
,101.1,99.97638738,3.61916795,291789.6183,1.714773902,477.5782005
,101.4,101.4803929,3.673719682,294184.8907,1.712592666,480.8972536
,101.7,102.5183351,3.729126437,294346.3019,1.721753148,483.9588016
,102,104.0903021,3.785335124,294084.839,1.733530886,486.934885
,102.3,104.6487315,3.842459823,291440.8307,1.755777956,489.0233986
,102.6,106.2886519,3.900376204,290377.1224,1.771481645,491.6061075
,102.9,106.8626135,3.959237779,291299.4038,1.775407551,494.2085301
,103.2,109.0206027,4.018884269,293972.6695,1.769300283,496.7561835
,103.5,109.5085813,4.07954215,297321.2761,1.762320746,500.1070032
,103.8,111.1570841,4.141039969,299242.7754,1.762320583,503.0578863
,104.1,112.1015491,4.203513195,301616.3252,1.759703181,506.1062852
,104.4,113.7813707,4.266881849,304655.7607,1.753595964,509.2346827
,104.7,114.4509663,4.331274398,308217.6998,1.745307758,512.6644005
,105,116.0231502,4.396580171,310262.7573,1.744871386,515.8640194
,105.3,117.2232283,4.463120292,309560.7171,1.756649149,518.3513977
,105.6,118.7734987,4.530193368,308001.0612,1.774097707,520.9647896
,105.9,120.0323279,4.598756481,308738.734,1.778895977,523.5836588
,106.2,121.1728816,4.668135558,312499.616,1.769299073,526.7843689
,106.5,122.8715922,4.738289214,318806.605,1.747924237,530.5154348
,106.8,124.5010387,4.809744392,324428.2202,1.732220242,534.4481149
,107.1,125.3898151,4.882327888,328977.547,1.72218715,538.356682
,107.4,127.0888053,4.95595441,332174.6208,1.718697244,542.0121381
,107.7,128.4781068,5.030713919,333307.7904,1.72393172,545.5109012
,108,130.0976983,5.106587878,334103.9534,1.730474825,548.9592599
,108.3,131.3210657,5.183634232,334628.4296,1.736145533,551.9364427
,108.6,133.2202642,5.261802371,339327.567,1.725676129,556.2175781
,108.9,134.3925048,5.341201323,345802.721,1.707791102,560.7211459
,109.2,136.2451471,5.421755058,351203.8778,1.696885489,565.2784105
,109.5,137.4806532,5.503564122,353729.6474,1.697757806,569.2220505
,109.8,139.2796569,5.586568656,352933.6453,1.713025238,572.7887541
,110.1,140.195688,5.67088485,350118.1525,1.735708447,575.876606
,110.4,141.8095814,5.756427958,349793.8063,1.747049936,579.0466442
,110.7,143.3101146,5.843270703,348316.3965,1.762753606,581.9000145
,111,145.3795406,5.931387755,350544.0263,1.762753398,585.3670099
,111.3,146.5177248,6.020897623,353444.8844,1.758827336,588.6214197
,111.6,148.3088293,6.111716589,361615.214,1.734835214,593.4427656
,111.9,150.0264979,6.203912488,368976.2199,1.715641502,598.2750691
,112.2,152.1624507,6.29747369,373218.7817,1.709534253,602.8202925
,112.5,153.7041166,6.392487623,372002.154,1.724801696,606.2938589
,112.8,155.4427429,6.48892421,368607.0591,1.747921018,608.9379431
,113.1,157.296788,6.586810132,366590.653,1.766241951,611.958969
,113.4,159.1248053,6.686176499,368033.7499,1.771040146,615.580468
,113.7,160.9966808,6.787041273,368800.0722,1.776710784,618.7143576
,114,162.571283,6.889449554,370345.7873,1.77845549,621.6729202
,114.3,164.1298309,6.993406089,374145.6381,1.771912085,625.4642589
,114.6,166.1049703,7.098905883,383536.89,1.744866455,630.4959962
,114.9,167.672167,7.206026548,392157.0897,1.722183039,635.475135
,115.2,170.388956,7.314689781,396980.828,1.713894661,639.5634407
,115.5,171.6610995,7.425090166,398095.7656,1.721746434,644.1152313
,115.8,173.8165814,7.537100175,399341.9978,1.727417037,648.3448809
,116.1,175.6639472,7.650822794,401350.4606,1.728289289,652.005834
,116.4,177.7132201,7.766250334,404756.3918,1.726544224,656.8008908
,116.7,179.1981074,7.883458726,406770.4522,1.730470025,661.0973755
,117,181.8059374,8.002364105,408909.8536,1.732214635,664.8449031
,117.3,183.5822955,8.123120694,414582.2329,1.723053921,669.9401998
,117.6,185.6104648,8.245685148,419477.8587,1.715201832,674.5654171
,117.9,187.3013724,8.370123432,425269.6558,1.70604113,679.8853432
,118.2,189.836479,8.496386208,427488.8494,1.709530614,684.8119039
,118.5,191.7738933,8.624596172,427615.1888,1.719127177,688.8651417
,118.8,194.1228481,8.754715986,425587.7071,1.736575586,692.7967558
,119.1,195.9098784,8.886838734,426040.8076,1.745299727,696.8368429
,119.4,198.5152962,9.020903802,426711.898,1.75358757,701.162931
,119.7,200.3357995,9.157045962,427182.4983,1.75969441,704.525846
,120,203.0146173,9.295188475,428438.4878,1.763620084,708.5352653
,120.3,204.4825182,9.435497931,429641.7632,1.768854525,712.5742532
,120.6,206.7479862,9.57787454,432515.0904,1.767981867,716.4565587
,120.9,208.7793154,9.722417627,436273.9403,1.765364369,720.7125174
,121.2,211.5482959,9.86909595,440613.5924,1.760565722,725.1459976
,121.5,213.7378402,10.01802858,447483.2804,1.746606609,729.9060082
,121.8,216.2024241,10.16919309,457659.4487,1.723923166,735.7201389
,122.1,218.5484982,10.32264923,464022.3877,1.714326199,741.2493749
,122.4,221.379269,10.47839215,466408.8197,1.717379431,745.9885759
,122.7,223.2095819,10.63655381,462780.8539,1.739626227,750.1141389
,123,225.7359121,10.79705924,461950.9553,1.752712432,754.1849237
,123.3,228.496485,10.95997431,463812.1982,1.755765663,758.2458584
,123.6,231.5985361,11.1258858,467585.6633,1.754020494,763.1713469
,123.9,233.5912884,11.29326336,471859.981,1.750094361,768.153798
,124.2,236.6576808,11.46366322,474574.1053,1.750966486,772.8842419
,124.5,238.5363775,11.63671604,479943.9114,1.743550647,777.7976581
,124.8,241.6061043,11.81230501,485798.3093,1.735698478,783.3543058
,125.1,243.7244155,11.99060945,491042.8611,1.730027477,788.8835447
,125.4,246.8457084,12.17154198,494454.4812,1.728282312,793.7093233
,125.7,249.2468732,12.35525576,499277.6177,1.72479236,799.3854022
,126,252.4130497,12.54169751,504011.7995,1.723047192,805.001224
End Of Loading Marker,126.244,254.4019263,12.69545634,505896.0929,1.725664283,808.7125993
,126.6,256.9632713,12.69719323,504806.8888,1.741803967,814.6056397
,126.9,257.8506916,12.6971358,504039.5485,1.753145453,819.2166103
,127.2,258.8624979,12.69707024,508064.1701,1.749219425,823.7596391
,127.5,259.454137,12.69703217,517701.9033,1.733079439,830.3922753
,127.8,260.7288598,12.6969494,530480.6781,1.709523744,837.3328276
,128.1,260.458532,12.69696775,538515.5479,1.700363271,843.8339535
,128.4,261.2956153,12.69691362,540225.8956,1.70734262,849.2513916
,128.7,261.4246544,12.69690583,538162.5283,1.723918756,854.2294261
,129,261.8324182,12.6968798,531771.5438,1.751400208,858.3209912
,129.3,262.4332094,12.69684114,527726.3197,1.770593582,861.7934605
,129.6,262.6695783,12.69682633,524032.6398,1.79022319,865.7162774
,129.9,262.7029357,12.6968248,520063.3224,1.809416622,868.9465708
,130.2,263.5766275,12.69676828,514873.1256,1.832099665,871.6443466
,130.5,263.616641,12.69676632,511945.5025,1.846930954,874.0243324
,130.8,263.6358542,12.69676572,511716.6671,1.853910368,876.9324728
,131.1,263.8431026,12.69675281,519563.1366,1.836898007,881.2530492
,131.4,264.1518567,12.69673326,527920.0124,1.818576969,885.7566196
,131.7,264.0853725,12.69673827,533555.8397,1.809852698,890.3938632
,132,264.2709885,12.69672678,533692.161,1.816832107,894.1468344
,132.3,264.3800592,12.6967203,533127.3078,1.825120166,897.2390692
,132.6,264.8027993,12.69669329,536926.9062,1.822066624,901.5618374
,132.9,264.5141672,12.69671284,542371.1227,1.8142148,906.0993668
,133.2,265.2539046,12.69666508,544477.6211,1.815959582,910.1986098
,133.5,264.8912234,12.69668948,540611.1982,1.833844401,912.9807333
,133.8,265.3821886,12.696658,533955.1901,1.859580986,915.0035108
,134.1,264.9571062,12.69668648,527969.9086,1.882700384,916.5266058
,134.4,265.3607099,12.69666073,524557.7751,1.89709541,917.970819
,134.7,265.3266742,12.69666361,526154.4136,1.896222986,920.3825848
,135,266.0730677,12.69661542,532174.2186,1.882264055,923.6852118
,135.3,265.6172009,12.69664591,538264.9448,1.868305251,927.0502754
,135.6,266.1015099,12.69661487,540252.1574,1.868305201,930.2411295
,135.9,265.9002394,12.6966287,537478.088,1.882264076,932.2299299
,136.2,266.1715529,12.69661161,528030.7476,1.915416324,932.6309763
,137,266.0963311,12.5639605,1.7977E+308,1.832971862,0
,137.3,266.0451389,12.37354664,1.7977E+308,1.486617834,0
,137.6,265.5047223,12.1831648,1.7977E+308,0.974066236,0
,137.9,265.1856215,11.99276847,1.7977E+308,0.374707978,0
,138.2,264.8998013,11.80236996,1.7977E+308,0.103382762,0
,138.5,264.612317,11.61197157,1.7977E+308,0.057580273,0
,138.8,263.9579145,11.42159718,1.7977E+308,0.04144035,0
,139.1,263.7977284,11.23119045,1.7977E+308,0.038386851,0
,139.4,263.331361,11.04080377,1.7977E+308,0.031843639,0
,139.7,262.9357149,10.85041245,1.7977E+308,0.030098782,0
,140,262.9369395,10.65999516,1.7977E+308,0.037950639,0
,140.3,262.2567445,10.46962246,1.7977E+308,0.040567926,0
,140.6,261.7595925,10.27923779,1.7977E+308,0.03882307,0
,140.9,261.5762109,10.08819785,1.7977E+308,0.032716071,0
,141.2,260.8244626,9.897829841,1.7977E+308,0.028790143,0
,141.5,260.3289746,9.707445058,1.7977E+308,0.026172858,0
,141.8,260.3342584,9.517662225,1.7977E+308,0.026172859,0
,142.1,259.8970115,9.32727363,1.7977E+308,0.029226359,0
,142.4,259.3565947,9.136891788,1.7977E+308,0.030535003,0
,142.7,259.2746179,8.94647994,1.7977E+308,0.03315229,0
,143,258.8764756,8.756088786,1.7977E+308,0.023555575,0
,143.3,258.3543631,8.565705746,1.7977E+308,0.022246932,0
,143.6,257.9162841,8.375317205,1.7977E+308,0.035769579,0
,143.9,257.5156457,8.184926214,1.7977E+308,0.035333365,0
,144.2,257.2631059,7.99452553,1.7977E+308,0.024428006,0
,144.5,257.1262161,7.804117277,1.7977E+308,0.021374505,0
,144.8,256.6615125,7.613730479,1.7977E+308,0.027045293,0
,145.1,256.0312381,7.423354518,1.7977E+308,0.022246936,0
,145.4,255.7354335,7.232956666,1.7977E+308,0.023119365,0
,145.7,255.4512771,7.042558051,1.7977E+308,0.025300438,0
,146,254.9740933,6.85217207,1.7977E+308,0.027045296,0
,146.3,254.4211961,6.661791045,1.7977E+308,0.017448579,0
,146.6,254.0596623,6.471397494,1.7977E+308,0.008288075,0
,146.9,253.5059332,6.281016523,1.7977E+308,0.025736655,0
,147.2,253.237585,6.090616874,1.7977E+308,0.04362145,0
,147.5,252.6788637,5.90023623,1.7977E+308,0.050600884,0
,147.8,252.1925276,5.709850848,1.7977E+308,0.054526816,0
,148.1,251.8176815,5.519458169,1.7977E+308,0.046674956,0
,148.4,251.4578117,5.32906451,1.7977E+308,0.039695524,0
,148.7,251.1120861,5.138669925,1.7977E+308,0.028790161,0
,149,250.3495211,4.948302622,1.7977E+308,0.030971235,0
,149.3,250.0287559,4.757906404,1.7977E+308,0.034897167,0
,149.6,249.6913504,4.567511274,1.7977E+308,0.026172876,0
,149.9,249.1367891,4.377130358,1.7977E+308,0.013522653,0
,150.2,248.8726009,4.186730436,1.7977E+308,0.02835395,0
,150.5,248.1932372,3.996357688,1.7977E+308,0.038386888,0
,150.8,247.757654,3.805968984,1.7977E+308,0.03664203,0
,151.1,247.1856202,3.615589212,1.7977E+308,0.022246948,0
,151.4,246.9680248,3.42518624,1.7977E+308,0.018321016,0
,151.7,246.0423846,3.234829611,1.7977E+308,0.010032938,0
,152,245.7723723,3.044430071,1.7977E+308,0.013522656,0
,152.3,245.282708,2.854044907,1.7977E+308,0.024864239,0
,152.6,244.6332967,2.663670199,1.7977E+308,0.035769608,0
,152.9,243.9913735,2.473295,1.7977E+308,0.037950683,0
,153.2,243.4717566,2.282911797,1.7977E+308,0.03751447,0
,153.5,243.0162048,2.0925244,1.7977E+308,0.026609101,0
,153.8,242.5481728,1.90213782,1.7977E+308,0.017884806,0
,154.1,241.9545064,1.711759463,1.7977E+308,0.008724296,0
,154.4,241.0138897,1.521403814,1.7977E+308,0.006107008,0
,154.7,240.24134,1.331037166,1.7977E+308,0.004798363,0
,230,239.6285389,1.146537225,1.7977E+308,0.005234579,0
,230.3,238.9598901,0.956798502,1.7977E+308,0.010905374,0
,230.6,238.4510891,0.76641459,1.7977E+308,0.010905374,0
,230.9,237.5529048,0.576056164,1.7977E+308,0.005670795,0
,231.2,236.8323557,0.385686112,1.7977E+308,0.010905375,0
,231.5,235.6566941,0.195345848,1.7977E+308,0.013958881,0
,231.8,234.6545077,0.004994229,1.7977E+308,0.017012387,0
,231.806,234.6170415,0.001188337,1.7977E+308,0.017448602,0
END,,,,,,