File: GB1_test 47.csv
Segment,Time On Sample,Displacement Into Surface,Load On Sample,Harmonic Contact Stiffness,Harmonic Displacement,Harmonic Load
Surface Marker,0,0,0,-335.2859422,0.512565812,2.186005814
,0.3,0.259912867,0.000967896,3974.390063,0.292707791,2.284622634
,0.59,0.522047525,0.001904457,10885.61846,0.211569712,2.40405856
,0.9,0.533455945,0.00291779,16643.03529,0.161403698,2.565132674
,1.2,0.269601798,0.003917987,22216.25452,0.128250508,2.74154716
,1.5,0.665553037,0.004874972,27915.98915,0.107747873,2.907004276
,1.8,0.545225023,0.005867406,34997.11079,0.099459576,3.38146067
,2.1,0.497700772,0.006851798,40091.07109,0.097714671,3.831810743
,2.4,0.928181543,0.007806521,42106.51696,0.104694288,4.312841648
,2.7,0.778732495,0.008799225,48318.75121,0.111237682,5.262850192
,3,0.865997985,0.009776426,49776.42396,0.127814278,6.209571538
,3.3,0.817641697,0.010760872,45796.43602,0.16096747,7.258196898
,3.6,0.832935202,0.011747698,43604.29103,0.191503304,8.310109483
,3.9,0.940170102,0.012720316,42135.88735,0.23774328,9.996456911
,4.2,0.978345406,0.013700732,41328.67344,0.277439864,11.44721969
,4.5,0.83097645,0.0146933,39545.65068,0.322807392,12.67445102
,4.8,0.924066199,0.015670119,38020.49129,0.38955,14.57446814
,5.1,0.674356686,0.01666939,36860.85969,0.447131865,16.12384766
,5.4,0.42714328,0.017668497,35210.86946,0.511257125,17.55926988
,5.7,0.907962297,0.018619923,33007.02729,0.595012543,19.11851144
,6,0.592521856,0.019623499,29739.88281,0.704505333,20.37751906
,6.3,0.542501232,0.020609691,25757.27265,0.858929415,21.56749525
,6.6,1.046617284,0.021559593,21936.64353,1.032547419,22.28411086
,6.9,1.24953592,0.022529218,18307.89764,1.24106353,22.74870585
,7.2,1.17954641,0.023516717,16165.59789,1.405957039,23.1026305
,7.5,1.819284477,0.024457734,15365.94078,1.489712416,23.4664174
,7.8,1.382366647,0.025469263,16680.03606,1.426895882,24.3386279
,8.1,1.573636762,0.026439652,18570.155,1.340523081,25.3237004
,8.4,1.371353367,0.027435814,20255.33767,1.280323882,26.23754926
,8.7,1.358774413,0.028419553,21167.75866,1.268545779,27.20618556
,9,1.664865636,0.02938242,21109.96165,1.300390263,27.82528011
,9.3,1.371890207,0.030384522,20894.46238,1.342268004,28.49039558
,9.6,1.440018844,0.031362974,20732.4661,1.381092129,29.06785166
,9.9,1.929158207,0.032313854,20652.20821,1.414681514,29.65516998
,10.2,1.638678893,0.033315792,20619.92333,1.444781136,30.21838128
,10.5,2.107849364,0.03426798,20340.63727,1.483605235,30.6413382
,10.8,2.200939108,0.035244797,20145.84554,1.520684446,31.11798619
,11.1,2.519510873,0.036206845,20619.65045,1.514141036,31.66476188
,11.4,2.625913207,0.03718279,22367.96497,1.438237668,32.44273902
,11.7,2.404492974,0.038180203,25056.40031,1.332234734,33.34124752
,12,2.135646629,0.039180724,28252.59703,1.227540462,34.38220247
,12.3,2.669715972,0.040128659,30293.2449,1.183045362,35.38371147
,12.6,2.531499436,0.041120623,30966.51075,1.183481598,36.22962433
,12.9,2.578827146,0.042100436,31092.81324,1.207910261,37.09635669
,13.2,2.897398905,0.043062484,31407.51987,1.224050608,37.92912104
,13.5,2.346492032,0.044081476,31517.94993,1.244989502,38.64464037
,13.8,2.405468259,0.045060526,31182.9798,1.285994759,39.45548956
,14.1,2.734856503,0.046021866,31131.63518,1.309550949,40.11183969
,14.4,2.952751789,0.046990508,31118.38648,1.334415825,40.85694458
,14.7,2.555771758,0.047999418,31515.47383,1.345321509,41.69737873
,15,2.888488147,0.04896054,31740.42344,1.360153174,42.4315263
,15.3,2.717822171,0.049954629,31754.44504,1.383273175,43.12732254
,15.6,2.725212106,0.050937056,31870.28291,1.398541091,43.78586359
,15.9,2.619028994,0.051926922,32083.81398,1.408138075,44.52329817
,16.2,3.017060284,0.052883765,32627.05213,1.404212009,45.31552023
,16.5,3.034850681,0.053865512,33194.1326,1.396796164,46.04966775
,16.8,3.196999489,0.054837803,33759.57439,1.395923699,46.91420851
,17.1,3.18899674,0.055821238,33941.90093,1.408574259,47.67355811
,17.4,3.135647977,0.056807644,33601.38891,1.442163678,48.33319471
,17.7,3.115580693,0.057791869,32960.74654,1.487531201,48.87010859
,18,3.309346904,0.05876209,32260.97179,1.537260967,49.37524597
,18.3,3.288447583,0.059746369,32062.10701,1.564743218,49.90120238
,18.6,3.173112067,0.060736834,32229.33058,1.572595299,50.43702004
,18.9,3.422624754,0.061703403,32789.63897,1.562998303,51.09227451
,19.2,3.418366172,0.062686593,33210.15526,1.559944721,51.65548589
,19.5,3.746922363,0.063647985,33495.9388,1.56474318,52.28225111
,19.8,3.472251778,0.064648883,33432.52435,1.587426965,52.84874934
,20.1,3.772518713,0.065612128,32947.29632,1.623197483,53.22678105
,20.4,4.097330733,0.066573764,32466.19251,1.660712902,53.607004
,20.7,4.201236247,0.067554287,33093.53234,1.6491529,54.15980631
,21,4.081737533,0.068564028,34943.52086,1.588735592,54.90107567
,21.3,4.316683605,0.069569025,38520.12662,1.477497908,55.98805264
,21.6,3.582720734,0.070649768,42042.08567,1.388071609,57.21199547
,21.9,4.301492424,0.071647331,43729.44467,1.360153081,58.25185622
,22.2,4.06757881,0.072726368,43737.57739,1.378910824,59.10982201
,22.5,4.44188159,0.073781844,42724.56722,1.423842087,59.74206612
,22.8,4.399331302,0.074880831,42910.73637,1.436928875,60.65262773
,23.1,4.111327469,0.076012613,43497.85589,1.436492672,61.54894482
,23.4,4.259308325,0.07713252,43937.1152,1.441727375,62.40471964
,23.7,4.548732756,0.078260129,43366.39294,1.480987704,63.21118665
,24,4.445433041,0.079430619,42216.48597,1.536388432,63.80069549
,24.3,4.633343475,0.080599441,41873.61057,1.565615567,64.39458855
,24.6,4.721406638,0.081792678,42534.72445,1.559508394,65.12106563
,24.9,4.919295807,0.082996736,44654.79996,1.51195973,66.22228743
,25.2,4.684522881,0.084247459,47143.4519,1.456559033,67.35857157
,25.5,4.88490229,0.085488289,48654.87893,1.431694128,68.31953827
,25.8,4.929687777,0.086758328,49527.22884,1.428640543,69.3802167
,26.1,4.940356724,0.088049651,49485.49033,1.449143175,70.3050236
,26.4,4.923565354,0.089362272,48555.30932,1.493638232,71.07204295
,26.7,4.909266945,0.09069455,47947.21058,1.529408783,71.89384978
,27,5.158721036,0.092029618,47636.23339,1.554709874,72.638955
,27.3,5.388203023,0.093386232,47835.28397,1.563870607,73.42898582
,27.6,5.160893468,0.094793528,48142.66733,1.569977787,74.20148372
,27.9,5.396193087,0.096191445,48333.63852,1.580010973,74.97179111
,28.2,5.222127181,0.097637478,48821.57565,1.580883434,75.79907624
,28.5,5.245250587,0.099092144,49518.2689,1.573903822,76.57814911
,28.8,5.503836925,0.100553407,50276.93293,1.568232855,77.5095307
,29.1,5.739122693,0.102038435,51218.50666,1.558635868,78.44091225
,29.4,5.738106429,0.103561369,51574.61221,1.566051702,79.2824424
,29.7,6.075725538,0.10508491,52383.49212,1.562998097,80.26970726
,30,6.003146775,0.106658653,52805.04043,1.567796586,81.14410933
,30.3,6.169358815,0.108240469,53892.89399,1.554709794,82.12370357
,30.6,6.182472257,0.109856342,54671.19012,1.548602628,83.03864822
,30.9,6.56667025,0.111472262,55966.61378,1.531589779,84.10042385
,31.2,6.623041835,0.113134194,56947.74993,1.524610157,85.17205964
,31.5,6.740980185,0.114816995,57886.07361,1.518939209,86.24698374
,31.8,6.671706182,0.116537674,58410.11543,1.524610154,87.36244901
,32.1,6.49675937,0.11829127,58673.57326,1.534207144,88.35847863
,32.4,6.538969984,0.120056958,58684.71442,1.550783732,89.32711477
,32.7,6.686012986,0.121842519,58515.84188,1.570413894,90.14344353
,33,6.679124902,0.123665055,59116.88089,1.572595026,91.1274199
,33.3,6.72298669,0.125511783,59504.7728,1.578265961,92.04565245
,33.6,7.11921166,0.127363124,61022.47315,1.558635754,93.26083155
,33.9,7.255004616,0.129259794,62076.46453,1.549911222,94.39054268
,34.2,7.320069874,0.131189854,63078.09623,1.5429316,95.50381678
,34.5,7.228707606,0.133159168,63871.1525,1.539878026,96.49984679
,34.8,7.351174073,0.135144158,64335.8694,1.547730085,97.64708909
,35.1,7.184919022,0.137177968,65239.96771,1.544676518,98.80309728
,35.4,7.454230356,0.139213888,65804.51042,1.54860253,99.91198899
,35.7,7.864150977,0.141271558,66727.90422,1.545985139,101.1874348
,36,7.479055487,0.143412641,67318.91161,1.549474981,102.3204309
,36.3,7.923495572,0.145531349,67814.88028,1.555582108,103.4041219
,36.6,8.113327308,0.147698789,67727.51193,1.575212264,104.5206836
,36.9,8.250319481,0.14990258,67784.81765,1.589607713,105.5309589
,37.2,7.913877428,0.152170832,67885.00093,1.601385847,106.5390406
,37.5,8.513055331,0.154411545,68552.5176,1.59964089,107.5000089
,37.8,8.395844148,0.156733476,69331.17262,1.598332223,108.6658783
,38.1,8.675924974,0.159064175,69991.89978,1.599640876,109.7703878
,38.4,8.814553928,0.161439534,70673.15876,1.600949543,110.931875
,38.7,9.085471022,0.163842056,71039.01389,1.607056684,111.9706401
,39,8.943276079,0.166308198,72057.97686,1.600077081,113.1945835
,39.3,9.153441438,0.168796829,72906.02609,1.597459706,114.4229121
,39.6,8.891006613,0.171337384,73463.41709,1.600513313,115.5263233
,39.9,9.186028979,0.173888006,73110.63738,1.623633267,116.5409823
,40.2,9.003456098,0.176508763,72254.0856,1.654605332,117.2718413
,40.5,9.310946599,0.179136667,71642.65489,1.681651318,118.0969372
,40.8,9.327217897,0.181823627,72209.90221,1.683396221,119.1028283
,41.1,9.398397164,0.184547597,73425.94003,1.669000756,120.0758481
,41.4,9.482882468,0.187311892,75282.99268,1.644572092,121.356771
,41.7,9.454204155,0.190125293,75861.25887,1.645008322,122.3933438
,42,9.517875186,0.192974968,75814.90501,1.659840001,123.4123842
,42.3,9.66058287,0.195862451,74917.73034,1.691248262,124.2078942
,42.6,9.983835553,0.19878188,74757.42608,1.706516142,124.9924462
,42.9,9.937656945,0.20176959,74761.82415,1.71829425,125.8394557
,43.2,9.832396551,0.204806352,75110.87266,1.72265652,126.728102
,43.5,10.08240856,0.207865513,75319.39793,1.728327435,127.4819741
,43.8,10.08613034,0.210987171,75716.77551,1.731381018,128.3980144
,44.1,10.24210737,0.214145749,76255.22409,1.729636105,129.1935243
,44.4,10.65351207,0.217335343,77024.61528,1.724837571,130.1523002
,44.7,10.87603675,0.2205857,77501.91546,1.72483756,130.9872571
,45,10.97458014,0.22389344,78151.61415,1.722220187,131.9558938
,45.3,11.18710464,0.227243431,78917.06097,1.716985464,132.9354885
,45.6,11.59847782,0.23063114,79742.58479,1.710442022,133.8668712
,45.9,11.49481217,0.234104024,81019.67053,1.697791491,134.9911026
,46.2,11.6848471,0.237610121,82105.64032,1.689939399,136.0945161
,46.5,11.72261095,0.241178974,83310.08941,1.679469976,137.1628652
,46.8,11.91346095,0.244791684,84293.96964,1.675107697,138.3955763
,47.1,12.26738145,0.248448314,84872.92184,1.676852578,139.5055649
,47.4,12.10792656,0.252194026,85634.72397,1.675543908,140.6593812
,47.7,12.5799785,0.255954558,86642.10218,1.669872928,141.8077216
,48,12.54780718,0.259805373,87790.85043,1.663329542,143.0930272
,48.3,12.64542435,0.263705618,88674.33808,1.661148404,144.3213551
,48.6,12.93772872,0.267651965,89364.27762,1.661148378,145.4609283
,48.9,13.49377919,0.271640592,90174.06075,1.660712101,146.7484288
,49.2,13.33842879,0.275736496,90850.91911,1.660712116,147.8485531
,49.5,13.61572758,0.279865686,92228.28217,1.651551347,149.2565839
,49.8,13.6400773,0.284074206,93552.64847,1.642826827,150.5605172
,50.1,13.91402789,0.288329753,94823.60326,1.636719639,151.9773144
,50.4,13.62301546,0.292686718,95287.12949,1.643263055,153.281246
,50.7,13.95768408,0.297068083,94850.34586,1.662456966,154.3747992
,51,14.00279348,0.301534653,94453.59346,1.680778451,155.5154669
,51.3,14.70436897,0.306025367,94583.26344,1.689939129,156.6670959
,51.6,14.58013741,0.310638478,94952.24583,1.694301401,157.7540718
,51.9,15.00295877,0.315285291,95352.66525,1.699972298,158.9352845
,52.2,15.03845597,0.320027829,95405.48993,1.711314169,160.0025375
,52.5,15.13634453,0.324837898,95790.29251,1.716112645,160.967888
,52.8,15.09568744,0.329729827,96426.91509,1.718730005,162.1699168
,53.1,15.32501447,0.334677745,96923.3633,1.721783565,163.2667569
,53.4,15.43576442,0.339708222,96875.29263,1.733125428,164.3066167
,53.7,15.78737684,0.344798841,96371.72901,1.750574429,165.148149
,54,15.58317668,0.350002965,95427.72681,1.775439325,165.8932524
,54.3,16.12654879,0.355236377,95017.22585,1.789834725,166.5298822
,54.6,16.51098933,0.360559551,95405.29846,1.792452043,167.4546903
,54.9,16.93826552,0.365969332,97140.05262,1.77151316,168.5329036
,55.2,16.65954872,0.371489074,99892.39928,1.73661512,169.856559
,55.5,16.83386104,0.377071527,102927.4556,1.702153262,171.4815465
,55.8,16.91164373,0.382744711,105123.5664,1.682523092,172.975044
,56.1,17.16538849,0.388491992,106101.2362,1.680778166,174.2965114
,56.4,17.35630069,0.394330269,106920.6472,1.6816506,175.6749561
,56.7,17.72400662,0.400245003,107668.1325,1.682523018,176.988754
,57,17.20890451,0.406327577,108695.5006,1.679905712,178.4449932
,57.3,17.77128142,0.412390078,109750.5209,1.676852079,179.9242491
,57.6,18.03909957,0.418584501,109770.2087,1.6877577,181.1755881
,57.9,18.57897874,0.424854412,109706.8228,1.699971973,182.4565141
,58.2,18.57635516,0.431254794,109624.0527,1.710877619,183.5150014
,58.5,18.58702877,0.437751127,110172.0785,1.714367425,184.8178401
,58.8,19.42140276,0.444291147,111075.9378,1.711749991,186.0965759
,59.1,19.48612744,0.450980797,112052.0146,1.709568857,187.4958399
,59.4,19.49259349,0.457775417,113008.3098,1.708260179,188.8819544
,59.7,19.96082339,0.464642135,113724.225,1.710005038,190.1650721
,60,19.89320541,0.47164802,114366.4723,1.713494852,191.4974946
,60.3,20.64845447,0.478705569,114647.8145,1.721346844,192.7839012
,60.6,20.49926318,0.485929241,114677.5258,1.730943826,193.8895044
,60.9,21.11053568,0.493211781,115877.5223,1.725272833,195.2997291
,61.2,20.96463771,0.500654339,118049.8467,1.707387591,196.8940338
,61.5,21.52844877,0.508162515,120825.8871,1.682522671,198.5376516
,61.8,21.4465817,0.515826657,122227.4483,1.678596643,200.288648
,62.1,21.91883238,0.523569779,121715.4646,1.697790541,201.6638079
,62.4,22.1139964,0.531448185,120717.2135,1.720038025,202.6488818
,62.7,22.4963496,0.539433438,119961.5528,1.740976834,203.880499
,63,22.38695026,0.547571719,120625.9641,1.741849285,205.1570388
,63.3,22.96396124,0.55578752,122697.9452,1.725708887,206.7425821
,63.6,23.24641164,0.56414712,124785.124,1.709568505,208.2810067
,63.9,23.60455723,0.572628074,127094.8768,1.692991899,210.0867931
,64.2,23.66564557,0.581256735,127836.8596,1.694300563,211.4904402
,64.5,23.99046863,0.589998336,127917.6874,1.70476996,212.9992801
,64.8,24.37351324,0.598868057,127480.0721,1.722218947,214.406216
,65.1,24.88883026,0.607863102,127463.1113,1.731815863,215.5468881
,65.4,25.13288191,0.617011985,128371.5904,1.73137961,216.9823125
,65.7,25.63401075,0.626281969,129400.2421,1.729198438,218.4188348
,66,25.49278549,0.635734456,131503.2617,1.715239232,220.1270966
,66.3,26.06792055,0.6452825,133462.3095,1.704333537,221.8912471
,66.6,26.32935505,0.654995743,134925.303,1.69953503,223.541437
,66.9,26.82040818,0.664840421,134740.5781,1.713494204,225.0185024
,67.2,27.22157773,0.674840004,134562.2728,1.726580934,226.4276295
,67.5,27.39224933,0.685005665,134520.2038,1.735741656,227.6537678
,67.8,27.45806002,0.69533162,135097.5853,1.739231455,229.1965737
,68.1,27.89077372,0.705789635,136473.7854,1.733996707,230.7963622
,68.4,27.89205162,0.716434431,138202.126,1.724399744,232.2799974
,68.7,28.21322174,0.727219165,140283.6522,1.7139303,234.1898801
,69,28.04013662,0.738199427,141360.3854,1.712185415,235.6735148
,69.3,28.42448919,0.749308797,141036.2537,1.726580823,237.1374305
,69.6,28.93362046,0.760577755,141035.9273,1.736613962,238.4961548
,69.9,29.799252,0.77199361,141016.1988,1.747519517,239.8943291
,70.2,29.97343432,0.78362748,142212.3184,1.744902148,241.4678168
,70.5,30.22288794,0.795432155,142869.5588,1.747955703,242.9383065
,70.8,30.40783045,0.807419335,143842.5636,1.746210783,244.3770178
,71.1,31.24547621,0.819544765,144539.1321,1.747955604,245.9198306
,71.4,30.90617824,0.831930972,146086.8529,1.740103579,247.6149423
,71.7,31.7337807,0.844427326,147694.5858,1.73225144,249.284861
,72,31.59161546,0.857176428,149156.1251,1.727889199,251.0577719
,72.3,32.2169726,0.870067426,150024.839,1.730070267,252.7441257
,72.6,32.36429422,0.883184801,149965.209,1.740539665,254.1302413
,72.9,32.71751318,0.896486819,149568.6545,1.755371297,255.5174551
,73.2,33.05239541,0.909990883,149775.0897,1.763223323,256.9167211
,73.5,33.54782806,0.923688642,150790.9664,1.761478373,258.2754464
,73.8,33.49117216,0.937629584,153128.6848,1.747519165,260.1491665
,74.1,34.31103245,0.951722641,155354.9994,1.735304773,262.0502875
,74.4,34.15155295,0.966093199,157253.075,1.727016506,263.9470176
,74.7,34.99629808,0.980664009,158520.6335,1.724835298,265.6695326
,75,35.44081471,0.995382953,158659.3429,1.733995989,267.3021927
,75.3,36.10577749,1.010359501,158462.0849,1.745774011,268.8307601
,75.6,36.16415037,1.025602346,158061.6897,1.758424542,270.1850986
,75.9,36.839025,1.041034648,158079.203,1.767585209,271.678602
,76.2,37.47226073,1.056703141,158608.1529,1.770202499,273.0110309
,76.5,38.33426852,1.072593471,158917.1746,1.775873344,274.5012489
,76.8,38.13040077,1.088793893,159517.2688,1.777618266,275.8731176
,77.1,39.16289876,1.105157547,160600.6562,1.775437037,277.4904428
,77.4,39.20939546,1.121833501,162850.7388,1.762350274,279.3115688
,77.7,39.82080415,1.138724122,165984.8519,1.74228385,281.3233586
,78,40.20169844,1.155885223,168639.1599,1.729197055,283.3943161
,78.3,40.76310323,1.173293412,169918.5686,1.729197001,285.2899577
,78.6,40.97168327,1.190987557,169294.509,1.744901091,286.7483932
,78.9,41.65864112,1.208917441,169153.4085,1.755806656,288.3580458
,79.2,41.77810786,1.227155397,169871.8754,1.758423997,290.060832
,79.5,42.33767746,1.2456399,171709.3119,1.750571888,291.8008774
,79.8,42.53776345,1.264427216,174038.8373,1.740538684,293.9573028
,80.1,43.47082732,1.283450288,175584.2961,1.735740123,295.7291278
,80.4,43.82225286,1.302799103,176424.0762,1.738357433,297.6236706
,80.7,44.91996751,1.322390768,177256.4491,1.740538461,299.4119333
,81,44.72132429,1.342364101,178297.1285,1.742283374,301.3009935
,81.3,45.84556896,1.362552002,179857.3566,1.739665922,303.300735
,81.6,45.86149434,1.383118056,181067.6321,1.73922969,305.1295312
,81.9,46.46062695,1.403956282,182658.0727,1.736176061,307.2147364
,82.2,46.92575183,1.425118236,183798.4074,1.736176009,309.1169513
,82.5,47.79519491,1.446573188,185694.6279,1.730941229,311.2602334
,82.8,47.90826662,1.468402206,187910.8858,1.723961615,313.570062
,83.1,48.97313394,1.490498045,191718.4788,1.704767611,316.192186
,83.4,49.23420239,1.512980817,194314.6655,1.69386196,318.4373663
,83.7,50.02771922,1.535767982,196612.433,1.688190959,321.2337124
,84,50.19299492,1.558940989,196332.0839,1.701277696,323.4164348
,84.3,51.25015635,1.582405351,195688.5768,1.716109247,325.0951244
,84.6,51.56841442,1.60627305,195405.0874,1.731377092,327.2394974
,84.9,52.38001181,1.630468854,196188.0842,1.734866814,329.05844
,85.2,52.57085311,1.655071115,198079.6766,1.730940771,331.3562157
,85.5,53.11275401,1.680021882,200293.0984,1.723961119,333.8260277
,85.8,53.78772045,1.705341351,201989.5867,1.72003503,336.0032773
,86.1,54.93771775,1.731012755,203309.4504,1.72003492,338.4204991
,86.4,55.43325807,1.757115246,203988.6636,1.725705796,340.6634914
,86.7,56.38053047,1.783582405,203856.8943,1.737483778,342.5788611
,87,57.08686526,1.810465279,203431.9669,1.751879131,344.4931319
,87.3,57.79604756,1.837754253,202775.176,1.767583157,346.2759145
,87.6,58.02549641,1.865487031,203332.7304,1.771945383,348.0269155
,87.9,58.84104696,1.89360023,204707.4952,1.770200403,350.0737733
,88.2,59.24508889,1.922165408,208157.9071,1.75275137,352.5161906
,88.5,60.2302383,1.951123707,211730.7636,1.734429832,354.8501354
,88.8,60.69529658,1.980553974,215200.0217,1.720906819,357.679351
,89.1,61.7293957,2.010391269,217507.431,1.716108247,360.3146256
,89.4,62.00044761,2.040729699,218926.3159,1.716980671,362.7701907
,89.7,62.82431344,2.071490215,219958.2076,1.719597941,365.0778366
,90,63.32277996,2.10273695,220416.5072,1.726577489,367.4041058
,90.3,64.92319232,2.134436237,219511.9565,1.743590098,369.4969942
,90.6,65.30045522,2.16658793,219915.2971,1.750569656,371.4923484
,90.9,66.25464802,2.199241287,222557.0895,1.742281294,373.9753144
,91.2,66.67709254,2.23242307,226958.8886,1.723523593,376.9667009
,91.5,67.7559325,2.266061385,230477.5365,1.710000526,379.65019
,91.8,68.27722882,2.300244575,232507.1633,1.709128028,382.5900771
,92.1,69.49984771,2.334898003,231493.9499,1.726576894,384.8528026
,92.4,69.92028356,2.370247347,231056.4051,1.740099816,387.0947004
,92.7,71.08867084,2.405843506,231403.0766,1.747515519,389.2566159
,93,71.42824771,2.44215223,234853.6545,1.735301199,392.0430976
,93.3,72.60393141,2.47895445,239107.3134,1.718724554,395.098046
,93.6,72.74780471,2.516380711,242137.3581,1.710000051,397.9217811
,93.9,74.24780322,2.554283129,244364.7252,1.706946336,400.8978397
,94.2,74.82082501,2.592819268,244760.5356,1.714798322,403.6273457
,94.5,76.3314562,2.631875888,243922.7619,1.728757358,405.7366704
,94.8,76.90345951,2.671584601,242906.54,1.745770055,408.1023893
,95.1,77.77406752,2.711873494,242433.3751,1.759292926,410.2653998
,95.4,78.51894165,2.752779432,244610.664,1.755366833,412.8064397
,95.7,80.16064966,2.794244241,247447.3809,1.74707841,415.4625441
,96,80.42274645,2.836426478,249767.9536,1.741843693,418.1964299
,96.3,81.74392068,2.879175245,251523.1914,1.740971116,420.94019
,96.6,82.05323956,2.922636464,254288.2317,1.733555273,423.7288644
,96.9,83.43411317,2.966682874,257944.8413,1.723085758,426.909827
,97.2,84.04025792,3.011445623,260864.1805,1.71697856,430.0348993
,97.5,85.44671113,3.056832144,261245.3887,1.72483046,432.4565118
,97.8,85.77890033,3.102975189,261644.2343,1.733991131,435.2802504
,98.1,87.08112948,3.149751168,262335.1334,1.740098148,437.9352558
,98.4,87.86488955,3.197268098,265649.4229,1.730937362,441.0362237
,98.7,89.49055294,3.245447525,267699.0629,1.728319866,443.9366807
,99,89.77819139,3.294442897,271600.8921,1.717850454,447.3225362
,99.3,91.83627838,3.344061932,272326.771,1.72439362,450.180265
,99.6,92.57380979,3.394517532,274251.606,1.724829773,453.1190625
,99.9,93.84288896,3.44570065,275353.7552,1.729191893,456.091835
,100.2,94.35136712,3.497707222,276200.0301,1.735298977,458.9342039
,100.5,95.85982381,3.550433456,277618.3731,1.737043724,461.5300439
,100.8,96.44126929,3.604017407,279574.2494,1.737479893,464.7416804
,101.1,98.01104095,3.658345546,281614.0606,1.736171069,467.8065007
,101.4,99.17465006,3.713521398,285466.4935,1.724829136,471.1430595
,101.7,100.8024007,3.769500289,288810.0395,1.717413173,474.4204557
,102,101.3242457,3.826397791,292067.6446,1.711742214,477.945475
,102.3,102.7262443,3.884096759,292584.7156,1.720902779,481.1001449
,102.6,103.686295,3.94269683,292819.6931,1.729190937,483.9677234
,102.9,105.0489087,4.002155655,295057.5852,1.727882134,487.3766059
,103.2,105.9924511,4.062540591,298863.5392,1.719593793,491.0068236
,103.5,107.91723,4.123776098,301937.1106,1.715231371,494.2228622
,103.8,108.9070735,4.185998433,304634.6081,1.715667499,497.9801885
,104.1,110.7400321,4.249105337,303258.5108,1.733552489,500.7831307
,104.4,111.5594239,4.313232589,302499.599,1.746202893,503.1806346
,104.7,113.1249943,4.3782795,301164.7096,1.763215457,506.0328816
,105,114.1620682,4.444344061,301545.7571,1.76888626,508.4139521
,105.3,116.0626323,4.511349745,305364.8353,1.758416708,511.7713441
,105.6,117.2241912,4.579416702,308591.8267,1.750564572,514.9764176
,105.9,118.819907,4.648483306,313956.8766,1.733551704,518.8170297
,106.2,119.7331909,4.71863854,317249.6392,1.728316935,522.5228556
,106.5,121.4849941,4.789798376,319437.9519,1.729189211,526.1410339
,106.8,122.4715732,4.862083975,319591.2685,1.738349805,528.8990416
,107.1,124.023344,4.935424653,320063.8981,1.746637895,531.9320891
,107.4,125.2828955,5.009892589,322879.1654,1.744020432,535.3946659
,107.7,126.9695162,5.08545766,330252.3458,1.722209108,539.9431319
,108,128.2274592,5.162192553,336331.8081,1.705196284,543.8549655
,108.3,129.919954,5.240058017,341220.4514,1.696035436,548.2478381
,108.6,131.0323361,5.319138211,341111.0055,1.708031465,551.9668186
,108.9,133.2864911,5.399335518,341323.4776,1.717410044,555.336273
,109.2,134.5266238,5.480809766,342036.6532,1.724825715,558.9719792
,109.5,135.9121662,5.563505345,344070.7001,1.725261804,562.4268874
,109.8,137.3158144,5.647449527,344485.3471,1.733549903,566.0878005
,110.1,139.3299258,5.732909777,342951.5434,1.749689953,569.2874114
,110.4,140.2814199,5.819156339,341275.5198,1.766266328,572.1999203
,110.7,142.5106596,5.906912505,342190.5788,1.771064557,575.1124506
,111,143.7678766,5.996058866,345256.0788,1.76757465,578.5827
,111.3,145.5274258,6.086518877,349343.7882,1.758850021,581.8546284
,111.6,146.830805,6.178375735,351495.7077,1.76015856,585.6864763
,111.9,148.9851305,6.271564128,353382.1819,1.761467014,589.1874231
,112.2,150.4078774,6.366208708,354204.8737,1.764956654,591.9980371
,112.5,152.5542631,6.462235727,357549.0627,1.760157993,595.737856
,112.8,154.2419693,6.559743663,362323.6728,1.750124708,599.9192551
,113.1,156.1540893,6.658710078,367160.8813,1.739218958,603.5451147
,113.4,157.8446514,6.75918659,372696.0695,1.72787701,607.9894942
,113.7,160.005069,6.861149802,377889.625,1.719588575,612.8732738
,114,161.4097586,6.964702508,381133.3756,1.716534882,616.6382879
,114.3,163.8459164,7.069749916,383474.9924,1.718279536,620.9369443
,114.6,164.8865082,7.17647533,386699.2326,1.716098324,625.2092825
,114.9,167.8130546,7.284687982,389435.4067,1.715661819,629.7062808
,115.2,169.0619695,7.394646294,392365.0417,1.714789254,634.3106347
,115.5,171.6909568,7.506174926,395073.3926,1.714352777,638.4953393
,115.8,172.9742848,7.619477256,397092.0812,1.718714872,643.1424284
,116.1,175.7666413,7.73439176,398790.427,1.723949269,647.3578199
,116.4,177.5619507,7.851108367,399475.2702,1.730928643,650.7897343
,116.7,180.0384113,7.969543455,400369.7405,1.739216619,655.0226531
,117,181.817347,8.089813781,404095.6373,1.736162892,659.5021029
,117.3,184.3215227,8.211853552,405615.7119,1.739652418,662.9899142
,117.6,185.9326382,8.335796095,412874.9731,1.725256946,668.3930779
,117.9,188.3347151,8.461558755,417838.9723,1.718713382,673.3141273
,118.2,190.1923431,8.589257287,423318.7789,1.71042499,678.3929547
,118.5,193.0480982,8.71881943,424730.8324,1.714786937,682.474671
,118.8,195.3011532,8.850379012,424066.0941,1.727873363,686.9037287
,119.1,197.6254464,8.983921448,426303.6675,1.730490465,691.4226396
,119.4,199.3911279,9.119518185,429019.6868,1.731798957,695.9996154
,119.7,202.2555923,9.257090975,434148.2982,1.724382915,700.7311123
,120,204.3226434,9.39679483,435490.6036,1.730489811,705.2324889
,120.3,207.0566448,9.538565522,435924.312,1.738777748,709.5782807
,120.6,208.9499575,9.682533705,435613.051,1.749246869,713.3246832
,120.9,211.8663171,9.82861522,439253.9734,1.747065476,717.8699072
,121.2,213.9627783,9.976959485,445290.8806,1.737032185,722.6457723
,121.5,216.8522208,10.12749274,450609.8815,1.729616146,727.5191717
,121.8,218.963356,10.28035198,457744.7441,1.717401753,733.3617501
,122.1,221.9032387,10.43546609,461255.6653,1.716529027,738.6433195
,122.4,224.0760357,10.59297433,464545.9953,1.715656374,743.1710025
,122.7,227.1345625,10.75280391,464942.5678,1.726125375,748.3013623
,123,229.5491325,10.91509097,465124.0883,1.735285773,752.2406334
,123.3,232.3502046,11.07980446,466131.3284,1.742265028,756.8516043
,123.6,234.6000793,11.24704294,467842.0845,1.747499453,761.7847182
,123.9,237.8592158,11.4167417,468874.5236,1.752297556,765.7678352
,124.2,240.0974642,11.5890717,472547.3929,1.750116232,770.7524511
,124.5,243.1348753,11.76395287,477137.8648,1.744445067,775.4226002
,124.8,245.5965201,11.94151438,485699.192,1.729177115,781.4010659
,125.1,248.7266867,12.12171452,492051.805,1.721761066,786.9050846
,125.4,251.1824793,12.30468193,494486.1956,1.726995468,792.1132405
End Of Loading Marker,125.696,254.0071207,12.48789251,493762.1775,1.739645574,796.4009701
,126,256.2217446,12.49024492,492204.0285,1.754040618,800.779641
,126.3,257.761049,12.49014466,495526.4083,1.753168027,805.843134
,126.6,258.4708243,12.49009872,502125.4171,1.74182624,811.1958922
,126.9,260.1058114,12.48999219,508252.2626,1.733537902,816.899307
,127.2,260.362965,12.4899759,510357.7912,1.737900077,822.2509586
,127.5,261.2774184,12.48991656,509050.48,1.751422805,826.2449861
,127.8,261.268324,12.4899177,507912.7487,1.766254282,830.6794889
,128.1,262.0296847,12.48986839,509735.0592,1.771488846,835.2312514
,128.4,261.9398839,12.48987482,513810.0042,1.767999097,839.6098691
,128.7,262.5265193,12.48983695,523749.7608,1.750114026,845.9685194
,129,262.318571,12.48985112,528500.8699,1.745751848,851.4330231
,129.3,262.9542959,12.48981003,531316.3473,1.746188007,855.962867
,129.6,262.9551858,12.48981052,531192.5185,1.756657284,861.1348104
,129.9,263.535997,12.48977303,527537.1635,1.77497846,864.5930095
,130.2,263.5335588,12.48977374,526393.7116,1.786756396,868.661533
,130.5,263.9671016,12.48974589,525666.8852,1.797661849,872.7508825
,130.8,263.5752758,12.4897721,527787.9911,1.800715428,877.1645566
,131.1,264.4048625,12.48971832,529926.596,1.802460224,880.883552
,131.4,264.3816236,12.48972039,529413.3868,1.812057063,884.5718479
,131.7,264.7511005,12.48969674,524996.9126,1.831686917,887.2180916
,132,264.4907346,12.48971434,520309.9282,1.851753055,889.6681857
,132.3,264.9841832,12.48968258,518822.6267,1.86178606,892.1993788
,132.6,265.0982285,12.48967565,521536.6141,1.85916873,895.187495
,132.9,265.2671874,12.48966514,524848.7955,1.855678953,898.5887063
,133.2,265.3762405,12.48965854,525299.8658,1.860477363,901.5340858
,133.5,265.6333941,12.48964225,524068.8962,1.870074171,904.220872
,133.8,265.4071412,12.48965762,522542.645,1.878798592,906.1603457
,134.1,265.8673088,12.48962803,522585.0587,1.883160742,908.5578575
,134.4,265.4663307,12.48965484,522755.7223,1.887086767,910.9816468
,134.7,266.0255093,12.48961877,524707.1613,1.885778043,913.4723015
,135,265.9739816,12.48962269,524465.8689,1.89144891,915.667088
,135.3,266.4358132,12.48959299,522529.0179,1.901918135,917.3742787
,135.6,265.9033753,12.48962841,519192.7072,1.915877229,918.5204197
,136.4,266.1218492,12.39158337,1.7977E+308,1.85218912,0
,136.7,266.0235515,12.20426769,1.7977E+308,1.556432131,0
,137,265.6024282,12.01697315,1.7977E+308,1.122829711,0
,137.3,265.0748057,11.82968559,1.7977E+308,0.567521951,0
,137.6,264.9190983,11.64237367,1.7977E+308,0.256497241,0
,137.9,264.1560127,11.45510153,1.7977E+308,0.14438876,0
,138.2,264.0090416,11.26778904,1.7977E+308,0.066741633,0
,138.5,263.6424158,11.08049093,1.7977E+308,0.034897587,0
,138.8,263.7899815,10.89315915,1.7977E+308,0.018757453,0
,139.1,262.8546667,10.70589828,1.7977E+308,0.025300751,0
,139.4,262.6752466,10.51858792,1.7977E+308,0.025300752,0
,139.7,262.3190211,10.33128913,1.7977E+308,0.027263742,0
,140,262.0439181,10.14398503,1.7977E+308,0.030099171,0
,140.3,261.566633,9.956694168,1.7977E+308,0.036642471,0
,140.6,261.3788926,9.769384346,1.7977E+308,0.037078691,0
,140.9,260.6033265,9.582113021,1.7977E+308,0.025300755,0
,141.2,260.2882862,9.394811536,1.7977E+308,0.012650378,0
,141.5,260.1051219,9.207501414,1.7977E+308,0.015267697,0
,141.8,259.5608587,9.020214941,1.7977E+308,0.010905499,0
,142.1,259.1168545,8.832921902,1.7977E+308,0.009596839,0
,142.4,258.5834076,8.64563472,1.7977E+308,0.012650379,0
,142.7,258.3004003,8.458331137,1.7977E+308,0.00741574,0
,143,257.9828639,8.271029815,1.7977E+308,0.0109055,0
,143.3,257.6894562,8.083726913,1.7977E+308,0.01265038,0
,143.6,257.0915273,7.896443955,1.7977E+308,0.02355588,0
,143.9,256.8958826,7.70913465,1.7977E+308,0.026609421,0
,144.2,255.980536,7.52187248,1.7977E+308,0.028354302,0
,144.5,255.7474502,7.334565628,1.7977E+308,0.023119662,0
,144.8,255.3388069,7.147270273,1.7977E+308,0.022247223,0
,145.1,255.2937588,6.959951105,1.7977E+308,0.026173203,0
,145.4,254.59567,6.772050297,1.7977E+308,0.031844065,0
,145.7,254.2344522,6.584751836,1.7977E+308,0.035333827,0
,146,253.9471854,6.398072941,1.7977E+308,0.033152727,0
,146.3,253.3496723,6.210789955,1.7977E+308,0.03969603,0
,146.6,252.9518454,6.023493892,1.7977E+308,0.048420433,0
,146.9,252.5648348,5.83619712,1.7977E+308,0.048420434,0
,147.2,252.3433972,5.648889505,1.7977E+308,0.037951152,0
,147.5,251.8324147,5.461600852,1.7977E+308,0.03053541,0
,147.8,251.4803492,5.274301792,1.7977E+308,0.022247228,0
,148.1,251.206494,5.086997609,1.7977E+308,0.02617321,0
,148.4,250.6564063,4.899711518,1.7977E+308,0.038823596,0
,148.7,249.9673703,4.712434526,1.7977E+308,0.034025175,0
,149,249.5986641,4.525136555,1.7977E+308,0.019193689,0
,149.3,249.0727051,4.337848884,1.7977E+308,0.010033065,0
,149.6,249.0767465,4.150526501,1.7977E+308,0.013522827,0
,149.9,248.1014936,3.963268254,1.7977E+308,0.010905506,0
,150.2,247.7111547,3.775971701,1.7977E+308,0.010469286,0
,150.5,247.5055256,3.58866305,1.7977E+308,0.018321251,0
,150.8,246.9987031,3.401374125,1.7977E+308,0.021374794,0
,151.1,246.5650988,3.214080404,1.7977E+308,0.021374794,0
,151.4,245.8502699,3.026805102,1.7977E+308,0.020066134,0
,151.7,245.4366342,2.839510074,1.7977E+308,0.01395905,0
,152,244.8590895,2.652225781,1.7977E+308,0.007851966,0
,152.3,244.2798807,2.464941596,1.7977E+308,0.008288187,0
,152.6,243.7256326,2.277655777,1.7977E+308,0.013522831,0
,152.9,243.2038336,2.090367833,1.7977E+308,0.025737002,0
,153.2,242.5563985,1.903088117,1.7977E+308,0.022683461,0
,153.5,241.9414125,1.715806276,1.7977E+308,0.018757478,0
,153.8,241.407133,1.528519149,1.7977E+308,0.015703935,0
,154.1,240.6282378,1.341248042,1.7977E+308,0.010905511,0
,229.4,239.7986507,1.160985928,1.7977E+308,0.004362205,0
,229.7,239.0771651,0.973711062,1.7977E+308,0.010469293,0
,230,238.7858371,0.786408024,1.7977E+308,0.012650396,0
,230.3,237.6878596,0.599157814,1.7977E+308,0.009596853,0
,230.6,237.1685563,0.411869707,1.7977E+308,0.014395279,0
,230.9,235.9753117,0.224625737,1.7977E+308,0.024428354,0
,231.2,234.2358416,0.03741754,1.7977E+308,0.031844108,0
,231.258,233.7007369,0.001236976,1.7977E+308,0.033588992,0
END,,,,,,