File: GB1_test26.csv
Segment,Time On Sample,Displacement Into Surface,Load On Sample,Harmonic Contact Stiffness,Harmonic Displacement,Harmonic Load
Surface Marker,0,0,0,160.2800684,0.44586889,2.220952897
,0.2,-0.005973002,0.000657885,2801.963818,0.319786592,2.279024187
,0.4,0.147405426,0.001305314,8040.599135,0.238203926,2.371061712
,0.6,0.621150949,0.001931725,12354.29876,0.198503267,2.458716518
,0.8,0.373446411,0.00260547,15933.36898,0.162729054,2.545275596
,1,0.610869191,0.003247385,18693.01678,0.141788048,2.628547648
,1.2,0.510450305,0.003911466,21466.8378,0.125209754,2.707436942
,1.4,0.187854755,0.004590125,24720.04548,0.11779315,2.967114194
,1.6,0.302955554,0.005240066,28844.50567,0.110376544,3.222408735
,1.8,0.503764953,0.005884384,34964.06539,0.09946977,3.480990349
,2,0.533157206,0.0065396,40581.38209,0.092053164,3.732997833
,2.2,0.850463832,0.007175611,45445.10158,0.086381641,3.95103913
,2.4,0.428845834,0.007860104,55706.24962,0.082018933,4.606258542
,2.6,0.627158971,0.008503922,59889.0061,0.085945371,5.206693791
,2.8,0.940304984,0.009140206,59444.10633,0.098160955,5.824660022
,3,0.527840334,0.009824098,54671.91925,0.119101961,6.411946967
,3.2,0.757774118,0.010465842,50761.2527,0.138734151,6.890761224
,3.4,0.594114041,0.01113341,50944.22801,0.16142024,8.052187007
,3.6,0.69340462,0.011783725,51322.85574,0.181488702,9.143489001
,3.8,0.530576664,0.012451238,50485.42719,0.205047333,10.21178155
,4,0.784641996,0.013091399,49494.37414,0.229478502,11.29212675
,4.2,0.891421675,0.013741223,47440.59394,0.25783611,12.18182278
,4.4,0.797659874,0.014404204,46175.41365,0.298845578,13.68838925
,4.6,0.490042633,0.015081217,43989.79771,0.345090301,14.99225391
,4.8,0.260644888,0.015753098,41075.34127,0.400060442,16.15806235
,5,0.318328829,0.016409424,38447.99237,0.453285495,17.09158575
,5.2,0.594861989,0.01704483,35102.35607,0.527887816,18.19384468
,5.4,-0.344336651,0.017766563,30795.99772,0.635646766,19.27309361
,5.6,0.254227871,0.018380841,26942.15703,0.748204646,19.94146161
,5.8,-0.451976519,0.019087286,22201.82864,0.923149325,20.52107846
,6,-0.276130677,0.01973258,18736.15835,1.091986172,20.73583267
,6.2,-0.125247985,0.02037623,15261.88575,1.324082304,20.72706731
,6.4,0.851931672,0.020968947,13214.73849,1.504698396,20.5901073
,6.6,1.33233427,0.021594257,11864.69643,1.653466737,20.49697437
,6.8,1.191973622,0.022260296,11612.61058,1.695348758,20.63831762
,7,1.021656568,0.0229283,12175.66801,1.648231516,21.05577338
,7.2,1.271561284,0.023568734,13528.4757,1.536982413,21.76139449
,7.4,0.893213651,0.024250387,16507.8378,1.33978799,22.87241853
,7.6,1.110665599,0.02489295,19219.61811,1.211088056,23.75554058
,7.8,0.712347026,0.025575913,22407.13526,1.100275268,24.82273718
,8,0.869886168,0.026222407,24303.35284,1.061447147,25.74092107
,8.2,0.219434517,0.026921914,24605.83791,1.077152939,26.39614004
,8.4,0.411090679,0.02756617,23069.89475,1.160044405,26.79716083
,8.6,1.428212185,0.028156266,20519.43817,1.303577471,27.04369066
,8.8,1.178843514,0.028829457,18502.81213,1.441002827,27.15106757
,9,1.537756251,0.029462738,16963.43164,1.565340008,27.15325917
,9.2,1.769354271,0.030104373,15931.89885,1.661755858,27.12915431
,9.4,1.735505279,0.030763423,15916.6952,1.681388053,27.32966453
,9.6,1.651728949,0.031425749,16797.58921,1.623800302,27.70548433
,9.8,1.754348014,0.032075845,18393.21194,1.526948154,28.30701535
,10,1.576541864,0.032744341,20116.91653,1.432713654,28.89430226
,10.2,1.486940677,0.033407049,22156.17484,1.339787958,29.57143527
,10.4,1.451427439,0.034066209,23924.23222,1.277401222,30.3044484
,10.6,1.400936,0.034726351,24294.62745,1.278273768,30.7525834
,10.8,1.330473625,0.035387804,23853.21271,1.320155782,31.19304852
,11,1.369019273,0.036042105,23122.48702,1.372508293,31.45272584
,11.2,1.628909455,0.036681883,22473.86474,1.423115695,31.71678607
,11.4,1.451103303,0.037350379,21855.42755,1.476340762,32.01919491
,11.6,1.808351793,0.037983769,21638.48254,1.502516989,32.26243721
,11.8,1.476603016,0.038662364,22081.23242,1.493355328,32.66893592
,12,1.769362028,0.039299986,23065.555,1.455836006,33.17185549
,12.2,1.980573052,0.039942957,24142.21281,1.413953986,33.64628718
,12.4,1.87058487,0.040607003,25396.73372,1.367709277,34.16125889
,12.6,2.078883465,0.041250166,27151.04229,1.307067609,34.82853109
,12.8,2.060428735,0.041908206,28323.97961,1.27303848,35.35226837
,13,1.805235213,0.042581778,29739.67642,1.236391743,36.0206358
,13.2,1.880394242,0.043233676,30666.97214,1.21763209,36.5564257
,13.4,1.94806417,0.043886066,31578.59536,1.2054165,37.25108988
,13.6,2.1110121,0.044532204,31604.74391,1.21937716,37.71346901
,13.8,2.03805336,0.04519382,31324.19764,1.246862231,38.22515369
,14,1.949700358,0.045856446,30855.18082,1.281327639,38.70615919
,14.2,2.379759541,0.046485059,30492.79938,1.310121491,39.10170182
,14.4,2.350071161,0.047143836,30183.78376,1.33804283,39.50491379
,14.6,2.113184332,0.047816207,30330.15227,1.350258433,40.01331123
,14.8,2.202073378,0.048467205,30781.03699,1.349385885,40.54362273
,15,2.275984223,0.049119184,31165.24314,1.350258422,41.03120253
,15.2,2.037849209,0.049791638,31682.80663,1.34502319,41.5352172
,15.4,2.158358902,0.05044056,32263.45326,1.338479118,42.10497345
,15.6,2.022158868,0.051106326,32668.44446,1.338042858,42.63911959
,15.8,2.226712913,0.051749734,32900.31504,1.343714366,43.14039559
,16,2.511150694,0.052387901,33149.51531,1.348949597,43.67728142
,16.2,2.454834402,0.053048425,33172.41913,1.360728916,44.11007686
,16.4,2.359408361,0.053711515,33161.12491,1.378179759,44.66887593
,16.6,2.537750551,0.054356643,32974.6016,1.397375666,45.04688734
,16.8,2.605836539,0.055009005,32880.29414,1.416571581,45.54871105
,17,2.62025064,0.055664888,32796.075,1.434458687,46.00122885
,17.2,2.419145071,0.056334912,32736.11451,1.449291914,46.39019664
,17.4,2.801773279,0.056966636,32745.23393,1.461943741,46.80217468
,17.6,2.681799633,0.057631337,33070.31085,1.463252564,47.30399803
,17.8,2.554752947,0.058296501,33287.24398,1.468487825,47.77952506
,18,2.62824773,0.058948508,33396.86531,1.475031884,48.16411053
,18.2,2.70091039,0.05960057,33550.85527,1.479394588,48.56293983
,18.4,2.976610883,0.06023931,33646.4591,1.488992526,49.06695516
,18.6,2.624059063,0.06091927,33508.87788,1.506879662,49.49427173
,18.8,2.514486944,0.061583288,33497.84499,1.516913902,49.83502959
,19,2.919998514,0.062213511,33643.70996,1.523457933,50.2787824
,19.2,2.92525927,0.062869994,33801.95125,1.527820643,50.65021953
,19.4,3.209280983,0.063508189,34149.86903,1.52782062,51.14437376
,19.6,3.034803331,0.064176465,34381.53401,1.531747074,51.60017837
,19.8,3.109130235,0.064828417,34447.63816,1.538727403,51.94312778
,20,3.440582914,0.065463499,34340.65555,1.554869398,52.3397661
,20.2,3.302718643,0.066129372,34141.19082,1.572756517,52.65203608
,20.4,3.360403101,0.066782416,33853.48488,1.59631514,53.02237755
,20.6,3.274962532,0.067444851,33813.53765,1.60678565,53.32697783
,20.8,3.27356631,0.068101771,33903.23484,1.613765985,53.69074511
,21,3.222242753,0.068761966,34154.4079,1.612020907,54.01945045
,21.2,3.818310302,0.069379687,34657.43386,1.603295439,54.5015526
,21.4,3.665467834,0.070046543,35132.83812,1.592824952,54.88175509
,21.6,3.646597045,0.07070461,35737.59788,1.579736828,55.36056929
,21.8,3.661843229,0.071360687,36399.3629,1.562722264,55.79774752
,22,3.590547905,0.07202744,37192.18208,1.543526353,56.32258043
,22.2,3.726449971,0.072687192,38054.79838,1.522149069,56.82002147
,22.4,4.027111184,0.073342757,39145.56648,1.497717877,57.47414577
,22.6,3.692862039,0.074046876,39911.99227,1.482012154,57.96610765
,22.8,3.736395294,0.074733085,40566.89753,1.474595546,58.56873436
,23,3.664262471,0.075433717,40936.74879,1.476340636,59.12643782
,23.2,3.508084175,0.076146951,41049.59286,1.484193525,59.57676385
,23.4,3.365218718,0.076866321,41007.67014,1.497717935,60.03037715
,23.6,3.891377816,0.077552693,40722.88036,1.52084025,60.5048095
,23.8,3.832555011,0.078277227,40371.34413,1.542653799,60.83351485
,24,3.83447539,0.079008722,40105.09266,1.564467343,61.27288441
,24.2,4.130133769,0.079728158,39817.12682,1.584099508,61.59611195
,24.4,4.027204441,0.080481044,39780.74894,1.596751373,62.05301223
,24.6,3.965880017,0.081238788,40101.50301,1.593261212,62.43869322
,24.8,4.078467941,0.08199266,40854.56519,1.577119182,62.98653571
,25,4.131141849,0.082758105,41695.46021,1.558795802,63.55190914
,25.2,3.8384838,0.083553956,42573.50358,1.538727367,64.06030645
,25.4,4.141624011,0.084318635,43553.45236,1.520403967,64.72867467
,25.6,4.122731685,0.085112197,43939.94153,1.52084024,65.3028134
,25.8,4.068056843,0.085916032,44052.42898,1.527384308,65.7399915
,26,4.308784116,0.086708512,44101.13688,1.53785479,66.25715516
,26.2,4.253274593,0.087528502,43950.89119,1.552688005,66.66474979
,26.4,3.951455593,0.088372809,43853.0985,1.565776157,67.09425768
,26.6,4.307011824,0.089182358,43943.8942,1.573629004,67.59498625
,26.8,4.13000851,0.090035149,44179.53812,1.576682916,68.11214908
,27,4.205969004,0.090879821,44296.47131,1.58148189,68.51864822
,27.2,4.751245088,0.091702124,44340.22201,1.588462178,68.92076561
,27.4,4.558427402,0.092581456,44514.1036,1.593697446,69.45874651
,27.6,4.252439716,0.093476858,44759.65096,1.596315098,69.96823936
,27.8,4.434074226,0.094349236,45020.21347,1.596315084,70.39117391
,28,4.440129571,0.095241795,45485.66296,1.591516105,70.93463359
,28.2,4.37545307,0.09614816,46022.97227,1.583663236,71.42769153
,28.4,4.349884895,0.097060879,46544.8898,1.578864259,72.03141383
,28.6,4.275220033,0.097986105,46845.40731,1.577991727,72.47845302
,28.8,4.442701281,0.098904609,46831.77196,1.589334754,72.99013825
,29,4.721685437,0.09982503,46754.2525,1.601986586,73.44265665
,29.2,4.661162236,0.10077712,46714.44998,1.612457097,73.84148571
,29.4,4.611871183,0.101737922,46760.72666,1.620746243,74.25346307
,29.6,4.867135346,0.102688256,47051.74522,1.622927575,74.75857428
,29.8,5.233070245,0.103640846,47648.18059,1.615510943,75.31518291
,30,5.301103844,0.104622748,48239.55322,1.606349249,75.79180593
,30.2,5.237244506,0.105623186,49268.31693,1.587153338,76.46126919
,30.4,5.115135041,0.106637344,50084.2682,1.57275641,77.02664227
,30.6,5.159864434,0.10765088,50948.84953,1.559232011,77.70487124
,30.8,5.031926855,0.108685916,51865.46042,1.545271357,78.40501353
,31,5.263880494,0.109707604,52483.04804,1.537418464,78.94080389
,31.2,5.41012391,0.1107452,53025.47839,1.534364558,79.60533695
,31.4,5.613366027,0.111789546,53574.75063,1.531310645,80.26548758
,31.6,5.343961057,0.112875526,54029.36906,1.531310667,80.93495036
,31.8,5.5085061,0.113943763,54352.75533,1.534364551,81.58688317
,32,5.579435692,0.115028861,54634.41232,1.536109629,82.11500336
,32.2,5.48601939,0.116135843,54881.00464,1.539599805,82.67928083
,32.4,5.674274713,0.117235243,54948.47432,1.55007029,83.36627561
,32.6,5.926185604,0.118341637,55173.28388,1.555741791,84.0357396
,32.8,5.786581228,0.119484957,55252.92153,1.562722137,84.54632838
,33,5.802997961,0.120629354,55419.76997,1.569266199,85.17306009
,33.2,5.794449187,0.121786971,55740.34751,1.570138742,85.71761544
,33.4,5.603663804,0.122968199,56426.97185,1.564903509,86.48130716
,33.6,5.942106275,0.124126335,56967.8548,1.560104503,87.05544695
,33.8,5.897770669,0.1253214,57790.48879,1.55094282,87.7961297
,34,5.960360866,0.126521372,58484.31903,1.546143836,88.5565351
,34.2,5.9846715,0.127736083,58943.70936,1.544398752,89.15258762
,34.4,6.802408702,0.128910682,59402.63005,1.546143768,89.94476988
,34.6,6.43894659,0.130174926,59600.30474,1.550942778,90.50466389
,34.8,6.303483952,0.131436727,59816.99482,1.557486853,91.20151908
,35,6.723876918,0.132674565,60234.63081,1.558795631,91.92248063
,35.2,6.869667558,0.133943115,60585.1003,1.560104432,92.54044737
,35.4,7.16523817,0.135214469,60934.98266,1.561413221,93.16170145
,35.6,7.157914272,0.136518642,61533.04062,1.558795598,93.9297765
,35.8,7.287056327,0.137826903,62192.96496,1.554869151,94.71209574
,36,7.126617777,0.139167435,62467.11212,1.55748679,95.29828674
,36.2,7.137594275,0.140509979,62870.15597,1.557923061,95.94693221
,36.4,7.305839705,0.141855718,63430.95493,1.557486777,96.78951432
,36.6,7.485732707,0.143214135,63947.84163,1.557050492,97.56087686
,36.8,7.759653319,0.144580123,64282.9771,1.558795553,98.188705
,37,8.249091373,0.145945642,65015.10692,1.553560264,98.9896521
,37.2,8.238421842,0.147357897,65716.82026,1.547888745,99.71170826
,37.4,8.239399766,0.148783564,66768.99373,1.538290789,100.6737196
,37.6,8.194608707,0.150226516,67709.64,1.530437919,101.5831379
,37.8,8.21804934,0.151679569,68717.71145,1.519094878,102.3479259
,38,8.272276198,0.153145018,69685.5669,1.511242,103.2737798
,38.2,8.367274686,0.154622585,70324.4032,1.508624369,104.0484294
,38.4,7.9305448,0.15614993,71134.80884,1.50600678,105.1035727
,38.6,8.141203484,0.157649949,71832.4138,1.502080327,105.9067101
,38.8,8.419261658,0.159160617,72444.48822,1.502516576,106.8632439
,39,8.399417703,0.160706099,73177.15814,1.500771495,107.7901933
,39.2,8.421177371,0.162264452,73885.52961,1.49815387,108.6382535
,39.4,8.695067547,0.163821847,74562.42011,1.499462661,109.6890159
,39.6,8.529594767,0.165423846,74678.40523,1.508188091,110.4428467
,39.8,8.577974796,0.167027917,74497.99521,1.524766378,111.3467869
,40,8.400015065,0.168662932,74403.52383,1.536545704,112.0556945
,40.2,8.934349248,0.170267389,74492.15772,1.545271076,112.7909008
,40.4,8.627405398,0.171943602,74942.03623,1.550070081,113.794547
,40.6,8.631672581,0.17361585,75685.95161,1.546143645,114.618502
,40.8,8.977939252,0.175282499,76615.15983,1.541344639,115.6363943
,41,8.742549907,0.177004293,77102.37342,1.542217201,116.4165212
,41.2,8.931540094,0.17871533,77230.42306,1.55007006,117.2021278
,41.4,8.657034129,0.180482984,77350.15465,1.560540582,118.1827648
,41.6,8.900108095,0.182216615,77400.56667,1.568829708,118.8916738
,41.8,8.978417702,0.183987426,77580.07095,1.576682576,119.7846572
,42,9.33465325,0.185757739,78015.00993,1.579300171,120.68312
,42.2,9.040998612,0.187588751,78794.52264,1.574937489,121.5618584
,42.4,9.107649936,0.189414261,79231.91253,1.576246297,122.3310294
,42.6,9.352372454,0.191246475,79538.47041,1.581917797,123.2349703
,42.8,9.064533923,0.193132133,79704.6353,1.588025613,123.9471643
,43,9.344199634,0.194999379,79997.35685,1.594133381,124.845627
,43.2,9.205304969,0.196912893,79818.05928,1.606348975,125.5249512
,43.4,9.747083088,0.198800865,79754.9042,1.618564511,126.4102664
,43.6,9.263683805,0.200775345,79665.52732,1.628162511,127.0457618
,43.8,9.668987743,0.202711078,79328.11591,1.644304494,127.7831592
,44,9.81383438,0.204683415,78760.50468,1.662627854,128.306897
,44.2,10.03856158,0.206670302,78317.44163,1.678769853,128.8350178
,44.4,9.689953489,0.208715123,77989.35424,1.694911904,129.5165328
,44.6,9.96210521,0.21073941,77882.8107,1.703637295,130.0106874
,44.8,10.12690995,0.212791128,78023.46926,1.70887253,130.6954912
,45,10.19518526,0.214869778,78405.94856,1.707563712,131.2882569
,45.2,10.03878428,0.216984225,79017.28122,1.702764749,131.9478584
,45.4,10.05629345,0.219108327,79492.52045,1.702328478,132.7236037
,45.6,10.21525998,0.221244405,79810.35206,1.703201006,133.3174653
,45.8,10.16536046,0.223415777,80141.14481,1.705818636,134.0449999
,46,10.53734333,0.225581282,80306.86029,1.710181311,134.599418
,46.2,10.43667743,0.227799594,80254.19338,1.718034194,135.1111025
,46.4,10.44834448,0.230032758,80247.65692,1.726759608,135.7652262
,46.6,10.51825649,0.23228456,80265.03991,1.732867396,136.271433
,46.8,10.68635531,0.234552464,80211.23896,1.741592798,136.8729647
,47,10.59732482,0.236860044,80089.82053,1.749445675,137.3276733
,47.2,11.27384291,0.239140244,79948.14988,1.757734757,137.7769071
,47.4,11.08661468,0.241500454,80243.91062,1.758607317,138.4277432
,47.6,11.01504766,0.243876621,80559.87175,1.757734783,138.9262795
,47.8,10.96511203,0.246275199,81240.28403,1.751626999,139.6187521
,48,11.18935676,0.248679849,82208.38519,1.738975128,140.2443891
,48.2,11.49514559,0.25110336,83802.1273,1.717597835,141.1417563
,48.4,11.40650473,0.253577156,84874.40725,1.705818535,141.8923001
,48.6,11.3490645,0.256073719,86225.8857,1.690985336,142.8236321
,48.8,11.46969439,0.258583661,87167.8643,1.682259911,143.5665069
,49,11.32612154,0.261136215,87797.84191,1.680296707,144.3460862
,49.2,11.96681958,0.263662777,88005.73718,1.685313765,145.0774585
,49.4,12.91165414,0.266194606,88054.45272,1.692294012,145.7458302
,49.6,13.45373761,0.268778427,88082.9921,1.699492429,146.4136523
,49.8,13.47282831,0.271422762,88325.18231,1.702328188,147.0891421
,50,13.97662582,0.274061567,88740.16433,1.702764412,147.8911858
,50.2,14.25283378,0.276741851,89478.53772,1.69622033,148.6022863
,50.4,14.59893566,0.27944466,90750.89203,1.681823368,149.4624007
,50.6,14.74948458,0.282187479,92290.83528,1.66524507,150.5022063
,50.8,14.74150989,0.284968454,93533.05387,1.652593223,151.355745
,51,14.43563114,0.287796905,95391.63088,1.632961072,152.5094999
,51.2,14.57451704,0.290624295,97111.18869,1.615510234,153.554784
,51.4,14.57401799,0.293489422,98526.88926,1.60547601,154.789621
,51.6,14.73452996,0.296372621,99600.14523,1.598059396,155.7483463
,51.8,14.86424881,0.299286841,100265.5236,1.598931927,156.8648497
,52,14.9086705,0.302236051,100225.1466,1.608093608,157.6855182
,52.2,14.82286042,0.305223398,99853.5798,1.622054277,158.4579754
,52.4,14.99417122,0.308223861,99942.78482,1.631652217,159.5185993
,52.6,15.06603869,0.311260888,100094.8753,1.63732373,160.2811964
,52.8,15.08506158,0.314331805,100792.4414,1.63732373,161.3560635
,53,15.2122554,0.31742652,101785.1973,1.63121593,162.2841092
,53.2,15.36856855,0.320550359,102974.1933,1.622926776,163.3009059
,53.4,15.34180988,0.323717798,104137.6741,1.617691531,164.5729959
,53.6,15.41157229,0.326910654,104774.1838,1.617255255,165.5163812
,53.8,15.54290661,0.330131605,105200.7236,1.621617951,166.6394589
,54,15.22489003,0.333414313,105122.6651,1.630343393,167.4425947
,54.2,15.6957197,0.336678024,104822.9775,1.64255893,168.2588823
,54.4,15.70804501,0.34000485,104104.1875,1.662627379,169.1967888
,54.6,15.86016148,0.34335586,103620.5808,1.676588027,169.8618702
,54.8,15.98980532,0.34674192,103100.16,1.6931663,170.6814431
,55,16.14107892,0.350160598,102870.3419,1.703636782,171.3355679
,55.2,15.93203831,0.353637407,102640.8264,1.714107297,172.0017432
,55.4,16.32628046,0.357109374,102806.2635,1.718906239,172.7468111
,55.6,16.70553884,0.360617336,103014.2291,1.723705181,173.5784377
,55.8,16.77524231,0.364180964,103041.8767,1.730685506,174.3695228
,56,16.83079403,0.367781298,103053.667,1.736357019,174.999542
,56.2,17.0319613,0.371408192,103281.5619,1.738974625,175.6701022
,56.4,17.7340601,0.375038365,103559.2261,1.742464725,176.5236442
,56.6,18.08166921,0.37872848,103822.5956,1.744209776,177.1613346
,56.8,17.89005755,0.38249119,104485.7498,1.741592172,177.9984373
,57,18.26345053,0.386254486,105587.0753,1.731557915,178.7840454
,57.2,17.96448314,0.390099938,107143.7847,1.715852202,179.7066106
,57.4,18.06159955,0.393957879,109066.8269,1.697965101,180.9348741
,57.6,18.19282681,0.397852267,110945.2567,1.679205455,181.9593404
,57.8,18.14597376,0.401797708,113244.5791,1.657828202,183.2895015
,58,18.21893997,0.405774764,114988.8951,1.644303808,184.5911765
,58.2,18.39508291,0.409784993,116089.1455,1.637759735,185.6561831
,58.4,18.29994777,0.413853372,116847.5805,1.636014662,186.7376238
,58.6,18.6092173,0.417935877,116855.0282,1.645176318,187.8508416
,58.8,18.64138043,0.422098733,116414.8467,1.657828162,188.6671273
,59,18.50711588,0.426293581,115868.7612,1.673533916,189.5885978
,59.2,18.50348774,0.430521941,115210.887,1.690112199,190.300793
,59.4,18.94171288,0.43474225,114634.1693,1.7058179,191.0458611
,59.6,18.99548762,0.439051862,114198.7898,1.720214825,191.8698164
,59.8,18.81709354,0.443419989,114128.2298,1.728067712,192.5633841
,60,18.71108708,0.447827182,113513.9554,1.744209734,193.2887271
,60.2,18.78814035,0.45226658,113423.8794,1.751190057,193.9428516
,60.4,19.05657453,0.456737964,113291.4564,1.759042903,194.6188908
,60.6,19.37160036,0.461251248,113708.7203,1.759915415,195.4603789
,60.8,20.01946762,0.465788116,114226.3265,1.758170273,196.1791518
,61,21.16660059,0.470337512,115523.597,1.747263403,197.1696578
,61.2,20.8009292,0.475032356,116373.4944,1.742028192,197.974984
,61.4,20.91372026,0.479742686,118047.799,1.728503796,199.1835255
,61.6,21.18211051,0.484490233,118864.0615,1.724577338,200.0403528
,61.8,21.31735373,0.489294184,119491.3112,1.724577326,201.0352358
,62,21.52581596,0.494141642,119797.2931,1.727194931,201.8120777
,62.2,21.32985936,0.499064501,120341.4632,1.72675868,202.6447975
,62.4,21.56576601,0.504008292,120859.0374,1.728503741,203.6922738
,62.6,21.82829263,0.509000061,121464.5658,1.726758635,204.533762
,62.8,22.19233014,0.514035122,122783.7623,1.717160652,205.6535537
,63,22.52057839,0.519123044,124312.9265,1.704072508,206.6878826
,63.2,22.47686017,0.524286729,125854.551,1.69185694,207.8032898
,63.4,22.7651502,0.529480339,127717.0234,1.67833253,209.2419264
,63.6,22.889504,0.534736898,129053.1201,1.67004338,210.3233685
,63.8,23.0138494,0.540046313,130122.6947,1.667425746,211.6338087
,64,23.09741236,0.545411732,130056.0328,1.675714876,212.5125491
,64.2,22.9230091,0.550847999,129683.7696,1.687494196,213.366087
,64.4,23.20376761,0.556309002,129111.7246,1.703199911,214.4234243
,64.6,23.64927743,0.5618141,128569.3453,1.715851711,215.1761634
,64.8,24.19962574,0.567367731,127990.0501,1.730248591,216.0790114
,65,24.67091365,0.572982174,127892.9888,1.737228871,216.8262716
,65.2,24.84054855,0.578672996,128035.4069,1.741591562,217.6173574
,65.4,24.99394798,0.584422158,129086.7578,1.737228843,218.7744021
,65.6,25.57504865,0.59020082,129927.3511,1.733738629,219.6520496
,65.8,25.59903479,0.596074299,131445.4579,1.724140675,220.8540166
,66,25.76322401,0.601997529,133193.3791,1.710616279,221.9277892
,66.2,25.77512557,0.607990234,135070.1947,1.696655628,223.1286604
,66.4,26.16604883,0.614018275,137000.9733,1.68444002,224.6330389
,66.6,26.53407912,0.620108365,138585.3457,1.673969501,225.8098073
,66.8,26.93912906,0.626257296,140212.3235,1.665244058,227.299942
,67,26.99717459,0.632490818,141055.6017,1.664807784,228.6596876
,67.2,27.29943778,0.638770851,141790.8212,1.664371487,229.8035849
,67.4,27.20185666,0.64514021,142783.3684,1.661753874,231.0219865
,67.6,27.48080025,0.651548845,143759.7375,1.66088131,232.4441878
,67.8,27.41357113,0.658044696,144796.6166,1.657827424,233.6461544
,68,27.59180743,0.664589584,146384.7126,1.650847083,235.1844981
,68.2,27.58197385,0.671212695,147458.0648,1.647793192,236.4916505
,68.4,27.82051791,0.677885985,147956.1586,1.650410794,237.721011
,68.6,27.78611551,0.68464432,148234.9556,1.656954854,239.1136271
,68.8,28.16526662,0.69144327,148363.0551,1.664153282,240.3029964
,69,28.4603626,0.698316161,147985.7773,1.676586961,241.4090922
,69.2,28.44548244,0.705278406,147623.9397,1.687929993,242.3886351
,69.4,28.56872329,0.712301504,147685.6751,1.69709166,243.7045542
,69.6,28.80928201,0.719387542,147636.7197,1.704508235,244.6446541
,69.8,29.19087397,0.726535425,147546.6408,1.713669878,245.7907433
,70,29.18718238,0.733780466,147527.0714,1.720213934,246.6870138
,70.2,29.42770685,0.74108187,147625.323,1.725885427,247.6325921
,70.4,30.22407664,0.748420047,147399.4928,1.736355842,248.7655361
,70.6,31.01793831,0.755832038,147781.9933,1.73810085,249.682631
,70.8,30.97467422,0.763373751,148239.5612,1.740282207,250.8539187
,71,31.7302344,0.770938619,148969.4812,1.737664515,251.8038829
,71.2,31.37573287,0.778652636,150363.7401,1.729375414,253.1625304
,71.4,31.87830381,0.786387662,152127.1944,1.717159801,254.487218
,71.6,31.98560484,0.794226485,153610.5848,1.709743197,255.9258542
,71.8,32.56886665,0.802112607,154904.9831,1.704071631,257.1212506
,72,32.8949904,0.810095071,155914.202,1.703199062,258.5051042
,72.2,33.16035658,0.81816162,156251.4552,1.707561741,259.5799736
,72.4,33.2493002,0.826320926,156413.3016,1.713669517,260.6603201
,72.6,33.38982228,0.834558819,156344.5534,1.72283118,261.8677666
,72.8,33.63933909,0.8428722,156530.9616,1.72719386,262.8571727
,73,33.75736747,0.851277873,157492.2265,1.725448769,264.2015795
,73.2,34.04596725,0.85975667,158141.3874,1.724139933,265.0770348
,73.4,34.27297653,0.86832476,159102.5186,1.723267372,266.5101929
,73.6,35.03835442,0.876943402,160035.9126,1.720649681,267.6475202
,73.8,35.32025622,0.885680541,161131.7415,1.718468305,269.0675311
,74,35.20022964,0.894531901,161683.0607,1.721085938,270.3472907
,74.2,35.63438151,0.903435625,162010.0573,1.724576061,271.4407884
,74.4,35.70654653,0.912452612,162485.6257,1.726757406,272.5715366
,74.6,35.76538322,0.921561067,163114.7098,1.728502482,273.8512976
,74.8,35.95568046,0.930752472,163587.9569,1.730247546,274.9097317
,75,36.10186059,0.940039193,164365.8835,1.730683804,276.2245558
,75.2,36.4702022,0.949404517,165027.2777,1.73112004,277.331201
,75.4,36.62051316,0.958878314,165528.2501,1.733301378,278.4838629
,75.6,36.98133559,0.968433344,165859.5426,1.737664047,279.7723929
,75.8,37.08668163,0.978101249,165589.9353,1.745953171,280.6620903
,76,37.41335639,0.98785169,164622.9935,1.761658867,281.6295834
,76.2,38.1236233,0.997674854,164015.2887,1.772565554,282.4217695
,76.4,38.77479389,1.0076007,163832.268,1.779545815,283.2643567
,76.6,38.74777015,1.017670883,164300.9062,1.781727169,284.3688077
,76.8,39.38808305,1.027849743,165627.3979,1.774310517,285.3998535
,77,39.98678994,1.038031035,168464.0491,1.754678307,286.9469667
,77.2,40.32418643,1.048383406,170981.9227,1.738100013,288.3604037
,77.4,40.09155528,1.058930056,173776.5038,1.721521772,290.1551353
,77.6,40.55291284,1.069431052,175739.0789,1.710614978,291.525842
,77.8,40.52911876,1.080122706,177642.3987,1.70232585,293.2044327
,78,40.80154261,1.090902247,178446.4774,1.701889556,294.4469426
,78.2,41.10057708,1.101788399,179138.1848,1.70276207,295.7672461
,78.4,41.71580005,1.112763027,179640.9858,1.707124715,297.4118756
,78.6,42.20701949,1.12385614,179328.3833,1.716286341,298.5031829
,78.8,42.4086432,1.135079775,178402.7927,1.731555775,299.6613244
,79,42.7800016,1.146404977,178358.9771,1.738099792,300.6934638
,79.2,43.00988139,1.157853336,178745.2223,1.741589932,301.7990127
,79.4,43.63500021,1.169390626,179847.3978,1.740717334,303.2880553
,79.6,44.08951584,1.181055149,181273.6402,1.735045782,304.5612458
,79.8,44.46745773,1.192841972,183001.0168,1.728501698,306.1478022
,80,44.60822643,1.204762802,183810.3821,1.728065416,307.3377182
,80.2,44.77560398,1.216801441,183750.6136,1.735045721,308.4717547
,80.4,45.03948829,1.228954683,183375.606,1.745952447,309.8084937
,80.6,45.65367596,1.241206794,183168.1575,1.75336898,310.7759899
,80.8,45.77356447,1.253614471,183692.9615,1.755986589,312.1203978
,81,45.95084946,1.266143129,184131.3157,1.757731653,313.1941712
,81.2,46.94692106,1.278743441,185415.3646,1.752496321,314.4388793
,81.4,47.23483797,1.291517071,188013.4701,1.738535657,316.284017
,81.6,47.70496885,1.304407042,189184.9766,1.734609185,317.5506343
,81.8,47.80062495,1.317451089,190439.0575,1.731555284,319.1558155
,82,47.98779336,1.330620857,191791.6107,1.726756297,320.5067975
,82.2,49.00082024,1.343868562,192438.5492,1.728501285,321.8095773
,82.4,49.54159759,1.357280572,192421.4932,1.736790362,323.26575
,82.6,49.72911843,1.37085046,193258.5528,1.736354076,324.5235993
,82.8,49.80178499,1.384564274,194196.8247,1.736790341,326.0400294
,83,50.13945998,1.398398408,195310.1507,1.734172689,327.312124
,83.2,50.80704859,1.412349755,196850.9452,1.728501122,328.7332351
,83.4,51.04607292,1.426469617,198787.5216,1.721957054,330.6046692
,83.6,51.62333159,1.440709104,200211.7163,1.71890311,332.3216147
,83.8,51.71003262,1.455123879,201255.2859,1.717158025,333.6868404
,84,52.01597431,1.469669094,201375.3753,1.723702046,335.1704023
,84.2,52.57277702,1.484343872,201682.0326,1.727628423,336.4567431
,84.4,53.13080447,1.499165955,202553.9783,1.727192103,337.8537482
,84.6,53.77576478,1.514131338,204208.2951,1.722393075,339.6265746
,84.8,53.86193246,1.529283924,205645.3754,1.718902911,341.3522806
,85,54.9054302,1.544525582,206994.5831,1.71454012,342.8128403
,85.2,55.29943378,1.559963345,208206.5252,1.711486194,344.3402314
,85.4,55.70506238,1.575555381,209372.1745,1.710613618,346.2401553
,85.6,55.9625487,1.591313783,210022.7625,1.711486137,347.6481139
,85.8,56.4068208,1.607218252,211342.732,1.709304749,349.4505219
,86,56.70253406,1.623292318,212841.0279,1.706687104,351.2748426
,86.2,57.37517203,1.639503029,213941.148,1.706250774,352.8175758
,86.4,57.96207572,1.655882235,214758.253,1.708432069,354.4260494
,86.6,58.25230245,1.672445641,215470.4541,1.711922201,356.1112176
,86.8,58.91029976,1.689151152,216327.1271,1.71366722,357.7607799
,87,59.29283865,1.706042811,216923.1412,1.716721073,359.3237805
,87.2,59.34874349,1.723125605,217453.2249,1.719774956,360.8084358
,87.4,59.78406773,1.740355068,218486.0666,1.720647456,362.6963078
,87.6,59.81453822,1.757783631,219009.7152,1.722828802,364.0516719
,87.8,60.66503507,1.775333055,219139.5041,1.729372769,365.6886362
,88,60.7000264,1.793112483,219908.2824,1.729809036,367.0801583
,88.2,61.2833563,1.811034525,221528.3287,1.726755095,369.1400547
,88.4,62.0230961,1.829126348,222591.1402,1.725446219,370.5808899
,88.6,62.10959293,1.847442906,224128.9735,1.722828594,372.4819071
,88.8,62.59381379,1.865917201,225364.9361,1.721083472,374.0399785
,89,63.29185991,1.884563065,225602.2438,1.727627451,375.6933764
,89.2,64.0606064,1.903391609,225632.8727,1.734171424,377.0465579
,89.4,64.41742355,1.922436419,226281.1002,1.736352739,378.5553214
,89.6,65.36667948,1.941633604,226931.09,1.738970268,380.2437845
,89.8,65.48794565,1.961078226,227975.308,1.738970258,382.0177028
,90,66.08598532,1.980686781,229008.0418,1.737225125,383.4738762
,90.2,66.88037389,2.000479429,230165.2819,1.735043704,385.0790659
,90.4,67.09474347,2.020509144,231294.3619,1.735479954,387.0436337
,90.6,67.78338921,2.040708867,232447.5588,1.734171083,388.5414451
,90.8,67.69480301,2.06116272,234090.9498,1.731553475,390.5082018
,91,68.50487326,2.08176288,235864.2812,1.726754437,392.11887
,91.2,68.79982861,2.102603861,237418.9324,1.723700524,393.7580205
,91.4,69.91189198,2.123600602,238958.9835,1.722391614,395.8442206
,91.6,70.68608127,2.14483051,240742.6771,1.718901388,397.871249
,91.8,71.44692273,2.166274506,241529.1586,1.720210126,399.4271337
,92,71.79832716,2.187961047,242226.4801,1.72326398,401.3303444
,92.2,72.23124466,2.209860021,243612.6474,1.720646325,403.0560567
,92.4,72.68160168,2.231977856,245371.027,1.71628359,404.9351642
,92.6,73.1635439,2.254315813,246722.7758,1.715411008,407.0290269
,92.8,74.05984584,2.27685097,248710.3405,1.710611964,409.2390372
,93,74.19555476,2.299662515,250045.5849,1.708430605,410.9307797
,93.2,74.81718491,2.32267118,250021.9275,1.714974589,412.485567
,93.4,75.69673523,2.345894117,249503.5621,1.726317509,414.3767329
,93.6,76.11691864,2.369380628,249654.8907,1.73286151,416.2284483
,93.8,76.49046583,2.393106301,249276.9894,1.741150592,417.6210708
,94,76.88396516,2.416948425,249393.3987,1.746385787,419.0465641
,94.2,77.3389647,2.441268354,250449.0055,1.746385745,420.6769513
,94.4,78.05772648,2.465693649,251576.2755,1.747694486,422.7050761
,94.6,78.34872013,2.490517574,251749.11,1.75292969,424.0790715
,94.8,79.06243028,2.515313619,252641.965,1.755547238,425.9264074
,95,79.46486835,2.540504649,252382.3121,1.764272585,427.4877665
,95.2,80.38900482,2.565914386,251994.3645,1.772125343,428.7631574
,95.4,80.81216499,2.591612614,252746.0069,1.772997842,430.2565839
,95.6,81.44997083,2.61755481,254130.1648,1.770380167,432.0589968
,95.8,82.21421729,2.643749344,254649.5887,1.771688902,433.3968398
,96,82.94763348,2.670209089,256544.3411,1.766017335,435.3307369
,96.2,83.63108025,2.696938038,258276.7963,1.761218311,437.0433036
,96.4,84.35941872,2.723932558,258921.3438,1.764708395,438.9048855
,96.6,84.93710055,2.751208238,259490.425,1.767325955,440.3380507
,96.8,85.66202383,2.778748208,261055.8913,1.765144542,442.1974415
,97,86.33780809,2.806568122,261136.3865,1.769943438,443.4859786
,97.2,86.81883212,2.834680345,261290.5996,1.774306083,444.9180476
,97.4,87.55693591,2.86305821,262575.784,1.773433475,446.8771446
,97.6,87.98627831,2.891741533,263315.2018,1.774742242,448.6138148
,97.8,88.32570609,2.92071892,264018.8475,1.775178479,449.9910983
,98,89.24424215,2.949949266,267328.4143,1.762962861,452.1726233
,98.2,89.90560684,2.97949029,269933.8673,1.754673689,454.0692666
,98.4,89.97612022,3.009366495,272423.3251,1.747257111,456.021782
,98.6,90.81296714,3.039492127,276401.7222,1.733296428,458.5298216
,98.8,91.70135729,3.069916751,278741.0631,1.727188581,460.5031657
,99,92.32508517,3.100664319,279066.9626,1.73286002,462.503899
,99.2,93.46467737,3.131686755,279451.6841,1.736786334,464.1605936
,99.4,93.846576,3.163071721,280011.1717,1.741585256,466.3081456
,99.6,94.74100936,3.194738724,279746.7578,1.749001739,467.8300679
,99.8,95.78434125,3.226714237,281377.1804,1.747256566,469.968864
,100,96.47272358,3.259034346,284325.7011,1.737222321,471.9641201
,100.2,97.60498934,3.291650024,287812.1701,1.725442959,474.2387819
,100.4,98.28910729,3.324622907,292202.0456,1.711046028,477.2102964
,100.6,98.67319395,3.357946806,296357.0049,1.697957931,480.0601849
,100.8,99.74830152,3.391560017,298339.8078,1.694467684,482.1683025
,101,100.3636101,3.425541293,298655.5437,1.701011658,484.5525271
,101.2,101.32877,3.459840905,298531.9386,1.70842814,486.5653185
,101.4,102.1973494,3.494491453,297254.3793,1.721516118,488.2778903
,101.6,103.3013629,3.52947456,295265.6027,1.738966765,490.055111
,101.8,104.1011812,3.564829441,295062.5487,1.745946984,491.6318167
,102,104.5481251,3.60056271,296881.613,1.74420187,493.9086621
,102.2,105.7876042,3.636602725,299228.0609,1.738966536,496.0200691
,102.4,106.3251342,3.673051154,302843.5843,1.728059772,498.5927523
,102.6,107.0652267,3.70985243,307190.897,1.713662837,501.333078
,102.8,108.2487792,3.74699419,310529.1522,1.704937361,504.1522988
,103,108.6966803,3.784557619,311577.3819,1.705809859,506.2812263
,103.2,109.6254853,3.822466753,312917.388,1.705809775,508.6117675
,103.4,110.6948577,3.860747582,313732.4149,1.71060863,511.2633477
,103.6,111.6010738,3.899423729,314196.7236,1.7154075,513.2049197
,103.8,112.3304031,3.93850012,313385.7829,1.727622949,515.3667232
,104,113.5809916,3.977934882,312811.5194,1.73678447,517.0310908
,104.2,114.5219693,4.017786345,311191.2958,1.751181239,518.6078
,104.4,115.283562,4.058049939,310080.8463,1.76383295,520.6238774
,104.6,116.1228934,4.098713031,308860.0548,1.774739579,521.989117
,104.8,116.9833787,4.13978322,308909.4897,1.780410986,523.8452252
,105,117.8267402,4.181266337,309515.3391,1.782155979,525.4679516
,105.2,118.7391013,4.223160625,310684.0552,1.781283355,527.2594161
,105.4,119.7179648,4.265471275,311576.7394,1.783464603,529.3083679
,105.6,120.7350381,4.30820453,312734.9223,1.783900774,531.3113008
,105.8,121.6813132,4.351371795,313520.2308,1.785209489,532.94389
,106,122.6391689,4.394972027,314740.3094,1.785645665,534.9227169
,106.2,123.5653345,4.439012324,316333.8424,1.783464236,536.7612967
,106.4,124.4806121,4.483495802,318499.1484,1.778228931,538.7543679
,106.6,125.6587677,4.528408885,322019.0544,1.767758384,541.240503
,106.8,126.5406178,4.573792826,325562.2742,1.756851599,543.4822942
,107,127.6362495,4.619618596,329788.4425,1.74463599,546.3004221
,107.2,128.5520706,4.665916671,332949.9156,1.73678308,548.7306733
,107.4,129.1424601,4.712701455,336656.6521,1.728493932,551.7657403
,107.6,130.2104099,4.759924655,339055.6751,1.724131153,554.0568419
,107.8,131.1867514,4.807628417,341800.1146,1.719332115,556.8968816
,108,132.4517611,4.855792427,343414.1458,1.718023195,559.1474471
,108.2,133.4512486,4.904457827,345436.156,1.715405495,561.6390579
,108.4,134.8434174,4.953586154,346862.6112,1.717586707,564.6916687
,108.6,135.8161209,5.003235899,346733.583,1.724130636,566.7077515
,108.8,137.010088,5.05336984,345082.0674,1.738963632,568.8388855
,109,137.6863986,5.10404154,344246.2804,1.750306533,570.9601495
,109.2,138.9051681,5.155186595,342878.7438,1.762521917,572.5478229
,109.4,140.0090238,5.206853001,341870.8083,1.772992239,574.2461581
,109.6,141.320826,5.259024921,341858.2395,1.77953613,576.3137442
,109.8,142.3071873,5.311742439,343376.9144,1.777790965,578.2443641
,110,143.5139752,5.364974983,345792.5062,1.772991906,580.7294065
,110.2,144.99278,5.418724589,348187.0265,1.767320285,582.9240959
,110.4,146.1544625,5.47303511,350830.9705,1.761212429,585.2809422
,110.6,146.9640732,5.527914416,354546.05,1.752050732,588.2217843
,110.8,148.2662089,5.583312613,357525.3115,1.745070329,590.6334176
,111,149.2154388,5.639290776,360021.2718,1.741580099,593.4581205
,111.2,150.2153384,5.695827794,362182.2075,1.738526133,595.8620793
,111.4,151.3383008,5.752924931,364689.0745,1.735472156,598.9135926
,111.6,152.4986172,5.810593223,366614.415,1.73329071,601.3230338
,111.8,153.6180676,5.868843738,368615.0825,1.732418071,604.1444517
,112,154.8605781,5.927671567,370365.3222,1.731545421,606.4530914
,112.2,156.1778373,5.98738541,372293.2453,1.730672763,608.9721033
,112.4,157.2762018,6.047416421,374359.1459,1.731545196,612.0827845
,112.6,158.5184749,6.107735922,375307.8991,1.734598952,614.2917155
,112.8,159.9511576,6.168954104,375248.9662,1.74245163,616.7351272
,113,161.179042,6.23080075,375352.8669,1.749431792,619.3100203
,113.2,162.5799075,6.293257489,376100.739,1.752485531,621.5474416
,113.4,164.1163079,6.356332658,377110.937,1.754230455,623.798017
,113.6,165.2972943,6.420065186,377419.7922,1.75946555,626.3772911
,113.8,166.537259,6.484434021,379464.2244,1.756411562,628.6399108
,114,168.161558,6.549424472,382871.1281,1.749867402,631.6487047
,114.2,169.3114474,6.615099176,385580.1235,1.745504623,634.2531801
,114.4,170.447086,6.681434602,388571.965,1.740269312,636.9902323
,114.6,171.7806619,6.748423393,392979.409,1.73110758,640.2871883
,114.8,173.2256341,6.816078025,396299.7693,1.726308504,643.5030659
,115,174.4433308,6.884427307,398401.1385,1.724999594,646.1152109
,115.2,176.1102602,6.953433765,401038.0281,1.721945571,648.9585572
,115.4,177.3735037,7.023160018,404865.4488,1.716273984,652.6061319
,115.6,178.5567528,7.093591634,408163.9274,1.710602406,655.4922017
,115.8,180.0502681,7.164710026,413146.633,1.701004398,659.3041361
,116,181.1409264,7.236569261,416091.7494,1.697077897,662.3359304
,116.2,182.7706801,7.309114059,417743.1904,1.697514015,665.2044769
,116.4,184.5309599,7.382379005,418491.5049,1.703185321,668.8137148
,116.6,185.9191674,7.456404154,417332.5568,1.713655595,671.1650914
,116.8,187.4840808,7.5311619,413707.8036,1.734159984,673.7115057
,117,188.9656628,7.606678872,412015.2855,1.746375308,675.7484224
,117.2,190.8852321,7.682925737,411360.2966,1.755536723,677.8773858
,117.4,191.997945,7.7599918,411514.4677,1.763389418,680.7481177
,117.6,193.6264454,7.837798192,414298.7934,1.759026596,683.2528974
,117.8,195.1612086,7.91639243,420057.3811,1.745938459,686.895002
,118,196.7162329,7.995775048,424316.7361,1.736776714,689.8008055
,118.2,198.035642,8.075970862,427781.4349,1.730668861,692.8775296
,118.4,199.4098426,8.15696874,430301.3844,1.729359937,696.5382603
,118.6,201.2511454,8.238749677,430007.9215,1.735903755,698.9137542
,118.8,202.6151004,8.321383683,430040.5903,1.742883893,701.9378879
,119,204.3762574,8.404821971,430218.1666,1.748118919,704.3100936
,119.2,205.9691941,8.489109524,432566.4845,1.746373706,707.0263432
,119.4,207.4679673,8.574250278,438414.0947,1.735030646,711.1165876
,119.6,209.1592386,8.66023368,443811.9712,1.7232513,714.3730153
,119.8,210.707665,8.74709049,450587.1273,1.708854377,718.5399598
,120,212.443178,8.834807606,457736.8356,1.694021168,722.9074199
,120.2,214.6137458,8.923377421,461675.6426,1.687040718,725.8099478
,120.4,215.9757742,9.012890466,467355.3138,1.678751536,730.7033334
,120.6,217.9559195,9.103262148,470208.9357,1.677006297,734.2347882
,120.8,219.425835,9.194575421,472284.401,1.679623759,738.2329951
,121,221.2247052,9.286784577,472983.9411,1.686167584,742.0789105
,121.2,222.9452093,9.379925365,472052.985,1.696637808,745.1874233
,121.4,224.7200679,9.473998399,470713.3159,1.70754429,747.9683243
,121.6,226.5305569,9.569014194,469146.8887,1.72019583,751.1469653
,121.8,228.3750105,9.664982567,468986.9389,1.726957777,754.1743994
,122,230.1032311,9.761922819,469196.4526,1.732410936,757.1054116
,122.2,231.6199401,9.859851066,470386.9807,1.734592122,760.1065433
,122.4,233.3224697,9.958750942,471977.6548,1.737209557,763.6949724
,122.6,235.061871,10.05863718,473701.2302,1.738081924,766.5207981
,122.8,236.9034623,10.15952021,476291.8311,1.738518017,770.0927947
,123,238.7557099,10.26141607,477626.5289,1.741135436,772.9021873
,123.2,240.5828311,10.36433732,479111.567,1.745061653,776.5793708
,123.4,242.2150736,10.46830544,480885.1266,1.745497764,779.3230202
,123.6,244.1625203,10.5732974,483349.8016,1.74549758,782.9717174
,123.8,246.1630543,10.67934073,484111.7737,1.748987514,785.7077046
,124,247.8056107,10.78647298,486520.6757,1.748551093,789.2501139
,124.2,249.7309138,10.89466294,489361.877,1.74593332,792.4484834
,124.4,251.8208019,11.00392911,491434.4552,1.745496858,795.5230419
,124.6,253.7116407,11.11430613,493154.7261,1.746805475,799.0216311
,124.8,255.8070024,11.22577862,495048.8829,1.746369012,802.0096324
End Of Loading Marker,124.914,257.3642292,11.28979454,496491.0556,1.7459326,804.1802337
,125.2,259.6847299,11.29246387,499275.5035,1.746368648,808.7054975
,125.4,260.6628327,11.29240043,503207.2155,1.742878438,812.7738266
,125.6,261.5069657,11.29234578,508079.7322,1.735025591,816.1036557
,125.8,262.3877114,11.29228873,515505.1967,1.722373827,820.7033925
,126,262.9281238,11.292254,520407.572,1.71539354,824.3137123
,126.2,264.1159184,11.29217681,525833.1633,1.707540664,828.3480814
,126.4,264.3226543,11.29216398,531093.7519,1.701869203,833.2491195
,126.6,264.9562631,11.29212314,532763.665,1.70405047,836.7706911
,126.8,265.2969688,11.29210152,534426.5063,1.707540558,840.8850246
,127,265.723382,11.29207428,536105.0125,1.711030638,844.9467665
,127.2,266.3886109,11.29203137,536773.9981,1.716265756,848.3697279
,127.4,266.7359735,11.29200931,537231.8279,1.721937167,851.6940668
,127.6,266.9784901,11.29199413,537502.7227,1.728917382,855.4435336
,127.8,267.2393132,11.29197775,536362.7946,1.73807892,858.3054895
,128,267.5209391,11.29196001,535477.3759,1.74767672,861.8325324
,128.2,268.3434368,11.29190678,534734.9947,1.755529409,864.7065525
,128.4,268.2015184,11.29191683,533394.7032,1.765999778,867.9750015
,128.6,268.662048,11.29188734,530750.9289,1.778651413,870.2058413
,128.8,268.8513096,11.29187566,529198.9504,1.78912175,873.0020548
,129,268.9099298,11.29187255,527357.3262,1.799155835,875.0981162
,129.2,269.1333079,11.29185863,525805.7318,1.808753638,877.2884128
,129.4,269.2510079,11.29185164,526773.5676,1.811807481,880.1898099
,129.6,269.8837844,11.29181086,529188.0592,1.809626097,882.7526503
,129.8,269.5554732,11.29183313,531850.5228,1.807881071,885.8260604
,130,269.8021504,11.29181768,533852.0811,1.807008519,888.35383
,130.2,270.2185781,11.29179109,535928.4005,1.80613595,891.0612977
,130.4,270.312147,11.29178569,536316.7912,1.810934854,894.0043307
,130.6,270.5380214,11.2917716,535942.5392,1.816170009,896.102587
,130.8,271.0409886,11.29173934,534758.2276,1.824458991,898.5876313
,131,270.9714638,11.29174463,534087.1801,1.83013044,900.4809868
,131.2,271.1740391,11.29173208,532069.3479,1.839728244,902.2330048
,131.4,271.1685868,11.29173317,529633.5582,1.851071128,904.2688033
,131.6,271.2064042,11.29173142,528312.465,1.858051361,905.7468934
,131.8,271.4364392,11.29171706,527984.8121,1.86285025,907.7344853
,132,271.6556567,11.29170341,527486.8449,1.868085406,909.626753
,132.2,271.6726713,11.29170303,528721.6931,1.868085405,911.5628432
,132.4,271.704664,11.29170167,529988.5482,1.867649138,913.2534967
,132.6,272.0861431,11.29167737,530748.3333,1.869830425,915.2651988
,132.8,272.2995358,11.29166411,530941.9043,1.872884257,916.754251
,133,272.0286403,11.29168261,532039.5513,1.873756815,918.7999019
,133.2,272.5998405,11.29164587,533210.6453,1.873320493,920.5102936
,133.4,272.7125479,11.29163921,534141.0418,1.873756748,922.3181897
,133.6,272.8593718,11.29163031,535686.8247,1.87244794,924.466845
,133.8,272.8597442,11.29163102,536785.2817,1.871575412,926.2396763
,134,272.7602634,11.29163828,538186.823,1.871139158,928.3773715
,134.2,272.8588249,11.29163255,539017.1031,1.872011679,930.1436312
,134.4,273.2515375,11.29160752,537584.3574,1.879864404,931.7543106
,134.6,273.0026929,11.29162458,535028.7573,1.890334783,932.7086516
,134.8,273.2165016,11.29161128,531359.5473,1.904295228,933.5249479
Unloading Marker,134.92,273.2502592,11.29160951,529234.7609,1.912147994,933.9763783
,135.7,273.4480842,11.16181162,1.7977E+308,1.808316992,0
,135.9,273.343244,11.04896029,1.7977E+308,1.606762733,0
,136.1,273.2887466,10.93610566,1.7977E+308,1.327989623,0
,136.3,272.683808,10.82328715,1.7977E+308,0.968071311,0
,136.5,272.6355514,10.71043211,1.7977E+308,0.556237462,0
,136.7,272.288151,10.5975967,1.7977E+308,0.314983101,0
,136.9,272.0822095,10.484752,1.7977E+308,0.1618542,0
,137.1,271.9553184,10.37190213,1.7977E+308,0.101213409,0
,137.3,271.637874,10.25906475,1.7977E+308,0.074164999,0
,137.5,271.4281879,10.1462203,1.7977E+308,0.040572618,0
,137.7,271.340406,10.03336786,1.7977E+308,0.041008883,0
,137.9,270.9018895,9.920538423,1.7977E+308,0.03970009,0
,138.1,270.7829035,9.807688026,1.7977E+308,0.034901178,0
,138.3,270.5623999,9.694844288,1.7977E+308,0.028793472,0
,138.5,270.3889106,9.581997467,1.7977E+308,0.025957752,0
,138.7,270.1634144,9.469154057,1.7977E+308,0.022249502,0
,138.9,269.9316774,9.356311057,1.7977E+308,0.018759384,0
,139.1,269.5152118,9.243480177,1.7977E+308,0.026175885,0
,139.3,269.4249335,9.130627896,1.7977E+308,0.032719857,0
,139.5,269.0226138,9.017796088,1.7977E+308,0.037955035,0
,139.7,269.1070788,8.904932342,1.7977E+308,0.033156122,0
,139.9,268.990173,8.792081807,1.7977E+308,0.02922974,0
,140.1,268.7239034,8.679241073,1.7977E+308,0.023558298,0
,140.3,268.2129932,8.56641639,1.7977E+308,0.024430828,0
,140.5,268.2105026,8.453558349,1.7977E+308,0.022685769,0
,140.7,268.0157944,8.340712919,1.7977E+308,0.015705533,0
,140.9,267.6088981,8.227881411,1.7977E+308,0.008725296,0
,141.1,267.4033725,8.115036691,1.7977E+308,0.01090662,0
,141.3,267.4890856,8.002172863,1.7977E+308,0.017886857,0
,141.5,266.8600157,7.889355932,1.7977E+308,0.015269269,0
,141.7,266.7177305,7.776507063,1.7977E+308,0.009597826,0
,141.9,266.5554746,7.663659505,1.7977E+308,0.001308795,0
,142.1,266.2226361,7.550823138,1.7977E+308,0.009161562,0
,142.3,265.9771692,7.437981039,1.7977E+308,0.013960475,0
,142.5,265.6934251,7.325141451,1.7977E+308,0.013524211,0
,142.7,265.461272,7.212298478,1.7977E+308,0.015705535,0
,142.9,265.2998482,7.099450865,1.7977E+308,0.018759389,0
,143.1,265.0094473,6.986611713,1.7977E+308,0.023994568,0
,143.3,264.9836576,6.873755201,1.7977E+308,0.034464925,0
,143.5,264.4760757,6.760930299,1.7977E+308,0.044062754,0
,143.7,264.3986952,6.648077172,1.7977E+308,0.052788052,0
,143.9,264.3978688,6.535219022,1.7977E+308,0.055405642,0
,144.1,264.0791761,6.422381727,1.7977E+308,0.052788053,0
,144.3,263.599886,6.309554969,1.7977E+308,0.041881432,0
,144.5,263.3868713,6.19671074,1.7977E+308,0.032719869,0
,144.7,263.3011696,6.083858159,1.7977E+308,0.026175895,0
,144.9,262.7819382,5.971034021,1.7977E+308,0.026175896,0
,145.1,262.6163538,5.858186681,1.7977E+308,0.034028665,0
,145.3,262.477397,5.745337593,1.7977E+308,0.035773725,0
,145.5,262.3193017,5.632489762,1.7977E+308,0.037518786,0
,145.7,261.8291941,5.519663713,1.7977E+308,0.031847342,0
,145.9,261.6777556,5.406815445,1.7977E+308,0.022685778,0
,146.1,261.4223033,5.293974001,1.7977E+308,0.008725299,0
,146.3,261.3091419,5.181123221,1.7977E+308,0.009161564,0
,146.5,260.9380261,5.068289366,1.7977E+308,0.007416505,0
,146.7,260.7832592,4.955441316,1.7977E+308,0.003053855,0
,146.9,260.4138077,4.842607351,1.7977E+308,0.003053855,0
,147.1,260.3555656,4.729752968,1.7977E+308,0.008289035,0
,147.3,260.1591035,4.617471948,1.7977E+308,0.01134289,0
,147.5,259.7765175,4.503510256,1.7977E+308,0.011779155,0
,147.7,259.4087301,4.390676182,1.7977E+308,0.015705541,0
,147.9,258.7712491,4.278424098,1.7977E+308,0.018759397,0
,148.1,258.9509908,4.1655541,1.7977E+308,0.023122047,0
,148.3,258.752122,4.052708944,1.7977E+308,0.033592408,0
,148.5,258.2254013,3.939885298,1.7977E+308,0.04231771,0
,148.7,258.1039188,3.827035064,1.7977E+308,0.049297952,0
,148.9,257.777737,3.71419826,1.7977E+308,0.054969399,0
,149.1,257.4823433,3.601359437,1.7977E+308,0.052351809,0
,149.3,257.1561614,3.488522633,1.7977E+308,0.041881448,0
,149.5,257.0413358,3.375671962,1.7977E+308,0.029666026,0
,149.7,256.7783944,3.26283101,1.7977E+308,0.014396748,0
,149.9,256.3706656,3.149999557,1.7977E+308,0.008289037,0
,150.1,256.3090951,3.037145392,1.7977E+308,0.022685786,0
,150.3,255.868914,2.924316068,1.7977E+308,0.034464944,0
,150.5,255.5161045,2.811481011,1.7977E+308,0.043626513,0
,150.7,255.3679944,2.698632524,1.7977E+308,0.047116634,0
,150.9,254.7472451,2.585815048,1.7977E+308,0.048861696,0
,151.1,254.7289444,2.472958044,1.7977E+308,0.051479287,0
,151.3,254.3054054,2.360127628,1.7977E+308,0.058023266,0
,151.5,253.7645388,2.24730491,1.7977E+308,0.056278207,0
,151.7,253.6688517,2.134452984,1.7977E+308,0.054096882,0
,151.9,253.4063263,2.021612004,1.7977E+308,0.046244109,0
,152.1,253.1808298,1.908768594,1.7977E+308,0.038827602,0
,152.3,252.5234675,1.795953519,1.7977E+308,0.025303382,0
,152.5,252.110746,1.683122394,1.7977E+308,0.019631935,0
,152.7,252.1552696,1.570261268,1.7977E+308,0.012651691,0
,152.9,251.7895624,1.457427058,1.7977E+308,0.008289039,0
,153.1,251.3348192,1.344598689,1.7977E+308,0.003490122,0
,153.3,250.8164194,1.231774497,1.7977E+308,0.012651692,0
,153.474,250.6112673,1.133601319,1.7977E+308,0.020068202,0
,228.7,249.4814438,1.012628233,1.7977E+308,0.004798919,0
,228.9,249.5929525,0.899762712,1.7977E+308,0.010470369,0
,229.1,249.1511068,0.786933498,1.7977E+308,0.017886881,0
,229.3,248.8806762,0.674093036,1.7977E+308,0.017886881,0
,229.5,248.2158246,0.561278453,1.7977E+308,0.018323147,0
,229.7,247.4619369,0.448469711,1.7977E+308,0.019195679,0
,229.9,247.0375656,0.33563935,1.7977E+308,0.021377007,0
,230.1,246.2079557,0.222835577,1.7977E+308,0.021813273,0
,230.3,245.127048,0.110048291,1.7977E+308,0.02704846,0
,230.486,243.93352,0.004604174,1.7977E+308,0.027048462,0
END,,,,,,