File: GB1_test29.csv
Segment,Time On Sample,Displacement Into Surface,Load On Sample,Harmonic Contact Stiffness,Harmonic Displacement,Harmonic Load
Surface Marker,0,0,0,-382.8810034,0.427124586,2.202283836
,0.2,0.181499238,0.000646058,2861.961195,0.269188833,2.274597644
,0.4,0.14164598,0.001306647,9440.641817,0.187166952,2.342528785
,0.6,0.515372382,0.001940086,16974.65484,0.138739137,2.470721452
,0.8,0.663585527,0.002588329,21934.97358,0.116924806,2.566044197
,1,0.336639752,0.003267764,25727.06921,0.102527351,2.682184515
,1.2,0.25434673,0.003931139,27345.2547,0.097291912,2.797229185
,1.4,0.252772475,0.004589215,27755.89933,0.104272498,2.998831288
,1.6,0.309448876,0.005243467,28792.38592,0.113434516,3.295756132
,1.8,0.491780264,0.00588947,28461.71651,0.130449692,3.667186109
,2,0.630007584,0.006538369,27826.23248,0.147901155,4.025468127
,2.2,0.60263661,0.007198138,28247.15481,0.15880832,4.376080475
,2.4,0.35141675,0.007872198,29769.04498,0.160117182,4.686153251
,2.6,0.460518868,0.008522216,34303.14689,0.157499462,5.380803992
,2.8,0.430235487,0.009181384,39869.75487,0.150955163,6.050254453
,3,0.563886095,0.009829791,45368.57583,0.147464869,6.702174317
,3.2,0.568969184,0.010486637,46838.00448,0.157935748,7.319032931
,3.4,0.863641246,0.011124473,46491.58355,0.172333203,7.841664535
,3.6,0.689395532,0.011793092,45603.82262,0.198946687,8.844196695
,3.8,0.678251652,0.012451003,43319.18808,0.230795608,9.743736526
,4,0.859751012,0.013096269,41317.52773,0.263953387,10.62136314
,4.2,0.450422292,0.01378032,40146.2946,0.294057168,11.48912858
,4.4,0.987250653,0.014402259,38506.59371,0.330268947,12.37880762
,4.6,1.032693124,0.015056456,37736.08335,0.368662166,13.56760266
,4.8,0.619203646,0.01574078,37520.3062,0.397238946,14.5509606
,5,0.666310422,0.016394868,36860.22235,0.43061487,15.50144878
,5.2,0.642684259,0.017053599,36126.22214,0.468571804,16.52479859
,5.4,0.564136048,0.017715935,35373.3772,0.507401314,17.52294809
,5.6,0.238438621,0.018394496,34597.96207,0.549284837,18.55615869
,5.8,0.126188242,0.019059046,32742.05952,0.610801253,19.55869083
,6,0.00561634,0.019724141,30525.11599,0.681915975,20.42207368
,6.2,0.474624308,0.020350533,27813.79738,0.774845004,21.23067365
,6.4,-0.3482841,0.021061734,25615.01788,0.861229789,21.81904453
,6.6,-0.334879489,0.021718034,22872.44618,0.97859089,22.30990189
,6.8,0.241476129,0.022337379,19923.13347,1.130854887,22.69886276
,7,0.563609223,0.022973413,17967.22496,1.255196549,22.91470864
,7.2,0.48838962,0.023635531,16061.85439,1.398734847,23.06481453
,7.4,0.835903354,0.024269898,14843.28727,1.509115331,23.15904179
,7.6,0.998263213,0.024916419,14555.41975,1.549689972,23.39132263
,7.8,0.85480713,0.025583017,15178.56647,1.51827735,23.87998842
,8,0.840750717,0.02624112,16292.24677,1.452398076,24.4234376
,8.2,0.6943821,0.026907908,18607.52384,1.329801553,25.32078599
,8.4,0.684486449,0.027565738,20877.82709,1.232509643,26.11514208
,8.6,0.363365858,0.028243999,23236.84946,1.156595795,27.02782961
,8.8,0.917669424,0.028864791,23885.09366,1.152232896,27.59976646
,9,0.916927448,0.02952202,23604.03673,1.188880971,28.17279856
,9.2,0.996904237,0.030173949,22595.41552,1.251706236,28.50040197
,9.4,1.430545716,0.030802662,21101.18504,1.344198964,28.72282203
,9.6,0.982105848,0.031489281,19449.36326,1.457197224,28.92551942
,9.8,1.198555601,0.032132252,18631.25244,1.521767623,29.07452987
,10,1.562296292,0.032765553,17942.63496,1.584156576,29.25202766
,10.2,2.02339826,0.033395746,17753.62641,1.611642593,29.43829083
,10.4,1.924462848,0.034056138,18478.59948,1.575430816,29.86121689
,10.6,2.152562722,0.034698344,19644.21791,1.514350679,30.32577849
,10.8,1.943782701,0.035369229,21793.21153,1.410078205,31.01495078
,11,1.849007527,0.03603263,24268.24127,1.305369435,31.69864472
,11.2,1.746742984,0.036696523,27911.50119,1.177973762,32.60914113
,11.4,1.750161768,0.037353479,30694.66369,1.102059898,33.37172301
,11.6,1.622100505,0.038019066,32964.86332,1.055813528,34.23620155
,11.8,1.19280014,0.038704427,33132.95518,1.066284431,34.77636319
,12,0.658648581,0.039396673,31467.07646,1.133908885,35.28584634
,12.2,1.599902923,0.039992063,28748.24611,1.240799042,35.52141487
,12.4,1.731473147,0.040640606,24810.81425,1.427529691,35.62988569
,12.6,1.937104915,0.041284286,22566.36218,1.559724509,35.62440754
,12.8,2.251748617,0.041920811,21229.41231,1.653089809,35.63865147
,13,2.322571728,0.042573341,20860.57161,1.687556443,35.73726131
,13.2,2.456638404,0.04322172,21689.77006,1.649599501,36.11526539
,13.4,2.513314928,0.043875179,23298.45466,1.567141336,36.624749
,13.6,2.351135431,0.044543005,26464.66531,1.424475643,37.46840988
,13.8,2.477712738,0.045191875,29223.47934,1.322384578,38.16415638
,14,2.356308697,0.045857024,32572.10565,1.221166104,39.06260048
,14.2,2.005230651,0.046537251,34345.51817,1.178846329,39.70465895
,14.4,2.423061223,0.047167002,35387.85483,1.162267414,40.31056138
,14.6,2.183491572,0.047839908,35804.21862,1.168811728,41.0260295
,14.8,2.300915206,0.04848938,35924.41219,1.182772892,41.67794949
,15,2.361752491,0.049142566,35743.96742,1.20458722,42.27508614
,15.2,2.617313384,0.049782969,35542.60225,1.225092671,42.76703949
,15.4,2.475937691,0.050449429,35576.89286,1.237744991,43.25570527
,15.6,2.444406085,0.051108678,35518.63071,1.259123035,43.90433811
,15.8,2.199011368,0.051781967,35049.48852,1.29140826,44.43025634
,16,2.641806502,0.052410079,34574.52775,1.32456601,44.93974045
,16.2,2.576156657,0.053071568,34365.22803,1.345071482,45.35280558
,16.4,2.359055115,0.053743,33959.89769,1.376484132,45.86119322
,16.6,2.353320226,0.054400556,33766.25854,1.3969896,46.30055432
,16.8,2.424143338,0.055053086,33787.42076,1.41182334,46.8220903
,17,2.355997035,0.05571474,33925.10872,1.421421651,47.35020007
,17.2,2.536664234,0.056360059,33955.22028,1.431456228,47.75230886
,17.4,2.367827518,0.057028322,33956.91506,1.442363406,48.1686608
,17.6,2.655010195,0.057666649,33860.04464,1.459814849,48.69019707
,17.8,2.679232785,0.058322239,33810.88003,1.474648591,49.19201105
,18,2.516221135,0.05899012,33773.12196,1.485992057,49.55905812
,18.2,2.773446333,0.059630413,33572.69899,1.506933791,49.99841965
,18.4,2.672846096,0.060294197,33406.83546,1.524385263,50.36217977
,18.6,2.71787249,0.060948421,33291.26227,1.539655289,50.71717483
,18.8,2.61976871,0.061612041,33170.68988,1.556670474,51.12804861
,19,2.642326995,0.062267739,32925.22335,1.575867082,51.42935613
,19.2,2.628270584,0.062925842,32794.37429,1.592445974,51.81174263
,19.4,2.476076911,0.063593012,32816.29575,1.601608006,52.13167621
,19.6,2.420412891,0.064253846,32947.90408,1.605970877,52.46804482
,19.8,3.1228395,0.064864914,32973.15192,1.616877982,52.83838018
,20,3.267308075,0.065512609,33199.42208,1.617750544,53.16598387
,20.2,3.299436109,0.06616768,33498.58427,1.618186829,53.56699679
,20.4,3.659016011,0.066801254,33855.31018,1.613823934,53.92418366
,20.6,3.930387782,0.067440619,34269.52003,1.608806616,54.34437106
,20.8,3.946288849,0.068096754,35027.76397,1.588955578,54.79194974
,21,4.063712475,0.068746225,36050.33238,1.561033231,55.3386861
,21.2,3.6423176,0.069431067,37303.0677,1.52525777,55.89802165
,21.4,3.644904233,0.070088076,38650.52229,1.48991856,56.52528913
,21.6,4.052748953,0.070718482,39883.59551,1.460251044,57.12133079
,21.8,3.904299976,0.071385406,41037.49,1.437564156,57.81379009
,22,3.958063965,0.072039056,42062.37759,1.419676405,58.49529298
,22.2,3.757605448,0.072709591,42502.56755,1.416622415,58.98724563
,22.4,3.650763283,0.073378767,42858.40441,1.41705871,59.52521624
,22.6,3.999939423,0.074024697,42983.41075,1.427093275,60.18590196
,22.8,3.595600744,0.074726786,42747.75519,1.446289915,60.74797673
,23,3.440074442,0.075419507,41911.1547,1.482065425,61.08653651
,23.2,3.986467404,0.076072866,40308.02691,1.546635791,61.39332335
,23.4,4.071430934,0.076763242,39154.96506,1.596808737,61.61136047
,23.6,4.338218612,0.077448534,38263.30647,1.641091799,61.8617201
,23.8,4.235945713,0.078165055,37761.99163,1.67054115,62.11207909
,24,4.149898616,0.078887835,38286.50467,1.659633995,62.548153
,24.2,4.379236058,0.079596918,39569.71877,1.620368188,63.04558481
,24.4,4.17044424,0.080342123,41488.86385,1.56452353,63.7544788
,24.6,4.473424804,0.081061089,43443.85252,1.512605408,64.49514793
,24.8,4.167268844,0.081827441,45476.52934,1.464177628,65.3004602
,25,4.297991552,0.082572616,46838.95374,1.438872999,66.05208569
,25.2,4.210689195,0.083339712,47316.06931,1.436255287,66.59882176
,25.4,4.212841979,0.084108564,47513.91649,1.445417305,67.30442909
,25.6,4.24370276,0.084883403,47273.22136,1.462868765,67.78871247
,25.8,4.34363096,0.085661297,46653.02814,1.493408816,68.3266835
,26,4.219708986,0.086461775,46119.36893,1.518713446,68.72221785
,26.2,4.124078916,0.087268368,45775.64057,1.540091495,69.20650101
,26.4,4.357147646,0.088061492,45590.95882,1.555361506,69.62942764
,26.6,4.456238598,0.088871499,45590.86728,1.567577522,70.17616393
,26.8,4.209985112,0.089712408,45817.84919,1.569758976,70.62757689
,27,4.471343115,0.090528198,46187.01711,1.570631528,71.1896529
,27.2,4.517172367,0.091366639,46214.23883,1.581538688,71.68598863
,27.4,4.412380768,0.09222326,46200.84041,1.592009575,72.10562761
,27.6,4.345034658,0.093085959,46446.67489,1.596808733,72.65784196
,27.8,4.334272821,0.093957967,46560.70197,1.602916747,73.07090717
,28,4.670517721,0.094811571,46842.21946,1.604661865,73.58696537
,28.2,4.554071179,0.09569924,47287.15547,1.60160787,74.13917948
,28.4,4.451769126,0.096599176,47698.72315,1.598117588,74.62346275
,28.6,4.431016528,0.097502889,47967.06638,1.601171596,75.19430334
,28.8,4.616636231,0.098402018,48249.25609,1.600735295,75.62270813
,29,4.406982219,0.099336274,48571.26767,1.602044173,76.17163535
,29.2,4.48109059,0.100261271,48832.8305,1.605098174,76.70960635
,29.4,4.721627932,0.101184469,48994.59494,1.609024733,77.14896796
,29.6,4.748300676,0.102131176,49196.47844,1.611642451,77.61572082
,29.8,4.837383312,0.103083321,49282.07213,1.619059315,78.13177854
,30,4.599428673,0.104066347,49254.67356,1.629530213,78.61715706
,30.2,4.447184124,0.105053661,49292.84626,1.637819672,79.10034424
,30.4,4.884933862,0.10601207,49384.064,1.643055073,79.49368855
,30.6,5.206180767,0.106987766,49529.90571,1.647854198,79.91771112
,30.8,5.216201228,0.107993695,49991.7264,1.643927619,80.44472534
,31,5.150494222,0.109014832,50672.57084,1.633893036,81.02871399
,31.2,5.212104856,0.110037872,51345.37282,1.622549582,81.5316238
,31.4,5.275378158,0.111071089,52363.73532,1.603789257,82.21093532
,31.6,5.406886307,0.112110044,53278.16465,1.587210359,82.82341165
,31.8,5.242146639,0.113178979,54279.54595,1.570631486,83.54764502
,32,5.376980013,0.114239001,55153.22797,1.558415453,84.25653962
,32.2,5.457721809,0.115313214,55814.51246,1.550126003,84.83285892
,32.4,5.446093004,0.116404318,56331.13951,1.547071999,85.43547396
,32.6,5.526831345,0.117500266,56853.26805,1.547071994,86.19586467
,32.8,5.598414276,0.118607748,57257.24112,1.549253424,86.89161142
,33,5.946269914,0.119708291,57618.02306,1.54968968,87.44711361
,33.2,5.77319657,0.120854266,58010.82962,1.551871127,88.13738125
,33.4,5.514409745,0.122017286,58307.84744,1.55448887,88.72575199
,33.6,5.777380445,0.123157552,58579.13161,1.560596859,89.48066493
,33.8,5.893890546,0.124318961,58659.15708,1.567577435,90.0032968
,34,5.799032145,0.125506051,58523.5558,1.582411185,90.62892051
,34.2,6.55047051,0.126649385,58459.10246,1.594627147,91.23044181
,34.4,6.848384184,0.127833902,58616.59804,1.59898999,91.7399262
,34.6,6.536328487,0.129070601,59000.10328,1.598553732,92.34144476
,34.8,6.80760942,0.130281249,59631.43057,1.59331827,93.05362688
,35,7.230340099,0.13149402,60868.68666,1.573685343,93.87318446
,35.2,7.27360749,0.132744063,62045.95085,1.554488739,94.58755733
,35.4,7.20037159,0.134014404,63585.58375,1.531365556,95.55941102
,35.6,7.175398498,0.135294206,64803.50897,1.514786674,96.34061903
,35.8,7.430026449,0.136568443,66335.66463,1.494717474,97.33329107
,36,7.467460657,0.137869946,67055.43379,1.48991832,98.08710782
,36.2,7.26689731,0.139200168,67553.46125,1.492099771,98.94501196
,36.4,7.351760012,0.140524796,67802.49421,1.500389208,99.84893478
,36.6,7.580582894,0.14185329,67711.77559,1.512168926,100.5129076
,36.8,7.305951648,0.143228452,67460.39907,1.529620408,101.2601495
,37,7.416604614,0.144591953,67307.8535,1.545326713,102.0084882
,37.2,7.297581432,0.145984332,67298.05444,1.554925026,102.58152
,37.4,7.520986604,0.147368055,67692.27838,1.55972416,103.4470951
,37.6,7.500569024,0.148781717,68148.74774,1.560160449,104.1307891
,37.8,7.684858583,0.150196109,68903.5581,1.556233856,105.0040337
,38,7.918658921,0.151621493,69860.73012,1.547944395,105.9189136
,38.2,7.675633872,0.153092613,70439.90473,1.545326697,106.6453381
,38.4,7.400984704,0.15458052,70729.36088,1.548817012,107.3487532
,38.6,7.867364551,0.156034538,71231.51144,1.550998407,108.2921211
,38.8,7.871065536,0.157533698,71346.37919,1.560160424,109.1149645
,39,7.855208556,0.159049197,71227.62256,1.571940161,109.7351102
,39.2,8.062781967,0.160565245,71143.07027,1.584374309,110.4390748
,39.4,7.936660006,0.162118451,70985.45142,1.598117344,111.1309861
,39.6,7.651594525,0.163697735,70592.04852,1.615568828,111.7215479
,39.8,8.121288416,0.165243125,70528.46067,1.627348524,112.4512614
,40,8.306383828,0.16682289,70933.63888,1.626912222,113.080173
,40.2,8.210209339,0.168437043,71577.72331,1.62342194,113.8953464
,40.4,8.49307753,0.170042323,72450.86981,1.614259901,114.6546426
,40.6,8.296207504,0.171695479,73374.49164,1.604661616,115.4566678
,40.8,8.244545372,0.173355621,74463.48664,1.594627033,116.4186603
,41,8.611869136,0.175004755,74833.30225,1.596372149,117.1034513
,41.2,9.103180905,0.176662282,75158.55615,1.601171259,117.937253
,41.4,8.856787281,0.178385142,75469.33989,1.604661572,118.6538164
,41.6,9.358495529,0.180076055,75829.33059,1.607279249,119.3747648
,41.8,9.204049232,0.18182726,76209.77377,1.610769555,120.239243
,42,9.426564986,0.18357119,76600.47846,1.61164211,120.9437555
,42.2,9.356160472,0.185351881,77134.5938,1.611642117,121.8104253
,42.4,9.785460373,0.187117494,77284.33849,1.617313805,122.4919297
,42.6,9.714218019,0.188934026,77214.4511,1.6273484,123.1635712
,42.8,9.697478741,0.190765069,77106.06295,1.639564422,123.8910921
,43,10.15423098,0.192583402,77149.63319,1.646981253,124.502474
,43.2,10.10669623,0.194453276,77498.0443,1.650035263,125.2847777
,43.4,10.20894584,0.1963321,77961.62391,1.649162682,125.9695681
,43.6,10.66818563,0.198206226,78733.6234,1.644799779,126.8734925
,43.8,11.06168241,0.200103527,79495.57023,1.63825545,127.6185453
,44,11.18306251,0.202037748,80070.37375,1.637382867,128.5016505
,44.2,11.28030709,0.203993082,80581.90695,1.636074001,129.2138325
,44.4,11.36839487,0.205968716,81417.53309,1.629529698,130.0125718
,44.6,11.14109394,0.207984871,82624.8406,1.616877413,130.9055369
,44.8,11.41557738,0.209988263,84111.21898,1.602043653,131.9738101
,45,11.43125837,0.212028905,85989.65091,1.581538192,133.1341181
,45.2,11.32128119,0.214098234,87282.16538,1.569322182,134.0774843
,45.4,11.38605092,0.216187364,88020.16401,1.567140746,135.0022249
,45.6,11.39173617,0.218291043,88127.38387,1.577175334,136.0157139
,45.8,11.68617648,0.220386076,87975.44035,1.58808247,136.7563837
,46,11.5503892,0.222541294,87522.40889,1.605970224,137.6110011
,46.2,11.74163419,0.224696486,87194.30077,1.619931373,138.2859307
,46.4,11.65992991,0.226891378,87028.19569,1.631274828,138.9981119
,46.6,11.87446819,0.229088821,87347.74841,1.636510247,139.965584
,46.8,11.51232169,0.231346462,87755.08054,1.637819138,140.7018687
,47,11.70105615,0.233590372,88353.79059,1.638255409,141.6594795
,47.2,11.91475158,0.235855172,88787.15561,1.639127964,142.394671
,47.4,11.9936348,0.238151603,89587.74719,1.634765095,143.2492891
,47.6,12.29137027,0.240456745,90252.31471,1.63476507,144.2671619
,47.8,12.06567855,0.24281948,90544.73882,1.638255381,145.0286475
,48,12.38337823,0.245170089,90757.47346,1.644363364,145.9062754
,48.2,12.62118755,0.247549722,91181.18494,1.645235917,146.6743367
,48.4,12.52197159,0.249975373,91330.29433,1.652216509,147.5870245
,48.6,12.72815148,0.252405283,91486.62525,1.657451928,148.3364592
,48.8,12.67053535,0.254877045,92106.96371,1.656579361,149.2611992
,49,12.63621552,0.2573721,92638.92606,1.655706792,150.0424075
,49.2,12.60605248,0.259891837,92641.15666,1.665305096,150.9068862
,49.4,12.77060895,0.262424079,92704.77905,1.672285665,151.6059204
,49.6,13.17398894,0.264966068,92885.86337,1.677521066,152.3443997
,49.8,12.97904771,0.267573029,92909.54872,1.686246812,153.178199
,50,12.81905268,0.270203873,92954.75579,1.692354836,153.8125878
,50.2,13.07346509,0.272833696,93585.53556,1.690609669,154.6945981
,50.4,12.90763661,0.27551778,93925.67742,1.69235483,155.4286923
,50.6,13.10628636,0.278204659,93947.31261,1.699335399,156.1167697
,50.8,14.24859192,0.280856573,93911.67779,1.708497307,156.8936004
,51,14.75263284,0.283576923,93959.70785,1.714168986,157.497314
,51.2,14.92630514,0.286346436,94146.39822,1.718968119,158.2829053
,51.4,15.21397781,0.289136307,94966.40266,1.711987514,159.0367234
,51.6,14.83842107,0.291997997,96599.08918,1.69279095,159.9789926
,51.8,15.31165456,0.294832349,98682.67403,1.668795161,161.1568335
,52,15.22234893,0.297732313,100424.7966,1.650034857,162.1615569
,52.2,15.35189458,0.300647011,102009.6702,1.636509971,163.3448746
,52.4,15.41153482,0.303595606,102462.087,1.638255113,164.2487976
,52.6,15.75743056,0.306554942,102244.4088,1.649598527,165.0584949
,52.8,15.4509146,0.309587071,102016.0839,1.66225086,165.9624162
,53,15.83674405,0.312603962,101701.1039,1.6757757,166.8422361
,53.2,16.40897064,0.315638934,101529.444,1.684937669,167.5127852
,53.4,16.09245436,0.318763004,101840.3303,1.687555412,168.2994704
,53.6,16.57147013,0.321865969,102524.9166,1.685373938,169.1836735
,53.8,16.73925618,0.325020738,103041.605,1.686682782,170.1401891
,54,16.63575575,0.328225117,103610.255,1.685373934,170.9246839
,54.2,16.4823211,0.33146494,104446.7638,1.682756233,171.9513202
,54.4,16.81069713,0.334705383,104779.1787,1.685810206,172.7402001
,54.6,17.06833506,0.337983209,104966.8017,1.69104562,173.5356536
,54.8,17.16827503,0.341304232,105128.7372,1.697589906,174.4351942
,55,17.53574647,0.344640932,105129.9876,1.706315599,175.2843357
,55.2,17.52999256,0.348035703,105229.157,1.711551036,175.9800821
,55.4,17.67235622,0.351454888,105628.5585,1.712423597,176.7371867
,55.6,17.66617536,0.354918176,106176.1905,1.712859884,177.7057537
,55.8,17.97870303,0.358395281,106696.695,1.711550998,178.4606675
,56,18.19303124,0.361913904,107277.4897,1.710678407,179.406227
,56.2,17.9230416,0.365499745,107768.2495,1.70980586,180.1841468
,56.4,18.3915808,0.369072857,108348.5994,1.708060674,181.0168539
,56.6,18.71115914,0.372691783,109245.5936,1.703697783,182.1278587
,56.8,18.466949,0.376384128,109928.6528,1.700643803,182.9452231
,57,18.89219893,0.380069439,110835.7127,1.696717189,183.9882975
,57.2,18.93964614,0.383816757,111551.9251,1.694099468,184.84182
,57.4,18.82689817,0.387612303,112104.2223,1.694099479,185.6942458
,57.6,18.90720333,0.391433167,112387.2169,1.700207481,186.696779
,57.8,18.94797516,0.395295143,112749.9035,1.702825195,187.4933269
,58,18.89553988,0.399201931,113033.284,1.70762435,188.4334064
,58.2,19.26125452,0.403120403,113027.286,1.715259327,189.2447475
,58.4,19.36691553,0.407095422,113135.396,1.720494753,190.0210261
,58.6,19.43512337,0.411112829,113537.9111,1.721585463,190.886601
,58.8,19.84825162,0.415147874,113808.9965,1.724203144,191.7927174
,59,19.77290043,0.41925581,114077.5891,1.72551201,192.5136639
,59.2,19.7233394,0.423403191,114924.4684,1.721149153,193.5424924
,59.4,19.69207908,0.427591022,115589.4929,1.71853144,194.3894402
,59.6,20.19006046,0.431786052,116479.0875,1.713732247,195.3130877
,59.8,20.2782005,0.436050235,118050.8151,1.702388799,196.4832576
,60,20.37590347,0.440356642,119905.4698,1.687991346,197.7345068
,60.2,20.35668228,0.444714023,121157.456,1.679265624,198.7074563
,60.4,20.89166706,0.449078508,122266.5338,1.673157571,199.7724449
,60.6,20.7397038,0.453532065,122913.9182,1.67490273,201.0193095
,60.8,20.93057984,0.458007837,122528.0072,1.686682442,201.8224322
,61,20.69788363,0.462556412,121338.4895,1.709805632,202.657327
,61.2,21.03021102,0.467113469,120479.8312,1.727257051,203.2741883
,61.4,21.43159972,0.471711676,119808.0138,1.742527032,203.9140579
,61.6,21.71065478,0.476364271,119428.2373,1.755179306,204.7270422
,61.8,22.00551328,0.481062594,119841.7905,1.755615566,205.4644262
,62,22.70645418,0.485781328,120299.4104,1.756924361,206.3541092
,62.2,22.63764746,0.490598182,120423.6798,1.760850943,207.0378034
,62.4,22.81931064,0.495446852,121032.0561,1.758669497,207.815726
,62.6,22.75881,0.500360224,121858.1355,1.755179214,208.8204494
,62.8,23.05862308,0.505299271,122403.9907,1.753434042,209.5797469
,63,23.3817285,0.510286423,124113.3143,1.738600285,210.7477264
,63.2,23.50843419,0.515361972,125710.1094,1.724639117,211.734921
,63.4,23.60933909,0.520465041,127018.4753,1.7154771,212.7703241
,63.6,23.64616429,0.525597692,128454.1672,1.706751375,214.0456773
,63.8,23.95509067,0.53079,129414.067,1.702388487,215.0361597
,64,23.87955482,0.536059758,129546.0685,1.709369073,216.0792317
,64.2,23.84977888,0.541379489,129493.7076,1.716785941,216.8845443
,64.4,24.50485502,0.546707516,129264.9884,1.725947891,217.6646613
,64.6,24.94189899,0.552103395,128949.4414,1.738163863,218.63104
,64.8,24.91043313,0.557584385,128556.9582,1.750379878,219.4900401
,65,24.93554482,0.563116615,128620.3809,1.755179024,220.1989353
,65.2,25.37838765,0.568676869,128901.8467,1.758669272,221.1083394
,65.4,26.00928777,0.574280672,129627.944,1.756487784,222.0330841
,65.6,26.43297322,0.579954635,130405.7833,1.752124885,222.8537392
,65.8,26.41644159,0.585714522,131776.2605,1.742526594,224.0063776
,66,26.4148795,0.591531231,132580.8712,1.73860002,224.8905788
,66.2,26.81440502,0.597380038,133602.9351,1.733364552,226.0224026
,66.4,27.24803941,0.603285233,134136.6405,1.732928227,226.9307108
,66.6,27.34131449,0.609272284,134906.6385,1.730746789,227.8850348
,66.8,27.38964386,0.615322377,135710.1273,1.729874213,228.9993262
,67,27.75750963,0.621412183,137016.5365,1.72332989,230.1859327
,67.2,27.79333735,0.627585007,138122.2381,1.718094455,231.1961355
,67.4,27.93650273,0.633812672,139331.9363,1.711986438,232.2644091
,67.6,28.36841463,0.640083904,140517.8809,1.708059826,233.6208446
,67.8,28.59560731,0.646431618,141276.7669,1.706314662,234.6222833
,68,29.02500261,0.652829664,141982.6942,1.70675091,235.8757263
,68.2,29.15398112,0.659311778,142366.071,1.708496044,236.8256684
,68.4,29.43440077,0.665849061,142976.6898,1.708059733,237.8851772
,68.6,29.31787388,0.672478242,143870.884,1.706314604,239.2547563
,68.8,29.7688635,0.679136535,144482.0045,1.705878276,240.2660582
,69,30.45284477,0.68584644,145210.7015,1.705878216,241.5008759
,69.2,30.88800214,0.692640135,146072.732,1.703696748,242.5691517
,69.4,31.39304932,0.699497554,146351.9064,1.709368422,243.8072559
,69.6,31.18659639,0.706470723,146744.9455,1.712422446,244.8612836
,69.8,31.2189597,0.71349808,147245.1523,1.713731299,245.8758691
,70,31.93367564,0.72055118,148316.1385,1.710677231,247.191767
,70.2,32.11996437,0.727710039,149221.4682,1.709804647,248.482461
,70.4,32.06491788,0.73495668,150597.834,1.703260362,249.6701609
,70.6,32.37350981,0.742252214,152035.5289,1.696716051,250.9389425
,70.8,32.22939993,0.749650873,153561.4354,1.69104434,252.4115144
,71,32.49885732,0.757096456,154266.6066,1.692789461,253.7109744
,71.2,32.6376551,0.764625463,155196.5629,1.690608019,254.851562
,71.4,32.85050231,0.772225201,155992.1808,1.690171715,256.0337855
,71.6,33.44196606,0.779876405,156619.1668,1.693661951,257.5425207
,71.8,33.76380065,0.787622333,156949.3645,1.69715221,258.6096995
,72,34.24373157,0.7954355,157862.0868,1.696715886,260.0220144
,72.2,34.31423171,0.80335437,158670.3091,1.695843305,261.1888976
,72.4,34.560303,0.811341535,159409.8292,1.695843284,262.4072789
,72.6,35.03270659,0.819394029,160496.1243,1.694098099,263.9850395
,72.8,34.77280449,0.827575747,161550.0527,1.690607836,265.2067035
,73,35.32090786,0.835786411,162805.2846,1.686681215,266.7559772
,73.2,35.83612815,0.844081709,163000.1342,1.690607742,267.8713674
,73.4,36.33219571,0.852461633,162782.6865,1.69889713,268.9922358
,73.6,35.93285554,0.860984786,162370.9527,1.711113171,270.3223702
,73.8,36.53665965,0.869527359,162092.0324,1.720275121,271.3846213
,74,36.77680018,0.878179714,161732.2899,1.730309674,272.420574
,74.2,37.10971171,0.886912884,161880.4817,1.735763218,273.4959712
,74.4,37.29864718,0.895743402,162691.3644,1.735108772,274.722569
,74.6,37.94400325,0.904632606,163297.6859,1.735981286,275.8806915
,74.8,38.19989853,0.913636843,163626.9906,1.740344121,277.1122207
,75,38.70043175,0.922715427,163939.3878,1.743834363,278.0753138
,75.2,39.04409007,0.931895437,164586.3149,1.745579475,279.3495744
,75.4,38.90508629,0.941199484,165373.2111,1.744270631,280.4397596
,75.6,39.69225141,0.950536076,166534.6323,1.739907702,281.6471883
,75.8,39.52575688,0.96002931,168168.9654,1.73249086,283.1186647
,76,39.81318542,0.969587897,169468.9725,1.726382833,284.353481
,76.2,40.27202172,0.979231334,171150.6899,1.718529649,285.9049461
,76.4,40.6800814,0.988975061,172068.5564,1.717220755,287.1693461
,76.6,41.17550134,0.998810868,172586.6435,1.71940214,288.3603377
,76.8,41.36717058,1.008765553,173458.1681,1.719402123,289.8175735
,77,41.47893746,1.018825493,174386.3951,1.717656971,291.0425276
,77.2,41.73465034,1.028976932,175033.0781,1.720274663,292.4559371
,77.4,41.91878204,1.039235183,175700.2011,1.721147219,293.6622654
,77.6,42.14991385,1.049593487,176712.6231,1.719402056,294.977065
,77.8,42.1026748,1.060073829,177320.2254,1.722456061,296.4058111
,78,42.68119629,1.070618039,177419.1397,1.729436581,297.7359532
,78.2,42.80035381,1.081298458,177404.5605,1.735108285,298.763688
,78.4,43.25734742,1.092063827,177757.9389,1.738162244,299.9152352
,78.6,43.42556758,1.102956384,178799.0196,1.736853372,301.4283501
,78.8,43.67864972,1.113952737,179823.3975,1.734235635,302.6182442
,79,44.34030017,1.125032758,181663.9267,1.726818719,304.2201109
,79.2,44.9886185,1.136224965,183164.9883,1.721146947,305.482323
,79.4,44.92210169,1.147576679,184636.3339,1.716347812,306.8935386
,79.6,45.75012849,1.158983576,185298.8544,1.719838023,308.5019818
,79.8,45.78759412,1.170557242,184992.2679,1.728563733,309.5538205
,80,46.43334326,1.182206942,184479.4153,1.740343387,310.8302758
,80.2,46.78532466,1.193993127,184605.8282,1.744706212,311.913891
,80.4,47.26460626,1.205889296,184313.4444,1.75255931,312.9350549
,80.6,47.62653563,1.217912762,185446.3668,1.749941563,314.4832326
,80.8,47.71133971,1.230075377,187307.9567,1.739906987,315.856102
,81,48.08487071,1.242403058,189588.2888,1.728563528,317.6245083
,81.2,48.50083143,1.254790385,190370.1636,1.729872348,319.0970851
,81.4,48.65132643,1.267256637,191262.4635,1.730308621,320.5236427
,81.6,49.01149338,1.27989738,190697.6464,1.741215728,321.5250841
,81.8,49.65623553,1.292646407,188959.5129,1.763029947,322.5276232
,82,50.16365253,1.305532371,188231.3901,1.774809611,323.3800554
,82.2,50.84330401,1.318536642,188745.6136,1.776990976,324.6280237
,82.4,51.00200866,1.331705957,189399.6227,1.776990962,325.7401254
,82.6,51.41449809,1.344990785,190908.3256,1.770010355,327.0275352
,82.8,51.89936338,1.35840431,192890.4436,1.76041203,328.6052975
,83,52.35175335,1.371954863,193750.904,1.758666846,329.7699938
,83.2,52.79496802,1.385642117,194145.8431,1.76215709,331.1439615
,83.4,52.96438344,1.399484875,194318.58,1.766083644,332.2319585
,83.6,53.56066978,1.413438516,193975.9233,1.774373014,333.2542198
,83.8,54.16275885,1.427532004,194534.3051,1.7761181,334.5887455
,84,54.74901455,1.441768135,195814.9494,1.77088262,335.8027476
,84.2,55.33108675,1.456147608,197190.8307,1.766519712,337.31258
,84.4,55.85155685,1.470675622,198387.4495,1.763029381,338.6032787
,84.6,55.77119144,1.485389159,199394.9419,1.760847962,339.897258
,84.8,56.39729789,1.500203947,200569.3094,1.758666478,341.4081867
,85,56.95348011,1.51517194,201311.5085,1.758666427,342.5783624
,85.2,57.25167193,1.530307216,202815.0517,1.754303546,344.1802276
,85.4,57.74123409,1.545581772,205185.4898,1.742523796,345.7459378
,85.6,58.0127486,1.561024012,208820.6446,1.722890931,347.6326758
,85.8,58.53804414,1.576604775,212415.6887,1.705439473,349.7396458
,86,59.0549933,1.592342522,214786.6236,1.695841148,351.467515
,86.2,59.58939245,1.608237316,217399.8255,1.68667911,353.5854417
,86.4,60.216967,1.624285547,218589.3126,1.686242768,355.2760582
,86.6,60.97266695,1.640486679,218304.6396,1.69584098,356.8132843
,86.8,61.20907955,1.656884762,218062.5711,1.70413038,358.1960172
,87,61.43880875,1.673448064,218371.1286,1.709802065,359.9326488
,87.2,61.83244499,1.690167019,219159.1349,1.711983461,361.7251606
,87.4,62.26766202,1.70705117,219925.7139,1.712855989,363.2448542
,87.6,62.15945829,1.724140841,221246.5841,1.710238292,364.9321764
,87.8,62.91666301,1.741345037,222788.5425,1.707620513,366.848503
,88,63.20866852,1.758752837,224194.2164,1.704566489,368.4492731
,88.2,63.39662751,1.776342509,225232.5366,1.705875324,370.3524458
,88.4,63.95902578,1.794084048,225488.8039,1.711546988,371.8732353
,88.6,64.33749064,1.812015906,225384.5363,1.719836373,373.3315699
,88.8,65.18359493,1.830097225,224980.5225,1.730743427,374.9257721
,89,65.77003962,1.848377342,223544.5072,1.748194781,376.2318115
,89.2,65.96950556,1.866866609,222760.8925,1.759538177,377.3198094
,89.4,66.50429824,1.885519569,223008.9806,1.763464697,378.5381951
,89.6,67.25625216,1.904345515,223573.6445,1.766518624,380.1455445
,89.8,67.73065405,1.923379357,224097.87,1.768700003,381.5222538
,90,67.95288415,1.942621574,225359.4883,1.765645987,382.9877091
,90.2,68.31030781,1.962048211,226871.4648,1.761719388,384.6662728
,90.4,69.10125029,1.981641551,227537.2754,1.762591885,386.0161411
,90.6,69.79604818,2.001438124,228514.3743,1.761719251,387.4679055
,90.8,70.14214385,2.021456535,230345.5706,1.756047513,389.2779495
,91,70.88639103,2.041649696,231430.054,1.753866019,390.6880789
,91.2,71.58566986,2.062048784,232929.9549,1.750375675,392.4959352
,91.4,71.47024188,2.082706614,234147.6321,1.747757976,393.9849434
,91.6,72.07042932,2.103524894,235955.2341,1.74339507,395.973583
,91.8,72.77668254,2.124545304,237319.7501,1.740341011,397.4626009
,92,73.6301926,2.145767095,239394.0898,1.735105513,399.4512436
,92.2,74.0563601,2.167230283,241138.6158,1.732051479,401.4585079
,92.4,74.63228015,2.188899352,242900.858,1.727688577,403.1798052
,92.6,75.39581523,2.210773761,244499.5863,1.724634514,404.9723231
,92.8,75.61134511,2.232904097,245007.9698,1.728997344,406.8513927
,93,76.56828455,2.255207742,245088.6345,1.734232677,408.2691956
,93.2,77.16278738,2.277759518,245941.8134,1.735977763,410.1416947
,93.4,77.94074304,2.300525803,246804.2563,1.736413977,411.7413757
,93.6,78.42449764,2.323540092,247942.3638,1.735541364,413.4539074
,93.8,79.35299911,2.346756372,249656.6225,1.732487285,415.4995264
,94,79.82170115,2.370236199,251604.8817,1.726815539,417.2383538
,94.2,80.40936299,2.393944084,253728.8386,1.722016353,419.4099704
,94.4,81.06064633,2.41788598,255167.7494,1.71983487,421.2068703
,94.6,81.64906418,2.44207254,256402.9036,1.720271102,423.4135489
,94.8,82.55449209,2.466481304,257705.6752,1.718525881,425.1556683
,95,82.86863923,2.491174296,258426.5823,1.721579847,427.1990894
,95.2,83.50686888,2.516094031,258878.4349,1.724633783,428.7900041
,95.4,84.27279374,2.541254599,258885.9425,1.731177985,430.4050251
,95.6,84.82980906,2.566681633,259601.0972,1.735540783,432.5032327
,95.8,85.54239556,2.592353932,259795.3823,1.740776135,434.0251214
,96,86.32900228,2.618279247,260438.0678,1.744702626,435.8757113
,96.2,86.96825629,2.644606564,261070.0184,1.749065414,437.7646471
,96.4,87.9553485,2.670910392,262418.7998,1.748192754,439.5725084
,96.6,88.63448249,2.69763208,263309.0206,1.749065262,441.1305537
,96.8,89.78789848,2.724590826,264573.029,1.747756302,442.7970772
,97,90.32631357,2.751861122,266679.0512,1.742520837,444.9599292
,97.2,91.28991299,2.779377256,268318.1258,1.739903041,447.0866288
,97.4,91.7433614,2.807203551,269458.6695,1.739030431,448.8484659
,97.6,92.46721362,2.835291528,270172.923,1.740775503,450.5697678
,97.8,93.4414976,2.86364532,271142.6173,1.742520552,452.6110055
,98,93.83073594,2.892322596,272420.7804,1.741647948,454.3377813
,98.2,94.58524163,2.921263737,274961.0714,1.735103611,456.6299249
,98.4,95.36882624,2.950493877,276529.9165,1.732922117,458.5002377
,98.6,95.54572803,2.980057736,278553.9755,1.728559256,460.5414668
,98.8,96.33918044,3.010029163,280694.299,1.724632624,462.9157864
,99,96.82557015,3.040020648,281405.3301,1.728122856,464.9756453
,99.2,97.62727204,3.070444143,281565.2547,1.733358197,466.5983378
,99.4,98.62198371,3.101160438,282126.9712,1.736412097,468.4029137
,99.6,99.39030197,3.132200406,283465.8407,1.736412027,470.6786227
,99.8,99.80490766,3.163575606,285310.7637,1.733794283,472.9850069
,100,100.7087663,3.195233738,287349.9061,1.728995073,474.9331141
,100.2,101.419516,3.22722276,290028.4878,1.722887027,477.4257652
,100.4,101.9754351,3.259543368,292366.9297,1.718087849,479.6050529
,100.6,103.0272627,3.292156051,293622.3344,1.719396607,481.6714949
,100.8,103.9666982,3.325103886,293745.1784,1.727249639,483.84531
,101,104.6830654,3.358397343,292831.826,1.738156682,485.4110276
,101.2,105.5616482,3.392014561,291912.2597,1.749936278,487.2221767
,101.4,106.5159028,3.425964509,290696.1086,1.762152149,488.726541
,101.6,107.672315,3.460242355,290285.0697,1.769568874,490.2374805
,101.8,108.1529684,3.494909129,290247.4225,1.775676809,492.0497203
,102,109.058794,3.529896135,291208.2829,1.776549293,493.9529063
,102.2,110.0211496,3.565230938,292461.6243,1.774804066,495.5799851
,102.4,111.0783137,3.6009143,294439.9901,1.770004842,497.4152414
,102.6,111.8017295,3.636977949,296561.7427,1.766078217,499.7040994
,102.8,112.6074704,3.67339819,299673.8118,1.756043607,501.765061
,103,113.7310335,3.710163139,303267.3823,1.745136401,504.2873028
,103.2,114.4343034,3.747325057,306081.1186,1.738592075,506.7514677
,103.4,115.234043,3.78485367,307966.7567,1.735974298,508.9219952
,103.6,116.0204083,3.822760157,309808.1233,1.733792806,511.1418286
,103.8,117.0264,3.861032869,310194.7909,1.73771927,512.9420232
,104,118.1063915,3.899685292,311380.8411,1.739464309,515.3284022
,104.2,119.1147567,3.938730799,312548.1558,1.73946422,517.2787029
,104.4,120.0906056,3.978170808,314185.9077,1.737282708,519.4152682
,104.6,120.8550262,4.01802099,316474.9503,1.733356085,522.1840304
,104.8,121.7899732,4.058260219,317287.4614,1.734664852,524.1178968
,105,122.4161294,4.098924088,317623.3597,1.739027634,526.433051
,105.2,123.9392752,4.139937398,317769.7148,1.743390328,528.272699
,105.4,124.6285439,4.181417881,318132.1252,1.747316822,530.1988924
,105.6,125.7646094,4.223285452,319407.9639,1.748625568,532.6630653
,105.8,126.8423577,4.265577611,322664.369,1.739463513,534.9606961
,106,127.9849458,4.308290383,325843.9972,1.732919148,537.7491869
,106.2,128.5915631,4.351467595,329055.6458,1.725065986,540.0588631
,106.4,129.7415033,4.395042733,333574.851,1.714158789,543.3513614
,106.6,130.6916586,4.439068955,336089.4557,1.710232148,545.7169221
,106.8,131.5277394,4.483544966,337641.2675,1.71197721,548.4046075
,107,132.5484857,4.528455583,339595.0271,1.710231983,550.6408808
,107.2,133.3170198,4.573834203,341264.0059,1.71154076,553.4227937
,107.4,134.4957293,4.61964401,341568.3163,1.717212341,555.6415383
,107.6,135.330273,4.665936754,340776.0753,1.728555641,558.098039
,107.8,136.6598699,4.712661862,340175.2756,1.736844906,559.8850946
,108,137.926149,4.759860654,338784.8157,1.749933296,562.063302
,108.2,138.9976303,4.807546629,337045.8326,1.762585419,563.5720537
,108.4,140.0852622,4.855710561,335319.0242,1.776110106,565.3382874
,108.6,141.4328629,4.904341342,336533.6348,1.77610998,567.3784417
,108.8,142.0285417,4.95351031,338572.546,1.772837798,569.6152576
,109,143.2798731,5.003130047,340799.1361,1.769129272,571.8970062
,109.2,144.6076827,5.053243348,345291.4212,1.75647693,574.755625
,109.4,145.8222403,5.103867616,349456.3821,1.74513345,577.4181181
,109.6,146.7055228,5.155022346,351085.2092,1.744260802,579.6280952
,109.8,147.6648649,5.206685972,351898.1927,1.748187263,582.1262336
,110,149.1125941,5.258836715,352139.7435,1.752986246,584.0754517
,110.2,150.1046401,5.311541399,353099.9168,1.755603853,586.4212934
,110.4,151.3803636,5.364756864,353602.9617,1.759530284,588.454875
,110.6,152.9289458,5.418488997,355660.7234,1.756912441,590.7590906
,110.8,154.0418138,5.472789912,359925.888,1.746005258,593.8434147
,111,155.017707,5.527645324,364070.2383,1.734879948,596.6855954
,111.2,156.3034868,5.583031491,366104.7131,1.732480273,599.2768724
,111.4,157.3008396,5.638993099,368027.4827,1.730298766,601.8856751
,111.6,158.5544039,5.695500144,369219.5931,1.732043784,604.7968876
,111.8,159.8053813,5.752575101,368877.8963,1.739024198,606.8206084
,112,161.2676325,5.810209679,367507.7344,1.752112553,609.1544074
,112.2,162.2138614,5.868457213,367555.8224,1.757347862,611.0685568
,112.4,163.5290536,5.927265802,367945.2211,1.761274286,613.1130975
,112.6,164.844984,5.986665036,369069.1682,1.763891861,615.8095604
,112.8,165.9236583,6.046675283,371058.1115,1.76083778,618.0031076
,113,167.5685117,6.107249634,375094.3645,1.750803121,621.0732003
,113.2,168.8204957,6.168458459,378093.6709,1.744695045,623.5855908
,113.4,170.4934472,6.230254634,381134.5965,1.73989578,626.2864428
,113.6,171.5779735,6.292710382,384369.3943,1.735969135,629.5252601
,113.8,173.1467083,6.355761715,386853.6193,1.732915012,631.9554806
,114,174.3991272,6.419467391,389991.6076,1.729424635,635.1197952
,114.2,175.9310449,6.48379476,393282.0383,1.725061669,638.3630025
,114.4,176.9078193,6.548805065,395331.0655,1.723752731,641.0265917
,114.6,178.3712944,6.614436352,398043.1972,1.720262337,643.930141
,114.8,179.7181643,6.680734604,399731.9379,1.721134779,647.0451517
,115,180.9342816,6.747707648,400396.3029,1.724624929,649.5181009
,115.2,182.4665068,6.815332596,401691.7936,1.727242484,652.5706622
,115.4,183.6948911,6.883657166,403277.4386,1.727678654,655.2660312
,115.6,185.3492241,6.952640123,406115.6788,1.725060808,658.6703064
,115.8,186.6189961,7.022341584,407531.5691,1.725933257,661.2845975
,116,188.2830931,7.092717263,409296.7814,1.726805669,664.4094762
,116.2,189.8796739,7.163804587,410736.4237,1.727241806,666.9514604
,116.4,191.4652656,7.235968544,412161.3873,1.728550507,669.7454456
,116.6,192.7645414,7.308517779,411528.2645,1.738148598,672.721309
,116.8,194.4590282,7.381401632,413535.7451,1.736839596,675.2874004
,117,195.6640392,7.455418709,417307.4853,1.730731534,678.7453548
,117.2,197.493872,7.53013827,420167.5297,1.726804826,681.5108613
,117.4,199.1862815,7.605617583,423457.0602,1.722005568,684.5798644
,117.6,200.8377953,7.681858024,428907.4633,1.712407211,688.7083802
,117.8,201.9166723,7.7589023,430824.9148,1.712843395,691.5987782
,118,203.8774984,7.836662431,430291.3825,1.722441421,694.5965689
,118.2,205.0443353,7.915256057,430359.7028,1.729421827,697.5253165
,118.4,206.7003469,7.994607289,429240.3111,1.739892442,699.8405003
,118.6,208.2705209,8.074761354,429807.1955,1.745563961,702.8404765
,118.8,209.9986739,8.155710476,430992.2913,1.747308929,705.3068644
,119,211.4928652,8.237488287,432700.234,1.749053918,708.4985795
,119.2,213.2207581,8.320072366,432932.2559,1.753852857,710.7907564
,119.4,214.6655902,8.40350488,434504.8155,1.753852723,713.4028632
,119.6,216.3807355,8.487757779,434644.9727,1.759960507,716.4981668
,119.8,217.9068496,8.572869549,434552.4678,1.765195745,718.6972077
,120,219.7656848,8.658814669,435411.4437,1.768685824,721.5284582
,120.2,221.0776649,8.745658128,438188.6336,1.764759166,724.0868747
,120.4,222.4943564,8.833366551,440272.9129,1.765631596,727.2884518
,120.6,224.1497327,8.921939761,442547.6439,1.764322596,729.9378175
,120.8,226.1952422,9.011377235,444574.2081,1.764322405,732.9564314
,121,227.5607485,9.101757031,447223.2477,1.760832025,735.6660554
,121.2,229.4445351,9.193010344,449156.5006,1.760831853,738.8008078
,121.4,231.0926795,9.285195878,452085.0205,1.75646888,741.7317595
,121.6,233.0602192,9.378286571,454621.3386,1.753414733,744.6221816
,121.8,235.0950136,9.472308032,459594.984,1.744252634,748.3201111
,122,236.9282791,9.567287449,463651.596,1.73901709,752.0114676
,122.2,238.7772035,9.663220119,467128.385,1.734654105,755.089244
,122.4,240.4786854,9.760126454,470997.9198,1.729854855,758.4727123
,122.6,242.1059517,9.858011202,477335.6516,1.717638837,762.2046027
,122.8,244.1740967,9.956850357,482059.933,1.711966994,766.3692931
,123,245.7403022,10.0567156,485634.8846,1.709785441,770.4112578
,123.2,247.5393478,10.15756864,487455.0408,1.710657841,773.4298712
,123.4,249.7825957,10.25940583,487113.9173,1.718510695,776.5219046
,123.6,251.3940853,10.36230778,484458.8249,1.73421666,779.7727969
,123.8,253.6303486,10.4662025,483709.7093,1.742069509,782.3827355
,124,255.5036322,10.57116495,483816.6041,1.748177269,785.5722766
End Of Loading Marker,124.19,257.3262842,10.67185302,484570.5135,1.751231054,788.2019288
,124.4,259.2147339,10.67439555,486400.5705,1.751667172,791.1854842
,124.6,260.149423,10.67433492,487570.4743,1.755593612,794.7508201
,124.8,261.3824345,10.6742547,488363.1322,1.758647459,797.3552602
,125,261.8935637,10.67422187,489222.8546,1.762573937,800.5677821
,125.2,262.8698597,10.6741585,491717.3773,1.761265008,803.9435655
,125.4,263.6801435,10.67410603,495511.2826,1.755593284,807.1067894
,125.6,264.2332958,10.67407044,501877.1756,1.742941093,810.8824868
,125.8,264.6612109,10.67404307,508290.595,1.732034039,815.2487469
,126,264.8881639,10.6740289,512211.6669,1.727234933,818.7077884
,126.2,265.7246601,10.67397471,514291.9365,1.728543699,822.5119801
,126.4,265.956606,10.6739602,513475.9202,1.73683301,825.4659158
,126.6,266.5842348,10.67391972,510951.0632,1.750357652,828.1590903
,126.8,266.948491,10.67389653,508950.992,1.762573474,831.0604384
,127,267.2245403,10.67387914,509127.2219,1.768026956,833.9108339
,127.2,267.4885236,10.67386253,510149.1303,1.771299036,836.8149186
,127.4,267.7978585,10.67384295,512624.9102,1.769990166,839.7370825
,127.6,268.0801489,10.67382514,517094.6197,1.764318494,843.7067079
,127.8,268.3878196,10.67380566,520410.6114,1.760391941,846.7713089
,128,268.6243422,10.67379086,522982.6105,1.75995564,850.4100395
,128.2,268.7680811,10.67378215,526414.4029,1.757337944,854.1123184
,128.4,268.9134843,10.67377332,528075.7963,1.758646773,857.1330884
,128.6,269.4479133,10.67373896,528274.5936,1.764318371,860.007048
,128.8,269.3378493,10.67374691,527575.9458,1.773480273,863.0760222
,129,269.639695,10.67372782,527656.24,1.779151892,865.6070317
,129.2,269.8096463,10.67371739,525278.1351,1.792240292,868.142419
,129.4,270.1447776,10.67369611,524042.3377,1.800965871,870.311858
,129.6,270.3946144,10.67368043,522896.3554,1.809255178,872.4385627
,129.8,270.4018823,10.67368068,521594.0761,1.818417068,874.8567099
,130,270.4686482,10.67367702,519673.2476,1.828887794,877.0502476
,130.2,270.8961471,10.67364968,518818.441,1.834995681,878.8219592
,130.4,270.6583496,10.67366601,515403.4954,1.8485204,880.1772981
,130.6,271.2060927,10.67363077,512388.9784,1.861608761,881.8591682
,130.8,271.0822985,10.67363962,510631.7402,1.869898103,883.1027532
,131,271.6183916,10.67360515,508208.0886,1.880805063,884.4745478
,131.2,271.3498049,10.67362351,507252.1367,1.887349298,885.939454
,131.4,271.5921525,10.67360832,507917.8898,1.888221836,887.3725971
,131.6,271.9410141,10.67358614,510076.5167,1.884295278,889.0971936
,131.8,272.2341222,10.67356763,512272.8879,1.880805006,891.1329586
,132,271.9796819,10.67358505,514475.5247,1.876878508,892.9221835
,132.2,272.2827757,10.67356588,515662.4474,1.876442199,894.8177034
,132.4,272.215567,10.67357101,516914.4785,1.875569646,896.5740648
,132.6,272.4446003,10.6735567,515348.8924,1.883422672,897.81437
,132.8,272.444795,10.67355741,513325.6522,1.893020843,899.0754893
,133,272.7395674,10.67353878,512487.5384,1.898256179,900.1437768
,133.2,272.5350555,10.67355293,511642.4113,1.903927847,901.4322808
,133.4,272.7332996,10.67354064,512197.4185,1.904800389,902.6550535
,133.6,273.1246003,10.67351568,515064.7781,1.899128705,904.5900215
,133.8,272.8851385,10.67353212,518574.4895,1.891275682,906.3956822
,134,273.3155498,10.67350459,520228.7802,1.889966799,908.2627185
,134.196,273.4952666,10.6734935,520827.7601,1.890839343,909.5731436
,134.9,273.3790094,10.58603814,1.7977E+308,1.846338756,0
,135.1,273.0142067,10.47939753,1.7977E+308,1.658301928,0
,135.3,273.0413423,10.37273118,1.7977E+308,1.403514155,0
,135.5,272.7980322,10.26608259,1.7977E+308,1.037911166,0
,135.7,272.5206043,10.15943624,1.7977E+308,0.626062441,0
,135.9,272.0101771,10.05280519,1.7977E+308,0.300597237,0
,136.1,271.9108273,9.94614715,1.7977E+308,0.106888713,0
,136.3,271.8397703,9.839487252,1.7977E+308,0.035774998,0
,136.5,271.5640067,9.732840793,1.7977E+308,0.056280181,0
,136.7,271.4613283,9.626182972,1.7977E+308,0.013088414,0
,136.9,270.81443,9.519560877,1.7977E+308,0.025304268,0
,137.1,271.2476502,9.412867876,1.7977E+308,0.043191768,0
,137.3,270.7130908,9.306238406,1.7977E+308,0.055407623,0
,137.5,270.5305269,9.199585829,1.7977E+308,0.055407623,0
,137.7,270.3671023,9.092931995,1.7977E+308,0.047990855,0
,137.9,270.3426451,8.986269039,1.7977E+308,0.033593599,0
,138.1,269.9037819,8.879633287,1.7977E+308,0.016142379,0
,138.3,269.8759962,8.772970549,1.7977E+308,0.00828933,0
,138.5,269.50204,8.666330536,1.7977E+308,0.010034452,0
,138.7,269.2029764,8.559685607,1.7977E+308,0.007416769,0
,138.9,269.088648,8.45302855,1.7977E+308,0.004799086,0
,139.1,268.8378486,8.346380452,1.7977E+308,0.005235367,0
,139.3,268.5046672,8.239737763,1.7977E+308,0.008725611,0
,139.5,268.3994924,8.133080105,1.7977E+308,0.012652136,0
,139.7,268.2477177,8.026425507,1.7977E+308,0.018760064,0
,139.9,268.036861,7.919774787,1.7977E+308,0.018760064,0
,140.1,267.8185151,7.813124559,1.7977E+308,0.023995431,0
,140.3,267.2015737,7.706500497,1.7977E+308,0.026176835,0
,140.5,267.026499,7.599847428,1.7977E+308,0.02225031,0
,140.7,266.6924855,7.493204793,1.7977E+308,0.020505188,0
,140.9,266.7828637,7.386534299,1.7977E+308,0.021377749,0
,141.1,266.4372002,7.279892428,1.7977E+308,0.024431714,0
,141.3,266.3802895,7.173231602,1.7977E+308,0.024431714,0
,141.5,265.9896904,7.066592682,1.7977E+308,0.019196347,0
,141.7,266.0318045,6.959925356,1.7977E+308,0.018760067,0
,141.9,265.7210909,6.853281191,1.7977E+308,0.021814031,0
,142.1,265.4669628,6.746633312,1.7977E+308,0.022686593,0
,142.3,265.3634523,6.639975545,1.7977E+308,0.020068909,0
,142.5,265.0073869,6.533334358,1.7977E+308,0.023777295,0
,142.7,264.7748945,6.426685058,1.7977E+308,0.021377752,0
,142.9,264.5303361,6.320036551,1.7977E+308,0.011343297,0
,143.1,264.2861937,6.213388016,1.7977E+308,0.00676235,0
,143.3,263.9451069,6.106745845,1.7977E+308,0.020505191,0
,143.5,263.8303624,6.000088816,1.7977E+308,0.034466173,0
,143.7,263.7796928,5.893427581,1.7977E+308,0.039701541,0
,143.9,263.4431828,5.786785109,1.7977E+308,0.040574104,0
,144.1,263.2090261,5.680135919,1.7977E+308,0.030975929,0
,144.3,262.7951269,5.573498528,1.7977E+308,0.015706105,0
,144.5,262.6633235,5.466842619,1.7977E+308,0.006544211,0
,144.7,262.4720221,5.360190615,1.7977E+308,0.021595895,0
,144.9,262.3576936,5.253533559,1.7977E+308,0.03664758,0
,145.1,262.0369943,5.14689005,1.7977E+308,0.046245756,0
,145.3,261.9110159,5.040233758,1.7977E+308,0.046682037,0
,145.5,261.5632719,4.933592024,1.7977E+308,0.040574108,0
,145.7,261.1085978,4.82695731,1.7977E+308,0.030975933,0
,145.9,261.2068814,4.720286297,1.7977E+308,0.024431722,0
,146.1,260.9315336,4.61363981,1.7977E+308,0.026613126,0
,146.3,260.5068166,4.50700313,1.7977E+308,0.028358249,0
,146.5,260.2926312,4.400352628,1.7977E+308,0.024868004,0
,146.7,260.0934244,4.293701144,1.7977E+308,0.021377758,0
,146.9,259.7531696,4.187058918,1.7977E+308,0.017451231,0
,147.1,259.6359287,4.080402053,1.7977E+308,0.013088423,0
,147.3,259.0830619,3.973773785,1.7977E+308,0.015706109,0
,147.5,258.7407267,3.867131696,1.7977E+308,0.022904742,0
,147.7,258.7275035,3.760468003,1.7977E+308,0.024868006,0
,147.9,258.1471759,3.653841537,1.7977E+308,0.023559164,0
,148.1,257.8872228,3.54719404,1.7977E+308,0.033157343,0
,148.3,257.9809296,3.440523327,1.7977E+308,0.043628082,0
,148.5,257.4838162,3.333891399,1.7977E+308,0.055407666,0
,148.7,257.1855845,3.227246415,1.7977E+308,0.05671651,0
,148.9,257.0279847,3.120592199,1.7977E+308,0.055407668,0
,149.1,256.7322495,3.013947051,1.7977E+308,0.044936928,0
,149.3,256.4889391,2.907298462,1.7977E+308,0.03053966,0
,149.5,256.0833612,2.800660525,1.7977E+308,0.015706111,0
,149.7,255.941572,2.694005271,1.7977E+308,0.006107932,0
,149.9,255.6791224,2.587357938,1.7977E+308,0.007416775,0
,150.1,255.659658,2.480694654,1.7977E+308,0.017887516,0
,150.3,255.1949981,2.374060595,1.7977E+308,0.036647595,0
,150.5,254.5996919,2.267435113,1.7977E+308,0.041882967,0
,150.7,254.530299,2.160775107,1.7977E+308,0.037520158,0
,150.9,254.1588388,2.05413493,1.7977E+308,0.030975945,0
,151.1,254.0553282,1.947477163,1.7977E+308,0.023122889,0
,151.3,253.6389324,1.840839936,1.7977E+308,0.022686609,0
,151.5,253.3382042,1.734195116,1.7977E+308,0.023995452,0
,151.7,252.7320801,1.627570344,1.7977E+308,0.026613138,0
,151.9,252.5679079,1.520383233,1.7977E+308,0.027921982,0
,152.1,252.3637081,1.413732077,1.7977E+308,0.034466196,0
,152.3,251.7017457,1.307644297,1.7977E+308,0.04013785,0
,152.5,251.4734138,1.200994724,1.7977E+308,0.045809504,0
,152.7,251.3441068,1.094338651,1.7977E+308,0.04406438,0
,227.9,250.6076681,0.994926776,1.7977E+308,0.017014963,0
,228.1,250.226222,0.888287255,1.7977E+308,0.018323807,0
,228.3,250.0195257,0.781636262,1.7977E+308,0.023122899,0
,228.5,249.4591692,0.675008486,1.7977E+308,0.027485711,0
,228.7,249.2349979,0.56835864,1.7977E+308,0.03053968,0
,228.9,248.7528626,0.461725729,1.7977E+308,0.038829022,0
,229.1,248.1450739,0.355101066,1.7977E+308,0.041882992,0
,229.3,247.781935,0.248460343,1.7977E+308,0.044064399,0
,229.5,247.00855,0.141846551,1.7977E+308,0.042319276,0
,229.7,246.2992399,0.035228553,1.7977E+308,0.034902497,0
,229.754,246.0238629,0.006447199,1.7977E+308,0.031848529,0
END,,,,,,