File: GB1_test55.csv
Segment,Time On Sample,Displacement Into Surface,Load On Sample,Harmonic Contact Stiffness,Harmonic Displacement,Harmonic Load
Surface Marker,0,0,0,432.879396,0.338977701,2.250554077
,0.2,0.261732419,0.000639225,5897.047226,0.199809247,2.322869855
,0.4,0.394487704,0.001286909,15003.94103,0.145712419,2.407238249
,0.6,0.457345705,0.001939177,19641.04684,0.133060742,2.521190359
,0.8,0.38373758,0.002600396,20547.62621,0.131751948,2.630759684
,1,0.236903208,0.003269699,20897.83284,0.133497008,2.74471178
,1.19,0.739800891,0.003857006,20890.19279,0.136550857,2.836750059
,1.4,0.325174812,0.004573078,22513.53086,0.137859655,3.104099196
,1.6,0.314807138,0.005229825,24758.76435,0.140913508,3.436094272
,1.8,0.516627647,0.005872656,27447.11576,0.140477242,3.760419524
,2,0.202539633,0.006549324,28877.03923,0.145276156,4.074883473
,2.2,0.670635508,0.00717469,28993.28697,0.155310241,4.383869046
,2.4,0.539611811,0.007839351,29895.32095,0.164908066,4.825433444
,2.6,0.546302403,0.00849498,30872.10981,0.175814684,5.38752413
,2.8,0.663247638,0.009143378,31219.4552,0.188030095,5.929892347
,3,0.704054761,0.009796769,31933.76249,0.197191654,6.486504565
,3.2,0.461528255,0.010468743,33352.21922,0.204171892,7.043116735
,3.4,0.71535567,0.011108163,34515.06178,0.218568625,7.730116501
,3.6,0.921336727,0.01175072,36795.94503,0.2312203,8.549695177
,3.8,0.938844756,0.012405639,38764.29933,0.244308241,9.361603947
,4,0.665114109,0.01307966,39441.48093,0.261322569,10.12091936
,4.2,0.920189686,0.013718998,40369.08417,0.274846772,10.87913921
,4.4,0.899420632,0.014376427,42685.21454,0.281390743,11.79623456
,4.6,0.579923906,0.015053449,44384.61296,0.293169895,12.86015267
,4.8,0.718920069,0.015700401,44578.3483,0.308875423,13.67315718
,5,0.650720716,0.016360941,43913.52084,0.336796367,14.7020132
,5.2,0.797621929,0.017007373,42323.6171,0.372570071,15.64211813
,5.4,0.648291801,0.017673235,40149.92662,0.417505341,16.60632821
,5.6,0.563450236,0.018334867,38298.15265,0.46898458,17.73598798
,5.8,0.461966461,0.018997591,36724.89269,0.518282497,18.77360953
,6,0.651305312,0.01964124,35326.77988,0.561908965,19.56798729
,6.2,0.960468073,0.02027703,33398.44434,0.62429481,20.54315455
,6.4,0.789503073,0.020944311,31897.82495,0.681881761,21.40108231
,6.6,0.814916151,0.021598712,29912.52565,0.757791821,22.29188101
,6.8,0.658513084,0.022265037,27787.60841,0.845044772,23.07420595
,7,0.624846316,0.022923313,25974.95728,0.926626281,23.65930617
,7.2,0.834155817,0.023565653,23446.43855,1.047471596,24.21591853
,7.4,1.010180896,0.024210175,20883.49297,1.184894974,24.52599986
,7.6,1.126294019,0.024858627,18886.18926,1.314247451,24.72377259
,7.8,1.424639336,0.025495126,17281.46449,1.436619682,24.86895217
,8,1.147580253,0.026169365,16126.21184,1.540014438,25.01248782
,8.2,1.237481894,0.026819535,16035.11707,1.562263933,25.27654996
,8.4,1.390623931,0.027465558,16805.44433,1.520818771,25.77618623
,8.6,1.362365883,0.028123478,18193.22777,1.444036185,26.43908069
,8.8,1.412326221,0.028776269,19725.69019,1.36768986,27.07348718
,9,1.332061268,0.0294376,21826.3072,1.28130945,27.92812794
,9.2,1.314204601,0.030094838,23066.0818,1.243790688,28.54938605
,9.4,1.426989279,0.030743508,23716.13306,1.236374179,29.14325194
,9.6,1.466548235,0.03139698,23655.60425,1.26167753,29.69548148
,9.8,1.75948483,0.032033834,23121.19016,1.303122656,30.06582607
,10,1.184946253,0.032727583,22345.48817,1.358092051,30.45260539
,10.2,1.356394722,0.033372405,21538.29516,1.413715789,30.76378243
,10.4,1.780388717,0.034000663,20665.54238,1.476319741,31.03770612
,10.6,1.872786686,0.03465067,20280.07821,1.510784645,31.27108889
,10.8,1.666040944,0.035320296,20141.1712,1.53565175,31.58226561
,11,1.977700021,0.035955922,20253.70801,1.544813283,31.85618927
,11.2,1.893274518,0.036617526,20752.92375,1.535215467,32.25830861
,11.4,2.005227083,0.037266249,21695.8507,1.499005488,32.71302144
,11.6,2.300243946,0.037902966,23063.69441,1.445344908,33.27949524
,11.8,2.338138679,0.038556547,24448.83783,1.392120614,33.8043324
,12,2.555769267,0.039198339,26355.69081,1.324499572,34.50228929
,12.2,2.318235446,0.039869985,27854.83058,1.278691797,35.08410223
,12.4,2.198861306,0.040533881,29152.48359,1.246844483,35.69769044
,12.6,2.18183675,0.041191064,29947.80284,1.236810397,36.32552279
,12.8,2.472693058,0.041828054,29953.45482,1.251643377,36.77037452
,13,2.410734539,0.042488183,29380.71516,1.291779732,37.24809678
,13.2,2.413680635,0.043144056,28876.27942,1.32973476,37.68527843
,13.4,2.700376387,0.043781319,28520.11298,1.359837002,38.0852068
,13.6,2.397937954,0.044457221,28456.3773,1.376851347,38.46979487
,13.8,2.288549139,0.045120462,29126.00306,1.366817268,39.02750264
,14,2.260707148,0.045778354,30050.27893,1.343258977,39.51618194
,14.2,2.187099082,0.046439248,31110.41037,1.31882816,40.13743999
,14.4,2.404729672,0.04708104,32050.78198,1.299196234,40.72144476
,14.6,2.582418958,0.047725452,32942.37638,1.283490693,41.36132995
,14.8,2.671072428,0.048375703,33315.96027,1.28654454,41.96396139
,15,2.613274462,0.04903556,33248.17075,1.300941278,42.38361185
,15.2,2.684453612,0.049686958,33117.37413,1.321445713,42.92378881
,15.4,2.941193386,0.050326185,32929.02905,1.3423864,43.39274587
,15.6,2.740272428,0.050995429,32686.77581,1.367253501,43.90881729
,15.8,2.663335922,0.051656541,32502.04386,1.386449153,44.31860649
,16,2.672938901,0.052311977,32379.42141,1.404772269,44.80509434
,16.2,2.615973045,0.052971779,32289.25288,1.420041537,45.20063957
,16.4,2.896011912,0.053609478,32321.76328,1.431820662,45.65206562
,16.6,2.715061604,0.054277412,32510.48258,1.439237176,46.16813697
,16.8,2.728825134,0.054932575,32802.69867,1.440109705,46.59107461
,17,2.902353866,0.055577259,33311.83994,1.437055839,47.14987851
,17.2,2.693943914,0.056246994,33793.65909,1.434002002,47.68786371
,17.4,2.93404148,0.056887313,34151.15184,1.435747043,48.18640448
,17.6,2.703996657,0.057558467,34344.45033,1.441418501,48.60824619
,17.8,2.825934543,0.058206535,34375.83172,1.454506432,49.08487298
,18,3.09265964,0.058845107,34258.35892,1.47021194,49.45521766
,18.2,3.237064504,0.059491702,33927.08058,1.495951544,49.8781555
,18.4,3.562869433,0.060126398,33548.40217,1.519946074,50.23535207
,18.6,3.361947961,0.060798921,33100.72247,1.546558236,50.6188445
,18.8,3.973167269,0.061411619,32728.60847,1.568807682,50.91139549
,19,3.823837166,0.062077478,32485.69827,1.586694546,51.269687
,19.2,4.399275192,0.062695801,32591.50459,1.589748349,51.60168299
,19.4,4.416367164,0.063350745,33259.83298,1.572297762,52.04434321
,19.6,4.228759987,0.064019114,34684.89412,1.530416373,52.66888805
,19.8,4.610316293,0.064650154,36389.06656,1.478937114,53.26165882
,20,4.66568534,0.065302587,39072.58886,1.403463329,54.12506538
,20.2,4.381969421,0.065977259,41486.02114,1.342386301,54.86356228
,20.4,4.316682467,0.066637606,43925.69815,1.291343342,55.78723184
,20.6,3.958492664,0.067317164,45257.1031,1.270402664,56.53011142
,20.8,3.851184135,0.067980267,45192.98678,1.287416993,57.23464204
,21,4.171996392,0.068615291,43213.95074,1.355910521,57.72003479
,21.2,4.083410155,0.069278375,40104.50279,1.461050308,57.89863271
,21.4,4.846071843,0.069891701,36753.09502,1.586694461,57.89205972
,21.6,5.320822378,0.070529925,34043.48211,1.702304545,57.76715136
,21.8,4.872345443,0.071235413,32170.51672,1.791302571,57.69373921
,22,5.261386451,0.071892872,31878.11001,1.808316854,57.81207471
,22.2,5.257254266,0.072582818,33304.1521,1.746803543,58.30294542
,22.4,5.583468775,0.073258007,36624.69488,1.619414245,59.1422471
,22.6,5.573509607,0.073962249,41364.9564,1.469557352,60.21876596
,22.8,5.305595135,0.074690378,46245.7629,1.346748883,61.33034653
,23,5.451238336,0.075398623,50668.53407,1.257314626,62.46767659
,23.2,5.093453666,0.076146997,53364.74974,1.215433246,63.48776663
,23.4,5.447122131,0.076856168,54196.23257,1.212815638,64.35007802
,23.6,5.010284641,0.077624443,53902.14359,1.232011309,65.09076602
,23.8,5.179638323,0.078360486,52675.70472,1.271711379,65.77667026
,24,4.846812223,0.079137008,50824.70428,1.327117012,66.4099807
,24.2,4.365453147,0.079931275,49152.25805,1.377723747,66.81538612
,24.4,4.504847149,0.080692644,45126.03543,1.500750364,67.07506572
,24.6,5.423095271,0.081410131,42002.75924,1.608071387,67.04329235
,24.8,5.533363052,0.082188207,39346.86737,1.712774884,66.9928907
,25,5.51673277,0.082982411,37406.74698,1.797846486,66.91180929
,25.2,5.672348052,0.083773302,36435.57391,1.844090517,66.88551294
,25.4,5.527986315,0.084591762,37186.52565,1.818350923,67.19668961
,25.6,5.734773822,0.085395394,39844.9385,1.721063895,67.94833573
,25.8,5.538818628,0.086233707,42797.5305,1.62639449,68.79256717
,26,5.277125383,0.087084729,46003.31544,1.536960268,69.70144439
,26.2,5.542988758,0.087909442,49487.92676,1.454069969,70.75550203
,26.4,5.862937959,0.088739025,51465.96772,1.416987451,71.61671775
,26.6,5.486409487,0.089622799,52444.26159,1.407389658,72.45163541
,26.8,5.376987041,0.090497731,52799.81167,1.410007253,73.06741495
,27,5.5662908,0.091361857,52698.82372,1.425712764,73.75660663
,27.2,5.319151302,0.092263404,52294.21807,1.448834809,74.38553411
,27.4,5.555882537,0.093142107,51780.373,1.473265608,74.95091244
,27.6,5.849611901,0.094026022,51150.70227,1.502059049,75.53382212
,27.8,5.241748319,0.09497808,50748.97656,1.522563536,76.01154317
,28,5.670692721,0.095871319,50515.9739,1.540014085,76.57363486
,28.2,5.512997868,0.096812387,50333.82127,1.55528336,77.12476825
,28.4,5.63364244,0.097744464,50222.63545,1.568807553,77.65070146
,28.6,5.446404687,0.09870624,50164.5695,1.57927792,78.09336116
,28.8,5.265406232,0.099677219,49970.40348,1.596728521,78.62258072
,29,5.398111826,0.100637309,49972.2424,1.605890067,79.04004026
,29.2,5.747996695,0.101592681,49986.53673,1.617669181,79.56268666
,29.4,5.458819299,0.102599714,50299.00562,1.618978001,80.07218346
,29.6,5.915211159,0.10356776,50769.4135,1.616360373,80.67591171
,29.8,5.80659852,0.104582966,51472.57968,1.606326297,81.31579644
,30,5.856917331,0.105597908,51864.21232,1.602836176,81.8066673
,30.2,6.004591463,0.106616426,52560.59983,1.593674607,82.46408385
,30.4,6.168074033,0.107644328,52914.63181,1.593674593,83.04480169
,30.6,5.914667687,0.108710031,53252.65279,1.59411088,83.55429853
,30.8,6.254554322,0.109747216,53316.48937,1.604581201,84.13282542
,31,6.377258492,0.110809213,53693.84649,1.606326249,84.71792601
,31.2,6.207890231,0.111901219,54166.90308,1.604581206,85.30960019
,31.4,6.194956982,0.112993775,54744.00295,1.599782296,85.91990146
,31.6,6.429158751,0.114081035,55326.78066,1.592802043,86.45131336
,31.8,6.180734788,0.115211098,56513.22759,1.573606422,87.22048965
,32,6.320072436,0.116326912,57426.10617,1.562263531,87.98857106
,32.2,6.427788136,0.117455852,57964.26313,1.558337141,88.56381032
,32.4,6.433152443,0.118603013,58643.97324,1.553101965,89.24533155
,32.6,6.505083751,0.119757261,59146.74654,1.553538224,89.96191538
,32.8,6.636093049,0.120919198,59330.3293,1.561390976,90.64562857
,33,6.487510466,0.122117294,59393.79103,1.571861339,91.31400124
,33.2,6.797420642,0.123285288,59423.82878,1.579714076,91.80487265
,33.4,6.617215042,0.12450325,59284.57145,1.592802029,92.35710168
,33.6,6.634217646,0.125720397,59224.72778,1.604581172,92.97068994
,33.8,6.916661487,0.126932309,59332.6563,1.611997646,93.59304482
,34,6.740610612,0.128186656,59658.77799,1.611997661,94.11678585
,34.2,6.821679823,0.129436617,60341.48371,1.605453685,94.82131688
,34.4,6.863637847,0.130701747,61189.02628,1.594547067,95.5159867
,34.6,7.030410387,0.131971411,62205.39068,1.581459116,96.32022607
,34.8,7.014116634,0.133265906,62968.19438,1.572733826,96.97873801
,35,7.157585987,0.134562882,63584.35621,1.569679962,97.75339378
,35.2,6.960720171,0.135895266,63898.24344,1.57360636,98.46449804
,35.4,7.124988094,0.137217215,64129.51123,1.578841521,99.11862783
,35.6,7.082058441,0.138566126,64320.16373,1.586258023,99.84945506
,35.8,7.087389038,0.139925357,64538.1255,1.590184404,100.4159288
,36,7.268292706,0.141286847,65123.52784,1.588003066,101.1938717
,36.2,6.736907821,0.142708797,65709.0132,1.583204201,101.8217025
,36.4,7.635917128,0.144057766,66258.50671,1.580586537,102.5580112
,36.6,7.50976663,0.145473942,66888.35977,1.577096432,103.3534842
,36.8,7.805492646,0.146883622,67416.03419,1.576223878,104.1577242
,37,7.542870422,0.148344298,67727.86592,1.580586546,104.9214219
,37.2,7.796154239,0.149785564,67832.37359,1.587130493,105.4977574
,37.4,7.434506265,0.151281876,67903.14233,1.598037139,106.2811772
,37.6,7.172709139,0.152786573,67665.69618,1.611561363,106.7808126
,37.8,7.516269841,0.15426646,67455.92183,1.626394329,107.4206986
,38,7.529064346,0.155783006,67104.85423,1.643408647,108.0003205
,38.2,7.698709209,0.15730448,66812.70358,1.656932834,108.4462683
,38.4,7.678630514,0.158853674,66552.96526,1.671547699,109.016029
,38.6,7.631505764,0.160420196,66639.71107,1.67787354,109.569354
,38.8,7.946346451,0.161978739,66781.74274,1.683981215,110.1654122
,39,7.960376786,0.163572806,67108.64574,1.683981214,110.6792925
,39.2,8.117943598,0.165173396,67822.47826,1.677437232,111.3783455
,39.4,8.023378442,0.166806726,68340.94532,1.674383389,112.0083689
,39.6,8.178859815,0.168439934,68870.81914,1.670020729,112.6011397
,39.8,8.312287656,0.170091009,69358.86792,1.668275659,113.3199151
,40,8.121189869,0.171780054,69539.62231,1.671329529,113.8326991
,40.2,8.127715588,0.173472903,69504.70007,1.680927349,114.4561488
,40.4,8.429221669,0.175163398,69544.56309,1.687907554,114.9974223
,40.6,8.339633246,0.176896619,69271.88163,1.702740558,115.5386945
,40.8,8.639469631,0.178621649,69063.0183,1.714083409,115.9517719
,41,8.661794507,0.180382266,69112.00764,1.72106364,116.5149586
,41.2,8.723225743,0.182158039,69381.80131,1.721499902,116.9861071
,41.4,8.797551871,0.183950684,69627.30786,1.72324495,117.5032747
,41.6,8.853568708,0.185762564,70164.61203,1.719754831,118.1475428
,41.8,8.815554205,0.187598802,70675.75411,1.715392191,118.6690925
,42,8.787106017,0.189452979,71006.69986,1.716700991,119.2793939
,42.2,8.690005789,0.191330226,71024.13523,1.7228087,119.7187664
,42.4,8.892046191,0.193206576,71064.35249,1.728916386,120.2184033
,42.6,9.07120055,0.195103375,71163.85025,1.734151544,120.7717292
,42.8,8.630845839,0.197059994,71243.10495,1.738077967,121.2187706
,43,8.929401889,0.198987468,71705.72554,1.735024089,121.8334557
,43.2,9.27788144,0.200931181,72370.29373,1.726298764,122.3725382
,43.4,8.8591523,0.202944884,73071.39622,1.718446042,122.9959863
,43.6,9.151042036,0.204932113,73824.1788,1.711029519,123.7092839
,43.8,8.927436332,0.206973248,74314.68571,1.707539423,124.2560342
,44,9.169809084,0.209004167,74574.57843,1.710593255,124.8893459
,44.2,9.192501486,0.211070051,74296.10981,1.723899314,125.3725473
,44.4,9.40657595,0.213143965,73887.25295,1.73960482,125.8064423
,44.6,9.338561732,0.215257408,73270.70082,1.759454865,126.1680209
,44.8,9.498958384,0.217377032,72619.515,1.779959278,126.4928949
,45,9.420952079,0.219533694,72166.54298,1.795664809,126.8046194
,45.2,9.66247264,0.221690957,72138.15288,1.802208754,127.2133137
,45.4,9.960573249,0.223866134,72618.97926,1.796537286,127.678985
,45.6,9.730280411,0.226098094,73279.44862,1.786503225,128.1326013
,45.8,9.978031335,0.228320746,74409.94796,1.768180091,128.794401
,46,9.72817681,0.230598648,75243.26914,1.755964709,129.3466297
,46.2,9.959694369,0.232867771,76041.16944,1.745930603,129.991994
,46.4,10.15376333,0.235162262,76360.01898,1.745930585,130.5212147
,46.6,10.02829835,0.237500712,76310.80157,1.754219623,131.0591999
,46.8,9.996025962,0.239856561,75958.96388,1.766871297,131.4076304
,47,10.09106266,0.242227744,75548.42685,1.781704282,131.818516
,47.2,10.19358456,0.244622278,75142.2616,1.795228473,132.1176404
,47.4,10.27363567,0.247042249,74884.56122,1.805698813,132.452923
,47.6,14.27708186,0.249227842,74966.66708,1.809624804,132.8879283
,47.8,14.29971002,0.251697865,75641.01244,1.79959072,133.34045
,48,14.47211402,0.254182861,77277.03547,1.771233517,134.0745654
,48.2,14.56213517,0.256698253,79246.45539,1.73676862,134.8251161
,48.4,14.70207887,0.259235742,82936.47507,1.675255326,136.1224178
,48.6,14.7979167,0.261801587,86024.91942,1.627702497,137.1951024
,48.8,15.15170452,0.264376216,89500.21121,1.579713382,138.5395202
,49,15.22257084,0.266995377,91691.99531,1.553537513,139.5968649
,49.2,15.34752012,0.269637284,93617.11835,1.535214398,140.8612957
,49.4,15.44334134,0.272307624,95005.7564,1.524744045,142.0128705
,49.6,15.4467941,0.275010871,96162.81067,1.516891286,143.0504922
,49.8,15.8687938,0.277713812,97714.07734,1.505984642,144.3905278
,50,15.62426916,0.280487789,99056.81811,1.499004432,145.6900193
,50.2,15.7999556,0.283261888,100391.8366,1.49027913,146.7900967
,50.4,15.80755139,0.286075053,101432.5308,1.487661544,148.0008383
,50.6,15.73858861,0.288921314,101690.0161,1.49769563,149.2773212
,50.8,16.3286523,0.291752847,101374.2574,1.512964836,150.2261947
,51,16.23055657,0.294658299,101205.4408,1.527797833,151.3777683
,51.2,16.39457082,0.297575646,100986.9231,1.540449486,152.2598025
,51.4,16.58770424,0.300520411,100611.7479,1.556154987,153.2470235
,51.6,16.52454313,0.303511634,100596.3274,1.567934131,154.3996932
,51.8,16.53210657,0.306528311,101194.2592,1.568370395,155.3956789
,52,16.75767799,0.309560853,102083.8277,1.566625318,156.6414836
,52.2,16.37580436,0.312663918,102652.681,1.56749788,157.6352762
,52.4,16.79774395,0.315744922,103667.1127,1.564007729,158.8405415
,52.6,16.94341816,0.318874958,104903.9166,1.558772545,160.2167335
,52.8,16.88438833,0.322050031,105286.6264,1.563135194,161.233537
,53,16.87195157,0.325253967,105683.1025,1.56967916,162.4727668
,53.2,16.94688126,0.328484196,106074.0004,1.574041798,163.4610829
,53.4,17.28558461,0.33172952,106291.5523,1.581894527,164.5370559
,53.6,17.07841869,0.335043535,105562.4451,1.603707763,165.584538
,53.8,17.61182527,0.338341866,105034.2267,1.619849498,166.387684
,54,17.90225049,0.341689408,104531.6678,1.635118724,167.1612455
,54.2,18.3441116,0.345077858,103979.7315,1.652132994,168.0969699
,54.4,18.3399619,0.348495433,104213.1197,1.656931902,169.044745
,54.6,18.46727455,0.3519735,105715.7394,1.644280226,170.2543917
,54.8,19.16125399,0.355413991,107460.373,1.627702121,171.3752901
,55,19.26442721,0.358945542,109346.6369,1.610687804,172.5411087
,55.2,19.37175531,0.362512404,111566.7728,1.592800959,173.9939993
,55.4,19.18159848,0.366134761,112966.4389,1.585384482,175.272673
,55.6,19.63798514,0.369750883,113801.3358,1.586693236,176.6039436
,55.8,19.75569734,0.373425718,114287.798,1.589747076,177.603217
,56,19.83221423,0.377140289,114746.7876,1.595418506,178.8632651
,56.2,19.82967479,0.380897262,115319.994,1.597163563,179.8844519
,56.4,20.34386947,0.384657957,116437.7344,1.593673405,181.1401198
,56.6,19.79878246,0.388526342,117129.2988,1.596291038,182.4735763
,56.8,20.3945117,0.392358327,117526.8892,1.600217365,183.5331155
,57,20.20763564,0.396280448,118102.4702,1.603707496,184.8304162
,57.2,20.53042051,0.40020833,117877.6624,1.615486604,185.8740663
,57.4,20.4254947,0.404203996,117471.3408,1.62944707,186.9029224
,57.6,21.06613279,0.40819063,117454.8838,1.638608563,187.9487654
,57.8,21.0510621,0.412260494,117425.4605,1.647770116,188.967213
,58,20.99604366,0.416373739,117333.5179,1.657367933,189.9505981
,58.2,21.20521347,0.420510902,117835.1641,1.6599855,191.0791638
,58.4,21.02411724,0.424715357,118115.0558,1.664784423,192.1091152
,58.6,21.40968099,0.428924625,118388.6316,1.668274503,193.013065
,58.8,21.26809655,0.433210932,118933.1509,1.670019573,194.1712128
,59,21.53257476,0.437513605,119382.4175,1.671328342,195.0872139
,59.2,21.57861732,0.441873879,119883.4788,1.674382188,196.2431717
,59.4,22.20754568,0.446239756,120450.0431,1.675690927,197.2698402
,59.6,22.5760168,0.450666293,120912.5672,1.677872217,198.2077559
,59.8,23.31060903,0.455113372,121539.1242,1.680053472,199.3768658
,60,23.25094555,0.459657505,122091.0792,1.680926005,200.2939611
,60.2,22.92541582,0.464264688,122655.192,1.683107358,201.4225241
,60.4,23.08957524,0.468885844,123357.2539,1.682671075,202.493018
,60.6,23.7721315,0.473519399,124535.0798,1.676563317,203.6445963
,60.8,23.81562022,0.478241645,125368.6188,1.674818257,204.7863098
,61,23.8736633,0.483010384,125779.2188,1.678744625,205.9455544
,61.2,24.15387203,0.487812368,126117.1508,1.681798452,206.8593648
,61.4,24.25392137,0.492674424,126694.3133,1.683107235,207.9320498
,61.6,24.27366437,0.4975907,126774.6732,1.690959991,209.0310311
,61.8,24.43693841,0.502546918,126997.3813,1.695322618,209.9316925
,62,24.57773757,0.507554435,128026.3377,1.691396227,211.1292872
,62.2,25.11419682,0.51258605,128724.358,1.690087382,212.1143194
,62.4,25.61029071,0.517670952,129117.8241,1.693141189,213.1607099
,62.6,25.5076737,0.522846384,129623.2801,1.695322519,214.2980397
,62.8,25.53360933,0.528065361,130283.0445,1.695104382,215.370725
,63,25.68185673,0.533328681,130860.3621,1.696195032,216.4236879
,63.2,25.80721271,0.538646438,131983.3315,1.69117798,217.5922463
,63.4,26.19301045,0.544000456,132929.3354,1.6874697,218.6348017
,63.6,26.29671457,0.549426617,134145.6206,1.683107049,219.9562094
,63.8,26.00432592,0.554933446,134804.3891,1.684852133,221.2020116
,64,26.23782168,0.560460737,134953.3636,1.690087281,222.1256832
,64.2,27.8725808,0.565951461,134350.0215,1.705356376,223.1282533
,64.4,28.13435062,0.57158784,133663.7323,1.720625595,224.0048106
,64.6,28.54256271,0.577270993,133379.6566,1.729787104,224.7674159
,64.8,29.10803437,0.583000924,133718.7625,1.733277164,225.8346257
,65,29.36728063,0.588808662,134939.8043,1.724988122,226.8328048
,65.2,29.81956696,0.594662026,137220.7977,1.70666499,228.2254351
,65.4,29.57786482,0.600619823,139744.5044,1.686596866,229.6498364
,65.6,30.15994135,0.60658325,141762.9611,1.672200099,230.9252281
,65.8,30.14205755,0.612646157,143423.8738,1.664347348,232.4318076
,66,30.06425222,0.618773834,143785.3525,1.670018788,233.7433526
,66.2,30.39500273,0.624936287,143641.8284,1.678744039,234.731671
,66.4,30.50606656,0.631175099,143932.2483,1.683979198,235.911735
,66.6,30.89005224,0.637458706,144555.5435,1.686160483,237.201369
,66.8,30.75312752,0.643839622,145370.6918,1.68441544,238.3003495
,67,30.99230597,0.650259943,146741.3646,1.67918025,239.7433807
,67.2,31.17738707,0.656748365,147780.0782,1.675690121,240.8982436
,67.4,31.25178728,0.66330918,148228.0407,1.679180227,242.1550053
,67.6,31.40605948,0.669930818,148752.1748,1.682234061,243.5476338
,67.8,31.53369361,0.676620702,149403.9125,1.68223405,244.6619557
,68,31.87766546,0.683363443,150036.4089,1.683106547,246.0151405
,68.2,31.65412809,0.690211234,150730.2551,1.682234039,247.138226
,68.4,32.1836386,0.697078174,151929.3585,1.679616407,248.7719096
,68.6,32.08905626,0.704055209,152238.7007,1.683542792,249.8248711
,68.8,32.67845651,0.711057272,152459.3978,1.690522963,251.1681965
,69,32.7369599,0.718164903,152631.4977,1.696194389,252.1839054
,69.2,32.57078249,0.725358557,152246.4,1.70884606,253.3387662
,69.4,32.9329829,0.732589695,151775.6048,1.721497683,254.3610516
,69.6,33.37588632,0.739888309,151837.0275,1.727605337,255.3088303
,69.8,33.47012436,0.747283181,152301.1421,1.730659177,256.4856065
,70,33.60928447,0.754749459,152776.1537,1.73240422,257.4783065
,70.2,33.54456594,0.762304086,153308.6488,1.73502181,258.6945267
,70.4,33.89089724,0.769907548,154039.1051,1.734585514,259.8362428
,70.6,35.01856681,0.777535874,154147.396,1.739384311,260.7456774
,70.8,35.67192199,0.785272123,153858.6975,1.749418321,261.7898788
,71,35.8151757,0.793159193,153838.3411,1.755089738,262.6532872
,71.2,36.09905585,0.801036838,154632.1273,1.75378092,263.8596494
,71.4,36.52853615,0.809023952,155962.84,1.746800657,265.0572463
,71.6,36.72834161,0.817106458,157724.6477,1.735457777,266.2603198
,71.8,37.06542559,0.825302285,160150.5322,1.719752245,267.8293576
,72,37.65629617,0.833523007,161470.1294,1.713644497,269.0138069
,72.2,38.17809521,0.84178905,162924.9111,1.708409282,270.4897116
,72.4,37.87941501,0.850234102,163668.6721,1.709281838,271.7661936
,72.6,38.43820953,0.858707604,163947.2308,1.713644425,272.8520308
,72.8,38.74777385,0.867282937,164417.0465,1.717570771,274.1789194
,73,39.1867174,0.875935877,165371.3637,1.715389411,275.3217321
,73.2,39.35354754,0.884693625,166327.8196,1.714953132,276.7592848
,73.4,39.63893918,0.893531654,167357.5422,1.713208051,278.1102782
,73.6,39.62267724,0.902478391,168445.9749,1.710154205,279.3495085
,73.8,40.16641028,0.911478038,169807.3288,1.706227781,280.8823894
,74,40.13514172,0.920606095,170877.9454,1.703173937,282.1161408
,74.2,40.34184172,0.929810099,172267.4173,1.699247544,283.7169524
,74.4,40.81813025,0.939088903,172878.3091,1.70142882,285.1084882
,74.6,41.23324397,0.948464887,173285.6662,1.704046364,286.2786936
,74.8,41.93001152,0.957916479,173596.8901,1.708845202,287.7052933
,75,42.51609347,0.967470476,173821.3969,1.712771522,288.8141411
,75.2,42.35575864,0.977169635,174661.724,1.712771537,290.2867535
,75.4,42.70923547,0.986932231,176069.7527,1.707972603,291.7779964
,75.6,43.13550622,0.996788096,177711.1369,1.700992344,293.1761062
,75.8,43.51141866,1.006746204,180101.5738,1.689649453,294.9533263
,76,43.2985983,1.016843147,181367.1652,1.686595626,296.3569094
,76.2,43.39697049,1.027020933,181774.6514,1.692267046,297.897457
,76.4,43.76118516,1.037283265,181567.7855,1.701864815,299.1969538
,76.6,44.67623934,1.047612496,180523.3032,1.718879015,300.4526274
,76.8,44.75334363,1.058100692,179384.4881,1.734584504,301.3039828
,77,45.45950525,1.068652884,178877.3714,1.746363561,302.5180182
,77.2,45.52991904,1.079353045,179093.3622,1.749853665,303.5041446
,77.4,46.08085846,1.090128945,179729.4983,1.750726139,304.7258487
,77.6,46.23195249,1.101039485,180937.8343,1.747236016,306.1765493
,77.8,46.57108562,1.112047293,181910.7543,1.744618402,307.3730509
,78,47.07079811,1.123155085,182348.3484,1.748108465,308.7087071
,78.2,47.16733628,1.134401056,182525.7649,1.752471088,309.7550964
,78.4,47.27425783,1.145759404,183136.4964,1.753779871,311.0118592
,78.6,47.48267848,1.157225168,184015.229,1.753343589,312.3727139
,78.8,48.19617065,1.168772909,184999.3377,1.751380335,313.6590659
,79,48.30178914,1.18047665,186437.9861,1.745490766,315.044025
,79.2,48.79931202,1.192272191,187926.1411,1.740255557,316.5944376
,79.4,49.37711451,1.20418088,188494.5618,1.742000552,317.9059898
,79.6,49.76808962,1.216221633,188513.9993,1.747235681,318.9666255
,79.8,50.02549209,1.228392216,189115.8069,1.749416975,320.3976053
,80,50.47509216,1.240672348,189597.6982,1.751161987,321.4998783
,80.2,50.80942561,1.253083395,190226.0279,1.752907007,322.8815529
,80.4,50.98688682,1.265629476,191631.0962,1.748108091,324.2873307
,80.6,51.86080263,1.278255784,192962.08,1.74330911,325.5649196
,80.8,51.82645205,1.291068801,193580.3094,1.745490431,326.9794615
,81,52.79310734,1.303944124,194547.6765,1.745054076,328.5068686
,81.2,53.49554769,1.316965966,195402.836,1.743745219,329.6518769
,81.4,53.91754676,1.33013713,196272.9947,1.743308916,331.0346475
,81.6,54.19390584,1.343450289,197611.724,1.740255046,332.6277906
,81.8,54.42780616,1.356899892,199350.5615,1.733274808,334.0511009
,82,54.96956501,1.370464361,201411.4378,1.725858279,335.814079
,82.2,55.43890877,1.384169916,202720.6034,1.722804391,337.2220513
,82.4,55.71850997,1.398025676,203476.4441,1.724985682,338.728635
,82.6,55.99060008,1.412021065,203718.8018,1.731093345,340.2560363
,82.8,56.68621084,1.426129282,204048.8358,1.734583388,341.476647
,83,57.19790318,1.440391246,204038.5167,1.741563555,342.8890034
,83.2,57.40169273,1.454816872,204598.3416,1.742872326,344.1424802
,83.4,57.93330982,1.469365809,205943.0762,1.738945905,345.7060417
,83.6,58.46739997,1.484060777,207495.1092,1.734146958,347.4131403
,83.8,58.54214305,1.498933556,208091.6381,1.736764531,348.9668369
,84,58.9829899,1.513931586,208752.7532,1.73807328,350.2740053
,84.2,59.47540345,1.529077112,209114.237,1.742872131,351.7860693
,84.4,60.10925114,1.544365481,209606.6107,1.745925915,353.1863741
,84.6,60.63323616,1.559814639,210589.3421,1.744180812,354.4727255
,84.8,60.97912539,1.575430856,213093.2274,1.733274197,356.3638993
,85,61.55631567,1.59118862,215626.6488,1.72105877,358.010735
,85.2,62.2441511,1.607097518,218511.8188,1.70840707,360.100232
,85.4,62.68732142,1.623182259,220037.9496,1.704916923,361.8522534
,85.6,63.15542925,1.639427107,220378.9657,1.710588303,363.6700162
,85.8,64.10114097,1.655803711,220019.2167,1.718877217,364.9618512
,86,64.43356312,1.672385183,219218.753,1.731092557,366.4333733
,86.2,65.21862536,1.689103481,218671.1666,1.741562802,367.8709334
,86.4,65.34296738,1.706033269,219366.848,1.74287158,369.3873769
,86.6,65.81843181,1.723109935,220672.6023,1.739817692,370.8632838
,86.8,66.1906876,1.740365017,222585.6415,1.734146236,372.7445964
,87,66.8083876,1.757777182,224224.2965,1.729347283,374.2720024
,87.2,67.21969706,1.775378019,226539.6681,1.72193077,376.3099995
,87.4,67.6842333,1.793152084,227930.1707,1.719749411,378.0784574
,87.6,68.10547156,1.81110755,228949.5578,1.719313109,379.6091483
,87.8,68.79045921,1.829226083,229197.4007,1.725856993,381.3852781
,88,69.38555029,1.847532622,229689.0233,1.728474516,382.7570945
,88.2,69.9223646,1.86602685,229797.1902,1.735454676,384.4521417
,88.4,70.55068117,1.884700892,230331.4274,1.738944722,386.0211848
,88.6,70.70965932,1.903593372,230666.9293,1.742434812,387.3667007
,88.8,71.29547839,1.922647614,231858.8648,1.74156223,389.1767954
,89,71.4968334,1.941918632,232347.6071,1.74417979,390.5781929
,89.2,71.74808407,1.961379999,233309.8389,1.744616029,392.345552
,89.4,72.55099082,1.981000697,233753.9161,1.747669795,393.8882996
,89.6,72.66236907,2.000964278,234090.9739,1.751159889,395.2612076
,89.8,73.52514021,2.020878593,234526.832,1.755522438,396.8653156
,90,74.0516921,2.041116171,234848.5311,1.760757544,398.4573675
,90.2,74.59152522,2.061557121,234791.6295,1.766865175,399.6418206
,90.4,75.12758119,2.082203813,235119.2099,1.771227754,401.0388386
,90.6,75.89076942,2.103043061,236379.3468,1.769918892,402.7207399
,90.8,76.46129153,2.124104335,238022.6307,1.764683681,404.2240407
,91,76.62904011,2.145403774,240896.05,1.752904566,406.2554623
,91.2,77.27854473,2.166885457,244079.172,1.73894409,408.1006211
,91.4,77.850213,2.188588072,247745.4676,1.723238571,410.231756
,91.6,78.49215965,2.210504074,250641.1729,1.71407699,412.583127
,91.8,78.71801771,2.232667797,251828.3021,1.713640706,414.3176154
,92,79.48221366,2.255018666,252721.4438,1.716258213,416.304121
,92.2,80.23846885,2.277594752,252704.9519,1.722365823,417.7942762
,92.4,80.85614214,2.300406798,252095.9172,1.733490468,419.539727
,92.6,81.6888786,2.323433952,252216.8519,1.739379938,421.1942372
,92.8,82.19081577,2.346714167,252513.1706,1.744615045,422.9594088
,93,82.39107702,2.370247942,252584.7537,1.74985018,424.3827204
,93.2,83.11594411,2.393983471,253114.3008,1.753340214,426.1183115
,93.4,83.79417527,2.417960548,253469.5251,1.757266515,427.7158446
,93.6,84.45489388,2.442179653,253119.5809,1.764682919,429.0219214
,93.8,84.91586821,2.466654905,252609.2299,1.774280656,430.5811028
,94,85.09471926,2.491394466,252519.4703,1.779952054,431.7929442
,94.2,85.71163502,2.516353751,251654.8055,1.791731089,433.1286052
,94.4,86.38800655,2.541559767,251470.508,1.798711229,434.3809945
,94.6,87.55860917,2.566986475,252151.5122,1.799583643,435.6027098
,94.8,88.02437679,2.592715028,254113.3323,1.793912182,437.3766474
,95,88.57456213,2.618696557,256109.9758,1.786495661,438.8766616
,95.2,89.6073278,2.644907218,260404.5473,1.766863743,441.1469566
,95.4,90.57015458,2.67138604,264549.6493,1.748540619,443.3778058
,95.6,91.18719874,2.698153791,268517.737,1.732180713,445.7204116
,95.8,92.17199121,2.725166155,272202.2588,1.718002088,448.013716
,96,92.59590075,2.752486843,275680.1038,1.707095484,450.6017557
,96.2,93.57519769,2.780045405,276874.6917,1.707531656,452.4940355
,96.4,94.14671842,2.807907846,277746.054,1.71058544,454.5375163
,96.6,94.8430106,2.836041885,277694.0575,1.719310628,456.6182523
,96.8,95.71233594,2.864447232,276775.8197,1.730653372,458.1336115
,97,96.23962018,2.893160553,275769.3489,1.743304934,459.9163161
,97.2,96.71193951,2.9221661,274854.0696,1.75377519,461.2947082
,97.4,97.48917947,2.951442847,274433.816,1.762064102,462.8703307
,97.6,98.1407246,2.98102202,274556.6378,1.767735452,464.6618017
,97.8,98.85255015,3.010894544,275321.1727,1.769044169,466.1957859
,98,99.49027054,3.041071924,277653.59,1.762936433,468.2622791
,98.2,100.0880016,3.071555139,280288.8422,1.754211128,470.106344
,98.4,100.9636075,3.102326061,283412.4084,1.74417701,472.3591061
,98.6,101.6581812,3.133416977,286968.3264,1.732834123,474.897844
,98.8,102.4617112,3.164813065,289171.8411,1.727162637,476.8810655
,99,103.830191,3.196487378,291357.3569,1.723236148,479.3803682
,99.2,104.4555495,3.228528852,292730.4349,1.721927303,481.2825061
,99.4,105.2414532,3.260881584,294838.7919,1.718000869,483.6305944
,99.6,106.2195217,3.29354678,296389.6573,1.717564516,486.0345662
,99.8,107.2616101,3.32653601,298073.4684,1.716691895,488.5185242
,100,108.1738373,3.359865297,298742.6371,1.719309383,490.3867005
,100.2,108.7481763,3.393551693,298942.7586,1.725853262,492.6022064
,100.4,109.326622,3.427576183,297920.637,1.738068549,494.3849132
,100.6,110.4217509,3.461908359,297365.5893,1.74679369,495.9868369
,100.8,111.4178044,3.49659199,296334.0257,1.759008935,497.7564018
,101,111.9727865,3.531653259,296285.6949,1.765116552,499.2914796
,101.2,112.7390674,3.567052797,296383.3936,1.771224148,501.1585584
,101.4,113.4503728,3.602811664,297908.4202,1.769042769,503.0902817
,101.6,114.1807595,3.638928413,299747.9366,1.765116341,504.9343502
,101.8,114.946869,3.675405777,303411.1485,1.753337192,507.4226887
,102,115.940917,3.712234687,306582.4992,1.744611857,509.9767718
,102.2,116.9665262,3.749431592,309039.8886,1.738504092,512.0783338
,102.4,117.8780775,3.787009631,311246.1797,1.734577648,514.4472437
,102.6,119.0533462,3.824947827,312709.0956,1.733268752,516.4425251
,102.8,119.9722657,3.863284156,312833.768,1.739812594,518.6744731
,103,120.6731124,3.902019948,312697.4613,1.747228981,520.7486382
,103.2,122.0895077,3.941097796,312941.9578,1.751591465,522.4535644
,103.4,122.9549869,3.980604683,312491.655,1.76031662,524.2461364
,103.6,123.7355282,4.020513974,311012.5573,1.774713187,525.9663924
,103.8,124.6100337,4.060817926,310541.8274,1.782129553,527.3798553
,104,125.5959767,4.101519634,311615.5366,1.783001982,529.3948568
,104.2,126.5294322,4.142633599,312813.0429,1.782129368,531.0921065
,104.4,127.0733968,4.184186381,315943.0939,1.772531556,533.3207626
,104.6,128.2946284,4.226111976,320716.2283,1.756389755,536.1027556
,104.8,129.4176046,4.26846536,325052.7307,1.743301796,538.9318638
,105,130.5688046,4.311242451,327854.6597,1.736321501,541.1408074
,105.2,131.5967848,4.354457247,331467.2678,1.727159909,543.9633395
,105.4,132.6638048,4.398103788,333973.9786,1.722797193,546.5908372
,105.6,133.5069189,4.442203509,336607.7453,1.717125713,548.955366
,105.8,134.4173631,4.486741835,340985.8847,1.706655349,552.1854961
,106,135.6414394,4.531707003,344805.1865,1.697493743,554.8097102
,106.2,136.763095,4.577130747,348043.3463,1.693131025,557.994921
,106.4,137.7532055,4.6230195,349587.9201,1.69487598,560.6432379
,106.6,138.9005104,4.669359005,348642.7846,1.705782411,562.660435
,106.8,139.7656578,4.716182644,345843.9499,1.725414097,564.8354091
,107,140.5333742,4.763483217,343239.4382,1.742428221,566.4329489
,107.2,141.4274948,4.81125092,341650.7156,1.755952241,568.4216542
,107.4,142.5378475,4.8597282,341813.0655,1.761187272,570.4629568
,107.6,143.8716197,4.908192302,344049.2538,1.758133315,573.0323896
,107.8,144.8079457,4.957415638,346496.0896,1.752898089,575.158058
,108,145.9210151,5.007121809,349335.5159,1.747662847,577.852397
,108.2,147.4567139,5.057299649,350379.8274,1.748971486,579.9210998
,108.4,148.8837428,5.107988955,351050.1513,1.753770224,582.6198269
,108.6,149.8476249,5.159218011,352255.6043,1.753770132,584.6140139
,108.8,151.1188874,5.210941582,353451.3946,1.755078794,587.0804507
,109,152.5019852,5.26317751,355211.7345,1.752897357,589.2631045
,109.2,153.4934947,5.315964122,358725.9015,1.745044562,592.2335583
,109.4,154.4994816,5.369280236,361229.7512,1.741118116,594.8621554
,109.6,155.8365606,5.423110238,361470.3346,1.746353123,596.9111332
,109.8,156.8203255,5.477504277,362551.2355,1.749406857,599.4235854
,110,157.8302148,5.532443301,362624.1804,1.755078154,601.316969
,110.2,158.9294673,5.587928384,363905.993,1.756823093,603.9126969
,110.4,160.2208471,5.643958343,366264.5286,1.753332882,606.4437818
,110.6,161.4468172,5.70055541,369703.6241,1.744607546,608.9376129
,110.8,162.7072291,5.757718618,372792.7088,1.738499774,611.9223169
,111,164.2558736,5.815436783,373940.3744,1.740026541,614.4862783
,111.2,165.6667126,5.873743796,374016.9586,1.745915929,616.7763119
,111.4,166.4741837,5.932676126,372864.2525,1.756822373,618.8614396
,111.6,167.8103622,5.992165384,370289.5336,1.774272677,620.7975624
,111.8,169.1414531,6.052251854,369023.2124,1.784742807,622.3414248
,112,170.5036518,6.112939881,369615.0351,1.788232761,624.5701
,112.2,171.877819,6.174236897,370570.109,1.78910515,626.4032283
,112.4,173.3043107,6.236146199,372394.1766,1.787359969,628.6176612
,112.6,174.638756,6.298683742,376324.1264,1.777762105,631.442396
,112.8,175.9111097,6.361853726,380102.7023,1.769473031,634.3219148
,113,177.2295442,6.425655313,383207.2285,1.762928996,636.6163318
,113.2,178.5724236,6.490096297,385719.0387,1.760311303,639.4147716
,113.4,180.0500007,6.555175802,387674.328,1.759002383,641.9644889
,113.6,181.627742,6.620902585,388649.7857,1.760747271,644.1471499
,113.8,182.9965206,6.687303647,390182.0863,1.761183402,646.8677955
,114,184.3564559,6.754372473,390520.4132,1.764673355,648.9014378
,114.2,185.5660895,6.822124939,392293.9069,1.763800716,651.6330378
,114.4,187.2877737,6.890524443,393859.6839,1.76336429,654.1411248
,114.6,189.0272388,6.959610025,395773.4068,1.761182822,656.443221
,114.8,190.6850473,7.029395136,399563.1416,1.75376624,659.6426936
,115,192.0107355,7.099903373,402434.9265,1.748530988,662.1639224
,115.2,193.3912298,7.171116349,406905.3661,1.739369392,665.601157
,115.4,194.5282204,7.243060952,410546.7801,1.732825382,668.7085825
,115.6,196.3977617,7.315680026,412842.9449,1.730643905,671.3503488
,115.8,197.7267368,7.389064334,414028.6523,1.734133861,674.3394421
,116,199.5432066,7.463150814,416783.6489,1.732388649,677.5926089
,116.2,201.0379508,7.538002195,418526.9437,1.732388508,680.1346599
,116.4,202.7322796,7.613592397,420834.0452,1.731515828,683.1051349
,116.6,204.2043165,7.689956865,423201.46,1.731079429,686.4065058
,116.8,205.558905,7.76709628,424433.0407,1.732824341,689.0142966
,117,207.3493914,7.844981983,424271.683,1.74024059,691.8609604
,117.2,208.7894385,7.923673401,422852.7171,1.752019469,694.4742318
,117.4,210.453195,8.003140691,420968.8915,1.764670844,696.6667597
,117.6,211.8588732,8.083423343,420827.4912,1.770342085,698.8023076
,117.8,213.4924187,8.164497539,421852.8165,1.773395746,701.5185803
,118,215.2806053,8.246376123,423299.8485,1.773831833,703.8097242
,118.2,217.2309207,8.329066782,427308.3694,1.766415231,707.0004404
,118.4,218.6443988,8.412623487,431256.2203,1.758998681,710.1232155
,118.6,220.2424697,8.49700749,433597.424,1.756380971,712.6159647
,118.8,221.7788303,8.582243363,435320.8861,1.757253343,715.7453158
,119,223.3691412,8.668332174,435619.7648,1.761179525,718.0123521
,119.2,224.9002353,8.755289706,435800.8513,1.766850751,720.7560174
,119.4,226.5352029,8.843114023,436957.7411,1.769031891,723.3736785
,119.6,228.2365982,8.931816435,438717.8334,1.768595467,725.8390397
,119.8,229.8122045,9.021418172,442880.7283,1.761615166,729.1776711
,120,232.0283847,9.111877965,448008.9525,1.750272212,732.1229594
,120.2,233.6985625,9.203282597,453625.1659,1.739365572,735.9217879
,120.4,235.3386386,9.295607568,457874.3741,1.732385269,739.3809487
,120.6,237.1283451,9.388850233,461689.1252,1.727586249,743.1644422
,120.8,239.0784978,9.483019216,464146.8129,1.72540477,746.0571323
,121,240.713134,9.578155114,465133.0536,1.729330947,749.4812306
,121.2,242.6430136,9.674227437,467230.1666,1.728458247,752.290648
,121.4,244.4121443,9.771275524,469610.1408,1.728021821,755.6062796
,121.6,246.216068,9.869296539,473597.9878,1.723659062,759.5234478
,121.8,248.1995684,9.968290561,478072.6612,1.71798751,763.576488
,122,249.708614,10.06831025,481288.4553,1.714933556,766.8603371
,122.2,252.0562557,10.16927959,482619.1239,1.718423407,770.5375611
,122.4,253.7162572,10.20429327,482494.1976,1.725403392,773.7030778
,122.6,254.7402932,10.20422631,480784.2735,1.736309765,776.1519939
,122.8,255.8084304,10.20415645,477212.965,1.754196272,778.6644589
,123,256.7143081,10.20409724,477117.9578,1.760303808,781.124329
,123.2,257.3064846,10.2040586,479326.2736,1.761176269,784.3884364
,123.4,258.1957203,10.20400047,482472.1792,1.758558632,787.6426876
,123.6,258.6672423,10.20396975,486409.7488,1.752450967,790.6920338
,123.8,259.1687199,10.20393706,493178.4914,1.73936316,795.0134914
,124,259.6369136,10.20390655,495482.165,1.738054341,798.10338
,124.2,260.4679023,10.20385225,495639.7268,1.743725624,801.4266602
,124.4,260.8096168,10.20383003,494177.8642,1.75375954,804.207559
,124.6,261.2079141,10.20380411,492286.9976,1.764665967,806.5194972
,124.8,261.5138484,10.20378425,488770.735,1.78255254,808.9662054
,125,261.9745531,10.20375423,486839.0716,1.795203994,811.318687
,125.2,262.2796553,10.20373442,486660.8575,1.800875326,813.4147704
,125.4,262.9446402,10.203691,489911.7657,1.796076417,816.17705
,125.6,263.102877,10.20368083,494865.9836,1.786914973,819.6811072
,125.8,263.2332384,10.20367248,499391.126,1.777753531,822.6855221
,126,263.7134974,10.20364118,505060.9073,1.766847022,826.642112
,126.2,264.014439,10.20362164,509505.4036,1.75899434,829.8141746
,126.4,264.0786486,10.20361763,509626.3222,1.764665695,832.7473683
,126.6,264.2048496,10.20360955,506169.5412,1.781243507,835.2094136
,126.8,264.528674,10.20358851,503115.4222,1.796948782,837.619964
,127,264.6182626,10.20358284,499193.2496,1.813526597,839.0158895
,127.2,265.1101709,10.20355077,494837.964,1.832285664,840.676985
,127.4,264.8993719,10.2035648,494843.1893,1.83664827,842.6415722
,127.6,265.2614728,10.20354125,496857.5227,1.834466942,844.7858689
,127.8,265.4896058,10.20352649,498270.3464,1.834903178,847.2621601
,128,265.533429,10.20352381,500751.6286,1.832285623,849.8556863
,128.2,265.8447719,10.20350359,501773.4362,1.833158109,851.7074298
,128.4,265.7113581,10.20351254,501407.0858,1.840138258,854.0588
,128.6,266.4142033,10.20346665,499113.5914,1.85104465,855.3057265
,128.8,266.4896462,10.2034619,496817.1236,1.862823621,856.8649119
,129,266.4190559,10.20346673,494084.5501,1.875038865,858.0833295
,129.2,266.5710519,10.20345696,492334.0706,1.883327761,859.1494514
,129.4,267.0679527,10.20342457,490311.9447,1.892489138,860.2714609
,129.6,267.0081796,10.20342869,491291.8899,1.892052885,861.9413089
,129.8,267.138541,10.20342034,492101.1698,1.891616614,863.2397188
,130,267.341295,10.20340724,494442.1826,1.887254011,865.1615842
,130.2,267.544049,10.20339414,495510.577,1.886381474,866.5520342
,130.4,267.5458512,10.20339422,497764.8113,1.882455149,868.4004825
,130.6,267.4731806,10.20339919,499036.4056,1.882455155,870.2609821
,130.8,267.7370938,10.20338208,499989.207,1.88245513,871.7423771
,131,268.0605021,10.20336107,501395.4351,1.881582579,873.6379488
,131.2,268.1242957,10.20335709,503384.1342,1.878092508,875.2869812
,131.4,267.9771522,10.20336694,504421.9477,1.878092523,876.9962719
,131.6,268.2102778,10.20335185,505153.9724,1.878965012,878.8666403
,131.8,268.3373108,10.20334371,505239.8393,1.881146295,880.2275048
,132,268.4585192,10.20333597,503833.1285,1.888998933,881.5883691
,132.2,268.4116436,10.20333924,501936.0105,1.897724106,882.4747905
,133,268.6955556,10.11152184,1.7977E+308,1.919536999,0
,133.2,268.321653,10.00954703,1.7977E+308,1.829231548,0
,133.4,268.2564589,9.907551968,1.7977E+308,1.674796076,0
,133.6,267.9179204,9.805574837,1.7977E+308,1.436162747,0
,133.8,267.765772,9.703585482,1.7977E+308,1.153903555,0
,134,267.5387347,9.601601038,1.7977E+308,0.81580328,0
,134.2,267.2692604,9.499619377,1.7977E+308,0.51347619,0
,134.4,266.9922972,9.397638208,1.7977E+308,0.294910714,0
,134.6,267.0648154,9.295634117,1.7977E+308,0.133495086,0
,134.8,266.7745387,9.193653821,1.7977E+308,0.012215237,0
,135,266.9286025,9.091644382,1.7977E+308,0.013960271,0
,135.2,266.2264369,8.989691101,1.7977E+308,0.016141563,0
,135.4,266.1733082,8.887695251,1.7977E+308,0.028793059,0
,135.6,265.8281129,8.785718557,1.7977E+308,0.041008297,0
,135.8,265.7125769,8.6837268,1.7977E+308,0.053223535,0
,136,265.5862235,8.581735752,1.7977E+308,0.062821222,0
,136.2,264.9040282,8.479781161,1.7977E+308,0.066747551,0
,136.4,264.9133069,8.377781218,1.7977E+308,0.061948708,0
,136.6,264.5498054,8.275805725,1.7977E+308,0.051042246,0
,136.8,264.7047014,8.173796231,1.7977E+308,0.039699525,0
,137,264.5450641,8.071807367,1.7977E+308,0.031410613,0
,137.2,264.2406416,7.969827998,1.7977E+308,0.02966558,0
,137.4,264.21414,7.867830402,1.7977E+308,0.030101838,0
,137.6,263.5469225,7.765874828,1.7977E+308,0.029229322,0
,137.8,263.7134679,7.663864571,1.7977E+308,0.02094041,0
,138,263.4256873,7.561884111,1.7977E+308,0.013087756,0
,138.2,263.2593932,7.459895683,1.7977E+308,0.003926327,0
,138.4,263.0772892,7.357908292,1.7977E+308,0.004798844,0
,138.6,262.9093308,7.255919974,1.7977E+308,0.010470205,0
,138.8,262.6157256,7.153939896,1.7977E+308,0.016141567,0
,139,262.4277969,7.051952887,1.7977E+308,0.022685446,0
,139.2,262.3006114,6.949961894,1.7977E+308,0.028356807,0
,139.4,261.9853716,6.847983236,1.7977E+308,0.036645721,0
,139.6,261.6559861,6.746005505,1.7977E+308,0.041880825,0
,139.8,261.6036894,6.6440096,1.7977E+308,0.04013579,0
,140,261.2693113,6.542032196,1.7977E+308,0.038390757,0
,140.2,261.1496147,6.440040712,1.7977E+308,0.034028171,0
,140.4,260.8917897,6.338058288,1.7977E+308,0.026611775,0
,140.6,260.8295079,6.236063038,1.7977E+308,0.01875912,0
,140.8,260.2521569,6.134101571,1.7977E+308,0.013960276,0
,141,259.9885072,6.032119528,1.7977E+308,0.008725173,0
,141.2,259.7897611,5.930133229,1.7977E+308,0.013524018,0
,141.4,259.6259633,5.828144638,1.7977E+308,0.019631639,0
,141.6,259.3706345,5.726162049,1.7977E+308,0.02268545,0
,141.8,259.1103131,5.624179789,1.7977E+308,0.02268545,0
,142,258.7817597,5.522202003,1.7977E+308,0.022249192,0
,142.2,259.0098804,5.420187707,1.7977E+308,0.022249192,0
,142.4,258.6530356,5.318211777,1.7977E+308,0.024866744,0
,142.6,258.2084853,5.215731601,1.7977E+308,0.024648615,0
,142.8,257.9007343,5.113752451,1.7977E+308,0.02661178,0
,143,257.8171529,5.012268596,1.7977E+308,0.021594805,0
,143.2,257.258524,4.910305901,1.7977E+308,0.020504159,0
,143.4,257.0194212,4.808322248,1.7977E+308,0.014396537,0
,143.6,257.0178826,4.706323015,1.7977E+308,0.009379562,0
,143.8,256.8262094,4.604336252,1.7977E+308,0.010906468,0
,144,256.3408052,4.502368753,1.7977E+308,0.021812936,0
,144.2,256.2706184,4.400374022,1.7977E+308,0.028356817,0
,144.4,256.2382922,4.298376808,1.7977E+308,0.024212359,0
,144.6,255.6097669,4.196418697,1.7977E+308,0.018759126,0
,144.8,255.554974,4.094422956,1.7977E+308,0.013524021,0
,145,255.2301649,3.992444925,1.7977E+308,0.017886609,0
,145.2,254.991062,3.890461272,1.7977E+308,0.022249197,0
,145.4,254.8505628,3.788471153,1.7977E+308,0.017886609,0
,145.6,254.830302,3.686473147,1.7977E+308,0.016141574,0
,145.8,254.4439176,3.584499154,1.7977E+308,0.013960281,0
,146,253.9747392,3.482530592,1.7977E+308,0.012651505,0
,146.2,253.5667202,3.380558018,1.7977E+308,0.01439654,0
,146.4,253.4532642,3.278566125,1.7977E+308,0.014832799,0
,146.6,253.4974911,3.17656389,1.7977E+308,0.016141576,0
,146.8,252.871462,3.074605615,1.7977E+308,0.018759129,0
,147,252.6024035,2.972623927,1.7977E+308,0.024430494,0
,147.2,252.4710575,2.870633207,1.7977E+308,0.027920565,0
,147.4,252.3971262,2.768638722,1.7977E+308,0.031410636,0
,147.6,251.9895232,2.666666121,1.7977E+308,0.034900707,0
,147.8,251.8332141,2.564677038,1.7977E+308,0.035773225,0
,148,251.4426691,2.462703319,1.7977E+308,0.035336967,0
,148.2,251.1161957,2.360725397,1.7977E+308,0.032283156,0
,148.4,251.1329633,2.258724962,1.7977E+308,0.03053812,0
,148.6,250.7536516,2.156750506,1.7977E+308,0.033373803,0
,148.8,250.3839091,2.054775422,1.7977E+308,0.034028192,0
,149,250.2538111,1.95278462,1.7977E+308,0.025303015,0
,149.2,249.6103079,1.850827491,1.7977E+308,0.010906472,0
,149.4,249.5696606,1.748830822,1.7977E+308,0.01177899,0
,149.6,248.8412831,1.64687926,1.7977E+308,0.02399424,0
,149.8,248.726579,1.544887449,1.7977E+308,0.036645749,0
,150,248.3684858,1.442911601,1.7977E+308,0.04079021,0
,150.2,248.0237062,1.340934879,1.7977E+308,0.034900715,0
,150.4,247.6543796,1.238959768,1.7977E+308,0.022685465,0
,150.6,247.4044593,1.136976825,1.7977E+308,0.011778992,0
,150.8,246.7834226,1.035018223,1.7977E+308,0.010470215,0
,226,246.2564327,0.939248449,1.7977E+308,0.032719426,0
,226.2,245.9470172,0.837269408,1.7977E+308,0.020940433,0
,226.4,245.731629,0.7352842,1.7977E+308,0.011342735,0
,226.6,245.2449763,0.633316784,1.7977E+308,0.011342735,0
,226.8,245.1460821,0.531323935,1.7977E+308,0.015705325,0
,227,244.2708388,0.429382006,1.7977E+308,0.021376694,0
,227.2,243.7700404,0.327415517,1.7977E+308,0.020940435,0
,227.4,243.0287651,0.225464801,1.7977E+308,0.021812954,0
,227.6,242.0287067,0.123531058,1.7977E+308,0.025303028,0
,227.8,240.7066257,0.021618435,1.7977E+308,0.024430512,0
,227.838,240.2043691,0.002271503,1.7977E+308,0.024866772,0
END,,,,,,