File: GB1_test 31.csv
Segment,Time On Sample,Displacement Into Surface,Load On Sample,Harmonic Contact Stiffness,Harmonic Displacement,Harmonic Load
Surface Marker,0,0,0,-300.9470082,0.474958755,2.194973792
,0.592,0.382966376,0.001922267,10632.77337,0.204550644,2.434963459
,0.8,0.309081267,0.002608468,15863.29272,0.159191867,2.534685184
,1,0.307115667,0.003263676,20667.6041,0.131278772,2.630023536
,1.2,0.286848782,0.003920081,24454.98503,0.115577657,2.723170202
,1.4,0.522799897,0.004559721,28366.14862,0.106418671,2.919326143
,1.6,0.485063603,0.00521727,31625.63897,0.103365677,3.183424331
,1.8,0.491416769,0.005871934,34498.61088,0.101621109,3.446426687
,2,0.59759513,0.006520066,34989.18234,0.106418671,3.713812423
,2.2,0.741207938,0.007165748,34673.18475,0.114269228,3.984485699
,2.4,0.997124085,0.007804082,35735.67768,0.124736636,4.473231772
,2.6,0.71481607,0.008477635,38146.48019,0.132587196,5.082520532
,2.8,0.864252014,0.009122936,40198.40556,0.141310037,5.703863614
,3,0.74083243,0.009786092,41470.5275,0.148724453,6.188226265
,3.2,0.64569665,0.010447396,43168.76254,0.156575012,6.805185938
,3.4,0.580508427,0.011106741,46124.3343,0.164861713,7.703777316
,3.6,0.798990131,0.011747525,48287.73595,0.177073689,8.629764807
,3.8,0.812830187,0.012401699,49484.23459,0.191902521,9.566710701
,4,0.923999806,0.013049504,49666.29092,0.206731351,10.30859654
,4.2,0.73486197,0.01371696,48247.2824,0.232463737,11.22910473
,4.4,0.307807415,0.014399983,46624.48293,0.263429832,12.23508859
,4.6,0.772524601,0.015024654,44704.33823,0.303118755,13.44709126
,4.8,0.471915295,0.015699404,42367.46197,0.349349824,14.6371768
,5,0.661281319,0.016342092,39859.64573,0.399942303,15.71767826
,5.2,0.193464805,0.017027782,38176.64185,0.440939674,16.55928552
,5.4,0.013477603,0.017694638,36346.05847,0.49894658,17.83375099
,5.6,0.216985535,0.018336401,34453.641,0.558261901,18.92959421
,5.8,-0.239184719,0.019021329,32590.11815,0.615396534,19.73942203
,6,-0.292726673,0.019679911,30079.72354,0.697827398,20.6785596
,6.2,-0.177397662,0.020327443,26698.96062,0.811660488,21.43030807
,6.4,-0.544557123,0.021006546,23259.972,0.949045277,21.9322039
,6.6,0.32777965,0.021604545,20440.19621,1.087738419,22.25109488
,6.8,0.700158534,0.022235257,17110.29139,1.293161324,22.44834679
,7,0.960234069,0.022873319,15147.00721,1.446683321,22.47793469
,7.2,0.717024251,0.023544313,14211.35144,1.5374009,22.59628561
,7.4,0.636030372,0.024204692,14016.26253,1.566186287,22.8713422
,7.6,1.011736757,0.024835188,14441.72555,1.543506864,23.26146258
,7.8,1.16366833,0.025480327,15972.99381,1.445374881,24.00882766
,8,0.871377794,0.026154532,17905.00617,1.338520094,24.7627676
,8.2,1.016654355,0.026800106,20303.16909,1.238207402,25.70300109
,8.4,0.690256874,0.027476542,22127.43358,1.180200528,26.48214534
,8.6,0.930367371,0.028115911,23133.27898,1.159701833,27.08705092
,8.8,0.720432616,0.028784727,23326.47438,1.178892101,27.72483148
,9,0.497187832,0.029454414,22718.07673,1.225995465,28.11714315
,9.2,0.777228411,0.03009117,21906.95555,1.287055339,28.55986397
,9.4,0.717863324,0.030750133,21043.27198,1.349859807,28.89190444
,9.6,0.777456595,0.031401314,20226.29994,1.411791982,29.22394487
,9.8,1.043355267,0.032038994,19766.03068,1.452353175,29.49023498
,10,1.067177843,0.032692515,19496.62348,1.486372257,29.82775473
,10.2,1.146736151,0.033342389,19471.0871,1.502509509,30.11048228
,10.4,0.884393171,0.034014635,19700.66996,1.507307097,30.45896016
,10.6,1.646922172,0.03461982,20050.66725,1.509487739,30.83483497
,10.8,1.519343208,0.035283248,20568.00392,1.496839631,31.19098392
,11,1.787737499,0.035920766,21550.30329,1.461075958,31.7005512
,11.2,1.687610463,0.036582398,22624.75013,1.41964247,32.16628444
,11.4,1.768000646,0.037232218,24140.96903,1.36207171,32.75694396
,11.6,1.517303947,0.037903702,26475.08792,1.278768593,33.51088383
,11.8,1.718316236,0.03854563,28614.0113,1.216400261,34.26811162
,12,1.543320306,0.039212161,29984.17833,1.184561902,34.85110011
,12.2,0.696168063,0.039922672,30788.48951,1.176275263,35.48668829
,12.4,1.818899642,0.040504288,30244.81494,1.211166551,35.96557282
,12.6,1.763693941,0.04116298,28626.68569,1.286182994,36.35569286
,12.8,2.016282576,0.041801533,27241.98868,1.352912713,36.60992876
,13,2.291331874,0.042438616,25555.71718,1.439704962,36.85978124
,13.2,2.239453682,0.043097091,24662.62563,1.4929143,37.06360799
,13.4,2.295719442,0.043748491,24865.15217,1.495531149,37.44276979
,13.6,2.18311426,0.04441094,26150.70808,1.449736242,38.01151225
,13.8,2.432791322,0.045049683,27870.54013,1.387804049,38.58792601
,14,2.257795398,0.045716215,30446.71947,1.304937071,39.37364541
,14.2,2.220475045,0.046373737,32505.52842,1.246930179,40.02348039
,14.4,2.564154157,0.04700633,34245.40991,1.207241227,40.73906637
,14.6,2.331758752,0.047676617,35276.07992,1.192848556,41.459035
,14.8,2.17298442,0.048342087,35464.07433,1.20375212,42.08914463
,15,2.01337795,0.049009247,35297.16317,1.2220701,42.56035704
,15.2,1.98728767,0.04966767,34781.41127,1.256525327,43.11594947
,15.4,2.184141093,0.050306598,34201.24139,1.292288963,43.59921651
,15.6,2.262035645,0.050956582,33878.42425,1.318457482,44.04303313
,15.8,2.354072098,0.05160564,33539.76388,1.347678994,44.58437969
,16,2.16992553,0.05227277,33343.71554,1.369922256,45.09394659
,16.2,2.314786146,0.052918372,33286.99979,1.383442649,45.52570895
,16.4,2.242111039,0.053578208,33293.0403,1.395218492,46.01555077
,16.6,2.2983768,0.054229607,33079.26352,1.413972597,46.42649196
,16.8,2.468609651,0.054873549,32784.15402,1.439704966,46.90975906
,17,2.436696496,0.055530718,32585.49685,1.459331363,47.28124976
,17.2,2.423084625,0.056186689,32527.07461,1.476777048,47.73821636
,17.4,2.723090217,0.05682214,32595.38262,1.488552858,48.16230811
,17.6,2.523137998,0.057490304,32896.03679,1.489425161,48.57653646
,17.8,2.239998118,0.058163912,33290.57707,1.489425187,49.08719903
,18,2.431027884,0.058806493,33473.73883,1.498148012,49.56389101
,18.2,2.717723452,0.059442814,33428.71168,1.512104534,49.91017791
,18.4,2.630906445,0.060103576,33298.83496,1.530422509,50.28824363
,18.6,2.480034941,0.060768529,32936.96487,1.558771759,50.66521347
,18.8,2.690197866,0.061409858,32708.83228,1.577525849,50.95122879
,19,2.565114536,0.062073123,32617.34038,1.591482408,51.32710284
,19.2,2.853473856,0.062709336,32582.35013,1.599769081,51.63722694
,19.4,2.917226504,0.063360245,32509.19079,1.610236485,51.95282979
,19.6,3.168983251,0.063998853,32517.64197,1.618523161,52.3254168
,19.8,3.138733851,0.064655914,32526.93841,1.625501438,52.61252776
,20,3.333922991,0.065298223,32603.30417,1.631607409,52.98621049
,20.2,3.488349894,0.065944997,32967.22413,1.625937552,53.38181009
,20.4,3.35577839,0.066616875,33687.50548,1.605002748,53.82343468
,20.6,3.491070038,0.06727808,34552.03414,1.579706495,54.26725135
,20.8,3.49575602,0.06795444,35621.03023,1.550921125,54.83161067
,21,3.814890233,0.0686171,36350.62228,1.5343477,55.27542743
,21.2,3.75551958,0.069311146,36941.45973,1.526497146,55.80252791
,21.4,3.591331362,0.070019113,37038.96109,1.535656143,56.22881064
,21.6,3.387211951,0.070736727,37044.50148,1.546123573,56.59701362
,21.8,3.598197807,0.071434226,37249.77474,1.550921118,57.06713067
,22,3.652789754,0.072149012,37889.48589,1.537836852,57.50765971
,22.2,3.795559472,0.072865196,39187.5833,1.504253903,58.1388656
,22.4,3.71205762,0.073603465,40669.81843,1.466745695,58.79527553
,22.6,3.615244568,0.074350003,42228.01744,1.431418201,59.55140716
,22.8,3.970971163,0.075074336,43226.72616,1.41222792,60.1289171
,23,3.944865256,0.075831094,43814.48821,1.408302644,60.79518971
,23.2,3.468712924,0.076625018,43583.7631,1.429237502,61.35406893
,23.4,3.627281184,0.077384918,43146.86087,1.455842154,61.84281545
,23.6,3.666889831,0.078160594,42491.06199,1.487244378,62.20115602
,23.8,3.562582623,0.078953337,41587.98373,1.529550168,62.59785119
,24,4.004817029,0.079718235,40943.13657,1.563569207,62.99564301
,24.2,4.111803964,0.080512827,40676.52867,1.581451022,63.31343765
,24.4,3.960907897,0.081332385,40666.9907,1.591046162,63.7178036
,24.6,4.047927229,0.082144435,41456.56343,1.5749089,64.28435468
,24.8,4.007668133,0.082973128,42781.02877,1.542634393,64.9407647
,25,4.067232911,0.083803519,43928.89596,1.516465867,65.51279498
,25.2,3.981217978,0.084651746,45403.21259,1.484627507,66.23605124
,25.4,3.899361059,0.08550831,46536.99955,1.465001123,66.92095312
,25.6,4.048764448,0.086358312,47203.19782,1.459767406,67.6168137
,25.8,3.908673452,0.087235808,47611.56419,1.459331278,68.18336448
,26,4.061401593,0.088102917,47925.002,1.463692686,68.83648724
,26.2,4.038602408,0.088990211,48028.44466,1.473287813,69.45783026
,26.4,4.130600756,0.089878954,48275.30716,1.477213085,70.03972315
,26.6,4.154383822,0.090781023,48455.30947,1.484627498,70.67092885
,26.8,4.064198359,0.091699654,48206.00824,1.501637047,71.13337463
,27,4.152864896,0.0926157,48011.01426,1.518210437,71.68458378
,27.2,4.088464662,0.093551154,47797.25052,1.535219984,72.21168423
,27.4,4.318547236,0.094476628,47645.78528,1.550048793,72.69823898
,27.6,4.272445331,0.095429474,47569.41824,1.563133059,73.21438106
,27.8,4.267103838,0.096389319,47829.05494,1.566622197,73.77874031
,28,4.434791145,0.097347361,47923.19312,1.573164313,74.21269458
,28.2,4.213158683,0.098340724,48103.08834,1.578834181,74.75184898
,28.4,4.267707655,0.099325863,48292.56304,1.582759456,75.24826604
,28.6,4.500276635,0.100309188,48319.06445,1.592354559,75.78303798
,28.8,4.669621424,0.10130656,48426.2941,1.599332817,76.3178098
,29,4.188437169,0.102356701,48835.02568,1.59627987,76.79450059
,29.2,4.286237325,0.103379241,49541.32423,1.587557021,77.4136522
,29.4,4.336618872,0.104415248,50124.93557,1.582323313,77.9791073
,29.6,4.488487708,0.105454959,51060.20443,1.569239038,78.67496813
,29.8,4.474811445,0.10651604,51622.21198,1.563569194,79.18672678
,30,4.773087185,0.107567293,52105.57761,1.561824599,79.81683721
,30.2,4.793514475,0.108647424,52482.03166,1.563133024,80.44475551
,30.4,5.164991929,0.10971534,53088.31079,1.557027002,81.04966181
,30.6,4.75783126,0.110845148,53738.55034,1.551357195,81.73346701
,30.8,4.608550525,0.111969228,54398.45999,1.543506653,82.31097602
,31,4.995828347,0.11306939,55160.93303,1.536528346,83.03861677
,31.2,4.925988248,0.114210735,55858.60443,1.531294649,83.7673523
,31.4,4.92851959,0.115358741,56463.79148,1.527369372,84.45773361
,31.6,4.984705126,0.116514814,56969.64392,1.526497084,85.16674426
,31.8,4.913611697,0.117690933,57229.69622,1.529550085,85.73329496
,32,5.016794531,0.118867352,57757.61195,1.527805509,86.47737285
,32.2,5.280527651,0.120045046,58193.70091,1.528241628,87.23021764
,32.4,5.026415756,0.121268639,58202.78728,1.538709061,87.87018954
,32.6,5.100477202,0.122482889,58165.86966,1.548304179,88.38414017
,32.8,5.553455464,0.123690675,58242.59048,1.557899263,89.0558931
,33,5.215318213,0.124956482,57968.68535,1.57621726,89.6542227
,33.2,5.113848299,0.126216342,57770.47666,1.591482242,90.17146039
,33.4,5.222425206,0.127474965,57694.97276,1.604566493,90.7719827
,33.6,5.451621691,0.128741482,57743.27999,1.611980886,91.24867502
,33.8,5.422934412,0.130037822,57951.04054,1.617214594,91.85029286
,34,5.407555109,0.131346176,58366.95222,1.617650739,92.49026525
,34.2,5.667524858,0.132649452,58793.44526,1.615906147,93.02503749
,34.4,5.726178403,0.13397911,59394.38789,1.61110858,93.65185987
,34.6,5.760705415,0.135323661,59960.93351,1.608055584,94.34552871
,34.8,5.776928979,0.136683029,60172.88237,1.613289287,94.98769298
,35,5.846390475,0.138052514,60190.19992,1.622448264,95.57835256
,35.2,5.949124843,0.139433568,60230.78098,1.628554243,96.03751111
,35.4,6.125894033,0.140823492,60143.78167,1.640330061,96.65447151
,35.6,6.468204401,0.142216606,60103.76639,1.648616726,97.10157622
,35.8,6.641641605,0.143634903,60147.79024,1.656467266,97.65497747
,36,6.410784594,0.145093986,60536.94284,1.656031148,98.2664574
,36.2,6.394549399,0.146553488,60938.33961,1.653414299,98.76725786
,36.4,6.567147802,0.14801541,61716.63011,1.644691443,99.52777336
,36.6,6.698150051,0.149494726,62313.64861,1.637713159,100.0888455
,36.8,6.567940721,0.151006143,63022.83412,1.629862617,100.774843
,37,6.71807137,0.152514136,63403.19772,1.630298746,101.4465954
,37.2,6.594512257,0.154055276,63363.29928,1.638585457,101.9199992
,37.4,6.861932621,0.155586155,63203.40661,1.652978117,102.5566848
,37.6,7.071951051,0.157136268,63135.41277,1.661700939,103.0059811
,37.8,6.885161951,0.158727995,63259.77452,1.667806944,103.6196528
,38,6.893861267,0.160322888,63562.37775,1.667806947,104.1094946
,38.2,7.201201701,0.161914027,64451.34666,1.656031088,104.8152185
,38.4,7.475264513,0.163523451,65535.89163,1.640329949,105.5384758
,38.6,7.690261529,0.165152914,66598.23699,1.627681812,106.3417298
,38.8,7.647374252,0.166815721,67247.59568,1.622011974,106.9477307
,39,7.448923434,0.168505441,68145.02046,1.612853007,107.7411209
,39.2,7.69136442,0.170183124,68881.84747,1.607619283,108.5235535
,39.4,8.061079796,0.171869393,69426.9795,1.605438538,109.219415
,39.6,8.30933852,0.17358059,70328.75571,1.597151816,110.0796532
,39.8,8.623312749,0.175304613,71315.80746,1.585375956,110.8171562
,40,8.784218959,0.177056089,72712.70709,1.56836641,111.7880739
,40.2,8.840305962,0.17883198,73778.57344,1.556154431,112.5957105
,40.4,8.935488313,0.180623171,75068.01487,1.541325595,113.5436153
,40.6,9.016525905,0.182433289,76208.72677,1.531294322,114.5890503
,40.8,8.947822856,0.184271485,76943.75606,1.52693291,115.4076448
,41,8.767645454,0.186135385,77558.62455,1.527805213,116.4180117
,41.2,9.137335349,0.187981822,77943.45486,1.530858172,117.1807201
,41.4,9.176767373,0.189868597,78306.35141,1.535655734,118.0343819
,41.6,9.420837965,0.191760852,78819.17447,1.539580987,119.041463
,41.8,9.45693644,0.193685867,79281.42592,1.541761694,119.8490994
,42,9.205202642,0.195649063,79688.0282,1.54655928,120.8134408
,42.2,9.608152367,0.197589029,80016.74091,1.550048379,121.5980661
,42.4,9.359739838,0.199591259,80434.4267,1.553101396,122.4878899
,42.6,9.576342981,0.201583008,80839.1587,1.557462797,123.4719579
,42.8,9.554194436,0.203610477,80979.09036,1.564004928,124.2423356
,43,9.673461632,0.205648987,81207.08531,1.570983189,125.1529819
,43.2,9.490754472,0.207727804,81485.30139,1.575344626,125.9156882
,43.4,9.738124041,0.209799291,81730.84789,1.581450591,126.7605843
,43.6,9.474718251,0.211925103,81908.11127,1.589301172,127.6558872
,43.8,9.76617057,0.214035818,82559.68293,1.589301145,128.6311888
,44,9.739010869,0.216188791,82945.21471,1.591481858,129.4092375
,44.2,9.651120768,0.218367331,82966.17692,1.599768564,130.1270147
,44.4,9.83192323,0.220550148,82765.43444,1.614597373,131.0628654
,44.6,9.920383944,0.222760906,82817.76339,1.621575636,131.7488635
,44.8,10.11615318,0.224986785,82516.50753,1.636404443,132.5312965
,45,10.09812664,0.227249117,82477.46682,1.644691142,133.1822272
,45.2,10.24314424,0.229523448,82842.93986,1.645563413,133.8835676
,45.4,10.42975202,0.231817961,83981.13621,1.635968274,134.9596864
,45.6,10.48741529,0.234144044,84466.06879,1.635532127,135.6928057
,45.8,10.40448778,0.236502654,85106.84511,1.634659853,136.6187929
,46,10.1177468,0.238898357,85616.46187,1.63422374,137.3541028
,46.2,10.40832416,0.241280108,86167.04374,1.635532138,138.2844748
,46.4,10.70555271,0.243685454,86164.75036,1.645563374,139.0351288
,46.6,10.52777606,0.246146195,86257.86772,1.652105521,139.6970174
,46.8,10.49391007,0.248622194,86256.13417,1.662136789,140.4969828
,47,10.49830644,0.25112054,86045.6816,1.673912621,141.0942174
,47.2,10.4893888,0.253644852,85696.05021,1.68917759,141.7604903
,47.4,10.92635281,0.256165252,85494.12489,1.700517236,142.3840268
,47.6,10.95486156,0.258737747,85519.97121,1.70880393,143.0886542
,47.8,10.776229,0.261349726,85840.89181,1.709676233,143.6902714
,48,11.10087741,0.263954825,86468.36656,1.706187066,144.4946218
,48.2,11.0811249,0.266608712,86777.11452,1.707059353,145.1214441
,48.4,11.23356651,0.269278126,87317.74787,1.704878629,145.8545638
,48.6,11.14351192,0.271990283,87687.77873,1.706187065,146.6369956
,48.8,11.18447351,0.274721107,87642.34277,1.713165332,147.19478
,49,11.50327741,0.277461134,87400.65956,1.725377273,147.8391373
,49.2,11.12413274,0.280274619,87416.62168,1.731047158,148.367332
,49.4,11.53776166,0.283064185,87165.45954,1.742386805,148.9119679
,49.6,11.19479465,0.285931633,86684.66711,1.758524092,149.4412588
,49.8,11.38172826,0.288792954,86509.56818,1.767683053,149.885076
,50,13.24987912,0.291572326,86641.83768,1.772480416,150.4669766
,50.2,13.39645771,0.294492914,86883.92808,1.775097253,151.0444867
,50.4,14.32832268,0.297391335,87783.31988,1.765065893,151.7151468
,50.6,14.21950358,0.300402408,89093.32646,1.747184092,152.4219653
,50.8,14.52828628,0.303386106,91293.62246,1.716654135,153.4728804
,51,14.62826089,0.306428721,93375.84492,1.688304908,154.3999645
,51.2,14.57474949,0.309512041,96294.88635,1.65079672,155.6766217
,51.4,14.70757344,0.312613926,98639.00318,1.624192058,156.8623249
,51.6,14.80586959,0.315749146,100595.3894,1.604129527,157.9274851
,51.8,14.95490517,0.318912581,102216.9219,1.592353685,159.2096228
,52,15.0623419,0.322110504,103028.2799,1.590172967,160.1794446
,52.2,15.6880323,0.325306505,103598.1621,1.592789759,161.3114537
,52.4,15.39782204,0.32859493,104448.2189,1.590609079,162.4149669
,52.6,15.65914037,0.331880032,104879.3897,1.593225906,163.3727352
,52.8,15.75740573,0.335208901,105605.3361,1.593662039,164.5935052
,53,15.61941299,0.338586693,106109.0669,1.594098195,165.5129174
,53.2,16.06206437,0.341960088,106943.308,1.592789729,166.7227304
,53.4,16.35830012,0.345377265,107360.2461,1.596714977,167.7911791
,53.6,16.62291912,0.348830823,107962.9644,1.597587237,168.7905899
,53.8,16.21537678,0.35236336,108838.1275,1.597151135,170.0310827
,54,16.29198066,0.355899459,109709.0927,1.59497042,171.0403549
,54.2,16.38355267,0.359469968,109923.4032,1.603257106,172.2140039
,54.4,16.703053,0.363061414,109749.1352,1.615032903,173.1991685
,54.6,16.62574274,0.366715028,109461.2053,1.628553306,174.2292612
,54.8,16.82377762,0.370387147,108933.2256,1.642945965,174.9941609
,55,17.09334797,0.374091427,108003.7102,1.663880744,175.8653576
,55.2,16.78309484,0.377871069,107787.8776,1.673475894,176.6214881
,55.4,17.26145411,0.381636817,108010.8181,1.677837266,177.5244658
,55.6,17.40872072,0.385462173,108024.6947,1.686123947,178.4701787
,55.8,17.58759249,0.389323966,108326.4717,1.688740777,179.2537082
,56,17.23239374,0.393259604,109257.8856,1.685251686,180.3396868
,56.2,17.32473798,0.397205268,110167.4663,1.680454121,181.2415669
,56.4,17.63585928,0.401176353,111141.367,1.676092674,182.2837152
,56.6,17.72070397,0.405202234,112083.8481,1.673039669,183.4102428
,56.8,17.55348382,0.409285061,112891.6327,1.669986694,184.3186962
,57,17.58257988,0.41339601,113681.9184,1.669114411,185.4616611
,57.2,17.74393766,0.417539533,113632.7622,1.67696495,186.2451901
,57.4,17.94937825,0.421721732,113457.8654,1.687432327,187.099949
,57.6,18.71799216,0.425908938,113461.4745,1.696155086,188.0533369
,57.8,18.95752629,0.430172976,112922.0775,1.710111603,188.7239944
,58,19.6995066,0.434447019,112112.7422,1.728865612,189.4625968
,58.2,20.12287164,0.438784736,112029.0721,1.735843837,190.1288719
,58.4,20.2442588,0.443185992,112419.02,1.738024531,191.1008862
,58.6,20.47045531,0.447624451,112983.3641,1.7358438,191.8570196
,58.8,20.61595276,0.452112891,114736.4836,1.719270403,193.0065603
,59,21.15408842,0.456620635,116508.3267,1.702260832,194.0388473
,59.2,21.2546502,0.461202437,118264.8451,1.686559716,195.1029125
,59.4,21.26536208,0.465836157,120281.1169,1.669114051,196.346695
,59.6,21.97650595,0.470470441,122308.4134,1.653849024,197.7723915
,59.8,22.11198437,0.47518921,123288.9261,1.649923737,198.8101561
,60,21.98375068,0.47997253,124808.5385,1.64163706,200.1766726
,60.2,21.89044812,0.484801611,126160.6056,1.635967229,201.5377096
,60.4,22.2995908,0.489646234,126642.3259,1.639892465,202.6927312
,60.6,22.21209592,0.494572172,126978.3372,1.643817749,203.693236
,60.8,22.49560976,0.499523172,127036.8629,1.652540554,204.8767488
,61,22.87478139,0.504517671,126819.5134,1.662571774,205.7534257
,61.2,22.99939106,0.509579112,126275.9947,1.677836719,206.7714654
,61.4,22.80538426,0.514712347,126794.8358,1.679581306,207.8377201
,61.6,22.94994267,0.519874866,127810.196,1.675219877,208.8930186
,61.8,22.90898457,0.525101398,130090.097,1.658646501,210.401995
,62,23.31057598,0.530351442,131552.7949,1.649487489,211.5340039
,62.2,22.92686834,0.535705832,134160.1536,1.630733439,213.1744796
,62.4,23.30764593,0.541063751,135756.0208,1.622446713,214.5925033
,62.6,23.42970161,0.546492544,136679.6185,1.620265994,215.7979323
,62.8,23.88699452,0.551953807,137210.7222,1.624191225,217.2565028
,63,24.11800852,0.557484805,137603.3215,1.627244194,218.3775525
,63.2,24.15019541,0.563084379,137566.027,1.636403165,219.6947569
,63.4,24.39866104,0.568725989,137408.018,1.646434398,220.8530649
,63.6,24.75692522,0.574417126,137247.598,1.657774044,222.0694538
,63.8,24.67594996,0.580194404,136841.5273,1.669986016,222.9779078
,64,24.86033381,0.586012216,136395.5187,1.68437867,224.0825194
,64.2,24.93074141,0.591895984,136047.9877,1.695718344,224.9471404
,64.4,25.57679753,0.597801025,135830.4428,1.706185676,225.9114869
,64.6,26.06977908,0.603775504,135526.849,1.717525307,226.9404869
,64.8,26.02203196,0.609845595,135955.4054,1.720142162,228.039618
,65,26.34695541,0.615952129,136667.3722,1.718397563,229.0138252
,65.2,26.66022284,0.622120742,137650.1944,1.7149084,230.2104884
,65.4,26.42860193,0.628387263,138703.757,1.71054701,231.397286
,65.6,26.82670079,0.634675341,139660.0015,1.706621697,232.4054646
,65.8,26.79554185,0.641054731,140639.1136,1.704440993,233.7128061
,66,27.07965354,0.647477485,141004.4521,1.707057814,234.6913964
,66.2,26.76813206,0.654004197,141671.4166,1.70793013,235.9165478
,66.4,27.24854564,0.660544502,142224.5595,1.709674648,237.0551327
,66.6,26.95322485,0.667201483,142817.3583,1.709674679,238.0238565
,66.8,27.37330638,0.673878339,143189.8804,1.714472194,239.2216164
,67,27.63407307,0.680632742,143400.3054,1.719269724,240.1519898
,67.2,29.05279957,0.687379071,143076.656,1.731045398,241.1908589
,67.4,29.61010826,0.694249577,142592.1733,1.743257302,242.0554834
,67.6,29.72027295,0.701218539,141955.2543,1.755905393,242.7403868
,67.8,30.23305418,0.708231083,141076.6317,1.772042572,243.533781
,68,30.62603415,0.715321922,140767.9128,1.780329218,244.2121108
,68.2,31.10967143,0.72251434,141360.5545,1.779456885,245.2115239
,68.4,31.38699784,0.729756682,142365.6903,1.773787018,246.2010727
,68.6,31.13067054,0.737069995,143455.7617,1.767244926,247.1369218
,68.8,31.2873518,0.744466417,145599.6808,1.751107679,248.4815231
,69,31.55382884,0.751929615,147191.3462,1.740204118,249.5543563
,69.2,32.24787785,0.759439657,148968.3646,1.730172795,250.9219745
,69.4,32.18657212,0.767074803,150428.1415,1.722758399,252.1580857
,69.6,32.59942306,0.774755632,152293.813,1.710546399,253.3744756
,69.8,32.83673606,0.782525111,154144.1026,1.700078984,254.8166078
,70,32.86523597,0.790386389,155764.5595,1.692228438,256.2850391
,70.2,32.92117521,0.798324851,157070.0761,1.686122454,257.5036177
,70.4,33.65175256,0.80629873,158739.3853,1.677835696,258.9665745
,70.6,33.69768388,0.814397757,159835.5748,1.675654986,260.4744563
,70.8,34.19198298,0.822548649,160731.2291,1.674346513,261.7007093
,71,34.04655704,0.830823584,162151.6399,1.670421257,263.2907779
,71.2,34.58824678,0.839136454,163053.977,1.669548921,264.5663442
,71.4,34.49936187,0.847574311,163554.6279,1.673038061,265.9229986
,71.6,34.76733791,0.856073503,164297.5747,1.675654883,267.4780031
,71.8,35.04029163,0.864657754,164793.623,1.678271705,268.6669957
,72,35.19344164,0.873336047,165069.2366,1.684377668,270.0981694
,72.2,35.35240093,0.882100972,165651.3493,1.687430642,271.5161923
,72.4,35.67023438,0.890943438,166467.339,1.687866753,272.9024374
,72.6,35.90320246,0.899880277,166810.525,1.691792001,274.0892385
,72.8,35.68361621,0.908936655,166747.6881,1.70051485,275.4415081
,73,36.10289559,0.91804191,166491.6159,1.709237634,276.4836591
,73.2,36.77089104,0.927222345,165995.602,1.721449522,277.7219679
,73.4,37.40310118,0.93649741,164821.0288,1.73889511,278.6534397
,73.6,37.87391275,0.945876191,164589.0377,1.746309466,279.5860073
,73.8,38.14089996,0.955362567,165153.9138,1.747617861,280.838559
,74,38.37043764,0.964946718,166051.7922,1.745000989,281.9322126
,74.2,38.63157127,0.974625081,167955.9578,1.734969717,283.4116042
,74.4,39.414275,0.984366457,171238.1098,1.713162578,285.077294
,74.6,39.32266262,0.994263188,173525.6496,1.700950632,286.5303821
,74.8,39.73431875,1.004226289,176095.318,1.688302504,288.3253781
,75,39.90637901,1.014305164,177908.7346,1.68045194,289.7949064
,75.2,40.68485994,1.024445492,179386.5815,1.676962737,291.515388
,75.4,40.87685289,1.034726205,179704.0348,1.682196408,292.9498496
,75.6,41.19028314,1.045102312,180488.619,1.682196379,294.2834945
,75.8,41.64677927,1.055573286,180814.5985,1.687430024,295.8527471
,76,42.04169993,1.066153499,181061.9409,1.691791398,297.0735208
,76.2,42.08305689,1.076863377,181788.4639,1.694408246,298.6844121
,76.4,42.24335486,1.087672891,182174.3895,1.69876964,300.1177777
,76.6,42.86698981,1.098560524,182715.7098,1.700950278,301.4086874
,76.8,43.35002052,1.109566812,183656.2398,1.701386371,302.9856113
,77,43.72821743,1.120690527,183909.966,1.705747751,304.1833722
,77.2,44.01405848,1.131932073,184610.6283,1.707928421,305.7635827
,77.4,44.49121275,1.143274003,185655.3149,1.707056091,307.2396891
,77.6,44.57653592,1.15475564,185781.5641,1.714470481,308.6697663
,77.8,45.22751551,1.166315491,186161.2514,1.717959544,309.8576674
,78,45.50496493,1.178015979,187070.3222,1.718831798,311.4071935
,78.2,46.1409336,1.189810503,187883.8119,1.718831734,312.6520782
,78.4,46.45328421,1.201744716,188970.6547,1.71752328,314.1522922
,78.6,46.95278754,1.213786534,191014.833,1.70923655,315.9396182
,78.8,47.20270925,1.225965771,192351.6206,1.705311257,317.3401097
,79,47.81614068,1.238243468,194432.2838,1.697460657,319.2293506
,79.2,47.69251166,1.250693035,195645.8129,1.694843825,320.6966854
,79.4,47.88164758,1.263247094,196087.5861,1.699205217,322.2385401
,79.6,47.88775106,1.27593927,196226.8254,1.70487505,323.5469783
,79.8,48.76896624,1.288701407,196283.048,1.712289357,325.0943185
,80,49.12691197,1.301626214,195885.0447,1.722756703,326.5309734
,80.2,49.70528377,1.314666367,195603.3273,1.730607181,327.6388775
,80.4,50.24786412,1.32783991,196237.6898,1.731915548,329.0481384
,80.6,50.4268943,1.341169846,197660.4807,1.727554122,330.7050568
,80.8,50.86378425,1.354616694,198915.7658,1.723628809,332.0836332
,81,51.20581904,1.368204806,201131.845,1.714905957,333.9323256
,81.2,52.08023169,1.381894514,204178.8366,1.70051322,335.9245794
,81.4,52.33737171,1.39576236,206988.7568,1.688301251,337.8620348
,81.6,52.52461215,1.409774056,208708.0674,1.683503683,339.527721
,81.8,53.17185667,1.423896294,210932.386,1.676525366,341.5758598
,82,53.83322048,1.438159529,212331.7019,1.675216878,343.488115
,82.2,54.15349305,1.452588518,212670.9981,1.679578254,344.9620292
,82.4,54.59685997,1.467154316,213070.8914,1.684375759,346.6474423
,82.6,55.64164861,1.481826985,213969.3318,1.686556359,348.5706595
,82.8,55.76552913,1.496707554,214678.0473,1.688737051,350.125664
,83,56.22463115,1.511715576,215512.6951,1.690917709,351.9327165
,83.2,56.61299988,1.526879173,216421.1517,1.693098374,353.7737393
,83.4,56.67358599,1.542216654,216602.8902,1.69964048,355.3944939
,83.6,56.85268965,1.557700529,216134.0446,1.7096717,356.6843047
,83.8,57.30753475,1.573322411,214981.0116,1.72537272,358.1571244
,84,57.78481547,1.589099795,213901.7288,1.738893034,359.2266736
,84.2,58.00543787,1.605052518,212683.844,1.755030218,360.5285394
,84.4,58.38575458,1.621155064,212206.9355,1.764625275,361.6967135
,84.6,58.84798515,1.637414054,212432.2121,1.768550493,362.8572177
,84.8,59.37008468,1.653832351,212904.1538,1.772039564,364.2456584
,85,60.09679894,1.67040228,213922.4937,1.770294925,365.5157497
,85.2,60.77149458,1.687142138,214632.9844,1.771603276,366.9896674
,85.4,61.22363719,1.704064878,215849.267,1.768550245,368.4394748
,85.6,61.56511355,1.721164895,217409.2628,1.763752663,370.1007789
,85.8,62.2380643,1.73841502,218956.2359,1.757646624,371.4727834
,86,62.44969945,1.755956903,220743.1671,1.751540634,373.2414795
,86.2,62.74369006,1.773493629,222351.9824,1.745870777,374.7405978
,86.4,63.54050633,1.791261639,223842.9808,1.743689995,376.6265551
,86.6,63.93425144,1.809234228,224943.45,1.742381529,378.0456788
,86.8,64.26807293,1.827391375,225807.4563,1.744126057,379.7398578
,87,64.68172527,1.845725741,227266.4731,1.74020075,381.2236362
,87.2,65.46719583,1.864220023,229049.3181,1.735403123,383.0657606
,87.4,66.07544776,1.882911653,230087.232,1.73496692,384.7226838
,87.6,66.60131433,1.901796475,230587.7153,1.737147569,386.124275
,87.8,67.25525926,1.920862592,231905.3079,1.73540294,387.9499601
,88,67.39424398,1.940154158,231672.3495,1.744561876,389.5750992
,88.2,67.74366192,1.959625594,231687.105,1.750231666,390.7914911
,88.4,68.4549137,1.979269033,231953.4993,1.755029138,392.2884228
,88.6,68.71775429,1.999139276,232245.3987,1.759826656,393.8872642
,88.8,69.25840887,2.019190904,231705.5496,1.768549408,395.0357152
,89,70.288173,2.039411815,232289.1387,1.770293861,396.614839
,89.2,70.731434,2.059874642,233236.1666,1.768549253,397.9868414
,89.4,71.41174624,2.080527378,235102.536,1.761570936,399.6711637
,89.6,72.09868049,2.101386956,238407.012,1.746742093,401.7971106
,89.8,72.82717508,2.122453257,241538.3803,1.732785526,403.6677265
,90,73.54981286,2.143731735,245698.6115,1.71533984,406.1246188
,90.2,73.92885306,2.165246086,248502.0144,1.705308575,408.0270102
,90.4,74.3303195,2.186974979,250854.6394,1.699638711,410.0861078
,90.6,74.88731153,2.208911851,251839.2267,1.703127777,412.1890408
,90.8,75.21300777,2.231084286,252777.3104,1.704872306,413.9248639
,91,75.71336196,2.253467967,252960.4548,1.712286639,415.8776656
,91.2,76.83093026,2.276035865,252764.684,1.721445476,417.6748646
,91.4,77.49093224,2.298860683,253354.4374,1.724934528,419.4632921
,91.6,77.97953192,2.321926017,254606.0912,1.724062201,421.1870613
,91.8,79.08867197,2.34518244,255477.8164,1.725370508,422.8472798
,92,79.371725,2.368726719,256637.1489,1.726242758,424.8910347
,92.2,80.08814621,2.392479097,257610.3499,1.727987244,426.8504146
,92.4,80.7853964,2.416471288,258495.0514,1.729731734,428.691443
,92.6,81.67477085,2.440692048,259180.3974,1.731476202,430.2913878
,92.8,81.88862584,2.465200516,260682.5838,1.730167761,432.3932218
,93,82.39775655,2.489935796,262686.6038,1.724934028,434.2419191
,93.2,83.05991233,2.514909543,265666.2918,1.715338876,436.5990906
,93.4,83.7128776,2.540134769,267742.5609,1.710541271,438.7601057
,93.6,84.29342965,2.565618104,269554.5895,1.708360513,441.1589185
,93.8,84.89972902,2.591355934,270418.9713,1.709668867,442.9484426
,94,85.69814985,2.617339641,270683.7807,1.715338605,445.0108326
,94.2,86.23032991,2.643601893,270745.5145,1.721008377,446.6754285
,94.4,86.52538432,2.670143596,271706.0127,1.722752901,448.6413791
,94.6,87.14149917,2.696930807,272761.4219,1.724933538,450.8144497
,94.8,87.9031489,2.7239776,272979.7177,1.729730999,452.4341183
,95,88.3652813,2.751315849,272885.5588,1.737581471,454.3671958
,95.2,88.918876,2.778922717,272664.9655,1.744559652,455.8312532
,95.4,89.80767119,2.806784998,272253.4431,1.752846218,457.4191437
,95.6,90.51091429,2.83493936,271354.0963,1.764185781,459.0859344
,95.8,91.00531241,2.863390419,270900.5672,1.772908527,460.7450512
,96,92.07698452,2.892089259,271354.5979,1.775525253,462.1477475
,96.2,92.79090562,2.921100066,272711.8763,1.774652898,464.0315151
,96.4,93.00316138,2.950435214,273844.3535,1.775089016,465.7180247
,96.6,94.02062263,2.980012266,275652.6451,1.77116365,467.3376981
,96.8,94.74854506,3.009905519,279376.3885,1.75851552,469.668571
,97,95.31337279,3.040109731,282181.7074,1.749356527,471.572062
,97.2,96.42469223,3.070581578,284228.1728,1.745867293,473.8328069
,97.4,96.98359988,3.101395852,286258.7724,1.741505838,475.9795759
,97.6,97.73961199,3.13250673,287188.7412,1.741941899,477.7175972
,97.8,98.80087141,3.163910104,288156.9755,1.743250208,479.8709481
,98,99.82131887,3.195631731,289974.7992,1.740197125,482.1130623
,98.2,100.4873382,3.227695289,292616.6055,1.731910403,484.1458674
,98.4,101.3853985,3.260065795,295801.3546,1.722315239,486.5720815
,98.6,101.8175589,3.292792112,298528.7746,1.716209241,489.2065015
,98.8,102.7621,3.325813542,299421.9731,1.717953703,491.1198606
,99,103.3189361,3.359192256,298680.9323,1.729293274,493.2447141
,99.2,103.7817173,3.392912457,297369.9343,1.741941273,494.6956206
,99.4,104.8633573,3.426930823,295100.492,1.760259019,496.1300982
,99.6,105.3934119,3.461327295,294044.1254,1.772907009,497.8659255
,99.8,106.0773078,3.496059227,293849.6188,1.779012889,499.2576587
,100,107.1878984,3.531112064,295892.6367,1.774651377,501.3693694
,100.2,108.077987,3.566531571,297957.28,1.76898147,503.2038286
,100.4,108.71513,3.602323452,301744.7891,1.755461082,505.5610027
,100.6,109.6167509,3.638457646,305881.9077,1.741068388,508.235976
,100.8,110.428472,3.674960733,309382.2177,1.731037099,510.9569732
,101,111.6244593,3.711805379,310214.677,1.732781532,512.8341754
,101.2,112.0629686,3.749071701,311062.1527,1.735834463,515.1508004
,101.4,113.1457027,3.786670272,309945.2089,1.747610111,516.9392367
,101.6,114.0254,3.824659956,308172.7621,1.762002615,518.2816614
,101.8,114.9657632,3.863027258,307729.9225,1.770725301,520.2059817
,102,115.9771901,3.901775448,308477.6011,1.772033611,521.8497652
,102.2,116.5297781,3.94094313,309738.3673,1.772469692,523.9833866
,102.4,117.3672194,3.980485652,312326.5423,1.765927516,526.149887
,102.6,118.3193957,4.020417925,316489.8199,1.751534824,528.4204949
,102.8,119.0236106,4.060767715,321396.6717,1.73670602,531.365045
,103,119.9631805,4.101507527,325600.9796,1.723621749,533.8120839
,103.2,121.033705,4.142647979,329250.9712,1.714898857,536.7467768
,103.4,122.2243524,4.184298596,331826.6991,1.710973484,539.4217557
,103.6,123.2610705,4.226167889,331798.231,1.717515463,541.3975829
,103.8,123.858027,4.26880699,329187.9685,1.736705518,543.3931293
,104,124.9907086,4.311408783,326811.1289,1.753714821,544.8330879
,104.2,125.9727192,4.354663929,325982.5037,1.764618191,546.7267261
,104.4,127.1676196,4.398339785,325901.0227,1.771160149,548.5644793
,104.6,128.3300071,4.442456573,327248.7429,1.771596165,550.7923532
,104.8,129.018158,4.487047869,330348.3594,1.762437176,552.9204986
,105,130.0148615,4.532066936,334949.0303,1.748044489,555.8135494
,105.2,130.9574215,4.577541807,337785.325,1.74063003,558.0118326
,105.4,132.0188663,4.623465819,340860.4878,1.733651699,560.6221561
,105.6,133.2025226,4.669843127,344291.8257,1.726237217,563.5875363
,105.8,134.5100534,4.716678358,346061.9843,1.726673221,566.3216947
,106,135.6028868,4.763998217,346887.2757,1.72928994,568.4038214
,106.2,136.8828154,4.81178124,348728.3765,1.729289808,571.1763353
,106.4,137.8016359,4.860068096,350109.9998,1.73016199,573.6540596
,106.6,138.9782589,4.908823159,351125.3601,1.731470284,575.7986513
,106.8,139.956819,4.958081184,353416.1171,1.728417212,578.6774572
,107,140.8055286,5.007842683,355253.9111,1.726236432,580.976558
,107.2,141.7423369,5.05809821,356671.7006,1.727108612,583.7545463
,107.4,142.7372958,5.108854942,357829.7237,1.728416925,586.2059722
,107.6,143.8844058,5.160111158,359803.6406,1.727544529,589.040948
,107.8,144.7419433,5.211900624,360898.5742,1.729288994,591.3082703
,108,145.9812264,5.264184583,362336.1987,1.730597281,594.0281827
,108.2,147.1904786,5.31699556,363854.2417,1.730161017,596.294415
,108.4,148.523595,5.370328922,366415.1303,1.726671772,599.0493974
,108.6,149.6203751,5.424213581,369337.6833,1.722746413,602.2109364
,108.8,150.5798107,5.478648511,372342.2058,1.717076516,604.8103021
,109,151.8378004,5.533610844,376534.7887,1.70878976,608.2030673
,109.2,152.9459657,5.589135186,378973.0598,1.706172819,610.8736652
,109.4,154.1638491,5.645210206,381722.1695,1.704428145,614.4417655
,109.6,155.3749878,5.701848998,382706.5433,1.707044849,616.8460758
,109.8,156.7440912,5.759046412,383844.2125,1.710533815,619.9199518
,110,157.9841633,5.816827087,383499.6001,1.717948036,622.1379688
,110.2,159.3040026,5.875182996,384717.7096,1.721000867,625.1033555
,110.4,160.4066307,5.934139487,386328.052,1.722309162,627.8747736
,110.6,161.4883679,5.993689488,389866.0938,1.717075397,631.1689109
,110.8,163.0616444,6.053805618,392637.2113,1.713586132,633.7880147
,111,164.2513332,6.114550992,397225.174,1.705735523,637.4415928
,111.2,165.3685524,6.175911485,399992.9435,1.702682445,640.2195867
,111.4,166.0705711,6.237915573,401503.2431,1.704863065,643.1422256
,111.6,167.5136856,6.30049396,400084.5832,1.71838319,645.9377595
,111.8,168.9417264,6.363702175,397189.8313,1.736264689,648.3026251
,112,170.0028122,6.427569497,394854.8222,1.750657126,650.1590107
,112.2,171.3782421,6.492057793,391986.1218,1.767666354,652.1973137
,112.4,172.5056722,6.557210329,390722.9541,1.77813354,654.186298
,112.6,174.2078192,6.622979649,392206.0872,1.777261083,656.3670675
,112.8,175.4132356,6.689442606,395768.2933,1.770282752,659.3806724
,113,176.7849194,6.7565622,398599.2028,1.765048954,661.8386849
,113.2,178.1648146,6.824355719,402018.2101,1.759379019,664.9377685
,113.4,179.6444255,6.892823727,405840.5178,1.751528387,667.8483699
,113.6,181.2678401,6.96197018,408110.4849,1.748911391,670.337071
,113.8,182.8653563,7.031813149,409484.9797,1.750655773,673.2038402
,114,184.1416598,7.10237892,409813.2131,1.754580876,675.3966568
,114.2,185.3995494,7.173654807,412067.9594,1.752400056,678.4354686
,114.4,187.1298258,7.245615828,414053.0874,1.750655324,681.2474475
,114.6,188.9381828,7.318294735,416139.0459,1.749346722,684.3618849
,114.8,190.1641162,7.391742047,419182.9115,1.743676809,687.1311176
,115,191.799211,7.465900529,423878.0107,1.734081618,690.6553964
,115.2,193.0739887,7.540827626,426968.2979,1.729283976,693.39614
,115.4,194.6314815,7.616488977,428003.1162,1.732772911,696.2672935
,115.6,195.8552745,7.692932402,428344.3304,1.738878703,699.2195338
,115.8,197.2844166,7.770130374,429177.1233,1.743676062,702.3208142
,116,198.6760012,7.848106465,429921.0403,1.746728875,704.6473285
,116.2,200.0583107,7.926866559,430868.3218,1.750653963,707.539301
,116.4,202.1051559,8.006374283,434778.4789,1.74454783,710.6899058
,116.6,203.414008,8.086729344,439766.7855,1.735824954,714.2503464
,116.8,205.0787707,8.167868359,442633.6668,1.733207959,717.1412285
,117,206.6818454,8.2498266,445082.3828,1.733207791,720.4803136
,117.2,208.3205594,8.332605972,448131.3468,1.729718526,723.4281798
,117.4,209.8767863,8.416222334,450431.4962,1.729282227,726.6215174
,117.6,211.9303355,8.500646335,452071.3362,1.731462697,729.9496517
,117.8,213.3540269,8.585959737,454395.724,1.730154138,732.8745023
,118,215.1269657,8.672107331,458596.6467,1.724484177,736.7516535
,118.2,216.550383,8.759143445,460194.9601,1.725356303,739.5647297
,118.4,218.2074156,8.847038706,462638.3294,1.724483857,742.9849089
,118.6,220.1450619,8.935800916,464551.7024,1.725355929,746.523447
,118.8,221.4428611,9.025499229,467060.1106,1.723175112,749.6247283
,119,223.2699995,9.116064013,467954.7281,1.727536286,753.1709355
,119.2,225.0994887,9.207538689,468887.2477,1.730152914,755.9281307
,119.4,226.5557398,9.299956847,468269.3043,1.738439352,758.7214832
,119.6,228.2064998,9.393290862,468441.3848,1.744981223,761.9356456
,119.8,230.1960957,9.48754028,468196.1768,1.752831465,764.9898216
,120,231.9517866,9.582752008,469051.8778,1.755448097,767.5267505
,120.2,233.8054855,9.678913997,470814.8991,1.756756309,770.858174
,120.4,235.1757168,9.776074005,474126.617,1.752394803,774.0646605
,120.6,237.1813378,9.874168573,476303.852,1.751522319,776.8492587
,120.8,238.686851,9.973281634,478714.3018,1.751522159,780.3845032
,121,240.6842539,10.07335792,479957.2486,1.753702628,783.0891054
,121.2,242.8137228,10.17468572,482761.8486,1.752393995,786.5761464
,121.4,244.4210343,10.27706643,484036.0215,1.75501064,789.6007296
,121.6,246.2270384,10.38020775,486694.4405,1.753702041,792.979275
,121.8,248.0537575,10.48385958,490665.9525,1.747595948,796.1594732
,122,250.2670446,10.58905164,496935.194,1.736256186,800.2853986
,122.2,251.8920352,10.69533948,501452.8691,1.729277845,803.7220223
,122.4,254.1573913,10.80265306,507701.0734,1.718374219,807.8490469
,122.6,255.9783604,10.9110741,511832.5301,1.71444881,812.160163
End Of Loading Marker,122.752,257.4661973,10.99419538,513094.8721,1.715320927,814.5535316
,123,259.491491,10.99626227,513503.3801,1.722298887,819.0169814
,123.2,260.3464494,10.99620708,511679.963,1.732329914,821.6601924
,123.4,261.5649323,10.9961281,507951.5435,1.748466798,824.3110822
,123.6,262.0896407,10.99609451,506263.7221,1.759370128,827.3038629
,123.8,262.7141728,10.99605439,507777.4345,1.76155074,830.6549884
,124,263.844478,10.99598118,509106.1376,1.765475839,833.8713374
,124.2,264.3841599,10.99594662,511173.8253,1.766348054,836.6668652
,124.4,264.8090446,10.99591957,515004.5576,1.762858927,840.0453825
,124.6,265.3387441,10.99588566,518041.4405,1.761550467,843.536777
,124.8,265.957453,10.99584592,518883.5376,1.765039484,846.2786088
,125,266.1618937,10.99583329,520509.129,1.766784005,849.7031492
,125.2,266.5576632,10.99580815,522767.8271,1.765475558,852.6400388
,125.4,266.9118394,10.99578572,525722.6602,1.762422575,855.8969148
,125.6,267.1395724,10.99577157,528569.8608,1.761114146,859.7082908
,125.8,267.5927403,10.99574266,529461.8056,1.764167046,862.4402578
,126,267.7813757,10.99573107,530712.2794,1.768092244,865.911918
,126.2,268.1621716,10.9957069,530992.2815,1.772889693,868.4630679
,126.4,268.5263301,10.99568382,530677.461,1.780303958,871.2903717
,126.6,268.8048067,10.99566635,528957.1546,1.791643443,873.9423392
,126.8,269.0333715,10.99565214,530289.1971,1.793824099,877.0578476
,127,269.2020422,10.99564186,531385.8788,1.795132483,879.4654363
,127.2,269.3965006,10.99562988,529842.0108,1.805163577,882.1272631
,127.4,269.3305857,10.99563494,526198.3673,1.820428317,884.049384
,127.6,270.0025337,10.99559172,525127.7684,1.827406405,885.8816632
,127.8,269.9524243,10.99559575,522275.6044,1.840490465,887.7906343
,128,270.3249014,10.99557213,520251.8004,1.850085402,889.2097704
,128.2,270.5518025,10.99555803,519937.1867,1.855318996,891.2360044
,128.4,270.653924,10.9955521,522894.2455,1.850085369,893.6392082
,128.6,270.7818333,10.99554448,525495.3268,1.845724007,895.8583096
,128.8,270.8323794,10.99554192,527693.3289,1.843543322,898.4050686
,129,270.7789424,10.99554616,528881.2725,1.843543327,900.4488294
,129.2,270.8486213,10.99554235,532011.3545,1.83874584,903.2958521
,129.4,271.1137881,10.99552575,533795.6385,1.838309674,905.6804305
,129.6,271.2117503,10.99552009,534746.0747,1.840926471,908.0628153
,129.8,271.6624226,10.99549135,536454.8508,1.840054152,910.1438477
,130,271.686349,10.99549054,538770.1877,1.838309616,912.8264894
,130.2,271.7843112,10.99548487,538607.6178,1.842670952,914.5699929
,130.4,271.7317062,10.99548907,537417.3961,1.850085257,916.4603338
,130.6,272.2464319,10.99545613,537432.756,1.853574281,918.609312
,130.8,272.3859873,10.99544775,536237.4072,1.860552429,920.4843147
,131,272.6919154,10.99542848,535562.1738,1.865786018,921.9516684
,131.2,272.5727613,10.99543703,535034.4347,1.871019654,923.7335192
,131.4,272.7638922,10.99542527,535881.9669,1.872328039,925.5614028
,131.6,272.8909696,10.99541771,535435.8538,1.877125512,926.9640948
,131.8,273.048826,10.99540813,534820.6741,1.883231387,928.5826722
,132,273.2174966,10.99539784,532178.0977,1.894570882,929.7114011
,132.2,273.0326253,10.99541068,530920.1011,1.901112931,930.7053346
,132.4,273.4009431,10.99538733,528691.9617,1.910707862,931.5973667
,132.6,273.4232057,10.99538662,527301.1712,1.917686022,932.5759619
Unloading Marker,132.758,273.3698602,10.99539071,526899.4161,1.92030284,933.2071705
,133.5,273.6162364,10.88487501,1.7977E+308,1.974819705,0
,133.7,273.3922762,10.77493782,1.7977E+308,1.959555007,0
,133.9,273.2814493,10.66499323,1.7977E+308,1.862296895,0
,134.1,272.9052581,10.555066,1.7977E+308,1.689587435,0
,134.3,272.6505188,10.44513083,1.7977E+308,1.432267742,0
,134.5,272.5995861,10.33518232,1.7977E+308,1.010525083,0
,134.7,272.228386,10.22525476,1.7977E+308,0.649841351,0
,134.9,271.9578414,10.11532062,1.7977E+308,0.372459412,0
,135.1,272.0233696,10.00536449,1.7977E+308,0.160933867,0
,135.3,271.6521694,9.895436935,1.7977E+308,0.020934487,0
,135.5,271.4623155,9.785497514,1.7977E+308,0.010031109,0
,135.7,271.4746044,9.675544867,1.7977E+308,0.011339514,0
,135.9,271.2722726,9.565606263,1.7977E+308,0.015264731,0
,136.1,270.8108153,9.455684614,1.7977E+308,0.020934489,0
,136.3,270.6945813,9.345740376,1.7977E+308,0.030965598,0
,136.5,270.4914175,9.235801827,1.7977E+308,0.033582409,0
,136.7,270.2458288,9.125866053,1.7977E+308,0.030529464,0
,136.9,269.9686292,9.015932348,1.7977E+308,0.023769369,0
,137.1,269.9359975,8.90598264,1.7977E+308,0.011993718,0
,137.3,269.6571341,8.796049043,1.7977E+308,0.00087227,0
,137.5,269.5246788,8.686105867,1.7977E+308,0.008286569,0
,137.7,269.1971515,8.576175455,1.7977E+308,0.01003111,0
,137.9,268.9087217,8.466242484,1.7977E+308,0.011339516,0
,138.1,268.7937355,8.356298165,1.7977E+308,0.014392463,0
,138.3,268.3767828,8.246373604,1.7977E+308,0.016137004,0
,138.5,268.1611411,8.136435871,1.7977E+308,0.020062222,0
,138.7,268.0137558,8.02621879,1.7977E+308,0.021370628,0
,138.9,267.9302493,7.917097055,1.7977E+308,0.017881546,0
,139.1,267.534268,7.806071597,1.7977E+308,0.023551305,0
,139.3,267.2204663,7.696140286,1.7977E+308,0.036199229,0
,139.5,267.0346843,7.586750362,1.7977E+308,0.045794205,0
,139.7,267.0286722,7.476798912,1.7977E+308,0.05277237,0
,139.9,266.9245002,7.366853885,1.7977E+308,0.043177394,0
,140.1,266.7754075,7.256911798,1.7977E+308,0.026604253,0
,140.3,266.1064001,7.14700373,1.7977E+308,0.010467248,0
,140.5,266.0671134,7.037054457,1.7977E+308,0.016573142,0
,140.7,265.8647815,6.927115853,1.7977E+308,0.031837879,0
,140.9,265.6275113,6.817179535,1.7977E+308,0.037071503,0
,141.1,265.225532,6.707253995,1.7977E+308,0.039688316,0
,141.3,265.2336616,6.597301619,1.7977E+308,0.03837991,0
,141.5,264.7618058,6.487380651,1.7977E+308,0.033146287,0
,141.7,264.8506262,6.377422996,1.7977E+308,0.023115174,0
,141.9,264.5085411,6.267493536,1.7977E+308,0.017445415,0
,142.1,264.2920674,6.157555858,1.7977E+308,0.017009279,0
,142.3,263.9832569,6.047624221,1.7977E+308,0.022242904,0
,142.5,263.8591201,5.9376805,1.7977E+308,0.027912665,0
,142.7,263.5394954,5.827749571,1.7977E+308,0.026168124,0
,142.9,263.3779247,5.7178083,1.7977E+308,0.02180677,0
,143.1,263.0383352,5.607878677,1.7977E+308,0.015264739,0
,143.3,262.8426581,5.497939637,1.7977E+308,0.003925219,0
,143.5,262.6012285,5.388003591,1.7977E+308,0.009158844,0
,143.7,262.3756043,5.278066511,1.7977E+308,0.016573146,0
,143.9,262.0867585,5.168133568,1.7977E+308,0.023551314,0
,144.1,261.5899467,5.058214233,1.7977E+308,0.026168127,0
,144.3,261.4167299,4.948273724,1.7977E+308,0.025295856,0
,144.5,261.2202209,4.838334739,1.7977E+308,0.023115179,0
,144.7,260.8456931,4.728407402,1.7977E+308,0.018753825,0
,144.9,260.6982641,4.618465206,1.7977E+308,0.012211793,0
,145.1,260.6290303,4.508517892,1.7977E+308,0.013084064,0
,145.3,260.2495112,4.398590882,1.7977E+308,0.020934503,0
,145.5,259.9889487,4.288656088,1.7977E+308,0.029221078,0
,145.7,259.6618371,4.178725649,1.7977E+308,0.036635382,0
,145.9,259.6732941,4.068773056,1.7977E+308,0.034890841,0
,146.1,259.5258651,3.958830859,1.7977E+308,0.023987453,0
,146.3,258.8901319,3.848920614,1.7977E+308,0.013084066,0
,146.5,258.5771619,3.73898925,1.7977E+308,0.012647931,0
,146.7,258.447202,3.62904591,1.7977E+308,0.015264744,0
,146.9,258.1059486,3.519116396,1.7977E+308,0.021370642,0
,147.1,257.7463942,3.40918808,1.7977E+308,0.025731998,0
,147.3,257.7678336,3.299234833,1.7977E+308,0.032710167,0
,147.5,257.4598548,3.189303142,1.7977E+308,0.033146303,0
,147.7,256.9663703,3.079383589,1.7977E+308,0.026604271,0
,147.9,256.9561988,2.969432411,1.7977E+308,0.020934508,0
,148.1,256.6240959,2.859502299,1.7977E+308,0.011339525,0
,148.3,256.2828425,2.749572785,1.7977E+308,0.008722712,0
,148.5,255.9557308,2.639642346,1.7977E+308,0.025295866,0
,148.7,255.9621966,2.529690079,1.7977E+308,0.043613562,0
,148.9,255.4795263,2.419769819,1.7977E+308,0.063675802,0
,149.1,255.1257949,2.309841121,1.7977E+308,0.070653973,0
,149.3,254.7387889,2.199914601,1.7977E+308,0.06018672,0
,149.5,254.5081734,2.089977848,1.7977E+308,0.042741294,0
,149.7,253.9972196,1.980059438,1.7977E+308,0.019626105,0
,149.9,253.7574536,1.870123283,1.7977E+308,0.007850442,0
,150.1,253.5443072,1.760185387,1.7977E+308,0.02529587,0
,150.3,253.0316896,1.650267086,1.7977E+308,0.039688349,0
,150.5,252.9749338,1.540318956,1.7977E+308,0.046230384,0
,150.7,252.5754498,1.430393252,1.7977E+308,0.048411064,0
,150.9,252.3223739,1.320457969,1.7977E+308,0.048847201,0
,151.1,251.9195624,1.210532483,1.7977E+308,0.048411066,0
,151.3,251.6049285,1.100601227,1.7977E+308,0.042741302,0
,226.5,250.9790457,0.996468884,1.7977E+308,0.004797495,0
,226.7,250.9331041,0.886520047,1.7977E+308,0.000872272,0
,226.9,250.224998,0.776614538,1.7977E+308,0.010031125,0
,227.1,250.1541004,0.666667333,1.7977E+308,0.0170093,0
,227.3,249.7537844,0.556741684,1.7977E+308,0.018317708,0
,227.5,249.1796085,0.446827411,1.7977E+308,0.018753845,0
,227.7,248.9839312,0.336888372,1.7977E+308,0.021806796,0
,227.9,248.0180344,0.226449967,1.7977E+308,0.02049839,0
,228.1,247.5718783,0.11707708,1.7977E+308,0.021806798,0
,228.3,246.7855768,0.007176688,1.7977E+308,0.024859751,0
,228.314,246.7335304,-0.000516536,1.7977E+308,0.025295887,0
END,,,,,,