File: GB1_test 12.csv
Segment,Time On Sample,Displacement Into Surface,Load On Sample,Harmonic Contact Stiffness,Harmonic Displacement,Harmonic Load
Surface Marker,0,0,0,367.736749,0.366842906,2.254016748
,0.3,0.168161078,0.000972925,9524.455144,0.186256741,2.383318646
,0.6,0.2606116,0.001950808,18033.88278,0.14394549,2.520290983
,0.9,0.576865846,0.002914036,20166.23607,0.136093916,2.644113999
,1.2,0.669316367,0.003891919,21632.17699,0.13173193,2.778894787
,1.5,0.756774982,0.004870128,23785.49174,0.133912922,3.262133198
,1.8,0.671180906,0.005859669,24595.94857,0.139147304,3.678529095
,2.09,0.787561493,0.006803186,26026.23638,0.142200692,4.08177568
,2.4,0.712148924,0.007823436,32218.71586,0.138711105,4.813755841
,2.7,0.946036961,0.008790658,37789.00251,0.14525408,5.58956719
,3,1.338001968,0.009747531,41448.00834,0.154850442,6.359899688
,3.3,1.194169233,0.010739485,42248.57724,0.177532762,7.331855388
,3.6,1.251676642,0.011718257,43395.10805,0.205013263,8.671992771
,3.9,1.154435014,0.012707161,42660.69064,0.235983353,9.813794164
,4.2,1.231078056,0.01368468,41435.22301,0.271315425,10.97312807
,4.5,1.287753481,0.014663506,42014.98726,0.306211299,12.60364679
,4.8,1.08568186,0.015659274,42125.72115,0.346341559,14.34155178
,5.1,0.923545472,0.016652427,42683.22123,0.377311651,15.79674585
,5.4,0.706498132,0.017649175,41929.47038,0.422240096,17.35165574
,5.7,0.588456898,0.018639441,39347.35906,0.497266232,19.14325382
,6,0.594381294,0.019621589,34905.27319,0.599772868,20.5074983
,6.3,0.623185254,0.02060224,29497.14303,0.750261332,21.77531427
,6.6,1.279305214,0.021541816,25285.7766,0.902494557,22.60810647
,6.9,0.635450039,0.02256651,20678.15353,1.12190241,23.25132816
,7.2,1.191731911,0.023512624,17763.57303,1.310776297,23.56800859
,7.5,1.175192737,0.024496244,15807.8525,1.480021292,23.84962367
,7.8,1.560917861,0.025453525,15562.98208,1.53541846,24.30327635
,8.1,1.547706624,0.026436927,17076.33769,1.461264729,25.19962329
,8.4,1.982102806,0.027391021,19330.34827,1.352215089,26.20006963
,8.7,1.226345798,0.028423043,21849.82939,1.253198104,27.34296623
,9,1.833378419,0.029367471,22642.82249,1.245782687,28.28424066
,9.3,1.210739117,0.030389139,21945.55028,1.305105719,28.92527069
,9.6,1.411347527,0.031360178,20679.88459,1.398452169,29.42165863
,9.9,1.66853137,0.032324239,19996.99884,1.462137119,29.80956444
,10.2,1.779701749,0.033299497,19604.45083,1.512736127,30.282941
,10.5,1.920407562,0.034272822,19830.54856,1.526258266,30.79795711
,10.8,2.318196439,0.035229313,20519.42748,1.505320709,31.33488904
,11.1,2.415639078,0.036205471,21877.18569,1.45341309,32.0679651
,11.4,2.50559386,0.037182118,23960.03363,1.370099188,32.90075699
,11.7,2.260259082,0.03818072,26068.79233,1.302488454,33.81463624
,12,2.468355596,0.039149632,27499.83431,1.272826947,34.67920588
,12.3,1.973425606,0.040164576,27530.08746,1.298998889,35.3629713
,12.6,2.810502042,0.041092304,26900.17383,1.354396024,35.97770401
,12.9,2.211574057,0.042114058,26533.44204,1.39845211,36.56284924
,13.2,2.725008706,0.043062978,26704.41405,1.414155212,37.12827163
,13.5,2.369020056,0.044068824,27377.14719,1.408484662,37.86134728
,13.8,2.681114571,0.045030927,28619.48409,1.376205956,38.65140401
,14.1,2.5031705,0.046025116,29837.22105,1.348725471,39.438173
,14.4,2.660515988,0.046997351,30886.00325,1.330405128,40.20302671
,14.7,2.574922142,0.047985493,31390.83346,1.335203312,40.96788018
,15,2.906152287,0.048946343,31650.42359,1.351342631,41.78861885
,15.3,2.442005716,0.049959272,31965.58318,1.360502833,42.48662936
,15.6,3.144300727,0.050895826,32824.3037,1.351342618,43.30079381
,15.9,2.395615627,0.051927385,33315.75619,1.355704654,44.07660425
,16.2,2.958969313,0.052873036,33339.86628,1.374024949,44.7077735
,16.5,2.720290412,0.053871202,33056.16828,1.406303646,45.42331672
,16.8,2.826884873,0.054846761,32706.20917,1.439018521,46.04243185
,17.1,2.778730309,0.055832452,32526.45828,1.466499019,46.74153863
,17.4,3.142407826,0.056791177,32378.14975,1.489181312,47.29929048
,17.7,2.486904936,0.057816635,32167.64873,1.515353269,47.85704099
,18,3.210831531,0.058751773,32488.11459,1.519278992,48.48273162
,18.3,2.73503719,0.059765464,32918.83036,1.521023828,49.15553907
,18.6,2.980572981,0.060731925,33809.7664,1.501831078,49.8864238
,18.9,2.950722065,0.061716418,34136.65088,1.504884469,50.54060377
,19.2,3.218721421,0.062681408,34116.76167,1.521459986,51.15862337
,19.5,3.095688298,0.063672002,33700.65468,1.553738678,51.64953206
,19.8,3.425254467,0.064632961,33434.27827,1.582963941,52.15906969
,20.1,3.396235536,0.065617399,33404.79073,1.602156673,52.67956451
,20.4,3.69252234,0.066580538,33768.69286,1.604773837,53.27566861
,20.7,3.34984545,0.067585514,34522.39819,1.586889735,53.83999414
,21,3.94731045,0.068528932,35774.84696,1.55243001,54.57745411
,21.3,3.865876531,0.069516802,37617.35461,1.501394808,55.48585456
,21.6,3.972470986,0.070492361,39251.61396,1.463009342,56.37672298
,21.9,3.697184803,0.071492925,40278.24295,1.447742423,57.23362149
,22.2,3.884480866,0.07246847,40474.71652,1.460828359,58.0171037
,22.5,4.06262284,0.073458857,39778.92353,1.502703388,58.6767627
,22.8,4.372215874,0.074455743,39729.95086,1.521023693,59.35285886
,23.1,4.151832716,0.075502549,40339.22483,1.516225531,60.11990355
,23.4,4.440621273,0.07653148,42002.68319,1.47784005,60.99981448
,23.7,4.189033737,0.077611656,43569.50084,1.448614781,61.96190774
,24,4.589303072,0.078665176,44579.5597,1.439018385,62.90646976
,24.3,4.556938202,0.079763105,44534.49724,1.460828306,63.77980537
,24.6,4.832820735,0.08085747,44231.53866,1.487436383,64.53370178
,24.9,4.850785599,0.081985409,44187.74552,1.506629109,65.29307645
,25.2,4.999369233,0.083121812,44759.63213,1.504448105,66.03163168
,25.5,4.506906515,0.084317425,45861.71189,1.492670793,67.12193061
,25.8,4.964150639,0.085468517,46564.00235,1.486563977,67.92404166
,26.1,4.911801786,0.086670738,46899.18906,1.492670759,68.80723913
,26.4,5.136084732,0.087872789,46935.61605,1.508373881,69.71235291
,26.7,4.537532644,0.089147205,47344.87659,1.513172115,70.58349585
,27,5.253096208,0.090354122,47821.47419,1.516225442,71.44149216
,27.3,4.899973098,0.091651997,48246.84144,1.521896052,72.26332546
,27.6,5.405870976,0.092908698,48365.91013,1.537599148,73.0840648
,27.9,4.969127634,0.094248859,48328.02997,1.556355716,73.85549229
,28.2,5.298638323,0.095558643,48162.48272,1.578165605,74.60171826
,28.5,4.938431161,0.096933668,47962.10878,1.59866696,75.33808094
,28.8,5.50837877,0.098268137,48165.71372,1.60608228,76.08211596
,29.1,5.219715719,0.09967942,48841.54486,1.600411729,76.88751277
,29.4,5.692314594,0.101061862,49636.09753,1.592996315,77.67866602
,29.7,4.98432494,0.102542859,50572.43622,1.584708611,78.56953282
,30,5.367894684,0.103974284,50726.19581,1.59692213,79.3332913
,30.3,5.157424441,0.105466493,50718.87098,1.613497687,80.13211369
,30.6,5.651641027,0.106934785,50675.65434,1.628328386,80.82683845
,30.9,5.570121186,0.108463246,51384.07309,1.621785419,81.65195966
,31.2,5.805583556,0.109993902,52265.69663,1.609571844,82.43215489
,31.5,5.546011816,0.111580246,53273.63562,1.597358315,83.38219445
,31.8,6.29147283,0.113124494,54487.68259,1.579474116,84.34209839
,32.1,5.8754806,0.114768444,55929.64048,1.557664237,85.39294942
,32.4,6.61927001,0.116360752,57546.1274,1.532800871,86.47010174
,32.7,6.460352998,0.118036942,58723.42676,1.521023529,87.58231689
,33,6.670832835,0.119713973,59096.87144,1.528875079,88.60796633
,33.3,6.375462424,0.121449734,58897.6464,1.551121216,89.60402864
,33.6,6.667468486,0.123172964,58671.80601,1.572494915,90.4675031
,33.9,6.626676841,0.124944213,59196.37307,1.575984504,91.44055462
,34.2,6.878739276,0.126722902,59720.69516,1.577729276,92.29087965
,34.5,6.59583178,0.128563816,60591.31991,1.573803515,93.35707174
,34.8,7.000138578,0.130387136,61338.94555,1.572058688,94.38381758
,35.1,6.620712173,0.132289638,62143.31156,1.568132936,95.41604026
,35.4,7.253805593,0.13415414,63044.20412,1.564207092,96.60496201
,35.7,6.949248704,0.136108574,64142.89405,1.555046958,97.76867825
,36,7.169668923,0.138058103,64696.47767,1.558100327,98.84363809
,36.3,7.063946796,0.140058477,65685.6337,1.551121165,99.94818275
,36.6,7.556416284,0.142049545,65940.90689,1.560281285,101.0308137
,36.9,7.422397112,0.14411215,66056.08713,1.572058652,102.0466004
,37.2,7.712684784,0.146177763,66052.05354,1.587761765,103.1204645
,37.5,7.434722497,0.148312189,66217.8169,1.598230549,104.005853
,37.8,7.857285482,0.150432748,66312.68004,1.611752658,104.9624692
,38.1,7.588464797,0.15263088,66243.06996,1.63050921,105.980447
,38.4,7.891211747,0.154824498,65956.39329,1.650138105,106.7595465
,38.7,7.385265121,0.157104575,66281.64379,1.656681128,107.6756163
,39,7.924284766,0.159350066,66881.3526,1.656244879,108.5862101
,39.3,7.787728104,0.161674179,67579.25627,1.654063901,109.5066641
,39.6,8.091285328,0.164004296,68201.93032,1.654063873,110.4906743
,39.9,8.090330849,0.166389831,68735.55076,1.655372468,111.4823543
,40.2,8.599376716,0.168777838,69078.34954,1.658425808,112.3414465
,40.5,8.105876359,0.171267895,69960.37292,1.651882882,113.4427027
,40.8,8.807930772,0.173716768,70715.61931,1.648829428,114.5165682
,41.1,8.321906408,0.176280991,71408.88379,1.647957078,115.5487904
,41.4,8.872111755,0.178815461,71835.88571,1.653191406,116.5021198
,41.7,8.600726966,0.181442601,72162.55896,1.660606802,117.4751707
,42,8.896748842,0.184071925,72435.48772,1.668894542,118.4427443
,42.3,8.857058919,0.186763215,73020.1885,1.668458348,119.3796352
,42.6,9.232938459,0.189467645,73236.39743,1.676746079,120.3559754
,42.9,8.775163707,0.192268108,73486.50806,1.681980503,121.1701376
,43.2,9.035800285,0.19506323,73269.03639,1.699428408,122.0336123
,43.5,9.344684419,0.19790235,73425.45625,1.70902474,122.9453014
,43.8,9.631098928,0.20078106,73973.04883,1.707716118,123.7474125
,44.1,9.967841512,0.203700101,74772.9953,1.702481707,124.7401895
,44.4,11.0571072,0.206608295,75483.76988,1.698119619,125.6803716
,44.7,11.11886519,0.209633267,76269.42942,1.693321434,126.7093082
,45,11.48678421,0.21269448,77398.37377,1.682416444,127.80728
,45.3,11.01730762,0.215836216,78970.11452,1.664532363,128.9468886
,45.6,11.72424676,0.218958304,80594.4324,1.648392963,130.2190906
,45.9,11.57423518,0.222184192,82156.8235,1.634434635,131.5055346
,46.2,11.65800328,0.225443369,83230.1179,1.627891655,132.6473366
,46.5,11.54042348,0.22876517,84214.62974,1.625274478,134.0104854
,46.8,11.68740654,0.232119547,85156.25611,1.622221077,135.3035049
,47.1,11.4641488,0.235549095,85716.81758,1.623965891,136.3718888
,47.4,11.92394143,0.238985345,86678.62142,1.622221056,137.7920198
,47.7,11.51180691,0.242531032,87304.35929,1.623965888,138.9414904
,48,12.10054026,0.246064138,87380.50174,1.637051779,140.1391792
,48.3,12.07110121,0.249691663,86807.29728,1.66147888,141.2524908
,48.6,12.2629611,0.253359415,86325.66345,1.682852574,142.2397879
,48.9,12.26844786,0.257094752,85922.37016,1.700300501,143.0660059
,49.2,12.71487701,0.260857295,86062.95171,1.708588223,144.099327
,49.5,12.69455427,0.264707609,86757.54353,1.705534838,145.1184018
,49.8,13.18339631,0.268582215,87655.13093,1.699864216,146.2974615
,50.1,13.10065628,0.272553204,89570.28628,1.678054316,147.6606106
,50.4,13.75088427,0.276535787,90909.62698,1.668021696,148.9229505
,50.7,13.69058867,0.28062561,92047.80897,1.663223525,150.2477472
,51,13.79917593,0.28476599,92724.61018,1.666276899,151.5067977
,51.3,13.79293951,0.288976519,92900.87714,1.674564666,152.577374
,51.6,14.10950259,0.293229485,94312.25635,1.664095882,153.9744935
,51.9,14.15649278,0.297564452,95317.34746,1.660170093,155.3244935
,52.2,14.96889742,0.301914415,95998.13502,1.660606214,156.5046511
,52.5,14.81036683,0.306394087,95982.25382,1.675436967,157.7976699
,52.8,15.49129682,0.310886256,95575.70616,1.693321026,158.7301807
,53.1,14.84769829,0.315533505,95743.51512,1.703789842,159.8456812
,53.4,15.49116713,0.320165894,96197.56952,1.709896553,161.045562
,53.7,15.16286809,0.324932419,97220.3203,1.70422601,162.1194241
,54,16.17072308,0.329682992,98699.1256,1.693757159,163.4891525
,54.3,15.97302257,0.334584884,100234.478,1.68197983,164.8040867
,54.6,16.48582418,0.339513958,101425.6146,1.677181602,166.2110693
,54.9,16.13751105,0.344574355,101633.4247,1.686777994,167.4624473
,55.2,16.91985137,0.349636082,101718.5896,1.695938078,168.5461764
,55.5,16.42425296,0.354858551,102235.5901,1.69986391,169.8786418
,55.8,17.0401719,0.360086557,103371.3145,1.694193275,171.2757629
,56.1,17.00962714,0.365436269,104856.3048,1.683724525,172.7167126
,56.4,17.36094991,0.370841704,106004.5182,1.678926313,174.0875339
,56.7,17.63738118,0.376333742,106629.2348,1.681543476,175.4594508
,57,18.1467546,0.381893415,106911.8881,1.6876502,176.5957762
,57.3,17.75258074,0.38759654,106712.7396,1.703789566,177.9019433
,57.6,18.35344531,0.393320166,107012.5585,1.711204874,179.127027
,57.9,18.11232892,0.399186014,107539.0349,1.714258285,180.2096557
,58.2,18.90036191,0.40507233,108630.9962,1.710332426,181.6056826
,58.5,18.51154025,0.411125514,109230.1833,1.712949652,182.8773324
,58.8,19.03622177,0.417209893,109291.0697,1.722545958,184.0054396
,59.1,18.9639406,0.423425746,109368.7449,1.732142322,185.1505286
,59.4,19.50232028,0.429695181,109670.428,1.738249041,186.2463103
,59.7,18.93456307,0.436132265,110892.7524,1.732142326,187.5831583
,60,19.64596477,0.442582174,111851.408,1.729961266,188.9079591
,60.3,19.78328246,0.44916756,112740.1475,1.727344064,190.1330411
,60.6,20.96181142,0.455783648,113677.7311,1.724726761,191.4983879
,60.9,20.72928082,0.462593041,114190.8673,1.727343972,192.80346
,61.2,20.98178011,0.469473225,114118.0525,1.737376501,193.8378768
,61.5,20.76086444,0.476488412,114076.1231,1.74871767,195.0322754
,61.8,21.28538891,0.483560408,114990.0136,1.745228035,196.1631221
,62.1,21.02908014,0.490790656,117469.0901,1.722109569,197.7717251
,62.4,21.76031418,0.498089672,119945.16,1.7002996,199.4219721
,62.7,21.56553725,0.505535585,121379.6168,1.692884254,201.0075643
,63,22.31837532,0.513006285,121329.3595,1.705970119,202.398112
,63.3,21.91223884,0.520691444,120907.2559,1.722981879,203.5486785
,63.6,22.70580366,0.52841368,121019.1282,1.733450552,204.8252653
,63.9,22.42609161,0.536323457,121776.8847,1.734759174,206.1412949
,64.2,23.04573441,0.544293144,122014.8022,1.740865884,207.2743339
,64.5,23.14703252,0.552417681,121604.5658,1.756132801,208.4336699
,64.8,23.76330867,0.560631005,121068.9654,1.772272062,209.4812373
,65.1,23.66988352,0.569015045,120812.7604,1.784049415,210.48278
,65.4,24.58729768,0.577459216,121025.2554,1.789283696,211.4821355
,65.7,24.36986663,0.586105734,121771.5007,1.787538928,212.6173624
,66,24.74728272,0.594843622,124158.5601,1.765292798,214.1076239
,66.3,24.74446159,0.603738469,126711.3629,1.742174311,215.659248
,66.6,25.86396422,0.612693654,128872.1185,1.726471078,217.3226475
,66.9,25.33861486,0.621892718,128736.0046,1.739120868,218.6233348
,67.2,25.8998133,0.63115876,127962.8725,1.75787732,219.5887194
,67.5,27.05086536,0.640526119,127942.0594,1.767909756,220.8149043
,67.8,27.60785908,0.650073967,129197.1758,1.761366729,222.2021642
,68.1,27.4210371,0.659815203,130792.0648,1.750025609,223.5236735
,68.4,28.09529407,0.669646785,132663.964,1.738248203,225.2232312
,68.7,27.89760931,0.679684468,134470.2534,1.726907077,226.7058196
,69,28.40625393,0.68982723,136012.6092,1.719927861,228.3703119
,69.3,27.99886101,0.7001837,137879.9524,1.709022958,230.0205532
,69.6,28.46252937,0.710638891,139605.2229,1.70160755,231.8362628
,69.9,28.63747452,0.721271246,141574.8537,1.693319779,233.7385371
,70.2,29.3223996,0.732030773,143112.6828,1.688957732,235.4260421
,70.5,29.71277688,0.742972384,144280.2333,1.689830092,237.332701
,70.8,30.33774708,0.754063535,144122.2771,1.702915964,238.9566502
,71.1,29.75964349,0.765401486,143829.4942,1.716438152,240.4677265
,71.4,30.71735296,0.776809438,143838.7234,1.726470605,241.8801928
,71.7,30.96285772,0.788436833,145482.6284,1.720363813,243.6630283
,72,31.63763765,0.800211592,148041.8226,1.705096827,245.6496807
,72.3,31.75662478,0.812201099,150789.8565,1.688085106,247.6692035
,72.6,33.01789542,0.824296146,152484.3148,1.682414414,249.7040748
,72.9,32.94047683,0.836662237,152653.8453,1.690702178,251.2973386
,73.2,34.17672911,0.84912877,151435.123,1.713820534,252.8467783
,73.5,33.83218444,0.861887815,150389.0658,1.73563045,254.3381335
,73.8,34.47267657,0.874774616,149947.9809,1.748716316,255.546782
,74.1,34.43673585,0.887900828,150419.381,1.753950692,257.044713
,74.4,34.95652801,0.90118861,150720.3477,1.760493604,258.4538889
,74.7,35.25747685,0.914691435,151372.9715,1.763983155,259.9529182
,75,35.83377943,0.928380397,152575.3364,1.761802109,261.5385153
,75.3,35.8825722,0.942310913,154951.3234,1.746971386,263.2972422
,75.6,36.30322771,0.956427378,158765.204,1.720363292,265.5457845
,75.9,36.73799298,0.970756368,161318.3285,1.706841124,267.6858464
,76.2,37.15275619,0.985303508,163068.2647,1.701170516,269.5694947
,76.5,37.25341107,1.000091177,164175.9459,1.702915297,271.6142207
,76.8,38.35407335,1.015036278,165180.39,1.705096177,273.6008776
,77.1,38.51955145,1.03026886,165339.4041,1.712947717,275.1733233
,77.4,39.39924985,1.045684467,165719.0247,1.720799187,277.1676485
,77.7,39.44152093,1.061388291,166241.121,1.725161158,278.7488602
,78,40.09151739,1.077289455,167989.8121,1.720799119,280.7859194
,78.3,40.11416095,1.09347229,169959.1124,1.714256155,282.8065381
,78.6,40.96583604,1.109844911,171929.287,1.708585504,284.9476979
,78.9,41.33242609,1.126496922,172602.1846,1.713819838,286.931063
,79.2,42.01554541,1.143379573,172238.0478,1.726469498,288.5210448
,79.5,42.4203261,1.160535664,172595.8812,1.733448617,290.4397591
,79.8,43.02972854,1.177966759,173636.7017,1.733884754,292.3869641
,80.1,42.71850087,1.195721478,175793.8844,1.723852244,294.2969075
,80.4,43.5928194,1.21357687,178286.428,1.71512821,296.7613223
,80.7,43.99368754,1.23179385,179655.0456,1.713819579,298.5836086
,81,44.48935789,1.2502798,180751.0207,1.716872912,300.678743
,81.3,44.68297432,1.269064882,181186.8505,1.725160644,302.7738774
,81.6,45.89405977,1.288066519,181206.9086,1.733884471,304.3890662
,81.9,46.1774395,1.307416602,181355.2922,1.742172193,306.2080648
,82.2,47.24366785,1.327007376,182580.6092,1.7399911,308.0172053
,82.5,47.48369097,1.346948716,184153.869,1.737373893,310.208769
,82.8,48.65049407,1.367130373,186170.0669,1.730830818,312.3893798
,83.1,48.92120414,1.387675893,186827.074,1.735628961,314.3913735
,83.4,50.05047016,1.408475303,187938.6606,1.736065047,316.3769358
,83.7,50.31775297,1.429645848,188809.4083,1.738682204,318.394271
,84,50.85454704,1.451118479,190054.9008,1.739118348,320.4762569
,84.3,50.82554198,1.472952285,190720.6819,1.743480323,322.3182643
,84.6,51.49618123,1.495069551,190789.3655,1.753512792,324.2030115
,84.9,52.15595159,1.517521627,190945.3385,1.761800473,325.9562664
,85.2,53.01534367,1.540299501,192291.1601,1.759619401,327.7303412
,85.5,53.6051189,1.563439474,195342.3596,1.746533428,330.1629796
,85.8,54.21147817,1.586927939,197672.1812,1.739118011,332.4531659
,86.1,54.99416114,1.610759512,199531.3311,1.733883572,334.4398235
,86.4,55.38825145,1.634976691,200848.9858,1.734755923,336.8165741
,86.7,55.61588725,1.659570849,202557.4021,1.731702527,339.1166191
,87,56.48159383,1.684494596,203924.8635,1.730393845,341.1405336
,87.3,56.52940267,1.709848769,204056.4739,1.739117787,343.1206091
,87.6,57.41412405,1.73553084,205695.018,1.737809102,345.4151817
,87.9,57.87530515,1.761628748,208862.7711,1.725159349,348.0176646
,88.2,59.07605503,1.788072457,213006.29,1.705530361,350.6563155
,88.5,59.3831933,1.814974545,217506.7303,1.686773862,353.903116
,88.8,60.70861219,1.842215875,219339.3075,1.685901338,356.6776438
,89.1,60.74356252,1.869953783,220126.8446,1.692008092,359.2406768
,89.4,61.77016801,1.898045292,219058.3022,1.709455871,361.3960861
,89.7,62.2218069,1.926599214,217541.5919,1.73039328,363.4967025
,90,63.14677452,1.955553389,215856.854,1.752203035,365.3759744
,90.3,63.74803187,1.984966372,216206.9967,1.759182125,367.3242805
,90.6,64.9316054,2.014785264,217980.1533,1.757001021,369.614472
,90.9,64.88377515,2.045135876,220467.8667,1.748277089,371.8323333
,91.2,65.9881659,2.075869005,222955.417,1.741297829,374.4172898
,91.5,66.20392697,2.107125073,224761.9279,1.739989217,377.0066228
,91.8,67.36973538,2.138790587,225611.1663,1.744351069,379.2661336
,92.1,68.01963944,2.170968583,227988.8415,1.737808052,381.5661856
,92.4,69.26017266,2.203593926,230604.7289,1.731701174,384.4338557
,92.7,69.25348802,2.236794488,231997.3529,1.733009765,386.9694937
,93,70.56291751,2.270409616,232134.805,1.740861176,389.0054672
,93.3,71.12389939,2.304582059,232578.3309,1.748712661,391.4381076
,93.6,72.12117283,2.339243885,235837.2353,1.737807644,394.2345508
,93.9,72.98233415,2.37443814,240028.7444,1.720359691,396.9586723
,94.2,74.17994709,2.410142093,242903.9211,1.71163564,399.6729333
,94.5,74.94775615,2.446413986,245762.7943,1.704656419,402.9624773
,94.8,75.77662865,2.483229818,246903.8845,1.708145911,405.8597302
,95.1,76.61706042,2.520601174,249045.069,1.706401042,408.8632769
,95.4,77.88420841,2.558509076,250701.2888,1.707709508,411.6246582
,95.7,78.67204448,2.597021417,251397.9632,1.715997165,414.4528795
,96,79.58791305,2.636107011,251659.4822,1.726029594,417.1024874
,96.3,80.25700548,2.675799569,252016.4529,1.734753458,419.4869164
,96.6,81.05662345,2.716083394,253087.541,1.739115343,422.1847368
,96.9,81.96471811,2.756968517,253754.5308,1.745222003,424.7620266
,97.2,82.67179128,2.798484578,254610.7046,1.748275307,427.0796106
,97.5,83.36919716,2.840627179,255996.8782,1.750020023,429.8475643
,97.8,85.16804374,2.88333316,257891.8099,1.748711253,432.6231971
,98.1,85.98669152,2.926896496,258232.6508,1.755254116,434.7621744
,98.4,87.00662048,2.970811233,258143.9314,1.765722726,437.2528958
,98.7,87.627878,3.015714325,257701.6335,1.777063767,439.4335099
,99,88.77239131,3.060958108,258718.5015,1.778372239,441.4705795
,99.3,89.65719384,3.107055369,261428.4428,1.771829204,444.2582599
,99.6,91.03857765,3.153816238,265077.8123,1.760051766,447.1642872
,99.9,92.02382662,3.201309869,268102.05,1.752200135,450.1338697
,100.2,93.18284525,3.2495096,271378.9589,1.74173131,452.9620935
,100.5,93.94322974,3.298463791,273323.8472,1.739986449,456.0850828
,100.8,95.51134895,3.34810436,274414.5856,1.743912058,458.8815355
,101.1,96.11425238,3.398558623,275271.6484,1.750018743,461.5793602
,101.4,97.60475687,3.449716797,276163.9319,1.755252946,464.0887162
,101.7,98.63505383,3.501677278,277966.5347,1.755689038,466.9794039
,102,100.2575954,3.554383306,279328.1969,1.756561266,469.4372618
,102.3,101.1270689,3.607934928,282517.3835,1.749582043,472.7421525
,102.6,102.5688157,3.662257253,285599.5299,1.741730371,475.5758612
,102.9,103.2732983,3.717448878,289566.6544,1.730825402,479.0319684
,103.2,104.6032967,3.773433027,294354.7294,1.717303192,482.8321547
,103.5,105.3166638,3.830304489,298057.582,1.70857921,486.1469072
,103.8,106.8602097,3.887979686,301489.8942,1.702908508,489.9766849
,104.1,107.8278873,3.946564421,303166.6157,1.705089401,493.4273155
,104.4,109.2713163,4.006002728,304383.341,1.709015014,496.7135855
,104.7,110.4550249,4.066356147,305357.3857,1.715557839,500.1258671
,105,112.1103206,4.127590329,305586.5702,1.725590171,503.2674974
,105.3,113.8578187,4.189743549,306148.8606,1.733441526,506.229421
,105.6,114.8430748,4.252885982,308455.4676,1.73300522,509.6022524
,105.9,115.9746075,4.316972606,312713.6544,1.722972622,513.4024411
,106.2,117.5502628,4.381998378,316527.1743,1.714684745,516.930881
,106.5,118.8936397,4.448021875,317934.837,1.719046574,520.5919104
,106.8,120.2684732,4.515040798,318300.554,1.728206537,523.9329695
,107.1,121.3061944,4.583094527,318711.137,1.736930343,527.1513
,107.4,122.8812101,4.652141065,321173.6094,1.735185404,530.451817
,107.7,123.9227617,4.722265746,323379.4537,1.735621495,533.9375197
,108,125.6796462,4.793402735,325357.5131,1.736929906,537.3235101
,108.3,127.0769451,4.865638224,326698.5555,1.740855524,540.5002072
,108.6,128.6271543,4.938955069,329874.6533,1.736929611,544.2116442
,108.9,129.9899923,5.013391895,332723.5237,1.734312303,547.9252748
,109.2,132.1172392,5.088903078,334821.9196,1.734312091,551.1753967
,109.5,133.4189824,5.165609577,336994.4929,1.735620546,554.9646352
,109.8,134.7604762,5.243472307,339159.7948,1.736492802,558.5106067
,110.1,136.5086201,5.322484604,342546.0784,1.732130677,562.4401126
,110.4,137.9395905,5.402711629,345166.0316,1.730821948,566.0814195
,110.7,138.8736775,5.484183342,346365.8296,1.736056195,569.581368
,111,140.7364712,5.566827929,346650.8633,1.745216103,572.9322987
,111.3,141.9634354,5.650764172,345992.805,1.757429438,575.9128514
,111.6,143.77175,5.735930234,346474.1471,1.763535984,579.1377667
,111.9,145.3132112,5.822400705,347626.5186,1.765934899,582.2826921
,112.2,146.9393262,5.91017204,352198.3399,1.753503181,586.0785093
,112.5,148.6380283,5.999264677,360713.5547,1.727767517,590.9361462
,112.8,150.6430999,6.0896832,369056.9875,1.705521386,595.8891168
,113.1,152.2290536,6.181495425,375861.4809,1.690254416,600.3730909
,113.4,153.8796808,6.274690838,380082.6351,1.688509476,605.543022
,113.7,155.3932239,6.369303092,382394.2696,1.690690302,609.5174571
,114,157.1777641,6.465327241,381164.0258,1.707265521,613.5061367
,114.3,158.9163147,6.562805261,378998.0856,1.726021714,616.8789907
,114.6,161.1733684,6.661721815,376714.4475,1.744777851,620.3110209
,114.9,162.844473,6.762170323,377920.9851,1.749139627,624.0904096
,115.2,164.4766499,6.864135647,380298.9119,1.747394685,627.6528284
,115.5,166.0486795,6.967645204,384086.4356,1.742596388,632.0984543
,115.8,168.1628522,7.073038928,387384.2599,1.740851398,636.3117758
,116.1,170.0023323,7.179333322,389900.7947,1.740851213,639.8511951
,116.4,172.1643066,7.287571114,392975.0059,1.741723384,644.3603795
,116.7,174.0597884,7.397461778,395599.0877,1.742159388,648.4707043
,117,176.0431954,7.50900732,396695.8077,1.746957323,651.7843867
,117.3,177.8532834,7.622249377,397829.5332,1.753500051,655.9516913
,117.6,179.8918926,7.737187449,400421.1686,1.753499844,659.9349
,117.9,181.8012692,7.853870773,402352.055,1.756116819,663.8863352
,118.2,183.7444763,7.972314711,406745.7724,1.748265127,667.7983184
,118.5,185.7215098,8.092545973,408744.8989,1.751318284,672.1409526
,118.8,187.979462,8.214575156,412723.8996,1.746956118,676.4923525
,119.1,190.0848693,8.33845826,418359.0608,1.736051062,680.7506134
,119.4,192.1958028,8.464211925,426953.119,1.717730715,686.5024229
,119.7,194.316418,8.591863089,433667.525,1.704208502,691.3567936
,120,196.6655195,8.721427551,436089.946,1.706389238,696.316356
,120.3,198.5716993,8.852976261,434693.2991,1.722092017,701.0447084
,120.6,201.6606311,8.986433917,432850.1588,1.736922286,704.4219733
,120.9,203.5378869,9.121987898,432211.8275,1.749135515,708.363554
,121.2,206.0704128,9.259546597,432760.1374,1.75742293,712.5253906
,121.5,207.5917592,9.399250049,433992.0868,1.763093288,716.6707783
,121.8,210.1984963,9.54099249,437833.4481,1.758294896,720.5762086
,122.1,212.5785957,9.684891612,444599.5084,1.745645054,725.628922
,122.4,214.8185776,9.830973891,450665.5829,1.736920958,731.09584
,122.7,217.1996439,9.979253656,454128.5087,1.734739766,735.3727388
,123,219.603649,10.12977229,452381.0689,1.750442459,739.4480142
,123.3,222.1270965,10.28255729,452009.7665,1.760474648,743.1551087
,123.6,224.6709761,10.43764929,453918.5469,1.763527737,747.3717443
,123.9,226.7327702,10.59511606,457409.155,1.761346567,751.9729913
,124.2,229.8391443,10.75489321,466413.0315,1.74302615,757.7522268
,124.5,232.3186584,10.9171257,471412.8956,1.736046817,762.4181408
,124.8,235.1571949,11.08178555,482187.2876,1.714236902,768.6280156
,125.1,237.701649,11.24895238,488187.994,1.707693761,774.388621
,125.4,240.407104,11.41863443,495899.4378,1.695916297,780.2982503
,125.7,242.7951695,11.59090077,497766.4385,1.702458948,786.0259796
,126,245.5613685,11.76574493,497639.0063,1.714235868,791.2145832
,126.3,248.4527749,11.9432223,491731.0241,1.742151885,794.9468997
,126.6,251.1948316,12.12339107,488218.0409,1.763088833,798.9027465
End Of Loading Marker,126.822,253.3492862,12.25845785,485953.1586,1.776610569,801.530489
,127.2,256.0612018,12.26134328,485889.1134,1.786206518,806.1405226
,127.5,257.1887804,12.26126985,488226.7618,1.786642595,810.5773933
,127.8,258.0692634,12.2612126,492699.2612,1.780972009,815.294771
,128.1,258.6094698,12.26117763,498816.4143,1.770939538,820.3091069
,128.4,259.3880361,12.26112705,505681.5112,1.759598468,825.3672705
,128.7,259.4161639,12.2611256,511495.6482,1.753055586,830.8549737
,129,260.1161088,12.26108017,515608.9058,1.75174694,836.0172367
,129.3,260.3717809,12.26106383,516556.2909,1.758725986,840.457374
,129.6,260.6586518,12.26104544,518904.3387,1.761343109,845.3380099
,129.9,260.9555065,12.2610264,518503.6133,1.770939302,849.4450285
,130.2,261.4794894,12.26099249,520527.5677,1.773556401,854.0287126
,130.5,261.5055372,12.26099119,519669.0176,1.785769773,858.2299629
,130.8,261.855222,12.26096869,520686.9022,1.792312617,862.3424548
,131.1,261.7855931,12.26097364,522879.1517,1.793621201,866.0977185
,131.4,262.2937685,12.26094077,527062.3923,1.790567805,871.1624519
,131.7,262.4246448,12.2609326,528535.6,1.792748752,874.8738895
,132,262.6990361,12.26091503,527097.5439,1.804525906,878.6324398
,132.3,262.8353202,12.2609065,522963.0869,1.823718336,881.5012171
,132.6,263.0260984,12.26089441,522846.4288,1.831133579,884.9376034
,132.9,262.9514777,12.2608997,520025.4601,1.845964112,887.7220002
,133.2,263.0856818,12.26089131,519477.7481,1.85337936,890.3485994
,133.5,263.1649758,12.26088651,517155.3693,1.866901301,892.8480958
,133.8,263.4905334,12.26086559,517893.7469,1.870826994,895.4462084
,134.1,263.5224051,12.26086391,520821.8418,1.86820984,898.5045559
,134.4,263.693216,12.26085312,521346.4591,1.872571741,901.0171926
,134.7,263.8715146,12.26084184,520371.9675,1.880859368,903.3380786
,135,263.9949031,12.26083416,515644.0512,1.899179414,904.7779397
,135.3,263.901147,12.2608407,513285.6344,1.908775646,906.2134235
,135.6,264.010392,12.26083394,513419.0907,1.910956594,908.0685869
,135.9,263.9981692,12.26083514,513643.1174,1.914009939,909.851437
,136.2,263.9493395,12.26083874,514998.2401,1.914009945,911.622222
,136.5,264.3065121,12.26081575,515444.0299,1.91706325,913.4390503
,136.8,264.4382203,12.26080752,517029.9778,1.91575466,915.3380475
,137.6,264.5055129,12.11742638,1.7977E+308,1.969842448,0
,137.9,264.0274861,11.93364038,1.7977E+308,1.894381312,0
,138.2,263.6759189,11.74984609,1.7977E+308,1.652731052,0
,138.5,263.0672725,11.56606865,1.7977E+308,1.13846086,0
,138.8,262.9112187,11.38226156,1.7977E+308,0.57446474,0
,139.1,262.6195534,11.19846336,1.7977E+308,0.194105402,0
,139.4,262.3162406,11.01466592,1.7977E+308,0.016575293,0
,139.7,261.8531892,10.83087894,1.7977E+308,0.005234303,0
,140,261.7994679,10.64706516,1.7977E+308,0.007415263,0
,140.3,261.17335,10.46328885,1.7977E+308,0.013958143,0
,140.6,260.6894992,10.27950324,1.7977E+308,0.028352478,0
,140.9,260.8188117,10.09567747,1.7977E+308,0.037512509,0
,141.2,260.00966,9.911913149,1.7977E+308,0.034895359,0
,141.5,259.9642583,9.728098822,1.7977E+308,0.018320063,0
,141.8,259.5810761,9.544306612,1.7977E+308,0.006106688,0
,142.1,258.9757574,9.360528946,1.7977E+308,0.01526672,0
,142.4,258.9777782,9.176711514,1.7977E+308,0.015702913,0
,142.7,258.4598165,8.992928128,1.7977E+308,0.023118178,0
,143,258.144856,8.809131451,1.7977E+308,0.020501026,0
,143.3,257.8107601,8.625336026,1.7977E+308,0.011340993,0
,143.6,257.1247401,8.441563644,1.7977E+308,0.013521954,0
,143.9,256.9620304,8.257756998,1.7977E+308,0.015266722,0
,144.2,256.6179508,8.073962227,1.7977E+308,0.013958147,0
,144.5,256.102485,7.890178678,1.7977E+308,0.012213379,0
,144.8,255.9422712,7.706371869,1.7977E+308,0.009160034,0
,145.1,255.2845381,7.522597635,1.7977E+308,0.015266724,0
,145.4,255.0677502,7.338794529,1.7977E+308,0.026171527,0
,145.7,254.4823987,7.155015556,1.7977E+308,0.031842026,0
,146,254.5077146,6.971196599,1.7977E+308,0.02442676,0
,146.3,253.894908,6.787419423,1.7977E+308,0.009596227,0
,146.6,253.5117257,6.603627213,1.7977E+308,0.004361922,0
,146.9,252.959653,6.41984606,1.7977E+308,0.001744769,0
,147.2,252.4201085,6.235757725,1.7977E+308,0.007415267,0
,147.5,252.2556861,6.052257554,1.7977E+308,0.010904805,0
,147.8,251.7086052,5.868476075,1.7977E+308,0.008723844,0
,148.1,251.4672741,5.684674577,1.7977E+308,0.014830535,0
,148.4,250.7637823,5.500903339,1.7977E+308,0.028352496,0
,148.7,250.5819372,5.317097945,1.7977E+308,0.052779262,0
,149,250.130117,5.133310229,1.7977E+308,0.064556454,0
,149.3,249.6300425,4.949525672,1.7977E+308,0.066301225,0
,149.6,249.1898699,4.765737193,1.7977E+308,0.054087843,0
,149.9,248.7576011,4.581948197,1.7977E+308,0.039257306,0
,150.2,247.9259855,4.398185348,1.7977E+308,0.025735347,0
,150.5,247.6459676,4.214386383,1.7977E+308,0.019192462,0
,150.8,247.2420831,4.029982802,1.7977E+308,0.020064847,0
,151.1,246.906323,3.846187487,1.7977E+308,0.028788695,0
,151.4,246.508997,3.662396202,1.7977E+308,0.041874466,0
,151.7,245.8769573,3.479233012,1.7977E+308,0.046672584,0
,152,245.364819,3.295449245,1.7977E+308,0.041002084,0
,152.3,245.1080962,3.111648754,1.7977E+308,0.034895391,0
,152.6,244.6192531,2.927863462,1.7977E+308,0.027480122,0
,152.9,243.9956304,2.744086995,1.7977E+308,0.010032426,0
,153.2,243.4069506,2.56030824,1.7977E+308,0.029224893,0
,153.5,242.932251,2.376522021,1.7977E+308,0.048417362,0
,153.8,242.7529017,2.192716465,1.7977E+308,0.048417363,0
,154.1,241.9853476,2.008949422,1.7977E+308,0.03707636,0
,154.4,241.1004854,1.825190059,1.7977E+308,0.028788705,0
,154.7,240.6158021,1.641404495,1.7977E+308,0.026171551,0
,155,239.9239575,1.457632494,1.7977E+308,0.018756279,0
,155.3,239.440938,1.273846821,1.7977E+308,0.006106696,0
,230.6,238.8244828,1.098134851,1.7977E+308,0.013085778,0
,230.9,238.348951,0.914348687,1.7977E+308,0.015702934,0
,231.2,237.6138437,0.730579519,1.7977E+308,0.035331603,0
,231.5,236.8229941,0.546814002,1.7977E+308,0.058886008,0
,231.8,235.859926,0.36305976,1.7977E+308,0.063247938,0
,232.1,234.6597456,0.179321044,1.7977E+308,0.046236427,0
,232.384,232.7471772,0.005432561,1.7977E+308,0.023118216,0
END,,,,,,