File: GB1_test 8.csv
Segment,Time On Sample,Displacement Into Surface,Load On Sample,Harmonic Contact Stiffness,Harmonic Displacement,Harmonic Load
Surface Marker,0,0,0,-676.9810676,0.278278092,2.243122494
,0.2,0.385636368,0.000628796,7323.082741,0.174032847,2.342841205
,0.4,0.351145707,0.001285096,15231.96578,0.148734839,2.426122741
,0.6,0.188537101,0.001949784,18765.16259,0.136522009,2.507212656
,0.8,0.629081153,0.002574986,20839.37724,0.129543245,2.586110985
,1,0.597086297,0.003231123,21345.58796,0.129979418,2.658434423
,1.2,0.550948551,0.003888186,24074.02432,0.12692621,2.940057523
,1.4,0.573029421,0.004540959,27997.45096,0.118638932,3.219489012
,1.6,0.617572504,0.005192414,30450.00765,0.116894241,3.490154019
,1.8,0.58474566,0.005848935,31229.66124,0.119947449,3.763010643
,2,0.658406457,0.006498484,30518.47014,0.125181519,4.001897174
,2.2,0.656361197,0.007152989,30190.63945,0.142192248,4.605688347
,2.4,0.878106366,0.007792843,29615.01053,0.163128528,5.141539337
,2.6,1.277885549,0.008421042,29826.85138,0.181883943,5.674102932
,2.8,0.991318635,0.009094173,30141.27336,0.201947882,6.212145482
,3,1.045012998,0.009745029,30492.72078,0.218522438,6.675673004
,3.2,0.928992168,0.010410268,32871.02816,0.229862925,7.522733924
,3.4,0.999325225,0.011060035,35094.23627,0.235096994,8.179124002
,3.6,0.760179103,0.011726789,37758.95326,0.240331068,8.970298565
,3.8,1.016865526,0.012364355,40608.81819,0.243820444,9.781197853
,4,0.984870619,0.01302082,42218.40107,0.24992686,10.43101302
,4.2,1.239061234,0.013658549,43934.70563,0.264756722,11.49394857
,4.4,1.323537179,0.014307389,43614.43423,0.28874621,12.49771034
,4.6,0.816507578,0.014994954,42771.16681,0.317097433,13.50037609
,4.8,0.954227343,0.015640308,41728.69103,0.343267782,14.2718262
,5,0.986291405,0.01629258,40488.80563,0.379033929,15.27558795
,5.2,1.037073996,0.016943626,39922.65319,0.411310695,16.29359523
,5.4,0.735116287,0.017617765,39010.48299,0.452310921,17.40145875
,5.6,0.59663374,0.018281202,37524.43287,0.499417558,18.40193298
,5.8,0.671126471,0.018930696,35688.04058,0.555247641,19.39473666
,6,0.494374927,0.019596639,33583.60288,0.615003285,20.17276146
,6.2,0.6562208,0.020240414,30742.14284,0.703982477,21.12721186
,6.4,0.513162611,0.020904151,28281.44332,0.793397853,21.91290735
,6.6,0.783991927,0.021540792,26339.91327,0.873217415,22.48711183
,6.8,-0.408135926,0.022273208,23980.98032,0.984005307,23.1193933
,7,-0.555769765,0.022937246,21734.69861,1.097846355,23.50073498
,7.2,0.482103367,0.023523672,19326.01948,1.235240639,23.73085569
,7.4,1.032046764,0.02414204,16560.51161,1.427592684,23.79770045
,7.6,1.123178186,0.024790444,14948.87799,1.564550849,23.75496395
,7.8,1.152330476,0.025442906,13657.49039,1.690168534,23.67606567
,8,1.594954284,0.026068298,13383.85785,1.725934635,23.7933176
,8.2,1.640329298,0.026719697,14126.86196,1.663998133,24.17685106
,8.4,1.545523327,0.027380273,16188.51195,1.508284551,24.96145079
,8.6,1.551797413,0.028034232,18568.08293,1.367837002,25.73728413
,8.8,1.449088062,0.028695325,22126.27244,1.209506385,26.75857876
,9,1.340555169,0.0293568,24956.31267,1.117037819,27.61988517
,9.2,1.227030666,0.030018602,26384.0424,1.087814269,28.328874
,9.4,1.73329747,0.030639828,26356.23233,1.113548413,28.98636027
,9.6,1.340242932,0.03131993,25701.71635,1.155857173,29.41372576
,9.8,1.601089017,0.031957223,24362.50468,1.232623515,29.8421876
,10,1.899372157,0.032592065,23226.67175,1.30153875,30.14134392
,10.2,1.521292446,0.033271185,22188.48279,1.371326382,30.409817
,10.4,1.646533185,0.033917355,21201.82398,1.445475697,30.69034442
,10.6,2.1028839,0.034541848,20669.46051,1.493018458,30.89745286
,10.8,2.40116703,0.035176689,20563.56872,1.518752612,31.2196212
,11,2.311768638,0.035836909,20911.49094,1.513954723,31.55822635
,11.2,2.253151826,0.036495115,21933.40962,1.473390687,32.08202339
,11.4,2.500686944,0.037133278,23187.83976,1.420613794,32.56965898
,11.6,2.729919497,0.037772638,25323.22012,1.335996313,33.2874146
,11.8,2.498260294,0.038442172,27196.68575,1.271442802,33.90983435
,12,2.65345067,0.03908638,28964.73594,1.21866592,34.5530748
,12.2,2.334438333,0.039761633,30468.0607,1.185080661,35.29603362
,12.4,2.359846915,0.040414338,30933.8748,1.188570038,35.91954946
,12.6,2.232179532,0.041077064,30618.38472,1.216921259,36.43348405
,12.8,2.42730277,0.041718658,29813.97961,1.259666149,36.78633505
,13,2.536736745,0.042365861,28513.92086,1.328581393,37.20603033
,13.2,3.250987146,0.042973468,27726.38134,1.373943274,37.50737874
,13.4,3.239790606,0.043628568,27130.44644,1.413198797,37.90296606
,13.6,3.155383826,0.044288461,26955.53267,1.431518047,38.23499636
,13.8,2.890447246,0.044960172,27610.25512,1.41581586,38.76208059
,14,3.075587263,0.045602418,28797.18611,1.376996494,39.29793181
,14.2,2.986188875,0.046262638,30486.52928,1.323347287,39.93898046
,14.4,2.757857414,0.046931953,32457.85995,1.268389571,40.70714288
,14.6,2.931350347,0.047574962,33824.83931,1.236112795,41.31422176
,14.8,3.033296908,0.048222655,34885.90512,1.219538233,42.04403118
,15,2.872352147,0.048887558,35042.3106,1.228261694,42.58097782
,15.2,3.006744155,0.049533127,34554.62758,1.258357585,43.08395471
,15.4,2.93065672,0.050192475,33804.88879,1.300230148,43.62418885
,15.6,2.847913808,0.050852259,33329.13173,1.329889882,44.02744676
,15.8,3.079642159,0.051491456,32811.21513,1.364347489,44.51289077
,16,3.168277766,0.05214002,32507.5012,1.38877314,44.91395732
,16.2,3.01898009,0.052804161,32560.26903,1.40447536,45.46624521
,16.4,2.902127862,0.053466178,32717.16305,1.413198819,45.88813187
,16.6,2.975788647,0.054115722,32938.88088,1.421922262,46.40425843
,16.8,3.057768778,0.054764722,32967.18458,1.434571257,46.79765428
,17,3.175522093,0.055411379,33072.51144,1.444603213,47.21625376
,17.2,2.948854505,0.056080585,33076.01014,1.460305441,47.74114639
,17.4,3.143145799,0.056722232,32970.79656,1.476007633,48.21344071
,17.6,3.000503601,0.057385937,32814.99202,1.491273681,48.56738711
,17.8,3.003449949,0.058040111,32766.79321,1.503922682,49.03201042
,18,3.285926304,0.058675985,32586.34313,1.519624866,49.38486166
,18.2,3.131637023,0.059340452,32467.58985,1.53401857,49.74976608
,18.4,2.963204853,0.060005846,32347.02301,1.551901656,50.16288619
,18.6,2.859663578,0.060666991,32291.44997,1.56324215,50.48067083
,18.8,3.11551803,0.061304607,32223.21572,1.577635817,50.8762585
,19,3.16838045,0.061955513,32215.47363,1.588976296,51.19294772
,19.2,3.508260285,0.062587628,32184.85475,1.601625266,51.50963729
,19.4,3.378097108,0.063250515,32461.08945,1.603369967,51.91289507
,19.6,3.519144588,0.063895647,32953.58118,1.595082677,52.27122512
,19.8,3.456368108,0.064554123,33855.39894,1.574146404,52.77529761
,20,3.707230943,0.065192065,34868.47131,1.546231344,53.2552626
,20.2,3.648614137,0.065850268,36420.80333,1.503486448,53.93137725
,20.4,3.622442776,0.066506347,37402.83534,1.479933138,54.45407851
,20.6,3.499767011,0.067168744,38205.53343,1.464667112,55.05458208
,20.8,3.991890853,0.067790891,38373.19484,1.468592621,55.48742775
,21,3.54143237,0.06847802,38450.8965,1.476443764,55.92684682
,21.2,3.912926226,0.069104809,38216.54082,1.497380009,56.43530316
,21.4,3.859300414,0.069766539,38148.57956,1.512209876,56.90978883
,21.6,3.893858615,0.070429074,38293.75273,1.517443942,57.29880139
,21.8,3.684658925,0.071114353,39208.12732,1.499124717,57.89272996
,22,3.869795132,0.071780497,39899.11925,1.487348045,58.39022786
,22.2,3.942619111,0.072460716,40863.82967,1.47164583,59.07072594
,22.4,3.648558858,0.073171949,41365.96689,1.46728413,59.56822314
,22.6,3.993423205,0.073848303,41583.04368,1.473826687,60.13366168
,22.8,4.507585145,0.074520283,41277.81503,1.496071436,60.60705231
,23,4.128248317,0.075257859,41159.3414,1.509592815,61.01688461
,23.2,4.257222304,0.075969434,41147.41949,1.520060941,61.47274173
,23.4,4.458573448,0.076683452,41479.11306,1.52136944,62.03598839
,23.6,4.117918118,0.077440232,42395.77287,1.50523109,62.66607853
,23.8,4.246472661,0.078173702,43262.18718,1.48952887,63.2194627
,24,4.144996146,0.078929606,44013.26283,1.478188395,63.76736746
,24.2,4.025215858,0.079694341,44803.9502,1.469901129,64.48183526
,24.4,4.159174391,0.080450012,45240.91754,1.470773462,65.11850108
,24.6,4.185396197,0.08122035,45295.10798,1.479496908,65.58202867
,24.8,4.201633557,0.081999089,45292.1084,1.492582079,66.14637081
,25,4.449563426,0.082770488,45326.24805,1.502177851,66.61428211
,25.2,4.154654795,0.083585287,45432.48638,1.512209842,67.23560572
,25.4,4.417556942,0.084371707,45613.82272,1.516571543,67.71557098
,25.6,4.196687921,0.085197757,45798.65615,1.522241804,68.28320005
,25.8,4.148444007,0.086020678,45797.69443,1.532709946,68.82124262
,26,4.299447083,0.086838848,45680.95899,1.544922754,69.25408786
,26.2,4.346457024,0.087672162,45471.65181,1.563678167,69.79432216
,26.4,4.523247414,0.088505332,45443.65364,1.573273945,70.19648467
,26.6,4.232489284,0.089377574,45483.62272,1.583305939,70.71589812
,26.8,4.583151291,0.090216278,45883.05839,1.58199739,71.25503727
,27,4.260776917,0.091107788,46464.08164,1.573710143,71.77006728
,27.2,4.449208924,0.09197459,47241.35998,1.559316434,72.34098458
,27.4,4.270756423,0.092874237,47972.50704,1.548848309,73.00942828
,27.6,4.501614266,0.093756012,48569.87905,1.542305702,73.64061525
,27.8,4.41883139,0.094667266,48924.24566,1.540997191,74.15126249
,28,4.591450958,0.095570846,49216.76722,1.544922731,74.81422783
,28.2,4.36058085,0.096510018,49040.54149,1.559752611,75.23720997
,28.4,4.765307189,0.097416925,48660.52896,1.583305886,75.71936717
,28.6,4.739921922,0.098361347,48351.80828,1.604678336,76.1817989
,28.8,4.638829128,0.099320109,48093.17822,1.621689067,76.51382909
,29,4.826416087,0.100269433,47673.85621,1.647423225,76.94886602
,29.2,4.852606229,0.101238957,47773.56218,1.653093464,77.32801622
,29.4,4.873803199,0.102218661,48139.09411,1.651784944,77.83428053
,29.6,4.902486012,0.103207731,48571.13293,1.647859389,78.34602382
,29.8,5.139982816,0.104192906,49023.92505,1.641752952,78.77996506
,30,5.277645899,0.105194592,49825.78825,1.628231594,79.42539724
,30.2,4.941936677,0.106237403,50244.04451,1.623869901,79.88344508
,30.4,5.157798357,0.10725437,50818.02778,1.617763466,80.48394952
,30.6,5.290464941,0.108287161,51321.21573,1.61165704,80.96391442
,30.8,5.40815507,0.109331214,51881.25739,1.605986787,81.56880186
,31,5.645642075,0.110377988,52231.83827,1.604242075,82.04986283
,31.2,5.329891022,0.111471489,52770.15215,1.59988038,82.71501889
,31.4,5.509971151,0.11254342,53320.48071,1.594210121,83.32648127
,31.6,5.83647001,0.11361661,53618.87589,1.59421009,83.82617124
,31.8,5.479948989,0.114745398,53999.80346,1.593773951,84.42557854
,32,5.943713526,0.115831608,54918.18634,1.581124908,85.17949684
,32.2,5.45241558,0.116991567,55592.97889,1.572837677,85.74822097
,32.4,5.761436728,0.118110502,56249.19742,1.56760358,86.43310299
,32.6,5.70690073,0.119264613,57184.82422,1.55582693,87.18044528
,32.8,5.744707619,0.120424203,57793.66495,1.550156685,87.76451193
,33,5.578688692,0.121609009,58109.35301,1.552773734,88.35515304
,33.2,5.944274001,0.122770631,58225.69007,1.562369493,89.05208921
,33.4,5.89472215,0.12397135,58591.8567,1.564986531,89.74464092
,33.6,5.9824376,0.12517487,58787.33151,1.569348246,90.27610897
,33.8,6.020235033,0.126393948,59134.73476,1.571529104,90.9281159
,34,6.485644827,0.127597032,59810.49026,1.564550303,91.58560321
,34.2,6.1124628,0.128867412,60912.02863,1.550592821,92.48416627
,34.4,6.926449147,0.13007245,61677.45743,1.543613989,93.28958856
,34.6,6.902675615,0.131344764,62304.24609,1.537507577,93.91967934
,34.8,7.007849889,0.132621317,63081.69369,1.530964982,94.76235751
,35,7.231156792,0.133903015,63686.32588,1.52703941,95.45162266
,35.2,7.176595564,0.135215876,64433.29778,1.523550036,96.34580341
,35.4,7.599562587,0.136510377,65317.30306,1.514826551,97.06684758
,35.6,7.546661073,0.137849274,66578.154,1.501305213,98.01581879
,35.8,7.894749783,0.139175204,67435.69053,1.496507286,98.90671331
,36,7.909230692,0.140536463,68097.63524,1.49389025,99.6672055
,36.2,7.930364903,0.141910957,68933.71465,1.490837042,100.6654884
,36.4,7.914059871,0.143301737,69311.72784,1.493454077,101.3898188
,36.6,8.084937846,0.144694157,69392.36756,1.504794542,102.2609884
,36.8,7.65266119,0.146140333,69592.61041,1.512645682,103.0938027
,37,7.972450889,0.147551424,69764.7336,1.519188238,103.7984095
,37.2,7.949481371,0.148999331,69931.07985,1.528784031,104.7166981
,37.4,8.023845861,0.150455366,70169.00501,1.533145747,105.4037712
,37.6,8.026661678,0.151930701,70841.01076,1.531401057,106.3384972
,37.8,7.903021122,0.153429173,71715.6294,1.523549966,107.1132343
,38,7.836781641,0.15493892,72918.15786,1.513081835,108.1597326
,38.2,8.060052913,0.156444694,73660.79884,1.510028609,109.0287109
,38.4,8.210111529,0.157970592,74148.99223,1.513954146,110.0072696
,38.6,8.148024452,0.159525796,74307.9908,1.521369081,110.7688572
,38.8,8.232354099,0.161094753,73674.59386,1.545358551,111.5841404
,39,8.073758918,0.162679721,73090.8644,1.565858664,112.2306678
,39.2,8.358580941,0.164259358,72667.33951,1.583305531,112.891442
,39.4,8.403803336,0.16587076,72532.048,1.596390696,113.6749463
,39.6,8.39993904,0.167501539,72344.27794,1.608603521,114.2633962
,39.8,8.829509913,0.169120161,72649.60734,1.613401375,115.0403269
,40,8.643446814,0.170795597,73112.3549,1.614273737,115.7482197
,40.2,8.822184239,0.17246378,74025.89279,1.60860348,116.6862337
,40.4,8.738859709,0.1741659,74490.68154,1.608603487,117.3722106
,40.6,9.003696957,0.175862232,75348.88291,1.602933222,118.2817336
,40.8,9.047236981,0.177590129,75947.87984,1.600316183,119.0225015
,41,8.961408451,0.179343992,76135.08202,1.605550258,119.7194363
,41.2,8.956274759,0.181110072,76284.28683,1.613837532,120.5785513
,41.4,9.301382566,0.182870916,76752.82096,1.613401327,121.2579547
,41.6,9.120289154,0.184683944,76861.11463,1.62212479,122.0578954
,41.8,9.158407499,0.186500939,76818.25351,1.633029093,122.8151004
,42,9.439447764,0.188320103,77070.32543,1.636954617,123.5405276
,42.2,9.648938757,0.190162349,76880.88735,1.647858903,124.1180203
,42.4,9.102198585,0.192072755,76191.68965,1.669231398,124.7415342
,42.6,9.275910445,0.193954877,75856.78074,1.681880377,125.2412243
,42.8,9.455858786,0.195855615,75742.92019,1.691912322,125.8724115
,43,9.991871939,0.197752054,75464.62234,1.705433609,126.371007
,43.2,9.72132182,0.199720586,75561.63179,1.712630478,126.9769889
,43.4,9.894189514,0.201679675,76087.93228,1.710667685,127.6070803
,43.6,9.750503086,0.203679376,76725.19536,1.707178321,128.3259313
,43.8,9.685015286,0.205693993,77091.82191,1.706742155,128.8990397
,44,10.26260943,0.207686507,77710.90049,1.701071856,129.5521448
,44.2,10.39095588,0.209728816,78417.55091,1.695837772,130.3740027
,44.4,10.2838617,0.211807006,78790.19741,1.694965441,130.9493025
,44.6,10.82900064,0.213863045,79165.79231,1.695837734,131.6769224
,44.8,11.49143895,0.215932262,79631.95856,1.694092977,132.2774288
,45,11.30862886,0.218077751,80246.45479,1.690167444,132.9349142
,45.2,11.41948811,0.220225497,81192.86101,1.681880159,133.8126585
,45.4,11.34898228,0.222406677,82024.98876,1.673156722,134.5172642
,45.6,11.2892881,0.224609173,83139.84976,1.661816247,135.4311696
,45.8,11.33441411,0.226826881,84150.59028,1.652656627,136.3538419
,46,11.2747129,0.229073618,84661.84194,1.651348117,137.0869386
,46.2,11.53280694,0.23132206,84994.81847,1.653528949,137.8266114
,46.4,11.54381295,0.233609357,85059.1922,1.662252396,138.637511
,46.6,11.81521067,0.235902606,84804.9728,1.674029018,139.2018542
,46.8,11.71057049,0.238243691,84668.54427,1.685369502,139.9119388
,47,11.70742256,0.24060146,84701.47907,1.691912089,140.51573
,47.2,12.06533025,0.242959339,84589.98288,1.701507842,141.1107563
,47.4,11.8874686,0.245376109,84825.53997,1.705869582,141.8548108
,47.6,12.0731583,0.247793304,85217.88225,1.705869563,142.4783275
,47.8,11.94936465,0.250255056,85603.91193,1.707178091,143.211424
,48,12.00027324,0.252730068,85947.75827,1.70805043,143.8579521
,48.2,11.98379122,0.255234301,86621.23386,1.703252537,144.5735162
,48.4,12.08377597,0.257756085,87355.38042,1.698890804,145.3855118
,48.6,12.17377348,0.260303896,87540.36766,1.704124861,146.1295674
,48.8,12.50585976,0.262861291,87599.98502,1.709795067,146.7114439
,49,12.40533621,0.265472884,87600.3664,1.716773832,147.2867438
,49.2,12.62260731,0.268089855,87159.99457,1.732912181,147.9179313
,49.4,12.47049549,0.270757376,86652.49131,1.747742051,148.3540631
,49.6,12.49391752,0.27344015,86627.72755,1.755156976,148.9545673
,49.8,12.78189029,0.27613252,86863.80843,1.756465462,149.4663118
,50,12.75538767,0.278872659,87081.23604,1.758210153,150.0175043
,50.2,13.15982251,0.281612026,87471.13309,1.758210111,150.708962
,50.4,13.77556425,0.28436482,87881.66243,1.756465359,151.254678
,50.6,13.59430877,0.28719778,88312.64248,1.755593032,151.9472296
,50.8,13.96295715,0.290023045,88286.85173,1.762135577,152.5334894
,51,13.86322216,0.292907496,88278.3205,1.767805825,153.0211246
,51.2,13.91655843,0.295810853,88492.78948,1.769550507,153.5613594
,51.4,14.22446186,0.298726682,88968.22923,1.767369614,154.2407626
,51.6,14.35349483,0.301683507,89346.58645,1.765624912,154.7733272
,51.8,14.60481737,0.304662051,90477.53094,1.752975893,155.5623117
,52,14.5566389,0.307690291,91959.99011,1.733784322,156.3644445
,52.2,14.9760025,0.310718126,93455.23286,1.715465049,157.2136992
,52.4,15.14245332,0.313793106,95113.53364,1.697145802,158.2262286
,52.6,15.2198823,0.316904851,96275.57218,1.685805318,159.0316495
,52.8,15.46618891,0.32003661,97427.80775,1.676209506,160.05185
,53,15.82563353,0.323192447,97942.13459,1.675337127,160.8320684
,53.2,15.89971975,0.326398881,98383.67855,1.675773291,161.6221481
,53.4,15.98128825,0.329637025,99062.34109,1.67315625,162.5908447
,53.6,15.98548172,0.332912826,99890.00158,1.667486011,163.4324271
,53.8,15.8207874,0.336232483,100773.5698,1.66399665,164.4592005
,54,15.94643271,0.339566405,101974.2736,1.65440085,165.3884485
,54.2,16.19852665,0.342925576,103748.3778,1.640007146,166.6628766
,54.4,16.14695933,0.346338495,104809.3094,1.633464569,167.5723989
,54.6,16.4073618,0.349765085,106073.6321,1.626049617,168.7306715
,54.8,16.78838921,0.353218137,107161.2708,1.619506999,169.725669
,55,16.5978725,0.356743575,107680.8582,1.621251705,170.692173
,55.2,16.71516571,0.360284164,107490.857,1.634336857,171.7649718
,55.4,17.09700823,0.363842907,107035.176,1.648294327,172.5265618
,55.6,17.73008618,0.367439151,105964.5234,1.672719901,173.3473266
,55.8,17.29579308,0.371105126,104788.9081,1.696273236,173.89523
,56,17.94134134,0.374755205,104017.6934,1.713720054,174.4792996
,56.2,17.89887446,0.378487388,103293.2093,1.732039284,175.2233548
,56.4,17.88634823,0.38227399,103023.2552,1.741635071,175.8041342
,56.6,17.86133994,0.386080648,103515.019,1.741198901,176.6511959
,56.8,17.75230331,0.38991181,104476.3363,1.732911642,177.4094957
,57,18.3687038,0.393752986,105608.0903,1.723315794,178.2631351
,57.2,18.82619876,0.397643352,107525.4941,1.704996521,179.4356543
,57.4,18.9733762,0.401593193,109137.5046,1.689730485,180.4153095
,57.6,19.17670287,0.405578943,110780.8563,1.676209131,181.6185106
,57.8,19.27020794,0.409611819,111992.2607,1.667049509,182.5959739
,58,19.48724874,0.41367702,113178.7862,1.658762218,183.6106956
,58.2,19.75045536,0.417780132,114264.3975,1.654400472,184.88622
,58.4,19.89177713,0.42193248,115088.2449,1.651783426,185.8625877
,58.6,19.90039883,0.426135272,115931.0952,1.65091108,187.040584
,58.8,20.07165687,0.430369591,116163.4398,1.655708956,187.9062751
,59,20.00206334,0.434662243,116270.6069,1.662251542,188.7905936
,59.2,20.05475721,0.438989959,116269.7744,1.672283493,189.895171
,59.4,20.23514599,0.44335285,116091.8745,1.681443087,190.697305
,59.6,20.22667885,0.447771945,115827.105,1.692783559,191.6407977
,59.8,20.61254122,0.452209515,115974.0942,1.69714524,192.4232084
,60,20.6269381,0.456716158,116554.981,1.696272894,193.3108151
,60.2,20.751559,0.461260811,116962.3703,1.699762258,194.4351172
,60.4,21.05004679,0.465839625,117393.4633,1.701070743,195.2580723
,60.6,21.37598107,0.470462666,118294.3891,1.698453679,196.3473098
,60.8,21.63826505,0.475136197,118640.4593,1.702815372,197.354361
,61,21.57650346,0.479877773,118759.2492,1.708485613,198.1586855
,61.2,21.69942357,0.484654751,119203.6795,1.710230288,199.0441013
,61.4,21.82150413,0.489479738,119637.1861,1.712847306,200.0566305
,61.6,22.2364176,0.494334005,119811.0285,1.717208985,200.8456169
,61.8,22.47994499,0.499248351,120054.5466,1.722006851,201.8197933
,62,22.47388444,0.504228466,120281.1846,1.725932398,202.6339804
,62.2,22.52189161,0.509255203,120189.1975,1.733783484,203.3977607
,62.4,22.56406724,0.514332634,120492.1742,1.73770903,204.3237207
,62.6,22.80756268,0.519447945,120817.1442,1.739453691,205.069969
,62.8,22.63009156,0.524642286,121591.7329,1.737272852,206.0649639
,63,22.84278901,0.52986306,122409.9942,1.733347279,206.9569549
,63.2,23.20938581,0.535126264,123324.9734,1.728549351,207.8916833
,63.4,23.40043623,0.540453846,124102.9452,1.726804647,208.9633871
,63.6,23.68631857,0.545828636,124549.2632,1.72767696,209.7929173
,63.8,23.63276344,0.551279745,124454.5394,1.736400405,210.7123021
,64,23.63743494,0.556781926,124342.6201,1.743815321,211.4399203
,64.2,24.01979547,0.562314565,124522.9354,1.747304661,212.2365768
,64.4,24.33808827,0.567907013,125117.0495,1.746432281,213.2392453
,64.6,24.69547302,0.573552993,126128.7052,1.739017324,214.1202791
,64.8,25.22505898,0.57924437,127912.882,1.724187426,215.3673147
,65,25.37361031,0.585017969,129336.1642,1.713283113,216.4192938
,65.2,25.4497742,0.590854394,130387.3568,1.708049043,217.4690808
,65.4,25.34290342,0.596761461,131234.9115,1.706740537,218.6591306
,65.6,25.7210404,0.602696018,131276.9317,1.712846905,219.4842782
,65.8,25.87454584,0.608705168,130969.1561,1.724623529,220.4310591
,66,26.0455123,0.614773386,130857.4544,1.732474605,221.2178522
,66.2,26.4735365,0.620885649,130646.987,1.74163417,222.0265634
,66.4,26.4947355,0.627086048,130437.0568,1.751666119,222.9273201
,66.6,26.9618409,0.63331941,130746.9308,1.75384693,223.7064439
,66.8,27.26254965,0.639626347,132003.4859,1.745995806,224.8362266
,67,27.15310519,0.646023623,133127.41,1.739017067,225.8005391
,67.2,27.52949958,0.652453206,134423.0377,1.730729764,226.8503282
,67.4,27.8509761,0.658951033,135872.0406,1.721570123,228.0721589
,67.6,27.78309743,0.665539804,136495.4545,1.720697786,229.0167476
,67.8,27.98891431,0.672176729,136663.3092,1.726367998,230.0665352
,68,27.88856915,0.678900373,136857.1433,1.729857382,230.9727701
,68.2,28.04777644,0.685674506,137269.7727,1.730729709,231.9305098
,68.4,28.53309075,0.692495334,138307.7437,1.726367941,233.1249461
,68.6,28.55500731,0.699415174,139515.7989,1.71938919,234.1714459
,68.8,28.80985414,0.706389254,140644.4217,1.715027446,235.4151927
,69,28.526429,0.713468793,141370.9027,1.714591302,236.4233365
,69.2,28.98840477,0.720570404,141794.5927,1.718080629,237.4479225
,69.4,29.38131874,0.727747894,141622.433,1.728548711,238.479083
,69.6,29.60949844,0.735008358,141205.401,1.739452982,239.2187566
,69.8,29.78608667,0.742345301,141946.5821,1.739452963,240.3496343
,70,29.70559583,0.749772718,142767.0669,1.737272112,241.3457257
,70.2,29.97367315,0.757251871,143792.9917,1.732910367,242.4075683
,70.4,30.22842759,0.764807021,145582.6974,1.721569875,243.7882917
,70.6,30.47901032,0.77243822,146947.6626,1.713282586,244.8939665
,70.8,30.84105988,0.78013887,147143.45,1.71851661,246.0621029
,71,31.46765188,0.787899509,146896.4492,1.726803809,246.9540973
,71.2,31.81553387,0.795756415,146523.3954,1.738144238,248.056485
,71.4,31.70750395,0.803722258,145903.8154,1.750793227,248.7961568
,71.6,31.9555287,0.811744626,145681.2783,1.760388979,249.7352684
,71.8,32.61035591,0.819820918,146128.3505,1.761261254,250.568089
,72,32.55719515,0.828024936,146609.047,1.762133602,251.4469292
,72.2,32.99402985,0.836279235,147307.4772,1.762133557,252.5986294
,72.4,33.33101942,0.844622918,148396.6896,1.756027118,253.5881487
,72.6,33.72123936,0.853046969,149342.1331,1.752973876,254.7529986
,72.8,34.09397525,0.861556763,150154.2073,1.750356807,255.7151231
,73,34.29282353,0.870163604,151433.5561,1.742941868,256.7977857
,73.2,34.4342547,0.878860588,152859.1219,1.736399279,258.2179577
,73.4,35.02241999,0.887615516,153445.3141,1.736399218,259.1899458
,73.6,35.42837795,0.896470535,154150.1526,1.736399177,260.4358857
,73.8,36.07059072,0.905398864,154493.6156,1.738143797,261.4045872
,74,36.23442776,0.914448566,154514.2277,1.743814011,262.3513689
,74.2,36.43734386,0.923632787,154662.7295,1.748175705,263.3441751
,74.4,36.52877356,0.932870815,155056.3767,1.750792725,264.4827238
,74.6,36.65430523,0.94215235,155415.139,1.752973569,265.4053971
,74.8,36.96283984,0.951562074,156385.8566,1.750792679,266.609696
,75,37.39698127,0.961058196,157507.7477,1.745994747,267.7120846
,75.2,37.50332594,0.970671477,158872.2596,1.740324505,269.0982865
,75.4,37.78352921,0.980370013,159753.1345,1.737707447,270.1393092
,75.6,38.12195225,0.990162359,161230.1447,1.730728667,271.5342792
,75.8,38.29064537,1.000064176,162307.7889,1.725930762,272.6257079
,76,38.71555796,1.010048701,163282.4315,1.722877518,273.8223368
,76.2,39.00651342,1.020142315,164729.1932,1.718079602,275.4046899
,76.4,39.08281409,1.030351556,165970.1739,1.713281707,276.6002206
,76.6,39.39245561,1.040647897,167184.6923,1.710664646,278.0653225
,76.8,39.78901764,1.051042074,168197.4418,1.708483748,279.2378432
,77,39.91684879,1.061558386,169237.0382,1.706739049,280.4793976
,77.2,40.27427658,1.072165165,170662.9774,1.703249641,282.0968181
,77.4,40.75314959,1.082870581,171923.9555,1.700632563,283.6452027
,77.6,41.08724918,1.093693168,172692.706,1.70063253,284.8451184
,77.8,41.11143659,1.104644791,173675.9385,1.700196355,286.3682961
,78,41.55822831,1.115678569,174396.2676,1.70019631,287.6416323
,78.2,42.01914527,1.12682213,175436.0483,1.698015406,289.0629026
,78.4,42.21507393,1.138094768,176819.7223,1.693653672,290.7548366
,78.6,42.40100149,1.14948076,178087.5699,1.688419596,292.1256979
,78.8,42.61186885,1.160979474,178988.2946,1.688419574,293.7792784
,79,42.95083546,1.172585261,179524.3196,1.691036569,295.1249375
,79.2,43.55516999,1.184290315,179277.2171,1.700632283,296.3906039
,79.4,43.32172974,1.196168103,178864.2459,1.711536588,297.4699763
,79.6,43.7954132,1.208118646,178134.5524,1.727238712,298.7115342
,79.8,44.42548086,1.220178998,178430.0432,1.731600358,299.778859
,80,45.05053764,1.2323609,178934.4695,1.734217321,300.9568613
,80.2,45.41018851,1.244682524,180096.6325,1.732908769,302.5600361
,80.4,45.67081971,1.257134567,181033.9529,1.731164059,303.7884426
,80.6,46.02127975,1.26970565,182372.5934,1.727238482,305.3729886
,80.8,46.41581211,1.282400254,183029.9745,1.728546954,306.7635764
,81,46.70383682,1.295229505,183150.4266,1.732472468,307.6577608
,81.2,46.67570674,1.308208406,184227.0728,1.731600128,309.2335371
,81.4,46.88632054,1.321301877,185078.5166,1.732036273,310.684393
,81.6,47.23168646,1.334518126,185991.776,1.730727725,311.8974591
,81.8,47.55456909,1.34786868,188011.1299,1.722004266,313.6189814
,82,47.64116163,1.361368747,189701.1113,1.714589352,315.118052
,82.2,48.26516088,1.374969145,190817.496,1.711972254,316.5765822
,82.4,48.50478566,1.388731557,192314.6197,1.707610516,318.3167327
,82.6,48.86585057,1.402624238,192844.4719,1.709355165,319.6437634
,82.8,49.26765797,1.416653778,192571.3933,1.719387062,321.1154416
,83,49.68358579,1.430823448,193038.7692,1.722440218,322.4216527
,83.2,50.22095309,1.445127424,193459.0605,1.725929533,323.7453974
,83.4,50.42219691,1.459597225,193642.6988,1.732035909,325.1666667
,83.6,50.78065282,1.474202025,194336.8153,1.733344386,326.4147993
,83.8,51.64573209,1.488920146,195332.9399,1.733780469,327.991679
,84,51.91762018,1.503825327,195377.5342,1.740323008,329.1554336
,84.2,52.44821537,1.518863156,195481.6938,1.74642935,330.3465857
,84.4,52.433871,1.534087942,196053.4448,1.74991872,331.8094934
,84.6,52.82798099,1.549438694,196267.9068,1.753844219,332.8691476
,84.8,53.26449498,1.564940965,197143.3828,1.753844174,334.2991852
,85,53.60448008,1.580605365,198415.3316,1.749918598,335.6525152
,85.2,53.7481042,1.596440032,200026.9812,1.7451207,337.3882817
,85.4,54.38254292,1.612401539,201521.3792,1.73945041,338.7832564
,85.6,55.33225833,1.628502716,203374.6743,1.732471575,340.4949224
,85.8,56.02488102,1.644782511,204289.4961,1.731599162,341.8449693
,86,56.47205777,1.661242028,204740.674,1.734216142,343.1533721
,86.2,57.43999758,1.677832593,204881.782,1.740758609,344.7499785
,86.4,57.77397878,1.694631627,204744.6149,1.747301139,345.8699012
,86.6,58.13372302,1.711597749,204869.7661,1.752971325,347.3295263
,86.8,58.36199494,1.728742954,205500.3289,1.753407472,348.5677956
,87,58.58441597,1.74606074,207396.4905,1.744684028,350.0230356
,87.2,58.85173364,1.763549601,210264.8886,1.731162699,352.0437145
,87.4,59.77125787,1.781171285,212978.6246,1.719385989,353.995364
,87.6,60.57345153,1.798977848,214452.746,1.71589654,355.4922503
,87.8,60.85066783,1.816997763,216047.3544,1.712843315,357.322259
,88,61.32502316,1.835185749,216244.2087,1.718513488,358.7106573
,88.2,61.5672405,1.853571751,215899.2621,1.729417737,360.3390359
,88.4,61.94586526,1.872133465,215708.364,1.736396432,361.5159416
,88.6,62.61397256,1.890862701,215839.055,1.742066585,363.0325514
,88.8,63.32697424,1.909777038,216441.5913,1.744683537,364.5951855
,89,63.59403037,1.928910789,217211.4404,1.744683509,365.9441331
,89.2,64.18717308,1.948215466,218422.6094,1.742066423,367.4618384
,89.4,64.84184789,1.967709927,220214.1532,1.737268476,369.2896588
,89.6,65.199492,1.987419844,222278.4894,1.729417364,370.8698236
,89.8,65.80585212,2.00731141,224385.2284,1.72331091,372.8170871
,90,65.90470229,2.027436207,226113.9232,1.71851302,374.4761477
,90.2,66.48936828,2.047731136,227901.3335,1.714151252,376.2787643
,90.4,66.69547304,2.06825504,229548.4978,1.711534206,378.2830063
,90.6,67.24513267,2.088962507,230144.2476,1.715459687,380.1228796
,90.8,67.86214568,2.109873481,230797.5772,1.717204308,381.6033288
,91,68.10974775,2.131018937,231705.3755,1.718076624,383.2306112
,91.2,68.93966795,2.15233855,232813.0267,1.718948881,385.2403401
,91.4,69.3660674,2.17389891,234267.4751,1.715895642,386.9103615
,91.6,69.71173508,2.195681177,236615.6192,1.708916875,389.021995
,91.8,70.4051152,2.217659571,238297.5957,1.704991268,390.7270861
,92,70.84470331,2.239987845,239353.1777,1.705427394,392.4771025
,92.2,71.29926616,2.262315158,240443.4776,1.707608202,394.6479111
,92.4,71.98006068,2.284964761,240503.963,1.713714522,396.1294567
,92.6,72.20408877,2.307872298,239249.2092,1.729416642,397.7687941
,92.8,72.92599088,2.330978162,238061.0283,1.743155943,399.0876115
,93,73.30718031,2.354338483,237977.3799,1.749916548,400.5938098
,93.2,73.76112637,2.377928841,238117.9545,1.754714378,402.0249453
,93.4,74.42384943,2.401742486,238905.9933,1.755804735,403.6259337
,93.6,74.78079979,2.425815493,240942.2268,1.749044054,405.4406032
,93.8,75.35942128,2.4501159,243537.0369,1.7385759,407.2224001
,94,76.09939854,2.474649866,245653.3613,1.732033265,409.0447439
,94.2,77.08434022,2.499414326,248597.331,1.722437413,411.3876018
,94.4,77.88372174,2.524439671,251352.7233,1.713713921,413.6438879
,94.6,78.78206303,2.549709814,253330.4359,1.708479784,415.5243123
,94.8,79.21323478,2.575264626,254821.7714,1.707607399,417.698409
,95,79.73047052,2.601070697,256292.9618,1.705426495,419.6270447
,95.2,80.32877826,2.627130789,256457.3986,1.710660479,421.3540516
,95.4,81.01938868,2.653446544,255781.678,1.72200084,423.2574859
,95.6,81.80937275,2.68002021,255517.4572,1.729415657,424.7182132
,95.8,82.32810508,2.706877928,255086.1906,1.739011352,426.4813813
,96,83.10718894,2.733987356,255582.7011,1.742500634,428.0812762
,96.2,83.59505386,2.761387754,257089.9652,1.740319732,429.8630733
,96.4,84.26756359,2.789051274,259821.3119,1.732032426,432.0744306
,96.6,84.9441888,2.816992267,263558.1989,1.718947247,434.537825
,96.8,85.40696323,2.845228022,267585.5452,1.703681239,436.7732882
,97,86.25570829,2.87372203,270452.0527,1.69539392,438.9506777
,97.2,86.84484549,2.90251954,273630.4514,1.687542793,441.7198022
,97.4,87.42395353,2.931606884,275825.1898,1.683181032,443.881848
,97.6,88.36407287,2.960962731,276544.8752,1.687978811,446.2521015
,97.8,89.176028,2.990622001,276549.6774,1.694521285,448.073352
,98,89.93386025,3.020582872,277042.5448,1.698446742,449.9844586
,98.2,90.46119995,3.050859927,278297.9295,1.700627539,452.5322295
,98.4,91.09747413,3.081434003,278807.2933,1.704553004,454.347999
,98.6,91.54401939,3.112327634,280585.4641,1.703244448,456.7368762
,98.8,92.52461445,3.143496543,281365.8538,1.705861371,458.5745665
,99,92.91532124,3.175017432,281983.0554,1.70978686,460.4648483
,99.2,93.45073353,3.206845368,281575.1921,1.720691059,462.7408581
,99.4,94.18659009,3.238980102,281983.8028,1.725925024,464.8996194
,99.6,95.33420064,3.271410582,281718.106,1.732903629,466.4447295
,99.8,96.27128106,3.304180635,282635.7079,1.735084384,468.6462295
,100,97.20747716,3.337280027,283464.1269,1.735956627,470.4258417
,100.2,97.76426034,3.370736899,284484.7733,1.737265078,472.6865113
,100.4,98.46325007,3.404520493,285316.4357,1.738573516,474.4748874
,100.6,98.93423705,3.438658568,286861.1897,1.737701127,476.7771966
,100.8,99.98502453,3.473101623,287360.2764,1.740754209,478.4581873
,101,100.4841875,3.507926871,288162.4292,1.742935006,480.2936807
,101.2,101.3227222,3.543079784,289427.4838,1.744679599,482.5696955
,101.4,102.0272601,3.57859452,289311.7805,1.751222075,484.0687769
,101.6,102.6576995,3.614471009,289623.6161,1.756892217,486.035769
,101.8,103.7822477,3.650675505,290099.1722,1.759945289,487.6137553
,102,104.764478,3.687253133,290208.4835,1.765179224,489.1917399
,102.2,105.4263571,3.724219264,290689.2721,1.769540853,491.2617398
,102.4,106.3610499,3.761538967,291834.3513,1.768668415,492.9536881
,102.6,107.1451039,3.799243452,293900.5202,1.764306635,495.1453247
,102.8,107.9889965,3.837322789,296060.9316,1.75950868,497.3873699
,103,108.5973922,3.875800259,298206.5798,1.752966071,499.0606857
,103.2,109.6566322,3.914634558,301478.6535,1.743806397,501.6994179
,103.4,110.3031732,3.953886128,305114.1498,1.733338258,504.3732116
,103.6,111.2200285,3.993514361,307074.7906,1.729848807,506.4048616
,103.8,111.9454767,4.033553365,309897.8018,1.724178527,509.0403032
,104,112.6808441,4.0739941,311498.7382,1.723306112,511.2089276
,104.2,113.4103233,4.114841449,312719.8555,1.724178377,513.323857
,104.4,114.1929808,4.156095691,312847.4776,1.73115701,515.5560413
,104.6,114.6694225,4.197784548,312549.2579,1.738571843,517.3159236
,104.8,115.5526108,4.239865463,312591.4117,1.745550464,519.4593473
,105,116.5139332,4.282363981,314055.1535,1.744678025,521.458125
,105.2,116.9718707,4.325322615,316871.5558,1.739007774,524.1735569
,105.4,118.0021067,4.368675239,319919.923,1.730720448,526.4813556
,105.6,118.9016605,4.412472065,323180.0203,1.723305475,529.2921302
,105.8,119.5973218,4.456722283,325430.224,1.719379879,531.5637624
,106,120.8311702,4.50138177,326612.5138,1.720688261,533.7992402
,106.2,121.8519736,4.546503913,326163.0763,1.730720053,536.2352482
,106.4,122.9958302,4.592071295,325585.5291,1.739443322,537.9721307
,106.6,124.1587483,4.63809526,326344.9363,1.743368726,540.3248591
,106.8,125.2583663,4.684585864,327091.2035,1.74511329,542.1669389
,107,125.7239805,4.731585199,327512.1763,1.749038764,544.1963936
,107.2,127.0497336,4.77900013,328568.1015,1.751219473,546.6762393
,107.4,128.210689,4.826902263,329801.1696,1.750783184,548.6355723
,107.6,129.1793925,4.875298355,330542.756,1.753836267,550.963096
,107.8,129.9134148,4.924196051,330863.1711,1.759506389,553.1667888
,108,131.0050882,4.973561476,331728.6721,1.761250952,555.0231143
,108.2,132.1332875,5.023420349,333093.208,1.761250834,557.0854528
,108.4,133.4020029,5.073771201,335171.4253,1.758633688,559.5203717
,108.6,134.4535045,5.124642148,337347.1869,1.754708056,561.6462665
,108.8,135.6089159,5.176017369,340232.7119,1.749037739,564.3792444
,109,136.5063475,5.227925655,342541.1405,1.744675956,566.7188221
,109.2,137.2755792,5.280364097,343785.181,1.746420552,569.3794708
,109.4,138.4723381,5.333301172,343835.877,1.751654455,571.2325117
,109.6,139.6448435,5.387041499,343051.7615,1.761250049,573.3255359
,109.8,140.2515946,5.441091805,341929.0358,1.77128187,574.8695466
,110,141.3832495,5.495376194,341361.2927,1.779568959,576.5582143
,110.2,142.4827443,5.550484693,343084.087,1.778696505,578.9690235
,110.4,143.3200938,5.606164691,345889.4077,1.771717716,581.0773843
,110.6,144.4069326,5.662387759,350208.3738,1.760377213,583.9035064
,110.8,145.5290384,5.719173397,354903.8795,1.745983527,586.449101
,111,146.6689399,5.77652859,360300.1461,1.729845166,589.4395972
,111.2,147.9614083,5.834450091,364929.217,1.718940816,592.8892422
,111.4,149.0295798,5.892968185,367979.32,1.712834346,595.5685267
,111.6,150.0918342,5.952074783,371262.9091,1.707164045,598.8428372
,111.8,151.0254614,6.011783798,374195.8467,1.70258418,601.8103185
,112,152.2031638,6.072076667,377937.0737,1.695823448,605.1251769
,112.2,153.1436705,6.132991007,382053.8257,1.687099982,608.3468875
,112.4,154.1780877,6.194511137,385419.6468,1.682302024,611.8721404
,112.6,155.6936764,6.256617754,388087.3883,1.679248694,614.8275782
,112.8,156.7557655,6.319378276,388998.8023,1.684482609,618.0920285
,113,157.8094351,6.382769819,387993.2529,1.695386715,620.6036542
,113.2,158.9786413,6.44679029,385497.3347,1.711960996,622.7591414
,113.4,160.4834279,6.511429442,382808.6716,1.730716083,625.2302299
,113.6,161.653261,6.576738463,380953.1194,1.743801013,627.0624523
,113.8,163.0742316,6.642686676,380695.725,1.752088064,629.631068
,114,164.0325456,6.709327662,380920.6012,1.757321983,631.7306654
,114.2,165.3243558,6.776615771,382561.9096,1.757321849,634.1217574
,114.4,166.4047491,6.844593574,384950.4247,1.755577063,636.9599368
,114.6,168.0191306,6.913219016,387183.1468,1.752959886,639.3630882
,114.8,169.0901544,6.982569734,389195.5198,1.752087438,642.217705
,115,170.5554004,7.052591198,392492.6331,1.7451086,644.9693213
,115.2,171.6128907,7.123343053,396495.0366,1.735512791,647.9598197
,115.4,173.4339761,7.194755666,401791.8006,1.721991392,651.656037
,115.6,174.3273496,7.266946675,405848.6439,1.712831777,654.7078986
,115.8,175.5983023,7.339838032,410472.5738,1.703672119,658.4731428
,116,176.6636528,7.413475285,413196.7024,1.701054998,661.5765112
,116.2,178.3544938,7.487811305,414959.7563,1.702363334,664.5889387
,116.4,179.5818333,7.56292459,416296.7295,1.706288724,667.8764074
,116.6,180.9621271,7.638782547,415937.6836,1.715884272,670.8460928
,116.8,182.6642548,7.715381509,416714.4116,1.720245779,673.4169077
,117,184.053456,7.792770641,417301.4883,1.72504348,675.9986751
,117.2,185.2129221,7.870952297,416742.2401,1.735511387,679.0888967
,117.4,186.7249996,7.949896248,416108.3196,1.743798413,681.2706942
,117.6,188.3317905,8.029627135,416282.4399,1.750776932,684.1362825
,117.8,189.6356329,8.11017907,416362.8274,1.756010808,686.2424651
,118,191.0300266,8.19153433,417037.3668,1.761244673,689.0992842
,118.2,192.4276178,8.27370677,419217.5757,1.759936024,691.6613281
,118.4,194.3300563,8.356671644,422515.9667,1.756010319,694.8436133
,118.6,195.3987731,8.440525023,426422.9608,1.748159192,697.5678327
,118.8,196.5438931,8.525215749,430957.4161,1.739871892,701.0383043
,119,198.294519,8.610717504,434905.74,1.732893033,704.2501753
,119.2,199.7629858,8.697096692,437751.4224,1.729403543,707.2779443
,119.4,201.5990252,8.78431969,441171.6116,1.725041681,711.0103288
,119.6,203.0539036,8.872444117,442317.2579,1.728094703,714.348214
,119.8,205.0003085,8.961421612,441575.3297,1.735945513,716.7108316
,120,205.9041698,9.051361607,440990.2051,1.743796429,719.1413701
,120.2,207.4817461,9.142160836,441576.9308,1.749466438,722.3970728
,120.4,209.2438645,9.233860294,440972.2425,1.757317263,724.5975069
,120.6,210.9492654,9.3264848,439966.4173,1.767785094,727.213254
,120.8,212.327572,9.420061448,441782.2583,1.766912615,729.7073613
,121,213.937004,9.514562959,444889.0782,1.761678442,732.5839108
,121.2,215.4614286,9.610019566,447546.4425,1.759497448,735.9820686
,121.4,216.9174829,9.706439741,452241.5997,1.749465457,739.0131277
,121.6,218.5980025,9.80381386,459273.47,1.734199442,743.1904155
,121.8,220.3798612,9.902159596,462485.9804,1.730273757,746.1962778
,122,221.7164833,10.00152276,463582.4833,1.733762953,749.0925475
,122.2,223.8382827,10.10183256,465219.4785,1.736815902,752.6013969
,122.4,225.4549439,10.20318348,464506.6134,1.745975235,755.5776687
,122.6,227.2070467,10.30554361,464890.9305,1.75033672,758.1506854
,122.8,229.3641325,10.40890557,467402.3035,1.749464163,761.553242
,123,230.8813039,10.51334818,470365.2522,1.746410839,764.6248486
,123.2,232.5480546,10.61883025,472638.2791,1.745538333,767.684406
,123.4,234.3252824,10.72536487,475723.773,1.743793482,771.2918743
,123.6,236.0757184,10.83297163,477823.7799,1.743357134,774.1213104
,123.8,237.9823838,10.94164911,480334.769,1.742484604,777.6915239
,124,239.6958694,11.05143119,484443.4348,1.735505765,781.0436661
,124.2,241.6704032,11.16229918,488981.5574,1.728090735,784.7409975
,124.4,243.5025009,11.27429058,494292.8177,1.718931056,789.1517011
,124.6,245.1164558,11.38742147,497765.2236,1.714133063,792.5553467
,124.8,246.7734899,11.50168605,501370.1575,1.711515897,796.8170167
,125,248.5223389,11.53553013,501704.7032,1.717622045,799.9872547
,125.2,249.7316766,11.53545066,502287.8446,1.722855915,803.1136492
,125.4,250.9360227,11.53537153,503539.4934,1.727653619,806.7430227
,125.6,251.2011285,11.53535388,505132.4323,1.731579086,810.5257916
,125.8,251.9861857,11.5353022,505442.9259,1.736812998,813.220424
,126,252.3935502,11.53527524,507157.0775,1.738557619,816.4859696
,126.2,252.9955844,11.53523553,507572.0792,1.745100047,820.1405356
,126.4,253.3455463,11.53521233,505761.3589,1.755567994,822.5338088
,126.6,253.4475953,11.53520536,502868.2051,1.770397625,825.3489668
,126.8,253.9880673,11.53516969,500639.5253,1.781737883,827.4003499
,127,254.4411874,11.53513973,496986.7192,1.797439809,829.2851668
,127.2,254.4317589,11.53514006,494326.9557,1.810960953,831.6422704
,127.4,254.7792249,11.53511702,493730.5308,1.817503405,833.511743
,127.6,255.2880838,11.53508342,494764.7368,1.820120345,836.0244649
,127.8,255.2324836,11.53508677,497622.408,1.816412941,838.6511385
,128,255.4152291,11.53507451,504438.4926,1.801801363,842.08434
,128.2,255.5988065,11.5350622,510478.1499,1.789588697,845.3904264
,128.4,256.0777161,11.53503056,516322.2105,1.779120665,849.2071697
,128.6,256.351973,11.53501231,520050.6469,1.773886646,852.1713629
,128.8,256.2888855,11.53501615,523142.154,1.772141988,855.7053742
,129,256.3451788,11.53501218,523281.6649,1.777375972,858.3802661
,129.2,256.6751745,11.53499028,523426.9272,1.782609928,860.9390089
,129.4,256.8662391,11.53497749,526043.8024,1.781737576,864.3404307
,129.6,256.9528976,11.53497152,527966.2479,1.7813014,867.0405275
,129.8,256.9388935,11.53497215,528288.6506,1.786535392,870.0923799
,130,257.1711383,11.53495665,527969.8704,1.792641689,872.4867475
,130.2,257.3239345,11.53494636,525844.9308,1.804854316,875.1495886
,130.4,257.3057708,11.53494726,522643.4295,1.818375459,876.7604391
,130.6,257.6212078,11.53492632,519250.0313,1.833205064,878.6803209
,130.8,257.6280017,11.53492558,517084.7592,1.843236877,880.2133699
,131,257.6402032,11.53492449,514953.5227,1.852832524,881.7014902
,131.2,257.7588906,11.53491643,511465.8648,1.866789818,883.2400216
,131.4,257.686236,11.5349209,509699.183,1.875076976,884.7336199
,131.6,257.9929378,11.53490053,509029.2599,1.8794386,886.084771
,131.8,257.9635431,11.53490216,509339.9423,1.881619432,887.843557
,132,258.0863902,11.53489383,511261.6261,1.879002423,889.6100182
,132.2,258.2458418,11.5348831,513457.9261,1.875949244,891.4608579
,132.4,258.1365826,11.53488996,514943.6805,1.87551309,893.4146982
,132.6,258.4857124,11.53486682,514364.0935,1.880747041,894.7055808
,132.8,258.5411738,11.53486289,514275.9201,1.884672535,896.3482131
,133,258.4826619,11.53486643,512146.6802,1.893832021,897.3640322
,133.2,258.7444399,11.53484901,511518.0841,1.898193647,898.5146498
,133.4,258.5553162,11.5348611,510605.7994,1.903863825,899.7748332
,133.6,258.7164317,11.53485026,511068.1668,1.905172304,901.1928255
,133.8,258.7111628,11.53485031,509150.0516,1.913459453,901.9204484
,134,258.9255212,11.53483599,510510.4986,1.911714766,903.1773568
,134.2,259.1398797,11.53482167,512086.5133,1.909970078,904.7564356
,134.4,258.6354576,11.5348544,513724.8972,1.907353139,906.0933207
,134.6,258.9288486,11.5348349,515192.5081,1.905608442,907.6789765
,134.8,259.0891322,11.53482412,516897.5656,1.902555267,909.1024478
,135.5,259.3588738,11.47772645,1.7977E+308,1.940501653,0
,135.7,259.0200315,11.36243726,1.7977E+308,1.89295962,0
,135.9,258.7028191,11.24714664,1.7977E+308,1.774322556,0
,136.1,258.5761168,11.13184356,1.7977E+308,1.574558622,0
,136.3,258.4793637,11.01653852,1.7977E+308,1.322454784,0
,136.5,258.2486711,10.90124224,1.7977E+308,0.992277268,0
,136.7,258.0146509,10.78594618,1.7977E+308,0.65294026,0
,136.9,257.7789668,10.67065023,1.7977E+308,0.39473009,0
,137.1,257.6356261,10.55534824,1.7977E+308,0.203253286,0
,137.3,257.44237,10.44004951,1.7977E+308,0.075456693,0
,137.5,257.0328143,10.32476495,1.7977E+308,0.012212644,0
,137.7,256.8853139,10.20946322,1.7977E+308,0.007850986,0
,137.9,256.4815816,10.09417828,1.7977E+308,0.008723318,0
,138.1,256.2733509,9.97888053,1.7977E+308,0.019191299,0
,138.3,256.0867502,9.863581367,1.7977E+308,0.022680626,0
,138.5,255.9117964,9.748281443,1.7977E+308,0.023989124,0
,138.7,255.4631403,9.632999436,1.7977E+308,0.020063632,0
,138.9,255.3023291,9.517698585,1.7977E+308,0.012648811,0
,139.1,255.0516704,9.402403617,1.7977E+308,0.009159484,0
,139.3,254.7693987,9.287110717,1.7977E+308,0.012648812,0
,139.5,254.5811341,9.171811664,1.7977E+308,0.020063633,0
,139.7,254.4153314,9.05651114,1.7977E+308,0.026606122,0
,139.9,254.0631782,8.941222816,1.7977E+308,0.027478455,0
,140.1,254.0254915,8.825913904,1.7977E+308,0.023552961,0
,140.3,253.7523709,8.710620406,1.7977E+308,0.021372132,0
,140.5,253.4908972,8.595326145,1.7977E+308,0.016574307,0
,140.7,253.3891525,8.480021428,1.7977E+308,0.013521145,0
,140.9,253.2716013,8.364717745,1.7977E+308,0.020063635,0
,141.1,253.0841687,8.249418637,1.7977E+308,0.03140395,0
,141.3,252.8626272,8.134121762,1.7977E+308,0.037510274,0
,141.5,252.2900146,8.018847871,1.7977E+308,0.040999603,0
,141.7,252.2539917,7.90353885,1.7977E+308,0.042308102,0
,141.9,251.90683,7.788250199,1.7977E+308,0.040999604,0
,142.1,251.6836246,7.672953433,1.7977E+308,0.041435771,0
,142.3,251.7840371,7.557635481,1.7977E+308,0.041435771,0
,142.5,251.4693203,7.442344706,1.7977E+308,0.034457115,0
,142.7,250.8018684,7.327077024,1.7977E+308,0.031840121,0
,142.9,250.4771686,7.211786902,1.7977E+308,0.026169963,0
,143.1,250.1790902,7.096495038,1.7977E+308,0.021372136,0
,143.3,250.0224386,6.981193915,1.7977E+308,0.017446642,0
,143.5,250.0429865,6.865881191,1.7977E+308,0.022244469,0
,143.7,249.8397473,6.750583118,1.7977E+308,0.017882808,0
,143.9,249.2854368,6.635308028,1.7977E+308,0.016574311,0
,144.1,249.1903475,6.520002875,1.7977E+308,0.019627474,0
,144.3,248.7633212,6.404719452,1.7977E+308,0.025733799,0
,144.5,248.506007,6.289424919,1.7977E+308,0.023989135,0
,144.7,248.3235658,6.174125485,1.7977E+308,0.023552969,0
,144.9,248.1536034,6.058825233,1.7977E+308,0.021372139,0
,145.1,247.6468041,5.942970477,1.7977E+308,0.025733801,0
,145.3,247.3777972,5.827964988,1.7977E+308,0.030967795,0
,145.5,247.3426063,5.712655913,1.7977E+308,0.039691118,0
,145.7,247.1705183,5.597644078,1.7977E+308,0.047542108,0
,145.9,246.9897409,5.482344534,1.7977E+308,0.05757393,0
,146.1,246.4741147,5.367066912,1.7977E+308,0.060190929,0
,146.3,246.480104,5.251755142,1.7977E+308,0.058010098,0
,146.5,246.1458369,5.136465646,1.7977E+308,0.05452077,0
,146.7,245.7354489,5.021181135,1.7977E+308,0.054520771,0
,146.9,245.3292205,4.905896351,1.7977E+308,0.049722945,0
,147.1,245.397604,4.790580495,1.7977E+308,0.046887864,0
,147.3,245.1885412,4.675282803,1.7977E+308,0.044488951,0
,147.5,244.7760734,4.559998428,1.7977E+308,0.04361662,0
,147.7,244.6560264,4.444694908,1.7977E+308,0.038382626,0
,147.9,244.2086178,4.32941282,1.7977E+308,0.037510294,0
,148.1,243.9762612,4.214116653,1.7977E+308,0.037074129,0
,148.3,243.5271887,4.098834674,1.7977E+308,0.038818795,0
,148.5,243.5593835,3.983521188,1.7977E+308,0.037946462,0
,148.7,243.1914235,3.868233898,1.7977E+308,0.040999627,0
,148.9,242.8193039,3.752946881,1.7977E+308,0.03838263,0
,149.1,242.4513439,3.637659592,1.7977E+308,0.032712469,0
,149.3,242.4502618,3.522348284,1.7977E+308,0.026606142,0
,149.5,241.9491941,3.407069709,1.7977E+308,0.020935981,0
,149.7,241.8241555,3.291766516,1.7977E+308,0.012648822,0
,149.9,241.3072813,3.176488976,1.7977E+308,0.006106328,0
,150.1,241.0183539,3.061196513,1.7977E+308,0.013521155,0
,150.3,240.5114628,2.945918319,1.7977E+308,0.021372149,0
,150.5,240.4022307,2.830614091,1.7977E+308,0.023989147,0
,150.7,240.1141352,2.715321573,1.7977E+308,0.027478478,0
,150.9,239.855989,2.600027095,1.7977E+308,0.023989148,0
,151.1,239.4306262,2.484743563,1.7977E+308,0.012212658,0
,151.3,239.0992707,2.369453878,1.7977E+308,0.003489331,0
,151.5,238.8760652,2.254157112,1.7977E+308,0.005670163,0
,151.7,238.5613481,2.138866337,1.7977E+308,0.013521157,0
,151.9,238.1201788,2.02358384,1.7977E+308,0.018318988,0
,152.1,237.6848329,1.908300962,1.7977E+308,0.020063654,0
,152.3,237.4666189,1.793003869,1.7977E+308,0.019627488,0
,152.5,237.1161292,1.677715436,1.7977E+308,0.013957325,0
,152.7,236.6125656,1.562437024,1.7977E+308,0.004361664,0
,152.9,236.4833673,1.447134104,1.7977E+308,0.005670163,0
,153.1,236.0754748,1.331849429,1.7977E+308,0.015701991,0
,153.3,235.6634227,1.216565026,1.7977E+308,0.02573382,0
,153.404,235.2380468,1.156630957,1.7977E+308,0.029223152,0
,228.7,234.6287282,0.991666633,1.7977E+308,0.016138158,0
,228.9,234.1509542,0.876386533,1.7977E+308,0.023552988,0
,229.1,233.696474,0.761104907,1.7977E+308,0.034020983,0
,229.3,233.4433192,0.645810102,1.7977E+308,0.040999647,0
,229.5,233.140249,0.530518565,1.7977E+308,0.035329484,0
,229.7,232.5027457,0.415248921,1.7977E+308,0.028350821,0
,229.9,231.9825435,0.299971599,1.7977E+308,0.020063659,0
,230.1,231.0447159,0.184721617,1.7977E+308,0.020499826,0
,230.3,230.2874156,0.069459817,1.7977E+308,0.033584824,0
,230.416,229.6324304,0.002622097,1.7977E+308,0.039691157,0
END,,,,,,