File: GB1_test 51.csv
Segment,Time On Sample,Displacement Into Surface,Load On Sample,Harmonic Contact Stiffness,Harmonic Displacement,Harmonic Load
Surface Marker,0,0,0,203.5846436,0.543557531,2.188158718
,0.3,-0.094085751,0.00099129,3943.668666,0.281376091,2.310879684
,0.6,0.127182477,0.001958618,16363.13573,0.141778649,2.437983559
,0.9,0.106318637,0.002945107,23289.5359,0.111677951,2.53988579
,1.2,0.061324849,0.003933177,28546.72966,0.100771902,2.818199417
,1.5,0.550518176,0.00488622,30485.26923,0.105570561,3.13486339
,1.8,0.577914231,0.005869543,29069.77967,0.123892724,3.488781907
,2.1,0.435568588,0.006863998,30325.29111,0.137416227,4.036643376
,2.4,0.621889468,0.0078369,35757.38562,0.137416225,4.776256387
,2.7,0.579392009,0.008824019,43334.17577,0.133053806,5.640781791
,3,0.456184095,0.00981606,44858.90787,0.142651131,6.300406997
,3.3,0.57510772,0.010792223,45781.44625,0.169261891,7.702932397
,3.6,0.615817034,0.011773516,42466.74566,0.208087427,8.84358003
,3.9,0.764695076,0.012747715,39577.7384,0.253456592,10.12886309
,4.2,0.988459158,0.013717004,39260.91631,0.289228431,11.52919711
,4.5,0.660146697,0.014722494,39481.28256,0.327617731,13.13114396
,4.8,0.765341214,0.015699558,40242.7793,0.361644604,14.68049627
,5.1,0.501929987,0.016700792,39289.31404,0.411376196,16.16410504
,5.4,0.612116908,0.017677528,37498.65301,0.48073867,17.84165695
,5.7,0.775140091,0.0186508,33899.4346,0.581728684,19.32471806
,6,0.278334027,0.019667338,30648.3085,0.685336175,20.48454054
,6.3,-0.389877892,0.020695116,27010.38412,0.829732302,21.8498109
,6.6,-1.126319347,0.021727367,23163.79652,0.987651956,22.52915865
,6.9,-0.276424674,0.022655599,17604.1422,1.278189081,22.8118557
,7.2,0.838067312,0.023566481,13491.80307,1.602316801,22.44478922
,7.5,1.260695435,0.02452273,11410.15455,1.839632394,22.05690355
,7.8,0.564609303,0.025552336,11861.1373,1.802988139,22.35932265
,8.1,1.330881154,0.026486051,14933.90035,1.531645559,23.53722533
,8.4,0.713425369,0.027510501,20758.08162,1.209699025,25.15122485
,8.7,0.799066308,0.028488847,26410.3821,1.028658598,26.68194987
,9,1.064849781,0.02945538,27906.09304,1.012953872,27.68782375
,9.3,0.978252823,0.03044502,26579.11327,1.093658643,28.55234911
,9.6,1.065141862,0.031423284,24831.37785,1.191813083,29.24703756
,9.9,0.862887573,0.032420508,23593.42394,1.273390348,29.87050369
,10.2,0.861993529,0.033404529,22696.33418,1.341444097,30.40740802
,10.5,1.003382966,0.034379219,22086.39415,1.401209239,30.95636529
,10.8,1.0815353,0.035358056,21593.14736,1.458793174,31.43848349
,11.1,1.070656451,0.036342731,21534.88841,1.489330114,31.90087851
,11.4,0.853840986,0.03734091,21807.2056,1.498054972,32.42792114
,11.7,1.086757807,0.038309599,22430.08949,1.485403936,33.03823893
,12,0.95938956,0.039301912,23527.82186,1.4443972,33.68471545
,12.3,1.464392327,0.04025276,24902.49695,1.399464238,34.46925354
,12.6,1.240504297,0.041251403,26488.31433,1.352786364,35.29323711
,12.9,1.847019242,0.042195594,27385.17912,1.341444028,36.04052059
,13.2,1.490000479,0.043202966,28075.77574,1.336209152,36.74397453
,13.5,1.76368858,0.044168982,28334.23173,1.348423907,37.43537591
,13.8,1.687908498,0.045157913,28859.78156,1.348860155,38.16184028
,14.1,2.097223532,0.046115035,29704.65501,1.336209108,38.88063484
,14.4,1.640356721,0.047128954,30650.98143,1.324866851,39.67722505
,14.7,1.834998446,0.048100153,31410.45157,1.321376902,40.47600724
,15,1.880700161,0.049081118,31556.58848,1.339699061,41.20356754
,15.3,2.269213513,0.050039604,31443.61425,1.367182276,41.93441497
,15.6,2.128532201,0.051032791,31386.87516,1.39030311,42.61924183
,15.9,2.199195927,0.052012119,31625.44236,1.40033667,43.2996858
,16.2,2.118423444,0.053001378,32007.75307,1.405135339,43.9713641
,16.5,2.328042372,0.053971594,32392.31488,1.412987678,44.69563706
,16.8,2.050069991,0.054973783,32676.70656,1.425202475,45.39361241
,17.1,2.438583341,0.05593227,32825.20758,1.439162187,46.01927058
,17.4,2.250474206,0.056928566,33055.58535,1.452685703,46.79613811
,17.7,2.263724782,0.057914938,33347.50753,1.459229332,47.47877331
,18,2.00572201,0.058915818,33473.35547,1.470571644,48.05402773
,18.3,2.221165931,0.059882374,33662.73494,1.483222644,48.7585778
,18.6,1.917399467,0.060886254,33504.81544,1.506779735,49.34478933
,18.9,2.194415832,0.061852052,33526.30648,1.522484423,49.92880985
,19.2,2.083688934,0.062843274,33556.28172,1.539061627,50.5566591
,19.5,3.053817157,0.063763623,33757.67023,1.548222626,51.14287211
,19.8,2.636889588,0.064774924,33869.687,1.560873678,51.72470073
,20.1,3.310801921,0.065714696,34052.21263,1.568289733,52.272563
,20.4,3.101891119,0.066712357,34852.83933,1.551276317,52.96286829
,20.7,3.396380874,0.067677008,36434.89424,1.506779615,53.78356509
,21,3.322264933,0.068665831,38924.4914,1.438725881,54.82121488
,21.3,3.257301728,0.069654052,41363.53565,1.381141952,55.90926764
,21.6,3.348767126,0.070632017,42600.58463,1.360638575,56.76721907
,21.9,3.245944872,0.071622721,43215.91405,1.361511067,57.71173193
,22.2,3.335746136,0.072600795,42828.36315,1.392484237,58.60912943
,22.5,3.172182692,0.073597342,42352.5926,1.425202395,59.39476231
,22.8,3.379303056,0.074582521,42024.32588,1.453121864,60.14314166
,23.1,3.97374829,0.075556921,41315.87895,1.495437281,60.8761813
,23.4,3.598832997,0.076610305,41167.46741,1.518776257,61.52704018
,23.7,4.081360344,0.077622672,41058.15192,1.542551399,62.19817128
,24,3.811696588,0.078700246,41803.79593,1.536444038,62.93504464
,24.3,4.210596127,0.079749989,42777.95686,1.52466547,63.802858
,24.6,3.815285154,0.080867897,44023.11155,1.504162137,64.71121168
,24.9,4.021555999,0.081962876,44789.3741,1.498490973,65.56697175
,25.2,4.054338216,0.083085951,45154.68346,1.506779567,66.49504923
,25.5,4.248538741,0.084215359,45183.29088,1.522048018,67.26534289
,25.8,4.045840576,0.085387976,45392.13438,1.531209117,68.05097596
,26.1,4.174718299,0.08655654,45684.35967,1.537316493,68.79497204
,26.4,4.228291167,0.087747595,46026.84238,1.543423876,69.60142449
,26.7,4.399598636,0.088949041,46592.66125,1.542551378,70.43636552
,27,4.041292539,0.090203609,47235.34967,1.538843353,71.28061973
,27.3,4.371518945,0.091431503,48037.99212,1.532517817,72.24649994
,27.6,4.189605113,0.092711862,48211.79397,1.544296365,73.07486644
,27.9,4.548531775,0.093975951,47959.61299,1.569162123,73.7925656
,28.2,3.972212063,0.095320694,47705.11018,1.592282995,74.42150964
,28.5,4.354430382,0.096622406,47818.01506,1.605370219,75.14907036
,28.8,4.185401122,0.097980344,48053.72337,1.612350105,75.8492372
,29.1,4.469013084,0.099328881,48126.76976,1.625001096,76.58885061
,29.4,4.48968863,0.100715078,48036.0504,1.641578287,77.2364232
,29.7,4.595231652,0.102116821,48239.54395,1.64899439,77.9048143
,30,4.827245502,0.103531359,48752.91952,1.645504435,78.54143008
,30.3,4.890346347,0.104978416,49567.95474,1.635907108,79.37198806
,30.6,4.568196684,0.106472743,50129.86486,1.633289686,80.13022802
,30.9,4.875918209,0.107947865,50781.42703,1.628490998,80.89723447
,31.2,4.869946906,0.109466071,51319.10413,1.628490999,81.72012278
,31.5,5.042034299,0.110995467,51807.11905,1.628927226,82.50466068
,31.8,4.920398367,0.112567303,52277.2852,1.628927237,83.26618823
,32.1,5.133249596,0.114140865,52663.71686,1.630672186,83.98607838
,32.4,4.773634938,0.115775952,53498.96012,1.621074897,84.84074182
,32.7,5.49570346,0.117364468,54001.40665,1.621074833,85.65596116
,33,5.43146482,0.119028989,54420.05746,1.623256049,86.48213668
,33.3,5.565254135,0.120705551,54730.49224,1.629363424,87.34337495
,33.6,5.838826657,0.122398342,55250.93057,1.628927158,88.1618811
,33.9,5.886072877,0.124131732,55839.5718,1.627182187,88.96504592
,34.2,5.464029185,0.125922076,56463.39272,1.624564774,89.76711452
,34.5,5.998026173,0.127676328,56860.96481,1.628927145,90.60863064
,34.8,5.50358414,0.129525005,56970.15499,1.639833237,91.37782755
,35.1,6.144077046,0.13132667,57056.99761,1.65161171,92.19085524
,35.4,5.998262307,0.133207564,57546.50094,1.651175482,93.01483906
,35.7,6.239353197,0.135097606,58925.58094,1.6276184,93.99441566
,36,6.211683964,0.137021062,60597.26559,1.598390198,94.99809849
,36.3,6.526820639,0.138957632,62201.25115,1.575705594,96.16285251
,36.6,6.551561313,0.140942492,62716.03932,1.580068011,97.14023809
,36.9,6.721908931,0.14294777,62131.48455,1.609732443,97.9554561
,37.2,6.853144601,0.144985833,61653.1899,1.635034459,98.66767698
,37.5,7.303889078,0.147033584,61411.22397,1.65422906,99.44344969
,37.8,7.39850398,0.149135833,62399.001,1.642886764,100.386868
,38.1,7.563839508,0.151265256,63850.80385,1.621947141,101.5220372
,38.4,7.386358346,0.153449524,65338.40504,1.601880033,102.6320048
,38.7,7.611592324,0.155640213,66154.8277,1.597953837,103.671846
,39,7.667911469,0.15787508,67048.60326,1.591846447,104.6448489
,39.3,7.864844542,0.160134496,68394.51152,1.580067901,105.9514989
,39.6,7.719792702,0.162450557,69551.2513,1.570034352,107.0674929
,39.9,7.783584126,0.164787613,71105.2767,1.554765883,108.3538716
,40.2,8.030424657,0.167147881,71951.21431,1.55607459,109.6643577
,40.5,8.333007997,0.16954013,72986.9571,1.553020867,110.9584073
,40.8,8.112631542,0.172003123,73421.44394,1.558255795,111.9861952
,41.1,8.413539092,0.174468803,74172.80365,1.560873214,113.347084
,41.4,8.594207029,0.176979832,74391.67389,1.57221549,114.5359444
,41.7,8.775701011,0.17952868,74059.73342,1.592936957,115.5177127
,42,8.851516362,0.182123121,73743.95332,1.614094682,116.4940026
,42.3,9.330461876,0.184730098,73697.23995,1.631108066,117.583153
,42.6,9.558532998,0.187392854,74462.83108,1.628054357,118.5747832
,42.9,9.847338568,0.190092028,75990.86605,1.612349623,119.8633547
,43.2,9.66352371,0.192863139,77531.37494,1.596208698,121.1464459
,43.5,10.27723822,0.195623539,79556.43653,1.573960313,122.6158129
,43.8,9.752678725,0.198500727,80626.25207,1.570034183,123.9810824
,44.1,10.28067684,0.201351781,81383.20332,1.572215346,125.2543141
,44.4,10.01737256,0.204298338,81705.78275,1.582685172,126.5647987
,44.7,10.24914096,0.207256618,81795.02893,1.596208648,127.8062534
,45,10.05446802,0.210287745,81759.32445,1.609295919,128.8767748
,45.3,10.42226493,0.213327651,81441.15861,1.628490524,130.0601566
,45.6,10.4630523,0.216435071,81073.31119,1.647685159,131.1109558
,45.9,10.22758605,0.219607564,80783.72631,1.666007335,132.1431258
,46.2,10.31828234,0.222806576,80757.48977,1.677785855,133.0712044
,46.5,10.66233527,0.22603725,81490.18183,1.67691334,134.21514
,46.8,10.52794203,0.229348407,82814.57605,1.664698584,135.425914
,47.1,10.67477943,0.232690938,84396.40408,1.649866351,136.6607942
,47.4,10.60360729,0.23609845,85552.11607,1.645940182,137.9581311
,47.7,11.00836917,0.23952595,85372.46572,1.6642623,139.0374193
,48,10.91637894,0.243038097,84642.21205,1.688691847,139.8142872
,48.3,11.33360513,0.246569718,83310.09431,1.724463632,140.615262
,48.6,11.14008584,0.250195072,83325.84203,1.733624728,141.4995105
,48.9,11.65714282,0.253828371,83948.50875,1.730570987,142.3629418
,49.2,11.2081616,0.257580292,85486.32059,1.714430085,143.6153523
,49.5,11.66529206,0.261329009,86531.98506,1.707886416,144.7538099
,49.8,11.54828747,0.265172278,86334.70066,1.72097368,145.5635497
,50.1,12.23921043,0.269020264,86199.50437,1.733188384,146.4072588
,50.4,12.65970244,0.272944356,86117.52529,1.74496687,147.2871269
,50.7,13.39387421,0.276906634,86528.45389,1.74758425,148.1987711
,51,13.53310875,0.280968366,87712.757,1.736241953,149.1893062
,51.3,13.75137986,0.285086206,89250.42125,1.720537232,150.3946022
,51.6,13.68424221,0.289285207,91486.67439,1.694362737,151.746725
,51.9,13.95907386,0.293525074,93180.6876,1.679094253,153.0977522
,52.2,13.90106869,0.29785085,94655.18105,1.667751975,154.403855
,52.5,14.4046981,0.302204933,95428.96681,1.668624413,155.7066717
,52.8,14.52806261,0.306649893,95994.34898,1.672114335,156.9733288
,53.1,15.19974591,0.31114103,96279.01792,1.67909414,158.1150749
,53.4,14.94533066,0.315746354,96419.98217,1.688255239,159.2633927
,53.7,15.08114607,0.320379753,96626.69781,1.696107577,160.4106148
,54,15.3583992,0.325089429,97263.82773,1.696107552,161.522776
,54.3,15.55825886,0.329875107,98544.47024,1.687818942,162.9461209
,54.6,15.18231702,0.334770811,100384.1534,1.672114278,164.4143894
,54.9,15.87723309,0.33966974,101615.5936,1.665134348,165.6832394
,55.2,15.99135491,0.344681171,103199.0437,1.65771823,167.3038154
,55.5,16.21196919,0.349761386,104571.8915,1.651610828,168.7939996
,55.8,15.83764371,0.354957574,105983.1854,1.645067237,170.337873
,56.1,16.33447942,0.360174683,107058.0751,1.642449743,171.808335
,56.4,16.148176,0.365515589,107018.9452,1.65553701,173.2163398
,56.7,16.49895869,0.370901792,106458.9376,1.673859126,174.2846709
,57,17.02695853,0.376358117,105906.8096,1.693926192,175.5250333
,57.3,18.189812,0.381854678,106362.9276,1.697852259,176.7445784
,57.6,18.65787672,0.387480348,107622.2459,1.691308592,178.1514906
,57.9,18.67037159,0.393220911,109884.2436,1.672113958,179.8246594
,58.2,18.90959079,0.399033094,112311.8019,1.651610589,181.4605766
,58.5,19.374286,0.404918312,114460.9175,1.638087053,183.2641391
,58.8,19.25984887,0.410930653,115870.3584,1.635033378,185.0227755
,59.1,19.55186174,0.41700696,116159.3294,1.644630663,186.4987159
,59.4,19.50812123,0.423197209,116197.2518,1.657717918,188.0141015
,59.7,19.69443222,0.429465793,116318.6583,1.669060175,189.4944249
,60,19.83870877,0.435831959,116823.0884,1.673422584,190.8377827
,60.3,20.20554779,0.442279612,117228.9557,1.680402408,192.3969992
,60.6,19.80520612,0.448875472,117935.2144,1.680838695,193.7556942
,60.9,20.09504769,0.455525207,119021.6817,1.67778497,195.3751751
,61.2,20.3049949,0.462280749,120154.3319,1.675167507,197.0236925
,61.5,20.80573305,0.469119274,121137.52,1.675167459,198.5659259
,61.8,20.6116794,0.476106927,121144.4178,1.688254725,199.985983
,62.1,21.09199874,0.483155527,121184.3379,1.700033202,201.2767474
,62.4,20.93244216,0.490352853,120915.8883,1.716174154,202.5861368
,62.7,21.30497467,0.497623942,120923.9138,1.72795264,203.8999103
,63,21.30264384,0.50502968,121237.6812,1.73362378,205.0646655
,63.3,21.82200081,0.512512727,122554.3296,1.728388833,206.6162121
,63.6,22.00268881,0.520131271,124343.5926,1.716610296,208.2159707
,63.9,22.15465229,0.527866424,125370.167,1.714429075,209.7521746
,64.2,22.05115286,0.535735242,125169.8654,1.725771364,210.9640457
,64.5,22.55587497,0.543682794,124062.319,1.749328356,212.0729196
,64.8,22.90997397,0.551760488,123607.1354,1.765033016,213.1489236
,65.1,22.70490507,0.559997064,124543.8258,1.762851829,214.3498341
,65.4,23.10223233,0.568318375,125448.2034,1.761979308,215.6625145
,65.7,23.4870586,0.576766251,126496.7335,1.758925581,217.0442233
,66,24.0590795,0.5853292,126684.2472,1.764596665,218.1278986
,66.3,24.52041501,0.594028931,127659.7719,1.761979172,219.5380965
,66.6,25.23634185,0.60284326,129351.9175,1.749764343,220.8880337
,66.9,25.37728978,0.611828921,131584.2177,1.733623397,222.5283319
,67.2,25.19870275,0.620971424,132776.3426,1.729697242,224.0042715
,67.5,25.38620287,0.630227732,132794.122,1.740167018,225.3432459
,67.8,26.03048505,0.639593796,132464.3051,1.754126682,226.6077165
,68.1,26.5599196,0.649108855,133044.694,1.756744079,227.8951937
,68.4,26.55680901,0.658802857,134194.6187,1.752817908,229.3689433
,68.7,26.67432472,0.668635331,134306.6154,1.760234,230.6739501
,69,27.02063499,0.678601245,134515.6523,1.765468864,231.8156975
,69.3,27.88197018,0.688683682,134272.4175,1.777247297,233.0659227
,69.6,27.73648129,0.698984814,135153.9449,1.775066105,234.2328689
,69.9,28.23332261,0.709399205,137314.2437,1.759797609,235.8019472
,70.2,28.34822064,0.719996086,140384.1185,1.736676807,237.7238487
,70.5,28.92655392,0.730722725,143915.0238,1.708757307,239.5854859
,70.8,28.84836139,0.741654728,147052.74,1.688690213,241.7166693
,71.1,29.16120764,0.75276365,148874.2936,1.682146565,243.5388588
,71.4,29.40664175,0.763970049,148972.3623,1.693925058,245.2865416
,71.7,29.82927297,0.775371907,148017.6177,1.715300843,246.8161734
,72,30.25104471,0.786946246,147236.6459,1.732314214,248.0357178
,72.3,30.56212393,0.798702455,147092.2616,1.743656459,249.5620622
,72.6,30.76500633,0.810643544,148050.0218,1.743220198,251.1278544
,72.9,31.30235051,0.822743038,150001.4471,1.733622839,252.8952596
,73.2,31.1923184,0.835068061,152393.6858,1.72009937,254.7404592
,73.5,31.75706213,0.84753448,154120.6642,1.714428181,256.6579785
,73.8,32.84015288,0.860155112,154517.7872,1.721407939,258.3706039
,74.1,33.46973744,0.872996271,153417.2718,1.741474976,259.6602742
,74.4,34.22659705,0.886023906,152975.5615,1.754998381,261.1285514
,74.7,34.41429238,0.899286157,153217.6798,1.76110574,262.6176401
,75,34.51791727,0.912754,154734.3195,1.754125871,264.1374113
,75.3,34.76337705,0.926415751,156834.984,1.7440923,266.0439715
,75.6,35.01837281,0.940283045,158721.353,1.734931211,267.7160495
,75.9,36.04424408,0.95430902,160368.5655,1.729696217,269.6028928
,76.2,35.89187673,0.968624485,161054.1767,1.734058647,271.4765811
,76.5,36.86525977,0.98308205,161069.5541,1.742783375,272.8648693
,76.8,37.0984857,0.997806973,161365.9727,1.750635699,274.5062666
,77.1,37.56756688,1.012738629,161686.5076,1.756743024,275.962487
,77.4,37.9242833,1.027903519,163455.1281,1.749763136,277.7671475
,77.7,38.38205928,1.043290701,165336.2083,1.741910747,279.6824768
,78,39.09108207,1.058893838,167737.8131,1.728823452,281.5791807
,78.3,39.81338039,1.074731979,169823.528,1.720971036,283.745433
,78.6,39.77804505,1.090859374,171089.6836,1.720098568,285.7527993
,78.9,40.5119155,1.107179641,172113.1563,1.721843456,287.7130553
,79.2,40.97740563,1.123764158,173038.8178,1.723588378,289.5757909
,79.5,41.57390623,1.140590544,173542.9268,1.729695694,291.462632
,79.8,41.75350163,1.157698778,175200.989,1.724897028,293.3894657
,80.1,42.62616639,1.175019712,176876.5469,1.721407017,295.5157238
,80.4,42.88056499,1.192643135,179733.582,1.708319763,297.8890665
,80.7,43.40451041,1.210515057,181238.8076,1.705266027,299.7923421
,81,43.88389738,1.228660086,181455.3975,1.714863284,301.8545009
,81.3,44.59372291,1.24706353,181660.7698,1.723151796,303.6525885
,81.6,45.15498067,1.265754307,181900.8577,1.731876561,305.5799739
,81.9,45.46990217,1.284744045,182911.6808,1.733621495,307.587342
,82.2,45.69741126,1.304026176,183787.9215,1.73623892,309.4719915
,82.5,46.18614251,1.323582336,185066.2495,1.736238873,311.5286683
,82.8,46.75886535,1.343428511,187127.7709,1.730131446,313.7025923
,83.1,47.67767963,1.363551483,189894.2061,1.718352854,315.9608867
,83.4,48.48994121,1.383985477,193149.9089,1.70439307,318.5522838
,83.7,48.99512165,1.404748622,194529.0281,1.705265505,320.8620741
,84,49.45532067,1.425828712,194676.6766,1.713990278,322.7237149
,84.3,50.25328746,1.447204826,193555.6979,1.734057281,324.6982162
,84.6,50.63433835,1.468931341,193272.9364,1.746271988,326.5488998
,84.9,51.39226247,1.490961214,193662.0863,1.753251768,328.4554659
,85.2,52.1085304,1.513326748,194471.9426,1.756305384,330.3368331
,85.5,52.67414087,1.536039996,195083.0972,1.761103978,332.2565459
,85.8,52.93765723,1.559116315,195457.1933,1.766338842,333.8420638
,86.1,53.39415723,1.582528454,196840.7809,1.765902557,335.9929737
,86.4,54.34484748,1.606261752,199413.4343,1.754123965,337.9488521
,86.7,55.31212197,1.63035254,202860.1703,1.737546725,340.4142399
,87,55.86746649,1.654834729,207099.9823,1.716170878,343.2729924
,87.3,56.73477645,1.679666177,207977.5084,1.720096962,345.6901678
,87.6,57.57872894,1.704874308,208173.034,1.727076733,347.6405677
,87.9,57.93669511,1.730495313,208720.0563,1.733184068,349.8528377
,88.2,58.8029912,1.756470023,210416.6517,1.730130301,352.1275726
,88.5,59.11007748,1.782874056,214065.6519,1.71486185,354.8866087
,88.8,60.52789215,1.809693996,217883.4677,1.700465777,357.8428898
,89.1,60.88062846,1.836808989,219954.1302,1.697848301,360.4211319
,89.4,61.60937828,1.86440005,221520.3956,1.699593195,363.1429219
,89.7,62.28148143,1.892411704,221168.8079,1.71398907,365.4658635
,90,63.17567848,1.920831881,220602.3203,1.727948682,367.4053073
,90.3,63.5214768,1.949717754,219665.7041,1.74583451,369.5474508
,90.6,64.46046762,1.979000901,220651.7506,1.748888103,371.7871242
,90.9,64.96837873,2.00875509,222196.6045,1.748015573,374.1648513
,91.2,66.22923655,2.038909003,223307.2684,1.749324173,376.3574119
,91.5,66.80107268,2.069564091,224125.0143,1.752814042,378.6189919
,91.8,67.65407274,2.100664603,225415.1038,1.7532502,380.8674308
,92.1,68.18540515,2.132256984,228522.5763,1.741907898,383.401846
,92.4,69.18261758,2.164295959,230479.5854,1.739726601,385.9669513
,92.7,69.56360964,2.196859132,232062.3734,1.739726564,388.459728
,93,70.09512716,2.229903895,232407.0261,1.746270118,390.4813483
,93.3,71.02762022,2.263421176,235042.3086,1.739290181,393.2688813
,93.6,72.03699867,2.297439631,240238.874,1.717041831,396.5440164
,93.9,72.58824416,2.33200232,244930.9925,1.697847204,399.5364469
,94.2,73.19931524,2.367083197,248690.898,1.688686107,403.0756474
,94.5,74.50673952,2.402648139,248946.4394,1.697847023,405.5169369
,94.8,75.3252408,2.43878269,248271.9528,1.713551602,408.0721781
,95.1,76.22644559,2.475457868,247330.9384,1.731001116,410.6723438
,95.4,77.72956036,2.512647464,246953.3301,1.741906984,412.7849195
,95.7,78.59605697,2.550441021,245885.6215,1.757175299,415.0048691
,96,79.3422296,2.588813394,245578.3437,1.766118156,417.1760576
,96.3,80.60585359,2.62773143,248386.9051,1.756520745,419.922508
,96.6,81.51326079,2.667261292,253714.9214,1.732745581,423.0431447
,96.9,82.22337399,2.707401118,259709.1094,1.708752304,426.5922075
,97.2,83.3677279,2.74811878,263239.0197,1.699591157,429.7698265
,97.5,84.23781905,2.789469765,263017.5368,1.713114515,432.6724123
,97.8,85.60205646,2.831413074,262205.4309,1.729255265,435.2123221
,98.1,86.62171883,2.874012754,262019.0707,1.741033647,437.613067
,98.4,87.5892749,2.917259458,261947.2704,1.752812032,440.0861344
,98.7,88.97067863,2.961131397,263013.5305,1.756301817,442.6775403
,99,89.98212503,3.005689291,264092.4655,1.758046679,445.0169284
,99.3,90.72803623,3.050937877,267780.2972,1.74539565,448.2559015
,99.6,91.84909923,3.096845115,272385.0916,1.729254669,451.7206028
,99.9,92.78616593,3.143458302,276185.5969,1.719657304,455.0570973
,100.2,93.90201421,3.190763841,278098.441,1.720965917,457.931203
,100.5,95.21494772,3.238771056,279952.4884,1.723146991,461.0354086
,100.8,95.961131,3.28754112,282227.1211,1.72227444,464.2031637
,101.1,96.92686174,3.337033394,285740.765,1.713985794,467.5013089
,101.4,98.18203141,3.387254425,289289.7856,1.7065696,471.1468074
,101.7,99.99289825,3.438197651,292485.6891,1.700898315,474.7123219
,102,101.0456335,3.489960592,293954.9099,1.703079414,477.7891369
,102.3,101.9476411,3.542515423,294231.7997,1.713112839,481.1552168
,102.6,103.2772026,3.595835798,293886.0465,1.72576366,484.1849196
,102.9,104.7846973,3.649949968,293179.6892,1.73972318,486.9604123
,103.2,106.0099928,3.704900465,293407.1842,1.748011613,489.6274291
,103.5,107.0096673,3.760696164,292745.9588,1.7610987,492.2845765
,103.8,108.3486891,3.817312402,293117.4516,1.76851464,495.0173396
,104.1,109.5577732,3.874792558,292781.726,1.778111788,497.3238578
,104.4,110.9880477,3.933126697,294744.2346,1.77636669,500.1913958
,104.7,111.9855098,3.99237047,297273.1564,1.772440438,503.1191889
,105,113.4970438,4.052475444,300626.4329,1.764151743,506.0163126
,105.3,115.0791587,4.113483842,304504.098,1.755426803,509.4262335
,105.6,116.4397983,4.175428878,308271.4768,1.746701886,512.8394431
,105.9,117.6114111,4.238322261,312520.7268,1.736232032,516.4290585
,106.2,118.9567737,4.302154438,316998.8078,1.724889684,520.0252547
,106.5,119.9824364,4.367190685,321860.8995,1.713547368,524.0016586
,106.8,121.5546768,4.432736819,324279.4735,1.713983458,527.6964754
,107.1,122.796396,4.499516197,323079.2261,1.729251708,530.5870181
,107.4,124.3558023,4.567283491,322517.6535,1.741902491,533.7142472
,107.7,125.6804044,4.636090098,323569.1955,1.745828514,536.9433725
,108,127.4832764,4.705904801,328461.9841,1.731868693,540.5614922
,108.3,129.1902936,4.776780599,333833.8386,1.718781361,544.8370417
,108.6,131.0502395,4.848717433,337021.7964,1.716163751,548.7477222
,108.9,132.4465545,4.921771725,338132.4452,1.723143439,552.3625448
,109.2,133.8880411,4.995927621,338900.0393,1.730123123,555.69358
,109.5,135.8356582,5.071173253,341564.3285,1.72881422,559.4705787
,109.8,137.1985715,5.147594652,344890.8535,1.723579224,562.9341964
,110.1,138.4739348,5.225176178,347527.981,1.723579102,567.1100303
,110.4,140.5042071,5.30387895,347454.0582,1.733176159,570.1693354
,110.7,142.1798324,5.383793258,345936.1295,1.749753065,573.314098
,111,143.940968,5.464908463,344626.6585,1.764585005,576.3788776
,111.3,145.857504,5.547239014,347424.3758,1.760658671,579.8474318
,111.6,147.828342,5.630809673,350554.8413,1.754987381,583.3269493
,111.9,149.2681246,5.715677892,356768.6772,1.738846413,587.60469
,112.2,151.3721034,5.801784643,360663.5562,1.733175116,591.4189554
,112.5,152.57517,5.889251871,365330.45,1.726195178,595.6331428
,112.8,154.5668195,5.977988349,368719.6496,1.724013807,599.7640696
,113.1,156.2682827,6.06808477,370886.8865,1.725758587,603.5717523
,113.4,158.7936848,6.159488052,372193.4985,1.730993213,607.384928
,113.7,160.3520134,6.252336271,371492.6931,1.744952674,611.2561612
,114,162.3086755,6.346561041,371733.5793,1.752368542,614.381211
,114.3,164.4756223,6.442195556,373256.9672,1.755858226,618.214105
,114.6,166.6544039,6.539274344,375272.9039,1.755421788,621.4772211
,114.9,168.271728,6.637856866,381157.1594,1.741462009,626.0015088
,115.2,170.2707305,6.737903665,387241.5255,1.728374678,630.9641001
,115.5,172.1155615,6.839472298,392257.0285,1.717904791,635.0720148
,115.8,174.1893806,6.942560525,393342.8938,1.724448161,639.2774603
,116.1,176.0116703,7.047221715,395088.9509,1.728374126,643.2275918
,116.4,177.6964193,7.153469063,396605.6162,1.734045055,647.2368939
,116.7,179.8060952,7.261293579,401643.2357,1.726628811,651.8795317
,117,182.1776104,7.3707298,407158.5253,1.717903831,656.8278889
,117.3,184.3117258,7.481835259,411121.1468,1.713541251,661.2842532
,117.6,186.6960237,7.594602795,413425.2713,1.716594687,666.0079863
,117.9,188.6074412,7.709105153,413398.7131,1.726627966,670.2342466
,118.2,191.0477728,7.825302378,413912.4932,1.734043768,674.2019296
,118.5,193.0060631,7.943287173,417672.8644,1.73055368,678.8960659
,118.8,195.5165566,8.063017942,422475.8282,1.724009879,683.6734949
,119.1,197.5150465,8.184591395,426489.3652,1.720519789,688.1977951
,119.4,200.2313102,8.307954385,430032.8119,1.719210818,693.1461641
,119.7,202.571187,8.433206225,430599.6144,1.727935337,697.4316035
,120,205.2926773,8.560325189,433141.276,1.728807549,701.5833784
,120.3,207.4447344,8.689402302,435638.3436,1.732297238,706.3947649
,120.6,209.5457258,8.820432836,438563.2862,1.733605746,711.0746696
,120.9,212.0549425,8.953416117,439246.8378,1.741894006,715.4050404
,121.2,215.0148145,9.088378808,437969.6021,1.754980824,719.027586
,121.5,217.3087162,9.225424608,437836.4794,1.764141573,723.0073189
,121.8,220.0607519,9.364510766,439183.9658,1.76850367,726.9870682
,122.1,222.3415088,9.505729239,441945.0926,1.767194735,730.9273571
,122.4,225.1694198,9.649045094,444527.857,1.76806693,735.1262545
,122.7,227.5942708,9.794552528,447425.8172,1.767630454,739.3843092
,123,230.283366,9.942241051,451981.2031,1.761522879,743.6040242
,123.3,232.9329994,10.09216357,457675.2855,1.753670363,748.5929358
,123.6,235.8343854,10.24433479,464778.5263,1.741455463,753.8327821
,123.9,238.4125676,10.3988266,469605.1785,1.737092849,759.0507015
,124.2,241.2698652,10.55616329,471373.189,1.741018699,763.47642
,124.5,243.8257481,10.71484027,472062.2503,1.747998229,767.9854039
,124.8,246.9461306,10.87641208,473918.0091,1.751051577,772.4670121
,125.1,249.9579572,11.04043246,477614.4877,1.747997631,777.1370784
End Of Loading Marker,125.396,253.1260928,11.20468167,485603.6683,1.733601538,782.8294699
,125.7,255.3932616,11.20677247,492943.1381,1.722695424,788.6127869
,126,256.7304691,11.20668518,498247.5929,1.716587995,793.7112553
,126.3,257.7390147,11.20661943,501076.8778,1.720077786,799.51536
,126.6,259.0495963,11.20653388,499623.8942,1.734909678,804.2621003
,126.9,259.6179845,11.206497,498260.3231,1.749305405,808.6450323
,127.2,260.3515356,11.20644929,497139.8364,1.762392406,812.6532359
,127.5,260.8683364,11.20641579,499221.2387,1.766318478,817.1994315
,127.8,261.3314696,11.20638581,500933.2023,1.771553262,821.6283906
,128.1,261.6065583,11.20636816,502772.5183,1.775043121,825.7527248
,128.4,261.9195055,11.20634802,506333.5972,1.77417062,830.5739509
,128.7,262.5561221,11.20630667,510313.344,1.771116908,835.4631147
,129,262.9368818,11.20628209,515836.9818,1.762828393,840.2361313
,129.3,263.356332,11.20625497,518492.6599,1.763700824,845.3871696
,129.6,263.7391718,11.20623026,519378.6462,1.768499384,849.4567248
,129.9,263.9759859,11.20621512,521002.5734,1.77286171,853.8703339
,130.2,264.2373457,11.20619837,525368.5911,1.770680516,859.2218916
,130.5,264.5814949,11.20617619,525560.6413,1.780277658,863.5916742
,130.8,265.2039665,11.20613576,520791.5151,1.80165315,866.3474539
,131.1,265.3222128,11.20612839,508966.8103,1.844840456,868.1762319
,131.4,265.0498092,11.20614664,498702.0863,1.881920524,869.0188423
,131.7,265.6015561,11.20611085,492288.5046,1.906349656,869.9699502
,132,266.077586,11.20608003,492295.1103,1.90940326,871.5543889
,132.3,266.0718561,11.20608079,499919.2056,1.888900181,874.9303361
,132.6,266.5066993,11.20605266,511951.4313,1.856618705,879.3592919
,132.9,266.6078884,11.20604642,522644.1855,1.830880795,884.2166678
,133.2,266.8039318,11.20603395,524859.8672,1.830880776,887.693431
,133.5,266.7125002,11.20604033,515398.2699,1.865779633,889.3255187
,133.8,267.2509342,11.20600542,505931.0606,1.899369718,889.6679506
,134.1,267.1228922,11.2060142,499049.1199,1.925107632,890.2804582
,134.4,267.5906015,11.20598392,501278.4783,1.921181462,892.1278757
,134.7,267.2512176,11.20600656,506603.1855,1.907658196,894.5045024
,135,267.5733173,11.20598583,509965.4191,1.901550864,896.992919
,135.3,267.8205321,11.20597001,510423.925,1.904604488,899.1000127
,136.1,268.0441578,11.11804957,1.7977E+308,1.83655172,0
,136.4,267.6840475,10.95009877,1.7977E+308,1.552126166,0
,136.7,267.4171274,10.78214186,1.7977E+308,1.100622367,0
,137,267.2217639,10.61418026,1.7977E+308,0.547475659,0
,137.3,266.7227004,10.44623857,1.7977E+308,0.214191679,0
,137.6,266.1703854,10.27830038,1.7977E+308,0.112548788,0
,137.9,266.0299375,10.11033517,1.7977E+308,0.032281436,0
,138.2,265.5192252,9.942394252,1.7977E+308,0.003926121,0
,138.5,265.1624431,9.774443236,1.7977E+308,0.023556724,0
,138.8,264.6242729,9.606504113,1.7977E+308,0.024865432,0
,139.1,264.7151364,9.438523744,1.7977E+308,0.026610375,0
,139.4,264.2027599,9.27058293,1.7977E+308,0.029664025,0
,139.7,263.9433282,9.10262553,1.7977E+308,0.019630605,0
,140,263.6539425,8.934670094,1.7977E+308,0.002617414,0
,140.3,262.9476971,8.766741993,1.7977E+308,0.015704485,0
,140.6,262.4544579,8.598799924,1.7977E+308,0.019194371,0
,140.9,262.5378328,8.430820046,1.7977E+308,0.021811785,0
,141.2,262.0121434,8.262880105,1.7977E+308,0.019194372,0
,141.5,261.833421,8.094917413,1.7977E+308,0.011342129,0
,141.8,261.4100743,7.926970761,1.7977E+308,0.019194372,0
,142.1,261.1432431,7.75845393,1.7977E+308,0.029664031,0
,142.4,260.6948457,7.591068837,1.7977E+308,0.030972739,0
,142.7,260.3405596,7.423117657,1.7977E+308,0.029227796,0
,143,259.9663042,7.255167787,1.7977E+308,0.014395781,0
,143.3,259.4040043,7.087230246,1.7977E+308,0.001744943,0
,143.6,259.1171146,6.919274647,1.7977E+308,0.018321904,0
,143.9,258.649669,6.751330887,1.7977E+308,0.030972743,0
,144.2,258.6381896,6.583357228,1.7977E+308,0.02704662,0
,144.5,258.1765684,6.415413086,1.7977E+308,0.027919093,0
,144.8,257.9733003,6.247452004,1.7977E+308,0.035335102,0
,145.1,257.8224516,6.079487484,1.7977E+308,0.041006168,0
,145.4,256.9443866,5.911570649,1.7977E+308,0.036207576,0
,145.7,256.6042453,5.743618542,1.7977E+308,0.032281454,0
,146,256.2487111,5.575667443,1.7977E+308,0.02748286,0
,146.3,256.106183,5.407702378,1.7977E+308,0.020939322,0
,146.6,255.6141916,5.239760227,1.7977E+308,0.012432723,0
,146.9,255.0256818,5.071824406,1.7977E+308,0.006107303,0
,147.2,254.8365586,4.903862396,1.7977E+308,0.004798595,0
,147.5,254.2259992,4.73592802,1.7977E+308,0.009160954,0
,147.8,253.9869527,4.567969283,1.7977E+308,0.013087078,0
,148.1,253.491633,4.400027351,1.7977E+308,0.014832022,0
,148.4,253.0295955,4.232083236,1.7977E+308,0.017885674,0
,148.7,252.5617337,4.064139504,1.7977E+308,0.035335114,0
,149,252.231993,3.896186714,1.7977E+308,0.051912082,0
,149.3,251.6605402,3.728249774,1.7977E+308,0.072197057,0
,149.6,251.3540971,3.560295457,1.7977E+308,0.069361524,0
,149.9,251.0642951,3.392340048,1.7977E+308,0.058019389,0
,150.2,250.6596694,3.224392169,1.7977E+308,0.036643826,0
,150.5,250.0499419,3.056457739,1.7977E+308,0.010033429,0
,150.8,249.5492138,2.888516161,1.7977E+308,0.009597193,0
,151.1,248.9128605,2.720583477,1.7977E+308,0.017449443,0
,151.4,249.2250509,2.552588595,1.7977E+308,0.017449442,0
,151.7,248.1568606,2.384684227,1.7977E+308,0.023120512,0
,152,247.9173979,2.216725518,1.7977E+308,0.032281471,0
,152.3,247.1695491,2.048800144,1.7977E+308,0.025301694,0
,152.6,246.6854619,1.880857475,1.7977E+308,0.010469667,0
,152.9,245.8585677,1.712937285,1.7977E+308,0.010905904,0
,153.2,245.6865015,1.544974157,1.7977E+308,0.017885682,0
,153.5,244.9919042,1.377045292,1.7977E+308,0.021375572,0
,153.8,244.6800526,1.209091329,1.7977E+308,0.019630628,0
,229.1,243.6670338,1.046879531,1.7977E+308,0.016140741,0
,229.4,242.9616196,0.878951375,1.7977E+308,0.022248049,0
,229.7,242.4309371,0.711011762,1.7977E+308,0.017013214,0
,230,241.6489736,0.543088626,1.7977E+308,0.012650852,0
,230.3,240.4484858,0.375192933,1.7977E+308,0.024429234,0
,230.6,239.1482401,0.206743866,1.7977E+308,0.034462671,0
,230.9,237.003368,0.038910098,1.7977E+308,0.025301711,0
,230.958,236.5802443,0.007022707,1.7977E+308,0.026174185,0
END,,,,,,