File: GB1_test 43.csv
Segment,Time On Sample,Displacement Into Surface,Load On Sample,Harmonic Contact Stiffness,Harmonic Displacement,Harmonic Load
Surface Marker,0,0,0,-41.30497768,0.340682466,2.229871852
,0.3,0.105874373,0.000977711,8379.98836,0.20545639,2.351501232
,0.6,0.30951017,0.001949024,13923.6646,0.17666632,2.479705181
,0.9,0.444920972,0.002924801,15741.48256,0.165324778,2.610100645
,1.2,0.894832346,0.003879996,16093.4493,0.164888561,2.745974936
,1.492,0.587363084,0.004858502,18572.54268,0.157036727,3.102096961
,1.8,0.588237922,0.005866989,22716.59648,0.144386546,3.513007008
,2.1,1.00070912,0.006822298,28378.47073,0.132172576,3.875703659
,2.4,0.571184077,0.007832712,39601.84201,0.114287841,4.532063937
,2.7,0.742787775,0.008803785,48805.75767,0.109053282,5.216914046
,3,0.916887508,0.009774694,53047.6085,0.115596478,5.987233456
,3.3,0.952873232,0.010754643,49676.63682,0.143950331,6.987662481
,3.6,1.046683797,0.011730807,47487.75031,0.17753874,8.229158749
,3.9,0.709096091,0.012735204,45406.94527,0.217234139,9.615295247
,4.2,0.988029349,0.013699252,45399.40164,0.245151775,10.87103644
,4.5,0.77274742,0.014695645,47557.29508,0.271760779,12.66698726
,4.8,0.69765953,0.015682863,47781.32477,0.305785405,14.37527729
,5.1,0.645451972,0.016668583,45874.70447,0.358567195,16.10986556
,5.4,0.774207047,0.01764246,41521.99351,0.438830408,17.82253874
,5.7,0.596781666,0.018636375,37740.92294,0.525636826,19.41029508
,6,-0.23502126,0.019673116,32179.78104,0.665225061,21.02215773
,6.3,-0.727363256,0.02068764,26472.97637,0.836656854,21.98094759
,6.6,1.094952517,0.02155068,19767.6507,1.118886658,22.44774236
,6.9,0.857206262,0.022548543,15264.0058,1.417256454,22.46965752
,7.2,1.455632158,0.023491682,13419.80046,1.592177865,22.50253068
,7.5,1.052315502,0.024500381,14109.85149,1.555536,23.08766634
,7.8,1.376177408,0.025461489,17196.80792,1.371017824,24.35874836
,8.1,1.005309222,0.026468064,21640.97356,1.185627275,25.90705713
,8.4,1.361619601,0.027427049,24553.69302,1.105364038,27.12444697
,8.7,-1.196608524,0.028576777,24366.67225,1.147240664,28.07337331
,9,0.914415506,0.029420922,20287.23688,1.373635142,28.41853931
,9.3,1.198340835,0.030384644,17235.2486,1.597848665,28.31115505
,9.6,1.736029841,0.031331758,15341.01406,1.776259779,28.11611015
,9.9,1.750383251,0.032313122,15616.9929,1.769716581,28.38018834
,10.2,1.846273323,0.033292423,17997.31945,1.593486478,29.21625343
,10.5,1.872275422,0.034269753,22792.00047,1.338301809,30.52678258
,10.8,1.749346842,0.035260102,28019.06113,1.155092315,31.88881237
,11.1,1.102250648,0.036284755,29437.07528,1.1332817,32.76761146
,11.4,1.188157099,0.037261437,27823.31185,1.222269172,33.50505809
,11.7,1.372240975,0.038231693,24647.83287,1.379305883,33.85350995
,12,1.952362593,0.03917603,22137.99319,1.529363147,34.04417279
,12.3,2.179711088,0.040143455,21323.04513,1.593486454,34.31701729
,12.6,2.281425763,0.041119102,22249.58188,1.558153184,34.8890042
,12.9,1.954654232,0.042122792,24795.5617,1.447355085,35.75136711
,13.2,2.290996306,0.043083084,27731.3197,1.33917421,36.67071023
,13.5,2.396039028,0.044058514,31118.63326,1.237100339,37.79934335
,13.8,2.32552721,0.045045433,33173.41804,1.193042821,38.76470795
,14.1,2.050340427,0.046045747,33832.42662,1.197404972,39.64789034
,14.4,2.573885207,0.046993787,33324.51598,1.242334887,40.50039235
,14.7,2.377739572,0.047988929,32230.67649,1.305149586,41.15784815
,15,2.586783798,0.048957552,31380.90768,1.357058929,41.69915397
,15.3,2.349037561,0.049955416,30909.08755,1.399371617,42.38290806
,15.6,2.476960614,0.050929348,30922.44804,1.42074605,43.0458431
,15.9,2.402288736,0.051916539,31370.12467,1.423799549,43.75260832
,16.2,2.80144771,0.05287272,31887.6126,1.422927093,44.42211828
,16.5,2.385234893,0.053882264,32653.34033,1.414639076,45.21544812
,16.8,2.882571287,0.05483202,33395.64843,1.40765963,46.01864096
,17.1,2.279987774,0.055853761,33685.6023,1.415947726,46.73198005
,17.4,2.459495574,0.056824317,33845.28666,1.431651385,47.48915056
,17.7,2.701820282,0.057790763,33650.24929,1.458696574,48.11154265
,18,2.513162755,0.058785414,33690.48336,1.478326181,48.75146633
,18.3,2.546236436,0.059765554,33527.07419,1.503626539,49.31687862
,18.6,2.808945437,0.060730665,33502.97201,1.524128533,49.92283433
,18.9,2.529182594,0.061731279,33590.52269,1.537214951,50.51016136
,19.2,2.87800484,0.062690754,34017.86677,1.536778709,51.17528828
,19.5,2.4809283,0.063699046,34783.63657,1.522383712,51.90944703
,19.8,3.01612124,0.064646324,35328.79219,1.517585323,52.60306411
,20.1,2.52003527,0.065661095,35502.78886,1.526309628,53.24517873
,20.4,3.078108541,0.066606876,35148.23628,1.55597207,53.76895304
,20.7,2.84327435,0.06760455,34656.37251,1.591305352,54.25656584
,21,3.344770795,0.068554033,34125.62608,1.628383419,54.68610463
,21.3,2.968078558,0.069560991,33380.03436,1.675930681,55.05208793
,21.6,3.737066017,0.070498251,32985.11369,1.705593098,55.38191293
,21.9,3.564213559,0.071511804,33462.31884,1.695560215,55.85528098
,22.2,3.779492319,0.072514903,34982.21152,1.641033562,56.48315201
,22.5,3.645739602,0.073556244,38233.87417,1.531544094,57.53836884
,22.8,3.8726616,0.074589589,41759.91542,1.432959922,58.68453439
,23.1,3.833337251,0.075656162,44067.12169,1.384540276,59.76933692
,23.4,3.541078699,0.076755371,44327.75603,1.396754265,60.63279549
,23.7,3.625302986,0.077846221,43241.10438,1.450408468,61.43270055
,24,3.939991947,0.078938636,42481.76842,1.491848684,62.10878506
,24.3,3.854480479,0.080073997,42484.3677,1.507988575,62.78706047
,24.6,4.027722031,0.081209443,43356.81156,1.498391874,63.64284952
,24.9,3.670969214,0.082396788,44594.2072,1.478762317,64.56986208
,25.2,4.032239916,0.083554912,45564.05625,1.470474239,65.54070631
,25.5,3.837723788,0.084767171,45625.67338,1.487486566,66.36690915
,25.8,4.151564099,0.085964297,45344.13909,1.51453175,67.10873926
,26.1,4.023603134,0.087208669,45351.48082,1.531544071,67.86700524
,26.4,4.409822624,0.088437913,45662.50077,1.537651021,68.62636761
,26.7,3.884153988,0.089745727,46083.48744,1.540704559,69.44161232
,27,4.684709403,0.090985817,46399.22563,1.54637526,70.23713572
,27.3,3.981816071,0.092343934,46627.95814,1.553790944,70.96581496
,27.6,4.724124391,0.093627186,46891.9424,1.561642715,71.76572133
,27.9,4.729266219,0.094983155,47454.53614,1.559897863,72.58973311
,28.2,4.876680303,0.096341052,48030.05371,1.557716786,73.43346861
,28.5,4.597268213,0.097752328,48586.38252,1.557280598,74.32870433
,28.8,4.926885519,0.099144821,48928.92829,1.562951339,75.1209395
,29.1,4.379558826,0.100616109,48911.76895,1.579963698,75.86276809
,29.4,4.993717398,0.102032912,48847.3038,1.600029444,76.61226924
,29.7,4.633586494,0.103535381,48626.59986,1.622712556,77.27191632
,30,5.087991744,0.105006815,48624.41671,1.637543759,77.92937324
,30.3,4.746157988,0.106552859,48928.74039,1.641469709,78.58134995
,30.6,5.265452932,0.108065562,49998.68028,1.623584927,79.41741609
,30.9,5.094174242,0.109646898,51727.92332,1.5886879,80.39702533
,31.2,5.594325436,0.111207825,53742.6636,1.549864896,81.50374412
,31.5,5.205052054,0.112851052,55429.07155,1.524128362,82.6794942
,31.8,5.51882488,0.1144726,56258.36046,1.519766205,83.69088139
,32.1,5.093767164,0.116167355,56457.57148,1.530671568,84.6146065
,32.4,5.591406687,0.117826813,56507.14562,1.544630343,85.47039633
,32.7,5.263686349,0.119565651,56732.61941,1.554663273,86.40069605
,33,5.436001067,0.12129762,57216.0389,1.559461602,87.3918115
,33.3,5.29589111,0.123076435,57591.08018,1.56600481,88.32704257
,33.6,5.792266033,0.124840271,57473.40484,1.585198142,89.18392832
,33.9,5.38507172,0.126690248,57207.02142,1.606572615,89.9663001
,34.2,5.941342837,0.128504645,57160.74828,1.620531385,90.69169479
,34.5,5.7275825,0.130397307,57430.20282,1.627510813,91.57268548
,34.8,6.122434372,0.132278441,58110.89665,1.624021074,92.46901837
,35.1,5.877048527,0.13423015,58855.14524,1.620095178,93.39274362
,35.4,6.178289854,0.136175311,59868.60218,1.611807105,94.43590817
,35.7,5.818077007,0.138193422,60382.44356,1.613551989,95.3431967
,36,5.97287474,0.140207943,60539.97501,1.623148664,96.20775182
,36.3,6.612314572,0.142221083,60547.928,1.636234996,97.07559574
,36.6,7.08992322,0.144275368,61029.80476,1.637107379,97.96645011
,36.9,6.912317555,0.146403827,61965.32283,1.627946923,98.94605943
,37.2,7.373691923,0.148522347,63405.75707,1.606572445,99.91690417
,37.5,6.869927372,0.150736583,65157.71699,1.58301699,101.1540164
,37.8,7.278042582,0.152924026,66538.98297,1.569058138,102.3242894
,38.1,7.242274145,0.155174015,67544.67951,1.563387373,103.4529224
,38.4,7.373734759,0.157446586,67571.75325,1.579527243,104.5475872
,38.7,7.214401722,0.159772858,67069.00517,1.605263825,105.4746
,39,7.671167902,0.16209373,66569.54651,1.628819285,106.2619051
,39.3,7.359565513,0.164500361,66708.58061,1.63972464,107.2015187
,39.6,7.724799029,0.166898686,67362.55719,1.638415968,108.1767462
,39.9,7.428577319,0.16937691,67958.76487,1.639724635,109.1706001
,40.2,7.687717615,0.17185586,68078.97207,1.649321298,109.9485905
,40.5,7.589086839,0.174395867,67967.78303,1.666333614,110.8679333
,40.8,7.860279264,0.176949768,68106.21241,1.675930275,111.7204355
,41.1,7.588161764,0.179578252,68268.11022,1.684218348,112.6025219
,41.4,8.102289191,0.182194567,68360.16036,1.692506347,113.3859919
,41.7,7.562251255,0.184920038,67887.50599,1.713880836,114.1004262
,42,8.101326201,0.187615479,67517.25225,1.733074156,114.7787033
,42.3,8.157827768,0.190383528,67770.55453,1.737436281,115.4690326
,42.6,9.05382261,0.193138266,68751.36915,1.72653087,116.3642713
,42.9,8.935588423,0.196001294,70364.93887,1.70253917,117.4129138
,43.2,9.118535668,0.198887562,71814.83985,1.681600931,118.4067688
,43.5,9.183330306,0.201825202,73101.23193,1.665461047,119.4324011
,43.8,9.575098506,0.204785833,74351.28764,1.652374622,120.5939081
,44.1,9.262145569,0.207837768,75331.90416,1.645395245,121.7225403
,44.4,9.85441418,0.21087597,76522.03292,1.634489868,122.8369303
,44.7,9.484869895,0.214023165,77809.80927,1.624457005,124.1047242
,45,9.869120741,0.217168253,78982.80063,1.617477563,125.3352642
,45.3,9.634347251,0.220401674,79694.88905,1.619222438,126.4628009
,45.6,10.26652224,0.223627102,79419.17715,1.639724388,127.5103495
,45.9,9.737201028,0.22697776,79053.66719,1.660662659,128.5020115
,46.2,10.17050943,0.230315481,78902.49181,1.674621433,129.3534185
,46.5,10.28015722,0.233725034,78883.10237,1.687271598,130.3626144
,46.8,10.93642852,0.237150177,79461.1435,1.685962898,131.2710017
,47.1,11.10346871,0.240659173,80030.37971,1.686835308,132.3163581
,47.4,11.78801175,0.244187082,81273.60765,1.674621283,133.4329401
,47.7,11.41921946,0.247837902,82287.79926,1.668950551,134.6284138
,48,11.75596432,0.251497424,83238.12498,1.664588391,135.8074528
,48.3,11.61429369,0.255243543,84146.07556,1.661098702,136.9306071
,48.6,11.84618731,0.259021746,85011.07371,1.65935383,138.1436142
,48.9,11.72197085,0.262880471,85712.41574,1.660226268,139.3182692
,49.2,12.29829898,0.266751315,85961.48721,1.667205621,140.3121259
,49.5,11.88701994,0.27074564,85818.36284,1.682909325,141.389257
,49.8,12.43088076,0.274737169,86001.39151,1.692069744,142.4389974
,50.1,12.16851266,0.278842186,86765.34926,1.689452493,143.4383303
,50.4,12.82467559,0.28294873,87672.67658,1.686835154,144.7017444
,50.7,12.87637214,0.287157326,88240.95062,1.687271363,145.7120362
,51,13.63318845,0.291383097,88486.67092,1.693814486,146.8067036
,51.3,13.52886257,0.295729407,89479.76684,1.686835091,147.9484857
,51.6,14.17167267,0.300092221,90737.74966,1.677238347,149.2458687
,51.9,14.01241306,0.304574019,92544.067,1.660662274,150.655016
,52.2,14.16431505,0.309102866,93777.30955,1.652810432,151.893226
,52.5,13.68138136,0.313741699,94698.60618,1.652810478,153.2947015
,52.8,14.45935009,0.318367691,95504.83697,1.654119041,154.6402987
,53.1,14.33457512,0.323123035,95559.31983,1.66676923,155.8434432
,53.4,14.6108183,0.327923904,95738.81102,1.675929671,156.9665989
,53.7,14.40614726,0.332829019,95419.73514,1.693378203,158.087561
,54,15.33882426,0.337733206,95612.12857,1.70101184,159.1378514
,54.3,14.74266822,0.34281233,95897.1918,1.70820941,160.2615514
,54.6,15.26971561,0.347894057,96518.11363,1.709954211,161.416485
,54.9,15.76846236,0.353054603,97052.83659,1.711699014,162.4202041
,55.2,16.86915705,0.358253248,97267.18184,1.719986952,163.558704
,55.5,16.88572822,0.363602164,97952.40015,1.718678313,164.6380285
,55.8,17.15022598,0.36901548,98894.37763,1.713443735,165.8619941
,56.1,16.77863796,0.374552516,100478.5754,1.69904875,167.2481297
,56.4,17.37549801,0.380109297,102168.7269,1.68421746,168.6331737
,56.7,17.3337759,0.385792184,103700.9353,1.674620784,170.1135462
,57,17.79457507,0.391527716,104747.2059,1.67287589,171.533654
,57.3,17.2565307,0.397415876,105310.6775,1.67723807,172.8145955
,57.6,17.61662859,0.403333588,105589.9417,1.685962291,174.1032115
,57.9,17.79242171,0.409352989,105838.2446,1.69468653,175.4016889
,58.2,18.30142095,0.415441286,106243.2386,1.69904861,176.5390907
,58.5,17.86440859,0.421683857,107301.0017,1.695558951,177.993163
,58.8,18.22819228,0.427967714,108601.0944,1.688579513,179.4439516
,59.1,18.92726145,0.43432449,109977.571,1.67941898,180.7698261
,59.4,19.71201249,0.440771707,112039.776,1.665023887,182.5394826
,59.7,19.90102791,0.447355523,113175.6102,1.661534168,183.9453453
,60,20.33630287,0.454022595,114339.652,1.659353065,185.552828
,60.3,20.21827429,0.460826829,115448.1221,1.658916864,187.2676935
,60.6,20.38144918,0.467715368,116035.9629,1.661534125,188.5979469
,60.9,20.60284833,0.474704105,117266.0753,1.658480617,190.2613136
,61.2,20.75267773,0.481803115,117046.9547,1.674620472,191.7099093
,61.5,20.67867904,0.489024141,116308.9763,1.698175965,193.0204393
,61.8,20.98322816,0.49632923,115844.7567,1.715188231,194.0756576
,62.1,20.93249087,0.503768344,116258.3309,1.720859001,195.4048158
,62.4,21.20206011,0.511298469,117775.9581,1.710389872,196.8161563
,62.7,20.96242034,0.51897603,119032.2692,1.704719131,198.3852851
,63,21.54312523,0.526715617,119915.0904,1.704282863,199.9051078
,63.3,21.17365043,0.53466137,120616.1585,1.706463963,201.2989142
,63.6,21.89326349,0.542629105,121317.4673,1.709517383,202.7694277
,63.9,21.67102503,0.550751722,121484.6431,1.718677871,204.1040641
,64.2,22.86900588,0.558930995,120822.2926,1.736998686,205.1198404
,64.5,23.29236458,0.56728506,119938.4356,1.759245489,206.2199871
,64.8,23.67659869,0.575767829,120159.4065,1.764480002,207.2017904
,65.1,23.77293656,0.584397738,121368.8337,1.75880923,208.5167043
,65.4,24.32020373,0.593128494,123860.3717,1.738743397,210.1997952
,65.7,24.4672526,0.602017253,125935.9349,1.72303973,211.6352439
,66,24.9262843,0.611019675,128243.5951,1.706463608,213.3566856
,66.3,25.00090523,0.620183535,129564.276,1.702537688,215.1088089
,66.6,25.740281,0.629442127,129829.0829,1.709080806,216.580419
,66.9,25.76327297,0.638887889,130403.6946,1.71169808,218.0706545
,67.2,26.16979938,0.648450981,131818.4318,1.703846216,219.560891
,67.5,26.13783304,0.658187135,134904.2596,1.68159938,221.6921466
,67.8,26.39205507,0.668051811,137199.8817,1.667640555,223.4497477
,68.1,27.32891842,0.678020718,138573.2558,1.666768042,225.3333672
,68.4,27.95084164,0.688160903,138204.0921,1.683344059,226.8455203
,68.7,27.86885921,0.6985007,137912.3374,1.699047718,228.4004051
,69,28.53774183,0.708947368,138306.0962,1.706899476,230.0046032
,69.3,28.5634549,0.719594101,139219.9855,1.707771904,231.5496263
,69.6,29.41449722,0.730347458,140642.5667,1.704282119,233.3346263
,69.9,29.65273766,0.741303669,141993.9779,1.701228615,235.1305801
,70.2,30.38849432,0.752392401,144186.4859,1.688142165,236.9188668
,70.5,30.59922547,0.763683363,147193.2304,1.669385018,239.1673697
,70.8,30.77248896,0.775147697,149280.151,1.660660747,241.330403
,71.1,31.22528055,0.786766832,149584.5471,1.670693597,243.219498
,71.4,31.51081007,0.798572469,148585.8816,1.692067974,244.7568526
,71.7,31.52757178,0.810573911,147031.8799,1.719549361,246.1955869
,72,32.12754422,0.822718337,146528.4261,1.734816735,247.6266546
,72.3,31.92002103,0.835099411,146613.0615,1.743104792,249.0051212
,72.6,32.70880099,0.84760203,147895.7476,1.739615015,250.6761617
,72.9,33.10775386,0.860319238,149095.7058,1.737433915,252.377882
,73.2,33.92684159,0.873200887,150175.7442,1.735688986,253.8944205
,73.5,34.47591087,0.88629506,151465.2883,1.733944083,255.7276332
,73.8,34.76702539,0.899603967,153268.7891,1.725656021,257.3811378
,74.1,34.72322366,0.91313604,156171.6919,1.708643745,259.4817123
,74.4,35.39658262,0.926825223,159305.1425,1.68988655,261.6403657
,74.7,35.56155019,0.940754737,160734.1756,1.688577898,263.7014945
,75,36.21861859,0.954862239,160716.4385,1.700355568,265.5785376
,75.3,36.4829441,0.969208776,159947.7282,1.718240248,267.1049357
,75.6,36.96189386,0.983757969,160837.4236,1.720857476,268.990743
,75.9,37.24112617,0.998539938,162546.437,1.715622902,270.9948929
,76.2,38.0137053,1.013512177,164560.8127,1.70646237,272.8960434
,76.5,38.83367302,1.028707647,165105.3051,1.712569263,274.9166351
,76.8,39.25590321,1.044158896,165216.2974,1.720857255,276.4967248
,77.1,39.33697201,1.059866078,165386.1837,1.730453917,278.2137845
,77.4,40.13270008,1.075763221,166417.392,1.732198689,279.9571454
,77.7,40.0780753,1.091956713,167242.7361,1.736124605,281.785972
,78,41.00435186,1.108330295,167512.7668,1.743976334,283.4679715
,78.3,41.1609795,1.125001907,167528.4421,1.752700563,284.9998485
,78.6,41.92493466,1.141885346,168400.1814,1.754009124,286.7278686
,78.9,42.5174551,1.159035204,171244.9439,1.738305429,288.8426943
,79.2,42.94935635,1.176454814,174507.8121,1.719112053,290.9213554
,79.5,43.2539182,1.194145882,177829.0374,1.702535963,293.4339399
,79.8,43.97028261,1.212077205,179737.51,1.698173773,295.7372347
,80.1,44.21152611,1.230310696,181205.6716,1.697737539,297.9835491
,80.4,44.93861979,1.248787574,182094.5577,1.701227166,300.0468724
,80.7,45.58163602,1.267549234,182837.9367,1.706025438,302.1726566
,81,46.28782973,1.286654447,182285.7261,1.72085658,304.1066798
,81.3,46.74771264,1.30600094,182169.8396,1.730889413,305.9146916
,81.6,47.64935689,1.325544861,183637.231,1.728272053,308.0306131
,81.9,47.56584378,1.345514904,186162.6723,1.716930549,310.0884546
,82.2,48.33342898,1.365730669,188243.0109,1.712568355,312.466262
,82.5,48.68579258,1.38627937,190057.9202,1.709514838,314.5690324
,82.8,49.34761455,1.407118048,191295.3285,1.712132046,316.8142522
,83.1,50.11754775,1.428264444,193427.4601,1.706897429,319.1887757
,83.4,50.77926881,1.449737643,194563.1184,1.709950849,321.6904042
,83.7,51.23543186,1.471548661,194890.7799,1.715621561,323.5455342
,84,51.88456879,1.493676571,193232.8361,1.737868307,325.3645027
,84.3,52.4754119,1.516142494,192762.8209,1.750518394,327.0377375
,84.6,53.31081189,1.538931861,193005.3529,1.759678762,329.0879137
,84.9,53.99389935,1.562075386,194692.1034,1.754880364,330.9046942
,85.2,54.46892879,1.585582178,197609.243,1.741793962,333.3329054
,85.5,55.18227244,1.609429119,201042.462,1.725217844,335.7107162
,85.8,56.17178602,1.633617976,205111.041,1.706024426,338.5706625
,86.1,56.41118479,1.658221626,207051.9285,1.704279557,341.1215994
,86.4,57.30490005,1.683153793,206751.2478,1.716929612,343.1213718
,86.7,57.91733612,1.708481385,205260.7174,1.738740145,344.9414388
,87,58.96027629,1.734163198,205724.3163,1.745719422,347.0201086
,87.3,59.41284399,1.76027191,208983.9318,1.731324397,349.4581833
,87.6,60.35665057,1.786742726,214678.0451,1.701225691,352.5800181
,87.9,60.73088308,1.813650952,219124.4317,1.681159924,355.7149966
,88.2,62.13507861,1.840897836,221013.5305,1.678106305,358.3601799
,88.5,62.67558288,1.868613362,222311.0082,1.682032164,361.2946358
,88.8,63.40738273,1.896734992,222409.7948,1.694246017,363.8192787
,89.1,63.98768929,1.925291683,221800.5874,1.711694428,366.1379174
,89.4,64.81253799,1.954263607,222058.4825,1.720854789,368.3491732
,89.7,65.46176311,1.983684865,222514.342,1.728270327,370.6689081
,90,66.40503282,2.013531212,225500.8042,1.718237369,373.488313
,90.3,66.6967676,2.043871578,228036.0942,1.711694168,376.1225292
,90.6,67.82834271,2.074615115,231418.6751,1.701661193,379.2049187
,90.9,68.01426561,2.105885362,234537.5769,1.693809368,382.2862044
,91.2,69.03919457,2.137572743,237334.0075,1.686393675,385.0935569
,91.5,69.28154286,2.169790535,239519.2488,1.684212595,388.3523582
,91.8,70.17361283,2.202452259,239704.2374,1.693809162,391.1794323
,92.1,70.88713837,2.235619297,239323.4206,1.706023015,393.5725863
,92.4,72.04820502,2.269258054,238449.7745,1.723471361,395.9799871
,92.7,72.78112226,2.303433107,238845.2602,1.733067941,398.436696
,93,73.73776776,2.338109865,238672.8225,1.745717978,400.7575295
,93.3,74.6885059,2.373310725,239509.8251,1.750079998,403.0323446
,93.6,76.05599609,2.40901428,240753.4923,1.751824708,405.5394626
,93.9,76.55228735,2.445314625,241542.7075,1.754878138,407.6279929
,94.2,77.5743209,2.482128738,244634.0879,1.7457176,410.5416348
,94.5,78.31421504,2.519517727,247607.6088,1.736993302,413.1594225
,94.8,79.36935065,2.557450574,250397.5872,1.73045003,416.0610115
,95.1,80.24135317,2.595968976,253340.0561,1.723034354,419.032731
,95.4,81.07415873,2.635071928,254551.6393,1.727396385,422.0877243
,95.7,81.49750098,2.674926026,256102.6781,1.728268766,424.9169909
,96,82.89174409,2.715049401,256929.5597,1.732630742,427.2739901
,96.3,83.40893238,2.755972166,256500.4846,1.746589448,429.8556149
,96.6,84.53089247,2.797473244,256549.0427,1.757058404,432.2915064
,96.9,85.51963151,2.839610075,255826.5397,1.769708428,434.0798058
,97.2,86.9958261,2.882351486,256130.6367,1.777123869,436.457626
,97.5,87.72727061,2.925787721,258059.9542,1.773197896,438.7762714
,97.8,89.08095283,2.96983947,261531.0878,1.760983852,441.7162169
,98.1,89.56424872,3.014613934,267962.7744,1.733502511,445.2982744
,98.4,91.08661509,3.059996614,272470.5838,1.717798767,448.5253117
,98.7,91.77020832,3.106120131,274982.5094,1.715181435,451.715089
,99,93.50948357,3.153029823,274781.4138,1.728267594,454.5706666
,99.3,94.26859106,3.20039627,273635.4834,1.744843533,456.9167068
,99.6,95.5966527,3.248600741,274977.3471,1.747896878,459.7547475
,99.9,96.53438682,3.297559347,277627.7594,1.743098466,462.829473
,100.2,97.68333328,3.347243675,280296.4539,1.737427613,465.5634134
,100.5,98.64079856,3.39769138,282913.5593,1.734374043,468.8824953
,100.8,99.86854512,3.448883379,285170.6995,1.73262908,472.0295407
,101.1,100.8607105,3.500864201,286587.1033,1.734810036,475.0571493
,101.4,102.2654268,3.553603194,287412.6756,1.739172005,477.8283508
,101.7,103.4977907,3.607150464,289738.1145,1.73655462,481.0181363
,102,104.6984097,3.661508737,291919.5481,1.736118291,484.2265452
,102.3,105.7516327,3.716698178,294829.7603,1.731319871,487.2892201
,102.6,107.1757984,3.772696423,297144.7797,1.730883521,490.635698
,102.9,108.3036347,3.829562209,298057.0586,1.736990358,493.7159065
,103.2,109.624776,3.887274213,299470.1136,1.73873507,496.5429921
,103.5,110.9557628,3.945857036,299729.0412,1.747895359,499.5936185
,103.8,111.7765885,4.005358377,301016.9228,1.751384959,502.5960188
,104.1,112.7187444,4.065750557,303531.8586,1.749203821,505.7912811
,104.4,114.3113845,4.127012463,307368.7559,1.740043235,509.1136571
,104.7,115.5169942,4.189225301,312790.8553,1.72433955,512.9948702
,105,117.1534339,4.252349747,316266.095,1.718668648,516.7851374
,105.3,118.3454303,4.316457099,315642.8781,1.730882429,519.6330464
,105.6,119.7943627,4.381516234,312241.4565,1.757054895,522.1171638
,105.9,121.3558756,4.447550985,309065.4652,1.78148252,524.3613108
,106.2,122.7333564,4.514595513,308867.6999,1.789770365,526.5780611
,106.5,123.8810422,4.582668317,312023.5679,1.782790895,529.8007195
,106.8,125.7286978,4.651723634,315914.4015,1.772757865,533.1373479
,107.1,126.6277002,4.721884657,320797.9001,1.758362848,536.4651974
,107.4,128.6763667,4.793030096,324395.1131,1.751383281,539.9870125
,107.7,129.6083098,4.865324028,330375.3054,1.734371001,544.1081964
,108,131.3354771,4.938657698,335399.7809,1.720412112,547.7549222
,108.3,133.0000676,5.013103562,341066.472,1.705580812,551.9835041
,108.6,134.8188164,5.08866409,345731.9101,1.696856438,556.3808317
,108.9,135.8228496,5.165419932,347217.6735,1.702527069,560.3058779
,109.2,137.7223529,5.243276212,348320.2285,1.710814872,564.4588512
,109.5,139.3999393,5.322323617,348961.153,1.717794066,567.7133001
,109.8,141.2054647,5.402556839,350530.1558,1.721719777,571.5726087
,110.1,142.5178338,5.484034744,353402.8717,1.7195386,575.637918
,110.4,144.4494353,5.566703203,355147.3366,1.722155669,579.3405343
,110.7,145.9881314,5.650646711,358394.6878,1.719538261,583.5252871
,111,147.7600038,5.735839821,361216.2275,1.719101878,587.5226616
,111.3,149.0778127,5.822348934,364588.1974,1.716484492,591.5178453
,111.6,151.2790033,5.910106686,368431.126,1.712558393,596.0127052
,111.9,153.0714684,5.999217324,371164.597,1.712558218,600.2555389
,112.2,154.7963268,6.089678945,373035.0895,1.714739097,603.9899312
,112.5,156.372871,6.18151698,375105.6227,1.717792409,608.446437
,112.8,158.6014862,6.274699497,377303.0721,1.719100819,612.5709301
,113.1,160.0378089,6.369342088,378805.987,1.721717934,616.1442475
,113.4,162.0446594,6.465376793,382062.7344,1.720845319,620.9514
,113.7,163.7867016,6.562879792,385079.864,1.719536521,624.8282505
,114,165.7431666,6.661842088,387983.3004,1.719972539,629.1357342
,114.3,167.6311693,6.762303948,392436.3981,1.714301636,633.6284074
,114.6,169.7252677,6.864269992,396606.6099,1.710375551,638.3391371
,114.9,171.2200779,6.96781604,401234.8788,1.704704688,643.2416208
,115.2,173.1963697,7.072894843,402596.0232,1.709939004,647.3858377
,115.5,175.6250191,7.179531379,403660.2604,1.717354318,651.9497483
,115.8,177.634082,7.287806891,403619.7099,1.728259342,656.1805309
,116.1,179.3308833,7.397738687,404134.2487,1.735674725,659.64209
,116.4,181.4850225,7.509301375,405715.377,1.740036599,663.6296174
,116.7,183.6904166,7.622930494,408979.4718,1.738727754,668.0554594
,117,186.0562359,7.737500395,415063.3635,1.726949888,672.9678176
,117.3,187.9840844,7.85421685,423296.4057,1.709937564,678.7666506
,117.6,189.7244516,7.972709039,428654.8236,1.703394266,683.9167791
,117.9,191.6933351,8.092976407,430904.7868,1.706011326,688.156339
,118.2,193.9240104,8.21504371,430264.7322,1.719969778,693.0303455
,118.5,195.7783269,8.33898004,432262.0374,1.721278222,697.088008
,118.8,198.5009567,8.464731845,435598.5267,1.718660705,701.9751724
,119.1,200.8921469,8.59240541,439411.2634,1.716043221,707.0803985
,119.4,203.4993508,8.721993832,442998.746,1.714734342,711.9281173
,119.7,205.3383047,8.853590719,442519.7631,1.728256614,716.2991701
,120,207.6095838,8.987146977,442392.5712,1.740034008,720.5496896
,120.3,210.2965426,9.1226962,444257.7647,1.743523405,724.7881725
,120.6,212.51559,9.260325385,447440.1907,1.742650768,729.3805718
,120.9,214.9393951,9.400020642,452463.3008,1.736107409,734.4167682
,121.2,217.7950897,9.541796125,455998.9044,1.733926087,738.9313823
,121.5,219.993162,9.685756187,460048.3945,1.732181038,744.2963054
,121.8,222.6505692,9.83186109,461061.978,1.739160093,748.9413135
,122.1,225.0967127,9.980187318,462933.0518,1.743521937,753.7002842
,122.4,227.8129002,10.13073687,462593.4705,1.754426847,757.6746858
,122.7,230.4775576,10.28356446,465985.4166,1.754426588,762.3799683
,123,233.3323758,10.43868898,467990.9271,1.757261642,766.5165506
,123.3,235.55658,10.59619864,473150.3911,1.751372628,771.5658941
,123.6,238.4559906,10.75604347,477955.0144,1.745265429,776.4262331
,123.9,241.1869527,10.91831442,482233.5863,1.741775505,781.2284935
,124.2,243.8992205,11.08303855,483703.4141,1.747445921,786.1058143
,124.5,246.5611723,11.25025474,487522.9367,1.746573244,791.205576
,124.8,249.094594,11.42000572,491254.1097,1.74439195,795.6467783
,125.1,251.5073836,11.59232943,498843.2978,1.732614129,801.3240068
,125.4,254.3927511,11.7672258,502828.7289,1.732613841,807.2138205
,125.7,256.7061612,11.77177991,505528.5162,1.733704131,812.1053845
,126,258.3509747,11.77167289,507574.9516,1.736539314,817.0582885
,126.3,259.3913401,11.77160542,511424.5109,1.734576282,822.5092136
,126.6,260.3651455,11.77154231,517881.0038,1.725633948,828.097101
,126.9,261.1417668,11.77149211,524033.2306,1.719090772,834.2180836
,127.2,261.8439241,11.77144678,526835.6629,1.721707945,839.3616299
,127.5,262.0984655,11.77143074,522471.3046,1.74569929,843.9945485
,127.8,263.0206867,11.77137101,516276.7422,1.774052635,847.5492376
,128.1,263.209916,11.77135925,510930.1813,1.799352605,850.7401218
,128.4,263.8342813,11.77131901,511153.4235,1.806768056,854.2926133
,128.7,264.0925666,11.77130273,514440.9397,1.805023204,858.361211
,129,264.5397159,11.77127409,518284.3171,1.801969712,862.7136083
,129.3,264.8445932,11.77125476,520470.5381,1.803278302,866.7263212
,129.6,265.2809264,11.77122682,523093.321,1.803278258,870.8968213
,129.9,265.5866357,11.77120744,523420.4601,1.809385121,874.8240669
,130.2,265.828281,11.77119225,521938.4851,1.819854056,877.937145
,130.5,266.2604542,11.77116459,516700.9547,1.841664343,880.5922064
,130.8,266.3589956,11.77115876,510006.3283,1.868272937,882.6270455
,131.1,266.5698569,11.77114558,505831.9105,1.8870298,884.1863327
,131.4,266.8256462,11.77112947,504506.7361,1.896190112,885.8694342
,131.7,266.9374995,11.77112277,506578.8234,1.894881482,888.2363017
,132,267.2806487,11.77110093,512964.1747,1.879178008,891.5236076
,132.3,267.3866781,11.77109462,518991.4448,1.865219387,894.9522765
,132.6,267.5509474,11.77108449,525330.4872,1.852133173,898.8433477
,132.9,267.6836007,11.77107643,529175.1594,1.847771094,902.4166558
,133.2,268.1831659,11.77104436,530691.0647,1.850388282,905.3138736
,133.5,268.0013233,11.77105688,530835.4663,1.856931401,908.3765479
,133.8,268.1173367,11.77104991,529760.3439,1.865219315,910.6086242
,134.1,268.303238,11.77103837,529717.2892,1.870017568,913.2286156
,134.4,268.6680192,11.77101512,530619.5204,1.871762357,916.2507477
,134.7,268.6733766,11.77101539,533609.3792,1.867400292,919.463547
,135,268.8742538,11.77100287,533630.2409,1.871762337,921.7635643
,135.3,268.8821072,11.77100298,530566.6758,1.887029566,923.8608689
,136.1,268.706859,11.68276622,1.7977E+308,1.91102095,0
,136.4,268.7843682,11.50626199,1.7977E+308,1.736102115,0
,136.7,268.3343897,11.32979228,1.7977E+308,1.394116209,0
,137,268.342011,11.15329262,1.7977E+308,0.927375177,0
,137.3,267.8795525,10.97682373,1.7977E+308,0.482444485,0
,137.6,267.4636859,10.80035179,1.7977E+308,0.198910209,0
,137.9,266.6505395,10.62390584,1.7977E+308,0.044493075,0
,138.2,266.6049128,10.44740967,1.7977E+308,0.015267232,0
,138.5,266.0621662,10.27094603,1.7977E+308,0.020065505,0
,138.8,265.8522196,10.09446062,1.7977E+308,0.022246539,0
,139.1,265.522465,9.917983039,1.7977E+308,0.013522406,0
,139.4,265.1981183,9.741505108,1.7977E+308,0.0065431,0
,139.7,264.6466357,9.565042042,1.7977E+308,0.004798273,0
,140,264.480785,9.388553738,1.7977E+308,0.01701206,0
,140.3,264.0012704,9.212085962,1.7977E+308,0.030752572,0
,140.6,263.5379798,9.035617124,1.7977E+308,0.025736196,0
,140.9,263.1595531,8.859142733,1.7977E+308,0.017012062,0
,141.2,263.0157504,8.682652986,1.7977E+308,0.011559478,0
,141.5,262.8290996,8.506166043,1.7977E+308,0.011341375,0
,141.8,262.450257,8.329691678,1.7977E+308,0.012649995,0
,142.1,262.0223263,8.153220526,1.7977E+308,0.013958616,0
,142.4,261.3913876,7.976762661,1.7977E+308,0.003053447,0
,142.7,261.0241928,7.800287534,1.7977E+308,0.005016378,0
,143,260.7106621,7.623808895,1.7977E+308,0.008724136,0
,143.3,260.5672753,7.447319121,1.7977E+308,0.010468963,0
,143.6,260.0074726,7.270856599,1.7977E+308,0.018756892,0
,143.9,259.6627418,7.094380002,1.7977E+308,0.024427581,0
,144.2,259.463611,6.917893876,1.7977E+308,0.018756893,0
,144.5,258.9899203,6.741425719,1.7977E+308,0.014394825,0
,144.8,258.4941814,6.564959005,1.7977E+308,0.014612929,0
,145.1,258.0558506,6.388488533,1.7977E+308,0.018756895,0
,145.4,257.7606238,6.212008697,1.7977E+308,0.021810343,0
,145.7,257.405493,6.03553278,1.7977E+308,0.019629309,0
,146,257.0166662,5.859059069,1.7977E+308,0.018320689,0
,146.3,256.5708473,5.682589088,1.7977E+308,0.013958621,0
,146.6,256.0925804,5.50612123,1.7977E+308,0.015703449,0
,146.9,255.9105056,5.329633988,1.7977E+308,0.013086207,0
,147.2,255.4172627,5.15316711,1.7977E+308,0.013958622,0
,147.5,255.0554758,4.97669163,1.7977E+308,0.007851725,0
,147.8,254.2718648,4.800243756,1.7977E+308,0.007851725,0
,148.1,253.9974379,4.623762557,1.7977E+308,0.009160346,0
,148.4,253.677251,4.447284354,1.7977E+308,0.007851726,0
,148.7,253.3379281,4.270807403,1.7977E+308,0.013086209,0
,149,252.8388611,4.094340907,1.7977E+308,0.016575866,0
,149.3,252.4737461,3.917865644,1.7977E+308,0.011341382,0
,149.6,252.2983273,3.741377966,1.7977E+308,0.00436207,0
,149.9,251.6262042,3.564922795,1.7977E+308,0.003053449,0
,150.2,251.013153,3.388463759,1.7977E+308,0.001744828,0
,150.5,250.6788221,3.211986481,1.7977E+308,0.006106899,0
,150.8,250.4185391,3.035504357,1.7977E+308,0.013958626,0
,151.1,249.7522399,2.859048806,1.7977E+308,0.012650005,0
,151.4,249.4237329,2.682571147,1.7977E+308,0.009160349,0
,151.7,248.8040257,2.506112546,1.7977E+308,0.020501734,0
,152,248.5879323,2.329039197,1.7977E+308,0.027917255,0
,152.3,247.8216994,2.153178519,1.7977E+308,0.01526725,0
,152.6,247.3609043,1.976709518,1.7977E+308,0.001744829,0
,152.9,246.747853,1.800250481,1.7977E+308,0.010032765,0
,153.2,246.3477938,1.623777505,1.7977E+308,0.015267251,0
,153.5,245.8620386,1.447310137,1.7977E+308,0.012650008,0
,153.8,244.980251,1.270868689,1.7977E+308,0.003925865,0
,229.1,243.908716,1.101655368,1.7977E+308,0.018756914,0
,229.4,243.6567529,0.9251727,1.7977E+308,0.006979317,0
,229.7,242.8939412,0.748723464,1.7977E+308,0.024863817,0
,230,241.5620407,0.572311474,1.7977E+308,0.03620521,0
,230.3,240.5275806,0.395880017,1.7977E+308,0.03664142,0
,230.6,238.8004793,0.21949389,1.7977E+308,0.020065541,0
,230.9,236.3749128,0.043153476,1.7977E+308,0.00872415,0
,230.968,235.6733162,0.003192916,1.7977E+308,0.012431914,0
END,,,,,,