File: GB1_test59.csv
Segment,Time On Sample,Displacement Into Surface,Load On Sample,Harmonic Contact Stiffness,Harmonic Displacement,Harmonic Load
Surface Marker,0,0,0,-86.55578258,0.404001732,2.220908234
,0.2,-0.03874719,0.000659985,2541.17841,0.28925826,2.274595702
,0.4,0.11223649,0.001307515,8372.196842,0.223378926,2.340335472
,0.6,0.231598358,0.00195712,12972.42669,0.19240255,2.457571387
,0.8,0.376756965,0.002605032,14741.00967,0.18367681,2.563850677
,1,0.308052271,0.003266984,16015.80451,0.175823645,2.667938624
,1.2,0.430742749,0.00391637,18145.02372,0.160553601,2.774217922
,1.4,0.387834796,0.004576629,19930.13506,0.150519001,2.868444907
,1.6,0.445617345,0.005230277,23381.43522,0.139611826,3.157699858
,1.8,0.500903436,0.005884088,26942.38156,0.129140939,3.429424207
,2,0.633579817,0.006532387,29660.72864,0.124341782,3.698957245
,2.2,0.961396116,0.007167475,31173.06792,0.126523214,3.984925244
,2.4,1.057873906,0.00781775,33293.05106,0.126523214,4.218301405
,2.6,0.985840735,0.008479087,37779.25645,0.128704649,4.806672267
,2.8,1.120181482,0.009126877,40533.04811,0.134812665,5.349025322
,3,1.075609356,0.009786411,41744.04909,0.144410978,5.884804383
,3.2,0.872096028,0.01045638,41494.02055,0.158372162,6.4118181
,3.4,1.112120193,0.011097232,40396.32405,0.173642203,6.861039859
,3.6,1.300550876,0.01174147,40840.88147,0.194583975,7.784683568
,3.8,1.061254975,0.012413788,40126.70547,0.219452333,8.619578491
,4,1.008361321,0.013073868,39191.05522,0.246502124,9.436942835
,4.2,1.23007812,0.013715922,38916.60794,0.270061616,10.24882897
,4.4,1.059850909,0.014383705,38401.21871,0.299292844,11.18781187
,4.6,1.011950172,0.015043458,38587.01411,0.321107192,12.06215069
,4.8,1.377629421,0.015676061,38473.33772,0.349465837,13.09536075
,5,1.160801648,0.016346903,37893.49222,0.383059935,14.14829255
,5.2,1.136201193,0.017005127,36886.46351,0.4210169,15.13877159
,5.4,1.19315172,0.017657996,36262.88286,0.451120697,15.95394468
,5.6,1.109468409,0.018320098,35911.24752,0.489077663,17.11863411
,5.8,1.270438047,0.01896614,35530.94732,0.525725762,18.1967663
,6,1.013666935,0.019639605,35246.33257,0.560628725,19.25188932
,6.2,1.029009818,0.020295206,34561.23541,0.595095393,20.03967083
,6.4,1.237412172,0.020938133,32896.52006,0.654866698,20.98851484
,6.6,0.7060306,0.021629626,30493.112,0.736452376,21.92311481
,6.8,0.850357184,0.02227676,28240.4708,0.814547735,22.51148576
,7,0.990523002,0.022924167,25209.32525,0.934526639,23.13601358
,7.2,1.139842501,0.023570973,23239.98546,1.029200899,23.57537442
,7.4,1.315790891,0.024216031,21326.04832,1.140454059,24.13087554
,7.6,0.82684912,0.024904737,20340.19193,1.210696287,24.50559179
,7.8,0.823884639,0.02556154,19642.79792,1.272649034,25.00192702
,8,1.175417293,0.026195072,18985.92165,1.326312305,25.356922
,8.2,0.938617849,0.026867226,17979.67292,1.405716546,25.68452497
,8.4,1.536467753,0.027484587,17002.50823,1.486429585,25.85764016
,8.6,1.491063476,0.028144176,15980.25873,1.578922419,25.98364133
,8.8,1.67200478,0.028788906,15631.27518,1.621242236,26.13046022
,9,1.51842063,0.029455597,16062.94066,1.608589928,26.49422018
,9.2,1.453876836,0.030116442,17114.07771,1.548382337,26.96425939
,9.4,1.485862255,0.030774233,18829.37176,1.454144356,27.60631776
,9.6,1.678454221,0.031414916,21475.11995,1.328493705,28.47846544
,9.8,1.745390581,0.03206713,23296.28347,1.259560366,29.13148051
,10,1.705811375,0.032726336,24679.01757,1.220730832,29.85242651
,10.2,1.574695352,0.033391552,24924.04894,1.227275145,30.34547463
,10.4,1.6008557,0.034049725,24652.17332,1.255633794,30.78045276
,10.6,1.57708792,0.034704612,23981.48689,1.306679367,31.22857874
,10.8,1.749707695,0.035349888,23472.50072,1.346381465,31.54851241
,11,1.703471265,0.036009532,22935.31648,1.39175531,31.93966396
,11.2,1.587333994,0.036673764,22696.1305,1.418368821,32.24425814
,11.4,1.968824137,0.037305328,22602.9537,1.439746852,32.57953128
,11.6,1.715381645,0.037978574,22760.10754,1.450654045,33.01341345
,11.8,2.121836372,0.0386085,22935.15947,1.456325744,33.35416491
,12,1.951609167,0.039276283,23358.29912,1.455016896,33.80338648
,12.2,2.399671531,0.039903477,23868.11345,1.444109689,34.18248629
,12.4,2.152054114,0.040576341,24905.94858,1.411388189,34.77085691
,12.6,2.318848814,0.041221999,25628.70145,1.390882692,35.21788746
,12.8,2.260962246,0.041882407,26946.31277,1.348999152,35.82378886
,13,2.180607551,0.04254429,28137.2491,1.312351057,36.34861128
,13.2,2.394834963,0.043186835,29731.59868,1.267849777,37.03887906
,13.4,2.243747277,0.043853361,30617.15964,1.251270884,37.58232756
,13.6,2.188357167,0.044513606,31575.12321,1.234255698,38.17069841
,13.8,2.356816173,0.045159155,32328.35572,1.226838809,38.81385263
,14,2.460367256,0.045808965,32628.10664,1.23425568,39.4022237
,14.2,2.667105289,0.046452001,32468.52611,1.257378873,39.9456725
,14.4,2.74402748,0.047103559,32401.84079,1.273521484,40.39599003
,14.6,2.745223764,0.047760089,32408.67723,1.287918952,40.88575131
,14.8,2.634911569,0.048423938,32161.12214,1.313659887,41.40947795
,15,2.582017919,0.049084019,31879.10891,1.34070968,41.90581307
,15.2,2.706372822,0.049732463,31859.09886,1.353798281,42.3210694
,15.4,2.789120083,0.050383639,31871.58311,1.366014306,42.745091
,15.6,2.781994838,0.051040715,31593.93636,1.393500383,43.25566981
,15.8,2.492769785,0.051716309,31442.50924,1.415314753,43.72023051
,16,2.830987964,0.052350714,31499.7907,1.425349322,44.09933021
,16.2,2.52095909,0.053027675,31512.80385,1.44192825,44.56827345
,16.4,2.97734297,0.053654322,31486.35815,1.45676197,44.93532105
,16.6,2.843730497,0.054319701,31785.46409,1.461561139,45.45466502
,16.8,2.933967133,0.054970385,32054.80689,1.462433704,45.85896469
,17,2.984260433,0.055623691,32308.07114,1.466360282,46.34215203
,17.2,2.802383096,0.056292239,32592.70805,1.46854173,46.83958268
,17.4,2.810236603,0.056948331,33061.24669,1.461124857,47.27894345
,17.6,2.959556089,0.057595137,33358.7425,1.461561128,47.72049574
,17.8,3.145490297,0.058239539,33650.81695,1.465487702,48.22997918
,18,2.805503926,0.058918466,33901.59406,1.470286881,48.70878333
,18.2,3.172015296,0.059551013,34113.29609,1.473340856,49.09774412
,18.4,2.924397889,0.060223876,34068.34472,1.489919779,49.58750502
,18.6,3.23848363,0.060859865,34147.15697,1.497772921,49.96441345
,18.8,3.213883177,0.061518088,34258.11682,1.506062372,50.42678325
,19,3.713538985,0.062141894,34307.57989,1.515660644,50.87490996
,19.2,3.7688252,0.062794872,34360.65238,1.52264123,51.22442645
,19.4,3.498323599,0.063469238,34403.02059,1.530930703,51.5859948
,19.6,3.664286135,0.06411495,34399.75203,1.542710435,52.04617338
,19.8,4.081974884,0.064744137,34383.25388,1.553181287,52.46581289
,20,4.323663317,0.065384878,34522.89545,1.554926414,52.80546865
,20.2,4.23415495,0.066047362,34690.00771,1.55798043,53.23387271
,20.4,4.489157825,0.066687229,34932.43998,1.557107836,53.62173769
,20.6,4.434599875,0.067347418,35436.05503,1.550563537,54.14108178
,20.8,4.13455686,0.068023722,35922.20585,1.545328119,54.63084256
,21,4.158221268,0.068678776,36117.67636,1.548818413,54.98035903
,21.2,4.002140679,0.06934563,36197.39069,1.559725598,55.39123235
,21.4,4.034958768,0.070000083,36440.95965,1.561034456,55.76923602
,21.6,4.349876645,0.070636017,36682.15126,1.564524725,56.25461513
,21.8,4.17715299,0.071304038,37047.82476,1.562779592,56.72574996
,22,4.595257125,0.07193747,37773.56813,1.545328083,57.1771637
,22.2,4.624744882,0.072602967,39054.21743,1.511297705,57.81045675
,22.4,4.050088635,0.073315055,40000.16116,1.489483407,58.33856533
,22.6,4.231026018,0.073984313,41266.60106,1.462869893,59.05951166
,22.8,4.507659894,0.074654026,42143.54272,1.446290971,59.61501322
,23,4.354069693,0.075358924,42713.62429,1.442364401,60.24501905
,23.2,4.496724786,0.076051205,42948.8679,1.448472407,60.81914655
,23.4,4.561988535,0.076755721,43096.41637,1.455016705,61.3001427
,23.6,4.276082696,0.077490378,43306.67095,1.459815883,61.82277342
,23.8,4.832314308,0.078176874,43583.89657,1.464178709,62.42977166
,24,4.621299931,0.078921013,43846.17589,1.468977881,63.02909866
,24.2,4.57338632,0.079661813,44025.32145,1.47377704,63.5100946
,24.4,4.659448153,0.080401044,44097.18995,1.485993066,64.14338797
,24.6,4.845367118,0.081141242,43963.39262,1.500390518,64.55426173
,24.8,4.804107197,0.081903824,43697.94423,1.521768577,65.04292736
,25,4.610562102,0.082684097,43595.67587,1.53747492,65.5348795
,25.2,4.769016405,0.083448882,43509.45019,1.550127227,65.93041413
,25.4,4.699459612,0.084236467,43631.65749,1.556235249,66.3708704
,25.6,4.863736499,0.085016504,44123.0757,1.55274494,66.98553751
,25.8,4.905685673,0.085812498,44713.25439,1.544891774,67.58924774
,26,4.777874392,0.086627793,45270.53324,1.538347481,68.18200123
,26.2,4.833135442,0.087439072,45799.36272,1.531366887,68.69038875
,26.4,4.854276932,0.088260749,46346.48491,1.524386296,69.219594
,26.6,4.903710301,0.089088834,46914.30847,1.52045971,69.89013976
,26.8,5.126230105,0.089913943,47209.11298,1.525258848,70.50699836
,27,5.273022696,0.090752285,47322.2807,1.531366852,70.95074208
,27.2,5.249221956,0.09161455,47430.1355,1.539656305,71.51829547
,27.4,5.813753175,0.092438225,47479.19183,1.547509422,71.96751815
,27.6,5.457089307,0.093335225,47557.22416,1.556671475,72.55917548
,27.8,5.206107407,0.094234227,47922.05547,1.556235209,73.1606938
,28,5.411143075,0.095116633,48389.36735,1.553181184,73.7644044
,28.2,5.604527891,0.096004282,48704.24286,1.553181169,74.22896595
,28.4,5.718857503,0.096901499,48822.93179,1.56277947,74.84472864
,28.6,5.614328793,0.097826681,48793.90553,1.573250363,75.24464533
,28.8,5.662082559,0.098751104,48702.0709,1.588084112,75.75960698
,29,5.730638669,0.099683433,48861.80302,1.595064696,76.28552529
,29.2,5.781718065,0.100626386,49015.95729,1.599863847,76.72050358
,29.4,5.929325693,0.101572317,49521.28344,1.59637354,77.3132575
,29.6,5.901347547,0.102539559,50144.04344,1.587647806,77.86437587
,29.8,5.43565555,0.103545159,50685.62509,1.583721263,78.49766776
,30,5.554133169,0.10452236,51096.35841,1.58284868,79.10466531
,30.2,5.655966185,0.105510399,51421.90156,1.581976098,79.60100085
,30.4,6.114791132,0.106484895,51813.09043,1.579358339,80.1214417
,30.6,5.778076491,0.107521767,52543.65964,1.57063263,80.8423871
,30.8,6.191129824,0.108519486,53506.30192,1.55492627,81.56004719
,31,6.233041438,0.109551755,54177.60189,1.545764243,82.13746156
,31.2,5.986194405,0.110613466,55147.81959,1.532675659,82.8923728
,31.4,6.255280361,0.111651837,55757.63537,1.527876482,83.50484899
,31.6,5.960997267,0.112737783,56182.00862,1.530494227,84.2707166
,31.8,6.019545229,0.113811147,56355.07976,1.536165951,84.80978288
,32,6.32856944,0.114878816,56694.43311,1.540528794,85.5011469
,32.2,6.233165713,0.115983946,56879.07624,1.547945679,86.14977904
,32.4,6.154403283,0.117099035,57122.27197,1.552308553,86.72390626
,32.6,6.376878351,0.118205489,57446.99512,1.557543977,87.46238349
,32.8,6.752467737,0.119313024,57594.65262,1.563215675,87.99049393
,33,6.581331006,0.120467884,57577.76608,1.574995436,88.61830824
,33.2,6.675649164,0.121616696,57748.09762,1.58153973,89.26036686
,33.4,6.8049159,0.122774754,57850.89414,1.587647733,89.78628545
,33.6,6.84181182,0.123950642,58136.89165,1.591574313,90.47984008
,33.8,6.792161991,0.125143993,58449.64153,1.592010601,91.01561909
,34,6.727531496,0.126350394,58842.83006,1.592883185,91.70588653
,34.2,7.004081698,0.127546296,59076.69453,1.59768232,92.35232834
,34.4,6.933622308,0.128777156,59449.69091,1.597246037,92.91659453
,34.6,6.951369155,0.130014454,59895.35703,1.595500885,93.52578313
,34.8,7.104754913,0.131255243,60375.53034,1.594192011,94.19852054
,35,7.264795902,0.132508107,60875.03874,1.592446854,94.90741485
,35.2,7.379898641,0.133776543,61151.7349,1.593755703,95.45415094
,35.4,7.563235847,0.135053385,61337.38628,1.60073628,96.19262822
,35.6,7.833114887,0.136337347,61209.01233,1.61207971,96.69005991
,35.8,7.602868144,0.137667115,61127.08503,1.623859475,97.29267387
,36,7.753745201,0.138985056,61368.07705,1.628658616,97.92487177
,36.2,7.946227786,0.140313487,61794.5023,1.626913451,98.45736453
,36.4,8.088779101,0.141658479,62295.66209,1.623859432,99.04792718
,36.6,8.192217084,0.143019626,63308.7741,1.611643394,99.87077031
,36.8,8.055992933,0.144410253,64046.53799,1.605099103,100.611438
,37,8.19895378,0.14579639,64566.14349,1.601608797,101.2228184
,37.2,8.328181886,0.147197407,65001.11568,1.601608786,101.9328083
,37.4,7.975175311,0.148644248,65466.05294,1.599863669,102.5704833
,37.6,8.40230952,0.15005418,66026.11723,1.598118486,103.3889446
,37.8,8.168712278,0.151521909,66814.07866,1.588956483,104.0529157
,38,8.349524711,0.152976995,67880.83602,1.576304151,104.9042463
,38.2,8.334778956,0.154459575,68982.9731,1.564088123,105.8125507
,38.4,8.372456459,0.155953531,70029.52129,1.552308377,106.6058108
,38.6,8.48169669,0.15745785,71126.10826,1.540964911,107.4439933
,38.8,8.850566136,0.158960136,71907.81402,1.537910874,108.3654468
,39,8.877418446,0.16050015,72510.28079,1.538347159,109.2627949
,39.2,9.021601815,0.16204789,72984.95243,1.538783434,109.9716893
,39.4,9.343863361,0.163599459,73191.33175,1.544891423,110.7003062
,39.6,9.228410148,0.165195602,73178.20701,1.557543749,111.6108018
,39.8,9.37008955,0.166790726,73081.36008,1.568450906,112.2769653
,40,9.396097193,0.168409519,72970.82515,1.581539507,113.0494076
,40.2,9.570225406,0.170034834,72900.32139,1.593755522,113.8404767
,40.4,9.46724422,0.171694716,72821.74683,1.6046627,114.5285528
,40.6,9.578123591,0.173357201,72902.93538,1.611643278,115.1673248
,40.8,9.51924118,0.175047592,73120.2416,1.616006151,115.8170527
,41,9.689198031,0.176739856,73059.74246,1.627349592,116.568678
,41.2,9.532116214,0.178470709,72902.90884,1.638256775,117.1351352
,41.4,9.538965692,0.180208123,72788.35098,1.648727657,117.7037842
,41.6,9.594909393,0.18195979,72653.21352,1.661816255,118.4214437
,41.8,9.125762023,0.183763634,72545.78219,1.671414605,118.9364038
,42,9.739242291,0.185514159,72943.30309,1.672287124,119.6704999
,42.2,10.02069086,0.187304278,73356.9312,1.67097824,120.2753068
,42.4,10.08993767,0.18912633,73977.93796,1.665306506,120.9359919
,42.6,10.12589547,0.190968896,74554.37761,1.662688782,121.7676002
,42.8,9.813178413,0.192852909,75081.34906,1.660943663,122.5477111
,43,9.868269782,0.194731575,75254.1011,1.665306526,123.120743
,43.2,10.27702298,0.196605851,75693.0293,1.667051637,123.8614125
,43.4,10.40034483,0.198517912,76134.3367,1.6679242,124.5034716
,43.6,10.92476116,0.20042263,76908.95636,1.662252426,125.2178457
,43.8,10.955708,0.202379039,77830.99763,1.65483555,126.0680804
,44,11.24378685,0.204338092,78788.54799,1.644364643,126.797793
,44.2,11.35627838,0.206328454,79582.02131,1.639129193,127.6885675
,44.4,11.1433951,0.208360275,80016.93412,1.638256638,128.4007475
,44.6,11.51384749,0.210374,80429.09735,1.63782032,129.1282691
,44.8,11.96834405,0.212402447,80765.11397,1.640438001,129.9850791
,45,11.98762161,0.214480034,81238.84495,1.638692852,130.6611034
,45.2,11.93949152,0.216582844,82418.21343,1.627349403,131.6461044
,45.4,11.8697221,0.218708231,83575.50234,1.616005954,132.4963388
,45.6,12.02213399,0.220840366,84272.76749,1.613388221,133.3345212
,45.8,11.93654516,0.223020386,85290.20662,1.607280215,134.3633487
,46,12.1896406,0.225189275,85629.6015,1.610770487,135.1182612
,46.2,12.04246901,0.22739521,85575.86333,1.622113954,135.9641126
,46.4,12.35214383,0.22960435,85594.12581,1.629967088,136.668625
,46.6,12.06682611,0.231874915,86356.55519,1.627785679,137.689782
,46.8,12.15930199,0.234143278,87035.05255,1.624295378,138.4731815
,47,12.67950061,0.236406245,88176.90245,1.6155696,139.5337853
,47.2,12.23023798,0.238756064,89029.10956,1.610334198,140.3829222
,47.4,12.2644522,0.241097463,89604.84249,1.610334195,141.2353486
,47.6,12.25122997,0.243465613,89641.36122,1.621241364,142.2126797
,47.8,12.62162624,0.24583225,89266.53693,1.635638793,142.8580268
,48,12.30216436,0.248268092,88738.66292,1.653962862,143.6227982
,48.2,12.41375355,0.250699992,88300.85774,1.668360313,144.1969262
,48.4,12.36972635,0.253166612,87982.14191,1.681012631,144.7995405
,48.6,12.46466467,0.25564887,87771.42477,1.693664937,145.5621222
,48.8,12.60453526,0.258153051,87697.05302,1.701954372,146.1493984
,49,12.64038279,0.260689267,87467.43874,1.714606683,146.814466
,49.2,12.72282679,0.263248037,87380.31345,1.724641269,147.4762469
,49.4,12.73786238,0.265836822,87364.23659,1.732058142,148.058044
,49.6,12.97757497,0.268436866,87422.78725,1.73729356,148.5861545
,49.8,13.18399734,0.271065129,87800.84565,1.738166115,149.2939538
,50,13.17904878,0.273733775,88434.84686,1.732930675,149.9184818
,50.2,13.1191739,0.276432818,89257.85897,1.725950094,150.7062629
,50.4,13.64596217,0.279120267,89934.52555,1.720714607,151.3943419
,50.6,13.38303353,0.28188673,90605.02213,1.715915478,152.1163825
,50.8,13.69678208,0.284642949,91029.43066,1.716351738,152.9030699
,51,13.73674805,0.287445113,91082.83603,1.721587174,153.4936326
,51.2,13.65188672,0.290283491,90825.45106,1.732930636,154.1302124
,51.4,13.89322458,0.293128986,90567.03142,1.743401491,154.6583231
,51.6,13.67271336,0.296033276,90553.64013,1.751254672,155.3485899
,51.8,14.02887912,0.298928591,90790.78347,1.752999789,155.8920404
,52,14.00973952,0.301877788,91177.43414,1.753436077,156.56916
,52.2,14.17366875,0.30484451,92091.05486,1.745146612,157.3602295
,52.4,13.87325221,0.307871643,92629.43567,1.742528923,158.0515916
,52.6,14.22607045,0.310886132,92913.48648,1.743401463,158.6311989
,52.8,14.50731876,0.313935657,92983.89551,1.749073165,159.3072243
,53,14.48565873,0.317035896,92817.38202,1.757362611,159.8079423
,53.2,14.64373867,0.320155343,92214.54516,1.774377776,160.3130437
,53.4,14.57130742,0.323321323,92192.10426,1.779176932,160.6877601
,53.6,15.36098096,0.326462205,92318.56801,1.784412301,161.3331093
,53.8,15.7137695,0.329663394,92508.47075,1.786593702,161.8097244
,54,16.07820302,0.332896143,93337.31001,1.779176794,162.532864
,54.2,15.79022399,0.336204311,94331.98246,1.767833369,163.1869734
,54.4,16.06935147,0.339508305,95468.0103,1.754744746,163.9046339
,54.6,16.26692271,0.342851114,96883.01517,1.739474695,164.860053
,54.8,16.12705088,0.346249622,98115.47181,1.725949823,165.6467386
,55,16.26927327,0.349663576,99498.81063,1.712424926,166.6174968
,55.2,16.30414255,0.353118923,100511.5662,1.703699191,167.4162356
,55.4,16.67602798,0.35658679,101547.0096,1.696718572,168.3979512
,55.6,16.70506114,0.360112105,102581.1847,1.688865411,169.2865345
,55.8,16.93130875,0.363659875,103483.9057,1.684066238,170.2923541
,56,16.79223586,0.367267283,103840.436,1.685375111,171.0417871
,56.2,16.8187555,0.37090004,103899.9682,1.692355694,171.8942131
,56.4,17.09408286,0.374553007,103702.5985,1.701953974,172.5899607
,56.6,17.31947524,0.378245919,103107.7014,1.717223985,173.2101071
,56.8,17.56150476,0.381974906,102995.6382,1.726822267,173.9737856
,57,17.64791587,0.385751538,103299.7757,1.728567406,174.6311839
,57.2,17.78841085,0.389562518,104180.9155,1.723331954,175.5416808
,57.4,17.76246928,0.393422808,105164.5538,1.715478799,176.3623323
,57.6,17.84054059,0.397314999,106637.328,1.702826481,177.4711436
,57.8,17.98933861,0.40124165,107493.24,1.697154743,178.2961791
,58,18.40941198,0.405189879,108276.914,1.694536986,179.318435
,58.2,18.08220635,0.409227091,108627.3649,1.695845875,180.0558145
,58.4,18.47147735,0.413257495,108954.676,1.698027273,180.8457898
,58.6,18.36228274,0.417361266,108930.5714,1.707189301,181.7858683
,58.8,19.0111722,0.421456357,108915.9781,1.71373354,182.4881917
,59,18.87200701,0.425644508,108761.9116,1.723331857,183.3230865
,59.2,19.23878363,0.42984152,108771.8594,1.729003549,183.9717206
,59.4,19.08629061,0.434114891,109133.0202,1.732057569,184.9249473
,59.6,19.0569493,0.438422955,109452.7203,1.733366431,185.6217888
,59.8,19.30886853,0.442755799,109805.378,1.736420414,186.497225
,60,19.18215161,0.447157186,110052.0048,1.739038145,187.1458571
,60.2,19.11284616,0.451598974,110360.4011,1.742092157,187.9807521
,60.4,19.18333519,0.45607608,110407.3976,1.747327589,188.6392462
,60.6,19.15063018,0.460605087,110895.5796,1.746891306,189.4084014
,60.8,19.41582842,0.465159921,111769.6529,1.741655843,190.3430035
,61,19.72678775,0.469757513,112687.8041,1.735111517,191.1527005
,61.2,19.35537497,0.474446338,113493.0676,1.732057545,192.0982558
,61.4,19.93676892,0.479119362,114149.3257,1.730312346,192.9134321
,61.6,19.97725651,0.483874998,114807.3366,1.728567197,193.7494235
,61.8,21.53974267,0.488578119,114965.0572,1.734238778,194.6161022
,62,22.13026767,0.493392447,115280.4128,1.73598387,195.3491041
,62.2,22.28057653,0.498284266,116539.4032,1.726385555,196.3976548
,62.4,22.29190819,0.50323436,117650.7883,1.717659824,197.3158205
,62.6,22.67104314,0.508209941,118952.5984,1.706752629,198.3325985
,62.8,22.53256755,0.513295,121356.9287,1.684502032,199.7109423
,63,22.87923657,0.518348208,123134.4819,1.669668261,200.8339989
,63.2,22.95377973,0.52349576,124181.4326,1.666177963,202.0940123
,63.4,22.8893453,0.528704144,124757.7803,1.667050542,203.0823001
,63.6,23.10699784,0.533972918,125059.5451,1.67228596,204.0914076
,63.8,23.4511375,0.539233157,124828.4841,1.68450195,205.1465333
,64,23.46822878,0.544594606,124443.6452,1.696281683,205.9277412
,64.2,23.62511303,0.55000071,124998.4383,1.698026815,207.0113536
,64.4,23.73122735,0.555464579,125493.7743,1.698899378,207.9317112
,64.6,23.71583879,0.56099119,125895.1151,1.701080812,208.8816511
,64.8,23.75536344,0.566569649,126005.2592,1.707625105,209.9082879
,65,23.91138043,0.572196626,126214.3267,1.711551669,210.7530455
,65.2,23.7753031,0.577899399,125855.6286,1.723331415,211.6449145
,65.4,24.12269695,0.583627531,125125.2636,1.738601408,212.3209413
,65.6,24.4259776,0.589416092,124849.6691,1.748199682,213.0484633
,65.8,25.24767964,0.59522863,125056.7304,1.75256247,213.9523904
,66,25.4410977,0.601141002,124972.8882,1.759106748,214.6349903
,66.2,25.71938581,0.607107133,125451.901,1.759543009,215.5542535
,66.4,25.98018918,0.613134446,126568.3481,1.75168983,216.4713256
,66.6,26.65456239,0.619195091,127920.4244,1.741655181,217.485914
,66.8,26.6382399,0.625362064,129311.6386,1.732929456,218.6560826
,67,26.76170907,0.631581766,130880.8967,1.720713426,219.6717635
,67.2,26.98086577,0.637857614,132610.7134,1.708933675,220.9493084
,67.4,27.28156331,0.644191218,134112.3888,1.698899062,222.0888002
,67.6,27.51484645,0.650592761,135370.632,1.691918459,223.2392482
,67.8,27.91621402,0.657047581,136910.9022,1.683192697,224.6132129
,68,28.08124018,0.66358281,137841.5522,1.680138678,225.7012078
,68.2,27.97663875,0.670201358,138806.0211,1.678829828,227.0346294
,68.4,28.10919003,0.676870594,139275.4726,1.681011248,228.0557889
,68.6,28.68776397,0.683577591,139666.2472,1.686246633,229.3771626
,68.8,28.42086101,0.690407775,140093.4003,1.688428091,230.3720236
,69,28.4443681,0.69728738,140673.9514,1.688864374,231.4161909
,69.2,28.85897553,0.704210332,141121.5571,1.691918339,232.6805896
,69.4,29.17621015,0.71120927,141191.9674,1.697590033,233.6590193
,69.6,29.4776227,0.718279526,141041.7491,1.706315733,234.6538838
,69.8,29.59095768,0.725433192,140329.9614,1.72202203,235.6377904
,70,30.08124595,0.732633861,139888.5337,1.73336543,236.4157148
,70.2,30.13464306,0.739935766,140351.6145,1.736419427,237.4905612
,70.4,30.36943758,0.747299098,141232.8894,1.733365403,238.4525554
,70.6,30.26719891,0.754758633,142922.7223,1.723767116,239.8473345
,70.8,30.49697684,0.762271232,144457.8811,1.714168794,240.9857305
,71,30.38056769,0.769882027,145863.207,1.70762451,242.3377786
,71.2,30.80338066,0.777533777,146410.7951,1.708060755,243.335931
,71.4,31.17458801,0.78526576,146462.5991,1.713732446,244.3055959
,71.6,31.33192003,0.793089583,146582.2079,1.720276728,245.5426012
,71.8,31.85080943,0.800968145,147174.0206,1.719840395,246.5615718
,72,32.50491081,0.808917285,148391.8203,1.714168613,247.8708945
,72.2,32.56609147,0.816985479,149619.046,1.708060601,249.0114809
,72.4,32.78079127,0.825124264,151220.6675,1.698898571,250.2517735
,72.6,33.04790362,0.833341306,153503.955,1.68580996,251.94348
,72.8,33.01542828,0.841660676,154583.2034,1.682755959,253.1289883
,73,33.15186644,0.850052406,155325.9015,1.684937379,254.4974731
,73.2,33.71768138,0.858500192,155822.8677,1.68930019,255.8451436
,73.4,34.20775702,0.867037851,156276.5128,1.69235415,256.975872
,73.6,34.48145964,0.875675502,156359.0449,1.698898419,258.0967379
,73.8,34.59287892,0.88441059,157003.4344,1.70107984,259.4882315
,74,35.04713064,0.893210998,157885.3888,1.698898368,260.6342992
,74.2,35.31663068,0.90211194,159683.8322,1.689736334,262.2054828
,74.4,35.59027727,0.911101973,160830.7791,1.686246021,263.5169946
,74.6,35.71828297,0.920192085,162407.2133,1.679701717,264.9676542
,74.8,36.0135366,0.929362402,163593.3517,1.677956546,266.5333602
,75,36.2330498,0.938629885,164198.4691,1.679701671,267.7254438
,75.2,36.85697376,0.947963903,164130.0248,1.689299911,269.0785932
,75.4,36.82348323,0.957434973,163920.0798,1.698461923,270.1928834
,75.6,37.04378373,0.966984489,163443.0208,1.710241629,271.2830703
,75.8,37.2898657,0.976628066,163099.5094,1.72114876,272.4631027
,76,37.58918994,0.986365094,162911.196,1.730310741,273.6529957
,76.2,37.81360499,0.996204991,163247.8561,1.732928437,274.6566254
,76.4,38.08210836,1.006140757,163709.9529,1.734673557,275.7248994
,76.6,38.40052492,1.016173132,164918.4773,1.730746953,277.2226742
,76.8,38.49590891,1.026320976,166070.7574,1.725947797,278.3873661
,77,38.4747755,1.036578478,166958.3148,1.725511513,279.7733805
,77.2,38.81477939,1.046915195,167096.7158,1.730310629,280.7792026
,77.4,38.95837905,1.057368772,167108.4776,1.736854907,281.8211802
,77.6,39.70443956,1.067887512,166212.6833,1.75343371,282.9267109
,77.8,39.96450689,1.078544106,165325.537,1.76739484,283.6860077
,78,39.75772035,1.089338564,165071.7508,1.77612058,284.6940168
,78.2,40.34478888,1.100189026,165498.8166,1.776993097,285.6110924
,78.4,40.79619941,1.111157487,166393.9167,1.773502767,286.6607425
,78.6,41.11111962,1.122245117,168761.9396,1.75779644,288.2122055
,78.8,41.56748782,1.133434757,170719.027,1.745580389,289.4864657
,79,42.39913831,1.144712134,172239.3091,1.739036022,290.9437057
,79.2,42.85214198,1.156127827,173591.9388,1.732927977,292.1445575
,79.4,43.12538278,1.167670062,174568.3729,1.730746522,293.3585551
,79.6,43.76391946,1.179304155,174733.5471,1.737727039,294.7653929
,79.8,43.86403582,1.191090573,175418.2001,1.73772703,295.8687278
,80,44.09561321,1.202986792,176854.6281,1.733364149,297.3785545
,80.2,44.23979575,1.215008277,177398.1309,1.73510928,298.4994203
,80.4,44.99226147,1.227110562,178190.5721,1.735109211,299.7101347
,80.6,45.26953982,1.239427364,179750.5852,1.73031004,301.3448683
,80.8,45.35292701,1.251756811,180223.5097,1.732491462,302.4613506
,81,45.76331995,1.264250828,180383.1378,1.738599428,303.7827247
,81.2,46.10878514,1.276874751,180470.4329,1.743834827,304.8290871
,81.4,46.23786063,1.289704405,180773.2118,1.747325103,305.952144
,81.6,46.79799034,1.30250553,181019.3754,1.752560482,307.3293987
,81.8,47.19581983,1.315510927,181755.7117,1.751687873,308.4327359
,82,47.59113211,1.32864708,183406.4436,1.744270976,309.9589992
,82.2,47.49545437,1.341947494,186051.1434,1.727692121,311.465537
,82.4,47.97810027,1.355343421,188545.5767,1.713294643,313.0411061
,82.6,48.4074671,1.3688775,191416.1138,1.698460885,315.0987672
,82.8,48.51060917,1.382569056,193294.1005,1.690171444,316.6710463
,83,49.05643363,1.396368997,194219.4942,1.691480253,318.3945311
,83.2,48.9223688,1.410352391,193752.516,1.703696269,319.864911
,83.4,49.33916549,1.42443999,193917.4047,1.709367948,321.1424585
,83.6,49.6893676,1.438673584,194058.9796,1.715475918,322.462737
,83.8,49.89558489,1.453059622,194571.737,1.719838757,324.0065303
,84,50.55946212,1.467560119,196076.6525,1.715039553,325.4418567
,84.2,51.03192152,1.482218831,197663.2934,1.711112938,327.1839674
,84.4,51.20894396,1.497044351,198355.3052,1.712858065,328.5557406
,84.6,51.54904428,1.512008017,198959.2039,1.715475749,329.9275156
,84.8,52.5523448,1.527078394,200008.068,1.715911944,331.6466223
,85,53.56976778,1.542299164,200565.6205,1.717656995,332.9460895
,85.2,53.68927591,1.557731724,201847.5295,1.715475555,334.6673791
,85.4,54.3430001,1.573284138,203163.8278,1.71198521,336.2056982
,85.6,54.82111567,1.58900428,204617.1673,1.707186024,337.8305734
,85.8,54.89394881,1.604908967,205495.4534,1.707622303,339.6033577
,86,55.57589078,1.620933262,205770.9757,1.711985099,340.9148745
,86.2,55.73854518,1.637152786,206111.3439,1.7176568,342.5298857
,86.4,56.18244059,1.653516582,206869.8693,1.718965614,343.9400108
,86.6,56.67124596,1.670041986,208113.3569,1.719401854,345.7949753
,86.8,56.72314592,1.68676215,209865.8437,1.713730138,347.3179499
,87,57.24268774,1.703619568,212216.262,1.705440662,349.3416472
,87.2,57.59161182,1.720657396,214023.6368,1.699332631,350.9435111
,87.4,58.56378936,1.737825319,215288.2282,1.697587402,352.5618182
,87.6,58.94677695,1.755204554,216749.3642,1.69627851,354.6140016
,87.8,59.63846457,1.77273802,217200.1302,1.69976873,356.0679554
,88,60.16619053,1.790458599,218119.4994,1.701513831,357.9415471
,88.2,60.60318378,1.808363222,218904.6145,1.704131501,359.7822679
,88.4,61.2615004,1.826433175,219782.6483,1.70456773,361.3545533
,88.6,61.34477228,1.844722642,220904.2402,1.70369515,363.0462602
,88.8,61.63771686,1.863181855,222893.8014,1.698023409,365.1291216
,89,62.08874049,1.881816212,224661.4206,1.692787946,366.8734243
,89.2,62.62960658,1.900631812,226642.6867,1.687552468,368.9288967
,89.4,62.896249,1.919655196,228667.2283,1.681880734,370.8397382
,89.6,63.31306411,1.938860076,230973.1214,1.675772699,373.0650381
,89.8,63.77353654,1.958254288,232139.3094,1.677081515,374.9945082
,90,64.11539662,1.977850965,232168.0611,1.686679761,376.9195946
,90.2,64.53378322,1.997639385,232212.5114,1.693660296,378.414085
,90.4,65.37237402,2.017599031,230574.5872,1.711547926,379.7354659
,90.6,65.69749628,2.037793114,227241.3756,1.742087879,380.9834312
,90.8,66.21564513,2.058177217,225467.6032,1.759975535,381.9618655
,91,66.61642824,2.078773918,224410.5481,1.773500347,383.241606
,91.2,67.06211456,2.099574547,223831.7071,1.782226014,384.2222313
,91.4,67.65256174,2.12057473,224279.2454,1.784407385,385.4548606
,91.6,68.24713614,2.141785444,226920.1854,1.773063908,387.3843326
,91.8,68.58204582,2.163226569,228946.5801,1.764338169,388.8470485
,92,69.05838676,2.184873711,231845.6092,1.752122133,390.8389724
,92.2,69.68780869,2.206728394,233901.2862,1.744705223,392.457277
,92.4,70.77404601,2.228772411,236668.6556,1.73467056,394.6124616
,92.6,71.21866049,2.251080362,238204.8395,1.731180236,396.3436169
,92.8,71.9994279,2.273590079,239361.3252,1.731180165,398.261039
,93,72.36408443,2.296353381,240156.874,1.731616417,399.728139
,93.2,72.95255287,2.319330768,242659.8335,1.722890657,401.9282408
,93.4,73.33794006,2.34255236,244957.2043,1.714601201,403.8642847
,93.6,74.1252185,2.365980718,247278.7883,1.70718428,405.8222474
,93.8,74.48889528,2.389672364,249134.989,1.70413025,408.0519296
,94,75.40674591,2.413565518,249818.6299,1.706747879,409.6998201
,94.2,75.61889542,2.43774529,248883.9398,1.720708987,411.4419301
,94.4,76.18466992,2.462144685,248095.2072,1.732052351,412.8356229
,94.6,76.32018409,2.48681747,248227.5923,1.738596617,414.7289339
,94.8,77.71553337,2.51165515,249689.8338,1.735542492,416.4096999
,95,77.95249067,2.536818881,252199.544,1.727253052,418.6218506
,95.2,78.53641417,2.56221248,254628.8679,1.718527295,420.5381762
,95.4,79.41487803,2.587841721,256226.7489,1.715473219,422.4468352
,95.6,79.88804411,2.613755221,257563.4153,1.716345746,424.7433549
,95.8,80.92703043,2.639891776,258053.4441,1.719835933,426.3627598
,96,81.3152341,2.666333902,258146.4362,1.727252744,428.2768918
,96.2,82.42819767,2.692993774,258374.8077,1.732488063,429.8228894
,96.4,83.01603234,2.71995629,259053.6553,1.735542005,431.4915946
,96.6,83.19274218,2.747216691,260608.0218,1.735105703,433.7103193
,96.8,84.23983667,2.774693602,261372.1063,1.736850747,435.2990464
,97,84.35987291,2.802507732,262283.477,1.739468446,437.3161675
,97.2,85.02492253,2.830565309,263052.2594,1.74077724,438.8490117
,97.4,85.49936512,2.858917417,262962.8869,1.746885186,440.3226882
,97.6,86.12937432,2.887544199,262056.0511,1.759101108,442.0921945
,97.8,86.45643548,2.916478461,261673.1303,1.766517922,443.4321976
,98,87.78452587,2.945637477,261597.0962,1.773062072,445.1261127
,98.2,88.35448178,2.975139397,261822.0155,1.776552298,446.4924155
,98.4,89.32382209,3.004911461,263597.5066,1.771753073,448.132639
,98.6,89.89617973,3.035008742,266500.8553,1.762591036,450.3535601
,98.8,90.5583614,3.065402424,269419.6898,1.753428991,452.5690041
,99,91.81878497,3.096217038,270880.887,1.75124745,454.2212834
,99.2,92.35271762,3.127235724,272113.8225,1.751683685,456.227454
,99.4,92.86415777,3.158409817,271839.1918,1.758664195,457.6967487
,99.6,93.83653355,3.190024318,271389.5708,1.766517231,459.1638578
,99.8,94.81967672,3.221955821,271514.7939,1.771752556,460.9202227
,100,95.21194315,3.254247275,272648.6008,1.77000738,462.4727855
,100.2,95.66240845,3.286859188,274622.0842,1.76477192,464.4942956
,100.4,96.43985611,3.319777271,276947.3428,1.757791291,466.394189
,100.6,97.19977604,3.353027217,280398.7008,1.746447817,468.8966998
,100.8,97.96047498,3.386611212,282668.0253,1.739903476,470.7954983
,101,98.59380151,3.420541085,284671.4891,1.736413139,473.0942137
,101.2,99.27783489,3.454808472,287330.7717,1.728559952,475.1540744
,101.4,100.2547298,3.489400925,289702.1479,1.722451877,477.215035
,101.6,100.837131,3.524366848,292533.2839,1.716780123,479.9509203
,101.8,101.7049034,3.559665204,295094.9162,1.711108344,482.1269244
,102,102.6258768,3.595314721,297586.506,1.707617983,484.7302388
,102.2,103.7931092,3.631306169,297929.8558,1.714598431,487.0103362
,102.4,104.3353405,3.667700582,298516.7776,1.719397512,489.1490835
,102.6,104.974043,3.704454018,299267.6008,1.722015161,491.0259686
,102.8,106.1394367,3.741541549,299755.0425,1.726814184,493.2468991
,103,106.798825,3.77903472,300797.1098,1.727250408,495.1369321
,103.2,107.6037793,3.816894981,302616.965,1.725068912,497.5517911
,103.4,108.5334954,3.855127364,303988.7274,1.724632542,499.652196
,103.6,109.3349997,3.893751895,304836.0577,1.728122744,502.0703426
,103.8,110.2030141,3.932760064,304381.8025,1.736412069,503.7313851
,104,111.536969,3.972129341,304326.6064,1.744265065,505.828509
,104.2,112.1177671,4.011943806,304259.9505,1.750372992,507.4457211
,104.4,112.8308131,4.052149412,304288.5075,1.756044623,509.1889371
,104.6,113.7926071,4.09274266,305429.285,1.757353387,511.4843703
,104.8,114.4763988,4.13376209,307312.5743,1.753426762,513.3963193
,105,115.6436029,4.175161728,309189.247,1.751245232,515.7388708
,105.2,116.8290481,4.216976156,311935.2782,1.745137141,518.2490597
,105.4,117.2213895,4.259262888,313303.1486,1.744700822,520.2387955
,105.6,118.152063,4.301939046,314775.5774,1.743828168,522.27894
,105.8,119.5220424,4.345014951,317557.4412,1.737720062,524.9019857
,106,120.2462062,4.388566413,320255.2325,1.730739446,527.1130513
,106.2,120.9611469,4.432555792,322076.5119,1.729430528,529.7393745
,106.4,122.2635135,4.476948346,325305.9535,1.720704727,532.183826
,106.6,123.2221321,4.521809733,328963.0351,1.711106388,534.9109545
,106.8,123.8890113,4.567141529,332518.7456,1.703253212,537.9777353
,107,124.850814,4.612911217,334912.1802,1.698890282,540.3323374
,107.2,125.7305772,4.65914556,339864.4633,1.685801678,543.7179607
,107.4,127.2431149,4.705800937,341798.3657,1.684492695,546.3004703
,107.6,128.1947106,4.75296213,343213.2835,1.687546598,549.4373769
,107.8,129.2019848,4.800593486,343402.5522,1.693654483,551.6495442
,108,130.2091829,4.848703317,343112.7014,1.70325264,554.2309511
,108.2,131.2870367,4.897291925,342024.0267,1.714595925,556.1900193
,108.4,132.275773,4.946374486,341783.2667,1.723757797,558.7056873
,108.6,133.4142174,4.995940335,342248.0971,1.728556816,560.9320992
,108.8,134.4885072,5.046008495,342659.0655,1.734228408,563.388602
,109,135.5452419,5.096580729,343458.5957,1.736846013,565.4188895
,109.2,136.5186811,5.147666631,345007.2646,1.737718491,568.0386449
,109.4,137.6027142,5.199258458,346612.0189,1.737282107,570.2847798
,109.6,138.7232793,5.251366172,348797.9354,1.735536868,573.1784544
,109.8,139.996044,5.303987318,350801.7546,1.732482764,575.468419
,110,141.4950685,5.357122356,352451.0438,1.732046343,578.2514372
,110.2,142.3316192,5.410834916,353033.46,1.734663968,580.3496544
,110.4,143.4959499,5.465065535,353192.0107,1.739026697,582.5399124
,110.6,144.8923628,5.519825697,353359.6191,1.745134539,585.1662497
,110.8,145.8917542,5.575162241,353726.0223,1.749497282,587.127511
,111,147.0891081,5.631041577,355192.9259,1.751242305,589.692489
,111.2,148.4761021,5.687470004,357249.0086,1.750369608,592.3484083
,111.4,149.5251544,5.744487543,358709.1154,1.751242078,594.5835879
,111.6,150.582437,5.802077334,360851.9605,1.749060561,596.9173776
,111.8,151.5921953,5.860248925,363587.3004,1.745133916,599.7135382
,112,153.2667455,5.918961084,367071.9891,1.738153226,602.6817293
,112.2,154.6341398,5.978283456,369784.7098,1.732917698,605.0703069
,112.4,155.7725991,6.038217065,374166.2142,1.721574225,607.9530278
,112.6,156.6879475,6.098767384,379076.001,1.710230774,611.6399661
,112.8,158.6916461,6.159854225,382003.185,1.704995192,614.3912217
,113,159.9188548,6.221606093,383377.2561,1.707176497,617.5390961
,113.2,161.4588517,6.283957675,386055.3728,1.704558657,620.8677619
,113.4,162.7923767,6.346949326,387058.3507,1.707612519,623.7055654
,113.6,164.1507653,6.410572432,387719.2486,1.711102661,626.1664585
,113.8,165.8310926,6.47481342,389557.0393,1.711975074,629.3702219
,114,166.6849966,6.539754294,391636.1101,1.710666147,632.0765374
,114.2,168.1870382,6.605304869,392694.3212,1.714592558,635.1630593
,114.4,169.4742815,6.671528299,392326.1203,1.722881818,637.503431
,114.6,170.699008,6.738421229,393124.7152,1.727244536,639.9982889
,114.8,171.6573411,6.806003737,393993.1925,1.732479844,642.8985399
,115,173.6008263,6.874200277,395691.8457,1.734224797,645.8327736
,115.2,174.7128893,6.943136819,397207.9505,1.73509726,648.2279248
,115.4,176.3199685,7.012733252,400067.0411,1.731606848,651.0230047
,115.6,177.6248677,7.083048978,401862.6941,1.733351859,654.3177028
,115.8,179.0719514,7.154061776,403262.2214,1.734224291,656.8520094
,116,180.7935293,7.225769934,404165.2122,1.738150677,659.8004868
,116.2,182.3186064,7.29821151,405467.3555,1.739023101,662.2098898
,116.4,183.9450894,7.371374128,407017.8039,1.739022951,664.9304636
,116.6,185.5040516,7.445276506,411059.9536,1.732042283,668.5374333
,116.8,186.8140243,7.520315824,412803.8754,1.732042162,671.0991318
,117,188.4169119,7.595335949,415361.7924,1.730733166,674.303993
,117.2,190.2692625,7.671472696,417741.5415,1.728551582,676.9763643
,117.4,191.5647867,7.748411053,421348.0094,1.72287979,680.0574104
,117.6,193.1464456,7.826103658,424574.7562,1.719389384,683.7136875
,117.8,194.6081515,7.904584805,427541.9515,1.716335273,687.3086058
,118,196.514097,7.983825242,429249.2237,1.715898816,690.1004061
,118.2,197.6909574,8.063909904,429746.3738,1.721134097,693.3447046
,118.4,199.4144085,8.144763037,427476.7161,1.735094975,695.6489302
,118.6,200.9588194,8.226440531,424837.8502,1.750800996,697.764699
,118.8,202.6037892,8.308931828,424285.1381,1.760399052,700.3395531
,119,204.1454412,8.392258825,424524.569,1.765634295,702.4859997
,119.2,205.9623996,8.476404875,424881.2471,1.771305792,705.1528951
,119.4,207.5154338,8.561413804,426371.5219,1.771305646,707.559015
,119.6,209.1532109,8.647271221,431327.3602,1.760398437,711.1550333
,119.8,210.8166471,8.733989454,435012.6626,1.752108921,713.8569885
,120,212.7545521,8.821560989,440332.6465,1.740329124,717.6075038
,120.2,214.482617,8.910025262,447307.9006,1.724622811,721.7031518
,120.4,215.8901653,8.999398931,454281.8125,1.709789094,725.5676061
,120.6,217.7577461,9.089639886,458958.0649,1.702372131,729.0431078
,120.8,219.8956292,9.180769497,461013.1676,1.704553346,732.7366553
,121,221.5482271,9.272846089,461062.4003,1.712842551,736.1003953
,121.2,223.1440922,9.365850696,461109.5608,1.71895035,738.7782451
,121.4,224.6416159,9.459795781,460442.3391,1.727239566,741.5273119
,121.6,226.6149752,9.554653262,460096.0161,1.736401301,744.9370786
,121.8,228.4034471,9.650475854,461337.6887,1.738582543,747.6324631
,122,230.5129729,9.747240043,465047.1572,1.734655812,751.4059956
,122.2,232.2537047,9.845000697,466534.2783,1.736400776,754.2262881
,122.4,234.0150838,9.943742171,467519.6382,1.739890862,757.0148055
,122.6,235.9602085,10.04346358,470056.5295,1.739890681,760.798196
,122.8,238.0865808,10.14417496,471856.9869,1.739890482,763.7116308
,123,240.1104386,10.24590492,471767.7517,1.74643452,766.8431002
,123.2,242.3654692,10.34864187,472882.8422,1.748179438,769.5801337
,123.4,244.1709787,10.4524405,473228.3923,1.752542077,772.3270188
,123.6,245.9863079,10.55728131,472846.5748,1.760394969,775.3686397
,123.8,247.7532053,10.66317859,470930.4826,1.773483241,777.9007732
,124,249.7362903,10.77012566,472614.6325,1.774355616,780.4252419
,124.2,251.6542972,10.87815151,476197.1115,1.769992623,783.8711685
,124.4,253.5805938,10.90523267,482122.5214,1.75734029,787.2425897
,124.6,254.5987717,10.90516597,490103.5836,1.739452672,791.1727828
,124.8,255.8120867,10.90508646,502582.9337,1.710221732,796.5076303
,125,256.6172362,10.90503374,510296.8742,1.694515542,800.7336502
,125.2,257.6229317,10.90496786,517267.4255,1.683608421,805.6817218
,125.4,258.286617,10.90492443,519758.7639,1.684044648,809.5472606
,125.6,259.0568165,10.90487401,520978.8524,1.687971108,813.207916
,125.8,259.8145337,10.90482441,519719.1377,1.699750627,816.9737534
,126,260.2327373,10.90479709,518245.3506,1.711530175,820.576328
,126.2,260.6625908,10.90476901,515554.6923,1.725054845,823.2563481
,126.4,261.1531906,10.90473695,513514.0151,1.736834386,825.9571878
,126.6,261.6030154,10.90470756,511978.7714,1.748613929,829.3767868
,126.8,262.3307755,10.90465992,510596.0946,1.758212042,831.8059069
,127,262.4768688,10.90465047,511260.595,1.76388368,835.0721039
,127.2,262.9891042,10.90461698,513925.5501,1.76257479,838.027141
,127.4,263.30329,10.9045965,515800.4958,1.763883603,840.9372513
,127.6,263.5434152,10.90458088,515948.4555,1.771300356,844.2418004
,127.8,263.7702261,10.90456613,515571.229,1.77915339,847.1792992
,128,264.0444691,10.90454826,513383.5331,1.790496667,849.1909564
,128.2,264.2088695,10.90453761,510576.814,1.804457639,851.6047237
,128.4,264.8875331,10.9044932,509220.7919,1.81274691,853.6711755
,128.6,264.913798,10.90449161,509677.7184,1.815364593,855.881144
,128.8,265.1780553,10.9044744,511323.1393,1.815364568,858.7255123
,129,265.3216521,10.90446512,511954.246,1.817545958,860.8675523
,129.2,265.2622064,10.90446916,511712.2607,1.823653896,863.3130882
,129.4,265.9533521,10.90442393,510231.2822,1.832815727,865.1231526
,129.6,265.6242927,10.90444567,506869.435,1.848521869,866.865262
,129.8,266.0408318,10.90441847,504741.628,1.858992568,868.108858
,130,266.275132,10.90440322,504287.528,1.865100476,869.9123394
,130.2,266.1432901,10.90441202,505154.1627,1.865973051,871.5733728
,130.4,266.446658,10.90439224,507444.9014,1.862482775,873.525865
,130.6,266.5944155,10.90438268,510312.432,1.858119952,876.0075646
,130.8,266.9327333,10.90436061,511182.3422,1.859428761,878.1024945
,131,267.2136334,10.90434231,510716.2102,1.863791542,879.5882327
,131.2,267.3206159,10.90433543,509292.7117,1.871644586,881.1495657
,131.4,267.3202523,10.9043356,508239.2254,1.877752517,882.4643712
,131.6,267.428067,10.90432866,507450.3235,1.883424157,884.1210278
,131.8,267.8953667,10.90429812,508907.5637,1.881678987,885.7196238
,132,268.0406277,10.90428872,511730.1361,1.876879884,887.8835777
,132.2,267.6749542,10.90431287,513766.2613,1.873825955,889.5632316
,132.4,267.8526687,10.90430134,514629.1317,1.8746985,891.192499
,132.6,268.2201115,10.90427736,513140.1175,1.883424079,892.7111099
,132.8,268.3545547,10.90426868,511258.5191,1.892585961,893.9941433
,133,268.4673622,10.90426141,509840.8096,1.899130162,894.9068385
,133.2,268.6775303,10.90424775,510314.1123,1.900002702,896.4769421
,133.4,268.5714847,10.90425485,511335.199,1.898693871,897.9111729
,133.6,268.6376924,10.90425065,514144.8279,1.892149653,899.6313776
,133.8,269.2090097,10.90421328,516362.9539,1.88865935,901.6090778
,134,268.7767648,10.9042418,516462.3655,1.891277078,902.8986708
,134.2,269.146704,10.90421765,514507.5581,1.900875218,904.0239363
,134.9,269.3783893,10.844261,1.7977E+308,1.906983126,0
,135.1,269.3645604,10.73527672,1.7977E+308,1.884296531,0
,135.3,268.9171861,10.6263209,1.7977E+308,1.797912988,0
,135.5,268.713629,10.51734907,1.7977E+308,1.643905902,0
,135.7,268.7613786,10.40836074,1.7977E+308,1.424892958,0
,135.9,268.4862574,10.29939361,1.7977E+308,1.09986381,0
,136.1,268.4682678,10.1904096,1.7977E+308,0.719863265,0
,136.3,268.1032754,10.08144837,1.7977E+308,0.426682598,0
,136.5,267.6242796,9.972494627,1.7977E+308,0.204179408,0
,136.7,267.3816119,9.863525367,1.7977E+308,0.059770469,0
,136.9,266.9825017,9.754566377,1.7977E+308,0.024431725,0
,137.1,267.0627047,9.645575921,1.7977E+308,0.023995444,0
,137.3,266.896594,9.536601634,1.7977E+308,0.022250321,0
,137.5,266.8494795,9.427619536,1.7977E+308,0.019196356,0
,137.7,266.2598089,9.318673056,1.7977E+308,0.020941479,0
,137.9,266.0654054,9.209700627,1.7977E+308,0.030975939,0
,138.1,266.0973442,9.10071334,1.7977E+308,0.043628083,0
,138.3,265.7756231,8.991749269,1.7977E+308,0.058025351,0
,138.5,265.3523807,8.882791863,1.7977E+308,0.063260722,0
,138.7,265.19792,8.773816812,1.7977E+308,0.066314689,0
,138.9,264.8329275,8.664855582,1.7977E+308,0.063697005,0
,139.1,264.7200738,8.555877799,1.7977E+308,0.055407669,0
,139.3,264.2735314,8.446921923,1.7977E+308,0.042755525,0
,139.5,264.4827164,8.337923,1.7977E+308,0.032721065,0
,139.7,264.501341,8.228936586,1.7977E+308,0.020505201,0
,139.9,263.8842097,8.119991908,1.7977E+308,0.017451235,0
,140.1,263.7081132,8.011018278,1.7977E+308,0.021377763,0
,140.3,263.5736238,7.902041916,1.7977E+308,0.025304292,0
,140.5,263.1270815,7.793086039,1.7977E+308,0.028358258,0
,140.7,263.3470843,7.684086406,1.7977E+308,0.030539663,0
,140.9,262.8556063,7.575133479,1.7977E+308,0.032284787,0
,141.1,262.5638421,7.466167442,1.7977E+308,0.033157349,0
,141.3,262.3078601,7.357199055,1.7977E+308,0.033593631,0
,141.5,262.1176172,7.248226353,1.7977E+308,0.034902474,0
,141.7,261.8092103,7.139261409,1.7977E+308,0.029667103,0
,141.9,261.493314,7.030296956,1.7977E+308,0.02312289,0
,142.1,261.4000156,6.921317889,1.7977E+308,0.013524709,0
,142.3,261.4315385,6.812330629,1.7977E+308,0.006107933,0
,142.5,261.237967,6.703358146,1.7977E+308,0.008725619,0
,142.7,260.7814389,6.594402925,1.7977E+308,0.012215867,0
,142.9,260.6927172,6.485423558,1.7977E+308,0.016578677,0
,143.1,260.5465778,6.376447961,1.7977E+308,0.016578677,0
,143.3,260.1890745,6.267486239,1.7977E+308,0.005671653,0
,143.5,259.7874677,6.158527413,1.7977E+308,0.003490248,0
,143.7,259.4873821,6.049561922,1.7977E+308,0.00872562,0
,143.9,259.248875,5.940592388,1.7977E+308,0.016142397,0
,144.1,259.1260355,5.831615261,1.7977E+308,0.01745124,0
,144.3,258.7518893,5.722654632,1.7977E+308,0.024431737,0
,144.5,258.7771711,5.613667782,1.7977E+308,0.033157357,0
,144.7,258.2956786,5.5047142,1.7977E+308,0.04275554,0
,144.9,258.1911463,5.395735871,1.7977E+308,0.053226285,0
,145.1,257.975107,5.286764863,1.7977E+308,0.060206782,0
,145.3,257.3579754,5.177820185,1.7977E+308,0.058897941,0
,145.5,257.4440035,5.068829346,1.7977E+308,0.060643065,0
,145.7,257.162225,4.959862654,1.7977E+308,0.058897942,0
,145.9,256.7156824,4.850906777,1.7977E+308,0.056280257,0
,146.1,256.6419393,4.741926427,1.7977E+308,0.050172322,0
,146.3,256.4358857,4.632954763,1.7977E+308,0.041446701,0
,146.5,255.9568896,4.524001017,1.7977E+308,0.025740584,0
,146.7,255.8690001,4.415021596,1.7977E+308,0.006980497,0
,146.9,255.8876247,4.306035182,1.7977E+308,0.01221587,0
,147.1,255.1639789,4.197097497,1.7977E+308,0.023122898,0
,147.3,255.2092321,4.088109335,1.7977E+308,0.034029926,0
,147.5,254.8625465,3.979146904,1.7977E+308,0.037956456,0
,147.7,254.4675966,3.87018764,1.7977E+308,0.034902489,0
,147.9,254.4778998,3.761201773,1.7977E+308,0.03141224,0
,148.1,253.9231788,3.652252998,1.7977E+308,0.02704943,0
,148.3,253.8236393,3.543274342,1.7977E+308,0.022686619,0
,148.5,253.6159213,3.434302787,1.7977E+308,0.020941495,0
,148.7,253.3025213,3.32533817,1.7977E+308,0.01919637,0
,148.9,252.928375,3.216377541,1.7977E+308,0.016142403,0
,149.1,252.5367537,3.107418059,1.7977E+308,0.01483356,0
,149.3,252.6419211,2.998425964,1.7977E+308,0.013524716,0
,149.5,252.2286641,2.889467902,1.7977E+308,0.018323809,0
,149.7,251.8145749,2.780509895,1.7977E+308,0.020505216,0
,149.9,251.3181037,2.671557297,1.7977E+308,0.031848527,0
,150.1,251.1661392,2.562582082,1.7977E+308,0.04362812,0
,150.3,250.9367855,2.453611947,1.7977E+308,0.041446714,0
,150.5,250.6991104,2.344642359,1.7977E+308,0.040137871,0
,150.7,250.2226106,2.235688449,1.7977E+308,0.034902498,0
,150.9,249.7486072,2.126734376,1.7977E+308,0.027049436,0
,151.1,249.7847068,2.017746815,1.7977E+308,0.026613155,0
,151.3,249.3456533,1.908790447,1.7977E+308,0.037520187,0
,151.5,248.9407176,1.799831839,1.7977E+308,0.041883,0
,151.7,248.477532,1.690877055,1.7977E+308,0.045373251,0
,151.9,248.2223819,1.581908614,1.7977E+308,0.053662596,0
,152.1,248.009671,1.472937387,1.7977E+308,0.056716566,0
,152.3,247.4691828,1.363442751,1.7977E+308,0.051917473,0
,152.5,247.2946638,1.255013944,1.7977E+308,0.047554661,0
,152.7,246.8106746,1.146060526,1.7977E+308,0.038392755,0
,152.8,246.7112191,1.092664312,1.7977E+308,0.032284817,0
,228.1,245.3625358,0.934231908,1.7977E+308,0.01614241,0
,228.3,245.1281892,0.825262102,1.7977E+308,0.01265216,0
,228.5,244.913814,0.716290984,1.7977E+308,0.013961004,0
,228.7,244.5463246,0.607329918,1.7977E+308,0.012215879,0
,228.9,243.8343283,0.498391468,1.7977E+308,0.009598191,0
,229.1,243.3669818,0.389436957,1.7977E+308,0.00610794,0
,229.3,242.605889,0.28050173,1.7977E+308,0.002617689,0
,229.5,241.6671338,0.171578166,1.7977E+308,0.014397288,0
,229.7,240.5436429,0.06266673,1.7977E+308,0.023122918,0
,229.806,239.8549554,0.004949789,1.7977E+308,0.026613171,0
END,,,,,,