File: GB1_test 40.csv
Segment,Time On Sample,Displacement Into Surface,Load On Sample,Harmonic Contact Stiffness,Harmonic Displacement,Harmonic Load
Surface Marker,0,0,0,247.4330657,0.341980852,2.263872246
,0.2,-0.114188284,0.000663567,4886.978664,0.206758833,2.338384974
,0.4,-0.103994484,0.001318991,14462.91947,0.144382223,2.409610386
,0.6,0.139155729,0.001959162,19534.15492,0.124317018,2.469878054
,0.8,0.418081387,0.002596992,24206.41346,0.112103415,2.652872588
,1,0.26728567,0.003262955,26565.61183,0.109922415,2.82600511
,1.2,0.061578875,0.003932024,27322.61774,0.113412017,2.992562977
,1.4,0.419543463,0.004563754,26676.21777,0.122572216,3.155833561
,1.6,0.356522539,0.005223046,26323.79538,0.129987618,3.3015717
,1.8,0.288925686,0.005882638,28939.30162,0.134349619,3.773850948
,2,0.306607518,0.006536647,30245.1989,0.14307362,4.205586516
,2.2,0.488190823,0.007179924,30813.1593,0.15441482,4.634034771
,2.4,0.423089932,0.007839353,31531.2914,0.164447422,5.060291449
,2.6,0.456995514,0.0084923,30974.80771,0.181023024,5.5062721
,2.8,0.439733885,0.009148596,31317.08116,0.202396827,6.231675503
,3,0.224459307,0.009817857,32395.52123,0.215482831,6.906673193
,3.2,0.562456201,0.010450894,33601.17672,0.227696429,7.594820299
,3.4,0.905029018,0.011083631,34912.8171,0.239910026,8.278584316
,3.6,0.60530775,0.011758421,36116.36208,0.249506431,8.849483305
,3.8,0.340529937,0.012430923,38358.05126,0.261720037,9.806095283
,4,0.52419321,0.013074064,39135.38594,0.280040437,10.67504533
,4.2,0.613841932,0.013723361,39796.56454,0.298360838,11.55495312
,4.4,0.489253959,0.014386685,39619.38367,0.321479443,12.39322137
,4.6,0.55560704,0.015037507,39439.48154,0.335874043,12.88851193
,4.8,0.747174189,0.015680131,38730.20885,0.376440645,14.18481448
,5,0.613018364,0.016344081,37488.22342,0.416134852,15.17977861
,5.2,0.797097628,0.016987195,35766.85319,0.463244454,16.12543299
,5.4,0.761948276,0.017644663,34585.23678,0.50599206,17.05136329
,5.6,0.59409697,0.018310819,33805.06874,0.54088807,17.82717229
,5.8,0.251528355,0.018988414,33432.71424,0.581018487,18.9426716
,6,0.524630251,0.019625699,33208.60917,0.615478282,19.93325283
,6.2,-0.025103177,0.020316858,32704.40671,0.653427708,20.85918285
,6.4,0.273790326,0.020952455,31583.81282,0.705335505,21.73799497
,6.6,-0.561314726,0.021662296,29954.07895,0.766403551,22.40203442
,6.8,-1.320708978,0.022367181,26993.9438,0.876326011,23.14716129
,7,-1.314674966,0.023021952,23983.26158,0.99671724,23.53397005
,7.2,0.356165475,0.023567725,20271.84607,1.179921172,23.75203045
,7.4,0.383831154,0.02422108,17256.04281,1.375774999,23.78161644
,7.6,0.613669716,0.024861198,15414.74903,1.527136401,23.72901935
,7.8,0.650487253,0.025513954,14307.31146,1.640548414,23.72573206
,8,0.64903338,0.026169215,14414.34864,1.649708616,23.9415998
,8.2,0.734106172,0.026818812,15779.66427,1.557670397,24.53879751
,8.4,0.789227427,0.027470369,17554.27307,1.448620379,25.19845444
,8.6,0.656319582,0.028134238,19959.32924,1.325611974,26.00275356
,8.8,0.602450517,0.028792931,22936.43159,1.204348363,26.94292897
,9,0.647587926,0.029445142,24548.90917,1.153749153,27.59381967
,9.2,0.4289854,0.030114621,25399.24291,1.140663166,28.2710088
,9.4,0.651336077,0.030755229,25460.62872,1.158983555,28.87587702
,9.6,0.634906435,0.031411471,25062.56917,1.193007161,29.34486892
,9.8,0.967911403,0.032044835,24514.54454,1.232701343,29.77441322
,10,0.648638433,0.032720905,23950.51031,1.277193772,30.24340485
,10.2,0.613905073,0.033378345,23526.27948,1.31208978,30.59295721
,10.4,0.686498059,0.034028759,23144.28496,1.35047538,31.02907597
,10.6,0.613493289,0.034688705,22996.01128,1.372721589,31.40383115
,10.8,0.981441718,0.035319781,22917.94629,1.392350563,31.77420363
,11,0.807766502,0.035986319,22735.32393,1.420703581,32.15882069
,11.2,0.855399872,0.036638366,22613.77678,1.443822181,32.46454207
,11.4,1.162613235,0.037273419,22532.27302,1.466940758,32.83381872
,11.6,1.213574553,0.037925249,22544.82887,1.483516357,33.14830636
,11.8,1.089818569,0.038588518,22702.24895,1.491367968,33.47484728
,12,0.983534314,0.039250643,23344.59941,1.474792376,33.93507291
,12.2,0.992896274,0.039905197,24130.36091,1.447311773,34.34818032
,12.4,1.202767139,0.040546623,25287.84037,1.408489952,34.91688799
,12.6,1.177185639,0.041203465,26305.9601,1.375774951,35.40889125
,12.8,1.215667149,0.041856112,27540.34808,1.340006544,36.02800443
,13,1.156806163,0.042515132,28343.51369,1.321249947,36.50357096
,13.2,1.385812731,0.043155305,28968.70939,1.31339833,37.05474627
,13.4,1.506660968,0.04380256,29473.16032,1.310781121,37.60811305
,13.6,1.268922746,0.044473292,29704.25569,1.31557934,38.02998643
,13.8,1.535368734,0.045111014,29923.62834,1.324303321,38.56801245
,14,1.277662821,0.045783053,29982.77739,1.335208342,38.97892802
,14.2,1.123123312,0.046448337,30062.09419,1.347421956,39.46435642
,14.4,1.560958653,0.047074838,30082.75237,1.361816524,39.95636011
,14.6,1.251669537,0.047750255,30114.06745,1.37272155,40.35412634
,14.8,1.313446167,0.04840465,30068.10968,1.387552347,40.76065902
,15,1.545781202,0.049041332,30024.60006,1.403691731,41.21102306
,15.2,1.644997773,0.049690003,30102.15687,1.415469124,41.66248268
,15.4,1.57698493,0.050349622,30302.23721,1.419831131,42.04929142
,15.6,1.530603752,0.051007826,30603.05568,1.423756936,42.54786918
,15.8,1.73797865,0.051649415,30994.93948,1.421139719,42.99056282
,16,1.752332533,0.052303642,31415.94556,1.419831118,43.50119417
,16.2,1.554529696,0.052971759,31762.29862,1.420267335,43.99429301
,16.4,1.410806022,0.053636336,32007.11703,1.424629348,44.47424252
,16.6,1.877344914,0.054260958,32066.92562,1.433789511,44.86433915
,16.8,1.737365184,0.054925289,32122.18795,1.443822124,45.26977594
,17,1.732999357,0.055580742,32319.67741,1.449928925,45.76287497
,17.2,1.787704615,0.056232327,32483.10687,1.456908122,46.23734583
,17.4,1.81745026,0.056885546,32594.57959,1.46257872,46.60662221
,17.6,2.109271848,0.057521607,32917.85699,1.460397697,47.03178348
,17.8,1.755055435,0.058199965,33315.48301,1.457780526,47.58295813
,18,1.959102383,0.058841773,33576.84409,1.45821671,48.03606164
,18.2,2.225132369,0.059479522,33861.94824,1.457780488,48.50341024
,18.4,2.27442971,0.060131462,34142.35246,1.459089085,48.99541348
,18.6,2.400685859,0.060778363,34215.00119,1.467376875,49.40194641
,18.8,2.680443625,0.061415214,34228.15708,1.481335253,49.90162046
,19,2.783404133,0.06206364,34324.73706,1.487878245,50.26322657
,19.2,2.373444596,0.062745648,34659.77846,1.488750681,50.75632501
,19.4,2.60702708,0.063385522,35063.68914,1.486569661,51.25052005
,19.6,2.754082903,0.064031061,35630.53616,1.476100847,51.70745869
,19.8,2.864115301,0.064679024,36593.0228,1.45647184,52.35177493
,20,2.592265624,0.06535199,37295.42595,1.44382206,52.84816087
,20.2,2.429822248,0.066017793,38029.68287,1.432917073,53.45302875
,20.4,2.547758525,0.066665238,38773.46081,1.420921566,54.01242227
,20.6,2.487649562,0.067324341,39365.5413,1.415469069,54.58386922
,20.8,2.495763541,0.067978977,39842.41398,1.412851872,55.13942744
,21,2.419430779,0.068639457,40061.43761,1.418958675,55.70594329
,21.2,2.857681269,0.069271082,39766.97716,1.442077242,56.22205427
,21.4,2.690660092,0.069948972,39156.23549,1.473701758,56.61872476
,21.6,3.045293768,0.070599321,38316.40367,1.513177828,56.97594815
,21.8,3.330455465,0.071260837,37492.73668,1.552435806,57.27071223
,22,3.212102353,0.071955562,36906.6991,1.585150817,57.61916868
,22.2,3.176530857,0.072651773,37046.07347,1.58994902,58.05419152
,22.4,3.155102039,0.073353996,37623.72712,1.575990622,58.47058621
,22.6,3.187751262,0.074059711,38699.46163,1.54589282,58.99436697
,22.8,3.119728928,0.07477907,40487.10715,1.497474628,59.76360128
,23,3.353716769,0.075485781,42102.48562,1.458652807,60.50982491
,23.2,3.273212337,0.076220378,43134.19258,1.439241913,61.13989568
,23.4,3.030469244,0.076973032,43713.12281,1.435098036,61.7359972
,23.6,3.299813018,0.077699562,43722.96564,1.446875414,62.22033046
,23.8,3.212649152,0.078456849,43408.37007,1.472175022,62.78684628
,24,3.056845144,0.079226224,43249.82928,1.491804037,63.33254222
,24.2,3.158539913,0.079986444,43118.31062,1.507507229,63.75003286
,24.4,3.246089694,0.08075518,43070.77567,1.522338022,64.24970667
,24.6,2.9500922,0.081556778,43324.52629,1.525391448,64.72198551
,24.8,3.534335776,0.082308644,43946.08996,1.519284598,65.37835614
,25,3.353150005,0.083118439,44287.2777,1.518848414,65.8506351
,25.2,3.316728711,0.083926757,44826.08767,1.514486418,66.46536516
,25.4,3.216243118,0.084747408,45386.28533,1.509252027,67.0910528
,25.6,3.413607596,0.085556744,45741.46253,1.508379611,67.60168456
,25.8,3.272352026,0.086396488,45988.23332,1.511869224,68.12765662
,26,3.197654089,0.08724026,46103.87806,1.520593231,68.70841749
,26.2,3.295176135,0.088081196,46078.86394,1.533679223,69.24206038
,26.4,3.226299411,0.088941546,46164.79982,1.54414803,69.78556487
,26.6,3.57507884,0.089783088,46080.36712,1.5576702,70.20743912
,26.8,3.659285011,0.090650562,46077.71533,1.568575193,70.65561151
,27,3.279240999,0.091557246,46374.56171,1.570756228,71.19144515
,27.2,3.538993631,0.092430912,46879.24566,1.566394205,71.78426024
,27.4,3.460126104,0.0933357,47317.57266,1.563340813,72.36392527
,27.6,3.426184436,0.094246616,47709.52032,1.560287416,72.87893973
,27.8,3.666797061,0.095148609,47895.23343,1.565957995,73.47942524
,28,3.471447017,0.096088252,48054.86145,1.570320014,73.94074641
,28.2,3.670457358,0.097011408,48100.49034,1.580352596,74.46233595
,28.4,3.740508213,0.097952382,48053.30621,1.59300239,74.95543508
,28.6,3.65580797,0.098912954,48204.45533,1.597800599,75.39593669
,28.8,3.627681325,0.099879404,48527.24212,1.597800602,75.88574835
,29,3.964795442,0.100831714,48761.16851,1.601726372,76.44569046
,29.2,4.028184278,0.101811634,48819.06618,1.610014166,76.96180082
,29.4,3.846135373,0.102817456,48880.65179,1.616120984,77.36395011
,29.6,4.386249673,0.103785729,48696.61065,1.630079334,77.75514324
,29.8,4.378082915,0.104799957,48405.11032,1.648835935,78.21975203
,30,4.539639903,0.105813178,48323.60993,1.660177119,78.67230759
,30.2,4.303505452,0.106862766,48475.90807,1.662794342,79.0470624
,30.4,4.511650432,0.107893587,48966.52316,1.656687524,79.56865199
,30.6,4.424438361,0.108954169,49865.11588,1.637494733,80.09462417
,30.8,4.660867563,0.110004121,51190.6998,1.610450313,80.82879428
,31,4.669330622,0.111079688,52303.74001,1.588640314,81.42489637
,31.2,4.735199062,0.112162341,53866.42892,1.557233911,82.20618442
,31.4,4.756970477,0.113258654,55302.89853,1.531498111,83.00062193
,31.6,4.732980849,0.11436902,56180.10135,1.519720714,83.68438571
,31.8,4.875386851,0.11547964,56926.4559,1.511432903,84.35171353
,32,4.800642474,0.116615607,57573.74439,1.50794331,85.14176746
,32.2,5.00211598,0.117744837,57628.85654,1.518412093,85.79923343
,32.4,5.195266872,0.118891856,57497.35495,1.533242875,86.44793298
,32.6,5.517374838,0.12003614,57572.16535,1.541094447,87.00020471
,32.8,5.326145926,0.121219742,57593.3815,1.550690863,87.57439068
,33,5.164033717,0.122419308,57637.97465,1.561595878,88.24390915
,33.2,5.592630386,0.12359204,57946.66725,1.56508544,88.92548278
,33.4,5.348979676,0.12482072,58171.56113,1.568138862,89.45912487
,33.6,5.434793851,0.126040154,58325.18148,1.573809454,90.02235366
,33.8,5.649564079,0.127263269,58601.63508,1.579043835,90.74775773
,34,5.652175647,0.128512739,58830.1063,1.583842035,91.40193572
,34.2,5.713024319,0.129770881,58936.34755,1.589948829,91.92681246
,34.4,5.651152894,0.131049754,59114.56183,1.596928035,92.5798945
,34.6,6.066839978,0.132309999,59304.32586,1.601289997,93.1135384
,34.8,5.492044527,0.133647995,59677.52295,1.60347105,93.8312699
,35,6.062893049,0.134924091,60005.76688,1.603907198,94.36820142
,35.2,5.805080464,0.136267577,60712.50595,1.597800423,95.09141264
,35.4,6.059769728,0.137590843,61775.2389,1.583405802,95.88256337
,35.6,6.174267062,0.13893666,62913.45298,1.566393995,96.59810522
,35.8,5.875264708,0.140323205,64222.05431,1.549818424,97.52513059
,36,6.377047643,0.141670878,65100.85565,1.540658181,98.24067351
,36.2,6.330132984,0.143068313,65900.09232,1.535423787,99.09647417
,36.4,6.353519009,0.144475059,65863.37523,1.547637384,99.81859028
,36.6,6.798720165,0.14586831,65372.82101,1.567702542,100.3533302
,36.8,6.40652422,0.147330561,64714.42622,1.591693574,100.8683436
,37,6.496046393,0.148775843,63913.04286,1.620046562,101.4129444
,37.2,6.501535582,0.15024112,63145.06825,1.647527158,101.9115222
,37.4,6.324401283,0.151733159,62727.77398,1.666283773,102.4243449
,37.6,6.465915617,0.153219222,62706.17075,1.673699156,102.8714217
,37.8,6.617411434,0.154719475,62931.27453,1.675443943,103.3776704
,38,6.361231229,0.156261655,63496.88162,1.670209568,104.0471887
,38.2,6.919563798,0.157765829,64155.02488,1.662794116,104.7309543
,38.4,6.564788273,0.159345117,64784.30295,1.654942552,105.2963735
,38.6,6.861456011,0.160897494,65603.25477,1.645346126,106.0919075
,38.8,6.639377402,0.162499544,66251.36257,1.63793075,106.7088285
,39,6.911496495,0.164085176,66798.78286,1.635313526,107.4331371
,39.2,6.966880451,0.165700992,67253.73137,1.63465922,108.0807407
,39.4,6.83589674,0.167345334,67466.84765,1.639239331,108.6724591
,39.6,7.015657532,0.168985772,67846.80855,1.641420316,109.325542
,39.8,6.899644358,0.170662033,68026.51224,1.647963328,109.9402718
,40,6.746189076,0.172357692,68298.62441,1.653197743,110.6328015
,40.2,7.027028306,0.174041681,68683.02448,1.653197713,111.2102761
,40.4,7.103196036,0.17575615,69286.04421,1.64839951,111.8282939
,40.6,7.054978976,0.177496038,69750.21198,1.649271917,112.6106775
,40.8,7.353281706,0.179230591,70056.6713,1.651016688,113.1969184
,41,7.342914508,0.181002878,70055.68346,1.659304489,113.7294653
,41.2,7.097924147,0.182808474,69739.49408,1.67588011,114.30913
,41.4,7.260604538,0.184605214,69267.08716,1.695072891,114.8131873
,41.6,7.263124549,0.186430673,68946.34649,1.709467489,115.2493058
,41.8,7.204906607,0.188278416,68563.42795,1.724734493,115.6481681
,42,7.623414223,0.19011342,68446.06424,1.73433085,116.1281193
,42.2,7.293962626,0.192016202,68473.81527,1.739129083,116.5543748
,42.4,7.600978012,0.19389616,68492.73561,1.745235852,117.0759652
,42.6,7.508636654,0.195821334,68615.49081,1.747853061,117.5120835
,42.8,7.57436975,0.197755392,69110.44987,1.743491056,118.1202392
,43,7.947102932,0.19968869,69645.02206,1.736948021,118.6199142
,43.2,7.865568182,0.201671185,70501.33798,1.726043032,119.2971034
,43.4,8.352277304,0.203636368,71312.48683,1.715137987,119.8614293
,43.6,8.244944616,0.205660485,72042.76041,1.7068502,120.453148
,43.8,8.460419624,0.207683632,72761.3509,1.701179581,121.198276
,44,8.417975473,0.209744007,73217.78892,1.698562387,121.730823
,44.2,8.501158044,0.211816867,73932.12461,1.692455581,122.4507479
,44.4,8.53608206,0.213913759,74662.27691,1.68591258,123.188205
,44.6,8.778999461,0.216017965,75639.1265,1.67413516,123.9410036
,44.8,8.62588774,0.218169375,76509.12675,1.664102578,124.6138096
,45,8.73235249,0.220325338,77116.97217,1.65974057,125.2745626
,45.2,8.676576363,0.222513582,77368.17727,1.664102574,126.0087322
,45.4,9.010998576,0.224698218,77161.21869,1.67718854,126.6519537
,45.6,8.647380322,0.226950631,76918.38013,1.689402172,127.1603925
,45.8,8.859493389,0.22918783,76725.43538,1.700743349,127.683078
,46,9.083250678,0.231446855,76800.22134,1.707722526,128.317533
,46.2,9.021632862,0.23374735,77223.94154,1.705977733,128.888432
,46.4,9.011594561,0.236067538,78085.88454,1.697689937,129.6642411
,46.6,9.067279551,0.238406514,78664.07928,1.693764133,130.3074618
,46.8,9.32596561,0.240755567,79086.74854,1.692891709,130.9462998
,47,9.231885488,0.243151425,79362.51703,1.695945118,131.6673201
,47.2,8.987211928,0.245581171,79379.1566,1.702051941,132.2042494
,47.4,9.19513534,0.248005597,79044.19277,1.716010317,132.7839153
,47.6,9.518701045,0.250446813,78803.25372,1.727351483,133.2967396
,47.8,9.665049643,0.252924242,78619.74867,1.736947866,133.7503912
,48,10.0318708,0.255412001,78339.69723,1.749597626,134.2533537
,48.2,10.21065896,0.257937126,78032.28998,1.761375005,134.6292053
,48.4,10.79628462,0.260460924,77982.05866,1.768790344,135.150797
,48.6,11.70222114,0.262988997,78161.2678,1.770098852,135.6110261
,48.8,11.83606989,0.265593234,78819.30004,1.762247243,136.1742554
,49,11.83430065,0.268232516,80255.06335,1.740437253,136.9730762
,49.2,12.13453836,0.270878613,82662.12348,1.702051641,137.9713289
,49.4,12.1801839,0.273568026,85094.8319,1.664974654,138.9082174
,49.6,11.97123723,0.276301071,87789.20065,1.627025291,139.9886515
,49.8,12.37213247,0.279021407,90434.04568,1.594310269,141.3276914
,50,12.37616346,0.281809253,91983.26197,1.578170877,142.3237514
,50.2,12.63311619,0.284594486,93095.2493,1.571191658,143.4633593
,50.4,12.57806942,0.287428414,93302.21598,1.575989861,144.2819035
,50.6,12.46561334,0.290280116,93301.35725,1.583841468,145.1070226
,50.8,13.00542799,0.293131944,93965.63644,1.584713819,146.2718342
,51,12.80310596,0.296061258,94519.17719,1.584713838,147.145167
,51.2,12.78048836,0.299008232,95215.90939,1.585150041,148.2639539
,51.4,13.0490614,0.301965675,95819.01774,1.584713817,149.1646828
,51.6,12.96985926,0.304975756,96292.70869,1.586894824,150.0665057
,51.8,13.13317643,0.308000223,96141.48963,1.601289402,151.1272176
,52,13.05396464,0.311071046,95894.86687,1.613939204,151.8920689
,52.2,13.32002243,0.314149988,95205.13609,1.634876769,152.7281469
,52.4,13.22000117,0.317283892,94595.04719,1.65276097,153.3406852
,52.6,13.10042322,0.320450522,94256.08968,1.666719375,153.9948628
,52.8,13.77829943,0.32359656,93956.03537,1.681550103,154.8386132
,53,13.69656678,0.326824237,93936.25385,1.688965508,155.4774502
,53.2,13.71383541,0.33007772,94334.47342,1.691146506,156.3365388
,53.4,13.77519411,0.333361077,95111.28876,1.686784503,157.2613737
,53.6,14.04828817,0.336663543,95643.65489,1.685039678,158.0295136
,53.8,14.3496645,0.33999735,96488.6604,1.679369053,158.8853159
,54,14.17014723,0.343396212,97551.80232,1.671953675,159.9021952
,54.2,14.4482172,0.346799001,98471.16409,1.665410653,160.7569016
,54.4,14.71005799,0.350237116,99704.53009,1.656250434,161.8581576
,54.6,14.96066147,0.353710477,100795.279,1.648835015,162.8805177
,54.8,15.37016885,0.357208185,101462.0952,1.646653978,163.7407036
,55,15.36076537,0.360768698,101960.1039,1.648834978,164.7718287
,55.2,15.3958675,0.364362009,102113.9205,1.654069372,165.5476381
,55.4,15.38770058,0.367994367,102407.5478,1.659303769,166.5426026
,55.6,15.48602214,0.371656171,102797.7125,1.661920958,167.3907336
,55.8,15.69624006,0.375347325,103611.5887,1.658431341,168.327623
,56,16.27585411,0.379051323,104645.9094,1.65363309,169.436551
,56.2,16.84839033,0.382792975,105384.2602,1.651015838,170.315366
,56.4,16.92131266,0.386605141,106363.3793,1.647526234,171.4308662
,56.6,16.88024676,0.390463046,107166.0066,1.644472842,172.4039151
,56.8,17.08752268,0.394343328,107902.9832,1.642728025,173.421892
,57,17.32224792,0.39826103,109185.6423,1.634440206,174.6535453
,57.2,17.16177333,0.402243959,110888.5654,1.619609434,175.7800022
,57.4,17.82329506,0.406212697,112700.5281,1.605650987,177.161779
,57.6,17.93278739,0.41025774,114271.027,1.595182185,178.3682289
,57.8,17.90998741,0.414352134,115473.1092,1.590383989,179.5746781
,58,18.27904651,0.418461931,116514.1675,1.589511556,180.9279633
,58.2,18.02286123,0.422654115,116522.4002,1.598671773,181.8845747
,58.4,18.18599044,0.426860775,116500.7406,1.610012952,183.0526725
,58.6,18.53838983,0.431097317,116458.3748,1.619173113,184.0125741
,58.8,18.66157019,0.4353915,116843.6772,1.623098899,185.0776689
,59,18.58881088,0.439741739,116740.1392,1.634440096,186.2369997
,59.2,18.79600923,0.444109891,116850.4196,1.640546874,187.1443033
,59.4,18.59344497,0.448563463,116842.585,1.650143286,188.2641853
,59.6,18.55727207,0.453043349,116837.3489,1.657994884,189.1594343
,59.8,18.69248123,0.457556954,116613.8764,1.669336062,190.0678334
,60,18.75280439,0.462120873,116708.7254,1.677187651,191.1153953
,60.2,19.00863707,0.4667178,117021.0374,1.680241024,191.9974965
,60.4,18.98491499,0.47137921,118026.818,1.675879031,193.1721685
,60.6,18.85469119,0.476094494,118398.2283,1.678496242,194.1178224
,60.8,19.00983121,0.48083839,118777.6415,1.681113425,195.1051171
,61,19.08925289,0.48563487,119242.8392,1.683730616,196.2107557
,61.2,19.15785107,0.490480348,119500.4414,1.687656407,197.0599826
,61.4,19.35872736,0.495365818,118971.7038,1.703359575,197.981531
,61.6,19.37073492,0.500312773,119172.2397,1.707721571,198.8143212
,61.8,19.08987538,0.505328653,119523.0776,1.710338797,199.7008019
,62,19.53782792,0.510347015,120127.5497,1.710774953,200.7549411
,62.2,19.40421395,0.51545402,120605.1674,1.712519765,201.7871617
,62.4,19.79973517,0.520577567,121214.8415,1.711211128,202.6451564
,62.6,20.32587005,0.525744001,121251.7148,1.717317872,203.4505548
,62.8,21.69979074,0.530906492,120887.4094,1.730403725,204.3896428
,63,22.01957647,0.536190269,120500.3275,1.741308683,205.0350565
,63.2,22.42421636,0.541521558,120389.5099,1.750032635,205.8941472
,63.4,22.50936501,0.546927426,120144.8747,1.758756618,206.5329856
,63.6,22.62528851,0.552385581,120416.4692,1.761373804,207.2715388
,63.8,22.97415944,0.557883285,121889.3078,1.750032582,208.3815622
,64,23.29972596,0.56343779,123487.1748,1.736074164,209.3611881
,64.2,23.65773108,0.569045895,125502.987,1.718626148,210.5994171
,64.4,23.77112329,0.57472649,128349.8501,1.692017966,212.0359804
,64.6,24.01096835,0.58045569,130798.951,1.670207968,213.3399556
,64.8,24.10104673,0.58625237,132780.8357,1.655377176,214.6976226
,65,24.35252117,0.592096701,134021.23,1.650578958,216.108984
,65.2,24.22543256,0.598024662,134635.0264,1.65145137,217.1751735
,65.4,24.66658107,0.603974632,134563.5209,1.662356316,218.3651892
,65.6,24.34978064,0.610034443,134112.1185,1.675878532,219.2944055
,65.8,24.63699251,0.61611529,133716.8211,1.688092091,220.1951352
,66,24.85264384,0.622262049,133928.0272,1.694198864,221.3139238
,66.2,24.73133096,0.628492708,134508.5835,1.694635076,222.3056003
,66.4,24.78056531,0.634774664,135726.3956,1.689400678,223.6336814
,66.6,25.17423188,0.641097156,136963.2526,1.682857648,224.8094521
,66.8,25.6178075,0.647479924,137805.236,1.681112808,225.9622111
,67,25.80678515,0.653943707,138421.9695,1.683293788,227.2672816
,67.2,25.91255388,0.660477789,138367.5614,1.690709169,228.214033
,67.4,25.98253678,0.667079807,137907.8691,1.704231347,229.2681705
,67.6,26.31874468,0.673730696,137836.4638,1.712082905,230.1612301
,67.8,26.68406146,0.680446509,138309.1483,1.714700066,231.1901665
,68,26.87630896,0.687275472,139083.6339,1.715136247,232.3790849
,68.2,27.68838605,0.694063697,140301.0605,1.709029376,233.4584301
,68.4,27.78577077,0.701001788,142075.5902,1.698124382,234.8281507
,68.6,27.74503475,0.708018612,143496.0837,1.690272796,236.0532285
,68.8,27.99797858,0.71508663,144592.8052,1.685910778,237.2750204
,69,28.10864153,0.722234962,145703.6142,1.681984973,238.6929556
,69.2,28.07036751,0.729465251,145781.2369,1.687219371,239.6933996
,69.4,28.04081781,0.736767537,145919.5342,1.694198565,240.9546377
,69.6,28.54455944,0.744108257,145848.1667,1.701613907,241.9364566
,69.8,29.02000183,0.751524493,145993.0677,1.707284453,242.9763519
,70,29.58320685,0.759009598,146443.5921,1.711210193,244.1937627
,70.2,30.51330569,0.766545744,147872.2458,1.704667112,245.5503403
,70.4,30.85975438,0.77419592,148976.5518,1.699868886,246.6976206
,70.6,31.39546761,0.781910626,150039.3887,1.695943041,247.9062658
,70.8,31.26266786,0.789746901,151350.9787,1.691144861,249.4261065
,71,31.33618811,0.797648233,151974.1281,1.691581054,250.5624271
,71.2,31.82152872,0.805601915,151993.0606,1.699868795,251.8094239
,71.4,32.12756368,0.813647281,152460.9302,1.702485962,252.8701379
,71.6,32.2921482,0.821782709,153413.2502,1.700741149,254.030566
,71.8,32.49499109,0.82999733,154951.132,1.695942937,255.6293054
,72,32.51727995,0.838306303,156503.3545,1.688527547,256.9091724
,72.2,32.8473903,0.846678314,158604.4262,1.677186334,258.5221576
,72.4,33.08222491,0.855140708,159857.3518,1.67238812,259.7976433
,72.6,33.19848804,0.863695878,160612.1794,1.672824308,261.0983306
,72.8,33.62298822,0.872316789,160891.5928,1.679803457,262.6631024
,73,34.08491397,0.881021882,160465.1538,1.690708396,263.7106682
,73.2,34.44906749,0.889820868,159620.4415,1.707283929,264.9039711
,73.4,34.65471368,0.898718621,159043.4493,1.719061293,265.794839
,73.6,35.31086589,0.907676226,158717.22,1.728657615,266.771181
,73.8,35.26522386,0.916770083,158503.0003,1.738254001,267.9666728
,74,35.61184856,0.925929374,158939.3953,1.739562561,268.9835557
,74.2,35.61235262,0.935203395,159910.0848,1.737381568,270.3193073
,74.4,36.03382658,0.944542997,160456.3401,1.738253924,271.3208502
,74.6,36.84007896,0.953951046,160796.562,1.741307243,272.3059594
,74.8,36.86341786,0.963505176,161364.446,1.744360633,273.6176042
,75,37.29399844,0.97312847,161587.8937,1.748722582,274.5698376
,75.2,37.65426085,0.982853156,162135.8029,1.751339744,275.7916309
,75.4,37.85393452,0.992686073,162884.9404,1.750031125,276.8227582
,75.6,38.64804614,1.002578673,164154.3908,1.74392426,277.95251
,75.8,38.2108034,1.012651573,166583.8172,1.729093529,279.6224701
,76,38.35468646,1.022787444,168898.1041,1.714262745,281.0272571
,76.2,38.90040231,1.032998887,171347.4822,1.699868123,282.7520136
,76.4,39.01679733,1.043341089,173944.4442,1.68416494,284.4175948
,76.6,39.08034474,1.053790761,175910.4628,1.673259955,285.8410092
,76.8,39.40636694,1.064327798,177024.1991,1.672823726,287.6994492
,77,39.44658534,1.074989256,177018.2821,1.679366709,288.9168576
,77.2,40.09413609,1.085717903,177025.2145,1.68809063,290.3972569
,77.4,40.09937693,1.09659661,176317.7633,1.701612807,291.4492022
,77.6,40.66286262,1.107547928,175497.2778,1.71600732,292.4584176
,77.8,40.64394103,1.118647464,175431.4947,1.726039902,293.8895018
,78,41.35798084,1.129810386,175669.5057,1.730838022,294.9798048
,78.2,41.49377298,1.141123464,175631.1768,1.739125792,296.2366621
,78.4,41.82256766,1.152537444,175619.1482,1.745232547,297.2447794
,78.6,42.17547166,1.164064624,175598.4825,1.751775498,298.2802915
,78.8,42.99759698,1.175676677,175470.0479,1.760499398,299.5283878
,79,43.28640115,1.187440468,175395.7204,1.766606156,300.4630877
,79.2,43.31061521,1.199339885,175600.1459,1.771404343,301.6224201
,79.4,43.57359004,1.211343137,176369.6437,1.77009572,302.6645061
,79.6,44.1352284,1.223447361,177101.8403,1.769223266,303.7285097
,79.8,44.87655622,1.235661369,178515.583,1.763988803,305.1946654
,80,45.18356823,1.248026693,180059.6064,1.75613719,306.3890649
,80.2,45.9157049,1.260488354,182610.6096,1.741306352,308.0502685
,80.4,46.62203009,1.273076935,184922.0853,1.727784114,309.4956045
,80.6,46.58537246,1.28584077,187987.9626,1.709027562,311.1831003
,80.8,46.86235286,1.298712104,192193.3566,1.684164195,313.4404033
,81,47.45962694,1.311691758,195020.7314,1.671078169,315.5475874
,81.2,47.72491824,1.324823628,196993.0429,1.662790365,317.1529032
,81.4,48.11914624,1.338079025,197749.1081,1.66584372,319.0266846
,81.6,48.48340159,1.351469617,196850.4271,1.679802051,320.3076515
,81.8,48.54645698,1.365014448,194834.9385,1.702920589,321.3968538
,82,48.61781059,1.378694808,193339.2029,1.722985732,322.6569982
,82.2,49.12177454,1.3924843,192167.2095,1.739125043,323.6070412
,82.4,49.35948127,1.406429776,192436.9181,1.744795605,324.950466
,82.6,49.34424228,1.42053207,193608.5218,1.741742215,326.2237586
,82.8,50.08858307,1.434725965,195629.0086,1.732145766,327.7600444
,83,50.66317623,1.449073678,197897.4184,1.722113135,329.5779437
,83.2,51.26603394,1.463563733,199569.4775,1.716442491,331.3596827
,83.4,51.730759,1.47820841,199876.637,1.719495838,332.6242134
,83.6,52.55654211,1.492976383,199836.3954,1.725602541,333.918334
,83.8,52.95632536,1.507920764,200021.5517,1.731709285,335.5455665
,84,53.20632745,1.523025252,199937.2929,1.737816044,336.6950392
,84.2,53.40971426,1.538284605,200684.0009,1.73956082,338.236799
,84.4,53.99994964,1.553671719,201811.6233,1.737379767,339.5758447
,84.6,54.45288292,1.569222602,203354.8963,1.732581536,341.0606268
,84.8,54.37415311,1.584964558,204961.8766,1.729091954,342.9059149
,85,54.70723062,1.600837606,206508.3964,1.723857537,344.3183744
,85.2,54.90050933,1.616879401,208129.4032,1.719931729,346.1176424
,85.4,55.56465281,1.633132866,208954.6519,1.720367863,347.4840829
,85.6,55.98334777,1.649484402,209928.5596,1.722112617,349.3710147
,85.8,56.64079611,1.665985117,210704.8299,1.72298495,350.7418383
,86,57.44382873,1.682558054,211072.3125,1.728219256,352.3603093
,86.2,58.1586311,1.699387428,211795.3412,1.729091583,353.7026436
,86.4,58.91001392,1.716383332,213220.7055,1.726038118,355.4821932
,86.6,59.26867276,1.73357645,215056.8637,1.719058905,357.1455866
,86.8,59.84029213,1.750928558,216770.8775,1.713388267,358.8933569
,87,60.26753445,1.76846462,219207.0623,1.703791855,360.9435602
,87.2,60.9751275,1.786158475,220495.8375,1.701174595,362.5302527
,87.4,61.34657056,1.804052221,221976.9422,1.699429765,364.5114221
,87.6,61.80659137,1.822119957,221994.2087,1.706408898,365.9720978
,87.8,62.03986755,1.840384164,222104.7315,1.714696649,367.8305387
,88,62.80683255,1.858796783,222255.8754,1.720367155,369.1860231
,88.2,63.25969401,1.877415069,223030.8994,1.723420501,370.954612
,88.4,63.40801947,1.896240417,223822.9057,1.724729083,372.4185724
,88.6,63.95400337,1.915228673,226017.6817,1.716877455,374.1444278
,88.8,64.91761303,1.934380342,229455.4163,1.703355207,376.5551478
,89,65.78800982,1.953730563,231334.6933,1.698120741,378.3390825
,89.2,65.89461414,1.973325516,233346.0013,1.693322547,380.5120102
,89.4,66.20169543,1.993103793,235323.8706,1.687651938,382.4542793
,89.6,66.55533627,2.013077495,235977.0657,1.690269095,384.2256075
,89.8,67.00919929,2.033245322,235454.6188,1.700737814,385.9459827
,90,67.67976202,2.0536012,235736.5091,1.706844528,387.8088118
,90.2,68.22674257,2.07416968,236141.7108,1.711206459,389.3615341
,90.4,68.68341999,2.094950737,236108.6295,1.719930383,391.1312203
,90.6,69.44124244,2.115920774,236806.2881,1.7225475,392.6938069
,90.8,70.23439069,2.13709914,238379.7456,1.719930234,394.4744537
,91,70.7558623,2.158508273,239250.6976,1.722111171,396.4589128
,91.2,71.39003353,2.180125049,239526.7326,1.726036896,397.92507
,91.4,72.0553696,2.201957029,240264.7386,1.728217822,399.8580292
,91.6,72.30967074,2.224035353,240817.2631,1.730398791,401.4293771
,91.8,72.54729692,2.246336626,240653.961,1.737377938,402.8834767
,92,73.06526606,2.268843535,241824.4492,1.738250285,404.7605497
,92.2,73.75125997,2.291565586,243740.8773,1.73476063,406.7187121
,92.4,74.45926514,2.314514432,245468.8859,1.731270973,408.3941642
,92.6,75.00416482,2.337704483,247289.3235,1.727345135,410.146319
,92.8,75.51741206,2.361129639,250203.5911,1.718621122,412.5175879
,93,76.53022811,2.384757318,252236.2889,1.712950444,414.3913795
,93.2,77.27843553,2.408639887,253423.3039,1.713386568,416.5139097
,93.4,77.90721514,2.432770204,253576.0084,1.718184688,418.0754004
,93.6,78.83172635,2.457123591,253208.1822,1.726036164,419.6084043
,93.8,79.686728,2.481726157,252768.008,1.735632439,421.5446538
,94,80.04374817,2.506608633,252100.0164,1.746101161,423.1916121
,94.2,80.7193783,2.531720125,253322.8052,1.744356299,424.8199468
,94.4,81.10751817,2.5571017,256501.6737,1.732578912,427.100265
,94.6,82.19781155,2.582692075,260075.5562,1.718184267,429.2315653
,94.8,82.94445483,2.608562234,264673.467,1.698991479,431.7387153
,95,83.21349833,2.634723538,270054.9408,1.678053946,434.7192346
,95.2,84.01413741,2.661112845,272581.5046,1.671947097,436.8932676
,95.4,84.6599854,2.687777481,273757.2534,1.675000421,439.4135647
,95.6,85.56952949,2.714692626,273645.7978,1.682851898,441.3005061
,95.8,86.08300652,2.741904304,272229.1112,1.698118779,443.0208826
,96,86.51490573,2.76939459,270883.4824,1.713385666,444.8968611
,96.2,87.22131548,2.797143093,270743.9476,1.719928567,446.510951
,96.4,88.09823744,2.825159167,271652.0837,1.72210947,448.669645
,96.6,88.66062498,2.853477456,273151.7561,1.720364624,450.5872639
,96.8,89.5274731,2.882060215,274945.4915,1.718619747,452.9848368
,97,89.81355134,2.910968369,276157.9076,1.718619719,454.8104081
,97.2,90.56299798,2.940136419,278611.2255,1.713385271,457.2222242
,97.4,91.34900524,2.969595218,280165.6959,1.713385194,459.5693915
,97.6,91.95359315,2.999361808,281169.2038,1.714693728,461.4957775
,97.8,92.8068964,3.029411136,282622.9407,1.713821249,463.5821507
,98,93.57196143,3.059768134,284649.7209,1.71076779,466.0860132
,98.2,94.38689692,3.090426869,285205.5713,1.714257292,467.9050159
,98.4,95.69681319,3.121361085,285693.0996,1.719491537,470.1721983
,98.6,96.48086684,3.152640716,286326.7997,1.722981042,472.0394155
,98.8,96.89963009,3.1842586,286618.1002,1.728651571,473.9022434
,99,97.60953677,3.216175098,286798.9096,1.736066862,475.9743707
,99.2,98.16797162,3.248422079,287945.5907,1.737811597,478.1188165
,99.4,98.94599836,3.280978724,289271.2057,1.737375322,479.9180941
,99.6,99.54426484,3.313874177,290255.0674,1.738683856,481.7666809
,99.8,100.5925813,3.347070591,291622.7438,1.739556147,484.1237145
,100,101.1474791,3.380633055,292547.0661,1.740864685,485.8868299
,100.2,101.6973313,3.414533016,293614.3396,1.742609421,488.0389462
,100.4,102.4326616,3.448761299,294367.6745,1.74566273,490.1812036
,100.6,103.1171861,3.483336871,295374.9505,1.746535057,492.0714315
,100.8,104.0836975,3.518241244,296449.9337,1.746971158,494.0087808
,101,105.192422,3.553487017,297183.7627,1.749588233,496.1269362
,101.2,106.1030784,3.589099837,297898.3449,1.751332931,497.8944387
,101.4,106.9737428,3.625073105,298229.3719,1.756567214,499.9260249
,101.6,107.9824587,3.661398804,299057.1002,1.758311902,501.6858597
,101.8,108.687443,3.698109427,300958.3376,1.755258449,503.6297814
,102,109.8349832,3.735159685,304106.09,1.747406781,506.1303644
,102.2,110.7919402,3.772594822,306362.6239,1.743917106,508.4906858
,102.4,111.3811013,3.810430328,308873.4569,1.737810285,510.6033563
,102.6,112.0758636,3.848638993,311146.1988,1.733012045,512.7806775
,102.8,112.8986902,3.887223065,312223.7311,1.73519295,515.2911194
,103,113.7289429,3.926194306,312166.0403,1.740863432,517.0947839
,103.2,114.7188424,3.965744721,313038.674,1.74304432,519.4638721
,103.4,115.9208654,4.005481185,313688.873,1.745225186,521.3321915
,103.6,116.7567527,4.045642148,315035.7174,1.744788905,523.3780241
,103.8,117.7407011,4.085992776,317312.6695,1.741735427,526.0079083
,104,118.9429476,4.126938816,320402.5479,1.733447561,528.3046783
,104.2,119.7149938,4.168326457,323868.3024,1.725159738,531.0781074
,104.4,120.8160227,4.210108247,326519.0318,1.719489067,533.3496727
,104.6,121.5438409,4.252334509,328442.5256,1.717744207,535.7088967
,104.8,122.5802569,4.294964634,329721.1516,1.720361287,538.3968586
,105,123.6195167,4.338023013,329589.6555,1.729085126,540.7725236
,105.2,124.5900691,4.381518574,329028.514,1.73780897,542.5323597
,105.4,125.3662844,4.425463898,328634.0535,1.746532833,544.6110644
,105.6,126.3346171,4.469838092,329485.5335,1.748713721,546.6371751
,105.8,127.3557098,4.514654713,331639.0732,1.746096438,549.3317114
,106,128.2860448,4.559927699,333172.2162,1.744351556,551.3348109
,106.2,129.3094894,4.605649396,335976.1991,1.738680894,554.1345432
,106.4,130.4801215,4.651820886,338584.5693,1.732574021,556.3633769
,106.6,131.5262986,4.698464485,339212.2687,1.735627295,558.4738639
,106.8,132.2961835,4.745594913,339249.7768,1.743042565,561.0270428
,107,133.3908817,4.793177509,338868.6704,1.750457801,562.7978395
,107.2,134.432673,4.841241219,338100.712,1.760926419,564.9017519
,107.4,135.6461918,4.889775881,337184.9702,1.771831216,566.8675998
,107.6,136.3417248,4.938832042,337941.247,1.774012129,568.769885
,107.8,137.4124029,4.988355979,339448.6931,1.772703429,570.768604
,108,138.6589658,5.038365708,343595.0747,1.760925992,573.5738187
,108.2,139.8147629,5.088883786,347789.2936,1.748276173,576.077695
,108.4,140.8402743,5.139917984,351138.7015,1.740424531,578.8686611
,108.6,142.0924187,5.19145009,353900.6853,1.73519005,581.4360931
,108.8,142.9176748,5.243527939,356729.7016,1.729955609,584.0418713
,109,143.8431014,5.296122327,357592.502,1.733881284,586.7101097
,109.2,145.3475023,5.34920707,358064.6396,1.737806903,588.8260853
,109.4,146.4100367,5.402854266,359924.2969,1.737370602,591.518434
,109.6,148.0066167,5.457005421,361002.9213,1.739115229,593.8239814
,109.8,148.970805,5.511742316,361965.2725,1.741296115,596.1459552
,110,149.9698491,5.567026833,363937.614,1.74042362,598.9391151
,110.2,151.3407,5.622842373,365906.0036,1.739551092,601.6906418
,110.4,152.7659563,5.679215188,367956.0238,1.736933771,604.0115292
,110.6,153.873306,5.736175349,370053.3304,1.734752679,606.4693815
,110.8,155.0908021,5.79370043,372830.3329,1.731699186,609.6931874
,111,156.1971369,5.851810914,373886.4605,1.733443856,612.0217403
,111.2,157.4801746,5.910493631,373591.4027,1.741731457,614.585887
,111.4,158.7835019,5.969764601,372369.9993,1.752200035,616.3917552
,111.6,159.8937152,6.029643828,371709.9283,1.760923846,618.355413
,111.8,161.008409,6.090122034,373149.1815,1.762668517,621.0598196
,112,162.4391585,6.151186358,375616.4503,1.760051196,623.8190192
,112.2,163.5120592,6.212887883,379800.455,1.749146186,626.4017919
,112.4,164.7104902,6.275201032,386771.3305,1.729517244,630.1208923
,112.6,166.1151525,6.338126618,390440.4719,1.720356989,632.5666988
,112.8,167.1761067,6.401707064,393987.4994,1.71425014,636.168549
,113,168.3850516,6.465916487,395895.327,1.713813825,639.4361877
,113.2,169.9208617,6.530749604,396025.519,1.718611829,641.818442
,113.4,171.024771,6.596262459,395987.9244,1.725590853,644.7792607
,113.6,172.2325729,6.662426727,395852.3535,1.732133671,647.1198705
,113.8,173.4552447,6.729254701,396962.2576,1.734750724,649.6938812
,114,174.7826391,6.79674717,399186.9166,1.734750592,652.7851029
,114.2,176.4460451,6.864895687,401324.4312,1.733878034,655.3624104
,114.4,177.9163229,6.933741732,403054.7499,1.736058866,658.3659729
,114.6,179.2725097,7.00328687,406590.1613,1.730388187,661.2720083
,114.8,180.5545391,7.07353564,408476.7156,1.730824255,664.0355917
,115,182.0336352,7.144477193,409419.0419,1.735186064,666.9679296
,115.2,183.545065,7.216129438,410178.0547,1.739547868,669.8334253
,115.4,185.2144562,7.28849111,410751.9235,1.743037265,672.1455541
,115.6,186.4685744,7.361607174,409126.2793,1.754814418,674.2549559
,115.8,188.0021205,7.435439465,408815.1351,1.762665781,677.0492279
,116,189.5330526,7.510013664,410100.3968,1.763101821,679.3909403
,116.2,190.8891501,7.585348427,410737.0808,1.767463637,682.0022131
,116.4,192.3299889,7.66143467,410775.459,1.772697834,684.0097123
,116.6,193.7041478,7.738289792,412821.0303,1.770952913,686.4741507
,116.8,195.0665362,7.815917911,415525.7164,1.768335602,689.5675679
,117,196.6409549,7.894312017,417605.5836,1.766154466,691.8796982
,117.2,198.4082671,7.973481003,423234.4899,1.752632235,695.4191054
,117.4,199.7935748,8.053470482,430087.0504,1.735620485,699.2357394
,117.6,201.1554594,8.134265128,435540.2658,1.723406885,702.649127
,117.8,202.9082443,8.215845771,440452.224,1.71381042,706.2115468
,118,204.3630508,8.298265727,445352.1629,1.705522571,710.2506265
,118.2,205.8776279,8.381509827,446783.4462,1.707267202,713.1248928
,118.4,207.8604752,8.465559568,448128.7637,1.710320371,716.5876026
,118.6,209.3839366,8.550484009,448946.5531,1.71380978,719.4903593
,118.8,210.8007691,8.636268583,450112.3132,1.716863004,722.5443306
,119,213.0885446,8.722857798,449184.071,1.728203843,725.7177618
,119.2,214.55918,8.810370866,449305.2983,1.734310424,728.2139838
,119.4,216.1503123,8.898755094,449820.0414,1.740853186,731.3139838
,119.6,217.78207,8.98802474,449262.4656,1.749576916,733.8573275
,119.8,219.6599503,9.078174961,448490.698,1.758300619,736.2713727
,120,221.1341776,9.169257392,451290.6997,1.756119497,739.5740925
,120.2,223.0084401,9.261228687,452408.9495,1.757864085,742.0571737
,120.4,224.688705,9.354136918,452733.8232,1.763534443,745.0366411
,120.6,226.4644986,9.447972354,455362.3919,1.760917096,747.871466
,120.8,228.0920503,9.542760393,459917.789,1.752629236,751.1621351
,121,229.6162089,9.638989339,462003.8648,1.752629082,754.4933467
,121.2,231.4048581,9.735689662,465022.286,1.748266958,757.3621434
,121.4,232.9255343,9.832888658,470839.92,1.736925752,761.3628774
,121.6,234.6656182,9.93154458,473347.0844,1.735180801,764.4387745
,121.8,236.8735307,10.03116253,474896.382,1.738233939,768.0801089
,122,238.5721144,10.13181503,477469.0302,1.736925186,771.0946426
,122.2,240.7580751,10.23344666,480946.3022,1.734307802,774.7710417
,122.4,242.7313034,10.33611373,482324.0166,1.736488575,777.6365565
,122.6,244.6215859,10.43981767,485475.8498,1.733435028,781.0094175
,122.8,246.701393,10.54455121,490729.5816,1.725147134,785.3794458
,123,248.2668717,10.65037105,495120.2733,1.717731681,788.8585912
,123.2,250.1766191,10.75723134,498989.3809,1.713369553,793.1519116
,123.4,251.9901024,10.86517173,501035.048,1.71293318,796.3867037
,123.6,253.8583235,10.97419326,502687.8405,1.71467777,799.7814818
,123.8,255.5086814,11.01970118,502214.9089,1.724710064,803.5192354
,124,256.8913223,11.01961111,499591.8533,1.738668126,805.8993073
,124.2,258.0659693,11.01953466,496436.7524,1.755679563,808.7034438
,124.4,258.5933397,11.01950059,495508.8463,1.764403384,811.0813053
,124.6,259.8133293,11.01942117,495306.216,1.770509972,813.5895807
,124.8,260.727152,11.0193618,496947.7603,1.772254654,817.011733
,125,260.8863735,11.01935183,500822.5873,1.767456509,820.705622
,125.2,261.3060031,11.01932482,503069.9717,1.766147886,823.5009754
,125.4,261.6960975,11.01929973,503322.9442,1.772254557,826.6075296
,125.6,262.1889409,11.01926792,501968.7196,1.78228696,828.9306022
,125.8,262.5428445,11.01924521,500158.7901,1.793191764,831.0410883
,126,263.0552392,11.01921212,497396.7012,1.807586099,833.2808827
,126.2,263.1146237,11.01920868,496372.2667,1.815001384,835.0637232
,126.4,263.7439109,11.01916794,498207.1109,1.815001322,837.8678458
,126.6,263.8611176,11.01916072,501763.3344,1.808894601,840.6051156
,126.8,264.4080393,11.01912537,505155.8987,1.803660224,843.4015678
,127,264.8967227,11.01909383,508512.0797,1.799734432,846.6703014
,127.2,264.8903812,11.0190947,509793.6104,1.801261109,849.2749786
,127.4,264.9352061,11.01909223,508880.8146,1.808894494,851.5005158
,127.6,265.277462,11.01907027,505693.165,1.822852649,853.1211877
,127.8,265.3992445,11.01906276,503808.0723,1.834193667,855.3193322
,128,265.4702766,11.01905856,505130.2792,1.834193663,857.3366712
,128.2,265.8237642,11.01903588,508258.2663,1.829831691,860.1287361
,128.4,266.0532874,11.0190213,511602.5079,1.824161151,862.519743
,128.6,266.3339772,11.01900338,518877.0049,1.808894353,866.3790975
,128.8,266.5722362,11.01898824,523573.6521,1.799734264,869.2730675
,129,266.6166451,11.01898579,526647.8257,1.796680902,872.5012485
,129.2,266.7459154,11.01897778,527488.8934,1.798861858,874.8769087
,129.4,267.4725435,11.01893067,527749.2913,1.803659914,877.7095269
,129.6,267.4146196,11.01893491,526970.4353,1.810639013,879.9854702
,129.8,267.4265815,11.01893459,526198.1408,1.817618108,882.1430683
,130,267.7305665,11.01891514,525529.8985,1.824597172,884.6294092
,130.2,267.7649917,11.01891334,526866.4334,1.824597169,886.8823412
,130.4,268.0997597,11.01889188,529012.7763,1.823288555,889.7774088
,130.6,268.167464,11.01888791,530274.8929,1.823724742,892.1607409
,130.8,268.3291813,11.01887777,530948.4873,1.825905693,894.3753218
,131,268.478419,11.01886846,532073.1015,1.827650451,897.0424641
,131.2,268.5810661,11.0188622,531789.2815,1.832448569,898.9337892
,131.4,268.7644148,11.01885065,531643.6683,1.837682871,901.335751
,131.6,269.0484324,11.01883251,531530.9344,1.842044776,903.3509057
,131.8,268.6826779,11.01885691,530951.8704,1.847279137,905.1688003
,132,268.8785062,11.01884455,529200.9497,1.856875372,907.076564
,132.2,269.1625237,11.01882641,527056.1277,1.866471597,908.3159014
,132.4,268.9423648,11.01884128,524883.8947,1.876940264,909.7897254
,132.6,269.1922714,11.01882537,523877.6309,1.883483139,911.0959059
,132.8,269.5170557,11.01880457,522469.1277,1.890898392,912.2147082
,133,269.2744334,11.01882091,522298.6545,1.89482416,913.7126389
,133.2,269.6025457,11.01879988,523678.4076,1.893515545,915.1448353
,133.4,269.6170035,11.01879939,523665.053,1.897005091,916.6603057
,133.6,269.5399441,11.01880489,522323.9277,1.903548001,917.6837653
,134.4,269.7611884,10.9224047,1.7977E+308,1.881302118,0
,134.6,269.5227648,10.81226358,1.7977E+308,1.770072829,0
,134.8,269.2485663,10.7021248,1.7977E+308,1.592978335,0
,135,269.1582341,10.59197399,1.7977E+308,1.350891001,0
,135.2,269.1619151,10.48181702,1.7977E+308,1.060822382,0
,135.4,268.8020232,10.37168385,1.7977E+308,0.737603079,0
,135.6,268.2674166,10.26156213,1.7977E+308,0.469780332,0
,135.8,268.2727616,10.15140505,1.7977E+308,0.254736968,0
,136,268.2182043,10.04125189,1.7977E+308,0.115155068,0
,136.2,267.9215424,9.931114587,1.7977E+308,0.010032449,0
,136.4,267.7347012,9.820970091,1.7977E+308,0.033150702,0
,136.6,267.481302,9.710829954,1.7977E+308,0.044491733,0
,136.8,267.3884739,9.600679303,1.7977E+308,0.045800314,0
,137,267.1741776,9.490536605,1.7977E+308,0.039693606,0
,137.2,267.194498,9.380378547,1.7977E+308,0.03271451,0
,137.4,266.9785377,9.270235958,1.7977E+308,0.030969737,0
,137.6,266.5695592,9.160106006,1.7977E+308,0.036640253,0
,137.8,266.0282968,9.049984715,1.7977E+308,0.036640254,0
,138,265.7108355,8.939848772,1.7977E+308,0.029224965,0
,138.2,265.7927221,8.829686682,1.7977E+308,0.016575353,0
,138.4,265.1657662,8.719571002,1.7977E+308,0.012649612,0
,138.6,265.3509052,8.608851366,1.7977E+308,0.02224587,0
,138.8,264.8669614,8.499277109,1.7977E+308,0.025735418,0
,139,265.1872963,8.388548622,1.7977E+308,0.027916386,0
,139.2,264.8011096,8.278967964,1.7977E+308,0.023990644,0
,139.4,264.4774085,8.168832429,1.7977E+308,0.017011548,0
,139.6,264.2435606,8.058691011,1.7977E+308,0.013958194,0
,139.8,264.0001451,7.94855022,1.7977E+308,0.010032452,0
,140,263.9501636,7.838396764,1.7977E+308,0.006542903,0
,140.2,263.6143989,7.728262019,1.7977E+308,0.000872387,0
,140.4,263.4966115,7.618113002,1.7977E+308,0.005234323,0
,140.6,263.1342236,7.50798,1.7977E+308,0.010032452,0
,140.8,263.1067054,7.397825074,1.7977E+308,0.009596259,0
,141,262.7318379,7.287692889,1.7977E+308,0.008287678,0
,141.2,262.3037239,7.17756419,1.7977E+308,0.006979098,0
,141.4,262.2183835,7.067413049,1.7977E+308,0.013085808,0
,141.6,261.8917704,6.957277705,1.7977E+308,0.020937294,0
,141.8,261.244847,6.847163332,1.7977E+308,0.022682069,0
,142,261.3358853,6.737000643,1.7977E+308,0.020501101,0
,142.2,261.1195089,6.626858081,1.7977E+308,0.013958196,0
,142.4,260.8802532,6.516717018,1.7977E+308,0.003925743,0
,142.6,260.5607119,6.40658121,1.7977E+308,0.011559132,0
,142.8,260.592264,6.296422416,1.7977E+308,0.02268207,0
,143,260.3567521,6.186281107,1.7977E+308,0.028788781,0
,143.2,260.0006039,6.076147697,1.7977E+308,0.031405944,0
,143.4,259.6120086,5.966016411,1.7977E+308,0.03315072,0
,143.6,259.434319,5.855871316,1.7977E+308,0.038385044,0
,143.8,259.2761808,5.745724941,1.7977E+308,0.041874594,0
,144,258.7815087,5.6356006,1.7977E+308,0.045364145,0
,144.2,258.8854427,5.525437067,1.7977E+308,0.047108919,0
,144.4,258.6632424,5.415294887,1.7977E+308,0.04710892,0
,144.6,258.0604135,5.305177627,1.7977E+308,0.04100221,0
,144.8,258.3685973,5.195000721,1.7977E+308,0.03402311,0
,145,257.7919757,5.084881746,1.7977E+308,0.022682074,0
,145.2,257.682508,4.974732184,1.7977E+308,0.020501105,0
,145.4,257.1682844,4.864609123,1.7977E+308,0.027480206,0
,145.6,257.0367694,4.754461006,1.7977E+308,0.034023112,0
,145.8,256.8045854,4.644319479,1.7977E+308,0.041002213,0
,146,256.519571,4.534181411,1.7977E+308,0.044491764,0
,146.2,256.3273217,4.42403727,1.7977E+308,0.044055571,0
,146.4,256.1346565,4.313893156,1.7977E+308,0.03925744,0
,146.6,255.8812572,4.203753018,1.7977E+308,0.033150727,0
,146.8,255.618706,4.093613479,1.7977E+308,0.027480209,0
,147,255.1215379,3.983489302,1.7977E+308,0.018756333,0
,147.2,255.1643217,3.873329772,1.7977E+308,0.008723876,0
,147.4,254.6205629,3.763208645,1.7977E+308,0.007415295,0
,147.6,254.5626777,3.653055706,1.7977E+308,0.009596264,0
,147.8,254.0987885,3.54292935,1.7977E+308,0.01483059,0
,148,254.0234318,3.432777555,1.7977E+308,0.017883947,0
,148.2,253.3615325,3.322664163,1.7977E+308,0.022245886,0
,148.4,253.0815098,3.212525768,1.7977E+308,0.023554468,0
,148.6,253.1525808,3.102364387,1.7977E+308,0.016139173,0
,148.8,252.4765378,2.99225192,1.7977E+308,0.009160071,0
,149,252.4319642,2.88209811,1.7977E+308,0.010904847,0
,149.2,252.170245,2.771958517,1.7977E+308,0.024426857,0
,149.4,251.9226694,2.661817998,1.7977E+308,0.034459317,0
,149.6,251.7508035,2.551672523,1.7977E+308,0.038385063,0
,149.8,251.2328358,2.441549707,1.7977E+308,0.041002227,0
,150,250.9977398,2.331408371,1.7977E+308,0.039257452,0
,150.2,250.5396744,2.221281633,1.7977E+308,0.034895514,0
,150.4,250.3728003,2.11113583,1.7977E+308,0.030533575,0
,150.6,249.9713092,2.001005388,1.7977E+308,0.023118279,0
,150.8,249.7145818,1.890865468,1.7977E+308,0.019628728,0
,151,249.4620143,1.780725276,1.7977E+308,0.017447758,0
,151.2,249.0397237,1.670596196,1.7977E+308,0.02093731,0
,151.4,248.9926541,1.560442549,1.7977E+308,0.030533578,0
,151.6,248.5795153,1.45031287,1.7977E+308,0.040129846,0
,151.8,248.0066372,1.340193649,1.7977E+308,0.046672757,0
,152,248.0527489,1.230033902,1.7977E+308,0.050162309,0
,152.2,247.6146507,1.119905857,1.7977E+308,0.045800371,0
,227.4,246.6096857,1.01521852,1.7977E+308,0.02878881,0
,227.6,246.2785402,0.904808079,1.7977E+308,0.029225005,0
,227.8,245.8266268,0.795231725,1.7977E+308,0.026171647,0
,228,245.5174848,0.685095236,1.7977E+308,0.0222459,0
,228.2,244.9670698,0.574974545,1.7977E+308,0.019628736,0
,228.4,244.6242327,0.464840263,1.7977E+308,0.020501125,0
,228.6,244.0758976,0.354719435,1.7977E+308,0.016575378,0
,228.8,243.4252295,0.244605307,1.7977E+308,0.012649631,0
,229,242.3560774,0.134518578,1.7977E+308,0.009596273,0
,229.2,241.1808482,0.024438794,1.7977E+308,0.008287691,0
,229.24,240.7809879,0.002433628,1.7977E+308,0.006979108,0
END,,,,,,