File: GB1_test 48.csv
Segment,Time On Sample,Displacement Into Surface,Load On Sample,Harmonic Contact Stiffness,Harmonic Displacement,Harmonic Load
Surface Marker,0,0,0,1067.487723,0.23032873,2.306531123
,0.3,0.083810345,0.000979524,13214.29157,0.160532144,2.408434877
,0.6,0.472979993,0.001939043,18384.83193,0.142210538,2.515817351
,0.9,0.635834297,0.002913389,23928.82828,0.119526647,2.794135134
,1.2,0.422605756,0.003912371,28482.84168,0.109929619,3.086697502
,1.5,0.555090538,0.004888706,33362.35583,0.101641274,3.381451377
,1.8,0.611027484,0.005870056,33505.53832,0.117345504,3.91617214
,2.1,0.546734406,0.006859282,35966.45134,0.127814992,4.633881356
,2.4,0.787800627,0.007828503,39611.03158,0.133485963,5.354877826
,2.7,0.697714257,0.008819419,43624.9261,0.137412021,6.08354442
,3,0.778196433,0.00979916,49346.57098,0.151371337,7.390761389
,3.3,0.830389295,0.010780095,45170.49822,0.195430429,8.665106178
,3.6,0.577223049,0.011779844,41236.14265,0.240361982,9.738930586
,3.9,0.671850228,0.012756809,40477.86488,0.282676159,11.26091245
,4.2,0.446973397,0.013754705,41171.12973,0.315393311,12.81905359
,4.5,0.488349907,0.014735159,41503.41101,0.356835032,14.59962993
,4.8,0.310899451,0.015729948,40000.45944,0.407873788,16.05148435
,5.1,0.572767012,0.016695958,37041.716,0.484650023,17.64359367
,5.4,0.050851288,0.017713314,32556.48719,0.595452116,19.02422479
,5.7,0.118852614,0.0186953,28334.82228,0.727193168,20.25145278
,6,0.336622488,0.019660925,23694.89623,0.907355592,21.24747989
,6.3,-0.402456137,0.020692507,19892.31178,1.104094759,21.93122077
,6.6,0.624889809,0.021608373,16047.0691,1.363214511,22.15146498
,6.9,1.024044244,0.022565389,14050.12074,1.541631993,22.16132687
,7.2,1.254294213,0.023533469,13191.39199,1.643709473,22.33664528
,7.5,1.637639844,0.024491519,14106.96508,1.577402688,22.99847207
,7.8,0.581553387,0.025543866,18081.43593,1.321772795,24.44375145
,8.1,1.182893951,0.026487636,22735.36131,1.126342325,25.83314923
,8.4,0.604399407,0.027508697,26059.48113,1.035170575,26.9968239
,8.7,1.010210177,0.028465277,25963.28743,1.070505072,27.87670291
,9,0.836087891,0.029459848,23293.43744,1.204863504,28.51332723
,9.3,1.057185405,0.030428527,21017.02832,1.346201567,28.95600611
,9.6,0.952954621,0.031418519,19616.54499,1.457003649,29.33184459
,9.9,1.368749884,0.032374444,19376.30115,1.501062708,29.74274718
,10.2,1.319433852,0.033360837,19831.0239,1.504116313,30.27527633
,10.5,1.729404816,0.034317143,20974.14233,1.464855706,30.95463512
,10.8,1.868130197,0.035291217,22957.89188,1.384589625,31.75452487
,11.1,1.915330998,0.036271287,25825.70138,1.2790223,32.76260507
,11.4,1.873503343,0.037257188,28753.08361,1.192212807,33.81341902
,11.7,1.979779099,0.038233389,30637.96126,1.152515998,34.74151025
,12,1.678354451,0.039236297,30079.64216,1.199192478,35.58084629
,12.3,2.067524367,0.040193964,28964.27568,1.262445605,36.16268424
,12.6,1.698704346,0.041201287,27454.92786,1.347510209,36.7105535
,12.9,2.431507453,0.042136443,27225.66659,1.38458959,37.3866254
,13.2,2.008604733,0.043147308,28108.35659,1.367576703,38.06488758
,13.5,2.284200961,0.044112415,29076.80015,1.351436228,38.87902217
,13.8,2.193282851,0.045101532,30638.80592,1.312830001,39.76383155
,14.1,2.683545813,0.046052576,32113.18315,1.282512079,40.64754583
,14.4,2.0068704,0.047080065,33778.65338,1.252412354,41.61069989
,14.7,2.604050715,0.048024105,35074.06795,1.239761683,42.62206801
,15,2.145370208,0.049037314,34949.12896,1.265499204,43.36059573
,15.3,2.396005186,0.050004056,34363.18622,1.305632218,44.10898602
,15.6,2.11829373,0.05100541,33519.24901,1.354489844,44.78615248
,15.9,2.320254273,0.051975341,32356.01631,1.417306749,45.46879836
,16.2,2.440674736,0.052950613,31785.16843,1.456567314,46.00132777
,16.5,2.507428514,0.0539294,31695.15347,1.479251197,46.63466527
,16.8,2.510115087,0.054912385,32422.70534,1.471835311,47.40606563
,17.1,2.877235885,0.055871495,33705.08817,1.443480423,48.20212082
,17.4,2.310805993,0.056891762,34766.7966,1.425158868,49.00803619
,17.7,2.644645132,0.057853052,35365.61605,1.425158842,49.8243625
,18,2.277489203,0.058860265,34885.86714,1.460493389,50.42592281
,18.3,2.954545506,0.059799071,34235.99254,1.503679965,51.01981453
,18.6,2.544955462,0.060809063,33722.57554,1.541631889,51.57206644
,18.9,2.752740293,0.061778611,33680.81228,1.559081016,52.10350041
,19.2,2.747522471,0.062762113,33709.20823,1.576093932,52.69191236
,19.5,2.963627716,0.063731116,33543.16098,1.599650258,53.20691017
,19.8,3.017484848,0.064710747,33324.7967,1.623206598,53.66383347
,20.1,3.337179268,0.065672963,33078.37992,1.6480716,54.12185302
,20.4,3.04657118,0.066675158,33152.6162,1.658977342,54.59849924
,20.7,3.586340598,0.067622957,33775.074,1.645454207,55.11021031
,21,3.184238941,0.068632456,35660.7152,1.585690927,55.9374928
,21.3,3.61501091,0.069587395,38328.85449,1.50586106,56.90283982
,21.6,3.088103014,0.07060507,41028.77159,1.436936987,57.95255723
,21.9,3.472280656,0.071563062,41872.57626,1.430393528,58.8006602
,22.2,2.937052339,0.072581283,40350.84786,1.496700318,59.37044367
,22.5,4.090036397,0.07348891,37312.97286,1.618844222,59.61369981
,22.8,4.020751376,0.074476606,35453.27247,1.701727658,59.75724144
,23.1,4.153652431,0.075451198,35924.04787,1.692130617,60.27881368
,23.4,3.931270257,0.076458401,39250.88494,1.580456124,61.31757411
,23.7,4.012580311,0.077464214,43273.70304,1.466164232,62.46043044
,24,3.637098168,0.078508609,46751.15573,1.389388033,63.75449785
,24.3,3.925582207,0.079528321,47839.23476,1.381099668,64.7757274
,24.6,3.89788794,0.080584531,47104.23703,1.419924014,65.59314889
,24.9,4.287876091,0.081628745,45750.71153,1.477942383,66.34592258
,25.2,4.236879646,0.082718032,44757.19481,1.523746388,66.97816397
,25.5,4.479591288,0.083804301,44023.17112,1.561262024,67.60273598
,25.8,4.507633565,0.084921278,45053.59809,1.545121566,68.51000818
,26.1,4.738691329,0.086041615,46194.81373,1.527236176,69.43809989
,26.4,4.322418011,0.08722176,47494.35258,1.507169698,70.39796671
,26.7,4.867149921,0.088356226,48002.94232,1.508478338,71.19237881
,27,4.351026059,0.089577897,48510.35122,1.512840668,72.13033068
,27.3,4.80921998,0.090753704,49007.21978,1.516766687,73.01897624
,27.6,4.551855315,0.091994419,49400.01033,1.523746366,73.89775858
,27.9,5.287945306,0.093188444,49373.36162,1.540322989,74.64505449
,28.2,4.684445482,0.094488896,48935.77133,1.568677898,75.3868687
,28.5,5.031966092,0.095746076,48850.56287,1.585690782,76.12430219
,28.8,4.959302649,0.097050175,49204.84058,1.590925532,76.98664876
,29.1,5.246078033,0.098350278,50195.94319,1.577402423,77.89063435
,29.4,4.762379831,0.099720621,50927.66159,1.573040179,78.77051199
,29.7,4.992570029,0.101064479,51125.87137,1.581764735,79.47616864
,30,5.017242699,0.10244238,50888.1303,1.605757296,80.23551607
,30.3,5.254082651,0.103827173,50741.87949,1.624515108,80.9203537
,30.6,5.525865001,0.105230695,51278.18306,1.623642624,81.70052075
,30.9,5.393271802,0.106681967,52219.90585,1.612736925,82.61546282
,31.2,5.334310793,0.108150328,53189.09152,1.601831217,83.50520305
,31.5,5.545759793,0.10962286,53843.66338,1.600086285,84.36535893
,31.8,5.400675472,0.111140998,54608.38025,1.594415328,85.20359922
,32.1,5.608373101,0.112658967,55865.55659,1.577620512,86.26044034
,32.4,5.606392593,0.114213823,57200.94409,1.559953257,87.36439771
,32.7,5.463793349,0.115801303,58212.5998,1.548611327,88.29029719
,33,5.587027567,0.117395256,58755.43477,1.552101146,89.32905839
,33.3,5.971102974,0.11899613,58602.80524,1.571295169,90.21332105
,33.6,5.828076217,0.120655956,58351.65795,1.591361695,91.03293377
,33.9,6.382296253,0.122295042,58286.85841,1.60793833,91.93144153
,34.2,5.769990128,0.124035793,58555.34582,1.614481814,92.80474415
,34.5,6.127840276,0.125738728,59155.75647,1.613609325,93.71859168
,34.8,5.655724907,0.127522051,59862.5786,1.609683311,94.58641608
,35.1,6.530264486,0.129243494,61169.87273,1.593979007,95.66353008
,35.4,5.656680652,0.131106326,62418.55692,1.581764686,96.7954266
,35.7,6.642705178,0.132874624,63413.86211,1.573912487,97.79255221
,36,6.724296321,0.134729206,63682.21745,1.585254421,98.84555802
,36.3,7.389976131,0.136573321,63878.54143,1.596160076,99.78570434
,36.6,6.987310207,0.138515964,64179.9638,1.604012225,100.7521453
,36.9,7.645076507,0.140417886,65295.46457,1.594415141,101.9070566
,37.2,7.216192066,0.142420237,66500.8239,1.580455867,102.9217101
,37.5,7.754551033,0.144389022,68278.44975,1.559953081,104.3374069
,37.8,7.369755243,0.14644854,69502.43159,1.549047403,105.5032725
,38.1,7.518293087,0.148504019,70205.47472,1.549919848,106.7107778
,38.4,7.784975874,0.150582799,70468.6276,1.559516852,107.8415817
,38.7,7.68555543,0.152717103,70335.45006,1.575221087,108.7839172
,39,7.314884357,0.15490142,70416.82648,1.59005289,109.9223894
,39.3,8.091593227,0.157043042,70795.14047,1.598777391,111.0499079
,39.6,7.755857484,0.159290605,71177.58265,1.607065763,112.1368801
,39.9,8.094069936,0.161527586,71409.58734,1.617535217,113.1372914
,40.2,8.159367407,0.16381644,71362.63545,1.633675666,114.1344144
,40.5,8.349465595,0.16613165,71217.45332,1.648507418,114.9397836
,40.8,8.44387346,0.168488129,71425.08377,1.657231979,116.0037468
,41.1,8.905205929,0.170856026,72228.99509,1.651560967,117.0644242
,41.4,9.120248441,0.173275976,73685.67133,1.63411181,118.2806956
,41.7,9.098153322,0.175748248,75289.87013,1.615790217,119.4334133
,42,8.885514798,0.178270338,76926.3946,1.601394698,120.8140445
,42.3,9.428363814,0.180780692,77888.79235,1.597468594,121.9415623
,42.6,9.184927663,0.183380932,78382.29166,1.603139586,123.1501622
,42.9,9.617102894,0.185975798,78972.98129,1.605756919,124.2941158
,43.2,9.180620658,0.188667302,79268.01866,1.615353985,125.5049062
,43.5,9.476328421,0.191350945,79537.23972,1.625823442,126.6729657
,43.8,9.562355291,0.19408906,79624.81063,1.637601603,127.6887164
,44.1,9.893827759,0.196852557,79901.28634,1.647198599,128.822808
,44.4,9.664497697,0.199694826,80413.09832,1.651124677,129.9262168
,44.7,9.832044562,0.202553756,80668.38875,1.658104317,130.8948511
,45,9.560266708,0.205484889,80240.33327,1.679479537,131.8930688
,45.3,10.30856458,0.208392774,79850.2927,1.698673519,132.7970565
,45.6,9.839578893,0.211425195,79858.00464,1.709579275,133.7185718
,45.9,10.50715446,0.214428254,80573.06502,1.705653156,134.6850163
,46.2,9.997384293,0.217554331,81523.09849,1.699109779,135.8026688
,46.5,10.23228365,0.220678446,82267.10147,1.694747473,136.7493886
,46.8,10.26166128,0.223863305,82843.38502,1.69692861,137.8944365
,47.1,10.5955584,0.227076239,83031.93855,1.704780697,138.8597843
,47.4,10.41524622,0.230371755,83167.20778,1.712196592,139.6881627
,47.7,10.99374784,0.23366696,82875.1609,1.729209451,140.5735225
,48,10.75434489,0.237066042,82128.13483,1.753638263,141.3317733
,48.3,11.42809914,0.240456209,81732.56562,1.76934242,141.9333369
,48.6,11.33054298,0.243948234,82065.24021,1.772396032,142.7321306
,48.9,11.49923164,0.2474755,83690.35654,1.751020824,143.7380202
,49.2,11.39458625,0.251074187,85693.95487,1.72528336,144.9389503
,49.5,11.92103555,0.254685553,87234.8174,1.709579086,146.1442658
,49.8,11.62458736,0.258405673,87746.99999,1.711324028,147.1227601
,50.1,12.60780972,0.262097534,88123.41997,1.716122448,148.1516635
,50.4,12.13827914,0.265941079,89011.66996,1.71176021,149.2857521
,50.7,12.79407517,0.269768286,89946.33737,1.705216722,150.2982182
,51,12.37860887,0.273724095,91399.29232,1.692566139,151.6109126
,51.3,12.87879448,0.277679207,92842.27871,1.680351698,152.913749
,51.6,12.60101203,0.281745346,94025.05258,1.673372071,154.1448112
,51.9,13.00674167,0.285827945,95054.77197,1.670318435,155.444908
,52.2,13.0068414,0.289999033,95300.87384,1.680351689,156.635977
,52.5,13.88140647,0.294175243,95926.44696,1.682532749,157.8511559
,52.8,13.82116319,0.29847624,96578.91022,1.682968984,159.0389375
,53.1,14.49393785,0.302794003,97534.07306,1.677734181,160.222339
,53.4,14.31302788,0.30723335,98432.17548,1.675989286,161.5744811
,53.7,14.79607609,0.311696056,98908.65447,1.680787753,162.6877546
,54,14.27026369,0.316292584,99516.80061,1.685150086,163.9894911
,54.3,14.80362864,0.320888785,100628.4882,1.680787753,165.3504021
,54.6,14.76495425,0.325592149,101812.2459,1.674680561,166.7529488
,54.9,15.51337946,0.330314801,102731.613,1.67249935,168.0985202
,55.2,14.84066712,0.335202229,103268.786,1.676861697,169.409022
,55.5,15.4230771,0.340080668,103222.7256,1.689948493,170.6329656
,55.8,15.09272624,0.345093045,102740.5499,1.708270114,171.6191298
,56.1,15.54448202,0.350129433,102454.209,1.723974291,172.7236374
,56.4,15.54775553,0.355271566,102191.7825,1.738806054,173.7262397
,56.7,16.17005527,0.360450534,102775.2451,1.739242223,174.7398015
,57,15.70070465,0.365779742,103577.3531,1.738369812,175.958262
,57.3,16.74399194,0.37108968,104738.5078,1.731826288,177.2380909
,57.6,16.056621,0.3765941,105493.3618,1.731390127,178.4357311
,57.9,16.57403236,0.382102061,105378.179,1.743168241,179.4054629
,58.2,16.56974071,0.387727775,105135.0556,1.756691319,180.3598524
,58.5,17.32592108,0.393388275,105526.7493,1.7606173,181.429298
,58.8,17.3066256,0.399185445,107478.9728,1.740550802,182.7211752
,59.1,18.23916796,0.405027268,109883.18,1.716121931,184.2628856
,59.4,18.04844718,0.410992072,111163.4939,1.707397385,185.5131239
,59.7,18.69391012,0.417011704,111772.5638,1.710014693,186.8871847
,60,18.56223229,0.423173634,112323.4667,1.713940761,188.2349438
,60.3,18.94058079,0.429395073,113449.4139,1.709578443,189.6331097
,60.6,18.71318854,0.43575028,114362.0808,1.706961096,190.8548589
,60.9,19.34028711,0.442145081,114525.3702,1.716994286,192.2453556
,61.2,19.42903978,0.448672217,114360.8081,1.730081125,193.4177978
,61.5,19.77071722,0.455281318,114824.7266,1.73313469,194.5146347
,61.8,19.38184685,0.462038376,116798.8396,1.719175425,196.1352321
,62.1,19.85495468,0.468840607,118717.9957,1.703907393,197.5509301
,62.4,19.72648056,0.475785326,120533.2286,1.692129244,199.1770078
,62.7,20.31520905,0.482787675,121320.1484,1.692565418,200.5346324
,63,20.04275838,0.489952526,121181.4171,1.706524747,201.9722418
,63.3,20.60233145,0.497170542,121024.8539,1.71961154,203.2761751
,63.6,20.41970669,0.504546556,120578.075,1.735315773,204.4705304
,63.9,21.07243331,0.511978685,121230.5856,1.736188167,205.7459752
,64.2,21.43059955,0.519542838,122227.1486,1.733570764,207.1156524
,64.5,22.27049928,0.527189393,123668.8317,1.726591033,208.6376391
,64.8,22.16518223,0.53501395,124269.8547,1.729208412,209.9251333
,65.1,22.5840321,0.542922109,125284.0137,1.727899688,211.4087675
,65.4,22.27482731,0.55099757,126297.1397,1.726154805,212.8617168
,65.7,22.48230048,0.559160901,127576.0605,1.720483825,214.268648
,66,22.38689112,0.567467941,128592.0486,1.720047606,215.8651404
,66.3,23.08522872,0.575848222,128519.5087,1.73051701,217.0321076
,66.6,22.78634531,0.584420884,128349.2344,1.744040113,218.303164
,66.9,23.34985158,0.593066178,128784.0036,1.748402337,219.5271086
,67.2,23.78353868,0.601850848,129818.3654,1.746221162,220.9899243
,67.5,24.10030294,0.610776013,130815.5777,1.74360376,222.4691748
,67.8,24.24689346,0.619847131,130640.4214,1.75450945,223.646001
,68.1,24.62976172,0.629039874,129799.0136,1.774139677,224.6639451
,68.4,24.33366274,0.638415947,129386.6477,1.78940769,225.6939394
,68.7,25.08924067,0.647864463,129423.6172,1.796823493,226.6077909
,69,25.0992874,0.657505164,130440.3547,1.793333668,227.8941899
,69.3,26.74302288,0.667183248,131981.2822,1.782864031,229.2605879
,69.6,26.33658692,0.677142979,133618.9536,1.770213459,230.5415057
,69.9,26.90902285,0.68718861,136189.1216,1.749710685,232.3330438
,70.2,26.66561881,0.697439873,138134.6789,1.735751411,233.8462596
,70.5,27.16561844,0.70779693,139944.6165,1.726590575,235.5545209
,70.8,27.12726293,0.718345987,141114.0154,1.724409439,237.1082806
,71.1,28.0977313,0.728987821,141650.9491,1.730516538,238.6423225
,71.4,28.14960126,0.739851287,142683.2297,1.730080306,240.2333379
,71.7,28.48184279,0.750860512,143957.7876,1.725717995,241.7366949
,72,28.65597017,0.762046463,145368.0836,1.721355698,243.5501466
,72.3,29.24068265,0.77337448,146231.5079,1.722664327,245.2156745
,72.6,29.1177176,0.784919534,145637.9834,1.739677231,246.6390412
,72.9,30.09509838,0.796566358,144977.4577,1.755817572,247.8147766
,73.2,30.24873108,0.808443624,144023.1822,1.775447816,248.9817409
,73.5,30.45308975,0.820496823,144864.0502,1.775011568,250.4040125
,73.8,30.39865489,0.832749219,145707.6306,1.77370289,251.727667
,74.1,30.84258284,0.845153782,147052.9519,1.768031883,253.2781414
,74.4,31.2972975,0.857745158,148003.3447,1.766286928,254.7891709
,74.7,32.01157852,0.870509537,149319.6739,1.760179667,256.2158293
,75,32.28151927,0.88349634,151308.0202,1.749273943,258.0007925
,75.3,32.69204368,0.89666984,154089.9193,1.730516104,259.7704154
,75.6,32.66155507,0.910071497,155802.1865,1.725281372,261.6265997
,75.9,33.28085775,0.923632843,156588.2365,1.728334909,263.293224
,76.2,33.45581834,0.937428331,157079.3342,1.734878311,264.970804
,76.5,34.17822828,0.951396286,158808.3413,1.729207279,266.8554821
,76.8,34.64183249,0.965640395,162013.1165,1.709140753,268.9045207
,77.1,35.26766558,0.979993039,166268.7518,1.682094568,271.4192484
,77.4,35.34347788,0.994647365,169579.8085,1.664645448,273.9306866
,77.7,36.31702635,1.00946398,170966.3418,1.663336674,276.018078
,78,36.68065377,1.024544607,170029.5703,1.683839348,278.0397231
,78.3,37.13660142,1.03984692,167923.7571,1.713502796,279.6449852
,78.6,37.18647673,1.055407236,165935.3965,1.740112688,280.821811
,78.9,37.7713165,1.071167164,164784.8422,1.761051565,282.3569474
,79.2,37.73042421,1.087206733,166554.6881,1.754508153,284.1999827
,79.5,38.2078544,1.103454328,168889.3628,1.742729957,285.9170112
,79.8,38.96647509,1.119928913,172474.6927,1.722663407,288.3583276
,80.1,39.92724191,1.13663901,174268.0873,1.71786481,290.4281881
,80.4,40.42535434,1.153631997,175875.8337,1.713066258,292.319441
,80.7,40.88099195,1.170884294,177499.3093,1.708703938,294.2819147
,81,40.7591524,1.188435162,178325.074,1.713066227,296.4712038
,81.3,41.65651967,1.206183894,178717.6593,1.720482013,298.4621712
,81.6,41.64858483,1.224260497,177306.6395,1.743165853,300.0520909
,81.9,42.25298799,1.24256967,177296.7745,1.752762805,301.6595469
,82.2,42.66764205,1.261168076,178452.7644,1.753198991,303.5409371
,82.5,43.11553304,1.280045234,181056.8647,1.741420803,305.7148898
,82.8,43.39613868,1.299218615,184026.3387,1.726589034,307.8384375
,83.1,44.73422086,1.318611975,186320.9119,1.719609261,310.165802
,83.4,45.01722993,1.338368093,188555.8621,1.713065823,312.4701472
,83.7,46.27242989,1.358359273,190405.8741,1.708703427,314.5980861
,84,46.92976124,1.378691896,191749.6815,1.709575823,316.9364023
,84.3,47.38610616,1.399344969,193116.7969,1.708267094,318.9427074
,84.6,47.39934033,1.420339395,194679.6582,1.706522188,321.2864968
,84.9,48.03156158,1.441610213,196462.5974,1.704340985,323.9217587
,85.2,48.28432167,1.463227371,196788.1033,1.710884377,325.8469776
,85.5,49.10281676,1.485133915,195786.1743,1.729205855,327.7393284
,85.8,49.39416213,1.507406209,194909.0591,1.746873041,329.5631925
,86.1,50.25124089,1.529977762,195593.4548,1.751017119,331.4517082
,86.4,50.6573,1.552919998,197485.5924,1.74578235,333.6289501
,86.7,51.54089467,1.57617741,199745.5997,1.736621488,335.7448326
,87,51.72926445,1.599832178,201973.3977,1.730078059,338.2343583
,87.3,52.60276194,1.623798945,203413.9024,1.730514202,340.5639105
,87.6,53.05394181,1.648155801,204354.6158,1.734876433,342.761972
,87.9,53.04036919,1.67291119,204733.169,1.742292301,344.7430703
,88.2,54.16122282,1.697965735,203347.9314,1.761486198,346.4283313
,88.5,55.81535338,1.723363775,201733.0421,1.781552493,347.9842985
,88.8,55.97924049,1.749243985,201272.1836,1.792894388,349.4832747
,89.1,56.74254976,1.775475481,202682.7212,1.791149403,351.3263172
,89.4,57.25909635,1.802119715,205573.2145,1.779371215,353.4805498
,89.7,57.88041586,1.829159604,208705.2218,1.764975652,355.5832821
,90,58.2940767,1.8566214,213516.5373,1.740546884,358.411395
,90.3,59.0001335,1.884477793,218270.1867,1.71742677,361.3271672
,90.6,59.03716393,1.912799109,221269.527,1.705648631,363.8101181
,90.9,60.11999955,1.941479096,221853.1402,1.712628164,366.5461928
,91.2,60.33744555,1.970649784,221523.3858,1.723533824,368.5272956
,91.5,61.51915473,2.000197684,221489.5891,1.734439391,370.7790551
,91.8,62.11004524,2.030230707,224269.7201,1.727895927,373.5786812
,92.1,63.29410736,2.060678463,227177.3754,1.720479951,376.311471
,92.4,63.8207855,2.091629905,230279.4681,1.710010449,378.843735
,92.7,65.16694764,2.12299455,233167.29,1.70259446,381.7671852
,93,65.57948682,2.154894572,234581.5987,1.705211783,384.6654268
,93.3,66.58602507,2.187237459,235326.1678,1.711755094,387.3532894
,93.6,66.86029148,2.220117304,234122.8933,1.728767924,389.2642665
,93.9,68.14873413,2.253427077,234123.7157,1.738364795,391.5171233
,94.2,68.21233575,2.287320954,235661.973,1.737928563,394.0712983
,94.5,69.44071011,2.321650152,238555.402,1.729203903,396.9257165
,94.8,69.83862716,2.356554267,240978.984,1.723532914,399.625629
,95.1,70.63667099,2.391959107,240304.9183,1.737928328,402.0198315
,95.4,71.63847916,2.427885699,237311.3876,1.766282984,403.8245294
,95.7,72.48211364,2.464365735,235919.5386,1.783731979,405.4484267
,96,73.31900419,2.50139721,236251.5851,1.791147753,407.5708894
,96.3,74.30640473,2.538978193,239991.6312,1.776752167,410.1239768
,96.6,74.45002802,2.577182629,244914.9134,1.754940808,413.0528959
,96.9,75.73594826,2.615888947,248820.3448,1.740545196,415.8875926
,97.2,75.95676637,2.655250448,251001.1131,1.737491587,418.7080362
,97.5,77.55368133,2.695115745,250885.4204,1.747088422,420.7899618
,97.8,78.52064744,2.735625202,251253.8414,1.755812864,423.3474354
,98.1,79.31029208,2.776758264,252870.7348,1.75537656,425.9333935
,98.4,80.36525812,2.818495058,256053.8332,1.745343241,428.7680925
,98.7,81.92101094,2.860828469,258815.1656,1.737054782,431.4154208
,99,82.23526123,2.903883176,260735.9424,1.736182298,434.3618761
,99.3,83.40224717,2.947531709,263274.5871,1.732256145,437.2743699
,99.6,84.00500648,2.991876839,266954.5582,1.722659101,440.485997
,99.9,84.73662518,3.036883221,271517.726,1.708263549,443.8356877
,100.2,85.63870353,3.082558419,274406.4049,1.703901203,447.1974366
,100.5,87.38269443,3.128868191,275281.9675,1.710008205,450.2677263
,100.8,87.92136717,3.175957568,274079.4276,1.726148539,452.6937056
,101.1,88.95332489,3.223727758,274360.5717,1.735309192,455.5174456
,101.4,89.68355415,3.272239569,275675.9767,1.738798937,458.4354157
,101.7,91.62344963,3.321404586,278199.3821,1.734436479,461.1287745
,102,92.37923733,3.371390723,279274.5153,1.73967113,464.1738517
,102.3,93.45565544,3.422110875,279829.6514,1.746214415,466.8989758
,102.6,94.17833575,3.473620557,279668.2325,1.756247558,469.5200012
,102.9,95.92721051,3.525840898,281870.6016,1.752757574,472.2812921
,103.2,96.75572636,3.57891085,286864.6976,1.736180891,475.7811052
,103.5,98.0941536,3.632749028,292841.4589,1.716114351,479.5833468
,103.8,98.98980759,3.687429988,295370.6152,1.713933133,482.8793537
,104.1,100.0941716,3.742923167,292676.8344,1.737925473,485.456553
,104.4,101.1455679,3.799258385,290696.323,1.757555552,487.9964996
,104.7,102.9306855,3.856396403,288958.6747,1.774131972,490.0291236
,105,103.4692742,3.914480042,293433.6944,1.76017268,493.4599024
,105.3,105.3252541,3.973354253,297957.2998,1.747085713,496.9367171
,105.6,106.0341294,4.033193886,302398.9553,1.735307539,500.4463923
,105.9,107.39601,4.093894598,305530.2988,1.730072693,503.6865195
,106.2,108.1848873,4.155550081,306694.7496,1.73530733,506.9014415
,106.5,109.5352413,4.218100205,309450.6774,1.732689843,510.3640051
,106.8,110.5022921,4.281620603,309957.5693,1.739669365,513.2513027
,107.1,112.3657098,4.346041543,311122.773,1.743595218,516.3862468
,107.4,113.0832582,4.411511323,310946.3129,1.753628344,519.3776372
,107.7,115.1260842,4.477879544,312574.951,1.753628144,522.1641388
,108,116.4540311,4.545297749,314733.0145,1.753191788,525.4426229
,108.3,117.7036047,4.613739691,318823.2429,1.744030922,529.0235266
,108.6,118.798255,4.683225754,320312.6384,1.747084396,532.2428373
,108.9,120.9103188,4.753694606,324068.8143,1.7387959,535.6725415
,109.2,121.963031,4.825298088,328521.0789,1.728762606,539.6183305
,109.5,123.5505704,4.897947982,333623.1887,1.716111907,543.7810796
,109.8,124.7668472,4.971719878,336510.6877,1.712621984,547.5044355
,110.1,126.9114988,5.046545382,335541.6501,1.726144773,550.8125132
,110.4,127.9901325,5.122571826,335561.4523,1.736177857,554.1359222
,110.7,129.8390487,5.19969605,334860.8487,1.750136895,557.3179867
,111,131.0837216,5.278025153,338053.765,1.745774517,560.6194823
,111.3,132.9181196,5.357498768,342772.9339,1.735304927,564.6452703
,111.6,133.9868106,5.438495087,350603.2673,1.712184874,569.3526031
,111.9,135.5138456,5.52013797,354865.6896,1.704768895,573.4704276
,112.2,137.4583223,5.603262726,356577.6793,1.709567188,577.4918401
,112.5,139.1571032,5.687946511,355029.418,1.728324714,580.924828
,112.8,140.2675223,5.77337715,353548.4149,1.745337393,583.9162306
,113.1,142.074104,5.860340596,353023.703,1.757987748,587.1256894
,113.4,143.3646148,5.948652042,353902.4262,1.763658549,590.4052746
,113.7,145.4553311,6.038245348,356838.412,1.758859865,593.7133564
,114,146.5548783,6.129257599,360600.611,1.751880154,597.8377563
,114.3,148.7183796,6.221574573,362043.9242,1.754061067,601.3014366
,114.6,150.883323,6.315286482,362508.6018,1.76147668,604.7081436
,114.9,152.6453363,6.410440916,363721.3598,1.765838755,607.8606256
,115.2,154.2731632,6.507041715,367294.068,1.761476344,611.5182504
,115.5,156.2027866,6.605082046,372893.6458,1.748825631,615.625128
,115.8,157.9366463,6.704616113,379860.6186,1.730940242,620.0103297
,116.1,160.0305379,6.805628799,384980.5256,1.721779317,624.6607007
,116.4,161.6033332,6.908201643,387523.3655,1.722651615,628.9889203
,116.7,163.5935635,7.012295334,387763.7089,1.730939692,632.4723238
,117,165.5577506,7.117962751,389119.0062,1.736174197,636.660296
,117.3,167.357773,7.225237318,392032.0813,1.734865347,640.8668875
,117.6,169.262374,7.334125297,397165.7177,1.72614067,645.5337012
,117.9,171.4254758,7.444641525,399307.4054,1.728757803,649.5923745
,118.2,173.3578385,7.556842633,401571.9594,1.732247421,653.9293685
,118.5,175.3065714,7.670743081,403378.0938,1.736609462,658.0263922
,118.8,176.8918478,7.786388909,406658.4465,1.73399197,662.1979225
,119.1,179.0850628,7.903741863,412439.4755,1.722649916,667.2219528
,119.4,180.9081569,8.022892501,416732.1675,1.715233935,671.5534661
,119.7,183.7256604,8.143777714,421036.1536,1.710871414,676.7079031
,120,185.9396491,8.266529253,421131.5373,1.723085482,681.22351
,120.3,188.2452824,8.391129496,419957.1258,1.738571212,684.778697
,120.6,190.2011622,8.51763533,418978.7732,1.752312081,688.3119681
,120.9,192.4637582,8.646032289,420601.4741,1.756455986,692.4342014
,121.2,194.5134611,8.776383346,421842.5863,1.760599911,696.1915551
,121.5,196.5420499,8.908705178,422852.3343,1.766270621,700.0880617
,121.8,198.7150943,9.043016558,424210.3374,1.770632644,703.7654294
,122.1,200.9285855,9.179354784,431123.5511,1.756237037,708.5056636
,122.4,203.1646299,9.317751176,440588.9778,1.733989405,713.9438971
,122.7,205.7215061,9.458217787,449776.533,1.713050418,719.2298208
,123,208.4161619,9.600797569,455166.2191,1.707379251,725.0373304
,123.3,211.2777133,9.745520642,454687.0844,1.720465683,729.6789647
,123.6,213.576047,9.892467321,450768.271,1.743149082,733.2106038
,123.9,216.3803189,10.041601,446899.2552,1.765832425,736.7488213
,124.2,218.7985854,10.19301348,445269.1542,1.778918885,739.8388787
,124.5,221.5663573,10.34669059,449680.4671,1.772811481,744.1978102
,124.8,223.6993357,10.50273156,456934.7921,1.758852124,749.5078444
,125.1,226.6182096,10.66107222,463823.8881,1.744892693,754.2393345
,125.4,228.9139277,10.82184429,470024.6832,1.735295559,759.6436083
,125.7,231.5820094,10.98502083,475097.4406,1.727879506,764.4989125
,126,234.1639996,11.15066826,479933.2833,1.72438947,770.2286297
,126.3,236.594994,11.31882835,484416.78,1.721771896,775.7085072
,126.6,239.2419122,11.48951462,487151.5381,1.724388976,780.9429508
,126.9,242.294451,11.66275315,487587.2384,1.732676912,785.558298
,127.2,245.1402297,11.83862278,485632.7557,1.747944429,789.9961405
,127.5,248.1578159,12.01713792,483117.5295,1.764520592,794.0022531
,127.8,251.0310316,12.19835974,483346.8403,1.772808535,797.8955099
End Of Loading Marker,128.058,253.9899839,12.35636689,484270.2763,1.778479131,801.4808575
,128.4,255.9766347,12.35932342,490392.5174,1.769754485,806.3854709
,128.7,257.7138437,12.35921015,495020.5038,1.766700757,811.4555259
,129,258.3178281,12.35917113,500429.0796,1.75972114,816.1058958
,129.3,259.3902452,12.35910142,506434.1586,1.752305254,821.4224799
,129.6,259.698859,12.35908174,512562.4847,1.744453222,827.0623022
,129.9,260.8128774,12.3590093,518246.1965,1.737909779,832.5399645
,130.2,261.0000149,12.35899758,521823.0052,1.738345984,837.9310488
,130.5,261.4409213,12.35896924,524871.1085,1.740963276,843.2673435
,130.8,261.5440237,12.35896303,526748.0594,1.745761712,847.9100317
,131.1,261.7910673,12.35894738,530643.6233,1.745325466,853.2824821
,131.4,262.4699342,12.35890345,532478.6131,1.750123846,858.4368973
,131.7,263.0239966,12.3588677,534074.2025,1.754049793,862.856055
,132,262.8525292,12.35887947,529794.9697,1.775424703,867.1513847
,132.3,263.1519906,12.35886039,521659.3745,1.806396456,870.0003292
,132.6,263.3998662,12.3588447,510934.8105,1.844783991,871.6943652
,132.9,264.0046824,12.35880562,503706.119,1.872702154,873.3730594
,133.2,263.9239063,12.35881145,502561.2243,1.880990386,875.2292593
,133.5,264.0270087,12.35880523,507558.973,1.870521042,878.4869125
,133.8,264.2565796,12.35879074,511982.6427,1.861796574,881.7314327
,134.1,264.3214086,12.35878703,516207.9871,1.85438079,885.3232855
,134.4,264.3205073,12.35878763,520468.8728,1.847401235,889.0082899
,134.7,264.7497653,12.35876005,524319.993,1.841730302,892.2966341
,135,264.7297273,12.3587619,531425.6735,1.828643638,896.8867233
,135.3,264.7928923,12.3587583,534295.4646,1.827334965,900.7700485
,135.6,265.2937048,12.35872604,533121.0053,1.837368032,903.7866592
,135.9,265.2915555,12.35872672,529258.6592,1.854816915,906.1403194
,136.2,265.39965,12.35872018,523487.7373,1.878372912,908.018434
,136.5,265.6387892,12.35870505,521715.9448,1.887969762,909.731093
,136.8,265.4997711,12.3587147,518476.937,1.901928901,911.4459338
,137.1,266.1357883,12.35867358,517479.2321,1.908472158,913.2133904
,137.4,265.7746183,12.35869778,518223.8521,1.909780875,914.956715
,137.7,265.8061661,12.35869625,518531.0606,1.913270643,916.8041456
,138,266.1027154,12.35867736,521630.9588,1.908035948,918.8970317
,138.9,265.8697361,12.18210732,1.7977E+308,1.721769092,0
,139.2,265.7921948,11.9968819,1.7977E+308,1.358395993,0
,139.5,265.2208441,11.81168883,1.7977E+308,0.834929358,0
,139.8,264.9615044,11.62647532,1.7977E+308,0.365336128,0
,140.1,264.5295185,11.44127312,1.7977E+308,0.130430454,0
,140.4,264.2115207,11.25606346,1.7977E+308,0.061507339,0
,140.7,263.7017401,11.07086635,1.7977E+308,0.018757558,0
,141,263.4374081,10.88565317,1.7977E+308,0.036642672,0
,141.3,263.110674,10.70044408,1.7977E+308,0.046675785,0
,141.6,262.7211216,10.5152391,1.7977E+308,0.043186008,0
,141.9,262.0794642,10.33005063,1.7977E+308,0.027918228,0
,142.2,261.7402496,10.14484235,1.7977E+308,0.009596891,0
,142.5,261.6939094,9.95961489,1.7977E+308,0.004362223,0
,142.8,261.2040974,9.774416478,1.7977E+308,0.008724447,0
,143.1,260.9131405,9.58920504,1.7977E+308,0.013959115,0
,143.4,260.2477702,9.404018129,1.7977E+308,0.018757562,0
,143.7,260.2538479,9.218787231,1.7977E+308,0.030099343,0
,144,259.6433915,9.033596723,1.7977E+308,0.030099345,0
,144.3,259.1435951,8.848398965,1.7977E+308,0.022683565,0
,144.6,258.8576303,8.663187199,1.7977E+308,0.012214227,0
,144.9,258.4243962,8.477985081,1.7977E+308,0.010033116,0
,145.2,258.1750407,8.292770917,1.7977E+308,0.006107114,0
,145.5,258.1029076,8.107545144,1.7977E+308,0.013959118,0
,145.8,257.3967677,7.922360903,1.7977E+308,0.020502455,0
,146.1,257.1257794,7.737148156,1.7977E+308,0.017885121,0
,146.4,256.8106936,7.551938298,1.7977E+308,0.017012676,0
,146.7,256.2967525,7.366741467,1.7977E+308,0.014831564,0
,147,255.7853076,7.181544473,1.7977E+308,0.026173349,0
,147.3,255.3587297,6.996341918,1.7977E+308,0.038823803,0
,147.6,254.9280897,6.810522193,1.7977E+308,0.044494696,0
,147.9,254.6912146,6.625307212,1.7977E+308,0.039260027,0
,148.2,254.1696871,6.440728314,1.7977E+308,0.029663132,0
,148.5,253.9486206,6.255512297,1.7977E+308,0.018757569,0
,148.8,253.5536597,6.070307672,1.7977E+308,0.016576457,0
,149.1,252.9698281,5.885115419,1.7977E+308,0.016140235,0
,149.4,252.6098125,5.699908504,1.7977E+308,0.026609577,0
,149.7,252.3429843,5.514695485,1.7977E+308,0.034461584,0
,150,251.5969067,5.329513861,1.7977E+308,0.030535582,0
,150.3,251.5680391,5.144285253,1.7977E+308,0.014395346,0
,150.6,250.7853521,4.959106027,1.7977E+308,0.00828823,0
,150.9,250.6707854,4.773883033,1.7977E+308,0.022683577,0
,151.2,250.1019301,4.5886898,1.7977E+308,0.03140803,0
,151.5,249.5430592,4.403495912,1.7977E+308,0.033152922,0
,151.8,249.1106569,4.218293739,1.7977E+308,0.036206481,0
,152.1,248.4311416,4.033107754,1.7977E+308,0.034025369,0
,152.4,248.1318641,3.847896861,1.7977E+308,0.04056871,0
,152.7,247.486462,3.662708642,1.7977E+308,0.045367162,0
,153,247.1405908,3.4775008,1.7977E+308,0.041441158,0
,153.3,246.3911848,3.292319394,1.7977E+308,0.027482032,0
,153.6,246.3369403,3.107092449,1.7977E+308,0.012650459,0
,153.9,245.7893017,2.921897825,1.7977E+308,0.010033123,0
,154.2,245.2437431,2.736703065,1.7977E+308,0.020938693,0
,154.5,244.6407744,2.551512066,1.7977E+308,0.022247362,0
,154.8,244.2241806,2.366308858,1.7977E+308,0.015704021,0
,155.1,243.8050906,2.181105813,1.7977E+308,0.012214239,0
,155.4,243.1259911,1.995919801,1.7977E+308,0.015704022,0
,155.7,242.4747645,1.810731963,1.7977E+308,0.023119811,0
,156,242.0398659,1.625529954,1.7977E+308,0.023992257,0
,156.3,241.6153677,1.440327264,1.7977E+308,0.024864703,0
,156.6,240.6808346,1.255157985,1.7977E+308,0.027918265,0
,231.9,240.2271229,1.076884143,1.7977E+308,0.022683593,0
,232.2,239.2555642,0.891717289,1.7977E+308,0.020066257,0
,232.5,238.2989821,0.706549455,1.7977E+308,0.028790718,0
,232.8,237.8732357,0.521346846,1.7977E+308,0.028790719,0
,233.1,236.9108293,0.336179394,1.7977E+308,0.030971835,0
,233.4,235.2678214,0.151056527,1.7977E+308,0.021374931,0
,233.63,233.5694241,0.009157738,1.7977E+308,0.018321371,0
END,,,,,,