File: GB1_test52.csv
Segment,Time On Sample,Displacement Into Surface,Load On Sample,Harmonic Contact Stiffness,Harmonic Displacement,Harmonic Load
Surface Marker,0,0,0,454.3402744,0.345071519,2.251695519
,0.3,0.280467813,0.000966954,7283.350276,0.214633609,2.338257068
,0.6,0.510178924,0.001937237,14858.09989,0.172317631,2.497135842
,0.9,0.463640461,0.002925633,18154.71752,0.152686509,2.658206033
,1.2,0.436239769,0.003912774,20223.50014,0.143961566,2.799553338
,1.5,0.558612942,0.004890094,22538.96438,0.144397812,3.146895193
,1.788,0.476825382,0.005841387,25214.32773,0.147015296,3.59175572
,2.1,0.572874166,0.006858499,26671.74525,0.153559003,3.977447619
,2.4,0.708560781,0.007833628,29694.54631,0.156176485,4.520922566
,2.7,1.078061033,0.008793426,35581.99974,0.153558999,5.360240773
,3,0.756937367,0.009798508,40118.94435,0.154867743,6.092178732
,3.3,0.660474493,0.010788859,39344.81313,0.176680102,6.83069104
,3.6,0.979218049,0.011751986,37593.72266,0.220304815,8.146645544
,3.9,0.807868245,0.012747247,36501.8586,0.256949579,9.216063936
,4.2,1.093328719,0.013712556,36018.33485,0.295339324,10.41587261
,4.5,0.773869207,0.014717529,36994.43339,0.323259148,11.68251975
,4.8,0.93451813,0.015691022,36976.54094,0.366883861,13.2362445
,5.1,0.995733851,0.016671034,36567.41241,0.40832734,14.55548614
,5.4,0.924232767,0.017663027,36696.46808,0.449334575,16.05552077
,5.7,1.001674509,0.018638697,37146.36623,0.485543088,17.5489812
,6,0.791217085,0.019636522,36333.8197,0.536584012,18.95587987
,6.3,0.684353247,0.020627555,34870.46352,0.599839854,20.32333293
,6.6,0.765122778,0.021606286,32459.1972,0.689270521,21.74009318
,6.9,0.825922461,0.022586325,30291.57608,0.778701187,22.93880615
,7.2,0.963273228,0.023561345,27825.97424,0.883836747,24.00165029
,7.5,1.276192242,0.024524854,24778.75028,1.024744563,24.98998608
,7.8,1.202611487,0.025513704,21396.47057,1.190954734,25.47757933
,8.1,1.19642897,0.026498136,17660.28288,1.427400693,25.71096686
,8.4,1.452350707,0.027465382,15826.46671,1.578778434,25.75698705
,8.7,1.150780855,0.028469182,15551.8536,1.625893154,26.0889887
,9,2.02992825,0.029395563,17619.8173,1.501562643,26.98747611
,9.3,1.506609891,0.030413903,20852.77234,1.339278747,28.0897657
,9.6,1.608181344,0.031391269,24960.73476,1.187464733,29.40681585
,9.9,1.215083024,0.032401071,26660.1973,1.153437481,30.45979835
,10.2,1.234278855,0.033383838,25161.28684,1.239814413,31.16215192
,10.5,1.603779101,0.034343637,22592.12685,1.377232243,31.51168562
,10.8,2.047334189,0.03529858,20297.67913,1.526864976,31.72206334
,11.1,2.088164021,0.036279929,19387.64335,1.605825709,31.98174801
,11.4,2.527558714,0.037235145,20270.19538,1.573543382,32.49892619
,11.7,2.269672919,0.038236081,22961.35191,1.447031738,33.39522134
,12,2.479414372,0.039206355,26555.96984,1.305251403,34.38684419
,12.3,2.377126967,0.040197088,30678.39313,1.180920983,35.60527988
,12.6,2.243220638,0.041189894,32610.09663,1.148202453,36.68894251
,12.9,1.73987213,0.042206925,32072.43134,1.192699699,37.47128293
,13.2,2.723445158,0.043126459,30041.9599,1.289982741,38.03996039
,13.5,2.41813098,0.044130505,28448.87603,1.377668435,38.51988369
,13.8,2.858357743,0.045085666,27661.67968,1.436125514,39.06226323
,14.1,2.449866025,0.046096477,28408.28421,1.425219371,39.76461655
,14.4,2.684569784,0.047065114,29895.93969,1.382030888,40.54805336
,14.7,2.54151061,0.048058521,32016.93844,1.320083807,41.50132596
,15,2.963431679,0.049014883,33808.359,1.278640299,42.48637475
,15.3,2.58822304,0.050023511,34441.81831,1.280385317,43.39033985
,15.6,2.990174262,0.050981182,34049.59398,1.318338788,44.20226539
,15.9,2.860428321,0.051973716,33095.01603,1.373742182,44.8640777
,16.2,3.495361072,0.052916111,32832.91656,1.402098197,45.45466894
,16.5,3.05358629,0.053929104,33118.4805,1.415185645,46.26768973
,16.8,2.907198811,0.054922729,33697.05806,1.413004421,46.95579874
,17.1,3.015426872,0.055899659,34159.43003,1.417803132,47.73704432
,17.4,3.08953978,0.056878826,34278.12462,1.433508023,48.51828933
,17.7,2.99474107,0.057869069,34362.49147,1.446595444,49.15928322
,18,3.102969132,0.058845999,34600.60467,1.455756626,49.88902969
,18.3,2.925794806,0.059841642,34479.77486,1.478005244,50.49276907
,18.6,3.292798791,0.060801605,34324.22469,1.505052535,51.1622515
,18.9,3.031584697,0.061802759,33937.01279,1.538643586,51.73969365
,19.2,3.21802799,0.062774561,33508.25219,1.572234598,52.26673284
,19.5,3.359539127,0.063749309,33138.87991,1.601026896,52.72583823
,19.8,4.029419094,0.064689412,32872.1027,1.62632917,53.1926137
,20.1,3.704135089,0.065694767,33240.77399,1.625456705,53.73827991
,20.4,4.094437213,0.066653203,34738.61667,1.579214479,54.45816555
,20.7,3.688441749,0.06766385,37324.19037,1.501998777,55.43444773
,21,3.740920655,0.068644436,40745.79246,1.409950635,56.58714046
,21.3,3.648618179,0.069634515,42196.87904,1.387265793,57.57547617
,21.6,3.934078617,0.070599824,40988.64848,1.445286636,58.30193569
,21.9,4.019007818,0.071582705,37979.52599,1.563509593,58.59668375
,22.2,4.32027471,0.07256585,36422.38697,1.636799079,58.90458008
,22.5,4.121460979,0.073596995,36910.29935,1.63200038,59.45901211
,22.8,4.374878589,0.074613861,40311.97307,1.527301056,60.54486657
,23.1,4.518043,0.075656898,44535.52531,1.416930533,61.82795009
,23.4,4.422815963,0.076724523,47848.34144,1.346694759,63.05734258
,23.7,4.169075152,0.077822222,49206.30034,1.332298625,64.21332249
,24,4.538973385,0.078895229,48101.30916,1.377668295,65.10413983
,24.3,4.474524871,0.080013187,46505.66893,1.43917914,65.85908802
,24.6,4.732087451,0.081126724,45241.16282,1.496763735,66.58664339
,24.9,4.635598625,0.082280464,46147.53637,1.492401272,67.4884176
,25.2,4.920614281,0.083426535,47464.54047,1.474951367,68.48880629
,25.5,4.680586653,0.084624566,48783.58561,1.456629009,69.46508876
,25.8,5.025506228,0.08580203,49469.18302,1.457065229,70.46438183
,26.1,4.599919765,0.08704806,49457.18541,1.474515147,71.34424097
,26.4,5.07921395,0.088253218,49327.62769,1.495891216,72.2854614
,26.7,4.721019829,0.089531851,49155.39491,1.515958612,73.12039639
,27,5.185746698,0.090775508,48695.95752,1.543005892,73.87863226
,27.3,5.360491744,0.092057291,48027.7834,1.575942531,74.5601681
,27.6,5.543970532,0.093357772,47206.51005,1.613896011,75.19951836
,27.9,5.439131579,0.094696781,46844.38587,1.637235239,75.76764696
,28.2,5.450364149,0.09604827,47097.682,1.644215189,76.46342622
,28.5,5.343022486,0.097428206,48294.94026,1.62545658,77.36191307
,28.8,5.390027823,0.098818475,49749.43892,1.599281748,78.28012283
,29.1,5.615510289,0.100218127,51281.03333,1.57179817,79.26078889
,29.4,6.077299191,0.101623518,52779.0151,1.546495792,80.25022122
,29.7,5.523950937,0.103117114,53813.27011,1.536025918,81.25827842
,30,6.0963991,0.104559014,54614.62912,1.532099641,82.26414677
,30.3,5.663694953,0.106088942,54673.15414,1.546059592,83.05963537
,30.6,6.044758317,0.107588254,53971.18049,1.581831813,83.85512588
,30.9,5.922411586,0.109143355,53217.00428,1.618476582,84.53337361
,31.2,6.201122147,0.110695622,52730.29771,1.645960116,85.13601792
,31.5,5.995560268,0.112303166,53769.12147,1.632436479,86.06299316
,31.8,6.493931535,0.113888635,56029.34237,1.58750299,87.16418845
,32.1,6.577092614,0.115525636,58708.0907,1.537770821,88.41111335
,32.4,6.346556797,0.117208028,61131.92162,1.500689842,89.80157578
,32.7,6.198392555,0.118910351,61623.06192,1.505052325,90.7669013
,33,6.366413432,0.120617512,61662.36821,1.521629699,91.80892688
,33.3,6.0243671,0.122384091,61685.29116,1.538207117,92.82465495
,33.6,6.531034927,0.124121312,62308.31205,1.542133298,93.97187022
,33.9,6.310463398,0.125932853,63278.26884,1.5373346,95.12127572
,34.2,6.659860192,0.127733945,63971.5244,1.537770818,96.21260928
,34.5,6.709704939,0.129582371,64425.25212,1.543005779,97.26230541
,34.8,6.892677537,0.131449956,64252.78059,1.561764387,98.24187536
,35.1,6.513993787,0.133382811,64084.68441,1.58095929,99.20720056
,35.4,6.937427507,0.135291679,63753.94416,1.60495284,100.1747181
,35.7,6.889069023,0.137260865,64044.26064,1.612369045,101.101694
,36,7.327470771,0.139227545,64355.94514,1.618476465,102.0429145
,36.3,7.169268687,0.141263496,64707.57147,1.621530209,102.8899028
,36.6,7.269005575,0.143312877,65182.74948,1.625456424,103.9045355
,36.9,7.579252959,0.14537942,65156.91915,1.640725043,104.7778224
,37.2,7.619902474,0.147495096,65546.81426,1.648577486,105.7968376
,37.5,7.613950642,0.149645599,65920.60457,1.652503711,106.6679321
,37.8,8.035681119,0.151800344,66626.7201,1.649013697,107.6113442
,38.1,7.961488634,0.154020502,67321.84907,1.645087481,108.5832442
,38.4,8.079500574,0.156261392,68433.62905,1.634617543,109.7315543
,38.7,8.076856014,0.158544008,69659.71139,1.621966381,110.8732906
,39,8.437823505,0.160837222,70936.43452,1.608006445,111.9054556
,39.3,8.492581237,0.163185282,72035.13713,1.601898983,113.1458065
,39.6,8.525699316,0.165570353,72996.13508,1.597536511,114.2546705
,39.9,8.645347638,0.167985827,73118.71505,1.611496405,115.3558657
,40.2,9.227624868,0.170406998,73054.95462,1.627637492,116.3529686
,40.5,9.301913411,0.172898401,72811.74697,1.645523613,117.2558391
,40.8,9.320861502,0.175439688,72870.55064,1.656429786,118.2244513
,41.1,9.275319583,0.178010804,73737.27777,1.650322333,119.3168804
,41.4,9.529735131,0.180601069,74671.25285,1.642906112,120.3819166
,41.7,9.752940902,0.183236785,75518.49992,1.640724858,121.5291324
,42,9.939112917,0.185914831,75704.09953,1.651194769,122.5656795
,42.3,9.785791222,0.188655647,75567.72245,1.666463427,123.4028065
,42.6,9.860868006,0.191422751,75768.99458,1.676497102,124.432779
,42.9,10.05159681,0.194223975,76405.63456,1.677369579,125.4879547
,43.2,10.05926204,0.197079476,77052.72918,1.675624591,126.3963025
,43.5,10.2724433,0.19996487,77729.81054,1.675624572,127.5468054
,43.8,9.946847992,0.202929336,78247.34418,1.676933343,128.5723936
,44.1,10.17124829,0.205902042,78851.12149,1.676497076,129.6472925
,44.4,10.49341043,0.208913439,79102.30714,1.682168258,130.5907043
,44.7,11.01817599,0.211956954,78763.10358,1.699618088,131.4760453
,45,11.2375621,0.215066641,78181.79405,1.721866662,132.2605779
,45.3,10.99555423,0.218253795,78282.65352,1.728846636,133.0242917
,45.6,11.38799717,0.22144712,79640.01407,1.714450448,134.1474012
,45.9,11.04945312,0.224736872,81081.38,1.697436855,135.1707992
,46.2,11.75765358,0.228007266,82978.63843,1.676060686,136.4374492
,46.5,11.47234666,0.231392736,84132.69674,1.668644519,137.5780884
,46.8,11.38298566,0.234816418,84659.28914,1.673006991,138.7044839
,47.1,11.18461442,0.238298902,84613.23795,1.686966923,139.7333603
,47.4,12.05295703,0.241763754,84588.8303,1.698309256,140.6417122
,47.7,11.69231413,0.245362155,84920.79669,1.704416753,141.6870237
,48,11.81093872,0.248983259,85590.2057,1.703980487,142.7586343
,48.3,12.22161349,0.252639908,86279.02472,1.702235475,143.7480674
,48.6,11.73613298,0.256410892,86389.36505,1.71226919,144.7780378
,48.9,11.71494217,0.260208117,86437.51107,1.720994139,145.596538
,49.2,12.00327474,0.264042313,85751.54982,1.744115192,146.3799756
,49.5,12.04863173,0.267950471,85434.00814,1.759383831,147.1075321
,49.8,12.36024385,0.271900143,85412.56898,1.768981233,147.8931608
,50.1,12.60444825,0.275914015,86279.70743,1.76200126,148.8354784
,50.4,12.66059372,0.280000848,87770.61182,1.744115132,149.8753119
,50.7,12.79910495,0.284144069,88783.77813,1.736698922,150.960072
,51,13.49343336,0.288313195,89050.93457,1.742370066,151.8925285
,51.3,13.37481296,0.292598989,88903.04413,1.753712497,152.6463814
,51.6,13.677213,0.296921783,89064.9037,1.760692419,153.5481563
,51.9,13.34556033,0.301351699,90262.19158,1.749350032,154.6055214
,52.2,13.71284132,0.305802375,91795.39174,1.732772616,155.7571195
,52.5,13.8071905,0.310338426,93653.67406,1.711832758,156.9722697
,52.8,14.07376863,0.314931637,95180.63172,1.698745327,158.2728851
,53.1,13.98753526,0.319617653,95992.79049,1.697872842,159.4836517
,53.4,14.30567987,0.324347525,96347.29275,1.703107776,160.5388266
,53.7,14.65959241,0.329146458,96252.13356,1.715758902,161.6170136
,54,14.91863667,0.334024276,96710.32044,1.71837636,162.7269744
,54.3,14.8356858,0.33899831,97160.42744,1.719685109,163.7284591
,54.6,15.31687085,0.344010107,98628.13347,1.708342646,165.1134453
,54.9,15.63162855,0.349108744,99396.59086,1.707033877,166.1730051
,55.2,15.97882497,0.354282302,100233.6359,1.706597598,167.4013034
,55.5,15.99068215,0.359556222,100488.201,1.714013794,168.4575745
,55.8,16.44519133,0.364880534,101029.3108,1.717503726,169.6540978
,56.1,16.24567566,0.370328468,101524.6624,1.720557473,170.8056954
,56.4,16.45719274,0.375831043,101618.6124,1.728846143,171.8312857
,56.7,16.58548893,0.381422406,100977.4102,1.748477239,172.7659331
,57,16.73290948,0.38709686,100671.334,1.762437123,173.6655156
,57.3,17.02260145,0.392847682,101272.4434,1.760692109,174.5848234
,57.6,17.07721802,0.39870099,103393.6811,1.73800727,175.9917225
,57.9,17.51665579,0.404617734,106091.0423,1.709214941,177.5553122
,58.2,18.18781264,0.410608331,107750.7101,1.696563722,178.8526424
,58.5,18.26526532,0.416749456,108473.5915,1.700053689,180.2902233
,58.8,18.61729498,0.422924014,108648.8524,1.708778592,181.444561
,59.1,18.40599084,0.429249848,108804.7698,1.716631055,182.5473991
,59.4,18.89319958,0.435625126,109665.3938,1.715758516,183.9488216
,59.7,18.83829526,0.442132649,110153.9183,1.718812249,185.0675483
,60,19.24184938,0.448708096,110948.0394,1.718812212,186.3758346
,60.3,19.21229199,0.455411515,112356.3602,1.709651033,187.6643975
,60.6,19.35246205,0.462205059,114514.5091,1.693073644,189.3320772
,60.9,19.6232518,0.469092474,116575.2605,1.678677477,191.0282482
,61.2,20.44194721,0.476047835,117280.1566,1.68173113,192.4800755
,61.5,20.51383748,0.483157523,116664.264,1.700489733,193.6404402
,61.8,21.0579139,0.490343638,115870.0836,1.721865771,194.7580727
,62.1,21.32905208,0.497656198,115514.8248,1.737570628,195.917343
,62.4,21.66632276,0.505074769,116306.7717,1.73713435,197.1303016
,62.7,21.77101034,0.512620754,117686.5124,1.729718146,198.5569255
,63,21.91145908,0.520278303,119499.7566,1.71706698,200.106268
,63.3,21.69700894,0.528074963,121237.8157,1.704852094,201.5679532
,63.6,22.25221056,0.535938519,122583.5638,1.69961708,203.1885198
,63.9,22.21329085,0.543960402,123502.1438,1.699617089,204.7356715
,64.2,22.91739593,0.552054107,124144.3151,1.700925756,206.0340982
,64.5,23.16175953,0.560300282,124846.7889,1.703979471,207.6667178
,64.8,22.98008036,0.568699036,125917.8267,1.700489507,209.0779989
,65.1,23.36502488,0.577187195,127501.7806,1.693509534,210.762117
,65.4,23.35138453,0.585829967,128771.0478,1.691764537,212.5043057
,65.7,23.72214259,0.594577995,129040.359,1.69874446,213.8235503
,66,24.16859855,0.603453166,128799.6442,1.71226806,215.2129212
,66.3,24.13658945,0.612494041,128749.5718,1.723174236,216.6384478
,66.6,24.70781378,0.621631714,128481.3361,1.735389082,217.8294943
,66.9,25.3331011,0.630903817,128258.4336,1.748040175,219.0676581
,67.2,25.94255669,0.640317024,128448.717,1.755456309,220.341979
,67.5,26.22914415,0.649893931,129016.6693,1.757637515,221.5812376
,67.8,26.06638759,0.659645064,130905.6175,1.745422627,223.142631
,68.1,26.46858724,0.669506008,132793.0503,1.734516424,224.767582
,68.4,26.62779701,0.679532083,134408.8081,1.726663971,226.3070632
,68.7,26.62389581,0.689720383,135777.4567,1.722737753,227.9473522
,69,27.34138,0.700014929,136340.7897,1.727100151,229.4397209
,69.3,27.94567707,0.710472752,137085.2904,1.728408834,230.8367638
,69.6,28.04155066,0.721122006,138073.074,1.728408826,232.4836254
,69.9,28.19148362,0.731928536,139291.8449,1.724482593,233.9343561
,70.2,28.71166436,0.742874049,141641.7689,1.710086409,235.7992676
,70.5,29.03378475,0.753997991,143219.8554,1.705287668,237.703626
,70.8,29.16450095,0.765302788,144691.123,1.700488944,239.4753993
,71.1,29.63218075,0.776755942,145593.9556,1.702233887,241.2197841
,71.4,30.09151228,0.788382664,146886.0315,1.699180119,242.9575921
,71.7,30.48341772,0.800189598,148186.4357,1.697871344,244.841133
,72,30.95767029,0.812169461,149310.6801,1.698307547,246.6753641
,72.3,31.4219092,0.82433087,149315.3701,1.708341173,248.1523944
,72.6,32.04254911,0.836665747,149662.8644,1.716193551,249.9395109
,72.9,32.17306679,0.849219318,149241.4895,1.730153426,251.4505067
,73.2,32.49742794,0.861949941,150447.1676,1.727099671,252.9888931
,73.5,32.66865658,0.874882952,151767.0417,1.724482176,254.6784904
,73.8,33.2251052,0.887985989,153831.8134,1.716193442,256.642017
,74.1,33.39710342,0.901312128,155223.1687,1.713575948,258.4751538
,74.4,33.5524209,0.91488611,156220.1217,1.71532092,260.4331989
,74.7,34.06384868,0.928550272,156666.2981,1.719683336,261.9584417
,75,33.84134561,0.942515368,157415.7004,1.722737082,263.7532222
,75.3,34.36268451,0.956643078,158316.102,1.723609526,265.3639307
,75.6,35.11697065,0.970968691,157672.805,1.741059311,267.014084
,75.9,35.56127419,0.985531346,156087.4264,1.766797805,268.2566316
,76.2,36.09914328,1.000357962,154371.9492,1.792536289,269.2975649
,76.5,36.66237088,1.015307294,153761.7969,1.806496117,270.3319268
,76.8,36.76084042,1.030563343,155150.0758,1.799952412,271.7903255
,77.1,37.26199787,1.046023278,157163.0487,1.78730122,273.2399635
,77.4,37.7473087,1.061718068,159826.9504,1.771160059,275.1607576
,77.7,38.00542522,1.077665063,161163.5818,1.767015694,276.6991467
,78,38.22231572,1.093855598,162105.9017,1.766361304,278.2167148
,78.3,38.65134657,1.110276719,163711.4719,1.759381323,279.9841104
,78.6,39.88204257,1.12689326,165692.4499,1.74934754,281.9520258
,78.9,40.30974589,1.14381391,168225.8203,1.735387619,283.9856809
,79.2,40.77027556,1.16098783,170365.7753,1.724917666,285.8078603
,79.5,41.18250359,1.1784245,171830.6166,1.724045135,287.9412257
,79.8,41.73156615,1.196115478,173115.5495,1.722954468,289.8220262
,80.1,42.13705324,1.214083011,174237.5983,1.723172553,291.6710534
,80.4,42.40686891,1.232330991,176843.5569,1.710521388,293.8548176
,80.7,42.93083976,1.250837756,180003.9153,1.695252722,296.337718
,81,43.52840484,1.269619001,182762.2979,1.684782759,298.869923
,81.3,44.18292197,1.288680119,184148.9456,1.684782701,300.9156333
,81.6,44.26617372,1.30806685,185172.4862,1.690453887,303.3097748
,81.9,44.60274593,1.327728875,185434.1983,1.701360017,305.4738185
,82.2,45.18140483,1.347671721,185332.8186,1.712266108,307.1809504
,82.5,46.13028916,1.367891889,185803.803,1.720118457,309.385541
,82.8,46.59402514,1.388449449,185881.7961,1.728407086,311.1014378
,83.1,47.42049646,1.409293614,187261.9821,1.727098278,313.2994533
,83.4,47.75183305,1.430485422,187241.4674,1.736259407,315.1084849
,83.7,48.41594872,1.451975569,188008.8231,1.739749317,317.1377587
,84,49.31382583,1.473774864,188115.1168,1.748474151,318.9840499
,84.3,49.90045455,1.495923925,189767.0073,1.744547883,320.8862199
,84.6,50.0610077,1.518435783,192277.3667,1.736259191,323.3088506
,84.9,51.11265899,1.541228944,194966.5698,1.726225433,325.7051956
,85.2,51.24647694,1.564427035,196231.4813,1.725789175,327.6731026
,85.5,51.81375019,1.587946856,197084.2747,1.730587828,330.0124655
,85.8,52.67635347,1.611802647,196952.0985,1.741930141,331.9168281
,86.1,53.4540278,1.636024385,196930.0137,1.750654986,333.5428811
,86.4,53.87801215,1.660635616,197242.5624,1.758507373,335.610502
,86.7,54.41759575,1.685611104,197851.7652,1.761561042,337.2891474
,87,54.81899501,1.710972707,200018.8755,1.753708577,339.5134557
,87.3,55.32600683,1.736710615,204041.3681,1.733641217,342.1398965
,87.6,56.27062806,1.762808573,208144.4478,1.713573817,344.7674346
,87.9,56.81911909,1.789326858,212581.1525,1.693942702,347.7488877
,88.2,57.76444595,1.816219797,215893.2709,1.682600223,350.7128103
,88.5,58.69473084,1.843519962,217555.141,1.682600137,353.3545955
,88.8,59.46103145,1.87124345,218290.3804,1.68958,356.001855
,89.1,60.08914108,1.899394918,217585.5019,1.706593527,358.311635
,89.4,61.0999373,1.927946543,217292.22,1.719680806,360.4855469
,89.7,61.63887874,1.956960661,218022.007,1.725788196,362.8457291
,90,62.23100323,1.986409606,219198.5777,1.726224386,364.9330752
,90.3,62.80641551,2.016304524,220699.1494,1.726224332,367.5069233
,90.6,63.54900293,2.046639954,223292.6564,1.71924433,370.338263
,90.9,64.27487596,2.077434908,226469.017,1.709646857,373.193712
,91.2,64.92412417,2.108700188,230077.5277,1.696559426,375.8256308
,91.5,65.34281272,2.140453121,232755.2142,1.693069422,379.0580044
,91.8,66.23071487,2.172654577,233863.0318,1.696559305,381.4784508
,92.1,67.37814679,2.205325326,234998.6956,1.700921654,384.2703535
,92.4,68.27005339,2.23850679,236231.6971,1.70397529,386.9373377
,92.7,69.21138847,2.272187537,237501.2185,1.707028922,389.7741632
,93,69.95211269,2.306390974,239192.6023,1.707465098,392.6339929
,93.3,70.43189954,2.34112843,240236.2354,1.710518772,395.109226
,93.6,71.43040105,2.376356499,240489.6843,1.72011608,397.7860734
,93.9,72.42047792,2.41223851,239177.9379,1.738874543,400.0651794
,94.2,73.23535541,2.448432577,237064.0575,1.761995476,402.0122774
,94.5,74.0576152,2.48529512,236804.8107,1.771592796,404.0021122
,94.8,75.56915951,2.522669296,238013.2193,1.771592649,406.2976563
,95.1,76.28931181,2.560660604,240331.3927,1.765485144,408.8265831
,95.4,76.93947867,2.599230386,243726.7494,1.753706456,411.4453543
,95.7,78.06050657,2.638351816,247166.7862,1.743672704,414.238354
,96,78.8723251,2.678084767,251698.9453,1.727531549,417.4115609
,96.3,80.17538758,2.718385724,254794.67,1.71880652,420.1651178
,96.6,80.88758097,2.759334716,257197.8806,1.715752736,423.4106411
,96.9,81.75111338,2.800892331,257585.9054,1.723605069,426.2156908
,97.2,82.60955349,2.843078201,257412.9695,1.734074874,428.463017
,97.5,83.42836878,2.885903968,258595.5166,1.738873494,431.3732566
,97.8,84.3897819,2.92936651,260327.5299,1.740182138,434.1322841
,98.1,85.58739951,2.973469379,262326.025,1.7380008,436.6195813
,98.4,86.42129515,3.018262454,263457.5911,1.742799415,439.5407743
,98.7,87.78885812,3.063697086,262987.0319,1.755450397,441.9382241
,99,88.75192433,3.109844869,263333.2634,1.761557725,444.1241927
,99.3,89.97989533,3.156670019,264043.4883,1.766356312,446.6542223
,99.6,90.97934973,3.204217681,267242.178,1.755886326,449.4296881
,99.9,92.14344035,3.252472859,270708.1722,1.744980096,452.5185342
,100.2,92.75159027,3.301493742,275030.1211,1.730583944,455.8593872
,100.5,94.09184663,3.351206901,277270.7791,1.728838841,458.8255142
,100.8,94.79794399,3.401712917,278818.0363,1.731892486,461.8595677
,101.1,96.33432871,3.452927177,280569.9291,1.733637323,464.8454206
,101.4,97.39214846,3.504946837,283547.8319,1.727966034,467.9507007
,101.7,98.77934402,3.557730654,286682.3279,1.722294723,471.3770309
,102,99.90264568,3.61132942,288366.5563,1.723603351,474.5206625
,102.3,101.1930652,3.665726711,288518.4728,1.731455636,477.0945235
,102.6,102.5207972,3.720943536,291267.5502,1.727529306,480.6490521
,102.9,103.6145841,3.777010121,295368.4789,1.716623084,484.2145368
,103.2,105.0676916,3.833899944,300942.8158,1.699609403,488.2446076
,103.5,105.9457004,3.891687342,304292.2496,1.694374384,491.8363883
,103.8,107.1405898,3.950327007,306055.7121,1.698300475,495.4982952
,104.1,108.3411629,4.009852085,306616.2792,1.707897745,498.8347775
,104.4,109.4700348,4.070281176,306209.2791,1.720984977,501.7833713
,104.7,110.9964919,4.131597086,308216.0743,1.722293566,505.1604003
,105,112.2773404,4.193855548,310868.7148,1.720112222,508.7368436
,105.3,113.5264206,4.25705666,312323.0284,1.722293326,511.869524
,105.6,115.1098418,4.321190678,313828.7259,1.725783132,515.4897998
,105.9,116.6573297,4.386295958,313901.826,1.735816607,518.5622214
,106.2,118.0274299,4.45239662,317291.184,1.731017788,522.1846875
,106.5,119.7626507,4.519471904,320169.0077,1.727963912,525.6307525
,106.8,121.0234294,4.587591741,322446.2231,1.727963792,529.1447394
,107.1,122.6709578,4.65671529,323461.4044,1.733634811,532.5590288
,107.4,123.6485024,4.726927421,323706.7665,1.741487114,535.5547371
,107.7,125.3456201,4.798153016,324534.7101,1.747158126,538.8331567
,108,126.4168489,4.870495847,326143.4104,1.748903,542.1455312
,108.3,128.1826835,4.943885881,327819.6782,1.750647806,545.2157667
,108.6,130.0431979,5.018378417,331488.3234,1.744540209,548.9171336
,108.9,131.6089799,5.09401603,333371.9948,1.746285035,552.3873034
,109.2,133.2469703,5.17079157,334725.2267,1.749338586,555.7270813
,109.5,135.0229,5.248717934,335733.2022,1.752828366,558.8247106
,109.8,136.7745123,5.327823332,338595.7173,1.749338246,562.3880152
,110.1,138.4360706,5.408131273,342315.8061,1.743230671,566.1408851
,110.4,139.7363167,5.489678887,346296.7066,1.736686887,569.7677365
,110.7,141.5522507,5.572424788,350243.2358,1.731015544,573.8109744
,111,143.2452554,5.656428797,352838.8535,1.730579138,577.7019008
,111.3,145.3861281,5.741672838,356776.244,1.72316279,581.4657366
,111.6,146.6660189,5.82826204,359909.3868,1.72098145,585.9012298
,111.9,148.6229829,5.916265741,361431.8295,1.725779944,589.8195591
,112.2,150.4137847,6.005312769,362512.4685,1.731450941,593.2667224
,112.5,152.3674342,6.095844735,362416.6417,1.743229331,596.8738686
,112.8,154.0999515,6.187759155,363209.9755,1.749772817,600.3571898
,113.1,156.2886383,6.281032204,366676.1246,1.744537684,604.2503233
,113.4,158.0889402,6.375740235,371672.2626,1.732322694,608.3516336
,113.7,159.6897337,6.471892322,378848.1505,1.713127831,613.2791186
,114,161.6734643,6.569471883,381771.9615,1.712255157,617.7507856
,114.3,163.8487524,6.668513424,381195.5042,1.724906007,621.2111122
,114.6,165.7592041,6.769068951,376426.2375,1.756315339,624.204651
,114.9,167.6423719,6.871145624,372271.7538,1.783362236,626.7040254
,115.2,169.6721548,6.974753755,371826.6796,1.793831871,629.3217369
,115.5,171.81277,7.079919165,376043.8717,1.78554304,632.9847718
,115.8,173.8653492,7.186678182,384729.6864,1.76024074,637.5714938
,116.1,176.230114,7.295028601,392447.5905,1.740173332,642.3017663
,116.4,177.7201136,7.405073814,400826.564,1.718361041,647.265407
,116.7,179.6895373,7.516745829,407966.4536,1.702656109,652.4766944
,117,181.7136094,7.630099361,412315.1879,1.696548514,657.0042497
,117.3,184.25662,7.745131192,414467.5932,1.70134695,662.0610508
,117.6,185.9964077,7.861954017,413503.6875,1.715306549,665.7624306
,117.9,188.9307652,7.98046295,413189.0273,1.728393561,669.8791109
,118.2,190.6658269,8.100841794,415470.4091,1.73101084,674.2806567
,118.5,193.0920482,8.222993552,417630.1732,1.733191829,678.3819885
,118.8,194.9746353,8.347026632,421115.5518,1.731446674,683.0508941
,119.1,197.5350599,8.472888692,423741.918,1.733191405,687.5072434
,119.4,199.7839883,8.600673067,423749.9943,1.743224756,691.2305494
,119.7,202.2880545,8.730371014,425279.367,1.748459429,695.549935
,120,204.5862881,8.862042184,427379.2187,1.750640414,699.7597421
,120.3,207.0256567,8.99569339,432435.0034,1.741479094,704.0824135
,120.6,208.8206836,9.131406334,434926.3969,1.742351405,708.7381707
,120.9,211.4174976,9.269116712,438397.1274,1.739733702,713.423532
,121.2,213.428205,9.408946448,439984.1464,1.743659687,717.8064589
,121.5,216.5785086,9.550813491,444044.6155,1.740605689,722.8183581
,121.8,219.3432237,9.694849586,448475.6501,1.735806761,727.5837089
,122.1,222.1342188,9.84105989,453214.0817,1.731007832,732.6657293
,122.4,224.5496001,9.989503891,455721.8156,1.732752567,737.1549517
,122.7,227.0128844,10.14018746,457700.5701,1.737114748,741.8381231
,123,229.6039448,10.29313921,459580.841,1.741476916,746.3426914
,123.3,232.5565864,10.44837804,462467.7598,1.741912873,750.6522329
,123.6,234.8723239,10.60600435,468991.9866,1.732315334,756.172531
,123.9,237.9723211,10.76596034,476950.9922,1.718355308,761.9843139
,124.2,240.699168,10.92835773,484460.1131,1.706576529,768.0218039
,124.5,243.9589788,11.09317331,487477.3569,1.707448704,773.1301383
,124.8,246.7000161,11.26051327,487143.9821,1.719226959,778.18148
,125.1,250.1337619,11.43033571,487532.469,1.728387697,783.1331299
,125.4,252.9513706,11.60276461,488839.4436,1.733622321,787.6420928
,125.7,255.5791653,11.63451994,493339.8699,1.7296959,793.083517
,126,257.2851138,11.63440859,499211.4228,1.722715882,798.9051297
,126.3,258.3778301,11.63433745,504621.4118,1.717917128,804.1021746
,126.6,259.1976289,11.6342842,509593.477,1.717044569,810.1231904
,126.9,260.3527499,11.63420897,514013.1402,1.71704446,815.8133129
,127.2,260.5734617,11.634195,519463.0051,1.713554512,821.7006373
,127.5,261.3737069,11.63414303,520012.3976,1.723151738,826.8264527
,127.8,261.5960828,11.63412896,516942.1891,1.742346319,831.4350693
,128.1,262.1666779,11.63409205,512426.4993,1.76328583,834.7792324
,128.4,262.3391299,11.63408125,509324.6173,1.78029921,838.4356649
,128.7,262.7861634,11.63405244,513112.4488,1.777681721,843.2864451
,129,262.9236686,11.63404393,515973.6194,1.77855419,847.9805265
,129.3,263.5945276,11.63400045,516608.8218,1.784661498,851.870363
,129.6,263.5007187,11.6340071,515647.1336,1.796003771,855.8916638
,129.9,263.906565,11.633981,515795.7624,1.803419827,859.7519105
,130.2,263.7694887,11.63399049,518718.2704,1.803419841,863.9375693
,130.5,264.3563091,11.63395252,520352.1737,1.80690971,867.6542802
,130.8,264.4992228,11.63394365,521493.3704,1.811708347,871.5638235
,131.1,264.9778746,11.63391277,520538.6138,1.821741839,874.9868782
,131.4,265.0671201,11.63390743,518658.7134,1.833084094,877.8982158
,131.7,265.2237628,11.63389766,513586.3115,1.85402364,880.3066229
,132,265.2759814,11.63389474,509788.4291,1.870600788,882.3830171
,132.3,265.5624262,11.63387646,508985.6085,1.877580612,884.4725719
,132.6,265.6778818,11.6338694,513725.823,1.869292025,887.7794675
,132.9,266.0837279,11.63384329,517570.6025,1.864057094,891.0765113
,133.2,265.8626132,11.6338583,515516.4348,1.87583562,893.2504192
,133.5,266.4544258,11.63382,511760.1651,1.89154023,894.8348531
,133.8,266.4305105,11.63382207,508771.2324,1.904191217,896.3633848
,134.1,266.5443018,11.63381512,511930.2589,1.897211353,898.8967033
,134.4,266.3656224,11.63382734,516345.9004,1.886741588,901.685314
,134.7,267.1987339,11.63377321,517980.2927,1.88630527,904.2854871
,135,266.6597703,11.63380906,513925.1052,1.903318711,905.7482648
,135.3,267.0011314,11.63378718,505407.0205,1.934728021,905.8753772
,136.1,267.6600486,11.57502183,1.7977E+308,1.984459407,0
,136.4,266.8966956,11.40064618,1.7977E+308,2.007144012,0
,136.7,266.5086039,11.22624593,1.7977E+308,1.843989991,0
,137,266.4583306,11.05182352,1.7977E+308,1.504594631,0
,137.3,265.7332526,10.87744536,1.7977E+308,0.903018559,0
,137.6,265.6946281,10.70302219,1.7977E+308,0.404831511,0
,137.9,265.2699256,10.52862434,1.7977E+308,0.092046822,0
,138.2,264.909292,10.35422228,1.7977E+308,0.016577153,0
,138.5,264.4471464,10.17982688,1.7977E+308,0.021375803,0
,138.8,264.3452851,10.00540786,1.7977E+308,0.032281826,0
,139.1,263.7566656,9.83102075,1.7977E+308,0.033154309,0
,139.4,263.6839265,9.656599817,1.7977E+308,0.028355659,0
,139.7,263.2500711,9.482202562,1.7977E+308,0.018322119,0
,140,262.7879256,9.307807162,1.7977E+308,0.013087228,0
,140.3,262.3990017,9.133406961,1.7977E+308,0.011778505,0
,140.6,262.0233909,8.959005887,1.7977E+308,0.011778506,0
,140.9,261.9323463,8.784586154,1.7977E+308,0.010906024,0
,141.2,261.4943306,8.610189172,1.7977E+308,0.010906024,0
,141.5,261.1037425,8.43578908,1.7977E+308,0.011342265,0
,141.8,260.7971931,8.261383477,1.7977E+308,0.017013398,0
,142.1,260.4207502,8.086982458,1.7977E+308,0.017885881,0
,142.4,260.0143529,7.912583402,1.7977E+308,0.015704676,0
,142.7,259.5064436,7.738191003,1.7977E+308,0.023557015,0
,143,259.1283365,7.563790092,1.7977E+308,0.037516728,0
,143.3,258.5280679,7.389403749,1.7977E+308,0.047550273,0
,143.6,258.3796108,7.214987781,1.7977E+308,0.055402613,0
,143.9,257.9574042,7.040589762,1.7977E+308,0.053221409,0
,144.2,257.8131075,6.866173521,1.7977E+308,0.050603963,0
,144.5,257.2294802,6.691786086,1.7977E+308,0.030100634,0
,144.8,256.7540214,6.517391559,1.7977E+308,0.019194608,0
,145.1,256.5427433,6.34297971,1.7977E+308,0.015268438,0
,145.4,256.327721,6.168568106,1.7977E+308,0.013523474,0
,145.7,255.7378531,5.99418108,1.7977E+308,0.003053688,0
,146,255.3368641,5.81978167,1.7977E+308,0.006107376,0
,146.3,254.8385235,5.645388643,1.7977E+308,0.01919461,0
,146.6,254.5169967,5.470984023,1.7977E+308,0.024865745,0
,146.9,254.2442382,5.295994784,1.7977E+308,0.023993263,0
,147.2,253.7691953,5.12160023,1.7977E+308,0.020939576,0
,147.5,253.4255264,4.947778482,1.7977E+308,0.021375818,0
,147.8,252.8002956,4.773393775,1.7977E+308,0.019194612,0
,148.1,252.4030509,4.59899412,1.7977E+308,0.013087236,0
,148.4,251.9700272,4.42459681,1.7977E+308,0.014832201,0
,148.7,251.998384,4.250169248,1.7977E+308,0.018322131,0
,149,251.5137723,4.075775321,1.7977E+308,0.010906031,0
,149.3,250.933057,3.901387696,1.7977E+308,0.004362412,0
,149.6,250.4879684,3.726991177,1.7977E+308,0.020503339,0
,149.9,250.1414796,3.552588194,1.7977E+308,0.029228164,0
,150.2,249.5624284,3.378200459,1.7977E+308,0.034463061,0
,150.5,249.2130273,3.203797666,1.7977E+308,0.038825474,0
,150.8,248.6510334,3.029408813,1.7977E+308,0.051912715,0
,151.1,248.158933,2.855015377,1.7977E+308,0.053657681,0
,151.4,248.0154682,2.680599081,1.7977E+308,0.045805338,0
,151.7,247.5200395,2.506205864,1.7977E+308,0.023993273,0
,152,246.8789993,2.331822193,1.7977E+308,0.00654362,0
,152.3,246.4226777,2.157426412,1.7977E+308,0.007852344,0
,152.6,245.5311856,1.983059163,1.7977E+308,0.017013414,0
,152.9,245.2703994,1.80865056,1.7977E+308,0.019630862,0
,153.2,244.8714903,1.634251014,1.7977E+308,0.016140932,0
,153.5,244.2129766,1.459868489,1.7977E+308,0.011778518,0
,153.8,243.4496225,1.285492839,1.7977E+308,0.008724829,0
,154.002,243.2097133,1.16806193,1.7977E+308,0.008288587,0
,229.4,242.4197523,0.94381228,1.7977E+308,0.010469796,0
,229.7,241.6913448,0.769434339,1.7977E+308,0.005234898,0
,230,241.0186858,0.595052742,1.7977E+308,0.013523488,0
,230.3,239.5871822,0.420720901,1.7977E+308,0.028355702,0
,230.6,238.3403972,0.246376949,1.7977E+308,0.028355704,0
,230.9,235.803077,0.072117615,1.7977E+308,0.021812083,0
,231.016,234.9339538,0.004729998,1.7977E+308,0.017449668,0
END,,,,,,