File: GB1_test 17.csv
Segment,Time On Sample,Displacement Into Surface,Load On Sample,Harmonic Contact Stiffness,Harmonic Displacement,Harmonic Load
Surface Marker,0,0,0,186.4561962,0.421390803,2.228751156
,0.2,-0.058155593,0.000660373,3181.772727,0.280054758,2.303262005
,0.4,0.259766245,0.001296127,9974.52093,0.19062917,2.393113354
,0.6,0.305614366,0.001949692,17008.63361,0.148751824,2.479677438
,0.792,0.305397342,0.00258329,19297.58506,0.13697382,2.544326561
,1,0.256697826,0.003264536,20770.40911,0.129121818,2.622124657
,1.2,0.338322938,0.003917563,23568.17718,0.119961148,2.836891241
,1.4,0.413292852,0.00456448,25110.35801,0.121269815,3.082338776
,1.6,0.738703182,0.005198275,26197.99151,0.123014702,3.283956412
,1.8,0.37103278,0.00587744,28595.93385,0.12039737,3.543648623
,2,0.691450933,0.006511563,30055.94341,0.123014702,3.793479175
,2.2,0.421128004,0.007184355,32120.8612,0.130430484,4.264650726
,2.4,0.595940961,0.007828009,34328.93769,0.133484039,4.69747116
,2.6,0.52114501,0.008488002,35752.43048,0.141772265,5.216855643
,2.8,0.730071184,0.009129422,36632.07874,0.153550267,5.741718903
,3,0.987255077,0.009767684,37811.07099,0.165328268,6.276443912
,3.2,0.708611855,0.01044102,38750.78389,0.178414941,6.903211663
,3.4,1.166314899,0.011066156,38157.54406,0.202407165,7.719543929
,3.6,0.977530885,0.01173361,38940.76689,0.218983616,8.540259069
,3.8,0.70637593,0.012406456,40227.55709,0.23207029,9.359878412
,4,0.882852945,0.013050001,41154.25628,0.244720736,10.17401912
,4.2,0.719029818,0.013715822,42155.07617,0.257807409,11.08239406
,4.4,0.666698669,0.014374344,45035.92106,0.266531857,12.20882286
,4.6,0.795749992,0.015020993,44959.29292,0.288779195,13.10295319
,4.8,0.764219585,0.015678154,42747.55158,0.329347874,14.1493924
,5,0.881622492,0.016325566,40219.42935,0.377768552,15.14542728
,5.2,0.799338275,0.016986049,38126.47232,0.427934124,16.12283434
,5.4,0.421267499,0.017665894,35197.50106,0.495548599,17.18132658
,5.6,0.254532263,0.018331906,32982.79256,0.558800846,18.14120166
,5.8,0.254618984,0.018986999,31285.81528,0.617254643,18.98602327
,6,0.319604023,0.019637842,29517.78638,0.682251773,19.79358944
,6.2,0.148292622,0.020304154,27692.01051,0.755537137,20.58033631
,6.4,-0.35208654,0.020992007,25940.09134,0.839728076,21.41529587
,6.6,-0.00587545,0.021624443,24354.65965,0.91912053,22.00590418
,6.8,0.278765435,0.022260909,21892.68005,1.047369891,22.55706552
,7,-0.043559361,0.022937108,19870.96716,1.165149951,22.85730018
,7.2,-0.268952699,0.02360696,17738.61433,1.306486011,23.01399205
,7.4,0.630142134,0.024203203,15576.72801,1.477921334,23.05891829
,7.6,0.554514153,0.024863251,14482.44455,1.583923373,23.12028012
,7.8,0.797137531,0.025502466,14173.23737,1.621438476,23.28464245
,8,0.985262962,0.026145249,14615.71818,1.595265118,23.70650551
,8.2,1.033607405,0.026797181,15855.74449,1.509329315,24.2916349
,8.4,1.093184248,0.027448378,17567.26732,1.404635947,24.9337432
,8.6,1.034612877,0.028107308,19886.29502,1.29078192,25.78185202
,8.8,1.013066827,0.028763816,21524.46942,1.229710793,26.44368372
,9,0.83301912,0.029430699,22840.63485,1.197866576,27.17564311
,9.2,0.8235375,0.030086417,23221.89569,1.204846134,27.73666601
,9.4,0.70339593,0.030749378,23039.95901,1.236254153,28.24947597
,9.6,0.687258072,0.031405532,22707.31019,1.269843277,28.62422171
,9.8,0.833366005,0.032051065,22277.14437,1.31128439,29.06909545
,10,1.230330886,0.032680177,21965.46073,1.340947479,29.42083081
,10.2,1.245394142,0.033334288,21684.61747,1.369738155,29.79119359
,10.4,0.92556545,0.034010321,21387.22375,1.401582412,30.17470506
,10.6,1.394500896,0.034634721,21140.54581,1.432990384,30.54616397
,10.8,0.998541491,0.035315737,21077.86822,1.451747978,30.8420156
,11,1.577304851,0.035932947,21274.06091,1.462653489,31.23538954
,11.2,1.526221748,0.036591388,21738.44609,1.457418826,31.62766727
,11.4,1.628648118,0.037239779,22411.24953,1.439533703,32.0221366
,11.6,1.636223107,0.037894379,23633.4563,1.397220136,32.57001053
,11.8,1.463247659,0.038560798,24883.2289,1.354034139,33.07953315
,12,1.221213745,0.039231738,26309.07675,1.310848146,33.70958797
,12.2,1.248341431,0.039885059,27398.558,1.282493692,34.26841942
,12.4,1.099910854,0.040549872,28331.37432,1.262863698,34.85026138
,12.6,1.627088374,0.041170459,28661.92395,1.266571551,35.34882718
,12.8,1.385470477,0.041841371,28729.43699,1.279440127,35.80246658
,13,1.723361243,0.042474349,28832.53187,1.291218107,36.30322371
,13.2,1.738424499,0.043128459,28894.50464,1.302996109,36.75467182
,13.4,1.906997226,0.04377252,29016.25194,1.313465433,37.26309903
,13.6,1.698660519,0.044441253,29482.5422,1.311284337,37.82850469
,13.8,1.980389279,0.045077907,29773.50447,1.312592984,38.25803817
,14,2.05286258,0.045728258,30063.43018,1.317827647,38.7872845
,14.2,1.781707635,0.046401104,30535.36446,1.313901667,39.30338141
,14.4,1.906598805,0.047048024,30940.72301,1.314774103,39.86988324
,14.6,2.036482153,0.047694618,31180.8048,1.318263873,40.30927827
,14.8,1.862674677,0.048361091,31924.73457,1.305613438,40.9163224
,15,2.069104753,0.049002673,32678.63017,1.293835421,41.5332287
,15.2,2.112457016,0.049654931,33080.97406,1.295144085,42.06028344
,15.4,1.999387706,0.050317428,33603.50708,1.295144094,42.69033844
,15.6,1.99448225,0.050972845,33865.43185,1.299942541,43.16041418
,15.8,2.076107877,0.051622597,33777.24902,1.321317429,43.69733078
,16,2.286698099,0.052263907,33665.66809,1.33920253,44.11919401
,16.2,2.366659666,0.052913768,33648.72013,1.357960084,44.71418521
,16.4,2.469086033,0.053562158,33666.29765,1.369301857,45.12728231
,16.6,2.61311388,0.054207825,33767.5663,1.379771182,45.65324144
,16.8,2.504204722,0.054870048,33945.07788,1.385878304,46.20111534
,17,2.848751707,0.055502589,34098.6677,1.3902405,46.63064887
,17.2,2.625022462,0.056172328,34343.72805,1.395038964,47.25522494
,17.4,2.642581806,0.056826273,34461.84517,1.401582298,47.71543913
,17.6,2.353122217,0.057500316,34566.77486,1.409434323,48.16688674
,17.8,2.750087072,0.058129426,34638.64875,1.422084739,48.71037826
,18,2.71439652,0.058786856,34635.94626,1.436916301,49.20784777
,18.2,2.568046029,0.059451531,34457.47811,1.457854985,49.64285958
,18.4,2.895952422,0.060085161,34259.27992,1.47704874,50.00664822
,18.6,2.657246644,0.060755881,33948.49787,1.502349655,50.43727689
,18.8,2.363626386,0.061433469,33746.97797,1.520671018,50.78024551
,19,2.67489219,0.062068188,33512.94341,1.542045886,51.19334295
,19.2,2.798951846,0.062711888,33468.31521,1.552951433,51.58014209
,19.4,2.677562244,0.063374929,33525.47891,1.559058557,51.93845142
,19.6,2.97468354,0.064010574,33602.2926,1.566910533,52.36688938
,19.8,3.178617516,0.064652319,33589.11658,1.576943629,52.67698624
,20,2.801794824,0.06533208,33520.40822,1.593083889,53.06378469
,20.2,3.019041276,0.065972953,33407.52667,1.61009654,53.36511571
,20.4,3.128955907,0.066620852,33150.53185,1.631907646,53.61604218
,20.6,3.094097386,0.067278227,33021.29441,1.650665209,53.93709621
,20.8,3.430323761,0.067913238,33155.02485,1.654591179,54.21541669
,21,2.937847604,0.06860909,33689.5793,1.643249446,54.63837464
,21.2,3.075216819,0.069270246,34442.54208,1.622746985,55.07009962
,21.4,3.342381584,0.06992962,35700.79861,1.585231844,55.61468674
,21.6,2.971378572,0.070637503,36785.29889,1.553823871,56.07818744
,21.8,3.163658487,0.071315536,37952.95998,1.523724516,56.67537039
,22,3.37091386,0.07199934,38908.06002,1.503222051,57.27693634
,22.2,3.422578582,0.072700348,39754.88372,1.486209377,57.8456295
,22.4,3.292027687,0.073420422,40189.97747,1.483592055,58.40336498
,22.6,3.434381372,0.074129731,40210.0875,1.49231649,58.79673882
,22.8,3.533884401,0.074848956,40626.14223,1.491007815,59.33913418
,23,3.31305487,0.075596489,41040.2048,1.490135389,59.88152901
,23.2,3.49326245,0.076325035,41361.62079,1.491880264,60.40091381
,23.4,3.427604105,0.077077088,41936.1097,1.48620938,60.98933036
,23.6,3.27166933,0.077842715,42569.80353,1.476612503,61.4922784
,23.8,3.564613323,0.07858651,42999.55056,1.476176253,62.10370627
,24,3.585898432,0.079355764,43322.14229,1.477921142,62.67787808
,24.2,3.672496671,0.080128251,43623.37882,1.480102248,63.23780555
,24.4,3.415465436,0.08093111,43711.3391,1.487081826,63.69363632
,24.6,3.421354277,0.081724779,43721.72382,1.497987383,64.25027628
,24.8,3.667282397,0.082510653,43752.13609,1.508020479,64.78500168
,25,3.712690115,0.083317639,43803.66436,1.518053587,65.31972677
,25.2,3.78014534,0.08413122,43934.01751,1.524596916,65.82267519
,25.4,3.749003728,0.084959624,44020.63404,1.532885142,66.29603823
,25.6,3.663778893,0.085799748,44208.63648,1.538992261,66.7836459
,25.8,3.673820097,0.086642123,44429.92383,1.545535597,67.32165814
,26,3.778295335,0.087486642,44509.12724,1.553387591,67.72927657
,26.2,3.536228862,0.088362572,44456.26136,1.569527834,68.29029904
,26.4,4.161135879,0.089190166,44550.32327,1.576071115,68.69353547
,26.6,3.847512139,0.090087944,44621.59678,1.585231812,69.18990867
,26.8,4.016048145,0.090962926,44758.44565,1.589594023,69.60081447
,27,3.909180952,0.091864797,45210.99121,1.585668034,70.14649673
,27.2,4.30277812,0.092742891,45645.48308,1.582178222,70.66588194
,27.4,3.915514102,0.093681108,46105.23202,1.578688479,71.23676577
,27.6,4.168911402,0.09458653,46519.95016,1.574762456,71.71012937
,27.8,4.386945962,0.095503583,47038.83659,1.569963993,72.29745075
,28,4.66571722,0.096425821,47379.53189,1.570400191,72.86395291
,28.2,4.617499361,0.097378922,47680.33625,1.570400196,73.36251809
,28.4,4.360440575,0.098355179,47888.2096,1.574762442,73.91039161
,28.6,4.736138725,0.099299703,48109.45103,1.577379743,74.36841486
,28.8,4.503205732,0.100293666,48258.02916,1.584359321,74.90533103
,29,4.716239,0.101268366,48485.14121,1.588721525,75.4334819
,29.2,4.719599247,0.102266695,48927.31357,1.586104192,75.95067506
,29.4,4.649739308,0.103279792,49554.25518,1.579124642,76.55991064
,29.6,4.866095929,0.104284241,50010.83871,1.57650729,77.15380656
,29.8,4.518334904,0.105335765,50557.7003,1.569527765,77.67647754
,30,4.839107978,0.106353869,51252.01334,1.560803292,78.34707602
,30.2,4.963104409,0.107395249,51674.91034,1.558622171,78.93330149
,30.4,4.608266143,0.108478637,52082.40332,1.556004869,79.47021711
,30.6,4.919049834,0.109529021,52717.72505,1.550333953,80.14848576
,30.8,4.812985022,0.11061739,53144.32083,1.550333963,80.78840236
,31,5.26105016,0.11168031,53405.22958,1.555132369,81.41407543
,31.2,5.092995697,0.112794464,53536.39224,1.562548163,81.97400236
,31.4,5.168724106,0.113903855,53511.78228,1.572581269,82.42216337
,31.6,5.207841446,0.115026772,53642.28665,1.580869489,83.03139921
,31.8,5.146281423,0.116167543,53962.71371,1.583486829,83.64720946
,32,5.004012728,0.117324959,54480.04419,1.579997064,84.26849834
,32.2,4.929136561,0.118489692,55109.33799,1.573453738,84.89636152
,32.4,5.259456949,0.119639407,55723.03564,1.566474153,85.48258765
,32.6,5.087229634,0.120833749,56317.8593,1.562111946,86.18824885
,32.8,5.30688634,0.122014321,56655.13121,1.564293039,86.86103866
,33,5.475787345,0.123210148,56559.32212,1.575198581,87.3322107
,33.2,5.452487635,0.124430486,56355.53523,1.590030141,87.86912718
,33.4,5.719564258,0.125644192,56173.57457,1.604861674,88.43672523
,33.6,5.617217829,0.126894338,56084.85068,1.617512129,89.00870544
,33.8,5.640505857,0.128148833,56281.20532,1.620129462,89.46672813
,34,5.925881211,0.129398558,57012.93075,1.611841214,90.13403938
,34.2,5.967469909,0.130676885,57859.36671,1.600499432,90.78600945
,34.4,5.989087849,0.131969422,58713.56773,1.590466319,91.50372453
,34.6,6.054801302,0.133271963,59603.99604,1.57999698,92.25650357
,34.8,6.445836207,0.134566272,60061.14466,1.577379612,92.81204872
,35,6.350963785,0.135905654,60440.10166,1.578688288,93.4914124
,35.2,6.494881713,0.137242683,60776.30783,1.580433165,94.129138
,35.4,6.298497436,0.138615496,61032.75271,1.584795406,94.82384167
,35.6,6.477356274,0.139977468,61225.4348,1.590466279,95.48457826
,35.8,6.760216626,0.141346264,61397.85318,1.594828477,96.03026143
,36,6.659509178,0.142754103,61705.27771,1.59744582,96.69538018
,36.2,6.777623244,0.144161683,61850.71825,1.602680477,97.28270146
,36.4,6.785906027,0.145597805,62287.48856,1.602680477,97.95768218
,36.6,6.715144844,0.147046434,62868.5184,1.600063151,98.66772685
,36.8,6.913960083,0.148484497,63740.03605,1.591338689,99.42708065
,37,7.032064985,0.149949717,64366.75815,1.586540235,100.0385083
,37.2,6.922191463,0.151444667,65142.53699,1.580433134,100.7803295
,37.4,6.877213853,0.152950373,65820.14382,1.576943361,101.5626933
,37.6,6.739046537,0.154477315,66189.06799,1.579996929,102.3209505
,37.8,6.810548226,0.156005759,66278.75745,1.586976479,102.9027929
,38,6.954434046,0.157544766,66182.3262,1.599626912,103.570104
,38.2,7.140750898,0.159096522,66099.29473,1.610968673,104.1672872
,38.4,7.026702627,0.160683607,66151.41877,1.620129351,104.8236398
,38.6,7.026639871,0.162279082,66034.97104,1.632779796,105.4350672
,38.8,7.213781198,0.163878309,65938.00072,1.642812891,105.9303458
,39,7.270291328,0.16550227,66035.78543,1.649792442,106.5428691
,39.2,7.150408628,0.167154056,65969.58543,1.659389343,107.0688278
,39.4,7.508940237,0.168791014,65753.1278,1.672912199,107.6156071
,39.6,7.472255213,0.170470499,65722.80985,1.68207287,108.1996407
,39.8,7.482993189,0.172163733,65761.83793,1.687743758,108.6488974
,40,7.426334099,0.173878247,65827.24284,1.693850875,109.1989627
,40.2,7.52276568,0.175600005,65948.58316,1.697776867,109.7325924
,40.4,7.687836937,0.177334583,66127.50164,1.701266629,110.3385415
,40.6,7.415257941,0.179115243,66234.06988,1.704756434,110.7965634
,40.8,7.686823392,0.180877922,66498.73904,1.706501298,111.4014171
,41,8.24626821,0.182639395,66644.37195,1.709554799,111.8550586
,41.2,9.638987656,0.184363668,66930.56571,1.710863334,112.3886922
,41.4,9.577732927,0.186201059,67607.89735,1.704320006,113.0417578
,41.6,9.669152676,0.188046742,68517.60753,1.691233332,113.6509941
,41.8,9.812987311,0.189907626,69872.03567,1.670730876,114.4749973
,42,9.881936339,0.191792067,71146.84572,1.651100874,115.1773718
,42.2,10.18509863,0.193679994,72918.17783,1.623618851,116.069312
,42.4,10.26943416,0.195601441,74958.9365,1.593955737,117.139858
,42.6,9.999322116,0.197565462,76530.17892,1.573017097,118.0186473
,42.8,10.09613191,0.199524916,78448.91499,1.549024873,119.1297362
,43,9.953730119,0.20151991,80065.05854,1.52983111,120.0742705
,43.2,10.36420865,0.203498586,81405.3492,1.517616856,121.1064666
,43.4,10.7376587,0.205499597,82235.12856,1.515435713,122.1967373
,43.6,10.77870983,0.207542615,82607.23916,1.518489266,123.0284102
,43.8,10.63421515,0.209618388,82762.25338,1.528086165,124.0375938
,44,10.83833744,0.211692077,82718.89736,1.538119258,124.7848947
,44.2,10.64183432,0.213812872,82801.83646,1.547279941,125.659301
,44.4,10.76441105,0.215934043,83510.56668,1.547716155,126.7331346
,44.6,10.83789466,0.21807973,84250.8682,1.545098815,127.6163078
,44.8,11.36732691,0.220216975,85212.1258,1.540736551,128.7405471
,45,11.20284331,0.2224213,85657.53388,1.542045229,129.5787937
,45.2,11.54339797,0.224614547,86187.29784,1.54379009,130.5540108
,45.4,11.46668644,0.226857274,86145.22853,1.556004317,131.5467585
,45.6,11.44696532,0.229118869,86062.86667,1.566473652,132.3324097
,45.8,11.30368423,0.231411304,85997.60161,1.579124107,133.2868057
,46,11.48530693,0.233705411,86191.75392,1.58479498,134.0220534
,46.2,11.5288091,0.236031655,86712.39379,1.586539865,134.9402905
,46.4,11.64594215,0.238376377,87449.66858,1.585667411,135.9911135
,46.6,11.56837661,0.240757472,87983.63666,1.587194196,136.9153766
,46.8,11.78784171,0.243142987,88522.42556,1.589157176,137.8538858
,47,11.82633663,0.245564378,88872.43767,1.593737506,138.7403461
,47.2,11.90684515,0.248007379,89024.91328,1.601153275,139.6158492
,47.4,11.72942071,0.250491829,89208.32939,1.607914735,140.4803939
,47.6,11.9667589,0.252973932,89558.32791,1.612713157,141.4304085
,47.8,12.01563846,0.255493535,89912.82409,1.615330486,142.2303048
,48,11.89186794,0.258049724,90237.55152,1.620565164,143.2022328
,48.2,11.88998563,0.260623537,90328.93582,1.628853385,144.0360972
,48.4,12.31201813,0.263195335,90425.01393,1.635396678,144.7395691
,48.6,12.14122566,0.265831997,90438.58391,1.645429803,145.6347947
,48.8,12.24125449,0.268477423,90404.78085,1.653718015,146.3075844
,49,12.29426944,0.271152514,90358.88525,1.663751119,147.1304914
,49.2,12.41384245,0.273850188,90349.67204,1.672039328,147.8766965
,49.4,12.68900063,0.276564669,90214.80449,1.681636189,148.5166146
,49.6,14.50673663,0.279204823,90532.62462,1.685125795,149.3570609
,49.8,14.4532347,0.281994771,91304.1726,1.68076358,150.2479041
,50,14.91309034,0.284778767,92154.13834,1.673783985,151.0412278
,50.2,14.98355187,0.287616459,93601.16417,1.658516208,152.0295928
,50.4,15.73044855,0.290438142,95901.64408,1.631470373,153.2897065
,50.6,15.64198346,0.293343261,97616.39608,1.613149057,154.336146
,50.8,15.57348243,0.296276251,99576.01307,1.593955294,155.6159794
,51,15.79785098,0.29921935,101247.0364,1.578687504,156.6898138
,51.2,15.75846159,0.30220944,103057.4321,1.563855959,157.9532114
,51.4,15.79145396,0.305224736,104282.3677,1.559493737,159.3042691
,51.6,15.9126366,0.308264562,104983.1987,1.559929949,160.3485178
,51.8,16.39325094,0.3113114,105295.8271,1.567345682,161.5450769
,52,15.87792159,0.314454315,104986.9357,1.580432388,162.431535
,52.2,16.23039356,0.317571733,104434.6925,1.597445016,163.3684013
,52.4,16.17017413,0.32074763,104182.0974,1.610967905,164.4257981
,52.6,16.07916456,0.323957332,104149.4008,1.619692354,165.2881515
,52.8,16.22444612,0.327183821,104453.3888,1.62579945,166.3915708
,53,16.30565629,0.330446908,104984.1967,1.626671887,167.3065206
,53.2,16.50417735,0.333735088,105517.847,1.62885298,168.3233761
,53.4,16.68022836,0.337057832,105865.7949,1.63452385,169.3873485
,53.6,16.63412231,0.340428457,105914.2909,1.641939629,170.2069682
,53.8,16.69617466,0.343825867,105710.3278,1.655026284,171.1898547
,54,16.60928837,0.347267295,105647.7681,1.664186955,171.9623569
,54.2,16.90595921,0.350735517,105646.3974,1.67334759,172.842244
,54.4,16.96882709,0.354236621,105621.4871,1.683380691,173.7856835
,54.6,17.08577412,0.357751423,105762.8168,1.688615344,174.5275059
,54.8,17.44732924,0.361303306,105613.2076,1.699520861,175.4117766
,55,17.68074624,0.364899117,105375.5124,1.709117723,176.0593649
,55.2,17.7535759,0.36854154,105025.7782,1.72089571,176.7672187
,55.4,17.78895844,0.37222308,105161.0828,1.726566593,177.6262855
,55.6,18.49411846,0.37589739,105550.2105,1.727002747,178.331951
,55.8,18.838172,0.379632509,107050.0143,1.713479834,179.3959243
,56,19.18221956,0.383405239,108419.3467,1.700829365,180.2999187
,56.2,18.84982155,0.387260284,110462.3601,1.680763188,181.4537395
,56.4,18.97087317,0.391124228,112149.5404,1.667240296,182.7237126
,56.6,18.96628226,0.395035198,113244.6584,1.659824524,183.7252265
,56.8,19.34774654,0.398960077,114084.1038,1.657207158,184.868094
,57,19.483756,0.402940527,114843.8814,1.656334702,186.020822
,57.2,19.44669708,0.40697244,115144.1254,1.660696925,186.9982292
,57.4,19.30063592,0.411052006,115341.7976,1.665931603,187.8781144
,57.6,19.81187113,0.415129282,115655.5532,1.671602441,188.9442803
,57.8,19.81181801,0.41928129,115761.6716,1.677709549,189.7562299
,58,19.93281847,0.423467084,115911.5884,1.684689089,190.7654147
,58.2,20.18860092,0.427686124,116032.8262,1.691232394,191.7000895
,58.4,20.11572522,0.431969113,116466.9557,1.692104846,192.5240918
,58.6,20.32739657,0.436276389,117002.5635,1.693413492,193.5880647
,58.8,20.24452281,0.440646241,117462.371,1.694285944,194.4569928
,59,20.54271133,0.445034869,117991.8135,1.695594582,195.5111045
,59.2,20.42903852,0.449494732,118740.1853,1.693413482,196.5246709
,59.4,20.86241759,0.453963433,119644.0454,1.689487442,197.5678262
,59.6,20.64847104,0.458519632,121019.1453,1.679890579,198.7008287
,59.8,21.0643631,0.463080052,122299.5902,1.67225666,199.8678031
,60,21.2951214,0.467698762,123108.6931,1.670729862,200.9734142
,60.2,21.75426426,0.4723487,123703.8999,1.672038486,202.0450592
,60.4,21.94299033,0.477063077,123744.7188,1.680762904,203.1287555
,60.6,22.64174252,0.481791357,123575.0633,1.6899235,203.9363261
,60.8,22.57127652,0.486617683,123188.7936,1.703010163,204.8863396
,61,22.83195026,0.491470814,123614.358,1.704318804,205.7355461
,61.2,23.1920437,0.496366108,124481.415,1.701265219,206.8071902
,61.4,23.34287408,0.501324297,125780.232,1.69384943,208.0420996
,61.6,23.53404995,0.506329606,126750.1389,1.689050973,209.0556681
,61.8,24.15537666,0.511357003,128432.0258,1.678145369,210.4165913
,62,24.22298022,0.516471289,129081.3804,1.677709144,211.4192016
,62.2,24.47362194,0.521624893,129297.2104,1.682943786,212.4623557
,62.4,24.97968822,0.526813578,129783.5692,1.685997292,213.6402883
,62.6,24.90207806,0.532092846,130168.391,1.688614629,214.5946847
,62.8,25.02955455,0.537411637,130182.3018,1.696466612,215.6805721
,63,25.11958126,0.542786304,130845.4239,1.695157939,216.6305866
,63.2,25.18297447,0.548216724,132263.2545,1.686869715,217.8676871
,63.4,25.33871419,0.553695581,133150.8363,1.685124818,219.113554
,63.6,25.38586541,0.559236699,133545.1215,1.687742145,220.0942489
,63.8,25.24829742,0.564845608,134522.4362,1.685997271,221.3883273
,64,25.56500813,0.570481018,134603.3667,1.692104347,222.2879389
,64.2,25.35753177,0.576207482,134085.5251,1.705627243,223.2028874
,64.4,25.83730196,0.581946271,134204.0363,1.713042968,224.3030218
,64.6,25.76085181,0.587779304,134789.6771,1.713042976,225.2300247
,64.8,25.84788598,0.593660159,135343.1283,1.715224077,226.3871358
,65,26.10838873,0.59958877,135888.1939,1.715660275,227.2998958
,65.2,27.03408888,0.605533246,136723.4037,1.713915299,228.389076
,65.4,27.79004566,0.611548567,137234.9368,1.716096336,229.5450956
,65.6,28.06466427,0.617656108,137798.0394,1.71609631,230.509356
,65.8,28.07052793,0.62384255,138714.927,1.71347898,231.7322115
,66,28.45911483,0.630065971,139524.6034,1.710425391,232.7534518
,66.2,28.77572134,0.636356598,140743.5585,1.703882036,233.9949373
,66.4,28.71416085,0.642735129,142543.172,1.692540277,235.4391331
,66.6,28.95960872,0.649157427,143490.2834,1.689050481,236.5370752
,66.8,29.10104277,0.655651065,144187.0474,1.689922912,237.8388258
,67,29.24413051,0.662209874,144831.1092,1.69035912,238.9104686
,67.2,29.23494655,0.668844603,145766.0875,1.689050457,240.1727712
,67.4,29.2989705,0.675541142,146286.219,1.692540225,241.469042
,67.6,29.99449339,0.682263393,146970.2103,1.69254016,242.531923
,67.8,30.10425746,0.689091866,148263.4016,1.688614155,243.9410564
,68,30.0700697,0.695998403,148966.3859,1.688614159,245.0510495
,68.2,30.03753498,0.702974179,149325.6755,1.692976379,246.2596606
,68.4,30.50254215,0.70998721,149611.5375,1.698647217,247.5296363
,68.6,31.49005195,0.71703636,149727.7365,1.703881784,248.4818483
,68.8,31.93922808,0.724191769,149920.4575,1.709552623,249.7288137
,69,32.07971023,0.731439464,150517.2145,1.710425053,250.949479
,69.2,32.50223845,0.738741263,151509.5595,1.707371462,252.1964437
,69.4,32.74420484,0.746128339,152641.1456,1.70213678,253.3513651
,69.6,33.09931526,0.753582299,154363.4499,1.692976093,254.8755535
,69.8,32.88281033,0.761148623,155401.8621,1.689922563,256.0480038
,70,32.86930821,0.768777745,156321.6296,1.690795008,257.4834344
,70.2,32.89989142,0.776480519,156408.2221,1.698210773,258.6241087
,70.4,33.31485943,0.784235349,155839.5649,1.711297382,259.5467324
,70.6,33.15321943,0.792105993,154407.2815,1.733980923,260.4835965
,70.8,33.36348349,0.800031425,153404.8362,1.751429767,261.4040268
,71,33.6269847,0.808033006,152836.0286,1.762335282,262.132702
,71.2,33.93789874,0.816111815,152770.9543,1.768878576,263.0575162
,71.4,33.82779356,0.824299504,153358.5154,1.768006144,263.9746568
,71.6,34.77268716,0.832500088,154552.3858,1.762335171,265.1876577
,71.8,34.79984049,0.84084335,155975.6514,1.754919402,266.4905033
,72,35.73222048,0.849253218,156636.4687,1.753610646,267.4208011
,72.2,36.16121661,0.857738744,157508.6674,1.750993275,268.5450426
,72.4,36.6126708,0.86626485,158753.8577,1.745322352,269.8632319
,72.6,36.55656732,0.874953195,160492.537,1.733980598,271.0860874
,72.8,36.69431253,0.883716102,162330.1912,1.72394749,272.5949343
,73,37.15903079,0.892545617,164464.762,1.7108608,273.9350393
,73.2,37.58546168,0.901466194,166464.4692,1.700827665,275.4186863
,73.4,37.68905138,0.910497738,167422.5851,1.701263877,276.8957563
,73.6,38.34675738,0.919583564,167114.4403,1.710860688,277.8600205
,73.8,38.40122848,0.928800362,166366.6435,1.726128435,279.0006956
,74,38.48480584,0.938107913,165777.324,1.737470186,279.8630506
,74.2,38.75141452,0.947496889,165573.325,1.746194591,280.9193547
,74.4,38.89070791,0.956988588,166128.4916,1.748375685,282.1575527
,74.6,39.31786784,0.966556713,167200.2053,1.74444965,283.2763151
,74.8,39.90476187,0.976210418,169141.7751,1.733980279,284.7796872
,75,40.18961427,0.985981174,170222.8883,1.73049048,285.9554281
,75.2,40.94745897,0.995818939,171286.8243,1.727873079,287.2944397
,75.4,41.50934528,1.005768945,172824.3431,1.721765925,288.7989075
,75.6,41.58239928,1.015850936,174020.2705,1.718494257,290.1746212
,75.8,41.63671656,1.026035436,175111.4199,1.716095035,291.5108874
,76,42.12824829,1.036293218,176953.1558,1.708243003,293.1380791
,76.2,42.13261129,1.046686077,178492.9518,1.702572125,294.6184359
,76.4,42.52260264,1.057157952,179856.1818,1.697773653,296.0012745
,76.6,42.65340057,1.067752091,182304.703,1.685559443,297.8519955
,76.8,42.68766635,1.07845896,184655.4352,1.673345239,299.4660342
,77,42.95321877,1.08925824,187084.7207,1.662439677,301.4230448
,77.2,43.74667563,1.100131243,188986.6068,1.655460065,303.2299409
,77.4,44.08374783,1.111143503,189471.5485,1.6589498,304.6577049
,77.6,44.95080414,1.122231602,188646.784,1.674653692,306.2279216
,77.8,45.78123349,1.133433411,187049.3244,1.69384735,307.2371128
,78,46.04004186,1.144785446,185201.643,1.716967057,308.4457272
,78.2,46.48687036,1.156239114,184159.2836,1.73267098,309.5655867
,78.4,47.05848472,1.167799681,184506.801,1.735724473,310.690926
,78.6,47.45202666,1.179488153,185192.2532,1.73746932,312.1351269
,78.8,47.45241687,1.191319846,186042.8378,1.736596878,313.3590787
,79,47.91539556,1.203239953,187152.5236,1.73485195,314.874504
,79.2,48.40664413,1.21527812,187955.2813,1.735288124,316.2321416
,79.4,49.13708139,1.2274215,188211.2461,1.739214044,317.385972
,79.6,49.35538624,1.239720654,190060.397,1.731798264,319.0734278
,79.8,49.82910392,1.252126533,192286.8106,1.720456467,320.541736
,80,49.87555564,1.264685064,195048.9346,1.706933609,322.4088927
,80.2,50.03722312,1.277362179,197312.5157,1.697336726,324.2026356
,80.4,50.41852561,1.290152335,199745.6614,1.687739825,326.1936155
,80.6,50.99450211,1.303058112,200728.4901,1.687303547,327.658638
,80.8,51.44648587,1.31610185,200807.5811,1.695155488,329.3055526
,81,51.58269438,1.329297258,201023.6053,1.70039013,330.6040171
,81.2,52.39864826,1.34258049,202150.1713,1.699953832,332.2257341
,81.4,52.72618077,1.356029485,203738.0079,1.697336474,334.1246702
,81.6,53.08905297,1.369611186,204963.2284,1.695591555,335.6488611
,81.8,53.37785301,1.383334336,206875.0449,1.690356875,337.5982021
,82,53.72487306,1.39719149,208067.9499,1.688175737,339.1234888
,82.2,54.10764814,1.411185515,209372.2723,1.685994596,340.8536808
,82.4,54.36726083,1.425328235,210534.0289,1.685994572,342.7876806
,82.6,54.75872722,1.439604543,212109.1733,1.681632324,344.472947
,82.8,55.14185056,1.454024751,214074.2525,1.676397635,346.5570661
,83,55.39973075,1.468598011,216166.6182,1.669418074,348.3540978
,83.2,55.83855361,1.483305707,218227.2727,1.66374716,350.3691855
,83.4,56.67298193,1.498135224,220790.8309,1.655458883,352.7053312
,83.6,56.95325637,1.513150303,222638.7231,1.651969089,354.9253224
,83.8,57.13491175,1.528321834,223844.4115,1.65109663,356.7037257
,84,57.76999771,1.543616021,224453.9491,1.655458782,358.7582628
,84.2,57.97074105,1.559092401,223911.3961,1.66680051,360.4983149
,84.4,58.37281024,1.574711012,222870.9331,1.680759546,361.8855376
,84.6,58.69581191,1.590491711,220964.9434,1.701698124,363.390005
,84.8,59.59039101,1.606393359,219097.8703,1.720891762,364.5000088
,85,59.99654476,1.622486991,217678.6053,1.738340562,365.8696991
,85.2,60.77292483,1.638717987,217345.3713,1.747501126,367.2043309
,85.4,61.15989031,1.655137611,218147.9199,1.749245973,368.8413848
,85.6,61.60257538,1.671718449,220059.2348,1.741830174,370.3644814
,85.8,62.15422951,1.688458691,222709.3826,1.731360819,372.3686127
,86,62.7166732,1.705366549,224354.1749,1.726562334,373.9223919
,86.2,63.27160164,1.722444747,226376.6721,1.720455189,375.7621617
,86.4,63.70086672,1.739702822,227965.1646,1.718274043,377.7268447
,86.6,64.46291498,1.757112433,228343.8728,1.723944842,379.4537546
,86.8,64.81557819,1.774723892,228430.5619,1.729615679,380.756605
,87,65.0018079,1.79252317,228796.6609,1.734850312,382.4648812
,87.2,65.59736639,1.810474361,228731.083,1.741829787,383.9386707
,87.4,65.96658491,1.828620768,229047.352,1.745319518,385.2754888
,87.6,66.62864786,1.846930266,229832.4871,1.746628116,386.9640466
,87.8,66.73821575,1.865460234,230951.6861,1.746191885,388.743546
,88,68.03089612,1.884098319,232114.2851,1.744446876,390.2315877
,88.2,68.27685704,1.902992565,233874.87,1.739648424,391.9935559
,88.4,68.76490757,1.922060662,235005.1721,1.740084597,393.8629107
,88.6,69.19218966,1.941324465,236007.3847,1.739648335,395.3783379
,88.8,69.94642746,1.960760241,237395.2322,1.737903379,397.2696106
,89,70.41275299,1.980410138,237850.1051,1.740520659,398.7181976
,89.2,71.0412923,2.000246935,238756.3076,1.740956818,400.3947013
,89.4,71.80209213,2.020274285,239921.8617,1.740520524,402.2837825
,89.6,72.09026885,2.040534096,240288.4966,1.744010261,403.6797715
,89.8,72.54065834,2.060987072,240772.5871,1.747936204,405.3343592
,90,73.05674516,2.081641714,241751.7206,1.747936153,406.7818508
,90.2,73.56364667,2.102504616,241686.4883,1.755351855,408.2468737
,90.4,74.11211618,2.12357435,242156.2383,1.759714008,409.9102288
,90.6,74.74957884,2.144849963,243153.1238,1.759277725,411.368679
,90.8,75.26469964,2.166347275,243440.2357,1.764512321,412.9487565
,91,76.05934695,2.188042207,243710.0925,1.76974689,414.5715719
,91.2,76.9438184,2.209949261,244430.428,1.771055464,416.0135888
,91.4,77.15098541,2.23212107,244478.0518,1.777598752,417.5027162
,91.6,77.52036216,2.254504813,244630.5939,1.781960921,418.6642157
,91.8,77.92132014,2.277111497,244713.4271,1.787631748,420.0908865
,92,78.7632159,2.299916313,245041.5425,1.791557649,421.5241378
,92.2,79.29140133,2.32297089,246287.8472,1.789376494,423.0132684
,92.4,79.6539767,2.346268064,248601.8494,1.779779607,424.5637596
,92.6,80.23450575,2.369784744,251438.2661,1.768437817,426.5755641
,92.8,80.93813695,2.393530509,254998.0483,1.75229759,428.4460179
,93,81.83434418,2.417502551,260357.3977,1.727869158,431.0177547
,93.2,82.47799318,2.441732001,264632.2313,1.710420279,433.4930618
,93.4,83.2285188,2.466197854,266414.1382,1.706494224,435.4500812
,93.6,83.93948412,2.490911907,268211.068,1.703876834,437.8059531
,93.8,84.41661068,2.515889473,268398.4544,1.708893323,439.6665434
,94,84.98189212,2.541111927,267845.3334,1.717835786,441.4241332
,94.2,85.74806753,2.566574514,267119.2841,1.728305001,443.1203645
,94.4,86.68393553,2.592281709,266920.5662,1.737029317,444.9579497
,94.6,87.26199132,2.618270731,266647.1762,1.744881226,446.4306456
,94.8,87.91322386,2.644516052,266825.2928,1.751424465,448.2112486
,95,88.50242854,2.671029096,266772.2696,1.757967711,449.6291563
,95.2,89.26423621,2.697797132,266815.4088,1.764074721,451.2443021
,95.4,89.71107936,2.72485483,267129.4474,1.768873097,453.053392
,95.6,90.39958275,2.752168515,267923.215,1.76974547,454.561154
,95.8,90.94493406,2.779766149,268514.2976,1.773235177,456.3549043
,96,91.33839662,2.807650898,269148.9712,1.774980019,457.7585652
,96.2,91.91652436,2.835803525,270500.6869,1.773671301,459.4712315
,96.4,92.70843767,2.864225045,273110.7762,1.766255482,461.5739871
,96.6,93.5518911,2.892928917,275225.7968,1.760148315,463.3019967
,96.8,94.37200197,2.921922593,278163.8658,1.750987612,465.5800729
,97,94.89336935,2.951227183,280819.8468,1.742917493,467.6872083
,97.2,95.6826021,2.980808608,282298.0016,1.74139064,469.6913466
,97.4,96.50257249,3.010685391,283182.8595,1.742699221,471.5497503
,97.6,97.59207137,3.040844488,284426.2947,1.743135334,473.6974364
,97.8,97.96930831,3.07135361,285197.0128,1.744880179,475.3575038
,98,98.43261117,3.102163423,285985.5535,1.747933677,477.3495837
,98.2,99.6721444,3.133231726,287091.7894,1.748805996,479.2682611
,98.4,100.6141789,3.164631931,287709.3488,1.751423222,480.9480594
,98.6,101.1692715,3.196373005,288038.0147,1.756657808,482.9061732
,98.8,102.4980967,3.22838211,288291.9117,1.760583657,484.4884554
,99,103.1520984,3.260757231,289679.7509,1.759274933,486.5901146
,99.2,103.6662682,3.293466859,291653.977,1.754476463,488.6457503
,99.4,104.4437216,3.326487828,294939.6025,1.74400711,491.1484559
,99.6,105.3168051,3.359834302,297933.9303,1.733973967,493.2150545
,99.8,106.0017977,3.393528157,302205.261,1.720014866,496.0289521
,100,106.8939106,3.427546911,304480.7789,1.715216362,498.1415724
,100.2,107.81301,3.461905728,306728.8898,1.711726515,500.5599087
,100.4,108.6646604,3.496614182,308191.0697,1.713035093,503.0998707
,100.6,109.4596777,3.531675016,307312.7817,1.72394051,504.8267863
,100.8,110.5654002,3.56706769,306896.5932,1.733973457,506.9974845
,101,111.4052343,3.602833543,306654.52,1.740952891,508.6542718
,101.2,112.54038,3.638938261,306320.3132,1.749240955,510.5488428
,101.4,113.4208687,3.675421671,305970.8762,1.757965262,512.5354524
,101.6,114.2089443,3.712277768,306709.6429,1.759710062,514.1889526
,101.8,115.0909797,3.749497903,306510.3789,1.767561929,516.162413
,102,115.6925635,3.787110454,306355.9337,1.774977603,517.9682202
,102.2,116.4887808,3.82508817,307638.8391,1.774541304,519.87703
,102.4,117.2907617,3.863446987,308777.5868,1.774105004,521.6094245
,102.6,118.6834186,3.902152359,310633.3152,1.771051329,523.8294374
,102.8,119.3563125,3.941293932,312489.9669,1.767125286,525.7108526
,103,120.5375107,3.980795412,314933.4452,1.761454316,528.0963209
,103.2,121.5073116,4.020707715,315178.3022,1.765816415,529.9886972
,103.4,122.2282734,4.061037292,315369.9459,1.769742318,531.6158999
,103.6,122.9774597,4.101770184,315422.6709,1.775849316,533.5718271
,103.8,124.2690606,4.142876534,315142.5447,1.782392478,535.076314
,104,125.2153058,4.184418727,314257.3853,1.792861649,536.7462532
,104.2,126.2030857,4.226375724,314761.9144,1.796351304,538.4731718
,104.4,127.2515364,4.268750222,315413.4829,1.798096076,539.9656014
,104.6,128.2658063,4.311552713,317391.8104,1.794169999,542.0124815
,104.8,129.2666955,4.354786044,320211.4798,1.785009294,543.9267749
,105,130.0628376,4.3984672,324757.9006,1.769305321,546.5927515
,105.2,131.0153305,4.442576936,329066.67,1.754909991,549.167782
,105.4,131.8105004,4.487140115,333566.3007,1.740078459,551.6956936
,105.6,132.7145942,4.532143789,338770.1925,1.724810699,554.828462
,105.8,133.7975011,4.577587885,342443.5704,1.716958649,557.7694762
,106,135.427807,4.623452611,344290.764,1.715649834,560.0935929
,106.2,136.3549795,4.669824347,345351.3819,1.718703279,562.5469955
,106.4,137.1838992,4.716668523,345126.7407,1.72742758,564.9675243
,106.6,138.1616762,4.763973581,343746.8657,1.7392054,566.7569033
,106.8,139.0270545,4.811761224,342803.1339,1.750110792,568.9396553
,107,140.3674417,4.859997896,343075.5333,1.75447285,570.7673903
,107.2,141.5263318,4.908976414,344674.5124,1.754472735,573.5385661
,107.4,142.4480558,4.958217636,346932.3802,1.749674236,575.6709145
,107.6,143.6542528,5.007936655,349843.3695,1.744003271,578.5166033
,107.8,144.7846964,5.05790773,351639.1426,1.741385847,580.7136041
,108,145.9233401,5.108633087,354133.4305,1.737459766,583.5242275
,108.2,146.9346032,5.159876364,356507.9822,1.734406135,586.1387085
,108.4,148.1354857,5.211622142,357507.7996,1.736150893,588.2798287
,108.6,149.4827214,5.263878213,359339.9723,1.736150761,591.0553913
,108.8,150.8207214,5.316659881,360620.3831,1.737023068,593.214046
,109,151.8940537,5.369989372,361579.0644,1.740076494,595.8449649
,109.2,152.7784316,5.423867084,361297.1537,1.747492126,598.044155
,109.4,154.5205388,5.478229682,362828.7663,1.748364392,600.7090546
,109.6,155.525387,5.533187037,364834.3816,1.745746981,602.8950979
,109.8,156.7706018,5.588680758,367902.303,1.740948454,605.8251611
,110,158.0648173,5.644728813,370706.6544,1.736149923,608.2292643
,110.2,159.4750102,5.701333209,375089.4393,1.726116759,611.1878203
,110.4,160.4483005,5.758537122,377765.1468,1.723935571,614.3523709
,110.6,161.9822824,5.816278802,378586.7771,1.726988952,616.633754
,110.8,163.218308,5.874620414,378307.6195,1.735713201,619.3096041
,111,164.4296957,5.93354953,378708.0233,1.739639048,621.4485346
,111.2,166.0257996,5.993044979,379300.6723,1.743564857,623.9578373
,111.4,167.3235284,6.053157346,382258.9762,1.738766328,627.1092446
,111.6,168.4722292,6.113883119,385698.4223,1.730914285,629.768657
,111.8,169.7364841,6.17521111,391817.1733,1.714337867,633.4350682
,112,171.3114012,6.23713442,396788.757,1.703432259,637.1168263
,112.2,172.3832621,6.299712798,399862.1053,1.699506192,640.3712324
,112.4,173.9767007,6.362885479,401253.6252,1.700814694,643.0503781
,112.6,175.1494513,6.426720587,400587.1221,1.710847599,646.1064544
,112.8,176.7335345,6.491170089,399636.7377,1.720444242,648.2442978
,113,178.2738335,6.556269914,399695.7306,1.7278598,651.106433
,113.2,179.8710219,6.62202009,400236.3166,1.732658043,653.8261221
,113.4,180.9601561,6.688464353,402780.3314,1.729604409,656.3891091
,113.6,182.3412235,6.755556952,408162.6841,1.719135043,660.0456635
,113.8,184.3395436,6.823283151,411425.4895,1.716081327,663.4282912
,114,185.8501908,6.891721851,412470.1937,1.719134707,665.9507438
,114.2,186.8764922,6.96088003,414397.9795,1.720443259,669.009011
,114.4,188.56414,7.030689446,414227.1716,1.729167448,671.9708646
,114.6,190.1231288,7.101208906,411960.0693,1.743126268,673.9235269
,114.8,191.293035,7.172462429,410077.1207,1.756648906,676.2925683
,115,192.5568458,7.244425716,409499.1056,1.764064479,678.3416517
,115.2,194.2020231,7.317086897,409207.3299,1.771043799,680.6175635
,115.4,195.4780829,7.390502526,409145.1115,1.777150721,683.0611185
,115.6,197.0369125,7.464637177,411264.3585,1.775405692,685.8575124
,115.8,198.8273412,7.53950151,414163.351,1.769734686,688.3744925
,116,200.3900926,7.61513295,418770.0055,1.759265309,691.7089016
,116.2,201.9581312,7.691524053,420767.7096,1.757520284,694.5085836
,116.4,203.8176708,7.768663496,423903.5915,1.751849272,697.2556748
,116.6,205.0805284,7.846617241,426685.6042,1.748795626,700.4410565
,116.8,206.7942165,7.925324535,428441.7284,1.748795456,703.0084424
,117,208.4878101,8.004824059,428529.0187,1.756210984,705.8475747
,117.2,209.989496,8.085134759,429391.3651,1.76013679,708.4554992
,117.4,211.5696795,8.16624728,429693.8768,1.764935023,710.6459434
,117.6,213.7467075,8.248135589,431182.8191,1.767115892,713.588088
,117.8,215.4048401,8.3308809,432526.2119,1.767988161,715.8979709
,118,216.8727238,8.414470077,435944.6032,1.763189626,719.1447213
,118.2,218.6990745,8.498875376,439518.2135,1.757082405,722.1383599
,118.4,220.1916503,8.584150756,443185.1034,1.750102784,724.9851592
,118.6,221.8309413,8.670272675,446556.6326,1.745304235,728.3294367
,118.8,223.9447623,8.757224899,449197.6304,1.742686725,731.6813931
,119,225.6549148,8.845077366,451659.5152,1.739633038,734.4909434
,119.2,227.4481287,8.933807084,454693.1621,1.736143127,737.8374157
,119.4,228.8243591,9.023455647,457363.2439,1.734834341,741.3964559
,119.6,230.6821854,9.11397317,460483.9371,1.730908208,744.4547463
,119.8,232.5556752,9.205399123,466272.7913,1.720875039,748.5342802
,120,234.303384,9.297751886,471971.3756,1.709969452,752.1020964
,120.2,236.2789183,9.391017557,476802.8221,1.702553578,756.0249411
,120.4,238.0729233,9.485232082,481720.1221,1.696010156,760.498946
,120.6,240.0697903,9.58038,483460.4738,1.696882397,763.8267977
,120.8,241.8668205,9.676497019,483092.0428,1.704734122,767.4242005
,121,243.8242767,9.773569182,480213.235,1.720437726,770.5789221
,121.2,245.6800714,9.871623375,480379.8661,1.726544575,773.7544606
,121.4,247.4899482,9.970665755,481231.4968,1.730034129,776.5826435
,121.6,249.312147,10.07070223,484318.3046,1.729161518,780.2030606
,121.8,251.2215478,10.17173812,486838.5948,1.728725115,783.3073789
,122,253.1582436,10.27378729,490931.7988,1.724362763,787.1392777
End Of Loading Marker,122.142,255.0548905,10.34682987,493452.6083,1.72305393,790.0211548
,122.4,256.8648721,10.34929777,497465.9557,1.720872674,794.7986902
,122.6,257.5456536,10.34925371,499359.9967,1.721308825,797.92928
,122.8,258.5209693,10.34919037,501494.7892,1.722617379,801.813756
,123,259.5378859,10.3491243,503085.5674,1.724362146,804.864363
,123.2,260.2244914,10.34907986,502082.7613,1.734395049,807.9171538
,123.4,260.8620078,10.34903863,499877.8891,1.748353901,810.8998137
,123.6,261.5128365,10.34899653,498738.6766,1.75795059,813.3543233
,123.8,261.8874353,10.34897251,499479.2079,1.763185146,816.5692779
,124,262.352724,10.34894256,501157.3094,1.764057533,819.3284021
,124.2,262.9353272,10.34890492,505294.029,1.758386667,822.7811409
,124.4,263.3490308,10.34887834,511846.9847,1.746608796,827.0414494
,124.6,263.7993432,10.34884937,516514.1236,1.740501729,831.1538318
,124.8,264.3727941,10.34881233,518178.6721,1.741374105,834.0795129
,125,264.5477087,10.34880139,518590.4971,1.747481112,837.6494895
,125.2,264.8890267,10.34877955,516678.753,1.75925891,840.4272377
,125.4,265.3618035,10.3487491,514682.6583,1.770600478,842.6647833
,125.6,265.6091036,10.34873342,511412.7245,1.787176659,845.1466757
,125.8,265.8380993,10.34871893,508612.8795,1.80069933,846.9820714
,126,266.3333405,10.34868701,507039.2211,1.811168463,849.2952237
,126.2,266.4857906,10.34867754,507530.4089,1.814658175,851.6817838
,126.4,266.3470346,10.34868712,508980.4838,1.815530622,854.4551385
,126.6,266.8822127,10.34865259,512415.7676,1.809423545,857.1222218
,126.8,267.0712715,10.34864072,517821.4732,1.798954346,860.6089214
,127,267.4142535,10.34861877,521089.6892,1.794155937,863.2738085
,127.2,267.6732018,10.34860232,522813.431,1.795028343,866.1096308
,127.4,267.8281479,10.34859268,523112.6215,1.800262919,868.9673659
,127.6,268.3466856,10.34855924,521372.4265,1.809859616,870.8608443
,127.8,268.3377243,10.34856033,516426.3244,1.829489331,872.6852781
,128,268.6757142,10.34853871,514137.2145,1.840176586,874.4100063
,128.2,268.7441305,10.34853473,511826.3066,1.850863865,876.0837754
,128.4,269.1212252,10.34851055,509864.5145,1.860460578,877.5493579
,128.6,268.9113317,10.34852479,508729.5713,1.86787627,879.2576352
,128.8,269.2464096,10.34850336,511053.3473,1.863950293,881.0853652
,129,269.6750894,10.3484758,512762.0089,1.863077817,883.3174303
,129.2,269.5987347,10.3484813,515255.8086,1.859151884,885.5177067
,129.4,269.5689729,10.34848375,517714.4109,1.854789729,887.5448544
,129.6,269.8770102,10.34846409,520747.6719,1.849991324,890.1483781
,129.8,269.920466,10.34846175,519137.6403,1.858715636,891.923503
,130,269.8936163,10.34846401,517235.1106,1.867439956,893.1671855
,130.2,270.318552,10.3484367,514450.156,1.879653956,894.3659534
,130.4,270.2575896,10.34844119,511297.7913,1.893176651,895.4321224
,130.6,270.6005716,10.34841924,507976.7902,1.906263089,895.9745291
,130.8,270.5142327,10.34842539,506178.6646,1.914987417,896.8401757
,131,270.7440603,10.34841085,505541.8834,1.919785768,897.8460846
,131.2,270.9143987,10.3484002,506803.4863,1.917822777,899.0147126
,131.4,270.9536944,10.34839813,508402.125,1.914987374,900.3849563
,131.6,271.4031746,10.34836921,512043.3797,1.905826791,902.2587104
,131.8,271.1346239,10.3483873,515199.0692,1.897974937,903.8979545
,132,271.433925,10.34836821,517256.2841,1.894485181,905.7870454
Unloading Marker,132.148,271.85312,10.34834114,517103.7836,1.897102438,906.8214496
,132.9,272.0467028,10.24383313,1.7977E+308,1.943341291,0
,133.1,271.8994324,10.14038067,1.7977E+308,1.890122983,0
,133.3,271.4522199,10.03694784,1.7977E+308,1.761439373,0
,133.5,271.3569505,9.933491979,1.7977E+308,1.56906822,0
,133.7,270.9326184,9.830057656,1.7977E+308,1.30886553,0
,133.9,270.9138947,9.726596781,1.7977E+308,0.910818608,0
,134.1,270.4017847,9.623168204,1.7977E+308,0.584529201,0
,134.3,270.2070893,9.519718849,1.7977E+308,0.328906733,0
,134.5,270.2187342,9.416255986,1.7977E+308,0.142642575,0
,134.7,270.0489993,9.312804997,1.7977E+308,0.02093836,0
,134.9,269.9433298,9.209349814,1.7977E+308,0.013958907,0
,135.1,269.683321,9.105904734,1.7977E+308,0.013086475,0
,135.3,269.506514,9.002454208,1.7977E+308,0.014395123,0
,135.5,269.3471793,8.899002538,1.7977E+308,0.015267555,0
,135.7,268.773084,8.795578018,1.7977E+308,0.018321066,0
,135.9,268.8816589,8.692108811,1.7977E+308,0.018321066,0
,136.1,268.8970479,8.588645703,1.7977E+308,0.020938361,0
,136.3,268.3479131,8.48521955,1.7977E+308,0.021374578,0
,136.5,268.2056348,8.381766763,1.7977E+308,0.023991874,0
,136.7,268.0874849,8.278312397,1.7977E+308,0.025300521,0
,136.9,267.7879553,8.174869904,1.7977E+308,0.018321068,0
,137.1,267.5450029,8.071423708,1.7977E+308,0.014395125,0
,137.3,267.5358473,7.967962207,1.7977E+308,0.010905398,0
,137.5,266.9567599,7.864538014,1.7977E+308,0.010032966,0
,137.7,266.7113113,7.761091981,1.7977E+308,0.014831341,0
,137.9,266.7346045,7.657628357,1.7977E+308,0.014395125,0
,138.1,266.5449011,7.554178675,1.7977E+308,0.010905398,0
,138.3,266.2744921,7.450734275,1.7977E+308,0.004798375,0
,138.5,266.192119,7.347277568,1.7977E+308,0.006107023,0
,138.7,266.067313,7.243823637,1.7977E+308,0.020502149,0
,138.9,265.5680992,7.140394216,1.7977E+308,0.028354037,0
,139.1,265.5581116,7.03693277,1.7977E+308,0.030098901,0
,139.3,265.1271232,6.933498882,1.7977E+308,0.02704539,0
,139.5,265.1445922,6.830035638,1.7977E+308,0.027481606,0
,139.7,264.7909814,6.726596686,1.7977E+308,0.023119447,0
,139.9,264.7552012,6.623136928,1.7977E+308,0.020065935,0
,140.1,264.382454,6.519699228,1.7977E+308,0.017448639,0
,140.3,263.9098647,6.416268064,1.7977E+308,0.020502152,0
,140.5,264.0188556,6.312798829,1.7977E+308,0.018321072,0
,140.7,263.4738807,6.209372403,1.7977E+308,0.013958912,0
,140.9,263.3865155,6.105916022,1.7977E+308,0.011777832,0
,141.1,263.2883341,6.002460349,1.7977E+308,0.012214048,0
,141.3,262.7458552,5.89903376,1.7977E+308,0.009596753,0
,141.5,262.6684742,5.795576725,1.7977E+308,0.007851889,0
,141.7,262.4063853,5.692131781,1.7977E+308,0.013086481,0
,141.9,262.1709209,5.588685095,1.7977E+308,0.020502154,0
,142.1,262.0752355,5.485229258,1.7977E+308,0.021810802,0
,142.3,261.8697238,5.381780611,1.7977E+308,0.020938371,0
,142.5,261.6026427,5.278335994,1.7977E+308,0.01439513,0
,142.7,261.3115154,5.174375638,1.7977E+308,0.002617296,0
,142.9,261.027794,5.07093211,1.7977E+308,0.007851889,0
,143.1,260.8555629,4.967481285,1.7977E+308,0.010905402,0
,143.3,260.5817435,4.864554422,1.7977E+308,0.013086483,0
,143.5,260.3354629,4.761108443,1.7977E+308,0.012214051,0
,143.7,260.0999985,4.657661757,1.7977E+308,0.005234593,0
,143.9,260.0209534,4.554204831,1.7977E+308,0.002617297,0
,144.1,259.8004653,4.450757164,1.7977E+308,0.005670809,0
,144.3,259.5192399,4.347313473,1.7977E+308,0.002617297,0
,144.5,259.0641228,4.243881165,1.7977E+308,0.006107026,0
,144.7,258.952629,4.140426363,1.7977E+308,0.013086484,0
,144.9,258.7179966,4.036979622,1.7977E+308,0.021810807,0
,145.1,258.5948546,3.933525583,1.7977E+308,0.030098914,0
,145.3,258.2175311,3.830088183,1.7977E+308,0.036205941,0
,145.5,257.6064106,3.726666087,1.7977E+308,0.034024861,0
,145.7,257.3884186,3.623218257,1.7977E+308,0.02399189,0
,145.9,257.2249237,3.519766859,1.7977E+308,0.010469188,0
,146.1,257.2174321,3.416305249,1.7977E+308,0.007851891,0
,146.3,256.7390184,3.312874466,1.7977E+308,0.01265027,0
,146.5,256.3812473,3.209435786,1.7977E+308,0.013086486,0
,146.7,256.475678,3.105967504,1.7977E+308,0.010032973,0
,146.9,256.2335574,3.002521253,1.7977E+308,0.011777838,0
,147.1,255.9893567,2.899075139,1.7977E+308,0.020938378,0
,147.3,255.5329915,2.795642912,1.7977E+308,0.027481622,0
,147.5,255.2858788,2.692196988,1.7977E+308,0.024646217,0
,147.7,254.9946691,2.588753951,1.7977E+308,0.020720271,0
,147.9,254.8661189,2.485300266,1.7977E+308,0.01046919,0
,148.1,254.3839611,2.381869728,1.7977E+308,0.009596758,0
,148.3,254.1181279,2.278425029,1.7977E+308,0.018321083,0
,148.5,253.9230163,2.174975701,1.7977E+308,0.032061896,0
,148.7,254.0078787,2.071508046,1.7977E+308,0.041004329,0
,148.9,253.3181324,1.968091097,1.7977E+308,0.043621629,0
,149.1,253.2994086,1.864630223,1.7977E+308,0.043621629,0
,149.3,252.7382089,1.761204859,1.7977E+308,0.044057846,0
,149.5,252.5139767,1.657757437,1.7977E+308,0.043185414,0
,149.7,252.3130409,1.55430849,1.7977E+308,0.044494064,0
,149.9,252.1803306,1.450855077,1.7977E+308,0.039259468,0
,150.1,251.4227747,1.347442567,1.7977E+308,0.029662711,0
,150.3,251.2072786,1.243994573,1.7977E+308,0.021810817,0
,150.5,250.7088962,1.140565097,1.7977E+308,0.007633786,0
,150.7,250.6897564,1.03710425,1.7977E+308,0.000872433,0
,225.9,249.6661583,0.940622726,1.7977E+308,0.038823264,0
,226.1,249.399077,0.837178109,1.7977E+308,0.037078399,0
,226.3,249.189405,0.733729734,1.7977E+308,0.028790287,0
,226.5,248.6602378,0.630302274,1.7977E+308,0.017012443,0
,226.7,248.5038149,0.526850413,1.7977E+308,0.016576226,0
,226.9,247.9738158,0.423423007,1.7977E+308,0.030535155,0
,227.1,247.3040374,0.320004751,1.7977E+308,0.038387053,0
,227.3,246.8297835,0.216573695,1.7977E+308,0.037078405,0
,227.5,246.2132543,0.113151953,1.7977E+308,0.029226508,0
,227.7,245.0800415,0.009764033,1.7977E+308,0.022247045,0
,227.716,245.1160843,0.001484706,1.7977E+308,0.022683262,0
END,,,,,,