File: GB1_test 49.csv
Segment,Time On Sample,Displacement Into Surface,Load On Sample,Harmonic Contact Stiffness,Harmonic Displacement,Harmonic Load
Surface Marker,0,0,0,398.700577,0.165332126,2.298852594
,0.2,0.180972756,0.000644854,17532.94268,0.102514642,2.394181571
,0.4,0.188047252,0.001301105,24579.2006,0.102514642,2.500467893
,0.6,0.438080079,0.001941433,25949.92215,0.102078408,2.605658503
,0.788,0.339159718,0.002565227,24727.7935,0.109930594,2.6867429
,1,0.367360237,0.003258415,24081.16177,0.116910314,2.789742023
,1.2,0.410213009,0.003911276,25394.38102,0.122581337,3.099835111
,1.4,0.389830052,0.004568282,27782.40416,0.127379894,3.485533923
,1.6,0.594100344,0.005210565,30131.94398,0.12868859,3.797818497
,1.8,0.319110369,0.005884255,34274.22977,0.126943662,4.254740084
,2,0.465137227,0.006530355,35915.41447,0.132178452,4.629481564
,2.2,0.607003839,0.007176728,38710.69073,0.136977008,5.170774811
,2.4,0.733061517,0.007824136,41362.47131,0.143956727,5.828215999
,2.6,0.859951244,0.00847149,42059.20765,0.156607469,6.474699857
,2.8,0.917780898,0.00912337,43044.21125,0.167949514,7.117896471
,3,0.909878677,0.009779556,43308.66357,0.181908954,7.769858975
,3.2,0.701452633,0.010448884,43879.9239,0.198485791,8.589468926
,3.4,0.679405577,0.011105998,44343.19136,0.218116255,9.541662882
,3.6,1.17905328,0.011728924,44622.2742,0.238182944,10.48070816
,3.8,0.941505521,0.012400159,43078.16455,0.268719222,11.40879589
,4,0.869535523,0.013060544,41917.80648,0.298383033,12.29743719
,4.2,0.829183389,0.013718858,40973.24297,0.329791775,13.26168423
,4.4,0.862051571,0.014372373,40006.72962,0.366871537,14.36289819
,4.6,1.090035257,0.015013101,38838.59757,0.40831362,15.48383551
,4.8,0.728512187,0.015692462,37420.06366,0.452373112,16.50615636
,5,0.782181596,0.016344614,35785.30469,0.502539849,17.53286036
,5.2,0.859564404,0.016995212,34316.7983,0.551397888,18.45437377
,5.4,1.041785392,0.01763894,32011.86803,0.622067548,19.46025887
,5.6,0.63533167,0.018321245,29731.60039,0.699716949,20.37848481
,5.8,0.21889335,0.019004204,27346.62195,0.787835935,21.19480737
,6,1.013918484,0.019607774,25011.86695,0.878136028,21.73281388
,6.2,0.53216432,0.020295013,22587.68644,0.988066646,22.27739404
,6.4,1.020579366,0.020918676,20482.25218,1.103668232,22.79677285
,6.6,1.26229186,0.021558505,18960.2753,1.198766902,23.12111066
,6.8,0.389474116,0.022274648,17474.05783,1.309133788,23.47831977
,7,1.02516185,0.02288866,16656.57854,1.381112105,23.74677536
,7.2,1.375873029,0.023519707,16032.26341,1.443929558,24.01961362
,7.4,1.20156126,0.02418516,15782.07905,1.484062962,24.37682326
,7.6,1.240253786,0.024838292,15802.08695,1.499767329,24.69349079
,7.8,1.695802879,0.025464107,16128.26949,1.49409627,25.15479565
,8,1.277700484,0.026147174,17033.51409,1.44611073,25.66759945
,8.2,1.414990821,0.026793845,18245.92061,1.38852803,26.2855943
,8.4,1.361325903,0.02745303,19407.10939,1.343159855,26.94413114
,8.6,1.532314226,0.028097493,20321.84267,1.310878638,27.48432875
,8.8,1.288526102,0.028769136,21242.37781,1.287758334,28.12533378
,9,1.391286404,0.02941807,21280.89256,1.304771394,28.55047911
,9.2,1.239439699,0.030083689,21060.05337,1.336616378,28.96028404
,9.4,1.622184502,0.030714276,20709.38366,1.375877274,29.35474899
,9.6,1.700815381,0.031364791,20310.47048,1.415574425,29.63087439
,9.8,1.690417013,0.03202114,19727.90679,1.469667255,29.92672289
,10,2.187568547,0.032644228,19416.4441,1.504565813,30.15573196
,10.2,2.054026926,0.033308646,19577.65114,1.511109312,30.4877397
,10.4,2.130161656,0.033959324,20472.38547,1.475338243,30.97534194
,10.6,2.166358034,0.034612619,21794.42113,1.417319321,31.48266746
,10.8,2.365636016,0.035255226,24212.87586,1.320475696,32.24310793
,11,2.196316289,0.035921989,26690.4844,1.234537914,32.93342105
,11.2,1.471187811,0.036625175,29659.23416,1.151653787,33.8461679
,11.4,1.547322543,0.037275853,30870.26864,1.128533461,34.42800347
,11.6,1.551069009,0.037931276,30804.90188,1.149472622,35.06462569
,11.8,1.661317752,0.038579719,29376.82471,1.210981397,35.42621842
,12,2.150980846,0.039203298,25890.40297,1.364098966,35.6409829
,12.2,3.012569821,0.039802503,23220.63878,1.505001982,35.63769655
,12.4,2.972217692,0.040460813,21419.32915,1.620603588,35.63550508
,12.6,3.14403805,0.041105219,20833.16095,1.666844214,35.71658966
,12.8,3.054595032,0.041766745,21195.89134,1.65419348,36.02449116
,13,3.134890004,0.042417149,23366.30609,1.539900571,36.67316656
,13.2,3.004676586,0.043081348,26671.35187,1.393326479,37.47195757
,13.4,3.160688014,0.043726789,29957.25943,1.277288632,38.22691931
,13.6,2.894850614,0.044399876,33753.11281,1.172156631,39.15500686
,13.8,3.066670973,0.045044282,36015.1922,1.123298584,39.84532031
,14,3.172759462,0.045692995,37145.42854,1.111520299,40.60028208
,14.2,3.373701533,0.046335492,37051.1253,1.129842053,41.19088367
,14.4,3.100375695,0.047009069,36628.41356,1.159069639,41.83627147
,14.6,3.276356297,0.047653202,35923.90245,1.196149391,42.42687302
,14.8,3.037976514,0.048324489,35294.15037,1.228430608,42.8783157
,15,2.852015814,0.048992341,34722.58141,1.26332922,43.43166182
,15.2,3.202726702,0.049625024,34339.7726,1.290811837,43.95323236
,15.4,2.965178967,0.050296256,34041.32143,1.313932175,44.4167281
,15.6,2.913178152,0.050955329,34010.91588,1.33007278,45.00294643
,15.8,2.9726719,0.051607096,34018.03871,1.34141482,45.46534688
,16,3.192751099,0.05224834,33735.41592,1.364971357,46.00006596
,16.2,3.005958351,0.052916246,33419.37186,1.390709086,46.46575321
,16.4,3.12119938,0.053564359,33325.29539,1.406849679,46.87007973
,16.6,3.271386465,0.054210182,33042.69461,1.434332312,47.36206513
,16.8,3.084593717,0.054878088,32899.65088,1.453090323,47.73461493
,17,3.264734565,0.055521948,33085.26344,1.463559888,48.24413206
,17.2,3.185276135,0.056182821,33430.53468,1.46443236,48.72954274
,17.4,3.410347626,0.056823737,33634.40901,1.468794667,49.15907131
,17.6,3.307591826,0.057486136,33789.75782,1.476210627,49.68173691
,17.8,3.063387699,0.058157804,33733.17846,1.488425157,50.07072263
,18,3.32174115,0.058796539,33334.24683,1.515035315,50.47504928
,18.2,3.143268893,0.0594639,32787.21242,1.547316533,50.79938668
,18.4,3.14618331,0.060119375,32269.49672,1.578289038,51.06236324
,18.6,3.274737122,0.060766616,31702.02575,1.616241251,51.35602047
,18.8,3.600486536,0.061400934,31353.8557,1.642415169,51.57845511
,19,3.486082051,0.062064096,31127.43899,1.664226802,51.86115469
,19.2,3.402463377,0.062725241,30972.88827,1.680803644,52.11426947
,19.4,4.019429917,0.063340475,31058.39739,1.685602143,52.36081075
,19.6,4.048969901,0.063994203,31528.76619,1.673823865,52.73883951
,19.8,4.158386582,0.064642696,32414.17382,1.642851353,53.14207025
,20,3.827649377,0.065320034,34165.00755,1.582215074,53.7666389
,20.2,3.894631563,0.065971309,36434.73887,1.50936425,54.46571817
,20.4,4.029841762,0.066618113,39531.79911,1.419064125,55.36312569
,20.6,3.265607046,0.067323859,41784.01081,1.363226431,56.06768238
,20.8,3.531448679,0.067963722,43128.4864,1.340106091,56.83031466
,21,3.501911919,0.068629299,42755.26022,1.364535111,57.40119262
,21.2,3.382928817,0.069307528,41077.19635,1.426043897,57.76716798
,21.4,3.418289743,0.069982273,37854.91929,1.546007819,57.91180518
,21.6,4.115960573,0.070620264,35274.21734,1.65332094,57.88331711
,21.8,4.041488937,0.071315427,33879.40189,1.720500743,57.9249549
,22,4.276954423,0.071997233,33392.30936,1.748419596,58.03124161
,22.2,4.211217096,0.072705695,34041.90017,1.730534074,58.41803613
,22.4,4.238668122,0.073415143,35625.08985,1.67295139,58.92426585
,22.6,4.175840699,0.074137681,38717.44359,1.569128076,59.77126921
,22.8,4.686709867,0.074829789,41211.48222,1.496277217,60.48897677
,23,4.004003699,0.075607405,44024.83086,1.424298922,61.36994676
,23.2,4.291049383,0.076328834,46008.984,1.381984353,62.17421711
,23.4,4.062639553,0.077091601,47327.9833,1.361045214,62.97300781
,23.6,4.029343999,0.077849113,47775.0536,1.360608984,63.56141761
,23.8,3.964429365,0.078616379,47573.32387,1.379803217,64.21447581
,24,4.295568811,0.07936532,46805.57608,1.414265555,64.75796113
,24.2,3.728926247,0.080180685,45914.97762,1.45178159,65.21926467
,24.4,4.324238469,0.080929696,44433.57108,1.508491759,65.61811342
,24.6,4.532646689,0.081711877,43404.0378,1.549933823,65.89752628
,24.8,4.626647879,0.082503454,42808.15478,1.580033853,66.29089552
,25,4.557149199,0.08331996,42759.0576,1.591812135,66.75000841
,25.2,4.417341749,0.084145067,43099.84343,1.589630986,67.21459997
,25.4,4.631569498,0.084957143,44474.55358,1.557349768,67.90272222
,25.6,4.964778921,0.085769699,46098.50267,1.519833751,68.64782299
,25.8,4.83536783,0.0866209,47122.59201,1.499330839,69.2219881
,26,4.711363702,0.087480259,48308.58307,1.47795546,69.98790685
,26.2,4.593598584,0.088347748,49121.62606,1.466177195,70.66616677
,26.4,4.811979855,0.08920183,49503.14501,1.467049642,71.3707251
,26.6,4.658017867,0.090088937,49687.77602,1.470975747,71.92626266
,26.8,4.839786202,0.090962932,49771.90992,1.480136614,72.56288522
,27,4.677084879,0.091868368,49924.69852,1.488861276,73.20608166
,27.2,5.000298706,0.092750836,50110.96275,1.496713433,73.81531109
,27.4,5.048934934,0.093660486,50226.5246,1.504565613,74.32482817
,27.6,4.764750131,0.094601197,50118.05034,1.522014935,74.93076923
,27.8,4.909069053,0.095523014,50284.36144,1.530739571,75.54438138
,28,4.94189193,0.096461514,50492.50362,1.535101893,76.03527087
,28.2,4.789998454,0.09742154,50460.2568,1.547752647,76.57875534
,28.4,4.998380651,0.098367402,50137.80668,1.568691786,77.09484703
,28.6,4.900567298,0.099343108,50020.14348,1.583087465,77.6339487
,28.8,5.176342382,0.100303886,49720.23373,1.600536738,78.01088236
,29,5.053564484,0.101300597,49190.45007,1.627146927,78.44588892
,29.2,5.427518197,0.102274669,48923.59188,1.644159957,78.84145022
,29.4,5.54769544,0.103275174,49104.85556,1.648522272,79.34220155
,29.6,5.279304223,0.104311419,49190.07936,1.654193318,79.74652727
,29.8,5.570880278,0.105321185,49643.84625,1.649394735,80.28562974
,30,5.491360909,0.10636549,50283.10566,1.639361397,80.85102902
,30.2,5.590730378,0.107408577,51229.39352,1.621039625,81.45039636
,30.4,5.750005721,0.108458079,52187.27039,1.602281623,82.01250898
,30.6,5.675473629,0.109533612,53669.25059,1.573490289,82.8014383
,30.8,5.79480721,0.110607225,55100.40704,1.5481888,83.58379365
,31,5.726096025,0.111703992,56550.94846,1.524196022,84.41326519
,31.2,5.612452455,0.112814681,57335.38461,1.516780085,85.12878014
,31.4,5.627774702,0.113927981,57586.84709,1.521142407,85.71719008
,31.6,5.65640796,0.115051552,57621.72253,1.532484449,86.39435462
,31.8,5.524453962,0.116197118,57572.00214,1.542954039,86.92469023
,32,5.972436231,0.117315966,57240.25247,1.561711993,87.50433535
,32.2,6.0884292,0.118467898,57019.34384,1.576543889,88.04672466
,32.4,6.200260083,0.119631687,56964.28654,1.587449688,88.64937941
,32.6,6.503460339,0.120794629,57145.63994,1.592684446,89.28600251
,32.8,6.275811567,0.122004106,57327.19414,1.596610558,89.80099751
,33,6.599809273,0.123189405,57872.88383,1.593556903,90.46172702
,33.2,6.631755928,0.124405843,58648.37299,1.584832253,91.14217875
,33.4,6.6137777,0.125637843,59720.59432,1.570436586,91.93877831
,33.6,6.930281147,0.126860207,60350.72565,1.564765538,92.5655398
,33.8,6.817445433,0.128123088,60893.65299,1.563020619,93.30844821
,34,6.86020084,0.129388411,61310.03563,1.56389308,94.03820808
,34.2,7.11512666,0.130652621,61556.43516,1.568255382,94.69126713
,34.4,6.906599264,0.131959959,61676.4861,1.574798887,95.25776183
,34.6,6.955172877,0.133263501,62171.91027,1.574798883,95.99409614
,34.8,7.140200418,0.134571162,63031.66349,1.566510452,96.77535591
,35,6.935827014,0.135917556,63884.97751,1.558658288,97.56647635
,35.2,7.421219964,0.137232013,64775.18067,1.549933599,98.36088594
,35.4,7.20020136,0.138606092,65752.60098,1.538155344,99.08626224
,35.6,7.32198466,0.13997156,66678.79433,1.530303151,99.97709541
,35.8,7.480375912,0.141348437,67253.5596,1.529866906,100.8273865
,36,7.300121096,0.142761387,67460.4643,1.53510171,101.4815401
,36.2,7.570002458,0.144158817,67449.25818,1.545571264,102.1839074
,36.4,7.500405657,0.145592672,66986.56665,1.566074192,102.8654544
,36.6,7.577247152,0.147031348,66503.53189,1.587013339,103.5228961
,36.8,7.637445379,0.148485534,66274.50558,1.602281467,104.1660929
,37,7.789998693,0.149948313,66479.752,1.605771313,104.731493
,37.2,7.700423465,0.151441715,67212.23838,1.601408998,105.5741134
,37.4,7.792232508,0.152938106,67859.3076,1.596610434,106.2414164
,37.6,7.992205493,0.15444249,68888.74721,1.585704608,107.0928033
,37.8,7.954210114,0.155977656,69879.95574,1.5761075,107.9748704
,38,7.983608235,0.157523825,70403.55495,1.573926336,108.6235459
,38.2,8.180245712,0.159074425,70770.48464,1.576543713,109.3686464
,38.4,8.178853097,0.16065363,71120.67597,1.580906038,110.2233203
,38.6,8.101325516,0.162253582,71145.498,1.590503157,110.9213035
,38.8,8.258433135,0.163854214,70968.35371,1.604026346,111.5699794
,39,8.357710806,0.165474725,70887.26329,1.616240843,112.2865906
,39.2,8.259790321,0.167124513,70886.53519,1.625837964,112.9418402
,39.4,8.534625044,0.168766451,71206.95819,1.627582869,113.5598359
,39.6,8.213710225,0.170464001,71889.60528,1.62409304,114.395881
,39.8,8.49353191,0.172139151,72590.34298,1.617985762,115.0796208
,40,8.705954959,0.173835606,73404.95824,1.611878491,115.9419652
,40.2,8.612181366,0.175569132,74191.93737,1.605771247,116.7571922
,40.4,8.535462011,0.177318907,74593.35992,1.606207487,117.4376438
,40.6,8.451251409,0.179086846,74631.70411,1.615804606,118.2342432
,40.8,8.50141387,0.180863651,74394.57726,1.628891573,118.8116958
,41,8.707166601,0.182648162,74118.17629,1.645032151,119.5009142
,41.2,8.7885252,0.184458718,73561.68622,1.665535064,120.0257718
,41.4,8.872793067,0.186287345,73045.60166,1.684293047,120.477215
,41.6,8.82809047,0.18814272,72721.30714,1.70086988,121.0535718
,41.8,8.718069086,0.190021006,72693.56663,1.708722073,121.5345992
,42,8.746164788,0.191909147,72803.99976,1.714829324,122.1471155
,42.2,8.924856799,0.193815803,73176.17625,1.713956843,122.7289517
,42.4,9.213377686,0.195725035,73567.20216,1.711775654,123.2680545
,42.6,9.342975761,0.197654149,74047.67874,1.709158248,123.950698
,42.8,9.658946536,0.199610106,74342.45588,1.709158219,124.4930882
,43,9.667475355,0.201585948,74764.60431,1.707849522,125.140668
,43.2,9.676415441,0.203591694,75260.66229,1.705232127,125.7740031
,43.4,9.881715831,0.205604625,75968.97534,1.699997321,126.523487
,43.6,9.984671015,0.207644496,76320.31984,1.699997311,127.0790253
,43.8,10.1417061,0.209701362,76781.35418,1.699561065,127.7967325
,44,9.8477675,0.211808493,77148.58955,1.699124861,128.3555567
,44.2,9.870420076,0.213915971,77478.61151,1.700433556,128.9877961
,44.4,10.14434798,0.2160282,77749.43877,1.703487157,129.6704404
,44.6,10.12705545,0.218180882,78190.93459,1.70174223,130.2610416
,44.8,10.20627714,0.2203488,78860.25511,1.6973799,131.0083336
,45,10.42111928,0.222529711,79430.12277,1.693453789,131.6329035
,45.2,10.68338473,0.224729346,79940.12996,1.691272603,132.3056862
,45.4,10.61282716,0.226973085,80589.96011,1.687782752,133.1022857
,45.6,10.43659584,0.229246261,81062.66998,1.685601608,133.724663
,45.8,10.62063798,0.231518519,81463.36514,1.686474056,134.4960615
,46,10.62079373,0.233825718,81891.81516,1.684729127,135.1162476
,46.2,10.39046832,0.236171184,82269.28977,1.684729149,135.8010815
,46.4,10.7109554,0.238503934,82473.06479,1.68865521,136.5472787
,46.6,10.60043753,0.240888527,82590.44515,1.693017544,137.1389754
,46.8,10.89429152,0.243270439,82325.25112,1.706104485,137.7734075
,47,10.95183987,0.245691863,81772.02696,1.72311754,138.2084145
,47.2,11.46617907,0.248107514,81322.93887,1.740566787,138.8077838
,47.4,11.63022193,0.250570498,81120.06405,1.751036344,139.2296424
,47.6,11.94652573,0.253048321,81183.62091,1.755834868,139.6975231
,47.8,11.83515259,0.2555791,81841.29045,1.750163863,140.3714
,48,12.83872057,0.258061861,82922.77675,1.737076798,141.1351313
,48.2,12.90622988,0.260631229,84133.71945,1.721372431,141.9043379
,48.4,13.2275099,0.263209732,85531.4447,1.702178182,142.6834072
,48.6,13.30249939,0.265830519,87085.19314,1.682983959,143.6290274
,48.8,12.94315534,0.268506161,88318.95984,1.668588329,144.4212428
,49,13.23696516,0.271165725,89926.87802,1.650702777,145.4764374
,49.2,13.11141826,0.273879478,91025.2524,1.641541912,146.4045249
,49.4,13.41354001,0.276592327,91471.58811,1.64241435,147.1726368
,49.6,13.73895476,0.279330988,91929.69681,1.645031715,148.1138751
,49.8,14.01860247,0.282100136,92164.329,1.649394012,148.8381575
,50,13.95294561,0.284919761,92427.42791,1.654628803,149.7125542
,50.2,14.11027326,0.287753087,92695.35712,1.658554877,150.5003888
,50.4,14.23431447,0.29061689,93417.51408,1.654628777,151.303564
,50.6,14.34171011,0.29351072,94556.50437,1.645904123,152.3390346
,50.8,14.45575749,0.296433319,95397.60801,1.640233097,153.1674108
,51,14.49824404,0.299389993,96429.17319,1.633689608,154.2204132
,51.2,14.47832222,0.302380453,97372.56049,1.628018591,155.2065752
,51.4,14.45506745,0.305401124,97779.55707,1.629763523,156.0470045
,51.6,14.50169994,0.308447452,97753.9448,1.638924395,156.9674225
,51.8,14.59492227,0.311521392,97558.71339,1.650702657,157.8560646
,52,14.93442605,0.314609988,97193.66309,1.66335336,158.5047417
,52.2,15.3288401,0.317726003,96826.36253,1.676876522,159.2323119
,52.4,15.03098482,0.320918876,96875.97907,1.684292497,160.0661655
,52.6,15.54686788,0.324090197,97011.57071,1.689527235,160.7597685
,52.8,15.46450299,0.327332873,97429.17419,1.691708405,161.6582712
,53,15.54687853,0.33059727,98134.60724,1.687782308,162.4132336
,53.2,15.5493722,0.333899712,99135.54619,1.681238825,163.32379
,53.4,15.84806986,0.33721576,100079.0773,1.677312708,164.3428253
,53.6,15.68996765,0.340594985,100978.4208,1.671641705,165.1733925
,53.8,15.71823891,0.343995857,101839.0877,1.66902431,166.207767
,54,15.93953997,0.347418246,102237.861,1.670769218,166.9747831
,54.2,15.82302388,0.350897308,102315.2385,1.677748945,167.7998715
,54.4,15.89537724,0.35439883,102309.4073,1.686473582,168.6797475
,54.6,16.05092986,0.357930063,102269.7705,1.693889515,169.3755405
,54.8,15.8728254,0.361518743,101883.4543,1.707412729,170.1283098
,55,16.06414474,0.365119095,101796.3492,1.716137355,170.9161448
,55.2,16.03912573,0.368769867,102071.8245,1.719190983,171.6820641
,55.4,16.55659647,0.372421649,102149.4255,1.723989488,172.3252633
,55.6,17.18888405,0.376102525,102350.1912,1.728351749,173.1361107
,55.8,17.48834636,0.379842392,102744.7629,1.728351721,173.8143724
,56,17.50948252,0.383638086,102583.4996,1.737948826,174.5309839
,56.2,17.47361726,0.387475909,102364.8201,1.747545937,175.1676063
,56.4,17.53717565,0.391345783,102768.8383,1.748854628,175.9751638
,56.6,18.07208328,0.39522344,103127.8761,1.749290808,176.5898741
,56.8,18.33116067,0.399158191,103824.4996,1.746237159,177.4061987
,57,18.36183451,0.403147503,105025.7815,1.734895121,178.188554
,57.2,18.4653062,0.407172111,106609.8438,1.719626988,179.1560893
,57.4,18.52633701,0.41123992,108125.1612,1.706540019,180.2321021
,57.6,18.78039652,0.41533598,109745.5848,1.691489988,181.2790789
,57.8,18.74780885,0.419491968,111452.207,1.676003752,182.3972771
,58,19.11584579,0.423663495,113051.5033,1.662916755,183.5960139
,58.2,19.17893036,0.427896951,114281.5961,1.65462834,184.7180477
,58.4,19.43296326,0.432160354,115121.2197,1.65113846,185.7074987
,58.6,19.40492499,0.436485068,115767.2621,1.652447159,186.8799357
,58.8,19.18467663,0.440865991,116003.4709,1.657245733,187.7674807
,59,19.56432812,0.44525139,115958.2032,1.665534108,188.5958587
,59.2,19.80335643,0.449690182,116121.4757,1.672077568,189.5644905
,59.4,19.49946613,0.454209262,116330.7055,1.678621078,190.6010548
,59.6,19.79381134,0.458734441,116427.6639,1.6847283,191.423954
,59.8,19.80442086,0.4633237,116573.1243,1.691271781,192.3936802
,60,20.07586646,0.467965361,117087.3554,1.692580452,193.3540942
,60.2,20.00367426,0.472641289,117263.2944,1.697379012,194.1808265
,60.4,20.55925505,0.477322697,117380.6727,1.703922441,195.1341197
,60.6,20.76827833,0.482086003,117402.5711,1.710902135,196.0008478
,60.8,20.55918978,0.486924567,117215.7492,1.720063028,196.7919681
,61,20.94084777,0.491772838,116836.4422,1.731623142,197.5409056
,61.2,20.84823051,0.496700998,116754.7633,1.739257212,198.3183294
,61.4,21.09965732,0.501656152,116871.4538,1.744055741,199.1028776
,61.6,21.41639199,0.506656755,117584.1393,1.741438318,200.0375423
,61.8,21.46561518,0.511725224,118368.0081,1.737075993,200.839621
,62,21.75945244,0.516828534,119371.0784,1.731404949,201.8893377
,62.2,21.8448535,0.521996603,120276.6744,1.726606389,202.8513947
,62.4,21.88198752,0.527219781,120952.5783,1.723988994,203.6885365
,62.6,22.51735583,0.532456135,121511.7482,1.725297629,204.7075747
,62.8,23.44726084,0.537725405,122151.5887,1.723552613,205.5359563
,63,23.79222754,0.543086347,123043.0803,1.720935188,206.6108753
,63.2,23.91502882,0.548515785,124261.258,1.713519233,207.6836014
,63.4,23.83480171,0.554013093,125949.2481,1.69999605,208.7574226
,63.6,24.12565928,0.559541147,127706.4759,1.687345295,210.0986051
,63.8,24.22513696,0.565137294,129005.9792,1.678620647,211.1581821
,64,24.58337266,0.57077262,130503.0384,1.669459742,212.5289499
,64.2,24.84591382,0.576470877,131226.6129,1.668587255,213.6959102
,64.4,24.79642787,0.582246858,131218.9283,1.674694507,214.5933177
,64.6,24.63127802,0.588088442,131266.9459,1.682546698,215.7558924
,64.8,24.89878384,0.593960217,131286.7144,1.689090153,216.6598763
,65,25.09638823,0.599895653,131436.1554,1.695197382,217.7106881
,65.2,25.3156164,0.605889169,131802.7481,1.698687222,218.7384901
,65.4,25.47825575,0.611946594,132270.8407,1.700868366,219.6819191
,65.6,25.92461378,0.618046285,132931.1441,1.702177017,220.8466898
,65.8,25.9990366,0.624231699,133361.1947,1.70435817,221.7791614
,66,26.38962779,0.630458439,133721.6891,1.709156689,222.9022928
,66.2,26.41327586,0.636771963,134051.7286,1.713082775,223.9059871
,66.4,26.54424802,0.643141883,134556.7304,1.713955228,224.843938
,66.6,26.61779873,0.649579439,134919.1504,1.717881306,225.9670678
,66.8,26.66554563,0.656083616,135316.4806,1.71962623,226.8502313
,67,26.78733444,0.662648084,135435.7253,1.725733464,227.8637879
,67.2,27.34260973,0.669250102,135539.662,1.731840657,228.8148903
,67.4,27.56588733,0.675940326,135084.133,1.744491359,229.6958644
,67.6,27.2499872,0.682733149,135151.5246,1.74972618,230.4552066
,67.8,27.61385937,0.689549572,135580.7215,1.75234353,231.4698609
,68,27.89867613,0.696439527,136261.7148,1.750598581,232.3168663
,68.2,27.85482294,0.703420341,137161.7638,1.747108725,233.3183687
,68.4,28.09635105,0.710452501,138756.9926,1.736639136,234.5828502
,68.6,28.35367683,0.717554308,139800.7785,1.730968097,235.5591534
,68.8,28.3339193,0.72474575,141148.3842,1.723552158,236.7940476
,69,28.31248621,0.732009474,142336.8055,1.71657245,237.8601987
,69.2,28.42416918,0.739337418,143846.5998,1.70741157,239.1148168
,69.4,28.68976931,0.74672884,144923.5153,1.704794154,240.4516165
,69.6,28.94370897,0.754195209,145381.2698,1.70697529,241.4586002
,69.8,29.16518681,0.761738935,145243.3757,1.71657237,242.5587205
,70,29.31759264,0.769362919,145157.34,1.723988298,243.4353102
,70.2,30.41020036,0.77700149,144684.6539,1.735766453,244.3042366
,70.4,30.8845843,0.784757582,144182.5198,1.747980898,245.2586261
,70.6,31.4055505,0.792588684,144298.6342,1.751906934,246.0749531
,70.8,31.22259179,0.800544679,145277.0912,1.748417098,247.2539638
,71,31.38159201,0.808558117,145715.7646,1.749289547,248.1217879
,71.2,31.47235151,0.816656569,146408.3751,1.748417075,249.1747911
,71.4,32.39764196,0.824781421,147639.12,1.743182204,250.4250327
,71.6,32.46091797,0.833044704,147787.0505,1.747544516,251.2698458
,71.8,32.64898795,0.841382738,147734.8042,1.754960438,252.2702542
,72,32.62736858,0.849818371,148344.1386,1.754087977,253.1840976
,72.2,32.97350082,0.858314542,149498.2525,1.748416931,254.32257
,72.4,32.9709915,0.866919097,151272.3024,1.737074906,255.6714211
,72.6,33.35869883,0.87558424,153977.3735,1.715699512,257.0301369
,72.8,33.60244804,0.884346081,157008.1155,1.693887902,258.7307216
,73,34.12991148,0.893177392,158533.9814,1.686035681,260.0182153
,73.2,34.47015012,0.902109617,159145.5668,1.688216808,261.3068037
,73.4,34.61983558,0.911144061,158835.1871,1.69955882,262.5625182
,73.6,34.85271129,0.920264388,157928.6951,1.714826908,263.409524
,73.8,34.87256825,0.929490315,157274.8205,1.729222554,264.507452
,74,35.23146988,0.938786541,157217.322,1.735765995,265.4256821
,74.2,35.37319223,0.948190513,158229.1108,1.732276128,266.6288011
,74.4,35.5976883,0.957683529,159640.3873,1.726168863,268.0324412
,74.6,36.20740722,0.967246552,160502.1075,1.723987647,269.1205118
,74.8,36.03581819,0.976957227,161683.565,1.72049781,270.5099043
,75,36.674628,0.986711889,163410.9245,1.712209347,271.9803873
,75.2,37.02220555,0.996583857,164656.0916,1.708283229,273.3325284
,75.4,37.0344522,1.006577061,165685.2754,1.705665839,274.5553702
,75.6,37.38907042,1.016648205,167155.329,1.700867257,276.0959783
,75.8,37.58225534,1.026831148,168045.9366,1.699558544,277.2925237
,76,38.22888987,1.037086497,168343.4346,1.705229495,278.6939758
,76.2,38.56182612,1.047465548,168482.2875,1.711336707,279.9179159
,76.4,38.69255825,1.057962192,168986.3915,1.713081621,281.0388553
,76.6,39.06623147,1.068548315,169898.6579,1.712645354,282.5268683
,76.8,39.45195246,1.079240032,170602.2653,1.712645318,283.7113624
,77,39.93875012,1.090032543,171485.4275,1.712645272,285.1928019
,77.2,40.11850069,1.100981129,172417.5848,1.711772792,286.5526121
,77.4,40.393928,1.111978199,173003.4794,1.713081461,287.7458713
,77.6,40.72590362,1.123165958,173573.2527,1.716571282,289.1911505
,77.8,41.07451116,1.134409364,173581.6842,1.723114723,290.2573049
,78,41.61448069,1.145696068,173771.7524,1.727913219,291.3322266
,78.2,41.79456262,1.157177187,173660.3332,1.73576537,292.4663153
,78.4,41.79032775,1.168785661,173502.7609,1.744926233,293.7055932
,78.6,42.1109888,1.180489435,172994.2387,1.754959528,294.5723232
,78.8,42.24109235,1.192323218,173662.8056,1.755831979,295.8740601
,79,42.67321014,1.204256081,174470.8906,1.754741358,297.0503362
,79.2,43.02418426,1.216314179,175452.1257,1.751905819,298.1926445
,79.4,43.51991531,1.228484053,176594.0346,1.748852151,299.6171058
,79.6,43.48810909,1.240810216,178450.3356,1.738382598,300.9352768
,79.8,43.56236923,1.253253154,179884.3033,1.733147813,302.4890319
,80,43.74893584,1.265813798,180487.989,1.733584027,303.6570884
,80.2,44.06528177,1.278492081,181102.0796,1.73445646,304.952252
,80.4,44.63787796,1.291280906,181873.8643,1.735328868,306.3931501
,80.6,45.03156357,1.304209973,181420.0891,1.745798386,307.3639763
,80.8,45.63407236,1.317255181,180718.2102,1.759757734,308.4542396
,81,46.15169149,1.330437083,180439.3485,1.768046082,309.2957694
,81.2,46.3289823,1.34377382,180358.1884,1.775461999,310.3060401
,81.4,46.75586592,1.357228124,180328.7609,1.78244166,311.432461
,81.6,47.15111027,1.37081967,180676.5276,1.784186547,312.3594577
,81.8,47.47810508,1.384552,181371.16,1.783750284,313.5724408
,82,47.67694275,1.398430521,182161.7123,1.781132876,314.61668
,82.2,47.88407873,1.412447879,183266.4079,1.77633431,315.8691088
,82.4,48.3832408,1.426586968,184848.5524,1.768482096,317.3406873
,82.6,49.38077642,1.440835193,186253.025,1.760629841,318.525187
,82.8,50.08707282,1.455245728,188913.4047,1.744925441,320.2652237
,83,50.51128227,1.469819679,191182.0519,1.73227469,321.6885894
,83.2,50.70332737,1.484555262,193344.1354,1.722677582,323.3343874
,83.4,50.88203619,1.499439714,194856.9704,1.719623944,325.0448341
,83.6,51.24709974,1.514461433,195602.9423,1.72136884,326.3312324
,83.8,51.58967401,1.529635653,195600.3778,1.7296572,327.7556933
,84,51.69592275,1.544977805,195120.0589,1.739690506,328.7780167
,84.2,52.60424009,1.560421456,195457.1765,1.744052738,330.0578457
,84.4,53.11481441,1.57604624,196886.0782,1.740562836,331.6521475
,84.6,53.41735207,1.591841702,199140.8175,1.730965719,333.4108079
,84.8,54.09178937,1.607771464,201406.0684,1.720496101,334.9152609
,85,54.35766628,1.623888144,204355.3501,1.70697291,336.8875897
,85.2,55.1110968,1.64013471,206250.9504,1.700865603,338.6802224
,85.4,55.36277722,1.65657749,207230.916,1.700429347,340.1342676
,85.6,55.39144287,1.673200125,207755.433,1.70479166,341.8458089
,85.8,55.87770765,1.68995954,207648.1505,1.711771309,343.1081025
,86,56.60690326,1.706871378,206945.7221,1.724421946,344.5500993
,86.2,56.7894172,1.723989268,206262.4706,1.736200166,345.8058156
,86.4,56.90201187,1.741283769,206344.6033,1.742743624,347.2828712
,86.6,57.51547098,1.758719029,206417.059,1.747542108,348.4060064
,86.8,57.51568392,1.776369721,207167.604,1.74841457,349.9148362
,87,57.77047493,1.794180968,208594.9487,1.744052234,351.5496792
,87.2,58.28733216,1.812153841,209985.9637,1.739689872,353.0859075
,87.4,58.52958531,1.830325481,211138.9925,1.736636231,354.4763996
,87.6,58.871655,1.848673176,213215.5945,1.728784038,356.3775071
,87.8,59.91594262,1.867158949,215014.1459,1.722240471,357.9466132
,88,60.11816966,1.885885903,217259.7539,1.714388291,359.9046973
,88.2,60.66400196,1.904778439,218962.4483,1.710025929,361.69185
,88.4,61.48271529,1.923842809,220077.4376,1.709153389,363.2094537
,88.6,61.87788653,1.943126643,220550.8032,1.713951893,364.9330526
,88.8,62.68156175,1.962577202,220489.2907,1.720495283,366.288487
,89,62.91525413,1.982260764,220177.857,1.730092344,367.8532027
,89.2,63.35027028,2.002128788,220055.0729,1.73750823,369.316016
,89.4,63.84266588,2.022192707,220650.8377,1.738816875,370.7108944
,89.6,64.16113176,2.04246963,221263.9345,1.740998,372.349025
,89.8,64.87395518,2.062924302,221695.2306,1.743615317,373.6507681
,90,65.40286368,2.083596579,221375.9258,1.753212348,375.1453594
,90.2,65.87099977,2.104480692,221467.7663,1.759755767,376.5161314
,90.4,66.384033,2.125571519,221102.3635,1.768480336,377.5844805
,90.6,66.58751137,2.14689468,221119.2043,1.775896243,378.95525
,90.8,67.19782624,2.168405257,221535.4748,1.7789498,380.1145468
,91,67.44533454,2.190156438,223887.0672,1.769352695,381.8271865
,91.2,67.73649043,2.21212382,225901.0067,1.761500509,383.4335407
,91.4,68.0213709,2.234312296,228736.9979,1.749286016,385.404775
,91.6,68.7971231,2.256691388,231581.8306,1.736199013,387.1228992
,91.8,69.29327205,2.279313794,234261.4648,1.725729424,389.1839867
,92,69.92043212,2.302154804,235525.1305,1.723548209,390.789249
,92.2,70.20600081,2.325247802,236739.6885,1.72267572,392.5632508
,92.4,71.35186813,2.348516191,237378.246,1.726165458,394.4183463
,92.6,71.51046633,2.372142613,237767.1504,1.730963982,396.210975
,92.8,71.92323575,2.395870636,238667.4144,1.731400173,397.706661
,93,72.703306,2.419872711,240078.7436,1.730091406,399.6384548
,93.2,72.94001196,2.444151704,241723.0603,1.726601537,401.4869666
,93.4,73.4321172,2.468657876,243813.0628,1.720058028,403.2817901
,93.6,74.45253236,2.493375523,244900.1696,1.721366622,405.2639905
,93.8,74.6400302,2.518396291,244785.4931,1.727910066,406.6785896
,94,75.89625083,2.543598089,244574.5748,1.73663456,408.3868585
,94.2,76.39110933,2.569103219,244274.9708,1.745359127,409.8518661
,94.4,76.74115113,2.594874172,243317.8499,1.758446015,411.3431688
,94.6,77.57956256,2.620871932,243669.2931,1.761499548,412.6701165
,94.8,78.19036793,2.647146008,245184.2684,1.758445873,414.476995
,95,78.73331961,2.673688489,246407.9889,1.755828436,415.9661087
,95.2,79.1655561,2.700572422,246988.2338,1.757573317,417.5626032
,95.4,79.74585359,2.72771771,247539.4697,1.760626874,419.3322264
,95.6,80.63439126,2.755048219,247721.9536,1.764552863,420.6471221
,95.8,81.43179835,2.782520296,247582.6002,1.771968705,422.1855473
,96,81.9558125,2.810425479,248099.7173,1.775458498,423.7579369
,96.2,82.61623752,2.83860206,249134.1967,1.775458433,425.3084135
,96.4,83.00786684,2.867079486,250436.5193,1.772841011,426.749314
,96.6,83.72186823,2.89582194,252062.9862,1.769787327,428.5353747
,96.8,84.21865986,2.924867493,253191.5569,1.768478587,429.9740843
,97,84.74660692,2.954201964,254683.1531,1.766297382,431.7984941
,97.2,85.67929726,2.983803784,256542.2689,1.761498755,433.6218128
,97.4,86.03366881,3.013741214,258365.3365,1.756263954,435.2511793
,97.6,86.81067153,3.043951523,260966.191,1.7479755,437.3933568
,97.8,87.13998565,3.074494875,263306.4713,1.740123319,439.2320088
,98,88.07997215,3.105304901,265831.0002,1.732707311,441.4815701
,98.2,88.7420063,3.136442893,268339.1363,1.72529133,443.6138846
,98.4,89.41730344,3.167892729,270534.4859,1.719184039,445.5325306
,98.6,90.24731069,3.199648428,272285.0052,1.717439038,447.8708457
,98.8,90.8318139,3.231739441,273344.836,1.719620135,450.0437015
,99,91.62094894,3.264139118,274602.388,1.719183829,451.8275722
,99.2,92.23280666,3.29687587,274783.1139,1.725290995,453.6947177
,99.4,93.14747649,3.329921169,274831.8951,1.732270592,455.6528132
,99.6,93.82080054,3.363314002,275280.4002,1.73576037,457.322727
,99.8,94.78611899,3.397023062,276582.0361,1.735760276,459.4692901
,100,95.34784183,3.431097297,276465.1638,1.741867446,460.9868947
,100.2,96.109201,3.465500587,277154.3889,1.744484754,462.831032
,100.4,96.67830289,3.500262033,278068.9333,1.746665849,464.884453
,100.6,97.21905972,3.535374602,279542.576,1.74622957,467.003618
,100.8,98.09257834,3.57081798,280804.0285,1.745357025,468.6592885
,101,98.61242132,3.606640862,283623.2125,1.737941058,471.0688249
,101.2,99.68884496,3.642786868,285676.4364,1.734014886,473.1595072
,101.4,100.5929776,3.679307502,286913.738,1.734014798,475.0058376
,101.6,101.219981,3.716213185,287758.1444,1.73706835,477.1644504
,101.8,101.895184,3.753486617,288586.5134,1.738376976,478.8979175
,102,102.5503584,3.791135878,289708.7056,1.7396856,481.0148928
,102.2,102.8834714,3.829184445,292523.5015,1.731833426,483.298416
,102.4,103.6957813,3.867583677,297360.524,1.714820375,486.1506341
,102.6,104.8425117,3.906346757,301498.2238,1.700860905,488.6412632
,102.8,105.3526662,3.945541247,305762.4874,1.688210188,491.6041469
,103,106.5258973,3.985085834,308728.0531,1.680794166,494.0060219
,103.2,107.2406089,4.02505793,309292.679,1.686028855,496.3870729
,103.4,108.3463174,4.065405831,307350.8624,1.703914185,498.5544578
,103.6,108.9211171,4.106194214,305781.5798,1.719618402,500.5859651
,103.8,110.0774506,4.147354001,305451.5404,1.72747043,502.2515054
,104,110.9009007,4.188949267,304205.581,1.740993477,504.1405714
,104.2,111.8357781,4.230955174,304826.3978,1.744483225,506.1337324
,104.4,112.6432857,4.27339141,307491.2252,1.738375929,508.6342197
,104.6,113.5647156,4.316246413,309485.1709,1.734449771,510.6723061
,104.8,114.448635,4.359534473,311196.0801,1.733577226,513.1881354
,105,115.1602521,4.403268786,311695.7753,1.736630766,514.9632421
,105.2,116.0806423,4.447428753,312410.2519,1.739684285,517.0583079
,105.4,117.228942,4.492017458,311066.5742,1.753207295,518.9408041
,105.6,118.2515318,4.537062431,309676.1711,1.766730316,520.7433088
,105.8,119.0202762,4.582576659,309070.5986,1.775018604,522.2181853
,106,120.1808405,4.628522432,311100.0513,1.771528652,524.4370735
,106.2,121.0160023,4.6749513,312403.7548,1.769783651,526.067545
,106.4,122.2829205,4.721818168,315501.7591,1.761058934,528.5625612
,106.6,123.1570392,4.769181736,320329.0724,1.744918353,531.4366977
,106.8,124.3805405,4.816998224,323766.5323,1.734448725,533.68846
,107,125.0914266,4.865328857,325811.3864,1.732267508,536.2919461
,107.2,125.8721272,4.914140467,326983.7389,1.733576121,538.5743829
,107.4,126.8915462,4.963426748,327165.379,1.738810776,540.4316759
,107.6,127.6055265,5.013228346,327117.2251,1.746226608,542.6604204
,107.8,128.5823529,5.063512889,328795.3801,1.745354054,545.140092
,108,129.7230115,5.114292058,330186.2755,1.744481484,547.069706
,108.2,130.9526176,5.165575535,332974.4212,1.738374153,549.5702026
,108.4,131.1212865,5.217444497,338059.1225,1.723106107,552.7993491
,108.6,132.8794907,5.269732071,341283.223,1.71525381,555.2779382
,108.8,133.7939196,5.322600531,343976.0856,1.711327658,558.1761832
,109,134.766507,5.37599635,347458.3632,1.702602979,560.7720054
,109.2,135.8912729,5.429918688,350930.4145,1.695623204,563.7502428
,109.4,137.2955191,5.484364384,351982.7435,1.700421593,566.7230056
,109.6,138.6260424,5.539361935,352102.9779,1.706528675,568.8958787
,109.8,139.7430588,5.594926172,351984.5255,1.715253152,571.5234794
,110,140.6016371,5.651065771,350170.7738,1.730521091,573.6700469
,110.2,141.6664723,5.70775577,349061.0635,1.741862945,575.7289588
,110.4,142.8572713,5.765007108,349821.7324,1.744043975,577.7648621
,110.6,143.8029423,5.822849865,352282.8954,1.74055405,580.561205
,110.8,144.9049449,5.881263416,355450.6071,1.734010507,583.5142418
,111,145.9456989,5.940268134,359041.2927,1.724849596,586.0750023
,111.2,147.0470978,5.999861571,363099.5699,1.715252452,589.0959746
,111.4,148.2528227,6.060046918,366067.1218,1.710890046,592.2988421
,111.6,149.2479448,6.120850834,367845.5702,1.709581264,594.7193484
,111.8,150.6718874,6.182237371,369700.0421,1.710017357,597.8499005
,112,151.6468451,6.244270319,370139.516,1.713943324,600.1345352
,112.2,153.0335646,6.306899471,369659.0095,1.721795311,602.5243668
,112.4,154.0033309,6.370185135,369370.0819,1.730519794,605.1804572
,112.6,155.5425287,6.434069452,369470.237,1.736626848,607.3193676
,112.8,156.5403811,6.498631295,369075.2713,1.746660013,609.8121931
,113,157.6233886,6.564000447,369485.8841,1.753203338,612.2140739
,113.2,158.824857,6.630021927,370431.1709,1.757129279,614.5184355
,113.4,159.9268702,6.69621428,372432.2456,1.755384256,616.7307547
,113.6,161.1972128,6.763395359,375069.8746,1.75233053,619.5106692
,113.8,162.1566806,6.831271712,378759.5054,1.743605863,622.0560907
,114,163.6955568,6.899792091,383509.1923,1.732699998,625.4331888
,114.2,164.9127394,6.969022153,387042.0248,1.725720223,628.4607406
,114.4,166.2571138,7.038939293,388447.969,1.726156322,630.907552
,114.6,167.8172916,7.109541455,390037.0404,1.727028628,633.9657913
,114.8,168.9272222,7.180882467,389185.6663,1.737061779,636.6799594
,115,170.1709974,7.252931473,387570.9375,1.748403594,638.553699
,115.2,171.6368125,7.325689669,386765.8577,1.757564247,640.7561636
,115.4,173.3903976,7.399160129,387035.444,1.761926358,642.8545391
,115.6,174.5980461,7.473404792,386830.8797,1.769778349,645.2443703
,115.8,175.9195656,7.548387843,388593.113,1.769778218,647.8960858
,116,177.3824122,7.624115014,391098.749,1.765852018,650.2420934
,116.2,178.6046779,7.700618904,394082.0863,1.760617159,653.0176272
,116.4,180.0065421,7.777879618,397762.979,1.753201141,656.104355
,116.6,181.1794717,7.855931385,402176.1177,1.741859093,658.9182393
,116.8,182.5120285,7.934756051,406281.801,1.733570628,662.3304009
,117,184.1664592,8.014350894,410324.7382,1.724409678,665.2297619
,117.2,185.5070833,8.094765878,415171.2439,1.71481253,668.7164356
,117.4,187.113,8.175970261,419224.2621,1.709141412,672.3280269
,117.6,188.4700068,8.258006606,422255.6731,1.70739637,675.8147014
,117.8,189.9150788,8.340861185,425055.5683,1.704778864,678.7348778
,118,191.5056255,8.424538286,425780.0724,1.710449675,682.0221332
,118.2,193.0735733,8.50905774,423953.6828,1.723536364,684.6256422
,118.4,194.1238569,8.594460344,423245.3753,1.731824591,687.0088997
,118.6,195.7264788,8.680684648,421692.349,1.744475045,689.7789655
,118.8,197.4288076,8.767768705,420868.5735,1.752763206,691.881726
,119,198.7790443,8.855750875,421745.1636,1.757125349,694.7591682
,119.2,199.9527479,8.944628588,425322.2363,1.751454271,697.7834374
,119.4,201.5681227,9.034370096,428405.5067,1.746655609,700.4954292
,119.6,203.1966666,9.125012454,433629.51,1.73574976,704.2045462
,119.8,205.3700516,9.216529662,436627.5489,1.731387273,707.1335064
,120,206.8144235,9.309014345,438670.4578,1.730950906,710.4569194
,120.2,208.1962446,9.402432151,438493.5864,1.737057953,713.1853437
,120.4,209.8724585,9.496769227,438596.8615,1.741856294,715.7088705
,120.6,211.5526816,9.592053858,437535.8499,1.752325588,718.4131949
,120.8,213.3783594,9.688286135,439329.9785,1.753634094,721.5065109
,121,214.8569229,9.785508147,442329.995,1.7497079,724.2097361
,121.2,216.8894691,9.883670596,447380.6729,1.740110697,727.6306838
,121.4,218.3036532,9.982860003,453884.286,1.727459966,731.6783835
,121.6,220.0679673,10.08302292,458290.2673,1.719607705,734.8231997
,121.8,221.8845396,10.18418874,462182.7224,1.715245258,738.7262702
,122,223.1950706,10.28640419,465641.8559,1.712191541,742.603033
,122.2,225.0021655,10.38961383,469028.3569,1.709137778,746.2442228
,122.4,226.9946399,10.49384832,470207.3129,1.711754949,749.2082476
,122.6,228.5700963,10.59915759,471223.0646,1.716553295,752.8034115
,122.8,230.266862,10.70551685,472478.3369,1.718734266,755.7027816
,123,232.2513429,10.81292577,473432.8308,1.723096343,759.1576985
,123.2,234.0085057,10.92142874,471507.0602,1.735310526,761.8532633
,123.4,235.4235272,11.03104448,472719.4487,1.738800202,765.3563839
,123.6,237.565575,11.14171359,475808.1261,1.734873952,768.3379445
,123.8,239.3138918,11.25352041,479502.9756,1.731383968,772.1697937
,124,241.3266179,11.36643324,481224.1991,1.732692452,775.1162903
,124.2,243.3666207,11.4804787,485970.395,1.725712627,778.8484348
,124.4,245.3531907,11.59567364,489958.1434,1.721786395,782.8325988
,124.6,246.9718158,11.71204999,491424.6725,1.723967371,785.9007143
,124.8,249.1751774,11.82955713,493044.1593,1.726584516,789.6251928
,125,251.0147507,11.94826891,496856.1888,1.7226583,793.5753866
,125.2,253.2193986,12.06814931,498404.3832,1.723530539,796.4046451
,125.4,254.7860377,12.10852396,500429.7766,1.724839067,800.2923753
,125.6,256.0005027,12.10844473,502224.2511,1.726583856,804.0431315
,125.8,257.112627,12.10837221,504685.4401,1.725275071,807.218621
,126,257.6414931,12.10833792,507681.35,1.723966341,811.2411059
,126.2,258.2427465,12.10829888,509515.855,1.725711189,814.8767949
,126.4,258.5997969,12.10827584,510804.6076,1.728328513,817.9295434
,126.6,259.2647011,12.10823263,511303.375,1.734871843,821.6276913
,126.8,259.6013666,12.10821093,510439.9413,1.743596336,824.1511972
,127,260.0570134,12.10818143,507187.1865,1.760609116,826.9179587
,127.2,260.259305,12.10816854,505187.3024,1.773259657,829.4195451
,127.4,260.967475,12.10812249,502362.9265,1.788527505,831.9846959
,127.6,261.069506,12.10811616,500360.1283,1.799433151,833.8047273
,127.8,261.5438736,12.10808544,498868.5959,1.809466307,836.2822135
,128,261.563117,12.10808454,497864.5259,1.816445925,838.1504564
,128.2,261.957193,12.10805908,496204.9844,1.825606635,840.1151331
,128.4,262.0051416,12.1080563,495830.1872,1.831277572,842.4151005
,128.6,262.2893888,12.10803803,496292.8515,1.833458674,844.3140299
,128.8,262.4459182,12.10802813,497629.3143,1.834331111,846.7717852
,129,262.4185675,12.10803029,500178.2753,1.830841305,848.9610791
,129.2,262.9274646,12.1079973,504356.8713,1.823425408,851.7957792
,129.4,262.9982942,12.10799302,509032.3959,1.815137104,854.9865848
,129.6,262.6768184,12.10801445,512508.0927,1.809466197,857.5681486
,129.8,263.2622629,12.10797645,515011.7254,1.80815746,860.5650198
,130,263.4495777,12.10796453,515941.1573,1.810774799,863.052363
,130.2,263.62566,12.10795335,515504.4732,1.816881948,865.1090758
,130.4,263.6611281,12.10795139,514428.6443,1.825606468,867.4101382
,130.6,263.985313,12.10793051,512914.3775,1.834330958,869.0932078
,130.8,264.0636309,12.10792574,512841.8283,1.839129438,871.3515368
,131,264.1344606,12.10792146,514465.6104,1.837820753,873.4531729
,131.2,264.2618687,12.10791347,516979.3642,1.834330932,876.0106418
,131.4,264.4874572,12.10789905,519385.0568,1.831713552,878.7467182
,131.6,264.4247449,12.10790352,521302.3819,1.829968655,881.0061391
,131.8,264.574202,12.10789409,521669.1728,1.833894675,883.4255443
,132,264.8093589,12.10787904,518875.2541,1.846981436,885.2225682
,132.2,264.9230385,12.10787195,516937.1649,1.856578399,886.7631871
,132.4,265.0683354,12.10786279,515216.5995,1.864866681,888.1120494
,132.6,265.365063,12.10784371,514185.3522,1.871410043,889.7370439
,132.8,265.2282994,12.10785303,513007.7282,1.877517223,890.9774227
,133,265.2446307,12.10785232,511736.5122,1.88449684,892.4709207
,133.2,265.489772,12.10783662,509865.7399,1.893221337,893.5984456
,133.4,265.4769819,12.10783782,506463.2759,1.906744348,894.4465524
,133.6,265.6430798,12.10782729,503814.1155,1.917213758,894.9834705
,133.8,265.7018449,12.1078238,503586.1302,1.920703561,896.0616822
,134,265.9586347,12.10780734,505257.9413,1.917649951,897.2439965
,134.2,265.84184,12.10781535,508682.4636,1.909361669,898.9675992
,134.4,266.0279068,12.10780352,513243.7227,1.898455997,901.0549935
,134.6,265.7555212,12.10782173,517533.2808,1.8879866,902.9692506
,134.8,266.2045115,12.10779267,522166.5254,1.877517126,905.4171514
,135,265.8755475,12.10781459,525072.266,1.872718674,907.6721835
,135.2,266.2787758,12.10778853,524481.8098,1.877953346,909.1043295
,136,266.0685762,11.99340474,1.7977E+308,1.95211181,0
,136.2,265.8121053,11.87236476,1.7977E+308,1.920703559,0
,136.4,265.5647869,11.75132418,1.7977E+308,1.802050089,0
,136.6,265.2800267,11.63028606,1.7977E+308,1.614472884,0
,136.8,264.8280272,11.50925889,1.7977E+308,1.357535733,0
,137,264.8286557,11.38820206,1.7977E+308,0.94617449,0
,137.2,264.4898132,11.26716748,1.7977E+308,0.600683401,0
,137.4,264.5761416,11.14610504,1.7977E+308,0.329786965,0
,137.6,264.1865448,11.02507378,1.7977E+308,0.13043162,0
,137.8,263.9974689,10.90402939,1.7977E+308,0.020938856,0
,138,263.8841084,10.78298003,1.7977E+308,0.006543392,0
,138.2,263.458734,10.66195112,1.7977E+308,0.014395464,0
,138.4,263.201431,10.54091119,1.7977E+308,0.025737345,0
,138.6,262.8110022,10.41987999,1.7977E+308,0.03097206,0
,138.8,262.7242668,10.29882889,1.7977E+308,0.035770548,0
,139,262.2522983,10.17780303,1.7977E+308,0.039260358,0
,139.2,262.1239611,10.05675465,1.7977E+308,0.033589418,0
,139.4,262.0089365,9.935705404,1.7977E+308,0.029227156,0
,139.6,261.7790908,9.81466368,1.7977E+308,0.027918478,0
,139.8,261.5342684,9.693622937,1.7977E+308,0.028790931,0
,140,261.0098815,9.572600514,1.7977E+308,0.027482253,0
,140.2,260.9572596,9.451547176,1.7977E+308,0.023992443,0
,140.4,260.9387513,9.330491602,1.7977E+308,0.021811312,0
,140.6,260.5957485,9.209457293,1.7977E+308,0.015704145,0
,140.8,260.3459339,9.088416878,1.7977E+308,0.005234715,0
,141,260.4297661,8.967354597,1.7977E+308,0.00697962,0
,141.2,259.7772455,8.846340571,1.7977E+308,0.010905657,0
,141.4,259.5682007,8.725297484,1.7977E+308,0.014395467,0
,141.6,259.2185415,8.604263611,1.7977E+308,0.016140373,0
,141.8,258.9545822,8.483224122,1.7977E+308,0.012650563,0
,142,258.8794954,8.362172256,1.7977E+308,0.010905657,0
,142.2,258.5980633,8.241133912,1.7977E+308,0.009596979,0
,142.4,258.0878209,8.120110563,1.7977E+308,0.010469432,0
,142.6,258.1425319,7.999050191,1.7977E+308,0.0082883,0
,142.8,257.8311464,7.87801381,1.7977E+308,0.009596979,0
,143,257.5264173,7.756976993,1.7977E+308,0.018321506,0
,143.2,257.0669292,7.635950317,1.7977E+308,0.027918486,0
,143.4,257.0297,7.51489597,1.7977E+308,0.03577056,0
,143.6,256.7520121,7.393857381,1.7977E+308,0.034898108,0
,143.8,256.1935115,7.272837194,1.7977E+308,0.027918487,0
,144,256.5011618,7.151760246,1.7977E+308,0.019630186,0
,144.2,255.8681939,7.030744939,1.7977E+308,0.020938866,0
,144.4,255.8430292,6.909689802,1.7977E+308,0.041441506,0
,144.6,255.4663288,6.788657701,1.7977E+308,0.054964525,0
,144.8,255.459469,6.667601364,1.7977E+308,0.059763015,0
,145,254.9384101,6.546578723,1.7977E+308,0.056709432,0
,145.2,254.8104888,6.425530319,1.7977E+308,0.040132829,0
,145.4,254.4599975,6.304496501,1.7977E+308,0.02312,0
,145.6,254.3445568,6.18344728,1.7977E+308,0.022683774,0
,145.8,253.8601075,6.06242224,1.7977E+308,0.032280756,0
,146,253.6077967,5.941381987,1.7977E+308,0.036206794,0
,146.2,253.4611545,5.820334811,1.7977E+308,0.030972077,0
,146.4,252.7699439,5.69932332,1.7977E+308,0.019193964,0
,146.6,252.7639161,5.578266929,1.7977E+308,0.003053585,0
,146.8,252.5386464,5.457224904,1.7977E+308,0.009160756,0
,147,252.1540416,5.336193321,1.7977E+308,0.015267927,0
,147.2,251.9570611,5.215149443,1.7977E+308,0.013959247,0
,147.4,251.2209204,5.094140897,1.7977E+308,0.006107171,0
,147.6,251.5422994,4.97306305,1.7977E+308,0.014831701,0
,147.8,251.1814076,4.852029913,1.7977E+308,0.023120005,0
,148,250.8213478,4.730996722,1.7977E+308,0.027918497,0
,148.2,250.5919179,4.60995497,1.7977E+308,0.029227177,0
,148.4,250.0729389,4.488932193,1.7977E+308,0.027046045,0
,148.6,249.8693984,4.367283459,1.7977E+308,0.021811327,0
,148.8,249.3533315,4.246260492,1.7977E+308,0.017885288,0
,149,249.1416942,4.12582286,1.7977E+308,0.01395925,0
,149.2,248.839461,4.004785879,1.7977E+308,0.007852078,0
,149.4,248.6828344,3.883739356,1.7977E+308,0.001744906,0
,149.6,248.5777941,3.762689453,1.7977E+308,0.000436227,0
,149.8,248.0226214,3.641669048,1.7977E+308,0.004798492,0
,150,247.8368734,3.520624434,1.7977E+308,0.011778118,0
,150.2,247.4123306,3.399595468,1.7977E+308,0.026609823,0
,150.4,247.124242,3.27855756,1.7977E+308,0.036643035,0
,150.6,246.9701115,3.157510874,1.7977E+308,0.034461902,0
,150.8,246.3908096,3.03649205,1.7977E+308,0.030099637,0
,151,245.8980397,2.915467556,1.7977E+308,0.018757745,0
,151.2,245.6640335,2.794426104,1.7977E+308,0.008724533,0
,151.4,245.3850973,2.673387597,1.7977E+308,0.020066426,0
,151.6,244.9131283,2.552361739,1.7977E+308,0.027918507,0
,151.8,244.6724658,2.431320723,1.7977E+308,0.033153227,0
,152,244.5233275,2.31027371,1.7977E+308,0.033589454,0
,152.2,243.9565061,2.189254068,1.7977E+308,0.029663415,0
,152.4,243.8206804,2.068206182,1.7977E+308,0.018321521,0
,152.6,243.2721638,1.947185341,1.7977E+308,0.013086801,0
,152.8,242.8118432,1.82615872,1.7977E+308,0.009160761,0
,153,242.5512118,1.705119013,1.7977E+308,0.014831709,0
,153.2,241.9469487,1.584101825,1.7977E+308,0.028790965,0
,153.4,241.594793,1.463068115,1.7977E+308,0.042750222,0
,153.6,241.4581352,1.342020284,1.7977E+308,0.057145705,0
,153.8,241.1742067,1.220982104,1.7977E+308,0.060199293,0
,229,240.1816602,1.106178739,1.7977E+308,0.015704166,0
,229.2,239.9518141,0.985137014,1.7977E+308,0.01657662,0
,229.4,239.3267498,0.864121189,1.7977E+308,0.011341898,0
,229.6,239.0503096,0.743082518,1.7977E+308,0.012214352,0
,229.8,238.3528579,0.622071437,1.7977E+308,0.013086807,0
,230,238.0073585,0.501037291,1.7977E+308,0.017449076,0
,230.2,237.2591524,0.380029536,1.7977E+308,0.020938892,0
,230.4,236.1049116,0.259048389,1.7977E+308,0.030972113,0
,230.6,235.1229027,0.138055955,1.7977E+308,0.033589476,0
,230.8,233.9141632,0.017078379,1.7977E+308,0.035334387,0
,230.826,233.5492046,0.001364913,1.7977E+308,0.035770614,0
END,,,,,,