File: GB1_test25.csv
Segment,Time On Sample,Displacement Into Surface,Load On Sample,Harmonic Contact Stiffness,Harmonic Displacement,Harmonic Load
Surface Marker,0,0,0,10.79240199,0.477274645,2.204532314
,0.2,0.371534218,0.000632607,2587.584605,0.301023308,2.276848007
,0.4,-0.103189755,0.001320519,8975.244476,0.195447022,2.361216261
,0.6,0.19012597,0.001957871,14863.37288,0.154874312,2.448871642
,0.8,0.475120567,0.00259577,19536.48855,0.132188496,2.556249478
,1,0.338234225,0.003261339,22789.46856,0.116919198,2.660340206
,1.2,0.392733713,0.003914356,25097.63089,0.110375213,2.763335263
,1.4,0.3998028,0.004570484,25627.95116,0.112556541,2.853182009
,1.6,0.316171645,0.00523256,29771.4904,0.109502682,3.212568978
,1.8,0.467196161,0.005879246,32839.93663,0.110375213,3.552233516
,2,0.428499071,0.006538375,35163.3805,0.113429073,3.88203681
,2.2,0.495480243,0.007190573,38771.25475,0.11168401,4.215127181
,2.4,0.385221495,0.007854397,43955.29726,0.106448822,4.576705535
,2.6,0.491311946,0.008504029,47851.14061,0.11168401,5.320680429
,2.8,0.430147824,0.009164632,50115.77657,0.11779173,6.042741455
,3,0.758412258,0.009799693,51126.93399,0.123026916,6.590587524
,3.2,0.628182816,0.010464826,50206.04953,0.138296215,7.276490698
,3.4,0.523748333,0.011131546,49829.10699,0.16098203,8.172766742
,3.6,0.779619518,0.011768075,51483.97794,0.176687592,9.069042869
,3.8,0.742586654,0.012427095,51141.93708,0.202427266,10.15487365
,4,0.772122772,0.013081749,48522.07966,0.236455987,11.20235523
,4.2,0.730097234,0.013741097,46940.73035,0.266558318,12.21039188
,4.4,0.507503325,0.014412288,45678.70534,0.293170527,13.07817988
,4.6,0.319026018,0.015081242,44633.55453,0.331561909,14.50586649
,4.8,0.45756885,0.015728746,43477.04132,0.368208223,15.76481668
,5,0.07104881,0.01641069,42128.15197,0.407472142,16.95035525
,5.2,0.1188914,0.017064144,39900.37456,0.460260288,18.12164999
,5.4,0.21998918,0.017714104,37841.52516,0.512612166,19.10010302
,5.6,0.05314679,0.01838164,34073.24421,0.604664229,20.28016323
,5.8,-0.604641888,0.019081377,30287.79402,0.7019515,20.99455397
,6,-1.706778612,0.01981026,25151.6553,0.863369859,21.63991584
,6.2,-0.919188101,0.020415194,19951.89059,1.083247736,21.87329869
,6.4,0.61397502,0.020971224,16467.57784,1.287856244,21.76373051
,6.6,1.186880467,0.021590238,13141.89314,1.565757426,21.41639645
,6.8,1.229730382,0.022244018,11732.1042,1.724121854,21.16438731
,7,1.497250611,0.022883062,11043.40711,1.817482679,21.07344505
,7.2,1.306276977,0.023552179,11607.8437,1.760331898,21.43173621
,7.4,1.285886358,0.024210107,13405.43775,1.594550954,22.26446213
,7.6,1.278809536,0.024867162,16078.39233,1.403466601,23.24181938
,7.8,1.111135044,0.025534751,20210.63112,1.195804161,24.49857805
,8,1.048306698,0.026195463,23760.15475,1.072777251,25.49565778
,8.2,0.923485986,0.026860241,26515.43481,1.009518738,26.55628749
,8.4,0.819884137,0.027523628,26597.85124,1.031768294,27.21808541
,8.6,0.881456579,0.028176181,25539.80271,1.093281752,27.72977364
,8.8,1.010430118,0.028824312,23557.32545,1.20103936,28.16147637
,9,1.002937239,0.029481395,21975.58557,1.295709011,28.40910276
,9.2,0.991699855,0.030138723,20308.54944,1.408701819,28.63043249
,9.4,1.08863707,0.030788956,19361.85557,1.481994443,28.81231744
,9.6,0.99710085,0.031451552,18749.37621,1.534782598,29.01502038
,9.8,1.309139091,0.032087676,18445.18046,1.567938761,29.2933264
,10,1.297485652,0.032745031,18415.18711,1.579717935,29.5519097
,10.2,1.830449695,0.033366664,18623.0247,1.578845358,29.9145842
,10.4,1.579980035,0.034039684,19030.55572,1.565757411,30.25972697
,10.6,1.263357445,0.034717042,19749.08568,1.535218843,30.65527152
,10.8,1.612008623,0.035350765,20820.20168,1.48984719,31.17791691
,11,1.68148613,0.036002798,21923.72516,1.444039289,31.65125592
,11.2,1.646533547,0.036661682,23409.32905,1.386888494,32.25607789
,11.4,1.791733271,0.037308749,24452.8157,1.353296029,32.77324465
,11.6,1.251688535,0.038000762,25199.59723,1.339335566,33.35067384
,11.8,1.584113524,0.038635549,25707.14772,1.332791558,33.78566388
,12,1.555401783,0.039294023,26179.76337,1.332355295,34.32693575
,12.2,1.875345084,0.039929628,26636.55765,1.331482742,34.84081566
,12.4,1.871596712,0.040586465,27516.91206,1.312287055,35.36893922
,12.6,1.906957616,0.041240736,28598.91254,1.283929786,35.88391449
,12.8,2.160747987,0.041880681,29890.64625,1.252954909,36.5325644
,13,1.641922123,0.042571301,31284.32138,1.220671287,37.22175412
,13.2,2.107069013,0.043197382,32303.18762,1.199730506,37.77179205
,13.4,1.743432086,0.043877824,33371.12464,1.182279904,38.47303455
,13.6,1.774216372,0.044532396,33917.56498,1.180098575,39.06689965
,13.8,1.876562314,0.045182273,34173.16488,1.188823882,39.71993225
,14,1.850762967,0.045840556,34140.44789,1.207583307,40.3335197
,14.2,1.940627224,0.046491252,34029.40545,1.225033928,40.79809325
,14.4,1.937710964,0.047148034,33646.7054,1.252518664,41.26485803
,14.6,1.834941231,0.047811366,33317.39687,1.283493533,41.86529713
,14.8,2.285526154,0.048438402,33215.56467,1.304434253,42.39780398
,15,2.052114799,0.049110302,33146.70724,1.323629958,42.94784114
,15.2,2.08664359,0.049764628,33106.14714,1.338026723,43.35872549
,15.4,2.250149782,0.050410494,33069.47468,1.353296009,43.81124671
,15.6,2.243905073,0.051067494,32895.01075,1.376418089,44.37004964
,15.8,2.318375252,0.0517192,32602.66933,1.403030288,44.86420688
,16,2.394509656,0.052370797,32333.13793,1.42527983,45.21044552
,16.2,2.150280842,0.053043406,31807.1918,1.461053633,45.62461684
,16.4,2.326268717,0.053688454,31459.99483,1.487665823,45.94675049
,16.6,2.090361025,0.054360518,31357.49012,1.508606594,46.39050543
,16.8,2.208101042,0.055009386,31420.28916,1.517331898,46.72907452
,17,2.322512611,0.055658472,31720.10576,1.517768155,47.17830831
,17.2,2.659098148,0.056292985,32411.42723,1.502062566,47.70971938
,17.4,2.523043929,0.0569585,33057.00388,1.486357015,48.19072808
,17.6,2.164815736,0.057638587,33550.97776,1.476322935,48.67283203
,17.8,2.269241957,0.058288328,33851.16993,1.47501413,49.17794615
,18,2.622469741,0.058921749,34014.18673,1.480249291,49.68306072
,18.2,2.638692063,0.059577276,33884.41825,1.494646056,50.05340458
,18.4,2.73479716,0.060227562,33665.99775,1.51253294,50.39745207
,18.6,2.413181909,0.060905247,33376.09982,1.537836374,50.83024989
,18.8,2.659899325,0.061545655,33216.54728,1.554414448,51.15347941
,19,2.584589299,0.062207185,32961.01408,1.577100269,51.53039733
,19.2,2.675701723,0.062857799,32838.27966,1.591497028,51.81856443
,19.4,2.628683514,0.063517473,32745.49344,1.605457533,52.1165927
,19.6,2.955283702,0.064152642,32698.36115,1.620290537,52.49570249
,19.8,3.012279523,0.064805493,32710.59336,1.629452111,52.78386962
,20,2.844605041,0.065473081,32805.03784,1.636868642,53.14983052
,20.2,3.437481101,0.066090997,32987.12587,1.637741122,53.45662518
,20.4,3.413761235,0.066754182,33425.41996,1.627707016,53.82477768
,20.6,3.477412075,0.067418415,34231.55809,1.605457465,54.33865726
,20.8,3.671703495,0.068080593,34937.35944,1.585825496,54.75063787
,21,3.228595348,0.068794724,36199.69452,1.549615489,55.34011945
,21.2,3.635905321,0.069456616,37408.79653,1.516023003,55.85619104
,21.4,3.555596998,0.070153884,38579.26467,1.48722948,56.40513267
,21.6,3.55516979,0.070856334,40107.22018,1.452328232,57.13705496
,21.8,3.459048531,0.071572272,41709.37576,1.416990725,57.85802015
,22,3.084168522,0.07231375,42609.43316,1.401721458,58.42777944
,22.2,3.261809911,0.073026033,42967.20059,1.40521157,59.03698443
,22.4,3.129072277,0.073765986,42970.09659,1.416990753,59.51908877
,22.6,3.622081877,0.074472177,42506.62369,1.446220512,60.09213654
,22.8,3.476028144,0.075227505,41462.02266,1.492028414,60.49535098
,23,3.437315681,0.075983379,40905.48295,1.520821949,60.8207714
,23.2,3.670702724,0.076728883,40787.81813,1.536963758,61.27329258
,23.4,3.512163695,0.077507761,40971.79541,1.540890163,61.70499498
,23.6,3.506732082,0.078284348,41485.15536,1.536527508,62.29009449
,23.8,3.864100156,0.079044914,42388.67188,1.519076855,62.90258699
,24,3.573251566,0.079855873,43143.61453,1.504680114,63.42961439
,24.2,3.902325322,0.080634042,43737.0417,1.498136104,64.02895848
,24.4,3.701342319,0.081455044,44203.33123,1.493773465,64.52968946
,24.6,3.675933703,0.082272631,44673.44499,1.492464671,65.18381765
,24.8,3.954244753,0.083078408,44874.48856,1.497699837,65.75138647
,25,4.101912872,0.083901024,44928.62625,1.5081702,66.31347678
,25.2,4.058193862,0.08474451,45032.86052,1.514714189,66.78571997
,25.4,3.711584663,0.085616336,45023.9936,1.524312062,67.22180475
,25.6,3.821803705,0.086466754,45179.26538,1.532164834,67.81567005
,25.8,3.865036353,0.087330128,45489.70989,1.534782426,68.39638695
,26,4.191185771,0.088183607,45766.26226,1.536091198,68.87191787
,26.2,3.866622067,0.089088464,45999.92579,1.540453884,69.42524177
,26.4,3.683932079,0.089992893,46313.60141,1.540890164,69.9139201
,26.6,4.104105929,0.090866947,46768.77804,1.540017599,70.56476201
,26.8,3.800756788,0.09179744,47098.525,1.542635218,71.15972217
,27,4.358642338,0.092680484,47411.87296,1.54307144,71.63415784
,27.2,4.009940193,0.093632151,47660.90065,1.54787039,72.21268254
,27.4,4.051497171,0.094567637,47916.63204,1.550051715,72.68602158
,27.6,4.617283359,0.09547798,48148.68733,1.55615939,73.31166292
,27.8,4.581866989,0.096437204,48340.37764,1.56139458,73.89018825
,28,4.526894473,0.097407208,48569.5103,1.562703381,74.34270895
,28.2,4.590080321,0.098379305,49034.45491,1.559649516,74.95629664
,28.4,4.711928541,0.099357227,49511.24708,1.554850587,75.49976016
,28.6,4.803403096,0.100347017,50033.73271,1.551796721,76.19004636
,28.8,4.975174922,0.101341308,50409.32008,1.550487912,76.71378754
,29,4.841976027,0.102365737,50899.84522,1.548306593,77.34600166
,29.2,5.157283968,0.103370945,51449.64766,1.544816443,78.00341751
,29.4,5.262898005,0.104400214,51946.76558,1.541326311,78.56222072
,29.6,4.862586196,0.10547306,52601.8197,1.534782359,79.19333858
,29.8,5.291888554,0.106501925,53505.79152,1.523875688,79.93950571
,30,5.077550482,0.107583539,54363.04673,1.513841595,80.66375793
,30.2,5.20063218,0.108653777,55182.64445,1.505988805,81.42416846
,30.4,4.956750678,0.109759015,55535.04018,1.507733888,82.03885113
,30.6,5.311156072,0.110836004,55652.90821,1.515586641,82.657918
,30.8,5.266561956,0.11195004,55558.13849,1.529547144,83.31314168
,31,5.155397109,0.113079507,55244.22368,1.54874284,83.90043242
,31.2,5.045894662,0.114220339,54759.2101,1.570119864,84.31789084
,31.4,5.369920848,0.115344072,54422.27191,1.588879257,84.78575209
,31.6,5.372749938,0.116500217,54517.99221,1.598477101,85.40481808
,31.8,5.500393994,0.117659852,54985.18907,1.59760456,86.04689396
,32,5.529014847,0.118837661,55397.7626,1.59542323,86.56515644
,32.2,5.595078864,0.120024864,56126.4023,1.586697914,87.24558137
,32.4,5.69442548,0.121221745,56894.65102,1.576227532,87.87560445
,32.6,6.149914174,0.122407304,57761.73331,1.565757121,88.66888663
,32.8,5.982981075,0.123645768,58261.13226,1.562267011,89.26932564
,33,5.990789555,0.124885147,59209.55016,1.550924107,90.0582239
,33.2,6.923904767,0.126075985,60301.23273,1.537399797,90.88109095
,33.4,6.721184994,0.127353672,61125.94753,1.528238238,91.57356823
,33.6,6.623309319,0.128637212,62013.1707,1.520821733,92.44245157
,33.8,6.719313725,0.129920861,62672.10323,1.516022805,93.13602501
,34,6.920162203,0.131210537,63176.22834,1.516459055,93.95450754
,34.2,6.8181198,0.13253316,63689.91225,1.516459064,94.77408479
,34.4,6.6128934,0.133875736,64084.55881,1.517767878,95.47204031
,34.6,6.871983417,0.135201283,64457.3955,1.51951292,96.17547532
,34.8,6.962152538,0.136551364,64959.54031,1.52082171,97.01696714
,35,6.951633931,0.137921676,65523.07923,1.521257977,97.88365972
,35.2,6.922806673,0.139306932,65897.40601,1.525184371,98.68461036
,35.4,6.829904586,0.140710212,66080.22232,1.531728362,99.36503492
,35.6,7.182180231,0.142098365,66369.66632,1.536527255,100.0553219
,35.8,7.212426273,0.143521629,66850.56432,1.538708581,100.8968136
,36,7.141984468,0.144965878,67487.29298,1.537399791,101.738305
,36.2,7.446822917,0.14639994,68443.74434,1.529546987,102.6334862
,36.4,7.349748925,0.147874877,69623.13093,1.516022764,103.4596379
,36.6,7.160308131,0.14937073,70886.38229,1.502062283,104.3668705
,36.8,7.136455268,0.15087064,71840.93151,1.496827099,105.3683331
,37,7.487882567,0.152360953,72178.46654,1.503371055,106.2898111
,37.2,7.520608547,0.153887215,72072.12671,1.515586488,106.9757144
,37.4,7.84873189,0.155409323,71666.03616,1.533909614,107.6397049
,37.6,7.799906008,0.156971635,70802.87447,1.564011941,108.4001151
,37.8,7.999047032,0.158533324,70358.11409,1.584516405,109.1276554
,38,7.640670482,0.160147287,70520.58291,1.589751623,109.7456246
,38.2,7.767412706,0.16174551,71057.71558,1.590187879,110.603552
,38.4,7.792634699,0.163366498,71603.44301,1.588442815,111.3256133
,38.6,8.204786212,0.164978357,72318.60516,1.58364386,112.0980773
,38.8,8.195885112,0.166642462,73167.58894,1.578408675,113.02832
,39,8.023888694,0.168325804,73277.20625,1.585388939,113.6846391
,39.2,8.267114859,0.169990262,72883.60638,1.604148337,114.409988
,39.4,8.859824104,0.171656758,72402.513,1.622471438,114.9676972
,39.6,8.706126164,0.173389177,71806.88822,1.645157259,115.6360688
,39.8,8.678074359,0.175130846,71308.61447,1.663044149,116.119269
,40,8.820602756,0.176878702,71292.03968,1.672205713,116.775589
,40.2,8.859946457,0.178650974,71724.07861,1.670024383,117.3617846
,40.4,8.766149401,0.180449808,72604.13909,1.65955402,118.0706971
,40.6,9.119193654,0.182237217,73972.32081,1.642103369,119.0349074
,40.8,9.291666712,0.184054627,75105.43514,1.628142858,119.8084668
,41,8.900797016,0.185927392,76120.05506,1.618981318,120.7200811
,41.2,9.064110978,0.187782304,76658.06806,1.617236242,121.4311862
,41.4,9.181655787,0.18965904,76708.06791,1.625089012,122.10175
,41.6,9.164395467,0.191563391,76368.94467,1.642539635,122.8621604
,41.8,9.035629087,0.193494243,76159.50227,1.654755081,123.4253456
,42,9.34954322,0.1954154,76333.28091,1.661299037,124.1561736
,42.2,9.326448921,0.197377981,76548.80535,1.665225429,124.7555169
,42.4,9.343292863,0.19935766,77101.61736,1.662607836,125.4216979
,42.6,9.256951747,0.201364053,78032.08789,1.655191331,126.3344094
,42.8,9.937814707,0.203340118,78493.07965,1.65431874,127.0049751
,43,9.35469634,0.205419331,78516.18137,1.663044103,127.7357999
,43.2,9.316192009,0.207483327,78367.94678,1.673078214,128.2935069
,43.4,9.640069191,0.209544067,78016.39369,1.687038682,128.8282058
,43.6,9.608631232,0.211648996,77425.81158,1.707543164,129.4363148
,43.8,9.773568332,0.213762242,77252.64605,1.717140992,129.8899321
,44,10.00548709,0.215892184,77481.78631,1.720631095,130.5495395
,44.2,9.583778457,0.218086609,77822.75573,1.720194872,131.1017667
,44.4,10.07239686,0.22024316,78225.93533,1.718886033,131.6781026
,44.6,10.10251809,0.222451611,78990.58594,1.712342045,132.4582357
,44.8,9.920863277,0.224696258,79577.27688,1.707543143,133.0783967
,45,9.946400779,0.226949754,80118.5546,1.705361818,133.8136062
,45.2,9.904949686,0.229230169,80381.50402,1.707106883,134.3844617
,45.4,10.40769619,0.231497762,80683.4406,1.708415632,134.9914771
,45.6,9.919809714,0.233853432,80773.40208,1.714959659,135.6850484
,45.8,10.34724269,0.236172457,80711.143,1.722376135,136.1770158
,46,9.921757157,0.238570968,80641.19383,1.731537751,136.7796448
,46.2,10.0392209,0.240957674,80566.77662,1.739826783,137.3137952
,46.4,10.72875782,0.243330753,80694.76225,1.744625644,137.9082109
,46.6,10.46593875,0.245790483,80875.59564,1.746806995,138.3859317
,46.8,10.64871175,0.248245441,81337.58176,1.745061917,139.042252
,47,10.58059905,0.25074167,81650.09808,1.744625658,139.5594184
,47.2,10.88984515,0.253238087,82207.87661,1.741135507,140.2398445
,47.4,10.9028554,0.255779132,82430.1069,1.742880566,140.7734469
,47.6,11.32692489,0.258318681,82731.68765,1.745061854,141.4582562
,47.8,11.37903629,0.260908114,82727.90668,1.750733301,141.9096814
,48,11.54098232,0.263516466,82904.65149,1.754223411,142.5123128
,48.2,12.48594152,0.266099315,83075.54488,1.75640465,143.009761
,48.4,12.7930828,0.26875012,83484.84953,1.754223294,143.5718525
,48.6,12.71994469,0.271452673,84305.36685,1.745934259,144.3267841
,48.8,12.73126164,0.274176732,85400.74781,1.7315375,144.9984435
,49,12.89901126,0.276917941,86923.30406,1.711905541,145.9023904
,49.2,13.36714886,0.279667076,88655.63815,1.690092228,146.8797495
,49.4,13.87147893,0.282441418,90290.19246,1.670460239,147.8012289
,49.6,14.1686087,0.285257319,91853.61744,1.652137067,148.7106547
,49.8,14.20445086,0.28811871,93536.17017,1.634250183,149.8304527
,50,14.55316249,0.290988287,94826.79371,1.622034722,150.7322089
,50.2,14.62560839,0.293904992,96620.30034,1.605456632,151.9407576
,50.4,14.33441679,0.296874831,97984.05642,1.594113758,152.9466022
,50.6,14.68644288,0.299832173,99135.08993,1.587133482,153.9929896
,50.8,14.70728373,0.302841113,100229.8822,1.582770827,155.1861986
,51,14.45685134,0.305898032,101002.7096,1.580153257,156.1350676
,51.2,14.63994432,0.308957183,101600.4623,1.581898304,157.3074589
,51.4,14.86463801,0.312044237,101905.832,1.585824674,158.268382
,51.6,14.79975185,0.315181445,101906.9878,1.594549988,159.20739
,51.8,14.71738633,0.318351367,102050.9542,1.602839039,160.2866465
,52,14.87050339,0.321537585,102003.8675,1.612436865,161.1182778
,52.2,14.81641953,0.3247694,102142.7685,1.621162178,162.1405585
,52.4,15.01778883,0.32801693,102261.8127,1.628578673,163.0017736
,52.6,15.11597107,0.331303929,102970.3026,1.627706134,163.9736533
,52.8,15.1950095,0.334625137,103493.8807,1.630759986,165.055102
,53,15.51202657,0.337964157,103679.232,1.636431409,165.8954995
,53.2,15.41464664,0.341364044,103545.9781,1.648210583,166.8224545
,53.4,15.24320334,0.344802915,103609.2661,1.655627111,167.626692
,53.6,15.47948934,0.348249396,103093.072,1.671332644,168.3597115
,53.8,15.69746335,0.351731846,103000.3155,1.681802994,169.269137
,54,15.79893615,0.355256903,103269.4959,1.68616564,170.1774666
,54.2,16.10676704,0.358803801,103682.6703,1.686601878,170.9455482
,54.4,16.45370154,0.362383651,103637.4898,1.694018358,171.6917165
,54.6,16.45363969,0.366022443,104416.6422,1.691400767,172.7786432
,54.8,17.07266317,0.36965698,105028.1369,1.68878312,173.5664489
,55,17.08507137,0.373368073,105877.6523,1.684856731,174.5985914
,55.2,16.81039513,0.377135229,106678.4597,1.680494104,175.4641871
,55.4,16.89185669,0.380916762,107919.0891,1.670459994,176.4141527
,55.6,17.30366054,0.384714686,109230.7954,1.662607182,177.655574
,55.8,17.23200143,0.388582506,109657.1961,1.664788516,178.523362
,56,17.29929882,0.392479949,109808.88,1.672205022,179.5138684
,56.2,17.29169676,0.396441357,109707.6259,1.682675391,180.4211018
,56.4,17.50044376,0.40038847,109556.1263,1.69227321,181.1880875
,56.6,17.99126387,0.404397187,109277.9539,1.703616065,181.9517872
,56.8,17.9811528,0.408438576,109360.8043,1.708851251,182.6683704
,57,17.81126659,0.41255145,109411.6553,1.716267778,183.5624547
,57.2,17.8186136,0.416693978,109753.3213,1.717576574,184.2965684
,57.4,18.13633164,0.420857731,110030.1321,1.720194137,185.0745117
,57.6,18.21439487,0.425079132,110594.7724,1.720630396,186.1022716
,57.8,18.2092402,0.429348299,111192.1753,1.718449071,186.8824045
,58,18.38547905,0.433648516,112699.5088,1.705797362,188.0284999
,58.2,18.9902485,0.437963837,113822.9343,1.698380797,189.1022812
,58.4,19.69320026,0.442315762,115030.0834,1.689655428,190.1793512
,58.6,20.27465674,0.446719531,115860.6068,1.685292723,191.095353
,58.8,20.19873799,0.451211026,116421.9386,1.686165261,192.1526959
,59,20.46397785,0.455724973,116538.853,1.690964156,192.9536484
,59.2,20.70591137,0.460285865,116904.7551,1.694454257,193.9748356
,59.4,20.78391161,0.464903437,117498.3037,1.694454251,194.8875474
,59.6,20.83860537,0.469568833,118556.9717,1.688782798,195.8999676
,59.8,21.13044349,0.474265358,120665.0558,1.671768428,197.2443842
,60,21.0578093,0.479032755,122207.2868,1.660861804,198.3203536
,60.2,21.0068024,0.483846618,124064.7673,1.648646383,199.6713422
,60.4,21.63395873,0.488664148,125356.4504,1.642102349,200.8426409
,60.6,22.482449,0.493515453,125584.9113,1.650391317,202.1300844
,60.8,22.70268729,0.498457101,124968.8349,1.665224313,202.9408985
,61,23.15923737,0.503432741,124799.236,1.676130903,204.0092013
,61.2,23.04495104,0.508495891,124450.9162,1.687037544,204.8013863
,61.4,23.48276257,0.513573587,124408.2031,1.694454014,205.6560291
,61.6,23.54070709,0.518727462,125980.7482,1.684419911,207.0245493
,61.8,23.61486956,0.523931957,127911.0628,1.668714358,208.1947496
,62,23.81092804,0.529180766,129928.8324,1.654753856,209.6454475
,62.2,23.6916079,0.534503103,132131.8224,1.637739526,210.9515125
,62.4,23.79112459,0.539864354,133841.3963,1.626832888,212.2290907
,62.6,23.64224745,0.545295907,134603.4885,1.629450493,213.767442
,62.8,23.87114022,0.550757129,134641.8359,1.636866982,214.8006817
,63,23.94733181,0.55628337,134347.1716,1.64995493,216.0103267
,63.2,24.80694748,0.561813393,132925.9617,1.675258234,216.9822113
,63.4,24.65429078,0.567465779,132003.0945,1.693145124,217.7700134
,63.6,24.61978488,0.57316707,131654.304,1.704488018,218.6542371
,63.8,25.04709169,0.578895286,131745.054,1.711468225,219.7488366
,64,25.34749235,0.5846895,132432.6357,1.709286873,220.6977083
,64.2,25.09036911,0.590578742,134386.2101,1.69445388,222.0881408
,64.4,25.39075112,0.596490267,136446.7845,1.678312043,223.3931125
,64.6,25.39447597,0.602480786,138393.058,1.664787824,224.7408144
,64.8,25.90037046,0.608498426,140083.838,1.656062475,226.2178115
,65,26.17284809,0.61459194,140870.1511,1.655626188,227.3430895
,65.2,26.43200222,0.620747437,140948.8407,1.664351468,228.6469654
,65.4,26.88461239,0.626952082,140647.4827,1.675258055,229.6582926
,65.6,27.14083437,0.633232012,139935.3701,1.690091047,230.5688151
,65.8,27.45779044,0.639571078,139215.2485,1.705796562,231.614108
,66,27.66281741,0.645981233,139330.4422,1.711904256,232.7163763
,66.2,27.68518572,0.652467828,140024.909,1.710595459,233.6992125
,66.4,28.09530753,0.658993943,140699.6584,1.710159157,234.7576546
,66.6,28.10309313,0.665612073,141920.0606,1.706232772,236.1535671
,66.8,28.26231246,0.672286468,143235.7646,1.699688782,237.2908973
,67,28.24594563,0.679039584,143667.3794,1.7044877,238.534508
,67.2,28.52330329,0.685841193,143535.8833,1.712776712,239.4066814
,67.4,28.75238763,0.692714318,143572.3891,1.719756933,240.3566483
,67.6,29.18699246,0.699642961,143933.6019,1.724555809,241.6166978
,67.8,30.0750868,0.706611348,143566.4911,1.734153558,242.419847
,68,30.15685428,0.713702825,143519.6656,1.741570057,243.4552773
,68.2,30.16372044,0.720870402,143799.39,1.744187648,244.3395011
,68.4,30.31785883,0.728100338,144006.2114,1.74724149,245.2072915
,68.6,30.47864255,0.735402498,144404.1518,1.750731596,246.374205
,68.8,30.53124016,0.742785148,145206.9179,1.748114001,247.3033527
,69,30.77687576,0.750229282,146599.212,1.741133739,248.5798368
,69.2,30.78701202,0.757763733,147369.9173,1.738952413,249.5363766
,69.4,31.20903127,0.765346657,148054.6345,1.738079845,250.5323642
,69.6,31.21581493,0.773033248,148669.6722,1.739824905,251.7759755
,69.8,31.35489201,0.78078824,149109.4282,1.741569953,252.7138896
,70,31.82347267,0.78859952,149352.5183,1.746368825,253.7789061
,70.2,32.30951521,0.796488015,149638.2703,1.749422635,254.6697082
,70.4,32.42691993,0.804480096,150247.4529,1.749422625,255.6558326
,70.6,32.83471863,0.812533367,151170.0768,1.747241262,256.9323177
,70.8,32.84808385,0.820693468,151904.4389,1.744623672,257.9118672
,71,32.99124535,0.828927072,153758.0018,1.73240824,259.3417476
,71.2,33.21261216,0.837238087,155121.7301,1.724119186,260.4768869
,71.4,33.25839023,0.845644357,156374.0269,1.717575207,261.6679052
,71.6,33.94155192,0.854093115,157891.9019,1.711031171,263.2183154
,71.8,34.70042219,0.862621744,158218.1452,1.716266281,264.4926124
,72,35.42016959,0.871238622,157898.7226,1.725427779,265.3943728
,72.2,35.6589431,0.879973757,158512.1325,1.727172817,266.6872922
,72.4,35.85027234,0.888799762,159297.2468,1.725864005,267.796135
,72.6,36.21549865,0.897703082,160471.678,1.721501323,269.0539932
,72.8,36.66808236,0.906690153,163008.6055,1.705359481,270.7073972
,73,36.87185058,0.915783813,165325.3309,1.690962721,272.1109821
,73.2,36.99488952,0.924974131,166911.3734,1.685727532,273.7446609
,73.4,37.35090481,0.93424149,167513.3291,1.687908825,275.0211459
,73.6,37.82589716,0.943594053,167787.3847,1.693143961,276.2592828
,73.8,38.11531383,0.953052933,167415.6728,1.705795617,277.5774036
,74,38.18836658,0.962621051,166846.1533,1.718011027,278.5405185
,74.2,38.94289507,0.972288987,166460.9168,1.729790109,279.7118198
,74.4,39.49604496,0.982019086,166816.8602,1.734152706,280.8842162
,74.6,40.27635339,0.991782486,167330.4735,1.735897693,281.8966427
,74.8,40.22369549,1.00174847,168416.7948,1.733716375,283.2772158
,75,40.59706237,1.01178645,169863.978,1.726736104,284.4857685
,75.2,40.83727551,1.021934062,171948.8051,1.715829463,286.0580896
,75.4,40.89440808,1.03219567,174004.3367,1.704486573,287.4956394
,75.6,41.34095207,1.042534693,175919.6031,1.694888708,289.0120822
,75.8,41.64269227,1.052987194,177818.5374,1.687035915,290.7619068
,76,42.03012317,1.063539086,178856.1206,1.686599616,292.4054492
,76.2,42.12962695,1.074215884,179404.5342,1.688344666,293.6665931
,76.4,42.4512872,1.084985364,179399.4889,1.695324874,294.9277388
,76.6,42.59236224,1.095874989,179331.6214,1.704922687,296.4978682
,76.8,42.91315575,1.106862327,179686.4335,1.708412776,297.6790277
,77,42.99927653,1.117975448,180709.0947,1.707976504,299.2403916
,77.2,43.34166964,1.129183237,181135.7649,1.711030327,300.4204566
,77.4,43.66823474,1.140504747,181707.6959,1.712775356,301.644348
,77.6,43.90075325,1.151946203,182359.068,1.715829189,303.2594018
,77.8,44.23393888,1.163495909,182594.8686,1.720191806,304.4044038
,78,44.24591138,1.175182856,182721.1612,1.727172041,305.8167523
,78.2,44.36479141,1.186980263,183565.5129,1.726299502,307.0187291
,78.4,44.87557663,1.198870556,184521.6023,1.724990661,308.3050772
,78.6,45.42378784,1.210877734,185933.0755,1.721936758,309.9771098
,78.8,45.92122113,1.22300879,187119.9669,1.720627922,311.5976446
,79,46.09452801,1.235283093,187714.9773,1.721936698,312.7766119
,79.2,46.61730167,1.247657685,187978.9095,1.727608092,314.2032093
,79.4,46.90123988,1.260172267,188388.705,1.730661919,315.4161447
,79.6,47.38902513,1.272799261,188853.6327,1.734151992,316.8246622
,79.8,47.88219892,1.285552826,189664.8812,1.734151945,318.1860656
,80,48.0662233,1.29845496,191268.287,1.728044225,319.6871672
,80.2,48.35673723,1.311479596,192692.4786,1.723681552,321.1827912
,80.4,48.51242847,1.32464393,193920.7359,1.720627686,322.5776102
,80.6,49.13948921,1.337909479,196000.4514,1.71321113,324.4863138
,80.8,49.64670483,1.351316312,198030.6597,1.704485793,326.0553513
,81,49.76322324,1.364883596,200189.5046,1.696633019,327.996921
,81.2,49.84934797,1.378589133,202019.9618,1.689652778,329.604304
,81.4,50.37230871,1.392403576,203430.4485,1.686162615,331.2533274
,81.6,50.17588804,1.406404234,204043.8936,1.688343957,332.8300284
,81.8,51.05661175,1.420474667,202884.6013,1.704485664,334.319084
,82,51.48963764,1.434716041,201446.1526,1.722808737,335.6602168
,82.2,52.77638586,1.449044022,200570.3513,1.735460291,336.7230516
,82.4,52.98136792,1.463587314,200551.9433,1.741567976,337.8779145
,82.6,53.88821165,1.478230515,200537.9635,1.749856916,339.4020329
,82.8,53.93005348,1.493077889,201611.6082,1.747239325,340.7168651
,83,54.26810283,1.508054792,202753.689,1.744621707,342.256318
,83.2,54.67228099,1.523177892,203530.1997,1.744185406,343.5492403
,83.4,55.05105563,1.538454617,203693.3542,1.748548016,344.761081
,83.6,55.38320771,1.553887819,204939.2566,1.746802927,346.4758449
,83.8,56.23332361,1.5694421,206017.0219,1.746802848,348.0240681
,84,56.27751609,1.585205819,206639.0976,1.748984167,349.2676798
,84.2,56.58671056,1.601109611,208083.6183,1.746366552,350.8969798
,84.4,57.11638879,1.617158588,209417.6255,1.742876387,352.2764633
,84.6,57.3315038,1.633389619,210868.4328,1.738949988,353.7863311
,84.8,57.87777265,1.649761848,212700.0673,1.7332785,355.6194315
,85,58.35245386,1.666303403,214915.0196,1.72368064,357.2410632
,85.2,58.7547151,1.683015868,217234.8308,1.71539158,359.2472825
,85.4,59.09537352,1.699900162,218593.7854,1.712773962,360.8360418
,85.6,60.23150201,1.716901689,219476.5555,1.713646387,362.4280964
,85.8,60.27337884,1.734146204,220144.035,1.716700234,364.1757274
,86,60.85609953,1.75152832,219885.3123,1.724552939,365.450026
,86.2,61.26987414,1.769096253,219742.0507,1.732841924,367.0278291
,86.4,61.59624918,1.786846388,219884.2522,1.737640801,368.3317078
,86.6,62.40105896,1.804743377,220153.9918,1.743748427,370.0409984
,86.8,62.96119988,1.822836264,220186.8363,1.749419811,371.2528417
,87,63.8167108,1.841091611,220064.0649,1.757272488,372.6772522
,87.2,63.99485529,1.859574811,219697.5967,1.766434021,374.0183836
,87.4,64.64477642,1.878212776,219656.4595,1.770796603,374.9321992
,87.6,65.00093309,1.897057196,219800.9902,1.77603174,376.4113898
,87.8,65.60003566,1.91607491,221039.9786,1.773414098,377.996865
,88,66.45040491,1.935267334,222820.447,1.765997526,379.4070319
,88.2,66.67998974,1.954693474,225607.5894,1.753345843,381.3310732
,88.4,67.05183429,1.974305372,227327.0307,1.747674374,382.8453265
,88.6,67.43945761,1.99411319,228244.1144,1.749419395,384.6214502
,88.8,68.01677023,2.014107631,228341.6668,1.754218247,385.8278153
,89,68.37520611,2.034317336,227695.1791,1.765561082,387.2204452
,89.2,69.04731497,2.054709512,226776.6944,1.777340151,388.1934298
,89.4,69.4680942,2.075323032,227308.0368,1.779085168,389.4337593
,89.6,70.24248699,2.096120463,230047.9982,1.767305963,391.4093045
,89.8,70.51841303,2.11715955,233338.0191,1.752036693,393.5086571
,90,71.24031609,2.138380644,235705.7925,1.741566287,395.1302921
,90.2,71.59938556,2.159838852,239141.6389,1.726297011,397.366608
,90.4,72.20056457,2.181496699,241422.197,1.718007938,399.2084767
,90.6,72.6169807,2.203384314,242848.257,1.71582658,401.0152814
,90.8,73.34457073,2.225471425,244459.0099,1.714081457,403.098203
,91,74.10540984,2.247778144,246519.4965,1.708409955,404.8841934
,91.2,74.93527835,2.270304471,248054.3274,1.707973615,407.0361466
,91.4,75.60035324,2.293067971,248602.0356,1.71189993,408.6884609
,91.6,76.24375691,2.316061612,249157.3598,1.715826247,410.408708
,91.8,76.88213118,2.339286599,249306.7971,1.723242676,412.3283717
,92,77.39480102,2.362871763,249072.1092,1.730659116,413.7374409
,92.2,77.78596391,2.386584576,249604.2637,1.734585456,415.6023162
,92.4,78.55821401,2.410390013,250105.6383,1.737202968,417.1669767
,92.6,78.85774964,2.434708037,251157.5827,1.738075468,419.243321
,92.8,79.58582146,2.458997451,252855.1481,1.733276498,420.951517
,93,80.08750128,2.483668768,255065.0559,1.727168757,423.1374332
,93.2,80.55003256,2.508590548,256098.9201,1.726732451,424.7798848
,93.4,81.05662579,2.533759841,257091.5396,1.727168668,426.497939
,93.6,82.0108534,2.559152533,257304.1661,1.734148801,428.5337506
,93.8,82.64967113,2.584821251,256254.9219,1.746364129,429.7981895
,94,83.1411646,2.610757484,255089.7704,1.76076079,431.3135407
,94.2,83.65341937,2.636952881,254521.1731,1.771231073,432.7938299
,94.4,84.35452098,2.663399003,255374.222,1.771667271,434.2543999
,94.6,85.24862955,2.69009813,257886.4209,1.762505647,436.1149004
,94.8,85.83065468,2.717086049,261811.6479,1.745927569,438.444354
,95,86.35854961,2.744348783,265043.0064,1.732839607,440.4648205
,95.2,87.1734785,2.771866403,270674.1962,1.708845027,443.2939139
,95.4,87.79364995,2.799673485,274281.5367,1.696193322,445.5970718
,95.6,88.29852991,2.82776772,276870.8421,1.689649321,447.8476349
,95.8,89.06755933,2.856127666,278724.0996,1.688776724,450.3633596
,96,89.99464412,2.884761639,280303.9832,1.689212901,452.8484066
,96.2,90.55222696,2.913707642,280185.7043,1.696193072,454.6190564
,96.4,91.18132492,2.942939541,279393.6968,1.706663342,456.344783
,96.6,92.10535864,2.972445574,278796.6873,1.717569848,458.5109833
,96.8,92.80009934,3.002263054,278592.0839,1.724113738,460.1545346
,97,93.26970707,3.032395001,278157.9743,1.73327523,462.1311739
,97.2,94.17154697,3.062801178,278348.7533,1.738946574,464.0891925
,97.4,94.95351464,3.093520865,279318.583,1.739382763,465.8817588
,97.6,95.7466667,3.12454834,280866.1675,1.737201374,467.8518292
,97.8,96.36294616,3.155899305,282197.6952,1.737637578,470.0991068
,98,97.2487786,3.187547426,283964.6913,1.734147389,471.9661832
,98.2,98.07714499,3.219517328,285790.2502,1.732838521,474.2989286
,98.4,98.95954729,3.25180496,286965.1047,1.733710965,476.2142151
,98.6,99.86644519,3.284415326,288610.4231,1.73240209,478.2303059
,98.8,100.5319796,3.317369248,291635.611,1.724985554,480.7295951
,99,101.4092329,3.350640316,293645.882,1.721495361,482.7237718
,99.2,102.2281854,3.384249526,296483.8023,1.715387599,485.3260586
,99.4,102.8943924,3.41820651,299068.9218,1.709279851,487.5853908
,99.6,103.4735899,3.452510367,301353.2639,1.706225953,490.3673685
,99.8,103.9832516,3.487163534,302915.7978,1.704917116,492.5280862
,100,105.17269,3.522120085,304844.447,1.703171956,495.1829719
,100.2,105.5615848,3.557480586,306383.2501,1.70186313,497.3645063
,100.4,106.3481707,3.593170106,307884.897,1.701426794,499.5876827
,100.6,107.1047436,3.629220175,310134.4876,1.698372884,502.0836865
,100.8,108.1387669,3.665614235,310609.4912,1.704916738,504.6355754
,101,109.1119881,3.702378,310551.481,1.712551255,506.7656208
,101.2,110.2474115,3.739500417,310269.5157,1.721058283,508.7959605
,101.4,110.9887727,3.777021947,310767.7704,1.724984583,510.8306767
,101.6,111.6859723,3.814922057,312124.0755,1.726293308,513.4241972
,101.8,112.6780937,3.853182832,314865.7261,1.719749269,515.7273629
,102,113.7350583,3.891823787,317866.5535,1.712332698,518.1072292
,102.2,114.326813,3.93088349,321509.002,1.704043645,521.1368354
,102.4,115.4543825,3.970300433,323204.9273,1.703607279,523.5857316
,102.6,116.2257471,4.01013686,322815.4042,1.712332469,525.6368845
,102.8,117.106054,4.050366258,320298.4647,1.731527961,527.6464037
,103,118.2484105,4.090982592,318524.2526,1.74679706,529.6131931
,103.2,119.584583,4.131994318,317178.3275,1.758576034,531.082541
,103.4,120.3115875,4.173458265,317855.0611,1.761193543,532.9561912
,103.6,121.4886956,4.215309005,320613.3743,1.755522014,535.6242282
,103.8,122.4768486,4.257592845,324004.7088,1.745487874,537.8715149
,104,123.0289099,4.300330209,327208.7581,1.738507616,540.5943266
,104.2,123.7348427,4.343486736,329735.6866,1.733272395,542.7977811
,104.4,124.8168189,4.387052097,330298.2879,1.737634923,544.8631848
,104.6,125.7697489,4.431063603,331115.0403,1.741997462,547.3953525
,104.8,126.6585364,4.475521597,331901.5114,1.744178693,549.3259812
,105,127.6537625,4.520419213,334145.9854,1.740688497,551.9151253
,105.2,128.7662438,4.565760196,337043.421,1.734144452,554.7157418
,105.4,129.8536895,4.611558398,340901.6349,1.722801519,557.4056912
,105.6,130.5158555,4.657844714,344175.3881,1.714948729,560.1186457
,105.8,131.5881761,4.704568993,346535.8666,1.712767316,563.0113002
,106,132.6013425,4.75176654,347300.2374,1.716693587,565.227909
,106.2,133.9755677,4.799414602,347257.5454,1.725854975,567.7129688
,106.4,135.1741422,4.847553077,345676.2954,1.739815267,569.5537569
,106.6,136.311896,4.896179184,344934.2305,1.749412937,571.4241296
,106.8,137.3738503,4.94529879,344415.786,1.75857435,573.574997
,107,137.9755714,4.994942288,345316.4521,1.761191869,575.8880222
,107.2,139.3860205,5.045031183,346805.3778,1.759882947,577.8942647
,107.4,140.2937973,5.095656509,349035.2989,1.755956499,580.1207344
,107.6,141.3729071,5.146779134,352545.707,1.748539935,583.1032365
,107.8,142.5717585,5.198407508,356603.7114,1.738942048,586.0714976
,108,143.8670516,5.250548348,358793.1984,1.73588809,588.3735765
,108.2,144.9201185,5.303228904,360416.0672,1.736760516,591.1621414
,108.4,145.6136315,5.35646238,360533.067,1.742431862,593.3206748
,108.6,146.9627589,5.410187539,360217.8713,1.749848195,595.3948501
,108.8,148.0663292,5.464468631,357877.968,1.765989796,597.3331563
,109,149.3620292,5.51928232,356275.9861,1.777332491,598.8529084
,109.2,150.6043867,5.574650626,354686.7815,1.789547715,600.6772644
,109.4,151.5146455,5.630596881,353421.9718,1.799581658,602.2013942
,109.6,152.5795867,5.687095072,352762.2871,1.807870537,604.1670917
,109.8,153.7958348,5.744440053,353602.3482,1.80830668,605.8106575
,110,155.4689088,5.801754778,355416.3403,1.806125206,607.9418163
,110.2,156.471168,5.859979511,357821.7543,1.800453701,609.8012306
,110.4,157.5415668,5.918784657,362173.4086,1.787801997,612.2567052
,110.6,158.9605238,5.978157855,367269.6679,1.773405212,615.3246808
,110.8,159.6953952,6.038172564,371808.6253,1.760317281,617.920399
,111,161.2747577,6.098734568,377080.9184,1.745920485,621.1812205
,111.2,162.3256365,6.159940135,381434.3962,1.734141313,623.9007583
,111.4,163.6285453,6.221743995,385021.462,1.725852214,626.7090532
,111.6,164.8797649,6.284172059,388608.4332,1.719744431,630.2624197
,111.8,166.1874678,6.347223707,391719.2657,1.715381691,633.5254282
,112,167.7863066,6.410889771,394553.3448,1.711018924,636.2548388
,112.2,168.9015906,6.475227431,395994.1643,1.713636392,639.3162367
,112.4,170.1107997,6.540205295,395836.8355,1.72105273,641.7760989
,112.6,171.7068337,6.605810448,396512.684,1.725415199,644.2896556
,112.8,173.0173509,6.672093451,396346.4886,1.734140311,647.1384942
,113,174.4459209,6.739034844,395447.943,1.745046719,649.7112182
,113.2,175.7058824,6.806662266,395708.8721,1.749409217,651.7842992
,113.4,176.9162253,6.874973464,398912.9618,1.743737701,654.5246596
,113.6,178.5782921,6.943939913,402276.4887,1.739374929,657.8797166
,113.8,179.9361145,7.01361868,405173.3845,1.735012185,660.5116069
,114,181.3063071,7.083996558,409525.5062,1.727159349,663.986089
,114.2,182.4101139,7.15509846,414768.7625,1.71668897,667.5438389
,114.4,183.9577348,7.226885261,416748.0799,1.716688827,670.4277448
,114.6,185.7873243,7.299374622,417777.0744,1.719742487,673.1549707
,114.8,187.2810438,7.372614461,419161.2354,1.722796178,676.4552417
,115,188.6265316,7.446599984,419953.1699,1.726286143,679.0345387
,115.2,189.9540109,7.521330112,418816.957,1.73719255,681.8165403
,115.4,191.7793851,7.596778192,418591.0144,1.743736297,684.1701358
,115.6,192.7425789,7.673041086,421424.2202,1.739809857,687.0123946
,115.8,194.37175,7.750026451,425301.906,1.733702046,690.5953583
,116,195.6525626,7.827808224,428254.4177,1.729339309,693.4135183
,116.2,197.5086505,7.906333525,433247.2875,1.719741395,697.1334493
,116.4,199.0076405,7.985671422,438675.4469,1.708398468,700.7438038
,116.6,200.9138182,8.065779602,442179.7469,1.704471942,704.6993116
,116.8,202.2615264,8.146729527,444122.6599,1.704035554,707.6894986
,117,203.8791228,8.228475103,444519.9782,1.710143057,711.1135878
,117.2,205.3680285,8.311050431,445128.0714,1.714069272,713.8287579
,117.4,206.9258668,8.394450891,444706.6209,1.72235808,716.5483124
,117.6,208.3824712,8.478695982,444032.9998,1.733264467,719.7521638
,117.8,209.8410212,8.563787339,443142.3373,1.74286207,722.0958923
,118,211.9493077,8.649690925,444539.2821,1.745915697,725.1167757
,118.2,213.5477936,8.736491262,445733.3563,1.749405632,728.1529891
,118.4,215.2068843,8.824159752,446964.0903,1.751150517,730.7859858
,118.6,216.3794708,8.912741048,448861.8189,1.751150406,733.6161991
,118.8,218.4759658,9.002151439,451479.7583,1.749405164,736.9208704
,119,219.6178961,9.092522336,452414.2937,1.752895141,740.0534956
,119.2,221.6442077,9.183739154,451989.1297,1.759438856,742.3238256
,119.4,223.2593148,9.275899517,450806.2716,1.769036434,744.5744245
,119.6,224.8992376,9.368984242,449888.2443,1.778197747,747.3323325
,119.8,226.6338713,9.46299792,450586.8021,1.780378882,749.5829357
,120,228.4989948,9.557947604,452833.5569,1.77906992,752.6629847
,120.2,230.1917212,9.653862656,457022.8353,1.770344549,755.4658199
,120.4,232.0823346,9.750728315,463056.5444,1.756384038,758.8548565
,120.6,233.6066682,9.848591274,469225.306,1.744604865,763.0601819
,120.8,235.7931987,9.947393692,472430.2502,1.740678316,766.1216128
,121,237.6716933,10.04720915,475370.6278,1.738933097,769.7571834
,121.2,239.4135636,10.14803659,475194.0073,1.745040575,772.3518376
,121.4,241.2235051,10.24987252,475070.0708,1.751148045,774.9596408
,121.6,243.0399406,10.35273111,477815.5317,1.749839092,778.642326
,121.8,245.0742223,10.45660879,480277.6426,1.748093858,781.5131035
,122,246.8079492,10.56154992,482674.1868,1.748093694,785.1059411
,122.2,248.4624587,10.66755061,486462.2152,1.742422157,788.1991376
,122.4,250.4845875,10.77459216,491019.8877,1.735005548,791.7010378
,122.6,252.3043446,10.88272239,495016.6052,1.731079038,795.952395
,122.8,254.331122,10.99192535,498827.3688,1.726716249,799.8410792
,123,256.1888083,11.10223673,501912.4856,1.723662257,803.0964449
,123.2,258.0903098,11.11488326,504600.476,1.72409834,807.1122277
,123.4,259.4995732,11.11479151,504679.3722,1.730642104,810.04764
,123.6,260.2514769,11.11474288,505245.0028,1.73587715,813.1408177
,123.8,261.5226114,11.1146602,506650.6388,1.739803368,816.7643268
,124,261.9158795,11.11463509,507995.5467,1.74198463,819.6591745
,124.2,262.9482011,11.11456807,510707.711,1.741548274,823.4327885
,124.4,263.4662843,11.11453478,513659.1112,1.739803188,826.8743924
,124.6,263.889508,11.11450771,515616.8368,1.741984447,830.7203104
,124.8,264.6547251,11.1144582,516325.9186,1.745910712,833.6425598
,125,265.021366,11.11443484,515211.9045,1.756380907,836.8080456
,125.2,265.4487502,11.1144075,513760.8555,1.765978577,839.061911
,125.4,266.021752,11.11437061,511370.7327,1.778630049,841.2653781
,125.6,266.2203085,11.11435827,508410.1844,1.794335373,843.8983491
,125.8,266.3489686,11.11435052,506909.9825,1.803933071,845.8848565
,126,266.5924585,11.11433524,507952.9064,1.806550605,848.6306865
,126.2,267.1088775,11.11430206,510570.5516,1.804369258,851.6975635
,126.4,267.5720419,11.11427237,513978.8793,1.798697841,854.5902222
,126.6,267.8629616,11.11425397,517315.4786,1.7934627,857.5015048
,126.8,267.8751276,11.11425386,521266.1593,1.787355067,861.0482859
,127,268.1776967,11.11423471,521751.4579,1.790408855,863.5464892
,127.2,268.4453175,11.11421784,521059.6942,1.797825241,866.3153296
,127.4,268.5498467,11.11421167,520434.1804,1.804369124,868.4672871
,127.6,268.4946125,11.11421599,519931.6712,1.810476763,870.7364806
,127.8,269.1108835,11.11417625,518534.5729,1.820074411,873.1032084
,128,269.3011189,11.11416446,518995.7555,1.823128209,875.1455969
,128.2,269.5945349,11.11414591,521073.0668,1.822691922,877.935257
,128.4,269.5509502,11.11414945,523437.2618,1.82051063,880.3238825
,128.6,269.8809785,11.1141285,525103.2063,1.821819377,883.2614626
,128.8,269.6376897,11.11414514,525955.5703,1.82356444,885.384924
,129,269.9810316,11.11412331,524762.051,1.831853336,887.602628
,129.2,270.2153684,11.11410863,523679.0712,1.838833464,889.3447981
,129.4,270.2616506,11.11410628,521340.1166,1.849303687,890.9006934
,129.6,270.8304917,11.11406966,518680.1626,1.861518895,892.6373912
,129.8,270.9391814,11.11406322,516957.8299,1.870680332,894.1231628
,130,270.7300087,11.11407763,515559.6091,1.878533024,895.3240463
,130.2,270.9651776,11.11406289,514933.3694,1.884640633,896.8657017
,130.4,271.0830203,11.11405585,516241.4179,1.884204362,898.4336504
,130.6,271.2944743,11.11404267,518533.0103,1.881150526,900.3845507
,130.8,271.5013518,11.11402979,522153.1891,1.873734096,902.5655473
,131,271.6050488,11.11402368,527422.7851,1.861955083,905.3278099
,131.2,271.8227436,11.11401009,530126.0643,1.857156209,907.3932092
,131.4,271.838238,11.11400976,529056.2822,1.86326384,908.9370514
,131.6,272.0051747,11.1139995,528208.7262,1.868935196,910.7351
,131.8,272.4945502,11.11396809,526306.6562,1.877660335,912.2022548
,132,272.1680514,11.1139902,525208.7715,1.88420426,913.7077381
,132.2,272.6395367,11.11395996,524637.4961,1.888566804,914.8713836
,132.4,272.7424017,11.1139539,526166.471,1.887258017,916.5006917
,132.6,272.3447583,11.11398067,526346.1083,1.890748136,918.2242187
,132.8,272.4942208,11.11397156,525782.3544,1.895546975,919.3714214
,133,272.889985,11.11394629,524466.1387,1.902963344,920.5887544
,133.7,272.7190283,11.04394484,1.7977E+308,1.853229799,0
,133.9,272.5054707,10.93282451,1.7977E+308,1.688760038,0
,134.1,272.184156,10.82171125,1.7977E+308,1.452961873,0
,134.3,272.1927692,10.71057635,1.7977E+308,1.141254546,0
,134.5,271.982956,10.59945577,1.7977E+308,0.759091336,0
,134.7,271.8010181,10.48833337,1.7977E+308,0.448038397,0
,134.9,271.4755429,10.37722038,1.7977E+308,0.242560228,0
,135.1,271.5960736,10.26607814,1.7977E+308,0.135240414,0
,135.3,270.8075345,10.15499552,1.7977E+308,0.109501114,0
,135.5,271.0279172,10.04384673,1.7977E+308,0.069365247,0
,135.7,270.9720425,9.932716054,1.7977E+308,0.034900753,0
,135.9,270.4065064,9.821618811,1.7977E+308,0.032719457,0
,136.1,270.1750585,9.710499654,1.7977E+308,0.028793123,0
,136.3,269.9194798,9.59938208,1.7977E+308,0.026611826,0
,136.5,269.672222,9.48826396,1.7977E+308,0.026175567,0
,136.7,269.7802711,9.377122535,1.7977E+308,0.026175567,0
,136.9,269.1918522,9.266026793,1.7977E+308,0.021812973,0
,137.1,269.0494391,9.154901796,1.7977E+308,0.025303049,0
,137.3,269.1092264,9.043763537,1.7977E+308,0.026611827,0
,137.5,268.6023532,8.932662445,1.7977E+308,0.02486679,0
,137.7,268.4557796,8.821537722,1.7977E+308,0.029665645,0
,137.9,268.0354449,8.710430954,1.7977E+308,0.037082057,0
,138.1,268.0794223,8.599293732,1.7977E+308,0.036209538,0
,138.3,267.8463102,8.488174684,1.7977E+308,0.031410684,0
,138.5,267.6156944,8.377055473,1.7977E+308,0.023994273,0
,138.7,267.3309921,8.265939809,1.7977E+308,0.013960304,0
,138.9,266.8149658,8.154839318,1.7977E+308,0.014396564,0
,139.1,266.7382886,8.04371001,1.7977E+308,0.025739312,0
,139.3,266.5509421,7.93258796,1.7977E+308,0.031846946,0
,139.5,266.342793,7.821467275,1.7977E+308,0.036209542,0
,139.7,266.078061,7.710350301,1.7977E+308,0.034464504,0
,139.9,265.8416205,7.599231472,1.7977E+308,0.025303054,0
,140.1,265.3264263,7.488130927,1.7977E+308,0.013524047,0
,140.3,265.233107,7.37700271,1.7977E+308,0.007416413,0
,140.5,265.1339631,7.265874875,1.7977E+308,0.015705345,0
,140.7,264.9499449,7.154752607,1.7977E+308,0.027048094,0
,140.9,264.388153,7.043655118,1.7977E+308,0.033591988,0
,141.1,264.4803923,6.93251473,1.7977E+308,0.038827103,0
,141.3,264.0600574,6.821407963,1.7977E+308,0.039263364,0
,141.5,264.1431436,6.710268175,1.7977E+308,0.03271947,0
,141.7,263.8659301,6.59915202,1.7977E+308,0.023121759,0
,141.9,263.3781951,6.488049674,1.7977E+308,0.018759164,0
,142.1,263.3755749,6.376915508,1.7977E+308,0.019195423,0
,142.3,263.1008577,6.265799189,1.7977E+308,0.020504202,0
,142.5,262.6297647,6.154695751,1.7977E+308,0.018322905,0
,142.7,262.3949883,6.043576812,1.7977E+308,0.017886645,0
,142.9,262.4572719,5.932438389,1.7977E+308,0.018759165,0
,143.1,262.0219592,5.821332604,1.7977E+308,0.017886646,0
,143.3,261.8728892,5.710208044,1.7977E+308,0.013524049,0
,143.5,261.5224508,5.599096692,1.7977E+308,0.011342751,0
,143.7,261.2751929,5.487978572,1.7977E+308,0.017014127,0
,143.9,261.1178019,5.376854558,1.7977E+308,0.023558023,0
,144.1,260.7889981,5.265741787,1.7977E+308,0.02748436,0
,144.3,260.4235819,5.154631417,1.7977E+308,0.027484361,0
,144.5,260.1456245,5.042959636,1.7977E+308,0.026175582,0
,144.7,260.0423201,4.931832074,1.7977E+308,0.023121764,0
,144.9,259.8798481,4.821264068,1.7977E+308,0.016577869,0
,145.1,259.5909851,4.710148677,1.7977E+308,0.01526909,0
,145.3,259.3746033,4.598472857,1.7977E+308,0.016577869,0
,145.5,259.143899,4.487909327,1.7977E+308,0.01614161,0
,145.7,258.4772622,4.376818714,1.7977E+308,0.013087792,0
,145.9,258.4371974,4.265687005,1.7977E+308,0.012215273,0
,146.1,258.1674727,4.154570358,1.7977E+308,0.013524052,0
,146.3,257.8944196,4.043453931,1.7977E+308,0.01875917,0
,146.5,257.6837741,3.932333409,1.7977E+308,0.020940469,0
,146.7,257.3582986,3.82122042,1.7977E+308,0.023121768,0
,146.9,257.081085,3.710104265,1.7977E+308,0.02050421,0
,147.1,257.0094004,3.598974629,1.7977E+308,0.02050421,0
,147.3,257.0017875,3.487840791,1.7977E+308,0.02094047,0
,147.5,256.4840967,3.376740409,1.7977E+308,0.016577872,0
,147.7,256.3525007,3.265614703,1.7977E+308,0.016141613,0
,147.9,256.0511562,3.15450013,1.7977E+308,0.017886652,0
,148.1,255.5288887,3.043400049,1.7977E+308,0.020067952,0
,148.3,255.3814829,2.93227538,1.7977E+308,0.019195432,0
,148.5,255.2390696,2.821150383,1.7977E+308,0.017886653,0
,148.7,254.609045,2.710057369,1.7977E+308,0.018759173,0
,148.9,254.4196181,2.598935456,1.7977E+308,0.020067953,0
,149.1,254.3084086,2.487808413,1.7977E+308,0.018759174,0
,149.3,254.1148211,2.376686773,1.7977E+308,0.021158603,0
,149.5,253.4490161,2.265596106,1.7977E+308,0.026611852,0
,149.7,253.3893969,2.154465679,1.7977E+308,0.031410711,0
,149.9,252.7972329,2.043370182,1.7977E+308,0.035337051,0
,150.1,252.5957404,1.93224906,1.7977E+308,0.028793153,0
,150.3,252.4129702,1.82112671,1.7977E+308,0.020067956,0
,150.5,251.8482655,1.710029412,1.7977E+308,0.011997148,0
,150.7,251.6501014,1.598908072,1.7977E+308,0.009597718,0
,150.9,251.4952066,1.487783894,1.7977E+308,0.004362599,0
,151.1,250.7441112,1.376698822,1.7977E+308,0.007416419,0
,151.3,250.4007454,1.265587006,1.7977E+308,0.015269098,0
,151.5,250.3606805,1.154455296,1.7977E+308,0.017886658,0
,226.7,249.356563,1.050868904,1.7977E+308,0.024430564,0
,226.9,248.8946226,0.939764866,1.7977E+308,0.015705363,0
,227.1,248.3561288,0.828665849,1.7977E+308,0.007852682,0
,227.3,248.2494959,0.717538505,1.7977E+308,0.018322924,0
,227.5,248.143695,0.606411107,1.7977E+308,0.028356907,0
,227.7,247.293163,0.495332556,1.7977E+308,0.026175608,0
,227.9,246.8878055,0.384224806,1.7977E+308,0.017014145,0
,228.1,246.1529357,0.27313867,1.7977E+308,0.005235122,0
,228.3,245.3015715,0.162060174,1.7977E+308,0.009161464,0
,228.5,244.2846191,0.050992539,1.7977E+308,0.020067969,0
,228.592,243.5320424,-7.99E-05,1.7977E+308,0.021376751,0
END,,,,,,