File: GB1_test 11.csv
Segment,Time On Sample,Displacement Into Surface,Load On Sample,Harmonic Contact Stiffness,Harmonic Displacement,Harmonic Load
Surface Marker,0,0,0,283.2535107,0.34110378,2.243070807
,0.3,0.228844911,0.000968705,9886.075611,0.209373161,2.382235444
,0.6,0.146530879,0.001957786,13764.99321,0.190616816,2.489622319
,0.9,0.448589657,0.002921697,15574.88374,0.174913826,2.593721865
,1.2,0.483584276,0.003902677,19182.28097,0.154848898,2.855614361
,1.5,0.398774508,0.004890721,24939.49933,0.130422031,3.197499109
,1.8,0.581860939,0.005861223,29806.45029,0.118644789,3.499935644
,2.1,0.927182638,0.006821101,34842.68917,0.115155234,3.999613407
,2.4,0.744199734,0.007815575,37921.92641,0.119517176,4.657084079
,2.7,0.751739277,0.008797572,37274.30256,0.136964939,5.402217532
,3,0.993064006,0.009764261,35229.77762,0.159647029,5.974217081
,3.3,0.937373392,0.010750399,36122.9085,0.198904495,7.315457288
,3.6,0.933265274,0.011733159,37011.22872,0.22943808,8.439732175
,3.9,0.866758975,0.012720005,39171.41678,0.246885844,9.550857648
,4.2,1.143026684,0.013684405,42809.70146,0.259971662,11.00386796
,4.5,1.100647682,0.014669672,43589.62345,0.288760471,12.4689318
,4.8,0.886881677,0.015666162,41743.37115,0.335869434,13.88468532
,5.1,0.753817317,0.016657367,38282.28269,0.41002243,15.44398657
,5.4,0.959367089,0.017626397,36443.35662,0.474142953,16.92219996
,5.7,0.718145882,0.018624685,34437.75709,0.545678788,18.33685759
,6,0.777267921,0.019603305,32805.11482,0.617650808,19.74932386
,6.3,0.728233113,0.020589007,30723.63269,0.70750679,21.21110033
,6.6,0.551074036,0.021583099,27653.22041,0.82222584,22.2805859
,6.9,1.154308219,0.022526087,22799.65375,1.017640753,23.03777328
,7.2,1.232565699,0.023503454,17574.27679,1.308145994,23.32158158
,7.5,1.413156194,0.024474119,14663.66458,1.540637414,23.27117556
,7.8,1.708559336,0.025437266,13979.29406,1.623078063,23.49033272
,8.1,1.45735443,0.026436208,15175.04928,1.545435545,24.18725144
,8.4,1.726134349,0.027401099,19075.75869,1.315125063,25.49671415
,8.7,1.510704399,0.028397698,24342.46356,1.112294843,27.01218395
,9,1.254507635,0.029396966,26886.19033,1.054717243,28.13097976
,9.3,1.147234526,0.030386483,25494.36814,1.138030317,28.99226625
,9.6,1.836162187,0.03132386,22512.39056,1.287208636,29.3615462
,9.9,1.281286142,0.032342687,19716.51408,1.461686303,29.58618159
,10.2,1.994341094,0.033278485,18540.42397,1.559393709,29.8206801
,10.5,2.200722828,0.034247462,19051.59283,1.550233613,30.35103995
,10.8,2.397952827,0.035217039,20815.03517,1.469101511,31.13343029
,11.1,2.276952126,0.036207455,23514.79054,1.354382487,32.064847
,11.4,1.972500782,0.037209883,26444.61474,1.258856016,33.10474625
,11.7,1.920138074,0.038195804,28223.68066,1.218289971,33.94959606
,12,2.077849231,0.039167968,28572.54717,1.237918695,34.78458401
,12.3,2.453954004,0.040125831,27161.30224,1.322104114,35.38945744
,12.6,2.70110254,0.041092139,26049.68733,1.390150368,35.82667571
,12.9,2.491496432,0.042088357,25732.56483,1.424609707,36.41401601
,13.2,2.656279377,0.043060059,26592.95035,1.402363802,37.09449838
,13.5,2.447505243,0.044056223,29184.17456,1.318178369,38.09166209
,13.8,2.611456213,0.045027979,31193.70163,1.269324627,39.07019788
,14.1,2.599860315,0.046011231,32421.21148,1.251004478,39.9161435
,14.4,2.961821491,0.04697002,32349.33448,1.277612289,40.70291722
,14.7,2.455200069,0.047985688,32097.24681,1.310326879,41.45900785
,15,2.815497297,0.048944587,32137.80569,1.328210807,42.13729907
,15.3,2.935353553,0.04991923,32312.79078,1.346094753,42.96680796
,15.6,2.953708779,0.050900521,32667.77363,1.35569102,43.75248572
,15.9,2.857251364,0.05188933,32847.15145,1.370957819,44.5052894
,16.2,3.071952845,0.052857763,33076.98187,1.382298847,45.22193291
,16.5,2.649360969,0.053867928,32977.23601,1.405853358,45.96816156
,16.8,2.983866948,0.054828516,32693.77235,1.438131689,46.63549478
,17.1,2.941487951,0.055813783,32503.59172,1.465175722,47.23927192
,17.4,3.186140554,0.056780255,32521.46126,1.486113015,47.89126414
,17.7,2.924119984,0.057779906,32814.01295,1.491347366,48.47641268
,18,3.354303157,0.058734228,33277.45419,1.490911135,49.19305645
,18.3,3.202935351,0.059726633,33395.16363,1.504869357,49.89435826
,18.6,3.389349657,0.060696918,33251.70042,1.526679042,50.40718578
,18.9,3.204702825,0.061691502,32852.33938,1.563319355,50.91562945
,19.2,3.180627293,0.062675572,32719.82613,1.590799581,51.46790502
,19.5,3.155719784,0.063659695,32805.58895,1.603885404,51.9314217
,19.8,3.666604588,0.064608733,33048.98365,1.609992073,52.47931483
,20.1,3.277291752,0.06561672,33217.50387,1.61653502,52.98556669
,20.4,3.890509553,0.066559056,33179.94978,1.631365559,53.4863411
,20.7,3.769092874,0.0675495,33427.15168,1.635727511,54.00245553
,21,3.670971493,0.068538537,34006.5741,1.625258864,54.52185718
,21.3,3.785834441,0.069522624,35326.15068,1.58992714,55.23630881
,21.6,3.790874222,0.070528904,37017.2273,1.543254381,56.03513588
,21.9,3.685258832,0.071557616,38967.64232,1.491783498,56.92491268
,22.2,3.843377266,0.072584461,40295.46403,1.466920427,57.85632994
,22.5,3.726109287,0.073644952,40848.33805,1.466484243,58.65844396
,22.8,3.977403977,0.074697225,40389.63161,1.498762578,59.30386163
,23.1,3.496557576,0.075813445,39929.23436,1.533658141,59.95694831
,23.4,4.027390322,0.076883621,39979.91195,1.549361078,60.60346218
,23.7,3.834402812,0.078010412,40194.43065,1.559393558,61.2707945
,24,4.010809213,0.079133541,41125.62176,1.541509588,61.97538442
,24.3,3.946771927,0.08028961,41812.26544,1.535839072,62.78955214
,24.6,4.37858938,0.081430342,42535.43868,1.528859931,63.59166735
,24.9,3.985084235,0.082642714,42896.55245,1.533658099,64.33679996
,25.2,4.515901138,0.083812473,42952.12901,1.547180067,64.99427185
,25.5,4.324560343,0.085047622,43246.18824,1.552414412,65.73283022
,25.8,4.304603568,0.086290124,43896.6299,1.54543531,66.53494448
,26.1,4.724758935,0.087522327,44585.78828,1.538892363,67.39951924
,26.4,4.881175022,0.088790773,45590.35319,1.524497948,68.26847683
,26.7,4.369511657,0.090122221,46185.22969,1.525370382,69.1133257
,27,4.894486771,0.091405272,46393.32394,1.535402797,69.80915
,27.3,4.883666431,0.09274341,46268.91421,1.557648691,70.56524118
,27.6,4.896138218,0.094100081,45865.09348,1.586437493,71.21175441
,27.9,4.831233009,0.09548238,45917.76737,1.599959513,71.90100253
,28.2,5.03921249,0.096867547,46063.49244,1.610864343,72.6450408
,28.5,4.829536883,0.098301153,46313.95941,1.616534885,73.34524674
,28.8,5.494680231,0.099698535,46317.33622,1.628312062,73.90300247
,29.1,5.075339974,0.101188745,46834.29123,1.627439711,74.68100865
,29.4,5.559937646,0.102641832,47827.36394,1.611736686,75.48750716
,29.7,5.19966061,0.104172491,49190.66617,1.58600127,76.384954
,30,5.556542884,0.105678923,50203.63274,1.570734455,77.19364381
,30.3,5.3310386,0.107246606,51489.73576,1.551541939,78.21820193
,30.6,5.779430786,0.10879356,52380.79778,1.54281802,79.14633249
,30.9,5.34758905,0.110422053,53335.91077,1.533221789,80.11062199
,31.2,5.884995008,0.11201105,54087.23943,1.531040774,81.14723557
,31.5,5.83169444,0.11366323,54474.5118,1.537583687,82.07536491
,31.8,6.229320673,0.115310607,54935.05773,1.541509399,83.0078786
,32.1,5.849045777,0.117034205,55283.39513,1.547179955,83.87135596
,32.4,6.055309531,0.118745134,55919.69434,1.546743743,84.84660479
,32.7,5.704977533,0.120518471,56585.11022,1.54630758,85.82952269
,33,6.118394858,0.122268276,57194.41083,1.547616126,86.81682572
,33.3,6.005167434,0.124079253,57811.23753,1.5502333,87.86658697
,33.6,6.61741835,0.125869802,57745.9706,1.568117197,88.73992903
,33.9,6.276220966,0.12775029,57890.22903,1.580330658,89.60998102
,34.2,6.270305242,0.12963692,58520.83684,1.582075435,90.64330609
,34.5,6.338430823,0.131547102,59437.47194,1.573787744,91.55719059
,34.8,6.909897023,0.133452977,60525.40562,1.563319038,92.62339062
,35.1,6.496299575,0.135452705,61203.92369,1.56375527,93.72136552
,35.4,6.989550669,0.137422871,61118.56407,1.580766789,94.66593339
,35.7,6.852159552,0.139464485,60906.85467,1.600395529,95.51845339
,36,7.23724416,0.141502548,60789.22803,1.617407056,96.35453819
,36.3,7.084035694,0.143606957,61487.08357,1.615662295,97.35060588
,36.6,7.352633786,0.14571522,62368.50648,1.609119362,98.37187791
,36.9,7.436528242,0.14786755,63427.32924,1.597778312,99.43040605
,37.2,8.167694455,0.150009779,63985.85317,1.59821444,100.4023693
,37.5,8.036096959,0.152241112,64297.7785,1.60475736,101.3820004
,37.8,8.570074479,0.154462305,64645.17442,1.61130022,102.3079401
,38.1,8.38937974,0.156764138,65870.86223,1.600831583,103.4804289
,38.4,8.787734404,0.159062516,68076.42772,1.569861781,104.7767437
,38.7,8.511351425,0.161440265,70904.44301,1.529295775,106.235232
,39,9.049466701,0.163800261,73084.64044,1.502687902,107.5907196
,39.3,8.68904285,0.166254985,74283.70983,1.498762188,109.0437288
,39.6,9.101518326,0.168695641,74131.34773,1.518827071,110.2808714
,39.9,8.751066451,0.171223509,73396.52627,1.550233061,111.4095283
,40.2,9.328261113,0.173728462,73101.5735,1.57160651,112.4658667
,40.5,9.230717669,0.176315816,73579.22687,1.578585621,113.6964326
,40.8,9.527524391,0.178916076,74246.50615,1.579021788,114.7823563
,41.1,8.933277746,0.181623429,74775.62442,1.584692363,116.086338
,41.4,9.56951913,0.1842725,74920.72264,1.594724764,117.0922706
,41.7,9.435343455,0.187021517,74680.06505,1.614353501,118.1639476
,42,9.733788347,0.189783838,74516.48734,1.63092884,119.083312
,42.3,9.556336678,0.19261921,74633.09393,1.643578479,120.1736172
,42.6,9.836464678,0.195467237,74887.03741,1.65230233,121.2222842
,42.9,9.439357871,0.198402838,75218.66672,1.65928147,122.2775233
,43.2,10.07555746,0.201314702,75463.8676,1.666696705,123.2363372
,43.5,9.913053681,0.204323193,75802.64394,1.673239628,124.2565123
,43.8,10.75640088,0.207311009,76648.17469,1.669313803,125.3325757
,44.1,10.03729115,0.210446925,77595.11819,1.663207158,126.4042506
,44.4,10.56364104,0.21354807,78988.15848,1.649248906,127.6512558
,44.7,10.12655599,0.216759607,79887.31467,1.643578427,128.7218358
,45,10.68284187,0.219953897,80206.66564,1.650121283,129.8789866
,45.3,10.2881722,0.223259285,79984.12751,1.666260493,130.7841036
,45.6,10.95675914,0.226544356,78783.43722,1.702028323,131.5588259
,45.9,10.7941948,0.229933852,78030.35903,1.728636163,132.3039586
,46.2,11.22315679,0.2333356,77506.83931,1.749137231,132.9428028
,46.5,11.24444266,0.236815825,78070.88396,1.748264842,133.8303887
,46.8,11.5036651,0.240333017,79286.15681,1.735615197,134.841799
,47.1,11.09813083,0.243947002,80845.91041,1.716422704,135.8948465
,47.4,11.53080302,0.247560359,82800.40644,1.691995812,137.1626712
,47.7,11.53832717,0.251256164,84051.22427,1.681527158,138.3384483
,48,12.2542694,0.254961207,84593.54387,1.682835674,139.3378068
,48.3,12.20478546,0.258772655,84921.78974,1.69025097,140.4587945
,48.6,12.69940422,0.2626057,85325.79153,1.693304279,141.3606273
,48.9,12.5267696,0.266540611,86563.91789,1.683271839,142.5846183
,49.2,13.00473019,0.270492057,87753.39348,1.673239337,143.7549184
,49.5,12.70145652,0.274554773,89087.85321,1.661898328,145.0665716
,49.8,13.24345995,0.278623105,90241.33161,1.654919176,146.4111019
,50.1,13.15065647,0.282794935,91147.47643,1.652738216,147.6164646
,50.4,13.18180729,0.28702155,91707.03402,1.657536345,148.8820965
,50.7,12.98332281,0.29132705,91878.75576,1.667568821,150.0293824
,51,13.93212182,0.295622064,91791.83435,1.680218349,151.0309338
,51.3,13.90583555,0.300046218,91635.68819,1.694612746,152.1694539
,51.6,14.58338967,0.304490825,91652.36674,1.70508133,153.2400389
,51.9,14.92647909,0.309024531,91473.57162,1.718603302,154.2350127
,52.2,15.3169802,0.313623629,91536.19795,1.727763332,155.1730065
,52.5,15.21327699,0.318324995,92788.54723,1.718603275,156.3619326
,52.8,15.71856829,0.323057248,94502.56201,1.70159167,157.6571525
,53.1,15.30201979,0.327921728,97198.28354,1.670185763,159.1430351
,53.4,15.65087673,0.332809203,99031.87539,1.652737982,160.5248215
,53.7,15.41567541,0.337808866,100309.1247,1.645758905,162.0008426
,54,15.97000646,0.342832182,100892.7914,1.65012079,163.4220782
,54.3,15.91365568,0.347971756,100756.093,1.665823769,164.7677018
,54.6,16.55615166,0.353142815,101045.2311,1.672802806,165.8832139
,54.9,16.13786699,0.358461838,101057.056,1.685888658,167.0995331
,55.2,16.46418726,0.363812128,101179.5959,1.695921082,168.2281933
,55.5,16.33956416,0.369273042,101932.6012,1.697229675,169.5014946
,55.8,16.68832178,0.374785237,103211.3015,1.690250542,170.8920476
,56.1,16.21590677,0.380434668,105069.4288,1.674983809,172.3483432
,56.4,16.93569849,0.386090966,106035.8767,1.673675159,173.8101239
,56.7,16.81268584,0.391888396,105741.37,1.690250531,175.0428814
,57,17.56156915,0.397715776,104519.6516,1.718603047,175.9008849
,57.3,17.43104079,0.403689452,103151.1849,1.750881392,176.7972361
,57.6,17.94278283,0.409710908,103279.7776,1.75916902,177.7922113
,57.9,17.83302507,0.415864314,103709.1468,1.762222387,178.8397815
,58.2,18.21910964,0.422077977,104959.661,1.752189894,179.9761121
,58.5,18.11514601,0.428417756,106176.1123,1.743902225,181.2121575
,58.8,18.90387289,0.434816113,107722.9399,1.731688725,182.5534021
,59.1,18.69921313,0.441333461,108839.2948,1.726018228,183.776297
,59.4,18.92383332,0.447942857,109894.4152,1.722528657,185.1153474
,59.7,18.90799688,0.454667915,110533.9878,1.72383724,186.2319521
,60,19.38217754,0.461462297,111572.3626,1.721220031,187.6016862
,60.3,19.42787476,0.468387677,112619.7238,1.717294284,188.842115
,60.6,19.88122307,0.475390792,113990.7179,1.709878949,190.3038945
,60.9,19.98096523,0.482522901,115426.1986,1.70159126,191.7623853
,61.2,20.53994037,0.489732759,117626.682,1.685452043,193.5704335
,61.5,20.56976215,0.497086406,118790.3247,1.680653911,194.93359
,61.8,20.88160579,0.504532409,120085.6615,1.676291945,196.5706947
,62.1,21.03286037,0.512101595,120067.6714,1.688941545,198.102603
,62.4,21.49442341,0.519764574,120089.7302,1.698973952,199.2959156
,62.7,20.84694557,0.527616317,119682.38,1.715985565,200.546203
,63,21.77437733,0.535482641,119750.2358,1.727326507,201.855671
,63.3,21.19757965,0.543566982,120295.9778,1.730816113,203.0982882
,63.6,22.02139218,0.551681375,121543.0622,1.725581709,204.5644531
,63.9,21.75654612,0.559990269,123385.728,1.713368315,206.1730646
,64.2,22.76168965,0.568341041,123972.3289,1.716421575,207.571292
,64.5,22.75721167,0.57688466,123539.7445,1.73212454,208.825966
,64.8,23.38626198,0.585515467,122710.6008,1.750880798,209.7771111
,65.1,23.46202839,0.594312843,121725.7249,1.771818078,210.8455021
,65.4,24.054014,0.603209095,122482.3875,1.769637049,212.088126
,65.7,23.66757596,0.61230416,123108.9912,1.768764708,213.1587058
,66,24.29778922,0.621469519,124907.0564,1.755678833,214.6511689
,66.3,24.47538617,0.630803418,125421.3407,1.758732172,215.8170854
,66.6,25.04482082,0.640252312,126143.5374,1.760476888,217.1320311
,66.9,25.21904479,0.649870042,127236.2638,1.757423518,218.5149131
,67.2,25.64034213,0.659616742,129345.2251,1.741720509,220.0205245
,67.5,25.62898926,0.66953917,132586.9536,1.714240323,221.9052754
,67.8,26.64094135,0.679544055,134744.1269,1.700718227,223.7319551
,68.1,26.55299892,0.689772832,135496.4796,1.703335397,225.2956404
,68.4,26.89183492,0.700127853,135197.8895,1.71685736,226.5273047
,68.7,27.17074388,0.710643244,134837.9877,1.732560296,227.8652608
,69,27.65429331,0.721304052,136144.9805,1.727762121,229.3160833
,69.3,27.59703365,0.732161732,137952.5921,1.719474452,231.1405656
,69.6,27.87004182,0.743161696,140146.3933,1.706824816,232.9968276
,69.9,27.85848828,0.754346485,140860.2368,1.710314364,234.6218771
,70.2,28.77289554,0.765639205,141308.9411,1.715984789,236.1351623
,70.5,28.72218523,0.777166145,141809.8599,1.720346728,237.699944
,70.8,29.54086057,0.788809933,142989.648,1.717729487,239.4071824
,71.1,29.47761497,0.800687938,144756.9451,1.708133239,241.1111285
,71.4,30.0349938,0.812704498,146713.7578,1.699845511,243.0846416
,71.7,30.17552456,0.824930002,148649.4878,1.691994017,245.064727
,72,30.71038185,0.837314207,149366.5968,1.695483512,246.7171743
,72.3,31.07631859,0.849896547,149447.1261,1.707260696,248.506595
,72.6,31.478,0.862666677,149128.1868,1.721655036,250.028643
,72.9,31.41956889,0.87566016,149174.681,1.730378909,251.3600226
,73.2,31.94348866,0.888811434,151409.4145,1.718601638,253.4365392
,73.5,31.71943188,0.902210718,153601.8176,1.70551586,255.2215725
,73.8,32.93715444,0.91571749,155949.1254,1.693738522,257.3802778
,74.1,32.77293519,0.92951952,155675.9517,1.707696724,258.9877947
,74.4,33.32667665,0.943482497,153790.5895,1.738230199,260.3235603
,74.7,33.27803516,0.957696238,151042.9777,1.777051405,261.2988094
,75,33.829213,0.97208517,149749.316,1.798861012,262.2028363
,75.3,34.41197131,0.986689266,150296.7934,1.802350498,263.5594233
,75.6,34.67188851,1.001535452,151852.0304,1.793190413,264.8787507
,75.9,34.95173743,1.016604639,155331.186,1.766146404,266.8215811
,76.2,35.74071835,1.031867962,158438.0481,1.74390047,268.7655097
,76.5,36.22100015,1.047382331,160561.3231,1.732995592,270.7280657
,76.8,36.86513508,1.06317385,160888.4752,1.740847005,272.3969512
,77.1,36.87611674,1.079138893,160332.9933,1.756549959,273.7469596
,77.4,37.72401744,1.095343818,159838.6895,1.771816634,275.1177931
,77.7,38.193331,1.111818479,161048.2736,1.769635621,276.7307941
,78,38.88973387,1.12852722,162886.5021,1.760475494,278.3317416
,78.3,38.86893496,1.145535833,165512.1664,1.746081123,280.3720949
,78.6,39.45876417,1.162760942,168018.6283,1.73299527,282.4080689
,78.9,39.41708374,1.180287871,170292.8228,1.72121806,284.2478935
,79.2,40.57090783,1.198000742,173442.1247,1.704642608,286.7638253
,79.5,40.56658156,1.21605786,175875.6452,1.694173975,289.049635
,79.8,41.03394116,1.234356637,176782.0369,1.695918702,290.9442513
,80.1,41.37479675,1.252940308,175853.67,1.71598355,292.8717421
,80.4,42.23392745,1.271770484,173938.1089,1.743463627,294.3532509
,80.7,42.2552153,1.290939894,173040.145,1.760038961,295.6199797
,81,43.08097582,1.310345892,173250.7735,1.767454159,297.2647603
,81.3,43.17372068,1.330094019,174613.0884,1.764400799,299.1297897
,81.6,44.08300039,1.350086679,176324.1848,1.756985425,300.8173061
,81.9,44.41858614,1.370419271,177635.454,1.755676814,302.6856243
,82.2,45.15929423,1.39103249,179541.8038,1.748697648,304.5966806
,82.5,45.15076056,1.412005913,180393.7997,1.752187198,306.483624
,82.8,46.21334276,1.433224979,181341.649,1.753931859,308.3114032
,83.1,46.453052,1.454818872,182252.4052,1.755676606,310.0624717
,83.4,47.13115948,1.476710179,183295.1171,1.756985115,311.9494209
,83.7,47.18024232,1.498973611,185322.8846,1.749569836,314.0292229
,84,48.07372491,1.521517717,186262.2682,1.750005933,315.7594767
,84.3,48.53452703,1.544431158,188076.8645,1.74433538,317.9236579
,84.6,49.42540443,1.567662375,189580.1673,1.742590517,320.0494906
,84.9,49.65563907,1.591287957,190914.7091,1.741281919,321.8684983
,85.2,50.93410355,1.615201336,192112.6636,1.743898946,324.0809007
,85.5,50.95789456,1.639558929,193118.5547,1.744771331,325.8418297
,85.8,51.44254036,1.664254091,195907.3072,1.732557884,328.1769532
,86.1,51.55939461,1.689346513,199280.146,1.717727316,330.9208033
,86.4,52.65375734,1.714753567,202815.088,1.702024268,333.6295955
,86.7,52.86783118,1.74060259,204053.1163,1.703769018,336.0052621
,87,53.69833516,1.766801641,204739.4418,1.708130864,338.0478143
,87.3,53.82908666,1.793442463,204977.1962,1.717727092,340.4760788
,87.6,55.19359055,1.820404486,205083.802,1.725578426,342.3082452
,87.9,55.77264686,1.847825767,205635.9378,1.731248874,344.4855787
,88.2,56.63866807,1.875642216,206041.9362,1.738664063,346.7429057
,88.5,57.1493699,1.903902418,208363.4569,1.731684929,349.1382999
,88.8,57.8372141,1.932578035,211357.8672,1.721652429,351.7134033
,89.1,58.10567497,1.961714459,213786.1105,1.715545706,354.1822132
,89.4,59.38907302,1.99122411,214278.6439,1.723833239,356.448311
,89.7,59.41944874,2.021262285,213028.7321,1.743025711,358.3527894
,90,60.84996289,2.051661976,210936.7589,1.766579967,359.7532169
,90.3,60.90182477,2.082611821,210529.2696,1.777920969,361.6500248
,90.6,61.96778731,2.113962549,211537.6951,1.778357052,363.637791
,90.9,62.45794927,2.145824788,215257.8247,1.759600722,366.1854998
,91.2,63.62609257,2.178123801,219543.4753,1.738227171,368.8099194
,91.5,63.79495888,2.210976652,223256.9926,1.722960416,371.6304762
,91.8,64.69421842,2.244277651,226364.3992,1.711619322,374.4455599
,92.1,65.072583,2.278116071,228093.0581,1.710310707,376.9866932
,92.4,66.14805946,2.312419821,228335.1714,1.720343027,379.4686602
,92.7,66.89316031,2.347263624,228574.8653,1.730811572,381.7643419
,93,68.30042769,2.382590064,226314.8209,1.756546783,383.3806412
,93.3,68.46464305,2.418532319,226356.403,1.767451576,385.540439
,93.6,69.60134803,2.454953589,227752.7996,1.76745146,387.7670885
,93.9,69.85690657,2.491983162,231569.0095,1.751748509,390.5065587
,94.2,70.56413724,2.529542486,235809.7951,1.733428359,393.3358862
,94.5,71.27874481,2.567798585,239077.9393,1.723395864,396.2824655
,94.8,72.54406723,2.606338325,240685.5566,1.722087162,398.6712933
,95.1,72.83337274,2.64565471,240626.0178,1.733428132,401.3559748
,95.4,73.95954802,2.685509939,240667.921,1.743024249,403.733844
,95.7,74.38427485,2.726013576,241112.5629,1.748694706,405.7599597
,96,75.69911475,2.767070394,241709.1959,1.755673648,408.1411176
,96.3,76.5687508,2.808777003,241638.6539,1.766578365,410.4302275
,96.6,77.57306611,2.85110499,241994.6282,1.772248761,412.3248526
,96.9,78.20954805,2.894096643,243492.5644,1.771376311,414.7027192
,97.2,79.19951486,2.93771449,247134.7669,1.757854254,417.6635454
,97.5,79.83079692,2.982014875,250575.4589,1.744768427,420.2956343
,97.8,81.5244008,3.026914694,252618.8532,1.742587296,423.0153955
,98.1,81.48489915,3.072606973,254365.1353,1.743895876,425.8874549
,98.4,82.77103515,3.118901703,254695.6134,1.751747203,428.0067201
,98.7,83.42351297,3.165939662,255683.7286,1.756109057,430.4843042
,99,84.99021498,3.213627203,256866.5592,1.75872605,433.0802402
,99.3,85.89621677,3.262078655,257562.4812,1.762651687,435.335383
,99.6,86.89653095,3.311255888,260585.4771,1.753491552,438.1855366
,99.9,87.63673585,3.361193065,265230.5494,1.736043803,441.3852444
,100.2,88.81610218,3.411853425,271430.8875,1.711180741,444.9410881
,100.5,89.52278691,3.463310292,276346.986,1.695477773,448.6492407
,100.8,90.81505601,3.515505959,279315.4714,1.690679529,452.2456306
,101.1,91.61550451,3.56852269,279808.9285,1.699403291,455.6261443
,101.4,93.12050544,3.622294094,280514.5747,1.705509828,458.3919306
,101.7,94.01304619,3.676918147,279975.9288,1.719904072,461.2957785
,102,95.12260023,3.732353211,280145.1212,1.729063977,463.8588394
,102.3,95.7186948,3.788659533,278980.2339,1.746947783,466.6355724
,102.6,97.02515755,3.845769839,280228.5317,1.750437186,469.4462841
,102.9,97.50783158,3.903797221,279618.8386,1.763959077,471.9249625
,103.2,99.29822491,3.962615048,279835.5538,1.771374152,474.2217558
,103.5,100.0410252,4.022390559,278218.2178,1.789257931,476.3958093
,103.8,101.4184759,4.083027336,278264.5876,1.796673045,478.6334239
,104.1,102.2957662,4.144613319,280147.3241,1.794055804,480.9795178
,104.4,103.6304926,4.207099693,283390.7349,1.784895644,483.7683134
,104.7,104.6855266,4.270548402,289640.894,1.761341195,487.1915701
,105,106.2404226,4.334922823,294205.749,1.746510528,490.3529382
,105.3,107.3251005,4.400300824,299402.6037,1.730807527,494.1619117
,105.6,109.094333,4.4666216,303527.4998,1.720774949,497.8766561
,105.9,110.0397553,4.533998791,306147.6538,1.716849132,501.0292521
,106.2,111.6464323,4.602350053,309922.8045,1.709869912,505.0519103
,106.5,112.9110051,4.671756569,310931.8007,1.715540273,508.4740751
,106.8,114.405035,4.742196521,310825.6686,1.725136332,511.215756
,107.1,115.2782457,4.813741761,310079.5057,1.739966746,514.4494406
,107.4,117.0805954,4.886306605,311809.5082,1.740838947,517.3072792
,107.7,118.4776011,4.959994601,315000.5441,1.736476894,520.842315
,108,119.8170238,5.034799731,319327.5459,1.725571982,524.2907776
,108.3,120.6046705,5.110771405,323646.4713,1.716848082,528.3945174
,108.6,122.2365844,5.187835175,328120.0118,1.707687908,532.4588181
,108.9,123.482279,5.266088811,330302.4044,1.709868739,536.339024
,109.2,124.8758761,5.345514992,330680.516,1.719028612,539.5398416
,109.5,126.0454826,5.426155756,328928.1529,1.737784705,542.6891559
,109.8,127.4370313,5.5080003,329212.9798,1.746072192,545.8527162
,110.1,128.5205545,5.591101615,332740.4879,1.738220646,549.363641
,110.4,130.4641346,5.675401794,339542.7436,1.717719482,553.7851755
,110.7,131.6970101,5.761022372,347031.121,1.69634601,558.5496853
,111,133.8772931,5.847874062,350267.2316,1.693292461,562.4397668
,111.3,135.1363772,5.936098785,349885.5821,1.70768663,566.4459912
,111.6,136.7621478,6.02563224,345238.9795,1.739092198,569.3279385
,111.9,138.0906901,6.116538388,341921.5604,1.76439112,571.9742919
,112.2,139.6485877,6.209115781,341061.1488,1.777476679,574.6228364
,112.5,141.1714193,6.302470346,342872.8302,1.778785093,577.7820211
,112.8,143.2397482,6.397514555,348799.8714,1.76133726,581.6414217
,113.1,144.5224699,6.494046623,351741.5915,1.757411414,585.0405806
,113.4,146.6186252,6.591983453,355918.6026,1.749995964,588.9580583
,113.7,148.075593,6.691442156,357987.529,1.751740577,592.5577525
,114,150.2669502,6.792355158,359357.1859,1.754793687,595.6139422
,114.3,151.9896665,6.894823824,364181.4114,1.745197325,599.8919337
,114.6,154.0915141,6.9988157,365008.8667,1.751303776,603.4795809
,114.9,155.5092336,7.104423719,367529.4138,1.750431251,607.2885699
,115.2,157.2686384,7.211605069,366908.5299,1.761335826,610.3874896
,115.5,158.5543957,7.320436806,371508.6367,1.751303321,614.4419346
,115.8,160.9929996,7.430835816,377203.1005,1.737781182,618.8393761
,116.1,162.1006046,7.54299361,383506.5984,1.722950609,623.3211768
,116.4,164.1784308,7.656782243,386164.1403,1.724258968,627.6495787
,116.7,165.6723581,7.772327386,386582.529,1.732110242,631.0005327
,117,167.7966395,7.889576471,387412.0579,1.739089064,635.0374565
,117.3,169.3640527,8.008633625,391417.8836,1.732982248,639.3384606
,117.6,171.6129781,8.129439454,395781.0256,1.726002983,643.7293296
,117.9,173.2642605,8.252108969,399659.2798,1.722513301,648.3798926
,118.2,175.5175926,8.376592041,400732.7606,1.728619727,652.4365461
,118.5,177.1682811,8.502995724,399890.8358,1.741705257,656.1885609
,118.8,179.4792479,8.631265654,401134.9564,1.746503101,660.2068651
,119.1,181.2799104,8.761507008,403394.9413,1.747375307,664.0750372
,119.4,183.4962436,8.893688686,410148.9877,1.733417011,668.9469611
,119.7,185.4601729,9.027884218,414460.4216,1.7299273,673.6424586
,120,187.8605624,9.164078412,416293.8461,1.733852758,677.4777697
,120.3,189.7414772,9.30236429,417293.0806,1.741703984,681.6593411
,120.6,192.3749896,9.442689856,418463.7981,1.747810364,685.7127199
,120.9,194.224452,9.585187306,423768.8823,1.739522581,690.4575297
,121.2,196.7907271,9.729790332,424671.2686,1.746065159,694.4035174
,121.5,198.6652906,9.876623678,425001.1122,1.754352561,698.3725105
,121.8,201.1376849,10.02563603,423507.556,1.768310358,701.8484036
,122.1,203.4000656,10.17691342,422747.2487,1.778342471,705.1270567
,122.4,206.0755697,10.33044936,425705.1834,1.776597439,709.238514
,122.7,207.9644969,10.48635669,429985.3822,1.769618222,713.0146502
,123,210.9454206,10.64454755,437326.3559,1.753915119,718.0213752
,123.3,212.9617156,10.80519203,444523.7318,1.74082925,723.4532535
,123.6,215.8994425,10.96820293,450746.5664,1.729488048,728.1378163
,123.9,218.3492456,11.13370879,458742.591,1.715529766,733.8261231
,124.2,221.0723675,11.3016971,462977.7299,1.714220928,739.4190935
,124.5,223.5296886,11.47224082,466993.5522,1.711603552,744.2121386
,124.8,226.4042463,11.64533373,467369.7426,1.720763222,749.0018996
,125.1,228.5396029,11.82109065,469345.7817,1.724252514,753.6952228
,125.4,231.693694,11.99943571,470972.1773,1.729486457,758.5934746
,125.7,234.0611497,12.18052718,470878.4528,1.739954735,763.1673633
,126,236.8092099,12.36432954,474039.7604,1.73908208,767.608661
,126.3,239.4711359,12.55091443,479496.4102,1.732975177,773.207123
,126.6,242.535284,12.74029189,487910.2559,1.718144477,779.1518564
,126.9,245.3660268,12.93254599,494575.9898,1.710292811,785.0341341
,127.2,248.5465643,13.12768166,495112.6531,1.719888626,789.8567807
,127.5,250.9079802,13.32581955,494772.9996,1.732101647,794.6662692
,127.8,253.8542959,13.43998983,492260.1664,1.749548858,798.9815595
,128.1,255.1789898,13.43990332,493776.7915,1.753474414,803.370241
,128.4,256.5502736,13.43981375,497145.6698,1.7526019,808.3561238
,128.7,256.9456642,13.43978809,502703.6966,1.746059046,813.6159397
,129,257.6114429,13.43974472,507287.0737,1.743878041,819.1201159
,129.3,258.1906974,13.43970702,508453.5932,1.74998461,823.4835788
,129.6,258.881435,13.43966202,509592.0861,1.756527354,828.195496
,129.9,259.1462072,13.43964492,511354.4106,1.760889203,833.0695918
,130.2,259.3252873,13.43963342,515649.57,1.756963497,838.0258619
,130.5,259.6474651,13.43961255,519707.5794,1.754782527,843.2297897
,130.8,260.0137369,13.4395888,518777.0903,1.766995741,847.6809034
,131.1,260.2710215,13.43957218,516459.5095,1.782262279,851.3288066
,131.4,260.2495984,13.43957382,512577.0639,1.802326909,854.8550621
,131.7,260.4403259,13.43956156,511214.2048,1.814103953,858.3320196
,132,261.0445392,13.43952222,510950.4758,1.821955265,861.5405095
,132.3,260.572192,13.43955339,511787.1412,1.825444815,864.8125403
,132.6,261.1863889,13.4395134,514270.2509,1.824136188,868.6565894
,132.9,261.1117201,13.43951852,516943.2424,1.821955259,872.5663793
,133.2,261.5245818,13.43949172,522116.3261,1.814540028,877.1588518
,133.5,261.3176309,13.4395055,527049.7204,1.808869613,881.4839438
,133.8,261.83532,13.43947183,527106.7725,1.818029494,885.0726728
,134.1,261.6275371,13.43948567,523315.2981,1.836785581,887.5864191
,134.4,262.1635294,13.4394508,515597.4653,1.866446274,889.2936718
,134.7,262.0110721,13.43946102,509182.7039,1.890872797,890.5100035
,135,262.3236822,13.43944078,505409.435,1.906139312,891.7361974
,135.3,262.1782966,13.43945053,503709.0944,1.914426903,893.3250952
,135.6,262.5404086,13.43942705,506518.3567,1.908756422,895.5594216
,135.9,262.5164896,13.43942884,513547.7339,1.890436558,898.4676576
,136.2,262.7463194,13.43941403,524784.9775,1.862956708,902.9286345
,136.5,262.7431995,13.43941446,533183.5567,1.845073028,907.2668803
,136.8,262.8939927,13.43940482,534707.3344,1.845945384,910.2156581
,137.1,263.0522737,13.43939469,531239.4714,1.861648127,912.824744
,137.4,263.1997391,13.43938526,527764.1304,1.876478478,914.8684007
Unloading Marker,137.672,263.1139248,13.43939109,523518.4158,1.893053612,916.1581469
,138.6,262.6672256,13.17808463,1.7977E+308,1.92882104,0
,138.9,262.2959684,12.97656437,1.7977E+308,1.745622339,0
,139.2,262.1202225,12.77503131,1.7977E+308,1.405396113,0
,139.5,261.6066995,12.57352037,1.7977E+308,0.820032519,0
,139.8,261.2670568,12.37199804,1.7977E+308,0.38166408,0
,140.1,260.7452142,12.17048764,1.7977E+308,0.095961257,0
,140.4,260.5902673,11.96895322,1.7977E+308,0.013958001,0
,140.7,260.1998749,11.76743422,1.7977E+308,0.012649439,0
,141,259.569045,11.56593096,1.7977E+308,0.019192253,0
,141.3,259.2759922,11.36440558,1.7977E+308,0.021373191,0
,141.6,258.675113,11.16290035,1.7977E+308,0.026607443,0
,141.9,258.4694164,10.96136925,1.7977E+308,0.027916006,0
,142.2,258.0232823,10.7598539,1.7977E+308,0.01831988,0
,142.5,257.560509,10.55833963,1.7977E+308,0.004798064,0
,142.8,257.2350096,10.35681638,1.7977E+308,0.02399032,0
,143.1,256.6665768,10.15530903,1.7977E+308,0.031841698,0
,143.4,256.2969834,9.953788665,1.7977E+308,0.032714074,0
,143.7,256.0871269,9.752257837,1.7977E+308,0.029224573,0
,144,255.3947315,9.550758609,1.7977E+308,0.020500821,0
,144.3,254.9028394,9.34924625,1.7977E+308,0.021373197,0
,144.6,255.0266003,9.147693576,1.7977E+308,0.044054957,0
,144.9,254.2501766,8.94619985,1.7977E+308,0.058012966,0
,145.2,253.8331611,8.744682588,1.7977E+308,0.047108274,0
,145.5,253.3753794,8.543167995,1.7977E+308,0.023990325,0
,145.8,253.0124416,8.341647192,1.7977E+308,0.015266571,0
,146.1,252.5173283,8.139463229,1.7977E+308,0.016575135,0
,146.4,252.1418041,7.938615066,1.7977E+308,0.013958009,0
,146.7,251.7189649,7.737098185,1.7977E+308,0.006979004,0
,147,251.2836461,7.535582122,1.7977E+308,0.006979005,0
,147.3,250.5447674,7.333414121,1.7977E+308,0.016138949,0
,147.6,250.1502148,7.131895388,1.7977E+308,0.020500828,0
,147.9,249.6249372,6.931057032,1.7977E+308,0.023117955,0
,148.2,249.2495198,6.729537046,1.7977E+308,0.019192265,0
,148.5,248.8325042,6.528019784,1.7977E+308,0.006542818,0
,148.8,248.6293033,6.326488521,1.7977E+308,0.011777072,0
,149.1,248.0775095,6.124980085,1.7977E+308,0.025735085,0
,149.4,247.5956007,5.923467073,1.7977E+308,0.022245583,0
,149.7,247.1311631,5.721952916,1.7977E+308,0.01657514,0
,150,246.6442624,5.520440231,1.7977E+308,0.012213262,0
,150.3,246.1490421,5.31892809,1.7977E+308,0.011340886,0
,150.6,245.4583103,5.117428752,1.7977E+308,0.025735089,0
,150.9,245.1215791,4.915906233,1.7977E+308,0.037948352,0
,151.2,244.6825163,4.714390415,1.7977E+308,0.039693105,0
,151.5,244.4955387,4.512858089,1.7977E+308,0.039693106,0
,151.8,243.8189501,4.311357825,1.7977E+308,0.03489504,0
,152.1,243.1419456,4.109857589,1.7977E+308,0.035331229,0
,152.4,242.4137752,3.908360703,1.7977E+308,0.030096974,0
,152.7,241.9659767,3.706845457,1.7977E+308,0.023554154,0
,153,241.3467936,3.505341434,1.7977E+308,0.026171284,0
,153.3,240.9289458,3.303824226,1.7977E+308,0.034895046,0
,153.6,240.4370531,3.102311868,1.7977E+308,0.034458859,0
,153.9,239.9376728,2.9008,1.7977E+308,0.011340891,0
,154.2,238.8975156,2.699323544,1.7977E+308,0.011777079,0
,154.5,238.4413974,2.497808843,1.7977E+308,0.026171288,0
,154.8,237.6416778,2.296316642,1.7977E+308,0.01657515,0
,155.1,237.5216732,2.094779931,1.7977E+308,0.022245596,0
,155.4,236.7876788,1.893283426,1.7977E+308,0.026171291,0
,155.7,236.0079263,1.691789918,1.7977E+308,0.020500846,0
,156,235.0767562,1.490306325,1.7977E+308,0.008287576,0
,156.216,234.6090136,1.345224865,1.7977E+308,0.0074152,0
,231.6,233.8876432,1.094071099,1.7977E+308,0.02791605,0
,231.9,232.8383339,0.892595243,1.7977E+308,0.012649461,0
,232.2,232.3389533,0.691083374,1.7977E+308,0.009596143,0
,232.5,231.5708481,0.489589104,1.7977E+308,0.016575157,0
,232.8,230.4083914,0.288120657,1.7977E+308,0.020937042,0
,233.1,229.1369473,0.086659347,1.7977E+308,0.013958029,0
,233.226,228.5570329,0.002048603,1.7977E+308,0.012649464,0
END,,,,,,