File: GB1_test58.csv
Segment,Time On Sample,Displacement Into Surface,Load On Sample,Harmonic Contact Stiffness,Harmonic Displacement,Harmonic Load
Surface Marker,0,0,0,-66.78703375,0.239082499,2.280090067
,0.2,-0.154273495,0.000667347,5639.662345,0.182802131,2.335969245
,0.4,0.128328262,0.001306018,11814.03897,0.157934058,2.403900826
,0.6,0.321890679,0.001950534,15258.10481,0.140046498,2.461971369
,0.8,0.0411314,0.002626183,18638.68076,0.13088458,2.648235316
,1,0.595844067,0.003246685,21348.36699,0.124776629,2.822446949
,1.2,0.520624286,0.003908254,24472.99475,0.121286374,3.005423898
,1.4,0.325575866,0.004577688,26076.30494,0.123467785,3.181826817
,1.6,0.529540166,0.005220932,26489.43674,0.129139449,3.337412028
,1.8,0.68440801,0.005867399,28494.12667,0.136992522,3.784445571
,2,0.495600666,0.006536423,28388.67469,0.152698673,4.190939266
,2.2,0.403321946,0.007199112,28742.13299,0.165350849,4.595241631
,2.4,0.473311173,0.00785115,29760.94178,0.173640205,5.001735356
,2.6,0.890720229,0.008480383,31223.93543,0.179311866,5.425759856
,2.8,0.911612999,0.009135644,34060.46483,0.184983531,6.114936551
,3,1.115577294,0.009778887,37691.54819,0.184547247,6.776721516
,3.2,0.935507459,0.010447339,39581.66183,0.191527759,7.428645366
,3.4,0.869441255,0.011108307,40192.91874,0.203743654,8.068516876
,3.6,0.869946515,0.011764905,40501.66824,0.215523265,8.630595801
,3.8,0.97030897,0.012414949,42589.14247,0.229484285,9.619986192
,4,0.924214205,0.013074606,44000.90841,0.245190435,10.54911469
,4.2,0.962998057,0.013728692,44851.64989,0.262205429,11.46619084
,4.4,0.670588874,0.014404517,44860.59072,0.282710683,12.36573615
,4.6,0.986476445,0.015040414,43381.09442,0.309323875,13.0888787
,4.8,0.836779839,0.015706872,41532.75157,0.352079505,14.24371526
,5,0.865994043,0.016361586,39295.30601,0.399197952,15.26159309
,5.2,0.396338332,0.017049045,37269.08709,0.448061537,16.24112222
,5.4,0.748007548,0.017685875,35203.6587,0.502596769,17.22174739
,5.6,0.731870463,0.018340285,33848.74424,0.546224961,18.01391708
,5.8,0.737784655,0.018996528,32771.11223,0.598578791,19.12273551
,6,0.610971988,0.019661483,31844.15659,0.648314934,20.13403922
,6.2,0.52160577,0.020323981,30399.87086,0.709394407,21.03906296
,6.4,-0.272585855,0.021032742,28607.47644,0.782689803,21.87615464
,6.6,-0.383587805,0.02169666,26667.07187,0.859911712,22.4721992
,6.8,-0.043568059,0.022330974,24314.34485,0.960692824,23.02332161
,7,0.887273434,0.022926507,21213.50176,1.10946491,23.44515532
,7.2,-0.114121868,0.023648868,18813.94439,1.246893779,23.63032298
,7.4,0.891612526,0.024239486,15940.91668,1.451946213,23.67524611
,7.6,1.200010805,0.024875875,14732.81716,1.560580385,23.69935107
,7.8,1.45015905,0.025516087,14083.64245,1.630821751,23.79138756
,8,0.975510492,0.026203873,14111.1109,1.642165122,24.00833002
,8.2,1.38792668,0.026833435,15056.3201,1.580649338,24.51562566
,8.4,1.050581765,0.027512209,16674.41535,1.478123117,25.14563593
,8.6,1.43720151,0.028143464,18682.9972,1.372979148,25.87754402
,8.8,0.974202958,0.028830485,21253.6245,1.263908704,26.74531467
,9,1.050433258,0.029482113,23194.32577,1.201520386,27.51118834
,9.2,1.108356405,0.030134943,24119.20246,1.18276026,28.0732673
,9.4,1.272793892,0.030780781,24180.64708,1.203701782,28.65725977
,9.6,1.210056262,0.031441531,23741.05442,1.242094594,29.08676249
,9.8,1.623304589,0.032071038,22981.24323,1.29575724,29.45271673
,10,1.358356143,0.03274506,22274.51537,1.34636596,29.75402588
,10.2,1.493668614,0.03339281,21681.62692,1.394793242,30.11778857
,10.4,1.326913075,0.034060387,21465.24921,1.419661325,30.43224582
,10.6,1.640304207,0.034696448,21417.84998,1.440166552,30.86503592
,10.8,1.622502315,0.035354248,21593.48591,1.442347962,31.20578943
,11,1.455746776,0.036021825,21994.85542,1.436240028,31.6703535
,11.2,1.914762978,0.036648327,22308.11469,1.432749739,32.02206412
,11.4,1.930246816,0.037303942,22605.16183,1.435367428,32.45704529
,11.6,1.58541262,0.037983208,23065.26158,1.425332973,32.85696467
,11.8,2.00115737,0.03861255,23715.12603,1.4070091,33.28865921
,12,2.031619787,0.039267182,24578.71767,1.383449879,33.8310161
,12.2,2.007992892,0.039925364,25354.6012,1.362508352,34.28571936
,12.4,1.956073127,0.040585403,26575.94732,1.328042082,34.88505098
,12.6,2.154628481,0.041229002,27475.0119,1.307973103,35.39782494
,12.8,2.10354086,0.041888986,28131.4635,1.298811185,35.89854631
,13,2.218881888,0.042538047,28857.35999,1.289649257,36.48253874
,13.2,1.988883467,0.043209775,29681.47524,1.276560818,37.08734857
,13.4,2.263996,0.043848348,30182.205,1.271325419,37.54753045
,13.6,2.411790614,0.044495278,30886.08588,1.263908614,38.16768015
,13.8,2.454735179,0.045149091,31522.18697,1.255619255,38.67935821
,14,2.446919007,0.045806235,32075.35336,1.254310411,39.30279476
,14.2,2.203606296,0.046478837,32219.82148,1.266090038,39.85610802
,14.4,2.388015214,0.047123363,32316.81991,1.276124509,40.29547215
,14.6,2.16467394,0.047794654,32280.30136,1.291394391,40.75236649
,14.8,2.532154371,0.048427165,32094.57558,1.316262433,41.31882845
,15,2.351252404,0.04909567,31982.70314,1.333713721,41.73847004
,15.2,2.435804132,0.049746751,31998.02198,1.349419863,42.25781795
,15.4,2.393037943,0.050406189,31939.81732,1.367307424,42.75525223
,15.6,2.688954052,0.051043397,31954.00866,1.379959577,43.16832038
,15.8,2.156887638,0.051734952,32182.47963,1.387376408,43.73697266
,16,2.758200317,0.052352114,32407.46925,1.394356875,44.24974726
,16.2,2.742894855,0.05300975,32644.94195,1.398719695,44.67815434
,16.4,2.363110657,0.053691309,33003.84588,1.401337414,45.20955401
,16.6,2.432683806,0.054343374,33226.47867,1.405700228,45.64563089
,16.8,2.949950012,0.054966052,33421.40116,1.415298391,46.20332789
,17,2.715790883,0.055638053,33584.3666,1.420533792,46.61639525
,17.2,2.732106864,0.056293613,33650.84392,1.431004556,47.09410763
,17.4,2.613615642,0.056958022,33674.21538,1.443220458,47.57948945
,17.6,3.018542509,0.057588074,33761.16125,1.451509783,47.99694044
,17.8,2.838472691,0.058256524,33896.9752,1.458490307,48.43959111
,18,3.087788773,0.058896791,33941.06088,1.471142462,48.91511242
,18.2,3.094119036,0.059553006,34024.90571,1.482049508,49.39830306
,18.4,3.2718708,0.06019797,34143.10936,1.488593723,49.76973562
,18.6,3.22827247,0.060857462,34257.87643,1.495137954,50.1597942
,18.8,2.992449058,0.061529572,34393.17456,1.503427329,50.66489801
,19,3.049956128,0.062182428,34539.57244,1.509535271,51.1250796
,19.2,3.090404263,0.062836404,34587.90765,1.517606483,51.52554726
,19.4,3.209906002,0.063485191,34477.9643,1.531785634,51.91834525
,19.6,3.360197039,0.064131957,34321.92421,1.547928051,52.24704666
,19.8,3.379425521,0.064787326,34105.61674,1.569742143,52.65354043
,20,3.318352185,0.065447966,33917.10535,1.589374832,53.00415489
,20.2,3.375027111,0.066100876,33969.24557,1.597664183,53.30327301
,20.4,3.328100209,0.066760587,34262.99174,1.598100469,53.70319265
,20.6,3.542466271,0.067403148,34701.47592,1.59068366,54.0976343
,20.8,4.18122534,0.068017924,35418.4296,1.575413742,54.61917444
,21,4.091026307,0.068684805,36366.64026,1.548364275,55.07935588
,21.2,4.207197707,0.069344887,37503.85253,1.517824537,55.66992249
,21.4,4.17815906,0.070021195,38819.15568,1.483358274,56.31855942
,21.6,4.397930166,0.070687794,39918.7602,1.456308783,56.88173438
,21.8,4.521587672,0.071367396,41362.82796,1.422496931,57.60871195
,22,4.180908173,0.072084535,42213.27016,1.408317797,58.23050437
,22.2,4.319542012,0.072777278,43117.54777,1.394356768,58.90105499
,22.4,4.339594352,0.073484713,43775.59733,1.389557666,59.57708369
,22.6,4.074636503,0.074218116,44189.52108,1.39043025,60.14354487
,22.8,4.159177338,0.074937679,43883.32802,1.413553182,60.70671963
,23,4.344406369,0.075657718,42908.90782,1.454999943,61.11430946
,23.2,4.446420212,0.076388698,41575.30185,1.509971447,61.48683744
,23.4,4.86880861,0.07710215,40324.51657,1.563634079,61.80129575
,23.6,4.686227141,0.07786663,39489.4609,1.601590614,62.04672555
,23.8,4.718337427,0.078624414,39457.84742,1.611188812,62.40939247
,24,4.630617867,0.079397817,40789.99721,1.574541146,63.04597705
,24.2,4.376468452,0.080189836,42615.9369,1.525241319,63.78993678
,24.4,4.588317967,0.08095906,44193.39577,1.485539655,64.42433038
,24.6,4.67451262,0.081744354,45763.98953,1.45020082,65.12117694
,24.8,4.779845317,0.082536246,46964.69869,1.430131848,65.91663393
,25,4.79780171,0.08334189,47063.41809,1.440602611,66.584993
,25.2,4.854867516,0.084153236,46786.60219,1.460671571,67.16022004
,25.4,5.018446373,0.084965579,46572.82089,1.476813986,67.60834958
,25.6,4.820041642,0.085810005,46380.82396,1.496446684,68.20658544
,25.8,4.834664222,0.086648832,46404.00409,1.506917448,68.68429775
,26,4.840131893,0.087496655,46705.34452,1.511716548,69.29787321
,26.2,5.074437574,0.088337965,47053.09521,1.515206784,69.9103536
,26.4,5.175598996,0.08919655,47335.88848,1.517388185,70.39683145
,26.6,5.133630434,0.090073118,47643.92523,1.519133316,70.91070069
,26.8,4.981817582,0.090965678,47997.11248,1.522187301,71.55824182
,27,5.142056983,0.091846706,48039.29049,1.533094334,72.12689501
,27.2,5.045994882,0.092753469,48256.31904,1.538766006,72.72513098
,27.4,5.129674254,0.093657518,48562.67125,1.539638563,73.22585261
,27.6,5.182562882,0.094572699,48779.02981,1.543128818,73.72657408
,27.8,5.482596576,0.095480718,48940.12574,1.550981865,74.36425491
,28,5.175164321,0.096437858,49134.60876,1.556653554,74.93071595
,28.2,5.213069957,0.097381795,49018.25149,1.571487136,75.46759455
,28.4,5.632095632,0.098310216,48743.67292,1.588502091,75.86203683
,28.6,5.253926675,0.099300549,48583.12374,1.602026858,76.2674341
,28.8,5.443277787,0.100263311,48621.72469,1.612497604,76.81855689
,29,5.823188131,0.101223234,48945.61072,1.611188731,77.27873923
,29.2,5.425875226,0.102244144,49558.80363,1.603335691,77.88354849
,29.4,5.38638225,0.103251676,50324.9137,1.591992365,78.5190373
,29.6,6.009273605,0.104225699,50813.41664,1.587629497,79.03509951
,29.8,5.857438128,0.105260637,51404.48986,1.583266691,79.71331923
,30,5.654008125,0.106309358,51505.35852,1.589810933,80.17788318
,30.2,5.428940755,0.107369838,51365.31993,1.60508082,80.6928477
,30.4,5.394432469,0.108428438,51375.81677,1.615115306,81.20233441
,30.6,5.895822673,0.109462389,51510.82081,1.61991436,81.66361285
,30.8,5.93453963,0.110537262,51772.54849,1.622968328,82.23555311
,31,5.659536924,0.1116435,52133.3457,1.620786946,82.68806424
,31.2,6.146775563,0.112710629,52877.32284,1.61031614,83.32793698
,31.4,6.138055157,0.113821368,53512.26346,1.602899349,83.93712984
,31.6,6.122675853,0.114943569,54123.88914,1.595046278,84.48934791
,31.8,6.132259063,0.116075327,54711.09143,1.590683459,85.17962029
,32,6.167636896,0.117216795,55213.39772,1.588065766,85.83483135
,32.2,6.13727359,0.118374123,55554.70672,1.587193205,86.3344571
,32.4,6.379019244,0.119525096,56087.14982,1.583702931,87.00172094
,32.6,6.355309408,0.120705107,56469.10055,1.582830369,87.55065189
,32.8,6.305801243,0.121898718,57164.4494,1.576722429,88.30995146
,33,6.421055509,0.123093472,57851.97495,1.569741911,89.02213764
,33.2,6.328272082,0.124313967,58302.38812,1.567124228,89.57325969
,33.4,6.365301025,0.125538217,58659.32058,1.569305634,90.2580538
,33.6,6.391510171,0.126775362,59023.97748,1.569741914,90.85409883
,33.8,6.367788762,0.128028179,59349.68081,1.573668452,91.59915466
,34,6.490522527,0.129284014,59513.30838,1.578903824,92.14699013
,34.2,6.743900749,0.130543882,59789.27009,1.583702903,92.81863695
,34.4,7.030562684,0.131814185,60306.14311,1.582830316,93.52205807
,34.6,6.683129543,0.133139093,60620.2917,1.585011754,94.09399724
,34.8,7.074637368,0.13442853,60824.48479,1.589810821,94.66484264
,35,6.897789399,0.13576839,61288.44052,1.590247118,95.38908037
,35.2,6.851585756,0.137113095,61838.55153,1.588065713,96.13194483
,35.4,7.026730023,0.138456758,62225.94225,1.586756854,96.68964183
,35.6,7.054582827,0.139823564,62739.94544,1.585884288,97.50153375
,35.8,7.145676295,0.141200106,63242.79786,1.582830308,98.10963117
,36,7.394874767,0.142579943,63689.47916,1.583266569,98.83606146
,36.2,7.772221036,0.143965374,64058.66029,1.58632051,99.56249208
,36.4,7.436418507,0.145411583,64133.58457,1.593737329,100.0960828
,36.6,7.781306713,0.146827357,64339.74197,1.5985364,100.6713107
,36.8,8.023006901,0.148264235,64657.2062,1.602899197,101.4174631
,37,7.795792189,0.149746426,65138.86526,1.602462935,102.1559444
,37.2,7.682994788,0.15123591,65644.65699,1.600281536,102.8390947
,37.4,8.16725765,0.152700997,66285.67854,1.595046114,103.5496385
,37.6,8.269980576,0.154205987,66791.05932,1.591992133,104.200467
,37.8,8.113072461,0.155743268,67593.43045,1.585884202,105.0824815
,38,8.482076289,0.157261342,68135.55406,1.58544789,105.8801308
,38.2,8.224057909,0.158836029,68408.85558,1.588501884,106.4849401
,38.4,8.49652821,0.160391504,68815.84635,1.591119552,107.2519103
,38.6,8.491060249,0.161980957,69350.65148,1.589374426,107.9202694
,38.8,8.398214734,0.163592116,69566.91073,1.596791224,108.7299698
,39,8.520059563,0.165205218,69988.14388,1.598536341,109.495844
,39.2,8.733853598,0.166828599,70602.43872,1.594609787,110.1740646
,39.4,8.744602134,0.168481727,71290.88079,1.591555814,111.0221137
,39.6,8.92760164,0.170140072,71646.81688,1.593737208,111.7200565
,39.8,8.898818106,0.171829004,72284.47119,1.590246957,112.4640166
,40,8.984035477,0.173527328,72999.55171,1.587192978,113.3493189
,40.2,8.867455437,0.175256131,73268.12733,1.590683242,114.0111035
,40.4,8.975551254,0.176987461,73220.58259,1.602026558,114.775882
,40.6,9.494306172,0.178713538,73106.84725,1.612933558,115.4091813
,40.8,9.583672523,0.180485394,72880.00389,1.626022002,116.0063221
,41,9.504943868,0.182281694,72561.76695,1.642164434,116.6976901
,41.2,9.711638827,0.184068159,72661.99543,1.647399797,117.2860659
,41.4,9.45316157,0.185912276,73376.15157,1.64260072,118.1056267
,41.6,9.619074294,0.187746914,74387.84058,1.630384818,118.858353
,41.8,9.426330454,0.189623676,75414.94517,1.618605228,119.6680529
,42,9.626355097,0.191493457,76555.93474,1.606825605,120.5993735
,42.2,9.679919607,0.193391566,77226.64048,1.604644192,121.4945367
,42.4,9.703523914,0.195310863,77585.25548,1.605953035,122.2034356
,42.6,10.15734308,0.197221056,77771.17844,1.611188377,122.8969966
,42.8,10.15431269,0.199180616,78062.87639,1.61686004,123.7768201
,43,10.27193989,0.201151985,78358.24471,1.619477721,124.4528493
,43.2,10.19068179,0.203156118,78654.85951,1.624276827,125.2822718
,43.4,10.26669552,0.205170036,78973.08308,1.626894511,125.9637791
,43.6,10.08640598,0.207221146,79137.57224,1.632129907,126.6354248
,43.8,10.39042039,0.209260872,79231.08067,1.640855516,127.4845704
,44,10.36074218,0.211343227,79168.20309,1.650017435,128.0948592
,44.2,10.40345712,0.213441542,79160.97065,1.659179347,128.8190975
,44.4,10.31718655,0.215569438,78695.15802,1.676630623,129.4611603
,44.6,10.67444478,0.217689462,78334.9599,1.691027888,130.028719
,44.8,10.62644599,0.219857576,78270.68393,1.699317245,130.5634061
,45,11.55038666,0.22198348,78301.67468,1.707170236,131.2186204
,45.2,11.61222387,0.224187571,78520.70615,1.709787918,131.7565951
,45.4,12.02438974,0.226390568,79294.66742,1.704116219,132.5290443
,45.6,11.78248777,0.228658831,80009.86688,1.698444581,133.1842545
,45.8,11.76359647,0.230935257,80752.52145,1.692336638,133.8854836
,46,11.74137296,0.233234727,81763.43519,1.682738446,134.7521592
,46.2,11.90221722,0.235545253,82699.54223,1.672703954,135.469824
,46.4,11.86833636,0.237891774,83698.97261,1.663542042,136.3671782
,46.6,12.01752318,0.240249817,84511.65613,1.656561518,137.151679
,46.8,12.37557409,0.242617836,85280.01984,1.651326108,137.95152
,47,13.13554621,0.244983109,85892.72652,1.650017199,138.846686
,47.2,13.35961454,0.247407502,86110.70052,1.653943712,139.5325768
,47.4,13.46551472,0.249864084,86512.02984,1.656561395,140.4003484
,47.6,13.47321812,0.252351797,87028.8783,1.655688831,141.1377349
,47.8,13.33945326,0.254873914,87704.91637,1.65219859,141.944148
,48,13.56100938,0.25739779,88739.24201,1.644345499,142.9280612
,48.2,13.53375074,0.259963549,89727.32428,1.636056151,143.7651536
,48.4,13.45655945,0.262558308,90763.29416,1.629511935,144.7994665
,48.6,13.60653901,0.265164167,91223.51329,1.630384488,145.6025937
,48.8,13.77149297,0.267795226,91276.65491,1.638237539,146.3783293
,49,13.79164987,0.27046228,91173.349,1.650017143,147.2428136
,49.2,13.96741324,0.27314581,91205.58899,1.656997633,147.9177476
,49.4,14.05912589,0.275861817,91254.83661,1.664850695,148.7296402
,49.6,14.31393419,0.278594419,91509.01236,1.667904644,149.4516883
,49.8,14.55542382,0.28135542,92090.63576,1.666159496,150.2581029
,50,14.64379478,0.284154214,92844.44408,1.662669236,151.2157198
,50.2,14.55824344,0.286992522,93372.79391,1.662669244,152.1667614
,50.4,14.64577325,0.289847989,93728.37971,1.663978081,152.8931916
,50.6,14.92469134,0.292719523,94377.64208,1.661360367,153.7204243
,50.8,15.21525483,0.295619197,95393.51568,1.654379836,154.7536432
,51,15.26532445,0.298563792,96437.09245,1.646090482,155.6444239
,51.2,15.27461435,0.301540762,98065.60266,1.631693189,156.8025478
,51.4,15.38209236,0.304541015,99574.37877,1.617732168,157.7820781
,51.6,15.2174549,0.307589393,100975.4399,1.606825143,158.8361126
,51.8,15.64280177,0.310629548,102384.8776,1.598972038,160.1531107
,52,15.59299027,0.313731579,103010.2335,1.599408324,161.1063443
,52.2,15.24027387,0.316884737,102996.1344,1.610751676,162.1757171
,52.4,15.77128803,0.320011212,102151.1226,1.632565711,163.0358214
,52.6,15.79052941,0.323202879,101419.0238,1.650889536,163.7326681
,52.8,15.66164428,0.326436464,100584.543,1.670958501,164.4119833
,53,15.74162182,0.32968869,99694.26335,1.692772574,165.1460829
,53.2,15.89981556,0.332968509,99616.85478,1.700189347,165.7771903
,53.4,15.80253626,0.336298108,99901.80734,1.70411589,166.6340044
,53.6,15.85254091,0.339651407,100386.7501,1.704115886,167.3867307
,53.8,16.18297228,0.34302002,100941.4119,1.703679575,168.2008155
,54,16.4680465,0.346425368,101749.3003,1.700625578,169.1529546
,54.2,16.48849391,0.349882344,101977.3323,1.705860956,169.9944301
,54.4,17.42387669,0.353313543,102119.6218,1.710659968,170.6814202
,54.6,17.88992549,0.356810297,102521.9312,1.711532489,171.4429136
,54.8,18.28482051,0.360346821,103334.5335,1.70760592,172.4410719
,55,18.36141532,0.363939887,104194.3732,1.701061691,173.2748778
,55.2,18.3406437,0.367575515,105699.9696,1.685791839,174.229207
,55.4,18.57575013,0.371230807,107689.6686,1.66615915,175.4640293
,55.6,18.56453651,0.374939049,109069.1619,1.654815831,176.4873859
,55.8,18.63195446,0.378679276,110233.3219,1.649580447,177.746312
,56,18.94817706,0.382440698,110899.8037,1.648707857,178.6579118
,56.2,19.29975969,0.386237688,111346.5209,1.65263436,179.7711153
,56.4,19.32763282,0.390094067,111380.47,1.659614862,180.5523289
,56.6,19.24565696,0.39399649,111610.7218,1.664413966,181.4157171
,56.8,19.43953013,0.397919871,112085.5731,1.667904201,182.5617899
,57,19.55642385,0.40188778,112220.0263,1.673139569,183.3747784
,57.2,19.69785942,0.405894025,112203.0431,1.681865187,184.3477348
,57.4,19.85468325,0.409939396,112293.0841,1.688409396,185.3195957
,57.6,20.25947908,0.414009089,112173.3623,1.696262427,186.0909504
,57.8,20.41046491,0.418136578,112124.7883,1.703679199,186.8885995
,58,20.66171734,0.422298841,112460.9323,1.707169428,187.8758005
,58.2,21.00117023,0.426496991,113024.2915,1.706296835,188.705225
,58.4,21.07349529,0.430776236,114053.3798,1.701497732,189.7713131
,58.6,21.54857385,0.435050716,115182.4155,1.694517186,190.743176
,58.8,21.76402062,0.439363283,116277.0096,1.687972946,191.7511944
,59,21.88043205,0.443747674,117887.0138,1.676629618,192.9969732
,59.2,22.23566138,0.448160306,119076.4701,1.669212802,194.0214277
,59.4,21.87024829,0.452664811,120035.0587,1.666158864,195.2189941
,59.6,22.36859187,0.45715758,120652.9911,1.665722539,196.2040053
,59.8,22.44669633,0.461723324,121591.9632,1.662232281,197.2854326
,60,22.52978636,0.466334519,122079.5811,1.665286244,198.4501315
,60.2,22.58624046,0.470993861,122512.3166,1.667031365,199.4077483
,60.4,22.68096567,0.475697448,123784.2663,1.660487136,200.719267
,60.6,22.93711899,0.480437728,124886.7432,1.654815455,201.820418
,60.8,23.11504336,0.485230717,125634.8273,1.653506595,202.9390993
,61,23.01502449,0.490090302,126215.5278,1.655688011,204.2177465
,61.2,23.15215846,0.494983001,126696.3129,1.657869407,205.225765
,61.4,23.42409171,0.499915827,126489.0607,1.669648981,206.2896631
,61.6,23.91570262,0.50488396,126143.5018,1.681428536,207.1486716
,61.8,24.27416282,0.509910766,125967.1416,1.691462976,208.0460284
,62,25.02455403,0.514962121,126187.9716,1.697570849,209.121982
,62.2,25.3081053,0.520095112,126601.1894,1.699315949,210.0368692
,62.4,25.6449055,0.525276078,127732.3411,1.693644261,211.2607355
,62.6,25.53816557,0.53053832,128874.2619,1.686663769,212.3125797
,62.8,25.57454573,0.535843917,130671.8188,1.67532045,213.7851616
,63,25.75154947,0.541193464,132146.4517,1.666158526,214.9246603
,63.2,25.99678033,0.546592316,133482.6033,1.660923129,216.3019206
,63.4,25.90165639,0.552067751,133895.5614,1.664413388,217.3274681
,63.6,26.15019846,0.55757554,134325.4074,1.667903622,218.4012276
,63.8,25.88113925,0.56317279,134764.39,1.672702737,219.7467101
,64,26.0506101,0.568797208,134691.9172,1.680119505,220.6714576
,64.2,26.33241115,0.574470843,134859.456,1.686663699,221.8723149
,64.4,26.17982487,0.580230146,135489.5791,1.686227437,222.8726617
,64.6,26.50321476,0.586016019,135950.1778,1.688408815,223.8938292
,64.8,26.75253476,0.591864757,136420.2592,1.692771601,225.1834358
,65,26.87702408,0.59778055,136928.1859,1.694516722,226.1574882
,65.2,27.11051455,0.603748732,137531.8933,1.696698104,227.3725891
,65.4,27.08353499,0.609793968,137855.747,1.700188356,228.3334925
,65.6,26.9899744,0.615904301,138686.8251,1.698006961,229.3984843
,65.8,27.29083947,0.622050036,140041.1613,1.692335274,230.8436765
,66,27.54259833,0.628260721,140826.6225,1.690590129,231.927297
,66.2,28.09891131,0.634513767,141643.9648,1.690590079,233.2541584
,66.4,28.32984668,0.640851163,142126.0593,1.692335183,234.2895692
,66.6,28.21460078,0.647275082,142115.0525,1.699751974,235.285534
,66.8,28.35980516,0.653746153,141937.3469,1.710658994,236.4491372
,67,28.33108148,0.660293766,142116.5779,1.715894372,237.3804577
,67.2,28.34312231,0.666904468,142511.2893,1.720257185,238.5517308
,67.4,28.90519855,0.673545334,142627.4,1.725492509,239.4216972
,67.6,28.96714674,0.680285928,142753.9447,1.730727879,240.3256262
,67.8,29.02991629,0.687094242,142835.1365,1.738144656,241.4859428
,68,29.14426779,0.693967574,142651.6252,1.745561427,242.2485304
,68.2,29.12546556,0.700918746,141888.0771,1.760394993,243.1152063
,68.4,29.45948052,0.707916326,141135.6744,1.774792244,243.9139531
,68.6,29.61873442,0.714996008,140595.1338,1.785699261,244.5603999
,68.8,29.82041629,0.722143779,140360.0394,1.793116024,245.2594399
,69,30.85090025,0.729308841,140394.7447,1.798351301,246.0910615
,69.2,31.77569068,0.736552768,141235.3465,1.79355212,246.8832384
,69.4,31.9557024,0.743918584,143040.5094,1.779591104,248.0260248
,69.6,32.07578813,0.751362405,145011.5523,1.763884969,249.1468971
,69.8,32.32401185,0.758872481,146796.6515,1.751232791,250.2863974
,70,32.11787403,0.766488034,149258.6229,1.73334528,251.7491172
,70.2,32.55164125,0.774137913,151012.7287,1.721565648,252.9401147
,70.4,32.68000012,0.781884866,152210.3542,1.716766543,254.2866958
,70.6,32.93483222,0.789701188,152627.4563,1.718075364,255.3363508
,70.8,34.03677232,0.797540313,153162.7389,1.718075264,256.4605177
,71,34.32819362,0.805511618,153151.9275,1.724619455,257.6482274
,71.2,34.35997392,0.813580115,152812.9314,1.7350902,258.7296554
,71.4,34.54984831,0.821719154,152921.984,1.740325557,259.6335855
,71.6,34.84123095,0.829933695,153694.5905,1.739889249,260.6503707
,71.8,35.26699136,0.838222027,155231.183,1.734217555,262.0605029
,72,35.38775853,0.846613677,156809.8754,1.725928203,263.2350635
,72.2,35.56260154,0.855086032,158820.1335,1.715021158,264.6988819
,72.4,35.60345617,0.863652331,160216.4667,1.708476938,265.8854945
,72.6,35.99254847,0.872281831,161375.3521,1.704550373,267.110458
,72.8,35.95557037,0.881026097,161996.1177,1.707604344,268.577562
,73,36.07335668,0.889848021,162880.724,1.707168053,269.9613957
,73.2,36.55768738,0.898734396,164055.926,1.702368917,271.1381507
,73.4,36.65713829,0.907735448,166194.01,1.691025599,272.7860411
,73.6,37.03700663,0.916808346,167667.9034,1.68491763,274.1885038
,73.8,37.68356189,0.925954879,169252.3018,1.678373356,275.6599956
,74,38.4245506,0.935187207,169837.298,1.681863539,277.1862719
,74.2,38.88093206,0.944531091,169920.665,1.687971433,278.3597396
,74.4,38.77809936,0.954005714,169367.838,1.701059874,279.68331
,74.6,39.25359004,0.963537264,169488.4457,1.706731485,280.8512995
,74.8,39.61090136,0.973172414,169682.0901,1.711530545,282.0105228
,75,39.97485441,0.982904017,170643.0962,1.71065795,283.4655777
,75.2,40.54308268,0.992719935,171703.0002,1.709349055,284.9293994
,75.4,40.57581213,1.002669701,172399.8136,1.709785334,286.0973855
,75.6,40.92390737,1.012698656,172817.7949,1.71327555,287.2708529
,75.8,41.10347797,1.022839116,173279.2452,1.718510906,288.796029
,76,41.08914338,1.033094192,173351.8972,1.724618842,289.8719783
,76.2,41.00987707,1.04350877,173016.0636,1.735525875,291.1166609
,76.4,41.53556932,1.053936232,172668.3036,1.744251447,292.0074462
,76.6,41.43797929,1.064456515,172702.8365,1.749486828,293.0209417
,76.8,42.10010928,1.075085531,173193.7803,1.752104453,294.415737
,77,42.5325512,1.085836587,173852.3473,1.751231851,295.4807334
,77.2,42.74695485,1.096709961,175294.5836,1.744687616,296.9051084
,77.4,42.85898773,1.107699351,177033.3512,1.735089425,298.2122456
,77.6,43.70661615,1.118750757,178242.1285,1.731162818,299.4788493
,77.8,44.73147303,1.129901369,179101.838,1.732471567,301.0073204
,78,45.40681266,1.141187,179710.1573,1.733780348,302.1347721
,78.2,45.43639249,1.15262867,180131.5011,1.738143155,303.5186058
,78.4,45.82793556,1.164161502,180785.3016,1.740324523,304.8892946
,78.6,46.13874249,1.175815466,181911.8064,1.737706809,306.262174
,78.8,46.34884169,1.187593233,183156.265,1.733343981,307.5101455
,79,46.74698603,1.199476877,184622.6333,1.728981136,309.0769597
,79.2,47.20419343,1.21147599,185473.5777,1.728544813,310.3139773
,79.4,47.38344644,1.223614017,185783.4762,1.733780168,311.7372563
,79.6,47.46448739,1.235880462,186249.9378,1.735961565,312.8964782
,79.8,47.9857115,1.248241223,186519.6464,1.740324325,314.1236352
,80,48.13910944,1.260750145,187329.419,1.740760592,315.6170371
,80.2,48.88330773,1.273345731,188468.3255,1.736833996,316.8672054
,80.4,49.16564751,1.286098052,189912.6696,1.730726039,318.2181708
,80.6,49.31149573,1.298987705,191428.879,1.724618094,319.6688422
,80.8,49.64039447,1.311994606,193196.9157,1.718073851,321.5150521
,81,50.48103928,1.325098415,194236.2126,1.715892371,322.8934153
,81.2,50.70837508,1.338374283,194710.969,1.719382596,324.4164013
,81.4,51.08464295,1.351773676,195597.3229,1.720255125,326.0533386
,81.6,50.70613737,1.365357479,195776.4651,1.72592681,327.4393605
,81.8,51.15142987,1.3790234,196007.6424,1.730289578,328.5920111
,82,52.19168143,1.392787521,196329.4607,1.735088567,330.0350207
,82.2,52.96479368,1.406707459,196888.3536,1.736833622,331.2402671
,82.4,53.27854179,1.420797544,197496.9944,1.739887556,332.7566801
,82.6,53.8477347,1.435012394,198883.118,1.735524701,334.1449019
,82.8,54.03994498,1.449394953,200651.6173,1.728544188,335.6810359
,83,54.15557533,1.463927029,203357.6722,1.716328319,337.6061327
,83.2,54.56825682,1.478585476,205248.3422,1.70891151,339.1389818
,83.4,55.188118,1.493377562,207642.8791,1.699749562,341.1122931
,83.6,55.31865663,1.508350592,209012.213,1.697131866,342.740463
,83.8,55.36262869,1.523479722,209915.9997,1.700185824,344.6304979
,84,56.5033384,1.538688372,210485.7285,1.703239686,346.073509
,84.2,57.15139633,1.554082415,211831.8179,1.701930788,347.9383493
,84.4,57.4607483,1.569653476,212798.5723,1.701494473,349.4153184
,84.6,57.92901432,1.585370441,214408.2746,1.697131629,351.0719796
,84.8,58.26161627,1.601254261,216874.4297,1.688842267,353.3301626
,85,58.69404973,1.617291151,218010.2075,1.687533387,354.8925957
,85.2,59.01744714,1.633496285,218240.5701,1.694513848,356.7026492
,85.4,59.77436401,1.649835685,218440.8095,1.70193055,358.5039418
,85.6,60.10852723,1.666367209,217892.2589,1.712401253,359.7946467
,85.8,60.54917807,1.683057777,217249.2958,1.723744508,361.1302765
,86,60.9215667,1.699920513,217383.8743,1.730288682,362.7551614
,86.2,61.15995373,1.716961571,217701.1699,1.733778905,364.065588
,86.4,61.70038064,1.734153826,218300.2256,1.736396539,365.7310159
,86.6,62.19251589,1.751522102,219258.7066,1.735087652,367.1685429
,86.8,62.33595646,1.769087856,220158.6362,1.734651358,368.7035809
,87,62.86381797,1.786804669,221236.2988,1.733778749,370.4972018
,87.2,63.21357307,1.804711226,222947.1141,1.72854335,372.4058667
,87.4,63.81210961,1.822781352,224030.365,1.726361893,373.8576388
,87.6,64.2308749,1.841044887,224997.3969,1.725925574,375.4452734
,87.8,65.05569562,1.859465092,226384.7953,1.725052938,377.4974754
,88,65.3920204,1.878102548,227787.607,1.722435225,379.047856
,88.2,65.85147221,1.896919112,228913.2797,1.723744024,380.8568156
,88.4,66.36165451,1.915921436,230733.3523,1.718944893,382.5167648
,88.6,66.55559309,1.93513544,232504.5457,1.714582071,384.1909544
,88.8,67.06821075,1.954521678,234360.8951,1.711964342,386.3866873
,89,67.19010741,1.974128923,235399.9537,1.711964331,388.0247191
,89.2,67.69475729,1.993908406,236228.9694,1.714581967,389.956395
,89.4,68.51683713,2.013865719,236239.2591,1.721998659,391.6941404
,89.6,69.42875622,2.034017669,236198.8152,1.728542781,393.1426296
,89.8,70.01902085,2.054393225,236751.6834,1.731596689,394.76971
,90,70.3978893,2.074987327,237872.388,1.731596655,396.6345488
,90.2,71.28973933,2.095754599,238252.051,1.734650535,398.0731767
,90.4,71.92359266,2.11674758,238463.7492,1.73988584,399.816399
,90.6,72.32649354,2.137966661,238907.8144,1.742503485,401.3010404
,90.8,72.99439717,2.159381518,239997.0722,1.742067143,403.1165766
,91,73.83493567,2.181000099,241351.6208,1.740321944,404.8926724
,91.2,73.98393114,2.202881504,243753.7018,1.732905166,406.8155795
,91.4,74.60180264,2.224951835,247322.2648,1.719380422,408.9609133
,91.6,75.1106285,2.247251166,251021.9648,1.704983128,411.0328365
,91.8,75.36062319,2.269791471,254399.3415,1.69538494,413.6580708
,92,76.12526051,2.292524337,256208.5029,1.69189463,415.4999055
,92.2,76.90359179,2.315484782,258727.666,1.686222918,417.9520305
,92.4,77.39604627,2.338694799,260028.6751,1.685786593,419.8738463
,92.6,78.23962677,2.362114748,259976.444,1.692767,421.6335066
,92.8,78.77527803,2.38579038,259542.0254,1.703237676,423.7689795
,93,79.68202586,2.409679493,258913.8021,1.714144597,425.6546432
,93.2,80.27876345,2.433828646,257018.4562,1.731159467,426.9398743
,93.4,80.43193203,2.458248839,255210.2544,1.748610657,428.4584788
,93.6,81.19167171,2.482999366,254652.3799,1.757772468,429.8006882
,93.8,81.54863582,2.507901378,254894.0019,1.762571515,431.3269638
,94,82.2575553,2.533030369,255899.3643,1.763444009,433.1457897
,94.2,83.08711518,2.5582762,258363.1261,1.754282051,434.8835374
,94.4,83.82923974,2.58390915,262495.635,1.73770334,437.3060795
,94.6,84.89668994,2.609778221,266272.3688,1.722869722,439.4700466
,94.8,85.047913,2.635967614,269254.3495,1.713271548,441.6679682
,95,86.15855126,2.662356815,272314.1497,1.704982128,444.2614407
,95.2,86.67416749,2.689050495,273169.6917,1.708472321,446.4506013
,95.4,87.40360097,2.715998064,272978.8072,1.715889013,448.0678244
,95.6,88.22868741,2.743210245,271863.6712,1.728541056,449.6302641
,95.8,88.90810594,2.770705427,270710.336,1.74293823,451.5214048
,96,89.34865649,2.798492666,269838.3682,1.753408907,452.8592276
,96.2,90.15363974,2.826535041,269439.1855,1.76213443,454.5378095
,96.4,90.97522094,2.854858206,269261.7096,1.768242271,455.9293248
,96.6,91.26918051,2.88350064,269472.5441,1.772168762,457.343842
,96.8,91.91508929,2.912407595,270612.4314,1.772168701,459.358794
,97,92.93791101,2.941580131,271719.274,1.771732325,461.2137818
,97.2,93.53795931,2.971073681,273115.1267,1.769114589,462.8419602
,97.4,94.1762389,3.00086105,274903.069,1.765624291,464.8591031
,97.6,94.81530303,3.030947652,276386.3223,1.763006552,466.6187625
,97.8,95.52421886,3.061331469,278025.0738,1.760388807,468.425537
,98,95.60648536,3.092061602,280501.969,1.754717163,470.6300339
,98.2,96.54913477,3.123043332,282185.7546,1.751663117,472.3688795
,98.4,97.16886468,3.154357566,284715.1717,1.745555143,474.6139226
,98.6,97.73029483,3.185990179,286694.7266,1.741628573,476.5916205
,98.8,98.80260787,3.217906818,288335.5136,1.739447071,478.5780915
,99,99.82494153,3.250147408,290576.8001,1.734647901,480.9250362
,99.2,100.5667928,3.282730479,292951.2428,1.729412484,483.3837382
,99.4,100.8550763,3.315670662,294108.9023,1.728976171,485.2463881
,99.6,101.6176263,3.348910609,295307.7012,1.728976104,487.3062648
,99.8,102.6147865,3.382468989,296057.9986,1.732466249,489.6707416
,100,103.6476749,3.416362303,295047.4502,1.743373141,491.1729248
,100.2,104.1213119,3.450632802,292948.438,1.761260559,492.8482164
,100.4,105.4628149,3.485190516,291892.3482,1.772167419,494.1433213
,100.6,106.8650087,3.520091468,291005.0242,1.782637998,495.553473
,100.8,107.1129704,3.55541908,291352.6585,1.78700077,497.3777731
,101,108.0540471,3.59105593,293904.5665,1.77827509,499.1845524
,101.2,109.1573339,3.627040229,298482.0414,1.760823806,501.7813147
,101.4,109.7271624,3.663421279,302470.0213,1.746862815,504.4120355
,101.6,110.707177,3.700140656,305680.6216,1.73639202,506.6735202
,101.8,111.3700882,3.737249991,308459.9554,1.729411486,508.991975
,102,112.3200278,3.77471316,309941.9693,1.729847678,511.3893235
,102.2,113.4338389,3.812541978,310996.2149,1.73115641,513.2980036
,102.4,114.3561976,3.850763496,313259.0197,1.728538651,515.8914772
,102.6,115.2269027,3.889372375,315009.9628,1.727229734,518.1299512
,102.8,115.6548485,3.928398279,315709.7236,1.73028365,520.1536675
,103,116.7975387,3.967769145,316540.4223,1.733773779,522.5323927
,103.2,117.5640396,4.007560485,316182.1379,1.741190455,524.2416549
,103.4,118.813117,4.047719708,315136.2676,1.753406157,526.2040263
,103.6,119.8316279,4.088297638,315203.1057,1.759077691,527.9790335
,103.8,120.8350954,4.129284348,316253.971,1.760386435,529.9085299
,104,121.7769193,4.170686867,318180.6747,1.75864123,532.2993058
,104.2,123.0781606,4.212481668,320698.7837,1.7525332,534.3438529
,104.4,123.5080865,4.254753896,324701.9227,1.741189903,537.1192026
,104.6,124.42641,4.297418529,328451.432,1.73071912,539.6305013
,104.8,125.2231732,4.340519808,330728.4133,1.726792535,541.9719703
,105,125.9416465,4.384059285,332762.2957,1.725047352,544.6969231
,105.2,127.1268796,4.428005431,333779.3828,1.727664918,547.1961734
,105.4,128.2471356,4.472397568,334713.0322,1.72940993,549.2308583
,105.6,129.3057425,4.517239593,333988.232,1.738571691,551.0989999
,105.8,130.2286393,4.562541133,334623.7751,1.743370674,553.6212572
,106,131.4377191,4.608278891,335820.9802,1.745551956,556.0218982
,106.2,132.5460371,4.654483025,336419.4294,1.748605805,557.8604578
,106.4,133.1803788,4.701182752,335841.0821,1.758203881,559.9773107
,106.6,134.2290501,4.748326356,336342.2237,1.761694014,561.8586003
,106.8,135.4752787,4.795930772,335695.941,1.771292031,563.9469758
,107,136.5458502,4.844024904,335954.803,1.77478216,565.6003659
,107.2,137.4153836,4.8926157,336106.3528,1.780017423,567.6679183
,107.4,138.5519555,4.941676998,336412.6224,1.783943824,569.5157916
,107.6,139.4862396,4.991244529,336856.9688,1.787870243,571.4765166
,107.8,140.9962835,5.04127213,337816.496,1.788742657,573.2252382
,108,141.8018432,5.091848967,338193.0657,1.793105367,575.1174808
,108.2,142.8594596,5.142917242,340111.9293,1.789615036,576.9976766
,108.4,143.9440389,5.194496976,342798.1803,1.78394331,579.3884569
,108.6,145.4017492,5.24657029,346596.2943,1.772599928,581.7595208
,108.8,146.2843696,5.29920479,349915.1671,1.763874273,584.1601589
,109,147.4581538,5.352348836,354344.844,1.752094642,587.1185013
,109.2,148.4804041,5.406036916,356540.6235,1.749476875,589.5525601
,109.4,149.4592975,5.460267206,360099.2091,1.741187492,592.1750744
,109.6,150.7073005,5.515024659,362236.3435,1.739005983,594.6578955
,109.8,151.9722748,5.570331182,367167.3441,1.72679007,598.0775179
,110,152.8402314,5.6262196,370703.7837,1.718500699,600.7257804
,110.2,154.2964194,5.682630716,376701.662,1.702358266,604.4017945
,110.4,155.6659749,5.739614411,378921.2933,1.699740471,607.0358217
,110.6,157.0437607,5.797170193,380798.9261,1.699304068,609.8199561
,110.8,157.9795905,5.855330436,380651.6404,1.708465827,612.8648536
,111,159.4969906,5.914036621,380066.0135,1.718936367,615.6084511
,111.2,160.8570231,5.973343254,379337.8276,1.728098085,617.6705359
,111.4,162.0155839,6.033258905,379731.4498,1.734205873,620.3845446
,111.6,163.2863871,6.093769874,380990.7108,1.735514589,622.8366885
,111.8,164.2633004,6.155217733,382607.3704,1.735514499,625.4016825
,112,166.4343289,6.216586332,384198.055,1.736386854,628.2625286
,112.2,167.1747681,6.278976424,384842.0195,1.739440731,630.4133533
,112.4,168.8712318,6.34193024,386714.6447,1.739440574,633.3224024
,112.6,170.1739946,6.405542594,389454.7539,1.735077673,636.0364151
,112.8,171.417574,6.469797908,392817.9955,1.729842221,639.3640036
,113,173.0787829,6.534671299,396021.3926,1.724170454,642.1470508
,113.2,174.2938632,6.600226079,401701.2068,1.711082005,645.8964749
,113.4,175.8333718,6.666417943,404533.0021,1.707155363,648.7058166
,113.6,176.8535218,6.733309202,406111.7982,1.708464103,651.5534961
,113.8,178.6957149,6.800818172,407806.4419,1.710645324,655.032302
,114,180.1292215,6.869032512,408062.5267,1.715444249,657.5151298
,114.2,181.181501,6.937957405,407458.5055,1.724605985,660.430744
,114.4,182.7254624,7.007542319,408887.5801,1.726350953,663.5063357
,114.6,184.493989,7.077811634,410516.3189,1.72635079,666.1250352
,114.8,185.9869665,7.14880515,413522.5453,1.722424154,669.1480342
,115,187.2684681,7.22052585,416713.3651,1.719370092,672.6268301
,115.2,188.9501121,7.292940776,419022.7702,1.717624827,675.3967322
,115.4,190.308772,7.36610401,419930.708,1.721987478,678.5928444
,115.6,191.7288931,7.43999733,420058.4756,1.728095232,681.2038686
,115.8,193.4983928,7.514609431,417860.7323,1.742055947,683.4368918
,116,194.9482335,7.589991607,416552.6165,1.75427158,686.0884572
,116.2,196.3197331,7.666136155,415453.8922,1.764305832,688.0157782
,116.4,197.7144108,7.743043867,416021.5864,1.769977306,690.7013091
,116.6,199.3203278,7.82071016,417422.2797,1.770849705,693.0964902
,116.8,201.3879553,7.899126237,421020.5739,1.763869071,695.8422974
,117,202.6591046,7.978382856,425334.7724,1.755579686,699.2115265
,117.2,204.3445302,8.058408409,429317.5788,1.748599092,702.6300732
,117.4,205.7885089,8.139253909,431498.2276,1.746417571,705.2432911
,117.6,207.5976653,8.220887556,432954.3695,1.747289952,707.8762388
,117.8,208.9997776,8.303368192,434073.0846,1.750780044,711.1413841
,118,210.6006381,8.386664334,435479.1577,1.751216168,713.7162572
,118.2,212.322857,8.470789379,437079.3949,1.751652283,716.7863791
,118.4,213.7977976,8.555775871,439713.8476,1.747725654,719.565046
,118.6,215.4007509,8.641607903,442467.9103,1.74379901,722.6143481
,118.8,217.0709699,8.728297853,445838.8293,1.739872363,726.30791
,119,218.8359135,8.815852547,447395.9128,1.740744749,728.8762138
,119.2,220.8378752,8.904271302,450916.345,1.737254351,732.3473607
,119.4,222.3454082,8.993610946,454186.6998,1.735072823,735.9620315
,119.6,223.9085513,9.083844446,457161.7812,1.732455014,738.9959947
,119.8,225.8476745,9.174959769,461127.3002,1.726783243,742.3608607
,120,227.7899805,9.266990392,464174.8946,1.72460168,746.0325154
,120.2,229.8220097,9.359939694,466252.6301,1.724165216,749.0533429
,120.4,231.4727732,9.453848079,468378.9273,1.725037617,752.590224
,120.6,233.0310199,9.548705932,470574.6546,1.724601196,755.6877383
,120.8,235.202397,9.644476472,472798.3709,1.725909825,759.5237524
,121,236.7761494,9.741248578,475572.9982,1.723728296,762.6059273
,121.2,238.6401615,9.838973876,478295.2591,1.723728124,766.3641428
,121.4,240.5472883,9.937678028,480813.7622,1.722419119,769.3345679
,121.6,242.7280288,10.03735604,483668.8682,1.721110088,772.6698574
,121.8,244.0232208,10.1380939,485603.1241,1.724163903,776.5694054
,122,246.348432,10.23977595,487431.2831,1.726781345,780.2597001
,122.2,248.0618631,10.34251989,488645.8007,1.729398843,783.149041
,122.4,250.2269779,10.44626629,487938.7805,1.738996718,786.4054441
,122.6,252.5067609,10.55104752,485703.0542,1.751648512,788.7820212
,122.8,254.012393,10.58951036,483590.577,1.763864101,791.1684432
,123,255.6198497,10.5894051,481003.2296,1.778261059,793.726888
,123.2,256.9119282,10.58932055,480264.7748,1.785241352,795.8514371
,123.4,258.2397884,10.58923365,480529.9915,1.790040262,798.5654619
,123.6,258.612361,10.58920946,483911.1214,1.784368639,801.4569653
,123.8,259.4642415,10.5891538,488370.1465,1.776079316,804.6125386
,124,260.2724352,10.58910101,492327.5469,1.770407653,808.0968142
,124.2,260.8114341,10.58906589,495896.2784,1.766481119,811.6413459
,124.4,261.3350386,10.58903178,499116.8268,1.762554587,814.6172212
,124.6,261.4180293,10.58902659,499484.2589,1.767353615,817.3235492
,124.8,262.1055637,10.58898172,499824.9244,1.773025137,820.5569108
,125,262.6083649,10.58894898,502163.5872,1.77084371,823.2621529
,125.2,262.9746964,10.58892519,503437.8273,1.773025055,826.5042746
,125.4,263.2515738,10.58890727,504429.7114,1.775424546,829.3979684
,125.6,263.7364841,10.5888757,507064.9508,1.773024984,832.462591
,125.8,264.1689701,10.58884758,510563.0717,1.768662185,835.8855016
,126,264.5120019,10.58882532,512728.8359,1.768662153,839.2645828
,126.2,264.5920801,10.58882032,514963.4931,1.767353319,842.0925308
,126.4,265.0403766,10.58879115,516941.6446,1.768225828,845.6030953
,126.6,265.4674537,10.58876338,515906.2541,1.776515028,848.1275484
,126.8,265.5754083,10.58875655,512947.879,1.790475844,850.1841403
,127,265.9438201,10.58873263,509073.8593,1.80792684,852.3163388
,127.2,266.3987736,10.58870303,506740.8017,1.819706243,853.9565814
,127.4,266.4343328,10.58870095,504742.7892,1.831485685,855.9835867
,127.6,266.6167632,10.58868923,505850.6591,1.832794495,858.0566158
,127.8,266.8499536,10.58867419,510320.6461,1.825377785,861.2461423
,128,267.0689978,10.58866007,513721.2595,1.819706179,863.7278601
,128.2,267.2555888,10.58864808,516093.7541,1.817088507,866.1515074
,128.4,267.5774012,10.58862721,518451.4468,1.815343373,869.087933
,128.6,267.6653847,10.5886217,518444.7386,1.819706122,871.2902471
,128.8,267.6077451,10.58862574,517742.6877,1.82668654,873.7358004
,129,267.8854546,10.58860777,516521.2083,1.834103201,875.4373956
,129.2,268.0982577,10.58859406,514510.0925,1.845010074,877.363605
,129.4,268.3526675,10.58857762,512865.2189,1.853735564,878.8099081
,129.6,268.6020844,10.58856151,511746.9753,1.860715951,880.3044171
,129.8,268.6626076,10.58855779,510951.5751,1.867260081,882.1780302
,130,268.5267476,10.58856697,511642.3368,1.868568922,884.1381969
,130.2,268.9276125,10.58854091,512506.026,1.868568883,885.8266481
,130.4,269.1395836,10.58852726,512374.997,1.872495344,887.6520531
,130.6,269.3149408,10.58851601,511532.5535,1.878166911,889.047952
,130.8,269.4245597,10.58850907,509779.9653,1.886456138,890.1688338
,131,269.3619273,10.58851344,507378.4021,1.897363038,891.3203911
,131.2,269.7736099,10.58848668,507416.6781,1.899980651,892.4774373
,131.4,269.8923822,10.58847914,508538.5092,1.899544363,894.1110978
,131.6,269.8572102,10.58848171,510261.0962,1.896926713,895.6001241
,131.8,270.2222934,10.588458,512903.9395,1.891691368,897.2940516
,132,270.1346971,10.58846401,514768.2975,1.889509999,899.1139731
,132.2,270.2185199,10.58845877,514492.5025,1.893872748,900.6062904
,132.4,270.4646083,10.58844287,514369.9144,1.896926653,901.7545674
,132.6,270.5392776,10.58843823,514269.0322,1.899980576,902.9411894
,133.4,270.6613819,10.48998124,1.7977E+308,1.858098102,0
,133.6,270.547342,10.38412876,1.7977E+308,1.727215412,0
,133.8,270.3409356,10.27828234,1.7977E+308,1.508205039,0
,134,270.1128937,10.17243734,1.7977E+308,1.234223926,0
,134.2,269.9173049,10.06659021,1.7977E+308,0.930139781,0
,134.4,269.4546019,9.960760615,1.7977E+308,0.598133994,0
,134.6,269.4878493,9.854898466,1.7977E+308,0.353819597,0
,134.8,269.0584315,9.749066685,1.7977E+308,0.188034834,0
,135,269.2239878,9.643195852,1.7977E+308,0.077220801,0
,135.2,269.0508665,9.537347248,1.7977E+308,0.006544136,0
,135.4,268.6497413,9.43151361,1.7977E+308,0.019632408,0
,135.6,268.4965912,9.325663696,1.7977E+308,0.024867717,0
,135.8,268.3034988,9.219816403,1.7977E+308,0.027921647,0
,136,267.8183282,9.113988281,1.7977E+308,0.031411854,0
,136.2,267.7583768,9.00813225,1.7977E+308,0.031411854,0
,136.4,267.4396325,8.902293204,1.7977E+308,0.0287942,0
,136.6,267.3081178,8.79644187,1.7977E+308,0.030103028,0
,136.8,267.1208503,8.690594195,1.7977E+308,0.031411855,0
,137,266.8961369,8.584748977,1.7977E+308,0.029666753,0
,137.2,266.4417552,8.478918835,1.7977E+308,0.025303995,0
,137.4,266.338533,8.373065643,1.7977E+308,0.01657848,0
,137.6,266.2128432,8.267213926,1.7977E+308,0.00828924,0
,137.8,266.033897,8.161365705,1.7977E+308,0.011779446,0
,138,265.7284668,8.055525786,1.7977E+308,0.01657848,0
,138.2,265.5037533,7.949680569,1.7977E+308,0.017451032,0
,138.4,265.0468751,7.84385059,1.7977E+308,0.015705929,0
,138.6,265.0884438,7.737987895,1.7977E+308,0.01352455,0
,138.8,264.9677468,7.63213585,1.7977E+308,0.022686343,0
,139,264.6689736,7.526295494,1.7977E+308,0.031848135,0
,139.2,264.3635434,7.420455575,1.7977E+308,0.043627584,0
,139.4,264.1904221,7.314606971,1.7977E+308,0.048862894,0
,139.6,263.9199414,7.208764758,1.7977E+308,0.050171722,0
,139.8,263.7759447,7.102914243,1.7977E+308,0.045372689,0
,140,263.4963105,6.997072631,1.7977E+308,0.038392276,0
,140.2,263.4363591,6.891216599,1.7977E+308,0.029230483,0
,140.4,263.3647579,6.785361331,1.7977E+308,0.026176552,0
,140.6,262.9087118,6.679531298,1.7977E+308,0.030975587,0
,140.8,262.5059221,6.57369777,1.7977E+308,0.03708345,0
,141,262.1014681,6.46786435,1.7977E+308,0.036210899,0
,141.2,261.9691213,6.36201307,1.7977E+308,0.035774624,0
,141.4,261.9749083,6.256152724,1.7977E+308,0.038828555,0
,141.6,261.5363369,6.150321544,1.7977E+308,0.035338349,0
,141.8,261.5820663,6.044458575,1.7977E+308,0.030975589,0
,142,261.2379418,5.938621196,1.7977E+308,0.030103038,0
,142.2,260.9578916,5.832779611,1.7977E+308,0.026176555,0
,142.4,260.7760328,5.72693158,1.7977E+308,0.028357935,0
,142.6,260.6054079,5.621082813,1.7977E+308,0.030103039,0
,142.8,260.422717,5.515234837,1.7977E+308,0.033156971,0
,143,260.2059088,5.409389101,1.7977E+308,0.02792166,0
,143.2,259.872186,5.303551039,1.7977E+308,0.026612833,0
,143.4,259.7573138,5.197698612,1.7977E+308,0.026176557,0
,143.6,259.2904499,5.091869289,1.7977E+308,0.02268635,0
,143.8,259.2404841,4.986012602,1.7977E+308,0.019196143,0
,144,259.2466872,4.880152228,1.7977E+308,0.017887315,0
,144.2,258.7939695,4.774321976,1.7977E+308,0.022250075,0
,144.4,258.5459562,4.668478289,1.7977E+308,0.028357939,0
,144.6,258.3208266,4.562633099,1.7977E+308,0.032284423,0
,144.8,258.0553386,4.456790558,1.7977E+308,0.031411872,0
,145,257.7881863,4.350948126,1.7977E+308,0.03381139,0
,145.2,257.3575201,4.245116427,1.7977E+308,0.035338357,0
,145.4,257.0125634,4.139279102,1.7977E+308,0.037083462,0
,145.6,257.0686944,4.033415451,1.7977E+308,0.038828566,0
,145.8,256.7158325,3.927578645,1.7977E+308,0.037956015,0
,146,256.4112343,3.821738672,1.7977E+308,0.029666771,0
,146.2,256.2173096,3.715891433,1.7977E+308,0.013524557,0
,146.4,255.9068864,3.610051842,1.7977E+308,0.004799037,0
,146.6,255.652216,3.504208591,1.7977E+308,0.023558907,0
,146.8,255.4017064,3.398365067,1.7977E+308,0.040137398,0
,147,255.0822138,3.29199677,1.7977E+308,0.045808987,0
,147.2,254.7217786,3.186689762,1.7977E+308,0.050608025,0
,147.4,254.4263337,3.080849188,1.7977E+308,0.053225683,0
,147.6,254.1400423,2.975008012,1.7977E+308,0.04580899,0
,147.8,254.3380519,2.869135048,1.7977E+308,0.036210915,0
,148,253.9469118,2.763300755,1.7977E+308,0.03359326,0
,148.2,253.4966904,2.65747034,1.7977E+308,0.027049119,0
,148.4,253.2586626,2.551625996,1.7977E+308,0.023122634,0
,148.6,253.0788842,2.44577783,1.7977E+308,0.025740291,0
,148.8,252.5787348,2.339950692,1.7977E+308,0.02486774,0
,149,252.6119821,2.234088542,1.7977E+308,0.017014769,0
,149.2,252.2865805,2.128249934,1.7977E+308,0.008725523,0
,149.4,251.9894713,2.022409469,1.7977E+308,0.000872552,0
,149.6,251.6349451,1.916572772,1.7977E+308,0.004362762,0
,149.8,251.4027422,1.810728047,1.7977E+308,0.006107866,0
,150,251.2595775,1.704877477,1.7977E+308,0.011779457,0
,150.2,250.8193416,1.599046406,1.7977E+308,0.015705942,0
,150.4,250.2351468,1.493224784,1.7977E+308,0.020941257,0
,150.6,249.9288841,1.38738492,1.7977E+308,0.02530402,0
,150.8,249.73912,1.281537409,1.7977E+308,0.028794229,0
,151,249.4278646,1.175697872,1.7977E+308,0.031848163,0
,151.2,248.5540876,1.069895258,1.7977E+308,0.022686364,0
,226.4,248.6294582,0.969949591,1.7977E+308,0.050608047,0
,226.6,248.2591213,0.864113932,1.7977E+308,0.049735495,0
,226.8,248.1484097,0.758261232,1.7977E+308,0.047554114,0
,227,247.585018,0.652438245,1.7977E+308,0.044936458,0
,227.2,247.2612805,0.546599528,1.7977E+308,0.042755077,0
,227.4,246.6454645,0.440779982,1.7977E+308,0.038392316,0
,227.6,245.926464,0.334967208,1.7977E+308,0.036647212,0
,227.8,245.4546068,0.229138213,1.7977E+308,0.031411897,0
,228,244.4135709,0.123346578,1.7977E+308,0.028357964,0
,228.2,243.4224629,0.017551665,1.7977E+308,0.023995202,0
,228.23,243.0594393,0.001696498,1.7977E+308,0.023558926,0
END,,,,,,