File: GB1_test 53.csv
Segment,Time On Sample,Displacement Into Surface,Load On Sample,Harmonic Contact Stiffness,Harmonic Displacement,Harmonic Load
Surface Marker,0,0,0,-126.319926,0.483804227,2.191417397
,0.3,0.232147474,0.000969972,5224.057616,0.26698664,2.311945368
,0.6,0.678141439,0.001925924,12117.24202,0.205038754,2.420420561
,0.9,0.520871947,0.002921428,15699.10821,0.171011048,2.538757088
,1.2,0.557478847,0.003904221,19839.4513,0.144399634,2.738176075
,1.5,0.516701608,0.004892088,24266.76366,0.129567044,3.026347464
,1.8,0.763826652,0.005861078,27750.23937,0.123459505,3.352868688
,2.1,0.858679678,0.006840052,27674.6712,0.13262081,3.733079622
,2.4,0.761320488,0.007831629,27664.03845,0.151379676,4.376260627
,2.7,0.979322535,0.008802093,28960.81724,0.170138539,5.022728814
,3,0.999287879,0.009784757,29772.29219,0.193696182,5.646187069
,3.3,1.082907917,0.010763248,30029.5013,0.225542626,6.555625345
,3.6,1.099960954,0.011746103,31857.29012,0.246046501,7.618462796
,3.9,1.028396673,0.012734768,34432.09745,0.255207808,8.553102328
,4.2,1.055850804,0.013716941,38763.34987,0.257389071,9.710170742
,4.5,1.041284516,0.014701869,41387.862,0.274839177,11.07761524
,4.8,1.190223423,0.015676077,41993.42288,0.299705577,12.28070345
,5.1,1.042939178,0.016669707,41193.60953,0.335478298,13.51118433
,5.4,0.969294677,0.017658508,40481.05554,0.380848576,15.10215333
,5.7,0.772501224,0.018655384,39174.95831,0.430581385,16.5243832
,6,0.327329638,0.019668545,37293.74958,0.493838034,18.01125967
,6.3,0.787053242,0.020622376,35399.25685,0.565819713,19.52443367
,6.6,0.713824784,0.02161115,33412.01358,0.642600185,20.88311238
,6.9,0.846537987,0.022586422,31177.27753,0.730286967,22.11688054
,7.2,-0.084572727,0.023631444,28635.09429,0.838477672,23.33311655
,7.5,-0.020922785,0.024611243,25891.21475,0.962373433,24.3170631
,7.8,1.664049687,0.02548474,22636.67853,1.120296805,25.03804049
,8.1,1.609127157,0.026472314,20295.00124,1.25553513,25.55959787
,8.4,1.694410847,0.027453974,18575.05564,1.375940856,26.07567669
,8.7,1.851255101,0.028424386,18382.74782,1.412586067,26.70461366
,9,1.396930578,0.029438147,19263.8462,1.389464712,27.4244939
,9.3,1.680667656,0.030403517,20830.36022,1.340604394,28.41063207
,9.6,1.778849222,0.031381052,21730.2687,1.320100513,29.16119257
,9.9,1.636557507,0.032374355,21558.9293,1.354564483,29.8624461
,10.2,1.744724123,0.033351236,20603.7319,1.430036184,30.4168747
,10.5,2.16825189,0.034307441,20017.7127,1.487185248,30.79489469
,10.8,2.240638743,0.035286668,19954.87671,1.520776695,31.2649537
,11.1,2.041765083,0.03628368,20668.90181,1.508561639,31.79965944
,11.4,2.626717809,0.037229301,22333.56752,1.452721255,32.5721346
,11.7,2.793962628,0.038202309,24126.77257,1.39426339,33.3906293
,12,2.800614572,0.039185846,25953.7057,1.338859307,34.26281339
,12.3,2.776479281,0.040171402,27644.06252,1.29087152,35.12513622
,12.6,2.790620011,0.041154448,29967.9552,1.228051142,36.12770968
,12.9,2.61670898,0.042149824,32245.90363,1.176137091,37.16644145
,13.2,2.823893997,0.043120213,33637.86787,1.155196951,38.08245421
,13.5,1.994298049,0.044158579,32924.02257,1.203621049,39.01709299
,13.8,2.460262272,0.045112001,30133.37337,1.320536721,39.44770692
,14.1,2.575917672,0.046088392,26998.83623,1.478023919,39.75998404
,14.4,3.221612764,0.04703003,25379.16872,1.578361964,39.94406384
,14.7,3.107612032,0.048021478,26404.43541,1.547388043,40.57300054
,15,2.816376675,0.049024546,28877.42215,1.45184874,41.49010844
,15.3,3.239904421,0.049980751,31967.69778,1.348456842,42.51459664
,15.6,2.800557502,0.05099353,34084.76616,1.297851562,43.52264818
,15.9,2.980283633,0.05196572,34748.0716,1.300032819,44.39044974
,16.2,3.133382964,0.052939655,34834.49571,1.322717943,45.22537988
,16.5,3.032695629,0.05393023,34494.93777,1.356745657,45.97813181
,16.8,2.827997364,0.054927625,34285.22122,1.384229585,46.71116071
,17.1,3.323916716,0.055879083,34233.96202,1.402115907,47.34338546
,17.4,3.100080444,0.056877732,34368.7634,1.416948514,48.15420938
,17.7,3.257340211,0.057851395,34542.99723,1.431344839,48.90805745
,18,3.019358452,0.058850972,34562.3554,1.449231216,49.51398395
,18.3,3.412931047,0.05980914,34712.10594,1.467553795,50.28865065
,18.6,3.396284543,0.060794205,34749.56941,1.484131396,50.87704617
,18.9,3.475328092,0.061772996,34698.59871,1.504199011,51.53556737
,19.2,3.394610857,0.062762262,34423.38943,1.530810427,52.10095284
,19.5,3.439538822,0.06374329,34199.58947,1.554368065,52.69592288
,19.8,3.478642175,0.064724699,33942.18062,1.580979472,53.24158573
,20.1,3.602618443,0.065700544,33617.19567,1.608027124,53.68644392
,20.4,3.273939159,0.066706068,33357.14647,1.634202311,54.19266067
,20.7,4.007419452,0.06764195,33216.42576,1.653833613,54.6572425
,21,3.591370996,0.068653202,33416.6722,1.659504935,55.14702341
,21.3,3.771097121,0.069625392,33723.62128,1.662558688,55.61927441
,21.6,3.994091788,0.070594745,34516.18811,1.646417322,56.18575604
,21.9,4.077295771,0.071573263,36240.75286,1.594503256,56.95713531
,22.2,3.679969283,0.072583288,38515.09837,1.526884136,57.82164872
,22.5,3.639192214,0.073570131,41158.24567,1.45839248,58.85161511
,22.8,3.783553062,0.074554461,41525.44525,1.465808764,59.64709967
,23.1,3.715729261,0.075567551,40105.63017,1.530810409,60.18838
,23.4,4.242013485,0.076556641,38009.02341,1.6206784,60.52805031
,23.7,4.492458323,0.077578973,37455.57163,1.654706081,60.95099459
,24,4.314791692,0.078645182,38746.35959,1.61980589,61.65991771
,24.3,4.563151281,0.079699293,41151.00716,1.550005454,62.5518252
,24.6,3.748100573,0.080839599,43914.48529,1.480641359,63.62342673
,24.9,4.391280424,0.081900608,44367.10395,1.485876339,64.45945399
,25.2,4.215683643,0.083031904,43476.29791,1.532555382,65.14974997
,25.5,4.377911668,0.084157855,42015.23133,1.595811995,65.62967095
,25.8,4.549705958,0.085300407,42130.9287,1.604973285,66.23669368
,26.1,4.191041161,0.086499025,42991.22631,1.588831971,66.92698981
,26.4,4.188508202,0.087684109,44382.0431,1.560475553,67.82875786
,26.7,4.391081287,0.088877736,45276.27779,1.549569221,68.66916721
,27,4.469670443,0.090097794,45556.86974,1.556985509,69.40329189
,27.3,4.281988713,0.091353704,45576.36879,1.573999377,70.16919243
,27.6,4.508267476,0.092601213,45700.87714,1.585341926,70.86496758
,27.9,4.579774961,0.093877899,45946.62242,1.592321962,71.58594442
,28.2,4.510656606,0.095183141,46451.29441,1.590576958,72.30253759
,28.5,4.74774329,0.0964879,47251.06675,1.580979381,73.11664987
,28.8,4.457283401,0.097847246,48026.57603,1.573999366,73.92856933
,29.1,4.891568413,0.099179196,48285.05068,1.58097937,74.60571843
,29.4,4.383095167,0.100593515,48313.02803,1.596248256,75.35189484
,29.7,5.369047548,0.101930483,47973.8336,1.62155082,76.00603528
,30,5.766710886,0.103326557,48195.40953,1.627658321,76.69633253
,30.3,5.952188581,0.10475775,49113.98088,1.615006981,77.57399589
,30.6,5.749078019,0.106236313,50611.51142,1.585778078,78.50863498
,30.9,5.955350918,0.107710051,52583.85001,1.547824088,79.57256885
,31.2,5.978561059,0.109218112,54127.25163,1.522957687,80.56966385
,31.5,6.174841732,0.110737649,54903.71184,1.520340159,81.56675944
,31.8,6.109843342,0.112297268,55126.90129,1.531246476,82.5024944
,32.1,6.346056838,0.113860524,55055.07982,1.549132821,83.40864631
,32.4,6.455789281,0.115455871,55354.22017,1.556549096,84.32465917
,32.7,6.722782402,0.117064928,55891.7242,1.558294091,85.26258659
,33,6.549597438,0.118727439,56901.40867,1.548696546,86.23776706
,33.3,6.588590739,0.120401163,58199.39104,1.532991456,87.26663777
,33.6,6.715781305,0.122094187,59480.07535,1.51946761,88.38316541
,33.9,7.272324874,0.123784391,60385.7701,1.515105045,89.50407698
,34.2,7.089138735,0.125549057,60738.66089,1.523830108,90.64032662
,34.5,7.506715404,0.127300706,61114.42445,1.531246368,91.71302669
,34.8,7.420875015,0.129112215,61793.65448,1.531682629,92.76271531
,35.1,7.694491999,0.130927319,62497.53142,1.531246354,93.74666287
,35.4,7.544572183,0.132797824,63243.84005,1.532991377,94.933315
,35.7,7.946321752,0.134660185,63597.47389,1.542152647,96.0169725
,36,7.432770816,0.136611133,63835.50524,1.552622751,97.05132012
,36.3,7.81454116,0.138532267,64181.01442,1.561784023,98.17113587
,36.6,7.403327686,0.140534796,64991.03723,1.560039048,99.29423596
,36.9,7.704376162,0.142520401,65730.98311,1.560475276,100.4184345
,37.2,7.902241008,0.144543018,66375.73511,1.561784017,101.4604539
,37.5,8.017724364,0.146601567,66582.45943,1.573126573,102.5024738
,37.8,7.978434529,0.148701506,66536.02043,1.588831668,103.4623142
,38.1,8.496222102,0.150796283,65987.75411,1.616315531,104.3739459
,38.4,8.138232768,0.152980637,65529.19871,1.640745704,105.2318845
,38.7,8.243294781,0.155167273,65384.87865,1.657323291,106.0679111
,39,7.983481282,0.15741095,65698.72409,1.662558345,106.9477642
,39.3,8.358961021,0.15964668,66537.1215,1.656668903,107.9476001
,39.6,8.330873064,0.161942796,67142.54973,1.656232654,108.9030577
,39.9,8.747114166,0.164244438,67689.68607,1.656886996,109.8097586
,40.2,8.646207532,0.166614829,67648.59844,1.671719591,110.7400147
,40.5,8.786600521,0.169005037,67865.23828,1.677827113,111.5201604
,40.8,8.753497566,0.171442873,68515.40845,1.675645855,112.4789051
,41.1,8.87307676,0.173907513,69209.3279,1.671283319,113.3379416
,41.4,8.707244109,0.176428215,70275.40774,1.661249528,114.4413195
,41.7,9.026096245,0.178954908,70831.37251,1.661685752,115.4504689
,42,9.110293703,0.181535288,71297.51368,1.664739512,116.4508512
,42.3,9.568092074,0.184130344,71472.34261,1.673464521,117.3109844
,42.6,10.33250832,0.186744468,71917.27146,1.677826977,118.2675405
,42.9,10.73121601,0.189421797,72754.90372,1.673464416,119.3029873
,43.2,10.77461603,0.19216317,74261.53312,1.654269305,120.3932175
,43.5,10.861278,0.194943071,76183.44289,1.629839161,121.7168346
,43.8,10.84475299,0.197781199,77562.0037,1.615442832,122.8563714
,44.1,11.03125345,0.200629843,78298.45321,1.614134059,123.9586557
,44.4,11.11415068,0.203537948,77961.78002,1.634201664,125.0697045
,44.7,11.12839374,0.206494587,77915.42195,1.649034247,126.1215855
,45,11.34815523,0.209482268,78450.82547,1.65121549,127.0836185
,45.3,11.60660156,0.212512735,80363.99238,1.632456613,128.4981802
,45.6,11.55716832,0.215609597,82732.9019,1.605408967,129.9784825
,45.9,11.89298401,0.218727703,84418.41285,1.589267598,131.2516977
,46.2,11.48823468,0.221941723,85817.2569,1.581851342,132.8032201
,46.5,11.84650155,0.225153784,86351.52499,1.586213836,134.01398
,46.8,11.74045608,0.228445099,86306.37582,1.601918934,135.272949
,47.1,12.02132324,0.231760441,86408.37156,1.615442735,136.5768442
,47.4,11.89778806,0.235152822,86267.94389,1.629839077,137.6024271
,47.7,12.12871387,0.238572831,85880.3259,1.650342921,138.7288171
,48,12.30804206,0.242048012,85496.69676,1.669538012,139.7894642
,48.3,12.46239929,0.245577319,85352.98158,1.683498076,140.7679329
,48.6,12.35048019,0.249177425,85588.40641,1.690914378,141.8274827
,48.9,12.91337505,0.252787501,85950.65803,1.694840601,142.7719863
,49.2,12.41535021,0.256522158,86048.29985,1.706183204,143.8644061
,49.5,13.33602489,0.260219448,86535.9561,1.707928132,144.8012412
,49.8,13.35470825,0.26403246,87229.49971,1.707491871,145.8969502
,50.1,13.64797119,0.267884875,88107.33404,1.702693079,146.9334922
,50.4,13.50271502,0.27182432,89422.5663,1.692223029,148.2187583
,50.7,14.98168323,0.275716245,91099.04992,1.676954066,149.5599124
,51,14.9312662,0.279767683,92798.462,1.661685235,150.9405057
,51.3,15.52487473,0.283837957,94373.26142,1.649033868,152.3112403
,51.6,14.95771215,0.288046358,95461.53129,1.644235135,153.6940228
,51.9,15.39819682,0.292251657,96785.16169,1.636382563,155.1721363
,52.2,15.74048512,0.296527026,97721.94261,1.634637521,156.5362951
,52.5,15.96959935,0.300874212,98867.93415,1.632019987,158.0407054
,52.8,15.62705944,0.305324664,99550.20545,1.637255044,159.4947097
,53.1,16.24556926,0.309778931,99432.22395,1.651651318,160.6211017
,53.4,16.13099976,0.31434902,99304.46634,1.668228918,161.9589617
,53.7,16.53480947,0.318953803,99074.83469,1.682625209,162.9648249
,54,16.37861359,0.323665287,99945.93267,1.681316467,164.2533774
,54.3,16.43042814,0.32843414,101170.7154,1.676517687,165.7720314
,54.6,16.56044741,0.333269861,102333.7974,1.669973891,167.0299054
,54.9,16.82442102,0.338170025,103203.5011,1.669973867,168.4411804
,55.2,16.73724221,0.343167256,103611.2622,1.676953913,169.8480702
,55.5,17.19132392,0.348204274,103513.5145,1.689387063,170.982132
,55.8,17.0841509,0.353354598,102828.0587,1.71054531,171.9967573
,56.1,17.36138968,0.358557209,102385.6401,1.727122873,172.9281121
,56.4,17.44931619,0.363850964,103076.0905,1.72799537,174.190369
,56.7,18.60770973,0.369154005,105025.3381,1.709236413,175.645477
,57,18.55041161,0.374617583,107599.3243,1.683061283,177.2912314
,57.3,19.15211313,0.380120204,109514.8969,1.667792399,178.8482378
,57.6,18.97912859,0.385757222,111116.026,1.659939875,180.4994701
,57.9,18.93135964,0.391470791,112043.768,1.659939879,181.8526714
,58.2,19.17896778,0.397251192,112396.2318,1.669537407,183.3083219
,58.5,19.52100386,0.403112851,112162.8181,1.684806206,184.5207264
,58.8,19.54600079,0.409084019,111499.2206,1.706182565,185.7084748
,59.1,19.72450336,0.415135405,110941.9843,1.724723269,186.810212
,59.4,19.57598131,0.421299787,111098.4184,1.732357698,187.957966
,59.7,20.14095886,0.427510205,111582.4648,1.735411411,189.1851637
,60,19.6529157,0.433883798,112291.965,1.735411458,190.438652
,60.3,19.91331929,0.44030433,112711.3789,1.739773956,191.5825744
,60.6,19.6573976,0.446856037,112996.7713,1.746754017,192.7560771
,60.9,20.64085343,0.453424803,113146.1913,1.755042717,193.8791851
,61.2,21.0771964,0.460129031,113800.3549,1.755478928,195.0000975
,61.5,21.86299601,0.466934517,114867.4325,1.750680079,196.2678377
,61.8,21.81878012,0.473851518,117366.1135,1.727558717,197.8434669
,62.1,22.14898292,0.480871672,120021.8227,1.702692311,199.3851324
,62.4,22.37016551,0.488004983,122250.7399,1.686550961,201.1656609
,62.7,22.66954715,0.495240671,123465.8408,1.683497168,202.7840256
,63,22.8133112,0.50259599,123329.1324,1.697020973,204.1974915
,63.3,22.80811408,0.510072209,123403.8758,1.706618522,205.5232997
,63.6,23.23641613,0.517632876,123638.5255,1.714907274,206.9586812
,63.9,24.32121635,0.525264302,123292.5447,1.72843099,208.0500141
,64.2,24.42413603,0.533075988,123954.5418,1.731920998,209.5631894
,64.5,25.31252665,0.540953891,124154.9727,1.738464696,210.6621914
,64.8,24.90201125,0.549036508,124782.2128,1.741082249,211.9901885
,65.1,25.20790296,0.557193905,125573.4894,1.740645968,213.254639
,65.4,25.20839934,0.565494617,125982.7361,1.746317246,214.6133185
,65.7,25.63323994,0.573892506,127309.8526,1.740645929,216.1056774
,66,25.71191239,0.582440067,128500.4379,1.736719653,217.5826942
,66.3,26.15335403,0.591092747,130169.5245,1.726685818,219.0805318
,66.6,26.08387378,0.59990995,132055.5862,1.715343266,220.8128481
,66.9,26.57519864,0.608823351,133678.7239,1.707490685,222.5265405
,67.2,26.57557108,0.617903744,134930.1221,1.702691909,224.1449035
,67.5,27.07850193,0.627088175,135704.3317,1.704873127,225.8333948
,67.8,27.2768671,0.636431341,135856.718,1.71228939,227.1230461
,68.1,27.87294711,0.645889576,136476.9135,1.717524362,228.7205944
,68.4,28.14865111,0.655511966,137020.9104,1.722759358,230.1439228
,68.7,28.78129705,0.665256174,138346.7539,1.719705539,231.8072139
,69,28.50528127,0.675207537,139975.4899,1.713598034,233.5252846
,69.3,29.30679346,0.685237996,140777.8071,1.71534297,235.0516133
,69.6,28.89676378,0.695500136,140686.9724,1.727994317,236.5352012
,69.9,29.57507844,0.705845339,139378.4871,1.752860622,237.7426776
,70.2,29.64095268,0.716387337,139109.0594,1.764639418,238.8975553
,70.5,30.40242578,0.727042638,139116.4784,1.773364386,240.1433828
,70.8,30.25190668,0.737919098,140657.3768,1.76463936,241.672992
,71.1,30.8161236,0.748912681,142245.4656,1.755041763,243.1116629
,71.4,30.94513298,0.760101137,144499.444,1.740209183,244.9404023
,71.7,31.44356174,0.771434546,146439.3271,1.729739089,246.7209349
,72,31.76223265,0.782950941,147691.5529,1.7275578,248.412712
,72.3,32.34131891,0.794624041,147873.8646,1.735846533,249.8623406
,72.6,32.47604309,0.806502813,147817.9416,1.747625323,251.3097738
,72.9,33.10083751,0.818528663,148678.5109,1.74893402,252.8832171
,73.2,33.17476188,0.83077322,149962.325,1.745443998,254.4719963
,73.5,34.87912965,0.843095133,150942.7735,1.745007584,256.0958507
,73.8,35.35530867,0.855684091,151341.4797,1.74980631,257.5011015
,74.1,36.01826075,0.868451079,152787.4154,1.744571225,259.1660375
,74.4,36.11245134,0.881448497,155374.7464,1.729084275,261.0966784
,74.7,36.74746662,0.894606636,158389.362,1.709671009,263.0886839
,75,36.7421601,0.90800587,161718.7374,1.689167173,265.4017267
,75.3,37.62590528,0.921548924,163405.584,1.68393207,267.4539981
,75.6,38.01660697,0.935329078,164312.5935,1.686549545,269.5029782
,75.9,38.42558145,0.94931625,164221.8488,1.698764559,271.3492526
,76.2,38.4771414,0.963538457,163512.2455,1.716214627,272.953372
,76.5,38.96717649,0.977946525,163667.9021,1.726248373,274.7130858
,76.8,39.45093633,0.992572634,165475.0699,1.719704551,276.7050898
,77.1,39.915107,1.007421086,168483.7415,1.701818185,278.7825596
,77.4,40.15624304,1.022508339,171958.608,1.683059337,281.3969248
,77.7,40.96440928,1.037786412,173477.6507,1.683059263,283.6902525
,78,41.07899528,1.053341137,173299.1328,1.695710554,285.3579234
,78.3,41.98111315,1.069078745,173038.6255,1.711415533,287.3981429
,78.6,41.77443889,1.085127354,173025.7194,1.721449343,289.0176004
,78.9,42.58744718,1.101351245,173453.6968,1.728429294,290.8945582
,79.2,42.55001598,1.117932228,174114.7074,1.733228067,292.6926175
,79.5,43.39457354,1.134594173,175475.6003,1.732791736,294.6857212
,79.8,43.92080933,1.151585092,176777.2143,1.732355435,296.6481418
,80.1,44.78607928,1.168809927,178198.2178,1.729301592,298.4473048
,80.4,45.35342121,1.186314336,179370.0047,1.729737791,300.5686046
,80.7,45.98479169,1.204078965,180925.4724,1.727120222,302.7172971
,81,46.3257216,1.222131244,181931.3331,1.728865197,304.7564166
,81.3,46.85049906,1.240444134,183007.8777,1.729737651,306.6991145
,81.6,46.73369457,1.259075998,183523.7798,1.735845185,308.6702964
,81.9,47.80589558,1.277910854,184349.6965,1.738026342,310.3741344
,82.2,47.47182678,1.29712318,186002.7748,1.736281367,312.626912
,82.5,48.28682198,1.316549779,188528.9953,1.726683756,314.9081876
,82.8,48.94117796,1.336280642,191322.5593,1.714032399,317.0897524
,83.1,49.80850046,1.356295217,194105.214,1.703562281,319.6482428
,83.4,50.48689153,1.376624239,195136.2618,1.706615979,322.0620991
,83.7,51.29753535,1.397251535,196326.3736,1.707488407,324.3510446
,84,51.60222172,1.418223755,197339.0474,1.708360879,326.3638677
,84.3,52.25134105,1.439490163,197520.1363,1.718394609,328.683492
,84.6,52.68073873,1.461092542,196670.9103,1.734535871,330.3062424
,84.9,53.33225132,1.48300647,195221.9961,1.756784636,331.9399523
,85.2,53.32969224,1.50529462,194793.2399,1.769872179,333.549551
,85.5,54.33639907,1.527852801,196671.9721,1.764200813,335.6357929
,85.8,55.11755657,1.550766723,198781.5366,1.756784462,337.8206467
,86.1,56.12831454,1.574011502,200874.9268,1.748931845,339.8466247
,86.4,56.16797325,1.597671845,202842.1039,1.745005573,342.2363694
,86.7,57.06462286,1.621632812,204494.0877,1.742824234,344.4880629
,87,57.45197878,1.645989682,205909.0491,1.742387949,346.718933
,87.3,57.94744725,1.670707342,206520.1333,1.747186664,348.6769724
,87.6,58.41706175,1.695799962,206117.393,1.76027416,350.5791303
,87.9,59.42164661,1.721236512,205400.6505,1.775542861,352.2972142
,88.2,59.38939246,1.747125764,205421.5976,1.783395388,353.8903764
,88.5,60.74166548,1.773315076,206954.4965,1.780341498,355.8911577
,88.8,60.85822947,1.799981265,210272.7578,1.764200189,358.2841904
,89.1,62.28276689,1.826963939,213513.3389,1.748931259,360.5238375
,89.4,62.67046169,1.854422826,218015.6907,1.727991162,363.4625371
,89.7,64.47929135,1.882202897,220584.9102,1.721447224,366.1240368
,90,64.54650079,1.910517622,222042.2002,1.721883469,368.6145878
,90.3,65.63211394,1.939192986,221499.3165,1.734970902,370.6854916
,90.6,66.46470433,1.96831888,222266.2015,1.739333335,372.9908758
,90.9,67.37252827,1.997880613,224137.863,1.735406989,375.1768282
,91.2,67.55761565,2.027936853,228859.0173,1.715775671,378.3642527
,91.5,68.37584724,2.058405404,233249.706,1.699634304,381.550588
,91.8,68.82289591,2.089358722,235187.387,1.698761761,384.4038237
,92.1,70.37238226,2.120706783,235243.6192,1.708359141,386.6610048
,92.4,70.12116238,2.15264739,232859.2442,1.734097977,388.8283179
,92.7,71.6164111,2.184955426,232643.222,1.745440362,391.1041257
,93,72.41304727,2.217797657,233389.8601,1.748930295,393.1322956
,93.3,73.81036939,2.251096712,235956.1448,1.743258899,395.9581497
,93.6,74.17208253,2.284967182,238183.87,1.739332606,398.6448366
,93.9,75.05584722,2.319314824,240178.4517,1.736278765,401.3085197
,94.2,75.56800376,2.354205984,242863.3857,1.7284262,403.9787728
,94.5,76.49695072,2.389596632,248471.6273,1.704432313,407.3886361
,94.8,77.04263783,2.42554745,252576.2512,1.691344735,410.4182836
,95.1,77.95435565,2.46201713,255669.3421,1.686982142,413.8796454
,95.4,78.67876688,2.499050321,255279.1902,1.700942103,416.4458092
,95.7,80.22934867,2.536588271,252403.0651,1.729734514,418.6909391
,96,80.70894802,2.574764299,250551.0834,1.751547009,420.8494955
,96.3,82.44823079,2.613434123,250179.6676,1.763325614,422.9620471
,96.6,82.9742422,2.652768306,252765.6084,1.756781802,425.6114829
,96.9,84.08134833,2.692793011,256731.1421,1.742385421,428.6323725
,97.2,84.27685315,2.73321371,260234.1476,1.730170383,431.5798385
,97.5,85.41707055,2.774318303,261825.8433,1.730170275,434.5415588
,97.8,85.89817903,2.816086066,261758.0524,1.740640246,437.1603162
,98.1,87.21459926,2.858429828,261976.5018,1.749365134,439.4021564
,98.4,88.09074545,2.901442277,262920.8014,1.755472559,442.0844694
,98.7,89.84047609,2.945047128,265376.1655,1.751546136,444.8949906
,99,90.35528983,2.989392274,267152.8275,1.750673586,447.7054976
,99.3,91.61387977,3.034358214,269946.3218,1.743257206,450.5357363
,99.6,92.42303653,3.080033291,271820.4849,1.741948378,453.4689661
,99.9,93.88110866,3.126355591,273273.3635,1.744129491,456.3276948
,100.2,94.89140856,3.173407322,274834.7141,1.745438146,458.9979578
,100.5,96.36173747,3.221139688,276340.8337,1.747183008,461.8906551
,100.8,97.0489614,3.269644102,280015.0871,1.736712932,465.1372588
,101.1,98.30687802,3.318843076,282455.9174,1.731914059,468.016804
,101.4,99.26346234,3.368804866,285183.144,1.727987715,471.4967975
,101.7,101.1119198,3.419462125,286761.5746,1.730605042,474.5889202
,102,101.8693946,3.470956811,288307.9176,1.733658722,477.6832213
,102.3,103.3664674,3.523180655,288925.7244,1.740638585,480.4049884
,102.6,103.8757323,3.576258759,289625.1548,1.74718229,483.2659006
,102.9,105.9367043,3.630036127,289752.1016,1.756343345,486.0578019
,103.2,106.6828561,3.68471309,291489.5088,1.755907022,488.8485904
,103.5,108.2168589,3.740163861,294615.7945,1.748926875,492.084249
,103.8,108.7721992,3.796516948,296531.996,1.748490575,495.1621117
,104.1,110.1827851,3.853665095,298412.6951,1.747617941,497.9540057
,104.4,111.5233388,3.911681151,300449.1837,1.747617809,501.1863752
,104.7,113.5860006,3.970526216,303975.4069,1.740201363,504.6357061
,105,114.4028935,4.030342512,307605.639,1.731476283,507.7584975
,105.3,115.9968077,4.091011129,310527.6235,1.729294883,511.5737902
,105.6,116.8591756,4.152644614,311093.5863,1.73758355,514.6867212
,105.9,118.4220088,4.215163158,311879.1034,1.7428184,517.3767171
,106.2,119.5611619,4.278654173,313842.6481,1.744563291,520.9235559
,106.5,121.3525148,4.343061426,317269.0332,1.736710623,524.0803281
,106.8,122.0312191,4.408515062,320181.3451,1.73278431,527.6556486
,107.1,124.4396648,4.474843476,322539.7797,1.732784081,531.4753376
,107.4,125.477512,4.542264522,324280.4188,1.733656482,534.4030974
,107.7,126.9495439,4.610675598,324846.9131,1.742381337,537.6825873
,108,128.611958,4.680108363,325907.8169,1.747616174,540.8305946
,108.3,130.2284403,4.750595919,327231.4423,1.751978515,544.2843053
,108.6,131.2265164,4.8221894,329558.4177,1.750233421,547.6481593
,108.9,133.5674003,4.894775846,332723.6383,1.744561952,551.2443239
,109.2,134.5380873,4.968549756,335322.5817,1.741944362,554.7155574
,109.5,136.4442728,5.043376283,341363.2667,1.726239199,558.92422
,109.8,138.3556868,5.119333184,345306.1663,1.719259027,562.4305322
,110.1,140.0014843,5.196455092,348363.8124,1.717950124,566.4627817
,110.4,141.5102191,5.274751331,348905.4353,1.726674969,570.2956104
,110.7,143.4718339,5.354200688,349203.9685,1.734309146,573.6096255
,111,144.5604046,5.434908126,352172.9103,1.730600923,577.3060322
,111.3,146.7396396,5.516763216,354366.5324,1.732127589,581.1936571
,111.6,147.7117444,5.599934506,356813.5792,1.731909371,584.8610261
,111.9,150.130222,5.684267063,358447.3527,1.736271633,588.6281279
,112.2,151.6099095,5.769935945,360435.685,1.739325236,592.5771034
,112.5,153.4139028,5.856877668,363299.794,1.737143818,596.0724585
,112.8,154.8336818,5.945158278,365803.5976,1.737579932,599.9250118
,113.1,157.0337403,6.034720908,370566.3995,1.727545995,603.8575638
,113.4,158.5479491,6.12568227,373502.962,1.726673354,608.2820819
,113.7,160.5308167,6.217986921,378200.2294,1.718384437,612.8994524
,114,162.1781339,6.311708631,380110.6702,1.721001774,617.0336102
,114.3,164.1892356,6.406982346,383782.8915,1.716639096,621.2280353
,114.6,166.1651604,6.503700697,388496.9635,1.709658929,625.9330658
,114.9,168.3210232,6.601709881,392884.1986,1.704423742,630.6391944
,115.2,169.8630454,6.700901242,398510.9617,1.694826127,635.3748985
,115.5,172.2501691,6.801870264,402218.8711,1.69308091,640.3155133
,115.8,174.2168498,6.90439242,402948.8832,1.701805698,644.7641507
,116.1,176.6267825,7.008434343,402634.8774,1.712275437,648.4753757
,116.4,178.3849467,7.114091291,398313.5448,1.738886429,652.1460534
,116.7,180.3799996,7.221329065,399907.7211,1.742812474,656.3152797
,117,182.6776717,7.330167136,400348.4466,1.750664725,660.0473273
,117.3,184.9459593,7.440651361,404064.6756,1.746302023,664.2297096
,117.6,187.0101219,7.552818399,407471.2607,1.743684335,668.5808329
,117.9,189.233774,7.666669654,409647.7427,1.746301611,672.6898007
,118.2,191.473794,7.78224001,412196.8787,1.747173892,676.6114099
,118.5,194.1595306,7.899526248,411749.712,1.759824829,680.2503263
,118.8,196.0520144,8.018634315,412046.4186,1.768549607,683.8344475
,119.1,198.291189,8.139517927,413556.0028,1.771166877,687.2980428
,119.4,200.4551861,8.262232167,419370.0399,1.759387973,692.0074694
,119.7,203.2296338,8.38675997,426474.8739,1.744119027,697.0762994
,120,205.281538,8.513216712,429818.1221,1.741065095,701.0548833
,120.3,207.9347309,8.641544293,429426.0933,1.753279777,705.341371
,120.6,210.1457817,8.771839814,427797.968,1.768111988,708.881672
,120.9,212.7176412,8.904080039,427887.1699,1.775964191,712.0001291
,121.2,214.8897854,9.038344503,434765.3177,1.762440304,716.9560931
,121.5,217.6116103,9.17460124,443782.6654,1.741936402,722.227635
,121.8,219.9636651,9.312940882,450348.1655,1.730157498,727.4739686
,122.1,222.6823335,9.453346643,451918.6099,1.733647217,731.7221137
,122.4,225.1252466,9.595891759,452380.0761,1.74149944,736.3756685
,122.7,228.2243262,9.740547249,453319.0284,1.747606603,740.6829915
,123,230.085759,9.887469879,456085.8751,1.746733934,744.7295089
,123.3,233.2823225,10.03652409,456821.0176,1.75458607,749.44444
,123.6,235.5574183,10.18789117,457152.3005,1.762002051,753.0702148
,123.9,238.488659,10.34150177,461116.6059,1.759384284,757.6974825
,124.2,240.864535,10.49747005,467934.7998,1.748914126,763.1542025
,124.5,243.9414768,10.65574818,474272.5741,1.738443903,767.9403567
,124.8,246.593679,10.81644587,479867.9383,1.7314637,773.3937953
,125.1,249.95692,10.97952447,482817.5147,1.731899625,778.024364
,125.4,252.6848947,11.14510878,487284.1169,1.729281884,783.6016237
,125.7,255.4012843,11.20297988,489486.3329,1.733207846,788.6321165
,126,257.0726605,11.20287079,491524.1377,1.737570154,793.6516333
,126.3,258.6200573,11.20276984,491945.2344,1.746294938,798.0717863
,126.6,259.224296,11.20273072,493039.9984,1.753274826,802.6464188
,126.9,260.5445359,11.20264466,496291.019,1.754147193,807.5486822
,127.2,260.7285764,11.2026331,503124.5964,1.74367726,812.7248531
,127.5,261.662317,11.20257238,510783.1271,1.732334763,818.5135451
,127.8,261.6811904,11.20257164,516677.0997,1.727099804,824.4161728
,128.1,262.8554009,11.20249515,519308.996,1.729280926,829.1891404
,128.4,262.849728,11.20249602,516184.7768,1.748475771,833.8678528
,128.7,263.3678468,11.20246256,511865.6722,1.769851797,837.9088661
,129,263.4204192,11.20245961,509864.114,1.782066693,841.2792943
,129.3,264.3687211,11.20239793,510743.3756,1.787301558,845.8561233
,129.6,264.2120265,11.20240871,512618.3915,1.789482806,849.9206847
,129.9,264.8899037,11.20236476,515400.0371,1.789918987,854.0838735
,130.2,264.6799563,11.20237903,513731.7201,1.805187632,857.9046347
,130.5,265.0270835,11.20235677,514000.6315,1.812603788,861.1128992
,130.8,264.8570758,11.20236842,512258.0811,1.826127444,864.3178695
,131.1,265.6772379,11.20231515,511372.456,1.835724783,867.1546971
,131.4,265.5550745,11.20232366,512003.7487,1.840523506,870.4955379
,131.7,266.2774677,11.20227679,509137.9615,1.854919564,873.0430942
,132,265.8191458,11.20230734,506062.9934,1.869315742,875.2575307
,132.3,266.452923,11.20226629,499728.7131,1.893309228,876.3707906
,132.6,266.2770907,11.20227832,495956.5915,1.909886609,877.5596421
,132.9,266.6583329,11.20225383,498472.7505,1.905960353,879.7587513
,133.2,266.8115865,11.20224428,503620.9733,1.89374544,882.4432637
,133.5,267.5173382,11.20219851,507393.8801,1.886329179,885.2724186
,133.8,266.8435087,11.20224319,507431.9806,1.890691713,887.4616491
,134.1,267.5750548,11.20219572,507015.9788,1.895926594,889.3002754
,134.4,267.316431,11.20221318,509842.9744,1.891564159,891.9234195
,134.7,267.6960091,11.2021888,514015.0581,1.88327544,894.8237867
,135,267.4806532,11.20220342,515472.8418,1.883711709,897.4721344
,135.3,267.8510784,11.20217963,513081.9732,1.89461783,899.1409151
Unloading Marker,135.506,268.0060984,11.20216981,512425.1275,1.898980278,900.529197
,136.4,267.7233714,11.00405272,1.7977E+308,1.647266175,0
,136.7,267.3741159,10.8361633,1.7977E+308,1.30437658,0
,137,267.4200962,10.66824797,1.7977E+308,0.81098196,0
,137.3,267.129086,10.50035473,1.7977E+308,0.398292923,0
,137.6,266.5842927,10.33247813,1.7977E+308,0.169699837,0
,137.9,266.2142353,10.16459008,1.7977E+308,0.039262174,0
,138.2,266.2285968,9.99667682,1.7977E+308,0.035772203,0
,138.5,265.5148921,9.828811298,1.7977E+308,0.018758595,0
,138.8,265.20308,9.660919425,1.7977E+308,0.005234957,0
,139.1,265.2590452,9.493003439,1.7977E+308,0.024866045,0
,139.4,264.6626632,9.325130224,1.7977E+308,0.03533596,0
,139.7,264.2551623,9.157244625,1.7977E+308,0.037080947,0
,140,264.1779955,8.989337368,1.7977E+308,0.0244298,0
,140.3,263.4093737,8.821475446,1.7977E+308,0.028356019,0
,140.6,263.2806182,8.653571571,1.7977E+308,0.057148286,0
,140.9,263.1942985,8.485664914,1.7977E+308,0.068054448,0
,141.2,262.4964032,8.317798355,1.7977E+308,0.059329521,0
,141.5,262.3634872,8.149894753,1.7977E+308,0.050604592,0
,141.8,261.8178617,7.98201821,1.7977E+308,0.048859607,0
,142.1,261.3279853,7.814138012,1.7977E+308,0.034027228,0
,142.4,261.2108787,7.646233374,1.7977E+308,0.019194846,0
,142.7,261.0155571,7.478333863,1.7977E+308,0.010906163,0
,143,260.4603627,7.310457948,1.7977E+308,0.012214903,0
,143.3,260.2001391,7.142562693,1.7977E+308,0.006543698,0
,143.6,259.582539,6.974690869,1.7977E+308,0.007416191,0
,143.9,259.3630871,6.806792941,1.7977E+308,0.006543698,0
,144.2,258.8029002,6.638917353,1.7977E+308,0.011342411,0
,144.5,258.5326917,6.471022752,1.7977E+308,0.019631096,0
,144.8,258.1347595,6.303136526,1.7977E+308,0.025084179,0
,145.1,257.8083859,6.135245608,1.7977E+308,0.029664769,0
,145.4,257.7590935,5.967336523,1.7977E+308,0.025302303,0
,145.7,257.3944444,5.799448115,1.7977E+308,0.028792276,0
,146,257.0643264,5.631557442,1.7977E+308,0.041443429,0
,146.3,256.423428,5.463687146,1.7977E+308,0.040570937,0
,146.6,256.1066231,5.295795601,1.7977E+308,0.041007185,0
,146.9,256.0756365,5.127885316,1.7977E+308,0.036208472,0
,147.2,255.4621965,4.960013219,1.7977E+308,0.033590993,0
,147.5,254.9656633,4.792133458,1.7977E+308,0.01832236,0
,147.8,254.6488584,4.624241913,1.7977E+308,0.00523496,0
,148.1,254.3345498,4.456350204,1.7977E+308,0.004362467,0
,148.4,253.8771241,4.288467878,1.7977E+308,0.006543701,0
,148.7,253.3019596,4.120593272,1.7977E+308,0.028792283,0
,149,252.802098,3.952713729,1.7977E+308,0.048423387,0
,149.3,252.5314733,3.784819156,1.7977E+308,0.047114648,0
,149.6,252.1734807,3.616930311,1.7977E+308,0.042315934,0
,149.9,251.5343352,3.448500191,1.7977E+308,0.033591001,0
,150.2,251.4305418,3.280594679,1.7977E+308,0.037517222,0
,150.5,250.7175796,3.113288817,1.7977E+308,0.040134704,0
,150.8,250.1711216,2.945412329,1.7977E+308,0.043188433,0
,151.1,249.8193695,2.777523075,1.7977E+308,0.043624681,0
,151.4,249.3694323,2.609640259,1.7977E+308,0.032282265,0
,151.7,248.8887083,2.441759461,1.7977E+308,0.010033677,0
,152,248.5161542,2.273871571,1.7977E+308,0.014396146,0
,152.3,247.6435222,2.106016468,1.7977E+308,0.035772243,0
,152.6,247.3932833,1.938120559,1.7977E+308,0.04318844,0
,152.9,247.2695201,1.770216356,1.7977E+308,0.032718515,0
,153.2,246.30952,1.602366982,1.7977E+308,0.019194863,0
,153.5,245.7056485,1.434494259,1.7977E+308,0.021376099,0
,153.8,245.2265886,1.266613352,1.7977E+308,0.026174815,0
,154.05,244.9764523,1.126702821,1.7977E+308,0.032282273,0
,229.4,244.448347,0.938241202,1.7977E+308,0.01744988,0
,229.7,243.6206468,0.770383154,1.7977E+308,0.015704892,0
,230,242.6856087,0.602532143,1.7977E+308,0.010906176,0
,230.3,241.8237932,0.434676331,1.7977E+308,0.012214918,0
,230.6,240.7631114,0.266833559,1.7977E+308,0.01352366,0
,230.9,238.788809,0.099050688,1.7977E+308,0.023121098,0
,231.064,237.2811315,0.007357473,1.7977E+308,0.025302336,0
END,,,,,,