File: GB1_test 10.csv
Segment,Time On Sample,Displacement Into Surface,Load On Sample,Harmonic Contact Stiffness,Harmonic Displacement,Harmonic Load
Surface Marker,0,0,0,178.0060938,0.729742664,2.135691297
,0.3,0.127186014,0.000974764,1988.294274,0.452327039,2.229929091
,0.6,0.124585593,0.001958028,5463.598435,0.306640221,2.335124763
,0.9,0.168575252,0.002937757,12698.94681,0.193231319,2.471002506
,1.2,0.398092986,0.003905122,17665.48558,0.152229638,2.586060295
,1.5,0.431267142,0.004885346,21515.89098,0.135654491,2.797547428
,1.8,0.503543619,0.005863009,24974.00242,0.130420233,3.137241801
,2.1,0.786307064,0.006826888,25579.24963,0.138271616,3.428721502
,2.4,0.75375604,0.007811416,24847.35073,0.153102011,3.725680123
,2.7,0.79192198,0.008791314,27334.95823,0.161389584,4.386440455
,3,0.553875773,0.0097893,30308.16358,0.167932407,5.134863811
,3.3,0.81001636,0.010754922,32890.93539,0.170985721,5.76165474
,3.6,0.725051585,0.011742883,35737.52156,0.185379928,6.707320004
,3.9,1.156736633,0.012697009,37563.6752,0.204572197,7.662847468
,4.2,0.772264716,0.013704585,37339.09595,0.239467247,8.76959354
,4.5,1.28132244,0.014653644,37686.01036,0.269564216,9.927841877
,4.8,1.077386775,0.015649396,37933.1492,0.301405947,11.18251941
,5.1,1.170462357,0.016625698,37104.16244,0.341971435,12.46020856
,5.4,1.006460977,0.017618835,34852.10731,0.398675885,13.71488611
,5.7,1.500543337,0.018568875,32969.18343,0.467157397,15.24241516
,6,0.970477678,0.019585986,31925.23027,0.526478988,16.59133033
,6.3,1.160061117,0.020555967,30662.26128,0.592779566,17.88326475
,6.6,1.183251699,0.021536845,30128.81184,0.648175448,19.11602667
,6.9,1.269671567,0.022513582,29305.77942,0.712295089,20.37947053
,7.2,0.80533108,0.023526389,28024.97042,0.794734652,21.71961937
,7.5,1.561066207,0.024459293,26401.971,0.880227474,22.68281769
,7.8,0.946972157,0.025481907,24185.77607,0.997125905,23.55396907
,8.1,1.717682635,0.02641383,22129.96493,1.124492769,24.30677602
,8.4,1.461749209,0.027412988,20905.89031,1.220890344,24.90288477
,8.7,1.689602998,0.028380463,20388.35091,1.288063287,25.61405142
,9,1.278508236,0.029389783,20795.87778,1.302457523,26.41616828
,9.3,1.812940854,0.03033718,21347.63552,1.307691739,27.236914
,9.6,1.645611623,0.031330536,21824.59058,1.31248982,27.95136794
,9.9,1.740767113,0.032306702,22431.43408,1.312926001,28.73595237
,10.2,1.608796361,0.033297742,22924.74434,1.314234575,29.4021916
,10.5,2.008034782,0.034253993,23479.49529,1.319032614,30.23060776
,10.8,2.366506947,0.035212914,23172.78141,1.358289509,30.75987399
,11.1,2.492029127,0.036187092,22856.29243,1.400163549,31.33187551
,11.4,2.407064359,0.037175054,22934.66674,1.419792017,31.95976221
,11.7,2.344562626,0.038161545,23836.26049,1.39362074,32.62600136
,12,2.628158005,0.03912537,24947.61604,1.363087556,33.39414938
,12.3,2.639701087,0.040107012,25633.4193,1.356980923,34.1403811
,12.6,2.774374871,0.04108059,25697.13251,1.377045562,34.74196915
,12.9,2.929847758,0.042052806,25653.21342,1.403653018,35.3665685
,13.2,2.814932282,0.04304273,25936.92229,1.414557728,36.00103001
,13.5,2.877225179,0.044021048,26405.00242,1.415866287,36.60590505
,13.8,2.652490428,0.045018164,26886.20136,1.418047245,37.24803697
,14.1,3.036753469,0.045975397,26983.66005,1.43636711,37.84524184
,14.4,2.628986075,0.046987774,27066.38557,1.455995605,38.45011668
,14.7,3.399280496,0.047919726,27026.01971,1.479549692,38.9848621
,15,3.319308039,0.048904087,27557.4319,1.474751631,39.57768364
,15.3,3.64034179,0.049865461,28373.15801,1.457304084,40.24282738
,15.6,3.448885615,0.050860398,29442.00402,1.427643316,40.91673716
,15.9,3.462092625,0.051841932,30586.86087,1.398418719,41.6837889
,16.2,3.377959826,0.05282984,31530.56505,1.379662642,42.44536188
,16.5,3.413629868,0.053809903,32375.5995,1.368757939,43.29021453
,16.8,3.330329034,0.054797756,32871.12059,1.370938886,44.03096752
,17.1,3.676321709,0.055757496,33033.96123,1.38795019,44.73994286
,17.4,3.516480173,0.056750362,32968.03377,1.409323415,45.30427382
,17.7,3.552150215,0.057730425,32697.25156,1.442037512,45.95188463
,18,3.770852371,0.058698501,32644.61145,1.462102141,46.56881389
,18.3,3.89637454,0.059672679,32680.90101,1.478241086,47.19889221
,18.6,3.906253693,0.060654431,33047.83428,1.483039153,47.91444225
,18.9,4.176537621,0.061619128,33233.66867,1.494816206,48.54780801
,19.2,3.688902215,0.062633462,33403.22248,1.507029512,49.16144908
,19.5,4.143882185,0.063586065,33373.13451,1.524476987,49.69400258
,19.8,3.948266195,0.064581274,33489.48395,1.537562651,50.27257884
,20.1,3.978112487,0.065561719,33834.86838,1.541052149,50.89498647
,20.4,4.136081256,0.066533772,34169.27263,1.545850206,51.51739475
,20.7,4.294049853,0.067506895,34705.1793,1.542796872,52.1967836
,21,4.460336197,0.068491384,34822.22476,1.554573939,52.77426432
,21.3,4.865393856,0.069475225,34891.83254,1.568095721,53.33750015
,21.6,4.136482017,0.070548484,35104.02394,1.574202425,53.88539325
,21.9,4.455010534,0.071568692,35349.11251,1.582053772,54.5297173
,22.2,4.32427593,0.072634011,35818.40282,1.578128098,55.13568807
,22.5,4.802536562,0.073675156,36068.48465,1.582053745,55.67810406
,22.8,4.674292777,0.07477224,36423.08248,1.582926133,56.2972243
,23.1,4.8771681,0.075864035,36886.27368,1.579000423,56.9174407
,23.4,4.760566583,0.076993264,37364.92746,1.576383306,57.55628541
,23.7,4.829490369,0.078127272,37855.39155,1.575074736,58.23676995
,24,5.038181388,0.079269333,38163.07082,1.579872784,58.85808256
,24.3,5.111259465,0.080437854,38410.12702,1.585979409,59.4651491
,24.6,4.759617088,0.08165169,38726.03685,1.588596569,60.05906607
,24.9,5.230784352,0.082829571,39345.77413,1.580308955,60.72859335
,25.2,4.995195216,0.084072005,40070.61669,1.568968089,61.43647255
,25.5,5.507954846,0.085283847,40900.58136,1.555882405,62.24954814
,25.8,5.270695874,0.086563582,41508.9566,1.551084359,62.98810932
,26.1,5.582946161,0.087826275,42302.40259,1.541488196,63.75516159
,26.4,5.435949189,0.089138489,42977.07393,1.53494539,64.4378377
,26.7,5.487788519,0.090457255,43836.38954,1.525785438,65.29912721
,27,5.40401454,0.091804809,44509.04904,1.520987378,66.11658552
,27.3,5.695453132,0.093148081,44935.98906,1.523604481,66.91760714
,27.6,5.768913893,0.094526033,44881.82297,1.541924368,67.6978089
,27.9,6.024571455,0.095912979,44481.35118,1.570712748,68.34651574
,28.2,5.573472183,0.097367407,43891.13176,1.604735449,68.91632534
,28.5,6.015066913,0.098784948,43320.2842,1.636577127,69.4094306
,28.8,5.957479775,0.100256799,43253.36034,1.651843711,69.96828284
,29.1,5.968110162,0.101746362,43899.24286,1.642247575,70.64438396
,29.4,6.075244831,0.103251925,45526.28654,1.603863027,71.52539854
,29.7,6.442780614,0.104763251,47206.04079,1.567223208,72.49955478
,30,6.138917761,0.106341578,48198.31086,1.553265221,73.37947273
,30.3,6.674502883,0.107888397,48224.54465,1.56853175,74.13885466
,30.6,6.291595919,0.109519289,47698.16354,1.59906494,74.71743059
,30.9,6.647469146,0.111126092,47461.43391,1.621310491,75.34203029
,31.2,6.460897943,0.112792872,47364.90553,1.639194213,75.97320457
,31.5,6.771005312,0.114451961,47680.05868,1.644428439,76.67560529
,31.8,6.538667187,0.116177743,47675.69826,1.658386475,77.30458772
,32.1,6.747267721,0.117888927,47915.97692,1.66362071,77.94233655
,32.4,6.757854833,0.119650735,48084.69192,1.668418776,78.49899752
,32.7,7.234339456,0.121396682,48700.89215,1.661439724,79.25180485
,33,7.462893608,0.123191546,49284.3441,1.655333071,79.97064308
,33.3,7.473468869,0.125027904,49792.7394,1.652279755,80.68071366
,33.6,7.518982236,0.126889541,50320.80577,1.651407375,81.45872396
,33.9,7.686789819,0.128771393,50888.73104,1.648354044,82.18304007
,34.2,7.462737848,0.130707374,51335.91568,1.648790253,82.90406876
,34.5,7.577290585,0.132650295,51640.53397,1.651843557,83.5670206
,34.8,7.577859603,0.134629963,51788.20377,1.659694939,84.24312263
,35.1,7.845484323,0.136621898,51871.98456,1.669291047,84.91045791
,35.4,7.994965358,0.138651779,52179.10747,1.672780536,85.5986139
,35.7,8.183543815,0.140709803,52541.15612,1.675397645,86.31306799
,36,8.095073307,0.142817249,53049.53655,1.673652902,87.02971398
,36.3,8.186301994,0.144944487,53042.22395,1.68673853,87.66527111
,36.6,8.330771251,0.147100457,52925.86885,1.702005092,88.22302816
,36.9,8.715672925,0.149273108,53072.51108,1.709856435,88.82899964
,37.2,8.497395477,0.151518466,53678.63369,1.703749832,89.51167585
,37.5,8.808241743,0.15376276,54564.96015,1.688919405,90.23927997
,37.8,8.574978204,0.156076673,55561.48252,1.673216673,91.05345047
,38.1,9.190312319,0.158369832,56069.23538,1.671035666,91.79639643
,38.4,8.959533564,0.160753495,56945.03944,1.661003377,92.62262038
,38.7,9.283669074,0.163136388,57555.58052,1.658822397,93.48062363
,39,9.378176783,0.165570583,58100.13831,1.657513834,94.28383687
,39.3,9.410281353,0.168045648,57875.56662,1.674525145,94.96322584
,39.6,9.348368071,0.170564205,57743.34997,1.688046983,95.59768724
,39.9,9.84885634,0.173083848,58053.15729,1.690227867,96.32638795
,40.2,9.771123619,0.175679728,58781.97876,1.685429815,97.18767754
,40.5,10.20337855,0.178281164,59401.36643,1.681940263,97.92076125
,40.8,9.761233154,0.180979584,59901.44452,1.681940311,98.67466272
,41.1,10.54456413,0.183637874,60344.00862,1.682812611,99.44609954
,41.4,10.14150819,0.186414638,61211.8646,1.673216518,100.3194426
,41.7,10.82415848,0.189161606,61888.07277,1.669726949,101.2103201
,42,10.3836509,0.192024316,62348.69377,1.670599367,101.9927123
,42.3,11.0529763,0.194856802,62773.78306,1.672780242,102.8057889
,42.6,10.98059907,0.197781242,63221.08995,1.674961188,103.692282
,42.9,11.04548885,0.200740831,63961.50999,1.66929074,104.5601463
,43.2,10.80836866,0.203764875,64454.77475,1.669726951,105.4126697
,43.5,11.22391687,0.206791512,65011.49671,1.668854535,106.2246497
,43.8,11.34244671,0.20988351,65268.58911,1.675397341,107.0388215
,44.1,11.81621764,0.212999036,65316.66848,1.686738178,107.808066
,44.4,11.44137798,0.216217523,65439.93335,1.695898158,108.6047036
,44.7,11.51204728,0.219454975,65594.90483,1.702440968,109.3761384
,45,11.69543989,0.222733972,65796.90761,1.705930452,110.1716822
,45.3,12.1774996,0.226042975,66150.12341,1.705494217,110.9891413
,45.6,12.02393099,0.229444061,66455.53847,1.708547547,111.7507146
,45.9,12.32710236,0.232866245,67347.80131,1.702877076,112.64707
,46.2,12.20929183,0.236367936,68342.25914,1.69458952,113.5598621
,46.5,12.45753695,0.239898406,69270.8697,1.686301928,114.4408764
,46.8,12.20825926,0.243514898,69978.63947,1.68281245,115.3821588
,47.1,12.94651391,0.247120936,70213.29816,1.688919007,116.265366
,47.4,12.94015225,0.250830855,70311.58685,1.696770387,117.0083113
,47.7,13.23328867,0.254576935,70605.80909,1.702876987,117.9090499
,48,13.23689268,0.258398797,71228.81965,1.699823672,118.6881564
,48.3,13.07076692,0.262289476,72069.11438,1.694153248,119.6546408
,48.6,13.23908128,0.26621671,72546.92823,1.69633417,120.6222232
,48.9,13.58293053,0.270191903,72332.71097,1.710292144,121.3147624
,49.2,13.72293912,0.274240502,72384.74795,1.719452073,122.1278386
,49.5,14.06843301,0.278336868,72673.79208,1.72294154,122.8937955
,49.8,13.69343647,0.282542613,74154.06362,1.703313129,123.9304107
,50.1,14.53059872,0.286746181,75452.58642,1.68935504,124.9944237
,50.4,14.49336153,0.291042389,76447.41398,1.681067477,125.9565269
,50.7,14.67575013,0.295403629,76458.53762,1.693716903,126.9076713
,51,14.8206899,0.299833115,76072.31811,1.713345336,127.7108857
,51.3,14.76761167,0.304342626,76232.73373,1.720760532,128.5469715
,51.6,14.93416103,0.308905701,76771.3459,1.71988814,129.4071672
,51.9,15.36110405,0.313520608,77934.71639,1.706802467,130.4613165
,52.2,15.39867697,0.318231086,78898.13811,1.698514897,131.5220408
,52.5,15.71827424,0.32299415,79509.8354,1.69764249,132.4545574
,52.8,15.23917499,0.327881739,80361.88144,1.693716848,133.51528
,53.1,15.57871626,0.332788995,81160.30727,1.691099689,134.5266935
,53.4,15.92406947,0.337770138,82001.47929,1.68630159,135.5205759
,53.7,16.36259063,0.342820428,82145.29908,1.696333864,136.5615761
,54,16.4416914,0.347970601,82161.213,1.705929985,137.3812271
,54.3,16.73542639,0.353184513,82371.24933,1.713345147,138.3225099
,54.6,16.6356301,0.358502957,83413.465,1.706366158,139.4687054
,54.9,17.02418366,0.36386965,84361.28905,1.700695676,140.5414835
,55.2,17.0499882,0.36934134,84527.55619,1.70767468,141.3830502
,55.5,17.1448326,0.374891049,84316.29567,1.723377415,142.3473437
,55.8,17.46762166,0.380509701,83993.39573,1.739516333,143.1768579
,56.1,17.70803283,0.386218685,84510.59743,1.738643931,143.9910296
,56.4,17.65890698,0.392032963,85636.00659,1.728611629,145.118596
,56.7,18.28532155,0.397890579,86755.81742,1.718143048,146.1059043
,57,18.1945695,0.40388392,87892.94331,1.709419317,147.2488116
,57.3,18.29515465,0.409955308,88867.87862,1.704621234,148.3544629
,57.6,18.81919465,0.416090396,90381.40339,1.690663188,149.5313423
,57.9,18.8665048,0.422349822,91662.04436,1.681503234,150.8079365
,58.2,19.06022553,0.428693957,92932.88362,1.672779469,152.1371299
,58.5,19.53180679,0.43511571,92941.70563,1.683247923,153.1595021
,58.8,19.24295804,0.441684574,92532.62297,1.702440208,154.178585
,59.1,19.48821406,0.448317442,91817.45779,1.726430502,155.0683659
,59.4,20.05791987,0.455029208,91600.68276,1.739516079,155.8661028
,59.7,20.02235617,0.461882203,92320.39659,1.737771326,156.9531249
,60,20.46390706,0.468807118,93685.24048,1.72555803,158.160687
,60.3,20.46034087,0.475866132,94562.34005,1.720759967,159.1753866
,60.6,20.40226416,0.483035157,95298.76248,1.719015222,160.2547391
,60.9,21.00350124,0.490269004,95858.51512,1.720759913,161.3779246
,61.2,21.06976843,0.497647657,97256.5527,1.708982842,162.6687649
,61.5,21.58028637,0.50510834,99442.7281,1.685864852,164.0439816
,61.8,21.76465672,0.512703374,101556.8005,1.666236395,165.5978118
,62.1,21.77596045,0.520424611,102667.252,1.662310706,167.0234325
,62.4,22.0538899,0.528244869,102952.6485,1.669289679,168.1915458
,62.7,22.33388047,0.536183138,103032.8702,1.681502903,169.5075886
,63,22.67167346,0.544237254,103535.1814,1.687173308,170.7798022
,63.3,22.69371706,0.552433705,104475.0786,1.685864743,172.119951
,63.6,22.77231449,0.560750247,105129.7759,1.688045673,173.3757263
,63.9,23.40414752,0.569155993,106672.1472,1.678013299,174.8879175
,64.2,23.01430946,0.577756044,107603.3631,1.676268587,176.3146336
,64.5,23.33827527,0.586438762,107944.0682,1.683247555,177.6021865
,64.8,23.85939546,0.595240015,106861.9945,1.710727316,178.6815418
,65.1,23.99446356,0.604199655,106272.0379,1.730791927,179.7214455
,65.4,24.40322605,0.613276555,106240.6321,1.740824198,180.6901259
,65.7,24.53492299,0.622508877,107126.9014,1.738643247,181.9776777
,66,24.91119495,0.631864479,107908.8702,1.735589897,183.0208718
,66.3,25.13186729,0.641371827,108516.98,1.73646225,184.2503473
,66.6,25.25184926,0.651029396,109807.8236,1.727302301,185.5488589
,66.9,25.44668472,0.660827983,111153.9036,1.718142345,186.9635225
,67.2,25.49923096,0.670783875,112911.0054,1.704620529,188.4833831
,67.5,26.2281393,0.680845763,114114.7077,1.698950021,189.8596968
,67.8,26.06265761,0.691153147,115324.9205,1.694588163,191.3970892
,68.1,26.69251889,0.701494771,116917.3444,1.685864353,192.9925604
,68.4,26.83315546,0.712059869,118212.778,1.681066278,194.4390037
,68.7,26.91220141,0.722788459,118529.4012,1.691534768,195.9544794
,69,27.46793642,0.733647849,117890.8448,1.710726959,197.0141114
,69.3,27.90550658,0.744679107,116171.2387,1.743440969,197.923618
,69.6,28.21076812,0.7558857,115991.975,1.754345623,198.9657158
,69.9,28.24062298,0.767279761,117357.9013,1.745185685,200.3453134
,70.2,28.59408411,0.778824533,119329.8249,1.729919091,201.8410687
,70.5,29.21790544,0.790526164,120841.5622,1.721631469,203.2853212
,70.8,29.25100493,0.802443559,121134.6934,1.729919025,204.6101313
,71.1,29.66761074,0.814515622,121415.5785,1.736897981,205.8582367
,71.4,29.99683144,0.826775905,121978.7853,1.739515072,207.0449794
,71.7,30.20206025,0.83922931,123174.8191,1.735153178,208.529774
,72,30.35318156,0.851874383,123981.7074,1.734716975,209.9159494
,72.3,30.93356541,0.864681979,124036.5604,1.743004476,211.1936414
,72.6,31.76433932,0.877666473,123960.5206,1.752600516,212.3365558
,72.9,31.73982421,0.890903475,124961.1141,1.750419571,213.7227273
,73.2,32.14789798,0.904312064,126274.8252,1.744749108,215.1560237
,73.5,32.47357523,0.917928582,127601.1511,1.738206256,216.5564437
,73.8,32.97725979,0.931739193,128878.7039,1.733408153,218.0971265
,74.1,33.20719543,0.945776423,129970.9031,1.729482433,219.3879676
,74.4,33.49699869,0.960021715,131904.6457,1.718577737,221.100688
,74.7,33.7468335,0.974484961,133154.4654,1.714652018,222.570143
,75,34.22292743,0.989151919,134073.0456,1.715524351,224.1831478
,75.3,34.19481672,1.004073561,134734.9741,1.718577658,225.7369768
,75.6,34.87134263,1.019174093,135554.0476,1.718577594,227.2086261
,75.9,35.72337636,1.034491285,136354.6618,1.719449879,228.8490282
,76.2,35.80497583,1.050090778,136429.8259,1.727737432,230.2965669
,76.5,36.61034531,1.065878441,136558.2991,1.73558872,231.6465841
,76.8,36.63030418,1.0819561,136545.2143,1.746493397,233.0250873
,77.1,37.52336914,1.098219417,138013.8353,1.740822874,234.5887836
,77.4,37.3427472,1.114799946,139350.6036,1.736461021,236.0385132
,77.7,37.97075308,1.13157753,141923.4157,1.720322034,237.9583391
,78,38.6440606,1.148605645,143572.6732,1.712906786,239.5516229
,78.3,39.27697701,1.165893781,144671.5232,1.712470536,241.2818775
,78.6,39.38862738,1.183477431,145501.3042,1.713779086,242.8729657
,78.9,39.72611335,1.201311823,146079.3554,1.71857711,244.5484289
,79.2,40.00199126,1.21941968,147209.1894,1.717704708,246.2852582
,79.5,40.44130631,1.23779028,148555.9135,1.714651355,247.9859252
,79.8,41.00578754,1.256430428,149337.8766,1.718576982,249.731523
,80.1,41.27737322,1.27537146,150559.4718,1.717704581,251.5253309
,80.4,42.03561149,1.294566053,151052.4598,1.722066376,253.0188987
,80.7,42.28713864,1.314083527,152939.9432,1.713778797,255.0592593
,81,42.87473168,1.333873847,153741.19,1.714214926,256.6602137
,81.3,43.49805156,1.353960793,154933.7832,1.712906303,258.5548366
,81.6,43.9008532,1.374365564,155323.5672,1.719449068,260.2226326
,81.9,44.84687714,1.395043037,156706.8266,1.717704226,262.1052054
,82.2,44.98085624,1.416086512,157649.7265,1.719885147,263.8946316
,82.5,45.5573887,1.437418709,158242.1897,1.724683146,265.5459893
,82.8,45.58227901,1.459109402,158822.3781,1.729917386,267.302542
,83.1,46.25521577,1.481085052,159740.3937,1.731662066,269.0919697
,83.4,46.8690304,1.503396742,161025.1369,1.72948107,270.7696299
,83.7,47.11756006,1.526069596,162140.8853,1.731225792,272.6697302
,84,47.99832648,1.549043181,162257.3582,1.739949442,274.1085098
,84.3,48.19599681,1.572409004,163180.5135,1.741694169,275.8924556
,84.6,48.92523478,1.59609281,164418.4583,1.739076974,277.6270977
,84.9,49.72679653,1.620129686,167519.8387,1.72032086,279.8778547
,85.2,50.09235242,1.644558568,169543.0888,1.71246946,282.0201285
,85.5,50.37963193,1.669445296,170440.8808,1.714214179,283.8533852
,85.8,51.1244573,1.694510704,170471.2662,1.724682588,285.6976071
,86.1,51.71695995,1.720049542,170327.2014,1.736459571,287.4223835
,86.4,52.2295329,1.745979572,172000.2761,1.731225278,289.209622
,86.7,52.89096475,1.772291449,173515.6396,1.729480465,291.2850521
,87,53.41755555,1.799009845,175101.4521,1.726427105,293.3111735
,87.3,53.84175086,1.82613867,176668.0242,1.723373755,295.3866012
,87.6,54.5620594,1.853657875,178050.0003,1.720756563,297.3765632
,87.9,55.10259809,1.881604686,181221.185,1.704617601,299.8256567
,88.2,55.17051541,1.910004734,184555.1467,1.686733939,302.1476381
,88.5,55.89228641,1.938790869,187754.9836,1.672775895,304.6745338
,88.8,56.61981201,1.968011326,189199.1242,1.674520571,307.1828048
,89.1,57.20167411,1.997683004,188327.9229,1.695021286,309.2407025
,89.4,58.15784772,2.027777767,186501.9871,1.720756203,310.7934461
,89.7,58.54821519,2.058364227,185685.5165,1.739076001,312.6727282
,90,59.36447356,2.089384416,187066.298,1.737331172,314.7722704
,90.3,60.06418279,2.120880912,189353.5783,1.727734997,317.0471358
,90.6,60.55083423,2.152867175,191727.5823,1.717266476,319.3055648
,90.9,61.10396576,2.185332302,195120.4259,1.701999882,321.9672418
,91.2,61.97815643,2.218266688,198027.6217,1.692403704,324.6081051
,91.5,62.54610616,2.25171886,200303.5652,1.68804177,327.074734
,91.8,63.62979156,2.285642496,200508.2296,1.69851015,329.3759033
,92.1,64.23085783,2.320110752,199963.4336,1.713776611,331.5083166
,92.4,65.08891739,2.355082493,199697.3916,1.724681194,333.3536353
,92.7,65.68399315,2.390600072,200775.5106,1.727298238,335.6997278
,93,66.36467559,2.426648628,202406.8886,1.723808689,337.7652989
,93.3,67.02447244,2.46324292,204606.9488,1.718574383,340.2461743
,93.6,67.62843998,2.500393851,206858.672,1.713776279,342.8881305
,93.9,68.36709595,2.53809731,208095.0182,1.716393317,345.3087385
,94.2,68.97670739,2.576378902,209586.6796,1.715520883,347.447728
,94.5,69.87991949,2.615154131,210248.1768,1.723372147,349.952712
,94.8,70.76762592,2.654649827,211707.4601,1.722935872,352.0632144
,95.1,71.68603053,2.694673915,212830.2306,1.725989083,354.4136928
,95.4,72.5972673,2.735303281,215681.7417,1.716829081,357.1586584
,95.7,73.19309326,2.776567377,219584.8271,1.699817758,359.9375874
,96,74.00845777,2.818440373,222794.0605,1.689349208,362.9488291
,96.3,74.63153871,2.860958834,225059.2466,1.685859657,365.884457
,96.6,75.9313176,2.904074996,224065.6167,1.703306976,368.1078308
,96.9,76.47640445,2.947892582,222619.4771,1.724243857,370.2588719
,97.2,77.39202457,2.992347574,221765.8834,1.740818838,372.3332148
,97.5,78.28424296,3.037475871,223147.3579,1.74169112,374.5467192
,97.8,79.27286038,3.083279412,226356.6778,1.731222554,377.2993575
,98.1,79.71477002,3.129808822,229233.4103,1.72337116,380.0541788
,98.4,80.62662559,3.177010297,230868.1003,1.72206251,382.4375353
,98.7,81.35700039,3.224936698,231449.5284,1.729041413,385.0937379
,99,82.56064553,3.273556062,230472.3954,1.744743988,387.2491727
,99.3,82.962996,3.322962743,230186.6332,1.756084782,389.4144583
,99.6,84.1938603,3.373061354,231700.6981,1.755212285,391.6444076
,99.9,85.19747903,3.423931889,236047.4119,1.737328559,394.60086
,100.2,86.01045665,3.47558352,240447.4697,1.71988104,397.6427871
,100.5,86.76590491,3.528019426,244149.2398,1.707231573,400.64526
,100.8,87.81074938,3.581228282,246007.7307,1.706795284,403.641167
,101.1,88.15495557,3.63528723,247977.484,1.705922877,406.6436362
,101.4,89.40753236,3.690103039,249683.0346,1.705486567,409.2538262
,101.7,90.4727864,3.745759394,252015.1603,1.704177904,412.5028568
,102,91.15686904,3.802281793,254730.4533,1.699815978,415.6729898
,102.3,92.09289978,3.859641472,257774.1469,1.693709284,418.9351693
,102.6,93.60783678,3.917829685,259689.7971,1.694145321,422.0242235
,102.9,94.03027063,3.976969178,262388.2322,1.690655793,425.3894016
,103.2,95.03909404,4.036964005,265380.4514,1.684112908,428.4148948
,103.5,95.96873677,4.097872735,269623.7746,1.674080547,432.4134458
,103.8,97.10871895,4.159687961,273418.2102,1.664484352,435.7928815
,104.1,98.2651918,4.222436033,273638.5588,1.675825065,439.0605437
,104.4,99.34081379,4.286137482,273115.215,1.690219084,442.2065749
,104.7,100.3963157,4.350802722,272022.5298,1.70679403,445.2758988
,105,101.5015798,4.416441917,273770.007,1.705049178,448.1567495
,105.3,102.3479467,4.483089894,276530.4312,1.698942497,451.589872
,105.6,103.3339228,4.550735643,278838.5501,1.698942399,455.3396849
,105.9,104.0327103,4.619422238,279239.7936,1.708102224,458.0364353
,106.2,105.5208623,4.689094636,278115.4468,1.727294234,460.7759347
,106.5,106.6735672,4.75984171,277136.9326,1.744305347,463.1801143
,106.8,108.0016456,4.83164603,278606.374,1.747794695,466.0138502
,107.1,109.1956062,4.904542705,283114.3025,1.735145199,469.4338296
,107.4,110.4343175,4.97853746,288025.4923,1.719442403,472.6949231
,107.7,111.3109489,5.053673106,292799.8363,1.706792942,476.6715617
,108,112.613363,5.129915252,293028.0098,1.715952702,479.8406106
,108.3,113.9230815,5.207308958,293243.6502,1.724240087,482.9121299
,108.6,115.6228027,5.285846007,295536.0569,1.721622814,486.1589856
,108.9,116.4504424,5.365627196,301230.6703,1.704611502,490.2046603
,109.2,117.8386306,5.446576688,307152.6258,1.687163967,494.4497771
,109.5,119.2432634,5.528748199,307941.6767,1.695015152,497.7788124
,109.8,120.9962895,5.612138337,307184.2745,1.710281461,501.0190936
,110.1,121.868903,5.696846325,305561.7789,1.729473504,504.0413002
,110.4,123.8112115,5.782763457,305486.5573,1.738633198,506.7304013
,110.7,124.7341646,5.870045997,308060.4949,1.735579804,510.2840682
,111,126.2076644,5.958610726,309759.1827,1.737324401,513.6930986
,111.3,127.5370226,6.048522999,313307.9628,1.730781486,517.3421057
,111.6,129.0192451,6.139783799,316218.3631,1.72772805,520.7237419
,111.9,130.7258769,6.232408435,321347.1395,1.716387072,524.8132621
,112.2,132.1044942,6.32645747,327421.8505,1.699375729,528.7285503
,112.5,133.2220664,6.421946223,333511.1459,1.685853892,533.5390939
,112.8,135.0291023,6.518832204,338292.2476,1.675821467,537.6439605
,113.1,136.4340697,6.617208617,340500.8731,1.678438437,541.960307
,113.4,138.1719998,6.717049393,340791.8578,1.688470512,545.9632643
,113.7,139.6463753,6.818416067,340914.2918,1.698066426,549.4446186
,114,141.1941355,6.92130945,338981.6656,1.71725839,552.8777618
,114.3,142.6655243,7.025762508,339471.1393,1.725981932,556.457738
,114.6,144.373354,7.13177827,339344.0241,1.736450186,559.6662472
,114.9,145.7589615,7.239416876,343157.3258,1.731215832,563.6746766
,115.2,147.3764263,7.348666712,348821.0271,1.718130138,568.0611624
,115.5,149.0639299,7.459557471,351597.3893,1.7172576,571.8931755
,115.8,150.8406024,7.572117365,354098.8258,1.71812979,575.851209
,116.1,152.4397975,7.686389393,354349.9714,1.728161866,579.5966534
,116.4,154.5952973,7.802351261,356507.8646,1.729034017,583.1130901
,116.7,156.0250519,7.920112925,362586.2759,1.71507598,587.8732366
,117,157.735725,8.039635312,368389.8129,1.702862654,592.5895607
,117.3,159.1657415,8.160981755,373625.3027,1.693266462,597.2971104
,117.6,161.0580344,8.284130907,376018.4738,1.695011011,601.5049894
,117.9,162.9425436,8.409141246,377351.0925,1.701989767,605.7698465
,118.2,165.2219317,8.536014472,379849.8082,1.703734276,610.0982707
,118.5,166.5600722,8.664866596,381929.3671,1.706351245,614.2436788
,118.8,168.490256,8.79562648,382632.3382,1.714202361,618.4099205
,119.1,170.4093102,8.928362673,384497.9064,1.717691638,622.5684884
,119.4,172.7240564,9.063078106,387992.26,1.714201936,626.5725601
,119.7,174.6266606,9.199856024,392513.0254,1.709403725,631.6033802
,120,176.9524016,9.338672255,396973.0675,1.704169289,636.5849015
,120.3,178.9125803,9.479610324,398952.5084,1.708094746,641.1390536
,120.6,180.7534507,9.622685398,402235.919,1.706786011,645.5649991
,120.9,182.7028857,9.768404217,408108.9694,1.69718978,650.6911563
,121.2,185.3442341,9.915797019,415156.8216,1.6845402,656.183326
,121.5,187.4195784,10.06495107,421730.2088,1.673635412,661.6064457
,121.8,189.5194429,10.21685996,424296.0371,1.677560855,666.8454795
,122.1,191.7395759,10.37105608,425557.8637,1.685411935,671.8982265
,122.4,194.1506878,10.5275695,426131.954,1.693262994,676.222277
,122.7,195.6787194,10.68650574,426270.9356,1.703731236,681.0854392
,123,198.2845826,10.84777221,427550.5258,1.709837539,685.8324706
,123.3,200.4599375,11.01150379,428728.6466,1.716380066,690.3449929
,123.6,203.0267494,11.17768363,432866.5299,1.712454162,695.0427156
,123.9,205.1921598,11.34640058,439423.6358,1.702421738,700.6521285
,124.2,207.4445199,11.51766098,445586.8415,1.69413404,706.3919473
,124.5,209.1548663,11.69154429,445540.1177,1.705910804,710.9187064
,124.8,212.0162198,11.86797646,445050.1286,1.719432182,715.3720758
,125.1,214.1417018,12.04712282,444130.0537,1.734262177,719.6731119
,125.4,216.6128467,12.22894924,448958.7575,1.728155369,724.2557773
,125.7,218.484548,12.41356102,455902.3863,1.716814433,729.9155945
,126,221.2651313,12.60090133,463591.8228,1.703292497,735.8954081
,126.3,223.2923462,12.79112158,470967.0448,1.691951546,742.0340918
,126.6,225.9330857,12.98417525,475329.7824,1.68977038,747.5909255
,126.9,228.2605468,13.18016615,477765.0673,1.695004331,753.2003505
,127.2,231.2922011,13.37907201,477800.9824,1.707217135,758.242169
,127.5,233.7210432,13.58102286,475061.1565,1.726408902,762.4204888
,127.8,236.3282699,13.78601296,472231.2014,1.745600654,766.5856635
,128.1,238.8043872,13.99410881,467024.7829,1.770898951,770.0856881
,128.4,241.8565476,14.20531068,468470.329,1.77351573,773.8607702
,128.7,244.5063672,14.41972997,475510.0601,1.760429993,779.2225566
,129,247.4535104,14.63736922,490248.2644,1.725535149,785.9771079
,129.3,249.7295769,14.85834072,504414.4903,1.694566015,792.4116687
,129.6,252.4102232,14.91545585,515836.543,1.676246123,800.1469551
,129.9,253.206869,14.91540374,521807.7493,1.671011864,806.0500238
,130.2,254.3629181,14.91532809,525679.2074,1.672756478,812.5010028
,130.5,254.6117235,14.91531185,529893.7072,1.673628817,819.1919388
,130.8,255.3156066,14.91526581,531882.7682,1.679735291,825.2549957
,131.1,255.1887857,14.91527417,528595.3723,1.70067202,830.6495952
,131.4,256.2803583,14.91520274,522888.0624,1.726406625,834.6350313
,131.7,256.0869813,14.91521547,517226.5158,1.753449901,839.0423179
,132,256.7991838,14.91516888,515358.0312,1.768280002,843.3652513
,132.3,256.7077209,14.91517493,515804.7359,1.775695097,847.7681562
,132.6,257.3471276,14.91513311,515227.092,1.785727207,851.6144183
,132.9,257.3575787,14.91513249,512692.1852,1.801865923,855.2316413
,133.2,257.6704444,14.91511206,513024.8779,1.809280976,859.0417321
,133.5,257.8526936,14.91510018,516737.7877,1.806227686,863.0381028
,133.8,258.3718832,14.91506623,525042.9407,1.790961279,868.2573953
,134.1,258.1522997,14.91508067,532506.6386,1.77874822,873.6476078
,134.4,258.5466966,14.9150549,535181.9019,1.779184361,877.855477
,134.7,258.2730362,14.91507288,534918.6769,1.788780382,882.3296047
,135,258.6832402,14.91504607,531630.6143,1.806663781,885.7868542
,135.3,258.3871171,14.91506553,529192.8533,1.821493984,889.0556064
,135.6,258.9786866,14.91502684,526383.204,1.836760274,891.7611426
,135.9,258.8056923,14.91503823,526316.68,1.844175378,894.950999
,136.2,259.3057471,14.91500554,526252.4053,1.850718046,897.9732185
,136.5,259.1003068,14.91501905,528017.46,1.85115425,901.0874647
,136.8,259.0953668,14.91501943,529882.5095,1.851154251,904.447178
,137.1,259.2135557,14.91501175,527336.9098,1.863803501,906.9905225
,137.4,259.7577039,14.91497617,523616.4346,1.879505976,908.616699
,137.7,259.3126614,14.91500538,516057.0746,1.907421639,909.5316765
,138,259.9391728,14.9149644,512017.7958,1.923560285,910.5332505
,138.3,259.5848131,14.91498767,511318.7621,1.928794502,911.8996981
,138.6,259.9650668,14.91496282,512426.9189,1.927922097,913.433826
,138.9,259.5716054,14.91498865,514412.1004,1.92486887,915.2133863
,139.2,260.245538,14.91494457,517744.4208,1.917889892,917.3534946
,140.1,260.1607755,14.77924054,1.7977E+308,1.960635687,0
,140.4,259.7196771,14.55557209,1.7977E+308,1.924868861,0
,140.7,259.1837363,14.33190984,1.7977E+308,1.713320901,0
,141,258.7858994,14.10823856,1.7977E+308,1.288043979,0
,141.3,258.1509563,13.8845828,1.7977E+308,0.692220072,0
,141.6,257.9128542,13.66090105,1.7977E+308,0.243389292,0
,141.9,257.3502908,13.43724055,1.7977E+308,0.023989985,0
,142.2,256.8517877,13.21357586,1.7977E+308,0.042745792,0
,142.5,256.6386441,12.98989248,1.7977E+308,0.04187343,0
,142.8,255.9230015,12.76624201,1.7977E+308,0.040564887,0
,143.1,255.7356484,12.54255693,1.7977E+308,0.034894527,0
,143.4,255.1264956,12.31889949,1.7977E+308,0.035766891,0
,143.7,254.7511214,12.09522673,1.7977E+308,0.028351805,0
,144,254.2301555,11.87156351,1.7977E+308,0.031841259,0
,144.3,253.980406,11.64788252,1.7977E+308,0.034022168,0
,144.6,253.4344815,11.42422093,1.7977E+308,0.036639259,0
,144.9,252.9035321,11.20055837,1.7977E+308,0.034894533,0
,145.2,252.3185059,10.97689934,1.7977E+308,0.021372902,0
,145.5,251.7143447,10.75324156,1.7977E+308,0.015266359,0
,145.8,251.4196697,10.52956352,1.7977E+308,0.031405083,0
,146.1,251.2622668,10.30587649,1.7977E+308,0.034022173,0
,146.4,250.702199,10.08221583,1.7977E+308,0.026607085,0
,146.7,250.2211667,9.858549989,1.7977E+308,0.010904543,0
,147,249.677738,9.634888238,1.7977E+308,0.010904544,0
,147.3,248.9874696,9.411236103,1.7977E+308,0.016574907,0
,147.6,248.7514472,9.187554219,1.7977E+308,0.013957817,0
,147.9,248.2254894,8.963891323,1.7977E+308,0.01701109,0
,148.2,247.6229919,8.74023344,1.7977E+308,0.019192,0
,148.5,247.2700802,8.516559212,1.7977E+308,0.011776909,0
,148.8,246.6729904,8.292900974,1.7977E+308,0.006324637,0
,149.1,246.0667491,8.069243336,1.7977E+308,0.011340728,0
,149.4,245.789545,7.84556415,1.7977E+308,0.004361819,0
,149.7,245.1354664,7.621909645,1.7977E+308,0.010468365,0
,150,244.5974451,7.398247539,1.7977E+308,0.01853773,0
,150.3,244.4321386,7.174561024,1.7977E+308,0.020064367,0
,150.6,243.9685771,6.950894042,1.7977E+308,0.017011094,0
,150.9,243.1605872,6.727249617,1.7977E+308,0.014394004,0
,151.2,242.7402872,6.503579801,1.7977E+308,0.01134073,0
,151.5,242.1236463,6.279922845,1.7977E+308,0.007415093,0
,151.8,241.5436114,6.05626349,1.7977E+308,0.011340731,0
,152.1,241.1357906,5.832592858,1.7977E+308,0.011340732,0
,152.4,240.3768857,5.608945218,1.7977E+308,0.008287458,0
,152.7,240.2394496,5.385256878,1.7977E+308,0.01308546,0
,153,239.6352879,5.161599104,1.7977E+308,0.028788014,0
,153.3,239.0094955,4.937942746,1.7977E+308,0.044490568,0
,153.6,238.3487609,4.714288677,1.7977E+308,0.048416209,0
,153.9,237.9683945,4.490616246,1.7977E+308,0.051033302,0
,154.2,237.4973452,4.266949755,1.7977E+308,0.037947841,0
,154.5,236.6918509,4.043305166,1.7977E+308,0.015266374,0
,154.8,236.070218,3.819648536,1.7977E+308,0.015702556,0
,155.1,235.4494171,3.595991851,1.7977E+308,0.037075482,0
,155.4,234.8277843,3.372335221,1.7977E+308,0.047543855,0
,155.7,234.4166355,3.148664807,1.7977E+308,0.039692577,0
,156,233.503819,2.925027246,1.7977E+308,0.029660389,0
,156.3,232.9422052,2.700621028,1.7977E+308,0.02180911,0
,156.6,232.235713,2.476969955,1.7977E+308,0.0196282,0
,156.9,231.5191188,2.254065202,1.7977E+308,0.020064383,0
,157.2,230.8575521,2.030411187,1.7977E+308,0.016138744,0
,157.5,230.0545532,1.806766435,1.7977E+308,0.005234187,0
,157.8,229.3181106,1.583117324,1.7977E+308,0.01134074,0
,233.1,228.4740935,1.36918328,1.7977E+308,0.006106553,0
,233.4,227.7742568,1.145531772,1.7977E+308,0.011776923,0
,233.7,227.0261667,0.921883423,1.7977E+308,0.015266383,0
,234,226.3687594,0.698229136,1.7977E+308,0.012213107,0
,234.3,224.3710751,0.474662624,1.7977E+308,0.033149865,0
,234.6,223.5460291,0.251019315,1.7977E+308,0.036203144,0
,234.9,221.4601573,0.027458578,1.7977E+308,0.035330783,0
,234.936,220.9391516,0.000649018,1.7977E+308,0.034894602,0
END,,,,,,