File: GB1_test27.csv
Segment,Time On Sample,Displacement Into Surface,Load On Sample,Harmonic Contact Stiffness,Harmonic Displacement,Harmonic Load
Surface Marker,0,0,0,394.5722873,0.429731746,2.216557202
,0.2,-0.218927895,0.000671734,3677.169562,0.280961673,2.286680598
,0.4,-0.412891837,0.001341829,10482.71458,0.195887877,2.355708317
,0.6,-0.105912429,0.001979049,14943.01773,0.168838768,2.444458279
,0.8,0.151139067,0.002619545,18164.77382,0.1483338,2.571556979
,0.99,0.12639299,0.003245667,20686.62098,0.136118075,2.695368625
,1.2,0.44389506,0.003914666,22639.91464,0.129137659,2.818084619
,1.4,0.214149518,0.00458672,25611.61969,0.118230764,2.941896248
,1.6,0.151662465,0.005247798,30874.41893,0.106887591,3.231155314
,1.8,0.434510106,0.005886213,36951.64295,0.098598348,3.582868077
,2,0.373687317,0.006547182,41576.56971,0.096416969,3.931293772
,2.2,0.274586466,0.007210662,44633.79157,0.097725797,4.276432426
,2.4,0.695567981,0.007840011,44186.36323,0.106887588,4.616092754
,2.6,0.256957362,0.008525773,43318.17486,0.122593523,5.184749735
,2.8,0.32927566,0.009178004,42393.14874,0.142662213,5.900227672
,3,0.356658841,0.009833184,42101.50428,0.1609858,6.610227225
,3.2,0.659477642,0.010470288,41355.08489,0.181490763,7.310365722
,3.4,0.705167722,0.011124266,40335.51813,0.203740832,7.998451705
,3.6,0.461275942,0.011797249,41629.28147,0.222064422,9.013049788
,3.8,0.603493309,0.012444892,42425.77379,0.241260559,10.02216953
,4,0.709929009,0.013094884,43015.34932,0.260892972,11.0455331
,4.2,0.453555252,0.013768686,44010.55191,0.277035183,12.03931323
,4.4,0.418528549,0.014427961,44730.07433,0.290996012,12.85121086
,4.6,0.603184637,0.01507282,44900.12661,0.318917665,14.09371012
,4.8,0.227816031,0.015754431,45289.96722,0.345530501,15.33182642
,5,0.196949986,0.016413434,44423.09977,0.374760986,16.26534432
,5.2,0.312539138,0.017062826,42474.95952,0.419261124,17.37197947
,5.4,0.217598944,0.017726033,40080.32188,0.471614233,18.41944786
,5.6,0.313216933,0.018376736,37464.5711,0.532256579,19.42856761
,5.8,-0.303469908,0.019074184,34300.19144,0.611222534,20.44973948
,6,0.025144992,0.019709596,30185.91788,0.720291497,21.31532555
,6.2,-0.902343105,0.020427442,26035.79669,0.85510079,22.01327199
,6.4,0.006267689,0.02102479,22534.12249,0.992963931,22.38142054
,6.6,-1.056025771,0.021751483,18586.03378,1.196704841,22.63013878
,6.8,-0.123699212,0.022347276,15857.00439,1.377759279,22.56439863
,7,0.568557282,0.022958822,13474.70064,1.587171651,22.36936832
,7.2,1.076080499,0.023582491,12220.22999,1.725034784,22.18200764
,7.4,1.163793233,0.024233712,11605.25857,1.811417398,22.13270216
,7.6,1.277718117,0.024883211,11809.16333,1.797892837,22.29486262
,7.8,1.097068356,0.025552044,13480.81605,1.644760025,22.98513985
,8,1.13318892,0.02620665,15657.65439,1.482029124,23.7586888
,8.2,0.835624643,0.026883155,19457.86755,1.274361832,24.91353347
,8.4,0.60504697,0.027555264,22914.6164,1.137807497,25.86786916
,8.6,0.969859589,0.028188299,26592.11398,1.030047335,26.88575458
,8.8,0.685609417,0.028863931,28036.73028,1.008669833,27.70641738
,9,0.324387049,0.029544614,27164.95685,1.060150408,28.31013582
,9.2,0.414180116,0.030195698,25849.69681,1.124282959,28.71663253
,9.4,0.651676575,0.030837089,23830.13422,1.226807778,29.10012021
,9.6,-0.108553001,0.031543957,22202.19072,1.319734594,29.38061325
,9.8,0.409371886,0.032166945,20829.0141,1.409171116,29.65015045
,10,0.956421371,0.03278802,20094.789,1.464141836,29.87476493
,10.2,0.632228871,0.033466273,19551.9121,1.513441036,30.14758854
,10.4,0.815636763,0.034111213,19319.59145,1.541798955,30.3842552
,10.6,0.864239305,0.034765,19310.89963,1.557068607,30.6647489
,10.8,1.194518453,0.035400301,19873.52564,1.537436167,31.07781989
,11,1.233967544,0.036054689,20784.93863,1.496862508,31.49527334
,11.2,0.735443439,0.036744383,22307.56974,1.432729994,32.10775705
,11.4,0.628437335,0.037408382,23956.82123,1.369033724,32.70873652
,11.6,1.147194336,0.038031314,25651.31008,1.312317824,33.33327363
,11.8,1.223257226,0.038683299,26905.29564,1.280905957,33.9309662
,12,1.137470485,0.039345906,27335.75516,1.282651067,34.43552599
,12.2,0.640194313,0.040037158,27436.5396,1.295739378,34.9028323
,12.4,0.97421832,0.040670573,27073.73228,1.328460046,35.35863477
,12.6,1.24250339,0.041311584,26694.71463,1.360308167,35.75088788
,12.8,1.489569618,0.041950705,26438.02192,1.384303322,36.08835703
,13,1.579362681,0.042601789,26403.39499,1.402190627,36.54087224
,13.2,1.383318483,0.043271631,26491.72396,1.411352436,36.89915885
,13.4,1.466038426,0.043923179,27015.48171,1.404372016,37.3965969
,13.6,1.657351563,0.0445676,27855.45471,1.382994485,37.91047027
,13.8,1.376845991,0.045242985,28682.92265,1.362053265,38.38380299
,14,1.779520596,0.045873535,29716.9646,1.337621789,38.97985239
,14.2,1.639645294,0.046539691,30603.08789,1.320607041,39.55946607
,14.4,1.655378629,0.047195635,31270.37111,1.312317799,40.12593185
,14.6,1.817567154,0.047841967,31699.03227,1.312317788,40.65952731
,14.8,1.769226345,0.048502116,31925.7201,1.317989379,41.11313805
,15,1.57193395,0.04917204,32280.39153,1.3214796,41.66426405
,15.2,1.978769211,0.049802317,32782.73612,1.318861917,42.23073017
,15.4,1.93874972,0.050461919,33264.79108,1.314499162,42.71282866
,15.6,2.041024758,0.051112183,33830.04653,1.309263845,43.26943334
,15.8,1.742212291,0.05178877,34627.93025,1.29835697,43.92136154
,16,1.904400816,0.052435102,35271.00731,1.292249098,44.56671633
,16.2,1.816949814,0.053097818,35747.91049,1.289195174,45.08935475
,16.4,1.955006518,0.053745734,36026.60438,1.294866754,45.68649965
,16.6,1.843423695,0.054410033,36171.88834,1.304464828,46.25406076
,16.8,1.829200288,0.055067942,36061.27182,1.322788416,46.82490918
,17,1.979738968,0.055715039,35989.31684,1.340675719,47.39575767
,17.2,1.913923392,0.056376335,35843.66847,1.358563033,47.8504642
,17.4,2.229224157,0.057012619,35857.60581,1.374268942,48.39611231
,17.6,2.306535241,0.057664521,35865.676,1.389102319,48.89355036
,17.8,1.790536389,0.058355361,35841.61553,1.40655339,49.4304322
,18,2.267270715,0.05898105,35534.31721,1.430548529,49.81611144
,18.2,2.367881488,0.059631423,35085.09208,1.461524107,50.24561748
,18.4,2.46349947,0.060282124,34466.6051,1.497734998,50.62253095
,18.6,2.69309066,0.060924032,33861.99734,1.531764496,50.96109588
,18.8,2.649742643,0.061583853,33473.42446,1.555323392,51.24706785
,19,2.79612066,0.062231222,33228.09197,1.574519518,51.63384251
,19.2,2.534754131,0.06290535,33094.98842,1.58760782,51.94611044
,19.4,2.969881855,0.06353377,32914.0014,1.603749989,52.32302442
,19.6,3.139559556,0.06417961,32769.18335,1.619019627,52.64296274
,19.8,2.595268245,0.064872306,32682.94905,1.631235401,52.91578582
,20,2.771603005,0.065517709,32465.78669,1.651740349,53.22367187
,20.2,3.139328056,0.066150552,32286.69865,1.668318799,53.45924316
,20.4,3.046884269,0.066813594,32509.52859,1.670063912,53.8032861
,20.6,3.452055242,0.067443979,33182.22082,1.651304016,54.19992216
,20.8,3.087504389,0.068124879,34081.0027,1.622509844,54.62394906
,21,3.602516447,0.068749931,35934.76156,1.560994909,55.29779208
,21.2,3.513399884,0.069420968,38419.01035,1.4837741,56.07024512
,21.4,3.097254464,0.070120364,40380.81216,1.430112201,56.72107746
,21.6,2.988164575,0.070806313,41989.11781,1.394337591,57.43765097
,21.8,2.57368122,0.071519349,42746.7909,1.387357209,58.11039687
,22,3.407394355,0.072157343,42014.34239,1.42487687,58.61331453
,22.2,3.774280546,0.072832508,40553.20051,1.485082906,58.96064508
,22.4,3.43635006,0.073561061,39632.30102,1.526529138,59.22470296
,22.6,3.767452337,0.07425274,39246.22884,1.550960558,59.59504282
,22.8,3.583463969,0.074985315,39726.87432,1.545288988,60.15164713
,23,3.560075864,0.075714605,41576.83163,1.492935892,60.89123001
,23.2,3.716427052,0.076439347,43590.95721,1.439710229,61.61328237
,23.4,3.689708085,0.077183547,45714.97809,1.390411063,62.44709344
,23.6,3.674221734,0.07793432,47417.76295,1.356381551,63.26337388
,23.8,3.766495227,0.078685635,48326.92416,1.346347201,64.06102791
,24,3.504279407,0.079467835,48068.50701,1.366852185,64.70747759
,24.2,3.532892388,0.080238658,47484.19481,1.393901285,65.19395881
,24.4,3.565248723,0.08101703,46751.56676,1.427930798,65.75275485
,24.6,3.585121837,0.081804062,46022.34032,1.462396588,66.2249922
,24.8,3.782653816,0.082587303,45758.08728,1.485082917,66.78926691
,25,3.780056866,0.083391588,45800.51044,1.495117262,67.25493025
,25.2,3.543629626,0.084219287,46084.25777,1.500788867,67.8805621
,25.4,3.972906432,0.085011536,46362.32501,1.505151592,68.47661191
,25.6,3.883763914,0.085845862,46838.79852,1.502097669,69.04746013
,25.8,3.752597403,0.086691388,47123.84248,1.506460439,69.680762
,26,3.808243121,0.087533055,47288.38993,1.513877124,70.2779068
,26.2,3.764863813,0.088389741,47320.8746,1.522602645,70.73918731
,26.4,4.138381143,0.089227487,47630.33816,1.525656547,71.33633267
,26.6,3.616939457,0.090132674,47733.57018,1.533945831,71.88526649
,26.8,3.836509644,0.090998035,47724.38897,1.546597813,72.45392407
,27,4.425960978,0.091847797,47607.28838,1.559686039,72.88890952
,27.2,4.328486236,0.0927513,47680.98856,1.568411565,73.42907885
,27.4,4.546387946,0.093643231,47602.48081,1.581936098,73.94514371
,27.6,4.83501942,0.094539476,47655.44524,1.591097866,74.42395578
,27.8,4.472506422,0.095487578,47941.21028,1.593279277,74.97288982
,28,4.665439824,0.096408549,48474.48323,1.586298848,75.47690235
,28.2,4.270886762,0.097377568,48872.21139,1.586298883,76.05980231
,28.4,4.594877881,0.098308958,49383.25054,1.581936098,76.65256495
,28.6,4.294352683,0.099290762,49849.03477,1.577573366,77.22231707
,28.8,4.732342784,0.100233897,50163.12425,1.577137054,77.70879926
,29,4.760922567,0.101213567,50352.32748,1.582372363,78.29060449
,29.2,4.998365858,0.102189196,50549.24052,1.586298826,78.8428269
,29.4,4.964116591,0.103192561,50674.55974,1.591534139,79.31287287
,29.6,5.17159998,0.10419004,50949.96896,1.596333156,79.94179269
,29.8,5.360774476,0.105201273,51576.1675,1.587607625,80.46662307
,30,5.167167169,0.106245493,52736.96412,1.567538956,81.21387524
,30.2,5.292680707,0.107279079,54162.3938,1.541362398,81.98413761
,30.4,5.155655453,0.108337815,55426.91802,1.518676068,82.65578799
,30.6,5.128885558,0.109402423,57231.06165,1.487046076,83.60519323
,30.8,5.244408481,0.110468339,58258.64269,1.474175931,84.39353417
,31,5.248007984,0.111552385,58997.13727,1.469813174,85.23391956
,31.2,5.509150495,0.112630431,59527.9411,1.47024943,86.04691357
,31.4,5.297640506,0.113750391,59853.73282,1.473303378,86.67583243
,31.6,5.568765089,0.114849846,60127.94856,1.479847494,87.39240662
,31.8,5.478742759,0.115984228,60562.32763,1.483337709,88.19334733
,32,5.304673339,0.117135415,61093.56857,1.484646551,89.0227755
,32.2,5.499236402,0.118273929,61415.90667,1.488136743,89.68237447
,32.4,5.430011908,0.119441265,61714.9388,1.49424461,90.49208051
,32.6,5.599607342,0.12060456,61833.25937,1.502970113,91.20317619
,32.8,5.988051537,0.121765158,61918.08235,1.513876978,91.97343909
,33,5.900514562,0.122968841,61816.7739,1.526092708,92.52675644
,33.2,5.788011715,0.12418626,61756.33531,1.540053543,93.23566018
,33.4,5.993381223,0.125394911,61701.88698,1.553141801,93.91059862
,33.6,6.027329666,0.126627098,61741.65151,1.562739866,94.53184813
,33.8,5.844089794,0.127885884,61840.02565,1.571901674,95.22212509
,34,6.433066076,0.129106449,62086.30197,1.575391832,95.81379308
,34.2,6.045949992,0.130403606,62428.86907,1.578445799,96.54351385
,34.4,6.221352844,0.131676608,62835.2517,1.580190885,97.27652307
,34.6,6.351818534,0.132965489,63182.04984,1.582808529,97.96351376
,34.8,6.359958833,0.134275261,63855.83086,1.578882052,98.75240211
,35,6.259919923,0.13560535,64322.6218,1.577573232,99.3878953
,35.2,6.626704741,0.136917998,64725.18621,1.579754581,100.1439144
,35.4,6.599057048,0.138269968,64934.03654,1.583681069,100.7224325
,35.6,6.681248577,0.13962824,65275.59845,1.587607543,101.5387132
,35.8,6.841658309,0.140994994,65331.19939,1.595024218,102.1161362
,36,7.364875224,0.142351648,65439.84848,1.602877138,102.8009367
,36.2,7.114207585,0.14377291,65630.52959,1.608985022,103.5010745
,36.4,7.024139069,0.145197898,66005.72183,1.608985029,104.0828794
,36.6,7.60476636,0.146592912,66461.59963,1.610730085,104.8882048
,36.8,7.676958999,0.148035558,66717.68682,1.613347731,105.4656275
,37,7.618504696,0.149501181,67360.34843,1.609421257,106.243559
,37.2,7.763920272,0.150968206,68272.25311,1.600259454,107.0883276
,37.4,7.582305807,0.152471428,68982.02834,1.593279056,107.7534038
,37.6,7.632853652,0.153974466,69973.87634,1.581935885,108.5477708
,37.8,7.611835774,0.155497363,71516.98733,1.562303476,109.5382641
,38,7.426053421,0.157046335,72741.97268,1.550960323,110.5265658
,38.2,7.558974998,0.158589844,73330.14114,1.549651486,111.2672448
,38.4,7.760961042,0.16014424,73660.52081,1.555323055,112.1426924
,38.6,7.80816812,0.161724502,73517.54794,1.568411325,112.8658404
,38.8,7.951899932,0.163314312,73115.65816,1.584989792,113.4596983
,39,7.741973265,0.164943519,72307.09749,1.611166356,114.1390185
,39.2,7.934795701,0.166562429,71758.95735,1.629489921,114.6452225
,39.4,8.046066639,0.168203083,71221.30664,1.649994873,115.2577072
,39.6,7.898542046,0.169877221,71004.71653,1.663519435,115.8285551
,39.8,7.734372147,0.171569268,71014.445,1.671372414,116.3632455
,40,8.149363147,0.173240014,71460.93701,1.671808654,117.0754379
,40.2,8.293076562,0.174945544,72101.95334,1.668318436,117.8380305
,40.4,8.269528794,0.176679332,72793.09799,1.661338027,118.4713325
,40.6,8.389937016,0.178421058,73666.06293,1.651739951,119.2152988
,40.8,8.362639129,0.18018986,74480.78515,1.645195818,120.0677364
,41,8.522151961,0.181964066,75090.20944,1.640833048,120.7503446
,41.2,9.162633977,0.183724466,75761.07437,1.637342787,121.5819668
,41.4,8.973894088,0.185557292,76105.11446,1.638651631,122.2327992
,41.6,8.727318146,0.187412236,76408.17222,1.641269308,122.9504678
,41.8,9.165167432,0.189240704,76867.10661,1.641705547,123.7492188
,42,9.327994318,0.1911057,77101.64219,1.645195739,124.3901914
,42.2,9.405940799,0.192995095,77480.99673,1.647813387,125.1966108
,42.4,9.579163333,0.194897115,77905.70832,1.647377097,125.8594968
,42.6,10.03988425,0.196799385,78614.10648,1.642578025,126.6264737
,42.8,10.16608526,0.198742771,79531.73966,1.635161328,127.5326001
,43,9.786347236,0.200738972,80559.96843,1.624254469,128.3313484
,43.2,9.97079118,0.202718025,81846.67733,1.611166183,129.3349906
,43.4,10.27006611,0.204709379,82810.00747,1.602440644,130.1403155
,43.6,10.39625449,0.206732263,83548.29532,1.599386705,131.0311025
,43.8,10.11635948,0.208802207,84337.54305,1.596769075,132.0270732
,44,10.29454954,0.210862759,84955.23475,1.594587682,132.8225364
,44.2,10.3745448,0.212950462,85722.27366,1.591970022,133.8272741
,44.4,10.38838227,0.215063545,86345.80522,1.590224919,134.6512242
,44.6,10.29944815,0.217204512,86913.46293,1.592842582,135.7315629
,44.8,10.60702124,0.219340936,87194.20213,1.597641589,136.5215483
,45,10.51267141,0.221525333,87267.70186,1.607675939,137.4090475
,45.2,10.56102864,0.223722332,87029.81714,1.620327931,138.0489239
,45.4,10.77747292,0.22593024,86621.3561,1.637778941,138.825761
,45.6,10.64649788,0.228188974,86630.59717,1.646504467,139.5609607
,45.8,10.17517838,0.230486974,86315.02305,1.660901608,140.3114987
,46,10.95954252,0.232719607,85724.44807,1.678352567,140.8593409
,46.2,10.78112604,0.235044047,85112.52353,1.697548714,141.5123645
,46.4,10.93514237,0.237369901,84647.0492,1.712382074,142.0087073
,46.6,10.95476576,0.239727969,83993.05827,1.731141928,142.4853277
,46.8,11.22735333,0.242093128,83807.86129,1.742485071,143.0923346
,47,11.56317913,0.244477733,84291.0702,1.739431112,143.6642801
,47.2,11.8765326,0.246893884,85555.71067,1.723725159,144.5167194
,47.4,12.20236613,0.249321213,86731.7626,1.708891758,145.2628777
,47.6,12.16579959,0.251815403,88408.66436,1.687077979,146.1963958
,47.8,12.47997542,0.254292947,90095.45101,1.667445548,147.2668749
,48,12.14924546,0.256837785,91179.35709,1.656974962,148.0656233
,48.2,12.67602082,0.25936447,91961.47082,1.654357262,149.0166745
,48.4,12.89032781,0.261930785,92446.71957,1.655666071,149.8395301
,48.6,12.93238054,0.264527692,92811.25442,1.659592549,150.7281255
,48.8,13.12754022,0.267147347,93244.27678,1.660465084,151.4666137
,49,13.02812122,0.269812732,93867.5733,1.659592543,152.415471
,49.2,13.12424885,0.272491896,94272.89191,1.660028811,153.1594375
,49.4,13.29193549,0.275193307,94477.13932,1.665264105,154.0644684
,49.6,13.26157056,0.277934853,94434.02107,1.673989621,154.8281563
,49.8,13.47834425,0.280687774,94194.91906,1.684896493,155.4680335
,50,13.56862957,0.283476678,93945.01771,1.697984755,156.2141909
,50.2,13.41842448,0.286309461,93734.56561,1.708455385,156.7795606
,50.4,13.59274609,0.289149318,93618.65446,1.718925985,157.4884651
,50.6,14.03667372,0.291999916,93931.58822,1.721107323,158.1962754
,50.8,14.23761443,0.29489529,94652.2999,1.715871998,158.9161371
,51,14.23467835,0.297833127,95640.12907,1.708019039,159.8474639
,51.2,14.57374355,0.30077788,96685.60881,1.69798467,160.6527894
,51.4,15.20405001,0.303732955,98420.77083,1.679224763,161.7210789
,51.6,15.38167231,0.306747625,99889.23752,1.664827653,162.7192429
,51.8,15.4261488,0.309801342,101178.9035,1.655229587,163.8269741
,52,15.41320335,0.31288948,102139.1936,1.648685456,164.6914647
,52.2,15.38111397,0.316009788,103125.3388,1.644322704,165.7838561
,52.4,15.73512851,0.319136052,103763.4532,1.643013847,166.636296
,52.6,15.68472227,0.322320367,104345.7828,1.643886406,167.6037794
,52.8,15.8148834,0.32552491,105191.4005,1.642141293,168.7378075
,53,15.75697776,0.328773984,105788.6569,1.643450132,169.7907544
,53.2,15.72652726,0.332053886,106308.4525,1.643886405,170.654149
,53.4,16.00312796,0.335346477,106710.735,1.647812861,171.7213413
,53.6,15.51000198,0.338722872,106929.2559,1.653048213,172.6603355
,53.8,16.08116652,0.342062966,106860.9168,1.660901129,173.4349831
,54,16.27037744,0.345461948,106780.8445,1.670062896,174.3937029
,54.2,16.07513829,0.348920407,106641.0398,1.678352143,175.1201368
,54.4,15.93897497,0.352409571,106483.3034,1.688822778,176.0043488
,54.6,16.14980478,0.35591107,106446.2455,1.697111996,176.8096737
,54.8,16.09434701,0.359465263,106520.6505,1.702783581,177.4966639
,55,16.17285667,0.36304643,106661.4976,1.709763986,178.3699202
,55.2,16.30794556,0.366659726,106531.6763,1.720234586,179.1982539
,55.4,15.96621748,0.370340725,106187.7827,1.731577783,179.7778669
,55.6,16.69793281,0.37398805,105874.8748,1.743357163,180.4265116
,55.8,17.36640031,0.377676197,105622.5011,1.754700265,181.1266537
,56,17.95497737,0.381406309,105712.8874,1.759062961,181.7150367
,56.2,18.14079697,0.385200481,106737.4241,1.751209985,182.6091118
,56.4,18.05367149,0.389050722,108097.9538,1.737249177,183.4396359
,56.6,18.46498643,0.392906771,109755.2026,1.72067067,184.4684798
,56.8,18.1040775,0.396852442,112015.1571,1.697111825,185.6934471
,57,18.45546655,0.400790718,113711.3996,1.6809696,186.71243
,57.2,18.96745061,0.404758044,115265.262,1.669626391,187.9615065
,57.4,19.05088078,0.408793516,115936.6533,1.668317558,188.8862596
,57.6,18.97453533,0.412880084,116557.1778,1.668753841,189.9337279
,57.8,20.12141609,0.416927037,116212.9781,1.68227828,190.9198457
,58,19.98098358,0.421099473,115952.2452,1.692748906,191.6758628
,58.2,20.20584993,0.425289804,116031.6038,1.699729294,192.6356784
,58.4,20.45983417,0.429520427,116298.904,1.702346925,193.4245685
,58.6,20.62935031,0.433799294,116888.5933,1.701910635,194.3723317
,58.8,20.81300585,0.438120174,118608.6555,1.687949804,195.6159284
,59,20.85602435,0.442493692,119830.0492,1.679224292,196.6381967
,59.2,21.14617879,0.446894874,121377.0672,1.668753655,197.9442474
,59.4,21.21123473,0.451355181,122640.0993,1.660900692,199.0081519
,59.6,21.30166357,0.455858522,123537.6853,1.658719308,200.1465631
,59.8,21.39832618,0.46040681,123840.877,1.664827156,201.2718256
,60,21.18043601,0.465021419,124233.5348,1.66831738,202.2173952
,60.2,21.32035482,0.469658823,123882.5343,1.681841908,203.2035067
,60.4,21.3674836,0.474348955,123639.1427,1.693621342,204.1885221
,60.6,21.84315236,0.479058025,123510.7107,1.702783085,205.0891729
,60.8,21.76336614,0.483851022,123304.1599,1.711508602,205.8473823
,61,21.84250931,0.488681598,122985.129,1.722851757,206.7809014
,61.2,21.92538933,0.493560581,123182.8704,1.725905679,207.5588335
,61.4,22.36358151,0.498465085,123052.2263,1.734194873,208.4605796
,61.6,22.45143871,0.503441914,123567.132,1.734194866,209.3951941
,61.8,22.73234235,0.508456051,124641.0569,1.726778158,210.3330973
,62,22.77108787,0.513536472,126356.4534,1.712817342,211.4983519
,62.2,23.19260554,0.518642591,128087.7885,1.699729042,212.6964792
,62.4,23.58748682,0.523801999,130414.1027,1.681841715,214.1120987
,62.6,23.63536125,0.529036128,131742.3473,1.67529758,215.3326853
,62.8,24.13465836,0.534292979,132337.5567,1.676170087,216.3253733
,63,24.24867046,0.539628086,132550.333,1.682714209,217.4594017
,63.2,24.56696217,0.545003306,132910.195,1.685331834,218.4038789
,63.4,24.70508895,0.55044444,133092.6767,1.691003402,219.5390032
,63.6,24.62726905,0.555954616,133550.7044,1.692748512,220.6204374
,63.8,24.74707144,0.561507099,134299.0642,1.690567125,221.6602376
,64,24.76534502,0.567121964,135340.9203,1.687076921,222.9553302
,64.2,24.79650764,0.572792453,135890.361,1.688385745,223.9611636
,64.4,24.78813501,0.578522403,136438.4344,1.69187595,225.185037
,64.6,24.93120104,0.584300016,136667.4709,1.697983793,226.2314114
,64.8,24.89576576,0.590147458,136447.0931,1.708018131,227.088232
,65,25.16862565,0.596033249,136232.3724,1.718924992,228.1094066
,65.2,25.13815965,0.602028236,136198.8789,1.725469126,228.9224
,65.4,25.17051708,0.608034523,136158.4449,1.733322081,229.9161809
,65.6,25.60478416,0.614074427,136649.0379,1.734194592,230.9307825
,65.8,25.69828157,0.620212832,137038.9479,1.735503411,231.8226657
,66,25.84668982,0.626409178,137423.842,1.73812105,232.865753
,66.2,26.00881836,0.632666726,137494.4195,1.744665166,233.8551522
,66.4,26.02781041,0.63899658,137897.5705,1.745973992,234.6626678
,66.6,26.15496936,0.645382823,138242.1407,1.749027908,235.5918044
,66.8,26.64159863,0.651809534,138736.622,1.750772965,236.6622856
,67,26.98425896,0.658310488,139074.3184,1.752518035,237.4785689
,67.2,27.14633654,0.664888624,139859.4035,1.75077292,238.59178
,67.4,28.03735017,0.671484692,140083.1969,1.753390489,239.3971098
,67.6,27.85906523,0.678217589,140134.0779,1.758625811,240.2539296
,67.8,28.18753716,0.684984682,140803.0963,1.758189505,241.3287932
,68,28.06997621,0.691849177,141829.05,1.753826768,242.4343316
,68.2,28.30689198,0.698759292,142665.4939,1.75033654,243.3196428
,68.4,29.29271436,0.705689498,143878.0467,1.744664871,244.5007911
,68.6,29.99227268,0.712708112,145232.0997,1.737248127,245.6753639
,68.8,30.20585546,0.71982936,146111.4391,1.734194181,246.6527113
,69,30.23302961,0.727034396,147230.5235,1.730267702,247.8963073
,69.2,30.82271258,0.734274625,148610.9573,1.722414694,249.0062345
,69.4,30.83904595,0.741625502,150471.2524,1.711507812,250.4240435
,69.6,30.87201024,0.749048938,151785.4767,1.705836232,251.7027006
,69.8,30.90995547,0.756546475,152853.9378,1.701909752,252.8608337
,70,31.40639271,0.764089088,154034.1663,1.69798323,254.249063
,70.2,31.45679585,0.771737112,154223.3755,1.702345985,255.2932448
,70.4,31.87498851,0.77943766,154121.3335,1.710635175,256.4919209
,70.6,32.59772865,0.787195495,154028.5718,1.71805179,257.5963715
,70.8,32.57736382,0.795080154,153856.3752,1.72546847,258.5068798
,71,32.83907865,0.80302543,153364.6827,1.738120424,259.5784564
,71.2,33.46858248,0.811026339,153308.4879,1.744664499,260.4550038
,71.4,33.88421596,0.819121767,153511.0869,1.749463489,261.5495904
,71.6,34.24658017,0.827301953,154352.4172,1.747718354,262.6474636
,71.8,34.94427989,0.835542242,155436.6058,1.742482986,263.6905554
,72,35.25252936,0.843891075,157489.9077,1.728958432,265.1620549
,72.2,35.3718719,0.852336156,159111.5817,1.719360366,266.3881208
,72.4,35.5394645,0.860862963,160934.663,1.710198575,267.8892026
,72.6,35.77943884,0.86947064,162039.224,1.707144623,269.2094979
,72.8,36.19581108,0.878153148,163233.7229,1.704963213,270.7040076
,73,36.45156827,0.886933518,164011.0939,1.704963192,271.8413246
,73.2,36.63824463,0.89580658,165456.1508,1.700164149,273.3281628
,73.4,37.22349725,0.904742578,166819.688,1.694928792,274.6155905
,73.6,37.29198264,0.913802403,168946.4513,1.684021909,276.2196655
,73.8,37.41787057,0.922949395,170476.8749,1.679222873,277.8500378
,74,37.87742816,0.932166288,171354.3619,1.678786557,279.164857
,74.2,38.05571094,0.941494494,171950.6884,1.682276743,280.6571734
,74.4,37.91860145,0.950937087,172663.3319,1.683149306,281.9325429
,74.6,38.57200067,0.960422477,172645.2548,1.692311025,283.4610206
,74.8,38.66203251,0.970040341,172961.416,1.696237493,284.6333982
,75,39.22303475,0.979723709,174610.5988,1.690129592,286.2703482
,75.2,39.67251603,0.989511862,175627.2227,1.687948178,287.5742099
,75.4,39.9297596,0.999410931,176499.7414,1.688820705,289.1519906
,75.6,40.14621297,1.009412152,177893.6377,1.685330486,290.6903259
,75.8,40.24615211,1.019521735,178597.5254,1.686639303,291.9821324
,76,40.30862919,1.029735662,178232.1855,1.698418724,293.425143
,76.2,40.50131833,1.040043647,178193.3931,1.705399108,294.5460248
,76.4,40.7692988,1.050450197,178122.2657,1.714124585,295.9156264
,76.6,40.93449457,1.06096811,177558.9392,1.725467722,297.0299335
,76.8,41.21242717,1.071584269,177641.9824,1.732011822,298.3699515
,77,42.11319223,1.082266104,177854.0949,1.73637449,299.4294814
,77.2,42.64281014,1.093079785,178104.7896,1.741609741,300.736631
,77.4,43.50859136,1.10397975,178604.5596,1.744009174,301.9342163
,77.6,43.54721785,1.115043802,179395.7362,1.744227309,303.1684997
,77.8,43.73769038,1.126209089,179720.4817,1.748590042,304.3677223
,78,44.30218757,1.137461784,180671.4476,1.74771744,305.7658142
,78.2,44.58956744,1.148845938,181407.4014,1.747281139,306.8779315
,78.4,44.8236728,1.160348072,181993.7317,1.749462493,308.2497241
,78.6,45.123082,1.17196136,182832.8823,1.747281091,309.3081529
,78.8,45.72786436,1.183671181,184667.886,1.738555537,310.913329
,79,45.87329225,1.195528981,185718.722,1.7355016,312.1755533
,79.2,46.09192864,1.207501078,187085.6697,1.731138831,313.7511424
,79.4,46.49444664,1.219581287,188750.6022,1.725030946,315.354125
,79.6,46.61859788,1.231801182,190174.9016,1.721104462,316.8617811
,79.8,47.03439114,1.244124674,190897.0992,1.722413249,318.1338691
,80,47.39649232,1.25657554,192006.2582,1.721976942,319.7291818
,80.2,47.32669818,1.269180019,192491.1787,1.724594598,320.9344284
,80.4,47.87307611,1.281870506,192421.7146,1.732447496,322.334712
,80.6,48.2729789,1.294698154,191425.9817,1.746408256,323.4282039
,80.8,48.93872669,1.307637151,190536.5396,1.75862389,324.366112
,81,49.30655129,1.320725897,189487.1556,1.773020926,325.4749428
,81.2,49.67102119,1.33397954,189173.0791,1.780001289,326.3690207
,81.4,50.69868799,1.347255727,189960.9876,1.780001192,327.6728889
,81.6,50.98864517,1.360747503,191694.7512,1.772148219,329.0293434
,81.8,51.32642827,1.374371699,193482.5705,1.762986418,330.3112915
,82,51.75489173,1.388126882,195973.2804,1.75033441,332.0446611
,82.2,52.4379649,1.402003435,197651.3691,1.742917676,333.3945448
,82.4,52.60884006,1.416053255,198817.5512,1.741172562,335.0030039
,82.6,53.06511328,1.43022532,199607.6648,1.741608795,336.404383
,82.8,53.36492347,1.444550112,200668.226,1.739863669,337.7213931
,83,53.59063964,1.459096658,201607.5997,1.740299923,339.2805476
,83.2,53.87168655,1.473676565,202712.6734,1.738118524,340.6118008
,83.4,54.20762486,1.488436306,204627.4637,1.731138098,342.3188733
,83.6,55.01453098,1.503275219,206150.0475,1.726775277,343.8824168
,83.8,55.48647528,1.518322757,206346.11,1.73288308,345.4251384
,84,55.77283065,1.533533644,206801.0569,1.735500703,346.6775028
,84.2,56.43445215,1.54887258,207327.3649,1.73899084,348.2268005
,84.4,57.35650565,1.564348539,207696.8447,1.742044677,349.4353444
,84.6,57.52878574,1.58002941,208694.011,1.741172113,350.9156104
,84.8,58.25191048,1.595831566,210837.8157,1.732882828,352.7454032
,85,58.48738212,1.611824625,212528.5849,1.726774963,354.2322427
,85.2,59.12641099,1.627951724,214327.2281,1.721539609,356.0488869
,85.4,59.5706958,1.644253676,216288.091,1.715867999,357.9937223
,85.6,59.57975091,1.660748123,217504.4948,1.71499545,359.672305
,85.8,59.95990937,1.677383845,218769.6467,1.712814043,361.1887296
,86,60.18193666,1.694197207,220391.7599,1.709760101,363.121512
,86.2,60.68519683,1.7111609,220521.7369,1.715431626,364.5185088
,86.4,61.24917534,1.728291002,219585.6759,1.729392361,365.9976823
,86.6,62.23917666,1.745565152,218813.88,1.741171683,367.3157956
,86.8,63.10183459,1.763021106,217651.9385,1.754696113,368.334787
,87,63.29543278,1.780696229,215964.3188,1.773019625,369.4742964
,87.2,64.13307075,1.798506338,216752.6909,1.773019547,370.9282731
,87.4,64.51384133,1.816525528,218290.6888,1.766911669,372.245284
,87.6,65.28069106,1.83470027,220643.0794,1.756004735,373.9381179
,87.8,65.85695419,1.853070054,224181.8935,1.738553704,376.0429254
,88,66.05540135,1.871649266,227168.021,1.724592904,377.8014945
,88.2,66.65324079,1.890388908,230516.5488,1.710632072,380.0268265
,88.4,67.09211367,1.909327099,232753.4742,1.702779092,381.8204597
,88.6,67.37534815,1.928465894,235183.7854,1.695362402,383.8551409
,88.8,68.02968162,1.947772429,237161.435,1.691872149,386.0432214
,89,68.41853506,1.967290573,238419.8902,1.692308389,388.0614687
,89.2,68.61430339,1.98701761,238485.8489,1.698852488,389.5789879
,89.4,68.97147326,2.006932011,238361.246,1.708014218,391.4109693
,89.6,69.65480586,2.027025078,237480.899,1.720666114,392.8802841
,89.8,69.75811247,2.047358339,236864.5499,1.73070041,394.183049
,90,70.46551223,2.06785594,236726.1031,1.738989562,395.8506823
,90.2,70.90576584,2.088577109,238297.2559,1.735935604,397.7823716
,90.4,71.91682675,2.109468866,239682.6254,1.732881586,399.3503016
,90.6,72.44189101,2.130602587,241792.3034,1.726337429,401.2677482
,90.8,72.63823063,2.15197025,243837.4113,1.721102119,403.397753
,91,73.30968168,2.17352121,244901.5354,1.720665785,404.9733491
,91.2,74.17165575,2.195276244,245346.2443,1.72590099,406.8403994
,91.4,75.00696692,2.217251645,246151.3537,1.728518565,408.7030647
,91.6,75.18735768,2.239490942,246952.8744,1.730699915,410.4572524
,91.8,75.83204076,2.261922924,247926.0606,1.73113613,412.0722927
,92,76.11471201,2.284604229,250349.8623,1.723719443,414.2285961
,92.2,76.78428685,2.307487958,251915.3839,1.720665462,415.9893622
,92.4,77.19669737,2.330618564,253901.7741,1.716738957,418.1686748
,92.6,78.2131963,2.353941736,255327.4962,1.715866316,420.1726867
,92.8,79.08819608,2.377508539,256001.9673,1.718483882,421.8118352
,93,79.38399673,2.401350339,254861.0612,1.733317176,423.5013782
,93.2,79.93189424,2.4254151,254106.6055,1.743787705,424.8041488
,93.4,80.32331299,2.449732903,252594.3604,1.759929812,426.2636007
,93.6,80.66934188,2.474298137,251893.6942,1.769964085,427.5915689
,93.8,81.85578124,2.49905478,251947.8294,1.775635536,429.1923731
,94,82.49380836,2.524096534,252713.7117,1.775635477,430.5707468
,94.2,82.90212805,2.549404913,253867.0713,1.77476289,432.320554
,94.4,83.60872531,2.574948038,255064.3354,1.772581454,433.7701483
,94.6,84.0361027,2.600766153,254953.5454,1.779561798,435.2109735
,94.8,84.8295753,2.626819572,255288.7475,1.784360738,436.7515103
,95,85.43660953,2.65314698,256226.2312,1.785233229,438.4103788
,95.2,86.04693021,2.6797387,257046.9594,1.785233171,439.7164376
,95.4,87.27631179,2.706556653,258293.4749,1.783924233,441.4333846
,95.6,87.98099366,2.733678758,261152.0413,1.772581043,443.3376871
,95.8,88.52919209,2.761083756,263414.0114,1.764291787,445.0721565
,96,89.30368559,2.788749073,265875.4405,1.756002511,447.1682042
,96.2,90.32943754,2.816675845,267515.108,1.75207595,449.0051258
,96.4,91.08303897,2.844901163,269782.3172,1.744659224,451.0294062
,96.6,91.87279285,2.873407746,271816.7648,1.738987591,453.1155924
,96.8,92.79064886,2.902192361,273968.3815,1.73375222,455.3584636
,97,93.39225026,2.931287017,275780.1666,1.729389427,457.2156506
,97.2,93.79700692,2.960687027,277356.5854,1.727644295,459.4716631
,97.4,94.54330512,2.990359775,278426.0422,1.727644226,461.180935
,97.6,95.45514932,3.020319862,278379.9654,1.734624523,462.9482805
,97.8,95.95712271,3.050607932,277339.2445,1.74771269,464.766022
,98,96.51896091,3.081196326,277103.7917,1.756438113,466.5224066
,98.2,97.48641252,3.112065302,277656.0386,1.759491939,468.0333632
,98.4,98.28738923,3.143255446,277680.8127,1.766472244,469.8434392
,98.6,98.87903598,3.174772831,278881.7859,1.766035915,471.6392686
,98.8,100.0127635,3.206571054,280062.0449,1.765163261,473.2444562
,99,100.6313404,3.238803658,282212.795,1.759927919,475.4040528
,99.2,100.971545,3.271215839,284465.7927,1.752947509,477.2404194
,99.4,101.7344056,3.304007539,288934.8065,1.736805314,479.9149873
,99.6,103.1878795,3.337083267,293230.435,1.721971877,482.4624663
,99.8,103.6015574,3.370559777,296690.253,1.711065,484.7853161
,100,104.369252,3.404349248,300483.0226,1.701030639,487.6220461
,100.2,104.9479996,3.438490909,301578.5976,1.704084501,489.9909165
,100.4,105.7239069,3.472962541,301860.9618,1.709319714,491.8513946
,100.6,106.6420529,3.507771085,301423.2171,1.718917647,493.840069
,100.8,107.4869019,3.543022857,301968.3821,1.724152852,496.0906107
,101,108.3595706,3.57862882,302429.5204,1.728079234,497.9609515
,101.2,109.2101741,3.614322956,303455.921,1.730260523,500.2859986
,101.4,110.1089262,3.65073545,304069.7083,1.732878081,502.0993642
,101.6,110.9369476,3.687151948,305613.3049,1.731569184,504.3268975
,101.8,111.4436805,3.724139725,306343.8099,1.735059325,506.6913856
,102,112.806613,3.761442641,306990.2699,1.738549386,508.8509927
,102.2,113.6302675,3.799156021,308974.8283,1.73462285,510.9262261
,102.4,114.487979,3.8372461,311731.3982,1.728514944,513.5503958
,102.6,115.3705934,3.875717022,313838.3584,1.725024676,515.9444733
,102.8,116.670042,3.914547026,315997.5814,1.720661824,518.1862577
,103,117.311216,3.953810708,318776.0033,1.714990213,520.9868287
,103.2,118.5398089,3.993429935,319714.1801,1.716298921,522.9809888
,103.4,119.3689176,4.033473737,320278.4344,1.72109785,525.4375187
,103.6,120.1913053,4.073920353,321669.6117,1.721970321,527.7790034
,103.8,121.1525935,4.11476418,323001.2772,1.72284278,529.9068322
,104,121.9973186,4.156026131,324356.9465,1.724587795,532.41486
,104.2,122.7263123,4.197710135,325516.199,1.725896548,534.5032415
,104.4,124.0027787,4.239776429,327210.6085,1.726332703,537.0912613
,104.6,124.6966893,4.282303576,327045.0243,1.734185555,539.1960775
,104.8,126.0370943,4.32521525,325750.8455,1.747273623,541.2231092
,105,127.0196163,4.368581281,324869.255,1.757307812,542.8567868
,105.2,127.7557597,4.412398871,324024.2283,1.768214569,544.8027296
,105.4,128.4943295,4.456656373,323444.3013,1.776067413,546.2950589
,105.6,129.9068509,4.501313969,325065.0035,1.774758461,548.3801639
,105.8,130.7825794,4.546455587,328983.1025,1.762979008,551.0032409
,106,131.7489376,4.592044742,332375.0389,1.752944644,553.299805
,106.2,133.0672123,4.638068718,336946.9232,1.739420056,556.2724128
,106.4,133.9244155,4.684585529,341584.3226,1.725895523,559.3206132
,106.6,135.1318695,4.731546604,343599.9562,1.72327777,561.9283562
,106.8,136.0613183,4.778997744,344678.9882,1.724586507,564.0989177
,107,137.1371455,4.826916007,345180.3127,1.730257954,566.7198071
,107.2,138.344372,4.875307106,345078.9128,1.736801936,568.6306966
,107.4,139.0980125,4.924214289,344873.9386,1.745527319,570.9360246
,107.6,140.3849675,4.973577639,345219.0174,1.751635021,573.1241233
,107.8,141.1076623,5.023474205,345248.2228,1.757742772,574.92215
,108,142.0849079,5.073855246,344800.9038,1.766904408,577.0466943
,108.2,143.2293303,5.124731437,344816.4359,1.772139567,578.7472123
,108.4,144.4152776,5.176115931,345243.6958,1.776502178,580.8608035
,108.6,145.4821488,5.228024524,347067.1962,1.774320714,583.1047804
,108.8,146.6113465,5.280450623,350158.6648,1.766031428,585.3673824
,109,147.7279785,5.333404285,354787.8037,1.752943151,588.3553277
,109.2,149.0192722,5.386878492,358548.9104,1.742908757,590.81954
,109.4,150.168187,5.440899323,363940.5786,1.728075385,594.1263309
,109.6,151.1980215,5.495470681,366419.1776,1.725021382,596.9455402
,109.8,152.4857276,5.550573405,366724.7521,1.72982026,599.1555535
,110,153.9589096,5.606217438,367481.3283,1.733746576,601.9353267
,110.2,154.9593555,5.662451693,368702.4259,1.733746483,604.1321877
,110.4,156.4772933,5.719216918,368882.3286,1.739417883,606.7487041
,110.6,157.4592519,5.77658783,370715.9942,1.738108975,609.3619255
,110.8,158.7931074,5.834513159,374106.108,1.731564767,612.5098461
,111,159.8493564,5.89304043,375568.0151,1.732000941,614.8995497
,111.2,161.1002291,5.952142913,377037.8997,1.733745914,617.6913718
,111.4,162.1238372,6.011854179,379190.4646,1.731128186,620.1161357
,111.6,163.5530108,6.072138628,382432.4287,1.725456515,623.1260039
,111.8,164.39544,6.133067558,385729.3806,1.720657444,626.4032069
,112,165.9646328,6.194560641,388808.954,1.715422034,629.1840788
,112.2,167.3618936,6.256682916,391855.9533,1.711931729,632.5270337
,112.4,168.1237279,6.319471282,392777.1998,1.714985564,634.8882449
,112.6,169.3202469,6.382861928,391836.1189,1.727637344,637.9320746
,112.8,170.7467471,6.446874333,391180.07,1.736362652,640.0336213
,113,172.026691,6.511539602,390678.5596,1.745960517,642.6194576
,113.2,173.2270637,6.576859665,390375.4688,1.752940756,644.6322496
,113.4,175.0763889,6.642793284,391249.7776,1.756430758,647.3057513
,113.6,176.4109398,6.709423335,392919.0516,1.756430633,649.8773448
,113.8,177.3925636,6.776746054,394536.9097,1.755994269,652.2221262
,114,178.9794501,6.844705366,396627.5348,1.755121576,655.121335
,114.2,180.2379549,6.913369238,398508.2673,1.753812642,657.4518774
,114.4,181.4306122,6.98272741,400823.7406,1.752503715,660.3236869
,114.6,183.0512864,7.052754132,403737.1801,1.748140845,663.17359
,114.8,184.4937742,7.123496313,406766.6616,1.743777993,666.3138478
,115,185.5263278,7.194976248,410044.5822,1.737233822,669.0410251
,115.2,187.1375094,7.26713614,414455.9377,1.728071967,672.606411
,115.4,188.6582901,7.340027105,416991.7372,1.724581654,675.4157735
,115.6,190.1993118,7.413834385,418561.635,1.726326597,678.4311255
,115.8,191.6483251,7.488016962,417873.9824,1.73679698,681.3456725
,116,193.1325553,7.56312965,415393.0783,1.751630073,683.206173
,116.2,194.8683828,7.638980374,413163.9749,1.766899411,685.4293507
,116.4,196.301196,7.715613263,412257.5237,1.775624704,687.3402507
,116.6,197.3327724,7.7932373,412236.9747,1.780859863,689.5316397
,116.8,199.0420513,7.871205181,415164.6817,1.776496986,692.4440012
,117,200.0222345,7.950201056,420296.8786,1.764717566,695.7299787
,117.2,202.2529723,8.029908445,423985.8072,1.756864472,698.4330759
,117.4,203.6685182,8.110470207,428226.051,1.749011456,701.8352046
,117.6,205.5906982,8.191807988,431246.8996,1.745521106,704.9480829
,117.8,207.0846208,8.273991462,431882.4196,1.749011136,707.4166896
,118,208.7256978,8.35699104,431555.232,1.756863862,710.2698848
,118.2,210.2801013,8.440830258,432390.1046,1.759045071,712.4612855
,118.4,211.8817679,8.525722097,432504.0786,1.765152715,715.2016247
,118.6,213.1725693,8.611057014,433772.7891,1.766461405,717.8543042
,118.8,214.7598516,8.697446687,436761.2616,1.761662274,720.5464335
,119,216.102282,8.78515944,440352.8708,1.755990624,723.8970658
,119.2,217.9265114,8.872839237,443719.3244,1.751191472,727.2170284
,119.4,219.4185133,8.961865353,447103.6313,1.74551981,730.0450216
,119.6,221.0168844,9.051778972,450059.7645,1.742465765,733.2959523
,119.8,223.0677864,9.142566079,451426.6642,1.745083198,736.4712904
,120,224.6359122,9.23429735,452174.5654,1.748573217,738.8851166
,120.2,226.3944474,9.326937505,452522.5994,1.754680842,741.7196916
,120.4,227.7509196,9.420535142,453397.0454,1.759479691,744.7766802
,120.6,229.6572747,9.515036877,453926.5436,1.764278488,747.4403324
,120.8,231.3379738,9.610502934,455731.8289,1.763842058,749.9757838
,121,233.3596901,9.706905727,459084.227,1.759042891,753.3132844
,121.2,234.990155,9.804302917,462356.3427,1.75380749,756.1478584
,121.4,236.6945231,9.90267388,466105.9566,1.748135813,759.7417429
,121.6,238.9113207,10.00199942,471342.6714,1.737665115,763.3926144
,121.8,240.5929054,10.10235813,477844.6559,1.725013116,767.6625387
,122,242.4490751,10.20371391,482292.6814,1.718032619,771.0142808
,122.2,244.1494761,10.30609807,487157.0754,1.711052137,775.2480482
,122.4,246.2050293,10.40948662,491600.027,1.704507894,778.8276987
,122.6,248.326155,10.51390757,495297.6583,1.701453808,782.7196223
,122.8,250.0102503,10.61940596,497009.1189,1.704507545,786.640025
,123,252.0561497,10.72593989,498430.4948,1.707124978,789.8920649
,123.2,253.966243,10.83355296,500210.9738,1.710614963,793.7971329
,123.4,256.108326,10.94223137,500913.903,1.715413736,796.768682
,123.6,257.9014838,10.98979057,500573.5782,1.724138971,799.9516899
,123.8,259.2953129,10.98969981,501541.6455,1.729810359,803.5926858
,124,260.6650105,10.98961063,502404.1891,1.733736657,806.462319
,124.2,261.1551567,10.98957918,503291.8319,1.738971858,810.0035879
,124.4,262.1687066,10.98951337,503275.9712,1.746388347,813.2413638
,124.6,262.5989401,10.98948585,506131.3249,1.744643234,816.6128001
,124.8,263.3145909,10.9894396,508127.472,1.745951975,820.1277781
,125,263.8488394,10.98940525,509223.9478,1.748569547,822.9590437
,125.2,264.0735392,10.98939121,508725.4497,1.756858655,826.0872332
,125.4,264.8707377,10.9893396,510792.0681,1.756422308,829.0368392
,125.6,264.9831012,10.98933294,510873.9914,1.762093801,831.9995775
,125.8,265.1994798,10.98931945,509186.6385,1.77300053,834.8406971
,126,265.8926632,10.98927467,508004.2081,1.781289593,837.1427503
,126.2,265.8053179,10.98928112,510096.4054,1.780853332,840.4352856
,126.4,266.4402529,10.98924016,509875.5946,1.786961045,843.3662655
,126.6,266.5368062,10.98923454,509460.9208,1.793505085,845.9203086
,126.8,266.789798,10.98921864,510759.5938,1.7943776,848.4371091
,127,266.9878699,10.98920636,512803.9246,1.793941312,851.5181832
,127.2,267.1684673,10.98919522,512152.8703,1.800485342,853.7095581
,127.4,267.4023203,10.98918058,511609.566,1.807901907,856.2931924
,127.6,267.6478231,10.98916518,512816.3445,1.809646963,858.859297
,127.8,267.7984641,10.98915601,514121.5322,1.810519489,861.1372319
,128,268.1238504,10.98913536,515852.0513,1.811391998,864.0002692
,128.2,268.1484252,10.98913446,518675.1418,1.809210648,866.9684837
,128.4,268.5274832,10.9891103,520051.8332,1.810083151,869.3242187
,128.6,268.6910221,10.98910028,521296.6416,1.811828215,871.9648264
,128.8,268.9781308,10.98908215,521034.9698,1.817063425,873.9907581
,129,268.8974425,10.98908815,520185.7392,1.824916289,876.367299
,129.2,269.0701347,10.98907753,519904.9244,1.83058778,878.7526139
,129.4,269.1941479,10.98907011,520289.6764,1.833205387,880.7007467
,129.6,269.1617225,10.98907295,520207.7923,1.837568089,882.7606357
,129.8,269.391831,10.98905856,518391.6611,1.847166001,884.6813805
,130,269.9339845,10.98902369,515806.88,1.858508961,886.1539959
,130.2,270.1066767,10.98901307,512780.025,1.870724497,887.3077569
,130.4,270.0388862,10.98901823,509758.9272,1.883376326,888.5546479
,130.6,270.132527,10.98901279,507764.7461,1.892537981,889.6601963
,130.8,270.3655479,10.98899821,507618.5117,1.895591847,890.8161521
,131,270.2503266,10.98900649,508629.9114,1.896028129,892.4443391
,131.2,270.5902749,10.98898489,508580.4798,1.899954523,893.8150503
,131.4,270.491696,10.98899207,508131.3226,1.904317231,894.8099313
,131.6,270.9344112,10.98896373,506885.454,1.911297502,895.8004432
,131.8,270.6906273,10.98898044,505459.2806,1.918714113,896.7558746
,132,270.9798163,10.98896217,504043.4761,1.92525813,897.3705628
,132.2,271.0613914,10.98895753,504691.6304,1.925694392,898.5287052
,132.4,271.3397628,10.98893997,505376.4514,1.925258095,899.4940121
,132.6,271.2162203,10.98894879,507118.5949,1.922204221,900.9775667
,132.8,271.2566054,10.98894685,508953.0549,1.918277791,902.1937815
,133,271.2670342,10.98894688,511926.2703,1.911297476,903.9435924
,133.2,271.6319461,10.98892364,513466.4519,1.908243552,905.2770507
,133.4,271.7992295,10.98891338,515943.2977,1.9030083,907.0323457
,134.2,271.7768707,10.89992975,1.7977E+308,1.838440396,0
,134.4,271.8006459,10.78979259,1.7977E+308,1.712794731,0
,134.6,271.6616542,10.68021542,1.7977E+308,1.515164584,0
,134.8,271.0317555,10.57039582,1.7977E+308,1.251221474,0
,135,271.0201219,10.46053564,1.7977E+308,0.942778804,0
,135.2,270.6993557,10.35069574,1.7977E+308,0.632591065,0
,135.4,270.5591595,10.240844,1.7977E+308,0.389588846,0
,135.6,270.3731967,10.13099526,1.7977E+308,0.20984573,0
,135.8,269.9916858,10.02115936,1.7977E+308,0.090962236,0
,136,270.1252571,9.911289646,1.7977E+308,0.028357532,0
,136.2,270.0171849,9.800886487,1.7977E+308,0.020068407,0
,136.4,269.393943,9.691066445,1.7977E+308,0.013088092,0
,136.6,269.2108926,9.581217514,1.7977E+308,0.020504678,0
,136.8,269.0876676,9.471913965,1.7977E+308,0.023994836,0
,137,269.0061359,9.362058372,1.7977E+308,0.024431106,0
,137.2,268.5834349,9.252225169,1.7977E+308,0.022249758,0
,137.4,268.2705738,9.142384758,1.7977E+308,0.01832333,0
,137.6,267.9011286,9.03254806,1.7977E+308,0.016578251,0
,137.8,267.813772,8.922692849,1.7977E+308,0.023558568,0
,138,267.8470729,8.81282972,1.7977E+308,0.031847694,0
,138.2,267.4293646,8.702996189,1.7977E+308,0.037082932,0
,138.4,267.3078911,8.593143217,1.7977E+308,0.0418819,0
,138.6,267.0873953,8.483296744,1.7977E+308,0.040573091,0
,138.8,266.7537312,8.373457698,1.7977E+308,0.035337854,0
,139,266.4650015,8.263615703,1.7977E+308,0.028793808,0
,139.2,266.2761263,8.153767154,1.7977E+308,0.025739919,0
,139.4,266.1812806,8.043912435,1.7977E+308,0.021813491,0
,139.6,266.0439968,7.934060501,1.7977E+308,0.027484999,0
,139.8,265.657077,7.82422495,1.7977E+308,0.038391745,0
,140,265.3708436,7.71438279,1.7977E+308,0.049734762,0
,140.2,265.1786399,7.604534461,1.7977E+308,0.051916112,0
,140.4,265.2127729,7.494671277,1.7977E+308,0.054097461,0
,140.6,264.6635895,7.384846374,1.7977E+308,0.045372065,0
,140.8,264.6361456,7.274987232,1.7977E+308,0.034901589,0
,141,264.3840292,7.165142834,1.7977E+308,0.027048732,0
,141.2,264.2284388,7.055292101,1.7977E+308,0.026612462,0
,141.4,263.6867445,6.945466707,1.7977E+308,0.017887065,0
,141.6,263.7683083,6.835600411,1.7977E+308,0.012651827,0
,141.8,263.579433,6.725751862,1.7977E+308,0.020504685,0
,142,263.3997111,6.615902713,1.7977E+308,0.035774131,0
,142.2,262.6866,6.506088569,1.7977E+308,0.053224929,0
,142.4,262.7573462,6.396222982,1.7977E+308,0.058896438,0
,142.6,262.2339585,6.286396387,1.7977E+308,0.05758763,0
,142.8,262.3895811,6.17652523,1.7977E+308,0.046680882,0
,143,261.9860187,6.066690771,1.7977E+308,0.033592785,0
,143.2,261.7988077,5.956842114,1.7977E+308,0.021813497,0
,143.4,261.358632,5.847010057,1.7977E+308,0.019632148,0
,143.6,261.2671148,5.73715512,1.7977E+308,0.017450798,0
,143.8,261.2097145,5.627297943,1.7977E+308,0.014396908,0
,144,261.0249998,5.517449121,1.7977E+308,0.011343019,0
,144.2,260.4175679,5.407628042,1.7977E+308,0.00654405,0
,144.4,260.2070575,5.297780913,1.7977E+308,0.00218135,0
,144.6,259.8659041,5.187942358,1.7977E+308,0.00392643,0
,144.8,259.5929846,5.078099326,1.7977E+308,0.00479897,0
,145,259.5380807,4.968241985,1.7977E+308,0.00610778,0
,145.2,259.3941398,4.858390488,1.7977E+308,0.01396064,0
,145.4,258.8557739,4.748564876,1.7977E+308,0.023994851,0
,145.6,258.8366511,4.638705187,1.7977E+308,0.031847711,0
,145.8,258.6020092,4.528859642,1.7977E+308,0.033156521,0
,146,258.0856944,4.419032583,1.7977E+308,0.031411442,0
,146.2,257.6675698,4.309199079,1.7977E+308,0.026176202,0
,146.4,257.6251477,4.199340919,1.7977E+308,0.020504692,0
,146.6,257.2727606,4.089503102,1.7977E+308,0.010034211,0
,146.8,257.2507254,3.979643604,1.7977E+308,0.005671511,0
,147,256.7106951,3.869818101,1.7977E+308,0.008725401,0
,147.2,256.6416452,3.759961689,1.7977E+308,0.018323343,0
,147.4,256.4020104,3.650116472,1.7977E+308,0.021813504,0
,147.6,255.9547616,3.54028488,1.7977E+308,0.022249774,0
,147.8,255.8187259,3.430432864,1.7977E+308,0.027266881,0
,148,255.5686896,3.320588329,1.7977E+308,0.034029068,0
,148.2,255.0973092,3.210758321,1.7977E+308,0.04057312,0
,148.4,254.5747534,3.100931671,1.7977E+308,0.044063282,0
,148.6,254.6138791,2.99106816,1.7977E+308,0.03446534,0
,148.8,254.5593912,2.881210792,1.7977E+308,0.020068426,0
,149,253.6411619,2.771410109,1.7977E+308,0.006544052,0
,149.2,253.7139885,2.661544386,1.7977E+308,0.008289133,0
,149.4,253.4535507,2.551700534,1.7977E+308,0.019632157,0
,149.6,252.9929879,2.441869815,1.7977E+308,0.020068427,0
,149.8,252.8482149,2.332018373,1.7977E+308,0.016578266,0
,150,252.5137183,2.222179381,1.7977E+308,0.011343025,0
,150.2,252.3040398,2.112332198,1.7977E+308,0.010906755,0
,150.4,252.1184929,2.002483431,1.7977E+308,0.012215565,0
,150.6,251.8380842,1.89264089,1.7977E+308,0.016141997,0
,150.8,251.4865291,1.782803018,1.7977E+308,0.017887078,0
,151,251.017645,1.672972846,1.7977E+308,0.014833187,0
,151.2,250.6719147,1.563134591,1.7977E+308,0.006544053,0
,151.4,250.2978924,1.453298193,1.7977E+308,0.00043627,0
,151.6,250.143966,1.343447352,1.7977E+308,0.005671513,0
,151.8,249.6247385,1.233620483,1.7977E+308,0.011343026,0
,152,249.3838555,1.123775348,1.7977E+308,0.013960648,0
,227.2,248.3360213,1.019743148,1.7977E+308,0.017450815,0
,227.4,248.189584,0.909891814,1.7977E+308,0.021377249,0
,227.6,247.9100072,0.800049219,1.7977E+308,0.026612494,0
,227.8,247.455685,0.690218091,1.7977E+308,0.031847739,0
,228,247.1378307,0.580378007,1.7977E+308,0.035337903,0
,228.2,246.6069532,0.470551903,1.7977E+308,0.037955526,0
,228.4,246.0169952,0.360729677,1.7977E+308,0.04013688,0
,228.6,245.6284105,0.250894235,1.7977E+308,0.042318233,0
,228.8,245.0892118,0.141068677,1.7977E+308,0.041445693,0
,229,244.2620991,0.031262014,1.7977E+308,0.040136884,0
,229.054,243.7496664,0.001633189,1.7977E+308,0.040136885,0
END,,,,,,