File: GB1_test21.csv
Segment,Time On Sample,Displacement Into Surface,Load On Sample,Harmonic Contact Stiffness,Harmonic Displacement,Harmonic Load
Surface Marker,0,0,0,-419.8417175,0.375168368,2.213357695
,0.2,0.26063471,0.000640073,3518.435636,0.268725246,2.275813843
,0.4,0.181785794,0.001302407,8504.524252,0.247349375,2.341557137
,0.6,0.308457602,0.001951264,10663.40198,0.234698347,2.406204717
,0.8,0.633993588,0.002587082,12621.70932,0.206778838,2.473043762
,1,0.526854372,0.00325127,15129.88864,0.176678122,2.583711638
,1.2,0.441348915,0.00391404,19228.89229,0.145704921,2.767792868
,1.4,0.730273922,0.004552259,24175.26432,0.122147836,2.947491243
,1.6,1.061634375,0.005187694,27204.51319,0.113422989,3.086647913
,1.792,0.675345194,0.005843901,28777.90292,0.11516796,3.2597719
,2,0.72254592,0.006523464,29835.15189,0.123892806,3.597254175
,2.2,0.584620323,0.007188892,30690.80981,0.133490137,3.992809677
,2.4,0.768704924,0.007833206,31188.98168,0.143087465,4.385078045
,2.6,0.45604511,0.008510091,32034.30861,0.150067344,4.787207843
,2.8,0.624320426,0.009155441,32232.30047,0.154866008,5.111541472
,3,0.689419346,0.009807556,33028.42949,0.165772064,5.777740244
,3.2,0.752022063,0.010459835,33997.0533,0.175805636,6.328888238
,3.4,0.938602866,0.011103985,35715.35745,0.188020418,7.026862963
,3.6,0.874731294,0.011764557,37535.21019,0.19979896,7.720454753
,3.8,1.077953449,0.012407615,39045.79526,0.21375871,8.388845006
,4,0.981631239,0.013070315,40443.63513,0.22684598,9.133935705
,4.2,1.104974896,0.013718612,42646.02554,0.239497005,10.11570234
,4.4,1.320678064,0.014360852,43382.98665,0.257819177,11.02953426
,4.6,0.933132167,0.015042648,43192.80547,0.281812508,11.96528043
,4.8,0.842634429,0.015704966,42404.12952,0.309295772,12.8813037
,5,1.101605119,0.016344368,41530.77448,0.339832727,13.8586875
,5.2,0.935389223,0.017011651,40109.03865,0.379530777,14.96207914
,5.4,0.659340389,0.017686136,38469.65211,0.422282526,15.99753597
,5.6,1.229504395,0.018305134,36792.07067,0.462853043,16.79193444
,5.8,0.753759319,0.018992713,34787.84432,0.517819583,17.78356228
,6,0.853805083,0.019642537,33187.43824,0.570168653,18.68424555
,6.2,0.665123356,0.020311293,31361.4155,0.63734997,19.71641523
,6.4,0.601667817,0.020971838,30176.47951,0.689262805,20.50095188
,6.6,0.396760766,0.021641658,28564.51909,0.759061578,21.39286917
,6.8,0.391549966,0.022298383,26565.71221,0.845437552,22.16864009
,7,-0.736952287,0.023028765,24506.03212,0.940102187,22.76690342
,7.2,-0.283277719,0.0236554,22005.54443,1.060068797,23.14164046
,7.4,0.573117614,0.024255629,18940.37633,1.235874388,23.36955109
,7.6,0.511742243,0.024916037,16882.12355,1.38812295,23.47693176
,7.8,0.863904522,0.025549329,15624.41156,1.499364705,23.54377103
,8,0.807105525,0.026209438,14881.88513,1.575707109,23.64786451
,8.2,0.972884637,0.026854951,15302.13134,1.560002374,24.06423884
,8.4,0.718053528,0.027528045,16560.84319,1.480170059,24.63510966
,8.6,1.059814958,0.028162019,18577.79316,1.369364495,25.4667626
,8.8,1.201048071,0.028809142,20534.48312,1.279062335,26.20747053
,9,0.811838031,0.029491047,22606.94414,1.201411237,26.99419839
,9.2,0.926861014,0.030139889,23846.00627,1.170874271,27.72394906
,9.4,0.820553988,0.030803243,23908.74264,1.191813908,28.34522317
,9.6,0.853202269,0.031457487,23618.88434,1.22322335,28.76707599
,9.8,0.840918894,0.032114676,22973.77056,1.277317395,29.22399192
,10,1.063278609,0.032756479,22464.38886,1.323559061,29.59653745
,10.2,1.2398746,0.033401284,22162.62681,1.357585946,29.92415837
,10.4,1.001268813,0.034073313,22050.12378,1.386377955,30.34820248
,10.6,0.998138182,0.034729903,22241.91949,1.39292159,30.72074778
,10.8,1.047427816,0.035383054,22602.20051,1.393794071,31.20615252
,11,0.893692932,0.036049519,22975.16083,1.390740388,31.65649396
,11.2,1.327397841,0.036677464,23169.88232,1.399028959,32.11560168
,11.4,1.141212319,0.037346057,23120.09874,1.416042423,32.44541373
,11.6,1.569092748,0.037974384,22761.02055,1.453559225,32.7938536
,11.8,1.452800914,0.038638393,22444.11728,1.485841163,33.0425823
,12,1.348158027,0.039301639,22028.71283,1.527284188,33.28583231
,12.2,1.733603001,0.039932749,21783.27065,1.558693599,33.56085888
,12.4,1.721319627,0.040589938,21892.39744,1.565237235,33.81835346
,12.6,1.653287718,0.041250783,22491.97757,1.546042582,34.22048325
,12.8,1.752501412,0.041900662,23145.00744,1.52204925,34.58645442
,13,1.879173337,0.042548739,24315.58116,1.476243803,35.13979398
,13.2,1.86439376,0.043206093,25443.5112,1.433055821,35.5967099
,13.4,2.005210835,0.043853243,26610.94444,1.39423025,36.15114519
,13.6,1.75828438,0.044525818,27458.60968,1.372418157,36.68366564
,13.8,1.862490479,0.045175369,28187.16181,1.353659733,37.11976291
,14,1.867680526,0.045831413,28928.26143,1.337518769,37.62598636
,14.2,2.08338369,0.046473653,29239.56592,1.341008692,38.13659287
,14.4,1.938801558,0.047139518,29530.68911,1.345371126,38.64172044
,14.6,1.991419462,0.047792452,29758.2501,1.348861061,39.03727595
,14.8,2.18382421,0.048439498,29959.47675,1.356277166,39.52706376
,15,1.989318019,0.049108636,30126.68124,1.3636933,39.97302221
,15.2,2.149273171,0.049751253,30543.98162,1.361948319,40.48910724
,15.4,2.260967877,0.050400313,30909.67806,1.362384554,41.01286238
,15.6,2.141347776,0.051064541,31174.12921,1.363257048,41.41280067
,15.8,2.067491395,0.051725768,31371.27973,1.370673173,41.92340689
,16,2.202483996,0.0523733,31377.81521,1.384196673,42.35950423
,16.2,2.379912047,0.05301805,31218.94446,1.406881258,42.82409044
,16.4,2.459156114,0.053669238,31031.95856,1.427384638,43.17033854
,16.6,2.205573121,0.05434225,30921.05589,1.44701556,43.58342532
,16.8,2.530277145,0.054977343,30850.65064,1.464028983,43.98993841
,17,2.369053663,0.055644298,30932.83238,1.473190084,44.3865895
,17.2,2.398373671,0.05629876,31316.62915,1.470136387,44.86651556
,17.4,2.380265824,0.056956331,31679.65559,1.464901482,45.24673093
,17.6,2.384623803,0.05761243,32163.26544,1.457921606,45.74857144
,17.8,2.334897385,0.058272074,32658.48896,1.451377977,46.24383772
,18,2.383354949,0.058925281,33121.07457,1.445706825,46.7182851
,18.2,2.292025148,0.059587654,33374.35466,1.447888044,47.13794648
,18.4,2.324673427,0.060241897,33491.76662,1.457485372,47.59924531
,18.6,2.330695542,0.060897886,33663.34566,1.464901491,48.07150133
,18.8,2.464024007,0.061545528,33725.37536,1.475807537,48.51307736
,19,2.262861275,0.062215102,33842.20816,1.483659915,48.93383418
,19.2,2.570923947,0.062851286,33914.48826,1.491512251,49.30637992
,19.4,2.65183215,0.063502365,34067.11833,1.498492121,49.76767887
,19.6,2.668671143,0.064157645,33975.32937,1.514633084,50.18514886
,19.8,2.593150629,0.064818981,33838.58047,1.529901575,50.49633371
,20,2.562561766,0.065477371,33528.57177,1.553894902,50.82943301
,20.2,2.602698654,0.066131123,33126.24952,1.582686883,51.14719235
,20.4,2.716889562,0.06678002,32765.52718,1.609297655,51.44303722
,20.6,2.779492276,0.067432299,32654.90206,1.623257398,51.70162761
,20.8,2.635742215,0.068098109,32821.05087,1.626311114,52.0610241
,21,2.982079994,0.068731783,33204.45438,1.61845872,52.42918708
,21.2,2.872444707,0.069395356,33788.10815,1.602754012,52.86637986
,21.4,2.825214492,0.070054837,34500.44034,1.583123114,53.34630587
,21.6,3.109147196,0.070692603,35033.97196,1.569599581,53.74186181
,21.8,3.008664241,0.071358176,35551.84418,1.559566018,54.21521341
,22,2.81748488,0.072036191,35983.97311,1.553022402,54.64911889
,22.2,3.029857257,0.072694447,36429.36293,1.547787479,55.13233247
,22.4,3.343740816,0.073352749,36633.68669,1.54909618,55.48515532
,22.6,3.200818162,0.074047849,36867.05565,1.552149891,55.93768814
,22.8,2.902297772,0.074759984,36972.38052,1.560002272,56.36830628
,23,3.08138308,0.075447874,36928.18765,1.57221704,56.73646903
,23.2,3.23217698,0.076144587,36911.69743,1.583995568,57.14079056
,23.4,3.293938546,0.076854034,37049.76955,1.587049259,57.4793688
,23.6,3.170979937,0.07758291,37146.12399,1.594029147,57.88916843
,23.8,3.431603368,0.078293772,37495.47412,1.590975429,58.32417035
,24,3.588633237,0.079018608,37969.51511,1.583123056,58.77012935
,24.2,3.52058763,0.079765666,38456.94117,1.576579429,59.24567248
,24.4,3.37682268,0.080525171,38763.3934,1.575270716,59.61821757
,24.6,3.745194146,0.081258644,39316.99988,1.566982083,60.11896293
,24.8,3.82358889,0.082018421,39748.1398,1.562401533,60.57478334
,25,3.952322517,0.082782487,40214.46791,1.55782098,61.09086846
,25.2,4.086463361,0.083553883,40512.14806,1.556512243,61.49190284
,25.4,4.060845973,0.084343645,41196.85936,1.543861221,62.03757218
,25.6,4.151716796,0.085133641,41986.75478,1.528592737,62.6106348
,25.8,4.709376292,0.085900798,42891.19169,1.509616155,63.17328882
,26,4.89967672,0.086699786,44085.99178,1.484532213,63.86414175
,26.2,4.90608891,0.087519055,45439.26462,1.453995259,64.48322451
,26.4,4.929141156,0.088345379,47108.31958,1.419095882,65.27543138
,26.6,5.411909405,0.089149827,48843.03006,1.385505197,66.11804222
,26.8,5.003531984,0.09002109,50180.10086,1.361511907,66.79958045
,27,5.467992056,0.090843664,52177.61008,1.328357467,67.83394254
,27.2,5.096222898,0.09172958,53200.25289,1.315706471,68.56150116
,27.4,5.172104686,0.092594882,54185.82516,1.307417865,69.44136581
,27.6,5.049953022,0.093481831,54791.98502,1.308726601,70.28178412
,27.8,4.916983067,0.09437837,55202.19341,1.31439776,71.08056503
,28,5.093540827,0.095263513,54882.24522,1.336209858,71.8157946
,28.2,5.270929209,0.096157692,54450.56689,1.35889444,72.42939905
,28.4,5.247787878,0.097074038,53832.23818,1.388122669,73.12079948
,28.6,5.109819758,0.098007144,53123.45664,1.419095877,73.78371099
,28.8,5.401197015,0.098921389,52383.06363,1.44788784,74.2548718
,29,5.400517102,0.099863983,51960.8664,1.471008677,74.84765716
,29.2,5.379033984,0.100817475,51578.25358,1.494129515,75.49303736
,29.4,5.446580582,0.10177464,51169.41558,1.517250347,76.08911003
,29.6,5.524942539,0.102740643,50912.35862,1.533827545,76.52959029
,29.8,5.671532498,0.103711838,50850.54527,1.547351041,77.12237615
,30,5.731585861,0.104698598,50670.76868,1.563055755,77.64941836
,30.2,5.74504187,0.105698304,50694.40283,1.57396181,78.22138519
,30.4,5.57960175,0.106719867,51006.73235,1.576579278,78.82512738
,30.6,5.810224153,0.10772566,51390.60076,1.574398048,79.32258549
,30.8,5.740468576,0.10876123,52038.74186,1.568290664,79.99316707
,31,5.673207538,0.109807099,52880.62727,1.556512132,80.65498298
,31.2,5.857229239,0.110846901,53888.43557,1.541679883,81.4088398
,31.4,5.912278805,0.11190565,55114.65527,1.522485223,82.22843987
,31.6,5.683591651,0.112993664,56123.27434,1.507653008,82.89573396
,31.8,5.769424312,0.114071811,57249.82687,1.492820768,83.70547243
,32,5.900186888,0.115157896,58077.74034,1.484968398,84.47247791
,32.2,5.805457409,0.116269821,58665.21009,1.484095923,85.27892889
,32.4,5.977819855,0.117375236,58714.52019,1.495874448,86.00539277
,32.6,6.45138806,0.118477747,58451.02966,1.514196581,86.67159274
,32.8,6.738572272,0.119597914,57920.37338,1.538189877,87.27204903
,33,6.692096542,0.120745489,57769.8279,1.553022116,87.86264287
,33.2,6.766267842,0.121902489,57860.60396,1.560438227,88.39954667
,33.4,6.964415346,0.123062992,58246.71697,1.56218318,89.09861768
,33.6,6.731550014,0.124263596,58878.25454,1.557820779,89.83384627
,33.8,6.998755351,0.125443277,59992.31896,1.542552281,90.64906416
,34,6.816642348,0.126664382,60980.13309,1.529901275,91.43798317
,34.2,6.847536682,0.12788371,61557.82638,1.525538851,92.10418211
,34.4,6.910879713,0.129113079,62200.25967,1.522485152,92.91939945
,34.6,7.025808956,0.130351472,62728.79943,1.522048901,93.70174497
,34.8,6.876970821,0.131619654,62767.89708,1.53339121,94.4621756
,35,7.052636998,0.132879179,62449.34082,1.551277125,95.06482294
,35.2,6.960375415,0.134169053,62154.42541,1.570035547,95.71129843
,35.4,7.323252709,0.135441862,61947.12218,1.583995265,96.21861866
,35.6,7.102016552,0.136766092,61717.65147,1.600572488,96.83989225
,35.8,7.241895595,0.138079739,61661.05028,1.612351014,97.46554976
,36,7.320199527,0.139410756,61963.90738,1.614532219,98.07148419
,36.2,7.22875959,0.14076614,62474.91609,1.612787259,98.78918158
,36.4,7.135653339,0.142135341,62839.18273,1.612351026,99.353478
,36.6,7.479380358,0.143489437,63149.23151,1.615840934,100.0394008
,36.8,7.268948253,0.14489365,63391.8896,1.62107586,100.6880675
,37,7.34973755,0.146292679,63499.24108,1.628055728,101.2600346
,37.2,7.648526279,0.147691512,63756.98581,1.632418123,101.9097984
,37.4,7.491339785,0.14913444,64125.11325,1.634163107,102.5727097
,37.6,7.592091905,0.150574903,64586.56132,1.631545648,103.1348151
,37.8,7.686185204,0.152030159,65443.65475,1.621948313,103.8985335
,38,7.89676561,0.153492465,66292.23259,1.612350968,104.6239019
,38.2,8.394406952,0.154950573,66955.5461,1.608424748,105.4029613
,38.4,8.446889866,0.156452662,67545.83632,1.605371049,106.1633924
,38.6,8.506858993,0.157969311,67995.39066,1.603626076,106.7967201
,38.8,8.569321889,0.15950111,68406.75704,1.604498554,107.5538637
,39,8.773233817,0.161038904,68943.2775,1.60144484,108.283615
,39.2,9.16602259,0.162579729,69758.88033,1.59315621,109.1404707
,39.4,9.02462161,0.164171217,70713.1398,1.581377686,109.8691252
,39.6,9.3350307,0.165748949,72238.25143,1.562183009,110.8914347
,39.8,9.300961356,0.167365218,73488.08102,1.546914536,111.7176088
,40,9.694572081,0.168969565,74896.57856,1.532082267,112.6895153
,40.2,9.905957477,0.170602029,76007.66794,1.525102383,113.709633
,40.4,9.733757184,0.172276227,76713.13034,1.52335743,114.542381
,40.6,9.831976132,0.173949369,77167.38434,1.528156083,115.5066166
,40.8,9.777924084,0.175649288,77461.0018,1.533390991,116.2769091
,41,9.906924128,0.177354364,77775.08309,1.538625891,117.1228065
,41.2,9.830816862,0.179089911,78735.94278,1.53382723,118.2009967
,41.4,9.641129633,0.180850303,79390.44795,1.531646037,119.0337448
,41.6,10.0788184,0.182587128,80140.74499,1.530337274,120.0965964
,41.8,10.07800487,0.184370338,80835.47616,1.529464791,121.1364364
,42,10.20158257,0.186163241,81121.11424,1.534699687,122.038216
,42.2,9.869184482,0.188004171,80946.7443,1.546914494,122.7789228
,42.4,10.30103734,0.189813316,80589.16216,1.564800384,123.6565974
,42.6,10.19037938,0.191676325,80281.56097,1.579632626,124.3425191
,42.8,10.31519351,0.193542573,79635.313,1.602317205,125.1007589
,43,10.42793969,0.195428323,79117.28796,1.621511847,125.7757238
,43.2,10.54941956,0.19733248,79093.41139,1.630236679,126.4090515
,43.4,10.79903475,0.199247382,79499.76389,1.632417868,127.2637154
,43.6,10.37425629,0.201225853,80121.1812,1.628927971,128.0088047
,43.8,10.73577834,0.203172401,81132.69149,1.620639339,128.9653713
,44,10.57184673,0.2051732,82239.91771,1.610605787,129.8671497
,44.2,10.87553376,0.2071634,83199.55756,1.604934614,130.8730237
,44.4,11.00697967,0.209184941,83737.3937,1.604498361,131.6214021
,44.6,10.8288933,0.211247184,84005.87361,1.611042009,132.5429036
,44.8,11.15586852,0.213296864,84142.72707,1.616713128,133.222252
,45,11.61763536,0.2153583,84170.70139,1.625001687,134.0045993
,45.2,11.57683025,0.217473455,83918.91095,1.638961437,134.8088591
,45.4,11.5044032,0.219611949,83622.81019,1.651612465,135.4279416
,45.6,11.40534658,0.221773717,83271.23354,1.666880947,136.1335861
,45.8,12.00355893,0.223911261,82996.87089,1.679531913,136.6956937
,46,12.00184733,0.226109769,82669.81323,1.696109112,137.4166787
,46.2,12.63000715,0.228288946,82705.50219,1.702652685,137.9733078
,46.4,12.6116472,0.230532586,83098.49275,1.703961413,138.7052501
,46.6,12.35364827,0.23281465,83541.37763,1.702652712,139.3385762
,46.8,12.6198481,0.235085069,84333.57977,1.696109058,140.1658472
,47,12.95593796,0.237373647,85231.59525,1.687384187,140.9690128
,47.2,12.63469101,0.239728535,85997.13355,1.680840587,141.7031451
,47.4,12.83681062,0.242072612,86865.83482,1.67473318,142.6191696
,47.6,12.94739908,0.244446267,87620.45758,1.669062025,143.3533037
,47.8,13.00140317,0.246847564,88347.32936,1.666008326,144.2123497
,48,13.15109118,0.249266573,88839.33191,1.666444556,145.0133233
,48.2,13.27498122,0.251711643,89355.75229,1.666880787,145.8811354
,48.4,13.13843029,0.254198576,89634.94136,1.669498253,146.5626738
,48.6,13.25815211,0.256693554,89800.11837,1.676041873,147.3976144
,48.8,13.35457208,0.259215009,90002.87261,1.679531801,148.0495694
,49,13.29955177,0.261771869,90400.01969,1.680840533,148.8231488
,49.2,13.35519232,0.264347174,91073.26091,1.678659319,149.7216409
,49.4,13.44327936,0.266946281,91661.86304,1.676478102,150.4656366
,49.6,13.01964092,0.269604979,92326.84584,1.674296932,151.3750839
,49.8,13.28411786,0.27224511,92735.52261,1.67473315,152.1026447
,50,13.63845384,0.274905845,92940.64558,1.679095539,152.8773213
,50.2,13.7731198,0.27760788,93018.94354,1.686511641,153.7155492
,50.4,14.0617117,0.28034063,92957.25959,1.69392773,154.3368246
,50.6,13.99168263,0.283096966,93054.65383,1.700471367,155.1224573
,50.8,14.1920688,0.285877066,93641.62613,1.699162623,155.9563022
,51,14.19608266,0.2886981,94206.73608,1.69829014,156.7474136
,51.2,14.09025914,0.291554697,94523.09025,1.700471361,157.433335
,51.4,14.56687812,0.294401556,95311.16224,1.696981381,158.3318293
,51.6,14.32458647,0.297324406,95750.31697,1.696981405,159.0035057
,51.8,14.67056168,0.300237872,95783.607,1.705269971,159.8011927
,52,14.5955062,0.303208455,95977.63089,1.709632399,160.5484748
,52.2,14.73927967,0.306194378,96258.73176,1.711377355,161.1872813
,52.4,14.89719349,0.30920953,96351.05938,1.717484729,161.9641487
,52.6,14.64655752,0.312281767,96484.10137,1.721410931,162.5974747
,52.8,14.95340168,0.315348032,97055.7947,1.719665935,163.4335123
,53,14.72522171,0.318480535,97690.16665,1.716612264,164.2246223
,53.2,15.11609475,0.321603567,98251.44661,1.713994776,164.9488965
,53.4,15.62844457,0.324750204,98901.65332,1.711813518,165.8309547
,53.6,15.8670393,0.327946268,99879.59231,1.704397383,166.7623197
,53.8,15.86100115,0.331190728,100643.342,1.699162481,167.5468567
,54,15.67439927,0.334479451,101444.5154,1.69480008,168.4267206
,54.2,15.86055823,0.337776715,102803.9908,1.683457772,169.496146
,54.4,16.06917772,0.341105674,104015.7677,1.672987946,170.391352
,54.6,16.25033369,0.344469848,104847.7686,1.670370479,171.4257145
,54.8,15.99048871,0.347896778,105001.4077,1.675605407,172.1686125
,55,16.04099929,0.35133777,104798.8189,1.686511453,172.9531501
,55.2,16.04657276,0.354816262,103760.482,1.710504761,173.6653692
,55.4,16.29177602,0.358313819,102886.196,1.730135627,174.1726898
,55.6,16.34809446,0.361858963,102470.6979,1.744095371,174.8443671
,55.8,16.45183504,0.365436695,102501.672,1.749330265,175.4196217
,56,16.4241033,0.369059079,102937.9505,1.74933027,176.1581381
,56.2,16.38554893,0.37271835,103990.8745,1.741041676,177.0851187
,56.4,17.45030975,0.376341435,104673.4423,1.736679156,177.7995348
,56.6,18.14229867,0.380025619,105161.5793,1.736679087,178.6454356
,56.8,18.93329768,0.383740165,105543.4465,1.737115257,179.3291702
,57,19.20258468,0.387526541,105866.6968,1.739296442,180.0950812
,57.2,18.71718088,0.391400541,106366.7407,1.738860248,180.9661778
,57.4,18.90574518,0.395269023,107280.0823,1.731007877,181.7638644
,57.6,19.14256318,0.399173291,109021.2853,1.713121935,182.8694492
,57.8,19.40350488,0.403115201,110733.5278,1.695235991,183.8610791
,58,19.39485058,0.407114456,112699.6069,1.676041349,185.0225444
,58.2,19.54927499,0.411143335,114632.0164,1.659900386,186.3187848
,58.4,19.62631076,0.415217622,115771.5583,1.652920512,187.3115091
,58.6,19.83979899,0.419324035,116929.8689,1.648121832,188.5628249
,58.8,19.92639044,0.423480066,117135.8753,1.652920484,189.4098185
,59,20.12738445,0.427670361,117171.4783,1.661209062,190.3970655
,59.2,19.99679307,0.431924638,117241.5407,1.669497671,191.4489581
,59.4,20.23646471,0.436197238,117338.9356,1.67647752,192.3644352
,59.6,20.35506379,0.440520684,117326.7853,1.684766105,193.215264
,59.8,20.22029157,0.444904294,118227.2526,1.682584909,194.3526228
,60,20.52234752,0.449303032,119339.4526,1.676913738,195.4428681
,60.2,20.53982953,0.453764852,120269.5748,1.67298756,196.4344967
,60.4,20.77780216,0.458256933,121572.9733,1.666443911,197.707727
,60.6,20.95960308,0.462797876,122766.1151,1.659027784,198.74976
,60.8,20.86182226,0.467402917,123674.2963,1.656846584,199.9890211
,61,21.12806336,0.472030274,124118.7632,1.659900254,201.1044678
,61.2,20.98242394,0.476731225,124328.6807,1.664262687,202.0566492
,61.4,20.85175425,0.481478278,124474.4546,1.670370086,203.1677111
,61.6,21.12421343,0.486246263,124203.4674,1.680403624,204.0103229
,61.8,21.29931315,0.491068689,124102.8358,1.690437171,205.0315367
,62,21.48189378,0.495938989,124160.8225,1.697417025,205.9760501
,62.2,22.22611177,0.500821278,124436.7192,1.701343132,206.8471536
,62.4,22.76979384,0.505765737,124438.924,1.710067919,207.8365938
,62.6,23.21195584,0.510766613,124605.8807,1.714430296,208.6134635
,62.8,23.80554599,0.515807848,124947.6309,1.717920175,209.6281057
,63,23.59451947,0.520952721,125447.1534,1.719228921,210.583574
,63.2,23.66638743,0.52613073,125918.8548,1.720101399,211.4513866
,63.4,23.82561418,0.531354827,126832.0614,1.717047692,212.5482057
,63.6,23.9440613,0.536634117,127587.7446,1.71661144,213.6636511
,63.8,23.81371199,0.541982968,128038.5563,1.717920179,214.5117399
,64,23.99537921,0.5473649,127962.8714,1.726208757,215.3773616
,64.2,24.06554089,0.552808246,128261.1828,1.730571169,216.3810431
,64.4,23.86527215,0.558324156,128462.8707,1.734497365,217.1842065
,64.6,23.93541631,0.563877648,128886.8591,1.736678568,218.1670697
,64.8,23.96145208,0.569489777,129256.5082,1.737987292,218.9658517
,65,24.40184814,0.575131059,130062.9595,1.734933558,219.9552909
,65.2,24.28724664,0.580865527,130818.7316,1.733188603,221.0389598
,65.4,24.51627957,0.586635,131446.4529,1.731443615,221.936358
,65.6,24.78357832,0.592460082,132191.0944,1.729698623,223.0605703
,65.8,24.77711782,0.598361602,132538.6483,1.731443592,223.9141378
,66,25.04689407,0.60430419,132782.512,1.735369743,224.8345466
,66.2,25.69275499,0.610281729,132943.1724,1.741040825,225.8239876
,66.4,26.11561244,0.616334111,132720.0875,1.74976562,226.5274442
,66.6,26.42113884,0.622454935,132760.7791,1.757181701,227.4478527
,66.8,26.43792832,0.62865618,132993.8571,1.760235392,228.1852739
,67,26.55622002,0.634913134,133463.4326,1.76241659,229.2470293
,67.2,26.90997661,0.641217398,133838.4877,1.76328904,230.0162288
,67.4,27.36939558,0.647578081,134689.1335,1.758926579,230.8862354
,67.6,27.58417678,0.654018868,136006.7222,1.750637967,232.041128
,67.8,27.41120464,0.660549844,136966.8209,1.745403084,232.9702994
,68,27.81067866,0.667141827,137997.303,1.740604388,234.0408228
,68.2,27.93722951,0.673785202,139107.452,1.735805718,235.2121509
,68.4,28.14282145,0.680456321,139957.8039,1.732315765,236.1807705
,68.6,28.46155843,0.687220755,140503.7832,1.733624461,237.3126536
,68.8,28.79276558,0.694052458,141090.9239,1.732751947,238.2199141
,69,28.91344897,0.700966632,141913.2481,1.730134486,239.2959146
,69.2,29.1689161,0.707941437,143326.4564,1.721845871,240.5943471
,69.4,29.06075901,0.715010207,144534.8868,1.715302257,241.6802071
,69.6,29.05160655,0.722143444,146513.2757,1.703087492,243.1134122
,69.8,29.36611658,0.729327133,147833.1458,1.696543838,244.237625
,70,29.34945266,0.736604744,149150.1905,1.691745182,245.552492
,70.2,29.53996167,0.743941909,150061.2071,1.691745165,246.9166676
,70.4,29.70216871,0.751354618,149683.5797,1.703959918,248.0397844
,70.6,30.5799411,0.758794789,149127.7721,1.71573836,248.8791137
,70.8,31.1348598,0.76633087,148644.7702,1.727516833,249.8992352
,71,31.83870634,0.773932855,148169.9196,1.738422807,250.8207428
,71.2,32.18641627,0.781634699,147835.064,1.747147606,251.6074739
,71.4,32.73380984,0.789400763,148266.7398,1.749328762,252.7075829
,71.6,32.64965259,0.797286421,148900.8151,1.748456291,253.6257978
,71.8,32.83257608,0.805233639,149781.0707,1.747147547,254.8157537
,72,32.79498931,0.813275031,151166.1167,1.740167686,256.0133782
,72.2,32.8539094,0.821390907,152230.7029,1.735369024,257.0521237
,72.4,33.06924501,0.829577983,153784.3398,1.727080414,258.422874
,72.6,33.20468916,0.837852613,155576.8302,1.716610604,259.875803
,72.8,33.66129772,0.846189275,156636.217,1.711811904,260.9715284
,73,34.36085637,0.854593441,157248.7156,1.712684326,262.2107957
,73.2,34.72923916,0.863103926,158234.0416,1.711375567,263.6242807
,73.4,35.14503612,0.871696854,158270.2276,1.717919154,264.621391
,73.6,35.19554228,0.880399956,158041.1796,1.727080221,265.542894
,73.8,35.7128237,0.889159934,158807.7728,1.727952656,266.8117446
,74,36.15187689,0.898013066,159791.9586,1.725771406,268.0312875
,74.2,36.29802862,0.906974399,160578.4931,1.72446267,269.137968
,74.4,36.70793103,0.916008423,162712.307,1.711811628,270.7355347
,74.6,36.72757993,0.925158966,164388.2013,1.701778073,272.0295832
,74.8,37.12830058,0.934376209,165811.0482,1.695670653,273.6194798
,75,37.3168296,0.943700114,167176.4247,1.689999501,275.0800795
,75.2,37.7275054,0.953103066,168565.9411,1.685637046,276.6677847
,75.4,37.61479654,0.962634969,169339.2944,1.686073298,277.9300563
,75.6,37.80078422,0.972243032,170288.2679,1.687382006,279.4596866
,75.8,38.03085608,0.981944593,170900.4414,1.689999438,280.6419731
,76,38.36034435,0.99173705,171273.6742,1.695234302,281.9184926
,76.2,38.74098894,1.001625173,171402.1994,1.703086614,283.3100635
,76.4,38.65940498,1.011643151,171376.1116,1.710066482,284.3751055
,76.6,39.00923133,1.021733269,171591.3402,1.716610072,285.7491444
,76.8,39.37152257,1.031923905,172346.9329,1.716173797,286.9347194
,77,39.85652727,1.042208809,173265.3486,1.715301269,288.2473992
,77.2,40.4580048,1.052589307,173892.0066,1.718354904,289.7014281
,77.4,40.75368144,1.06309434,174203.2027,1.722281048,290.7927703
,77.6,41.19828112,1.073695115,174171.9224,1.730569593,292.1032583
,77.8,41.77973872,1.084393398,173834.9962,1.739730607,293.0685949
,78,41.66307582,1.095245208,173608.0621,1.748891688,294.262384
,78.2,42.35391566,1.10615287,174239.1086,1.749327864,295.4189248
,78.4,42.63660969,1.117196988,175940.4585,1.741039252,296.9211627
,78.6,42.75869736,1.128362586,177266.2379,1.734931862,298.142895
,78.8,42.60909765,1.139658285,179362.6051,1.724025843,299.7820947
,79,43.06605608,1.151026982,180484.3793,1.721408352,301.2273574
,79.2,43.47057619,1.162513333,181152.6774,1.721844556,302.455666
,79.4,43.69618376,1.174126972,181095.2643,1.72969688,303.7661518
,79.6,44.2263089,1.185837248,181311.4943,1.734059243,304.8728367
,79.8,44.78803385,1.197662987,181736.3213,1.737985362,306.2622181
,80,45.73748256,1.209582098,182997.5934,1.7340591,307.6888577
,80.2,45.93472469,1.221670514,184316.2944,1.728824187,309.0070137
,80.4,46.16855842,1.233877962,185764.5024,1.722716788,310.3668075
,80.6,46.56046513,1.246197728,187649.8925,1.714864408,312.1155844
,80.8,46.88911518,1.258645325,188180.6973,1.716609343,313.3406061
,81,47.05216425,1.271228923,188383.5601,1.722280465,314.6971122
,81.2,47.19605571,1.283940161,188918.7574,1.726206623,316.2157859
,81.4,47.6095162,1.296761265,189398.3165,1.728387791,317.4035529
,81.6,48.04958228,1.309709537,190294.8727,1.728823991,318.9309947
,81.8,48.29575637,1.322800662,192017.2854,1.721407867,320.346671
,82,48.40212251,1.336032514,193811.6675,1.714427999,321.9573846
,82.2,48.56754417,1.349393428,195447.1471,1.710065572,323.7510848
,82.4,48.95593812,1.362873826,196519.7944,1.710065536,325.3519393
,82.6,49.26692842,1.376494783,197086.0367,1.712246713,326.6032579
,82.8,49.67192037,1.390246494,197436.7695,1.717917811,328.1745286
,83,49.47697101,1.404175833,198264.3642,1.719226554,329.6866243
,83.2,50.40279184,1.41817135,199180.1608,1.718790226,331.0212234
,83.4,51.17049782,1.43231781,200406.6121,1.717481431,332.7239841
,83.6,51.7559588,1.446618462,201966.5685,1.712246482,334.211981
,83.8,52.23988495,1.461069411,204244.2967,1.703521615,336.129501
,84,52.79617769,1.475660893,205210.441,1.703957804,337.7391244
,84.2,53.09617095,1.490415721,205260.3958,1.710065152,339.0298891
,84.4,53.6141418,1.505304443,205049.1342,1.719226167,340.5726719
,84.6,53.83337734,1.520362505,204508.0543,1.729259692,341.7385227
,84.8,54.43117864,1.535546803,202716.2112,1.749762967,342.8956127
,85,54.90081758,1.550892158,202456.1491,1.757615262,344.0713281
,85.2,55.18321727,1.566404114,203827.2298,1.754125307,345.6951922
,85.4,55.71687594,1.582055313,205094.4828,1.750635327,347.0319797
,85.6,56.33788911,1.597778476,206760.9253,1.745400376,348.7073465
,85.8,56.94802202,1.613901094,208784.8625,1.736239256,350.2216426
,86,57.60393117,1.629941043,210183.8207,1.732749266,351.8181173
,86.2,57.87621966,1.646248662,210555.1864,1.737111651,353.4091098
,86.4,58.16013104,1.662719269,210957.3351,1.739729071,354.7042576
,86.6,58.59045958,1.679345771,212019.5112,1.739292789,356.3686657
,86.8,58.67046209,1.696162391,212899.8592,1.739292782,357.7207888
,87,59.24634863,1.713115298,214869.6271,1.732312872,359.4082087
,87.2,59.75897113,1.730242706,218260.2307,1.71660815,361.4944709
,87.4,59.98699996,1.747560885,220990.3142,1.704829623,363.2870763
,87.6,60.6676446,1.765023228,223888.5028,1.693487296,365.4862001
,87.8,61.38736836,1.782658593,225761.7913,1.687379856,367.2141631
,88,61.73762701,1.800495512,226447.1862,1.68999727,369.0166315
,88.2,62.03793329,1.818514782,226262.7633,1.699158302,370.8322485
,88.4,62.39562327,1.836711374,225590.1751,1.711373014,372.4681678
,88.6,63.09193464,1.855068608,224906.1797,1.722715211,373.7435964
,88.8,63.10592334,1.873655202,224789.6533,1.730131306,375.0617522
,89,63.73394636,1.89238806,225128.5733,1.735802378,376.6001542
,89.2,64.08735801,1.911327041,225080.2117,1.744090921,378.1330754
,89.4,65.17462074,1.930407898,225392.6047,1.749325707,379.6944923
,89.6,65.38818477,1.949737909,225211.7528,1.75630554,380.9063655
,89.8,66.40798885,1.969208899,224650.8198,1.766775221,382.2387755
,90,66.4925209,1.988936836,224763.9873,1.771573862,383.5613151
,90.2,67.26513912,2.008817572,225623.5017,1.770701306,384.876191
,90.4,67.58591433,2.028927884,226444.5166,1.771137516,386.3762404
,90.6,68.06807801,2.049229542,229158.7333,1.759358969,388.2378799
,90.8,68.52940764,2.069736475,231724.4228,1.748016666,389.9077674
,91,68.89917738,2.090455483,234273.7303,1.737983096,391.7376297
,91.2,69.82140505,2.111346167,235910.8797,1.734929323,393.6661143
,91.4,70.48316303,2.132464038,238165.1582,1.726640685,395.4170871
,91.6,70.79292391,2.153817185,239508.8447,1.725768179,397.3729572
,91.8,71.749997,2.175342199,240444.6935,1.727513054,399.2094008
,92,72.13540725,2.197121232,241109.8349,1.730130459,400.8650435
,92.2,72.34188884,2.219130672,242398.0031,1.728385478,402.5031528
,92.4,73.07919248,2.241326416,243357.0494,1.730130367,404.3615085
,92.6,73.33635937,2.263776854,245372.9524,1.723586735,406.0390644
,92.8,73.99038522,2.286426602,248805.3611,1.710499456,408.4036437
,93,74.47546578,2.309315004,252724.0918,1.694794754,410.8153373
,93.2,74.82488324,2.33244237,255891.8957,1.683452461,412.9278967
,93.4,75.58863188,2.355774835,259029.3617,1.674291336,415.4831335
,93.6,76.4646718,2.379335133,259540.648,1.680398625,417.7666321
,93.8,77.16302823,2.403144293,259723.0321,1.68606969,419.4770652
,94,77.55389881,2.427212907,259620.2583,1.694358222,421.428554
,94.2,78.18145327,2.451507712,259459.6709,1.702646733,423.4490767
,94.4,78.92753808,2.476038805,259351.4586,1.70875403,425.1145861
,94.6,79.25089501,2.500844152,259728.5397,1.712680165,427.15921
,94.8,80.04266452,2.525867889,259374.9938,1.719659938,428.694329
,95,80.16832658,2.551186962,258069.1248,1.734492103,430.6414321
,95.2,81.20422651,2.576700386,257294.1439,1.744525535,431.9387821
,95.4,81.67802625,2.602507296,257790.6086,1.749324134,433.8201456
,95.6,82.35605653,2.62855995,258632.7329,1.75019655,435.300477
,95.8,83.16010289,2.654866139,259968.2084,1.749760233,437.2497799
,96,84.34311239,2.681411726,262391.4608,1.742344033,439.3053723
,96.2,84.62786628,2.708283109,264272.1064,1.737109122,441.0870239
,96.4,85.54411398,2.735382152,265827.946,1.735364073,443.1776758
,96.6,86.23566117,2.762767667,267006.5548,1.734927767,444.8618128
,96.8,86.99123351,2.790424196,268680.0652,1.733618975,447.0160156
,97,87.38980622,2.818382049,269146.7728,1.738417581,448.762605
,97.2,88.03129694,2.846604826,269546.1288,1.744961124,450.7162895
,97.4,88.51132215,2.875121861,270000.9823,1.748887241,452.2360645
,97.6,89.37571533,2.90390005,270375.7193,1.754122041,454.0977107
,97.8,90.24921522,2.932966692,271554.0086,1.753249476,455.7456915
,98,90.75988883,2.96234933,273760.5057,1.747578305,457.8012768
,98.2,91.65409689,2.992001914,277069.725,1.736235974,460.1987329
,98.4,92.37435625,3.021963815,280142.0002,1.725329901,462.2740439
,98.6,92.9348115,3.052237252,284096.8408,1.712242643,464.9728209
,98.8,93.33379803,3.082825477,286577.1231,1.705699004,467.0700427
,99,94.103004,3.113696768,289311.7199,1.70046405,469.9342759
,99.2,94.95037463,3.144873065,290240.4099,1.702208932,471.8912503
,99.4,95.63877129,3.17637304,290922.8365,1.707007509,474.2448754
,99.6,96.55177476,3.208174758,291214.8115,1.711806064,476.0517375
,99.8,97.20096328,3.240313251,291350.2461,1.718785844,478.2004624
,100,97.97823822,3.272766317,291816.1556,1.723584412,480.2220838
,100.2,98.98843907,3.305529969,292734.5514,1.725329276,482.0694891
,100.4,99.67574694,3.338644126,292932.6313,1.731872811,484.2269803
,100.6,100.4021089,3.372088375,293296.7788,1.737107622,486.370227
,100.8,101.2465704,3.405860783,294257.9224,1.737980022,488.1979069
,101,102.2066347,3.439965045,295003.7344,1.74059737,490.2009047
,101.2,102.7605976,3.474438772,295397.3827,1.745395956,492.3200434
,101.4,103.5915825,3.50924051,296346.3115,1.746268356,494.075406
,101.6,104.0738773,3.544414923,298223.5041,1.744087111,496.3468501
,101.8,105.1984687,3.579900319,299497.7229,1.743650763,498.1635776
,102,106.238965,3.615747764,301788.842,1.739288265,500.3922956
,102.2,106.897487,3.651980473,305192.4587,1.730563406,503.001226
,102.4,107.7423333,3.688565003,307900.0654,1.725328448,505.6211161
,102.6,108.5138995,3.725521925,309412.0133,1.724455895,507.6745159
,102.8,109.7264001,3.762821108,310971.3181,1.72445578,510.1070418
,103,110.3355954,3.800534959,310627.9876,1.732744278,512.1067483
,103.2,111.3557695,3.838600531,309374.6561,1.744086414,513.610097
,103.4,112.4266385,3.877045388,308522.3622,1.754992303,515.6306298
,103.6,113.193743,3.915898044,307352.2884,1.766770701,517.4692669
,103.8,113.9075333,3.955144713,306553.2454,1.775059185,518.8838586
,104,114.6137723,3.994786283,306928.4714,1.778112794,520.6720918
,104.2,115.5113225,4.03481353,307844.3716,1.778548946,522.6904309
,104.4,116.2099456,4.075256067,308586.4944,1.778985117,524.3712837
,104.6,117.09239,4.116092852,310097.1009,1.777676312,526.4915242
,104.8,118.3808157,4.157313201,311643.8557,1.775931228,528.2655226
,105,119.3155488,4.198970982,313003.2693,1.775931137,530.1841512
,105.2,120.0455281,4.241060801,315350.7764,1.772441149,532.4983334
,105.4,120.9701427,4.283560622,316665.7723,1.77200482,534.1879552
,105.6,122.0078498,4.326479997,318568.8277,1.769823521,536.4385903
,105.8,122.9314958,4.369838239,320795.5253,1.764588558,538.41858
,106,123.941607,4.413626334,323409.6771,1.758481108,540.711948
,106.2,124.7685945,4.457866469,325114.732,1.75717231,543.0513337
,106.4,125.3483888,4.502567337,327060.9574,1.754991057,545.4849492
,106.6,126.4822652,4.547680942,329338.5768,1.750192314,547.5504084
,106.8,127.932253,4.593226994,330799.3954,1.750628414,549.9621223
,107,128.6199991,4.639280841,332455.627,1.749755869,552.2204239
,107.2,129.7078935,4.685770934,334449.8172,1.746702089,554.3012232
,107.4,130.4745378,4.732748139,337359.9344,1.741030905,556.971518
,107.6,131.8959399,4.780153815,338841.9733,1.741903247,559.5070493
,107.8,132.9744566,4.828058508,340046.1228,1.742339383,561.458553
,108,133.9497212,4.876450869,340907.5958,1.744956725,563.6938484
,108.2,134.9798246,4.925325602,342074.2808,1.746701582,566.1428112
,108.4,135.8451016,4.974702282,341880.6386,1.753245086,567.9858362
,108.6,137.2428192,5.024539778,342267.5798,1.758479822,570.3175627
,108.8,138.3592203,5.074896616,343279.7202,1.759352189,572.2219519
,109,139.3024721,5.125770722,344734.7904,1.759352098,574.4528647
,109.2,140.4203755,5.177144517,345535.4496,1.762841903,576.7856838
,109.4,141.838571,5.229014693,348055.8656,1.757606897,578.983732
,109.6,143.0012407,5.281422926,351121.1563,1.751499436,581.7307357
,109.8,144.2753228,5.334350282,354314.0205,1.744955733,584.5588251
,110,145.0309461,5.387843579,357150.5379,1.739284553,587.1502293
,110.2,146.1609116,5.441849587,359772.2309,1.734049578,589.6057699
,110.4,147.8873786,5.496358977,360359.8309,1.737975563,592.247594
,110.6,148.4730025,5.55149123,360484.2866,1.742774133,594.3075687
,110.8,149.4978667,5.607148468,360166.4199,1.750626332,596.6798328
,111,150.8979014,5.663340595,360075.1195,1.757169782,598.8307666
,111.2,151.5960024,5.720145888,359527.9321,1.765022009,600.5751744
,111.4,152.9488446,5.777478781,361161.3725,1.765021881,603.0274324
,111.6,154.2745532,5.835389569,363309.8719,1.762404318,605.6626761
,111.8,155.3318296,5.893899763,364027.188,1.764149168,607.5626843
,112,156.8978177,5.952964289,363818.3789,1.770256357,609.6259632
,112.2,158.1487763,6.012643197,364606.4025,1.772001189,611.951116
,112.4,159.6034943,6.07290828,363890.5688,1.780507699,613.888385
,112.6,160.5784331,6.133810489,364121.8844,1.785524346,615.8245506
,112.8,161.7504729,6.195311592,366548.9215,1.781598084,618.1403888
,113,162.9286548,6.257430261,370471.087,1.771782602,620.7224887
,113.2,164.3459548,6.320157257,374921.4895,1.760658383,623.5100424
,113.4,165.4827502,6.383533065,380269.6957,1.746262405,626.7325935
,113.6,166.9335471,6.447524927,384076.193,1.737101259,629.4368718
,113.8,168.0996771,6.512178159,386363.3145,1.735356193,632.4402794
,114,169.5739825,6.577457804,387075.4872,1.739282197,634.9834885
,114.2,170.7561305,6.643412571,387281.4341,1.744516943,637.1683877
,114.4,172.2518597,6.71000915,388360.5822,1.748006705,639.9066356
,114.6,173.5860627,6.77728566,389433.5804,1.749751529,642.0356565
,114.8,174.2719835,6.845280791,392738.9388,1.744516604,645.1080867
,115,175.9346341,6.913894714,395752.2093,1.739717823,647.9876885
,115.2,177.41745,6.983209827,396886.2501,1.74233511,650.8234567
,115.4,178.7420637,7.053231763,397609.0639,1.745388649,653.1343684
,115.6,180.4235191,7.123933674,398274.609,1.749750867,655.8956326
,115.8,181.777862,7.195367558,397085.6407,1.759784211,657.7562017
,116,183.3193041,7.267506766,396525.9621,1.768072582,659.9323442
,116.2,184.6334786,7.340385708,399996.3427,1.761965122,662.9478097
,116.4,186.1081242,7.413986286,401882.7875,1.760220027,665.2674914
,116.6,187.891346,7.488306086,404188.6242,1.758038664,668.1372349
,116.8,189.1960149,7.563404054,407942.4108,1.750186256,671.2414544
,117,191.0771809,7.639218454,411310.1605,1.744078744,674.2481659
,117.2,192.1594488,7.715847335,411647.6349,1.74800478,676.4582684
,117.4,193.4912119,7.793229719,413785.7236,1.747132175,679.4638746
,117.6,194.8719429,7.87138617,414516.8789,1.751494419,682.312792
,117.8,196.3773578,7.950319799,416047.6289,1.751930511,684.737666
,118,197.9933104,8.030038991,418939.6609,1.748004215,687.6753437
,118.2,199.5642043,8.110562196,423279.5855,1.739715549,691.1762238
,118.4,201.3687779,8.19187905,426155.2589,1.735352999,693.9353001
,118.6,202.952726,8.274027523,431360.0095,1.724883147,697.6158814
,118.8,204.2927496,8.35701738,437515.7414,1.711795894,701.5681984
,119,206.2358829,8.44080132,441485.1281,1.706124623,705.0438849
,119.2,207.7021128,8.525458482,444190.754,1.704379535,708.0725055
,119.4,209.163215,8.610966351,448814.2712,1.698272074,712.081803
,119.6,211.0002709,8.69730861,452985.9966,1.692164578,715.4917447
,119.8,212.6857541,8.784528287,454693.5188,1.695654318,719.1986276
,120,214.5233645,8.872614221,456573.8098,1.697399095,722.5658376
,120.2,216.1162089,8.96160147,458250.8639,1.700452605,726.3329826
,120.4,217.7513461,9.051479845,458696.0208,1.70525106,729.1074
,120.6,219.5128124,9.14225304,457034.9737,1.718338007,732.2587506
,120.8,221.1426683,9.233946997,457313.3919,1.723572696,734.9827655
,121,223.0311476,9.326545203,457830.8797,1.72880736,738.002631
,121.2,224.6689546,9.420561631,461378.0503,1.725317307,741.7884067
,121.4,226.6777832,9.515031217,463210.2107,1.725753352,744.5847475
,121.6,228.5475834,9.609979139,467798.8867,1.71920962,748.6466523
,121.8,230.4454453,9.706359248,470089.5032,1.719209439,752.3042349
,122,232.2857412,9.80371167,470422.4413,1.724880342,755.5531085
,122.2,234.0859427,9.902044725,468622.1147,1.735786088,757.9582723
,122.4,235.915941,10.00136373,467610.1114,1.74538312,761.1205849
,122.6,237.9529627,10.10166711,466484.5157,1.754543893,763.3975519
,122.8,239.4989104,10.20301064,468370.8284,1.755852452,766.7209316
,123,241.6179833,10.30533458,472195.0452,1.75018117,770.0826722
,123.2,243.4598176,10.40870488,476740.3565,1.741892497,773.1923923
,123.4,245.4645697,10.51310314,482156.7265,1.732731337,777.2685476
,123.6,247.0780882,10.61857608,486049.2462,1.726623871,780.6248013
,123.8,249.0167723,10.72508741,489386.9698,1.724006267,784.562895
,124,251.2240403,10.83265116,491528.409,1.724878528,788.0287345
,124.2,252.9385588,10.94132814,492641.7753,1.727932018,790.9642328
,124.4,255.0381457,11.05107137,494871.6775,1.729676761,794.7193422
,124.6,256.6067053,11.16195251,497432.8299,1.728804138,797.8181023
,124.8,258.5457757,11.18750944,499933.9823,1.729676425,801.6082736
,125,259.4746522,11.18744921,503086.3783,1.727931393,805.3195292
,125.2,260.7712975,11.18736486,507100.8075,1.724005145,809.3956736
,125.4,261.6344415,11.18730894,510377.6671,1.720515174,812.7672514
,125.6,262.4742879,11.18725454,514858.1104,1.715280262,817.1052639
,125.8,263.1402346,11.18721155,518642.0155,1.710481603,820.6543483
,126,263.8635931,11.18716479,521156.8449,1.7100453,824.5343425
,126.2,264.2108624,11.1871427,522445.7823,1.713971392,828.6049856
,126.4,264.8127407,11.1871039,522313.6874,1.720951113,831.6829035
,126.6,265.1425368,11.18708295,521419.5293,1.731420749,835.2056825
,126.8,265.7560639,11.1870434,520817.9975,1.73927294,837.928586
,127,265.9976621,11.18702823,520142.9034,1.747997629,840.9801975
,127.2,266.1419098,11.18701945,520230.1056,1.754977398,844.3879199
,127.4,266.8885657,11.18697116,521567.5174,1.758030978,847.9150913
,127.6,266.9454475,11.18696811,521403.1083,1.763702043,850.5086847
,127.8,267.5781119,11.1869273,520100.7535,1.774171641,853.4616911
,128,267.5817421,11.18692773,518631.7631,1.784641308,855.9906352
,128.2,267.8183479,11.18691289,516667.0348,1.795547177,858.0582826
,128.4,268.1181899,11.18689391,513361.167,1.810379177,860.1741437
,128.6,268.0852097,11.18689674,509879.4377,1.825647438,862.102627
,128.8,268.5905695,11.18686428,508095.4773,1.83437211,863.7232233
,129,268.8746025,11.18684633,505740.9355,1.845277978,865.4533873
,129.2,269.0492201,11.18683555,504977.494,1.851821499,867.4114604
,129.4,269.0120797,11.18683866,505089.3696,1.855747628,869.0561498
,129.6,269.5740192,11.18680249,507187.1023,1.854438864,871.3308978
,129.8,269.5435351,11.18680517,508918.0347,1.853566396,873.2363712
,130,269.5134671,11.18680781,513664.3123,1.84396921,875.8968013
,130.2,270.1648526,11.18676577,518035.3494,1.836116898,878.8848719
,130.4,270.2683295,11.18675966,520223.3817,1.833499474,881.0894842
,130.6,270.5086795,11.18674458,522500.669,1.831318271,883.8266227
,130.8,270.3633718,11.18675478,525663.3504,1.826519692,886.7127702
,131,270.5400696,11.18674387,526264.0397,1.82913709,889.0411998
,131.2,270.8357514,11.18672515,528381.0821,1.827392118,891.3531979
,131.4,270.6521691,11.18673787,532378.65,1.821284835,894.4026093
,131.6,271.0219038,11.1867143,534593.3513,1.819976091,896.8110324
,131.8,271.0263661,11.18671468,532935.9119,1.830445753,899.0145461
,132,271.4984435,11.1866844,531118.0896,1.840479131,900.7852543
,132.2,271.2940599,11.18669847,528063.9666,1.853129993,902.1023173
,132.4,271.5822531,11.18668025,524245.6614,1.86839822,903.381041
,132.6,271.5168227,11.18668522,522750.0421,1.876250474,904.8843797
,132.8,271.971427,11.18665608,524777.7756,1.873633012,906.9695647
,133,271.9883702,11.18665565,526405.3393,1.871888068,908.9309224
,133.2,272.1991822,11.1866425,527974.2741,1.870143104,910.6840938
,133.4,272.3326131,11.18663442,528955.7708,1.870579327,912.7648885
,133.6,272.4127924,11.18662984,527371.8195,1.877995329,913.9625237
,133.8,272.6377494,11.18661576,524585.0453,1.889337439,915.2116602
,134,272.6655093,11.18661462,521841.5762,1.900243333,916.1364572
,134.2,272.706582,11.1866126,520296.9606,1.907223103,916.9834583
,134.4,272.9939431,11.18659443,519199.1247,1.913766612,918.0550888
,134.6,273.1024124,11.18658799,521247.1043,1.909840479,919.4072208
,135.3,273.0609142,11.12453676,1.7977E+308,1.857492188,0
,135.5,272.8659835,11.01273705,1.7977E+308,1.764137741,0
,135.7,272.5104661,10.90094786,1.7977E+308,1.6062204,0
,135.9,272.5401904,10.78913342,1.7977E+308,1.380686466,0
,136.1,272.3835343,10.67733119,1.7977E+308,1.116763788,0
,136.3,271.8216671,10.56555554,1.7977E+308,0.795694225,0
,136.5,271.5526835,10.45376068,1.7977E+308,0.518684457,0
,136.7,271.3544246,10.34196118,1.7977E+308,0.300566522,0
,136.9,271.3300652,10.23015028,1.7977E+308,0.143957841,0
,137.1,271.0003415,10.11835941,1.7977E+308,0.03926123,0
,137.3,270.7879376,10.00656084,1.7977E+308,0.010905897,0
,137.5,270.5622209,9.894763141,1.7977E+308,0.012214605,0
,137.7,270.2366574,9.782971992,1.7977E+308,0.003053651,0
,137.9,270.0092765,9.671174405,1.7977E+308,0.003489887,0
,138.1,270.1521604,9.559352539,1.7977E+308,0.009160954,0
,138.3,269.9464129,9.447553533,1.7977E+308,0.013523314,0
,138.5,269.5276592,9.335768495,1.7977E+308,0.026174156,0
,138.7,269.208009,9.223417892,1.7977E+308,0.031845224,0
,138.9,269.0297194,9.111617086,1.7977E+308,0.031845224,0
,139.1,268.8239719,8.99981808,1.7977E+308,0.030100281,0
,139.3,268.4026332,8.888592277,1.7977E+308,0.025301686,0
,139.5,268.1602753,8.776795672,1.7977E+308,0.014832023,0
,139.7,268.2340985,8.664978334,1.7977E+308,0.019630619,0
,139.9,268.0033894,8.553180965,1.7977E+308,0.023556743,0
,140.1,267.7027875,8.441388179,1.7977E+308,0.025301687,0
,140.3,267.5719251,8.329584263,1.7977E+308,0.022684271,0
,140.5,267.3928033,8.217783512,1.7977E+308,0.016576968,0
,140.7,267.1046823,8.105989907,1.7977E+308,0.010469664,0
,140.9,267.0620178,7.994180208,1.7977E+308,0.010469664,0
,141.1,266.8030187,7.882384694,1.7977E+308,0.013959552,0
,141.3,266.4574858,7.770594854,1.7977E+308,0.021811801,0
,141.5,266.2367613,7.658796831,1.7977E+308,0.030100285,0
,141.7,265.8770835,7.547007918,1.7977E+308,0.037952535,0
,141.9,265.8760217,7.435195491,1.7977E+308,0.039261243,0
,142.1,265.4922143,7.323408161,1.7977E+308,0.034462647,0
,142.3,265.4037866,7.211601463,1.7977E+308,0.024429218,0
,142.5,265.1838942,7.099803384,1.7977E+308,0.017885678,0
,142.7,264.6761104,6.988024184,1.7977E+308,0.011342138,0
,142.9,264.51779,6.876222068,1.7977E+308,0.009597193,0
,143.1,264.4609805,6.764413296,1.7977E+308,0.009160957,0
,143.3,264.09215,6.652624984,1.7977E+308,0.01003343,0
,143.5,263.9770966,6.540820032,1.7977E+308,0.011342138,0
,143.7,263.7214257,6.429024299,1.7977E+308,0.015268263,0
,143.9,263.3625798,6.317235333,1.7977E+308,0.020503097,0
,144.1,263.1351988,6.205437746,1.7977E+308,0.024429222,0
,144.3,262.8845203,6.093641686,1.7977E+308,0.025737931,0
,144.5,262.7977567,5.981834878,1.7977E+308,0.018321917,0
,144.7,262.3299115,5.870053059,1.7977E+308,0.01352332,0
,144.9,262.0401263,5.758259564,1.7977E+308,0.011342139,0
,145.1,262.0998046,5.646443154,1.7977E+308,0.009597195,0
,145.3,261.6119901,5.534662643,1.7977E+308,0.008724723,0
,145.5,261.3222048,5.422869148,1.7977E+308,0.00567107,0
,145.7,261.3527612,5.311054648,1.7977E+308,0.005234834,0
,145.9,261.0904338,5.199259352,1.7977E+308,0.009160959,0
,146.1,260.4599216,5.087488199,1.7977E+308,0.012650849,0
,146.3,260.4110166,4.975678909,1.7977E+308,0.014395794,0
,146.5,260.1187351,4.863885577,1.7977E+308,0.01483203,0
,146.7,259.8975945,4.752087581,1.7977E+308,0.015268267,0
,146.9,259.5350043,4.64029886,1.7977E+308,0.013523322,0
,147.1,259.288486,4.528502527,1.7977E+308,0.009597197,0
,147.3,259.1043718,4.416702103,1.7977E+308,0.008288488,0
,147.5,258.7347092,4.304913846,1.7977E+308,0.016576976,0
,147.7,258.3833517,4.193124388,1.7977E+308,0.02661041,0
,147.9,258.3182216,4.081316162,1.7977E+308,0.027482883,0
,148.1,257.8378954,3.96953516,1.7977E+308,0.025737939,0
,148.3,257.8139521,3.857724233,1.7977E+308,0.016576977,0
,148.5,257.6523035,3.745922336,1.7977E+308,0.016140741,0
,148.7,257.2090038,3.634138907,1.7977E+308,0.031845247,0
,148.9,256.5156712,3.522371873,1.7977E+308,0.041878683,0
,149.1,256.6602192,3.410549898,1.7977E+308,0.048422227,0
,149.3,256.2514498,3.298764205,1.7977E+308,0.044059865,0
,149.5,256.1838235,3.186956142,1.7977E+308,0.034026431,0
,149.7,255.7409398,3.075172686,1.7977E+308,0.023120524,0
,149.9,255.5792912,2.963370789,1.7977E+308,0.022248052,0
,150.1,255.0923085,2.851590224,1.7977E+308,0.033590197,0
,150.3,254.7983628,2.739797002,1.7977E+308,0.041878687,0
,150.5,254.5834625,2.627998596,1.7977E+308,0.042314924,0
,150.7,254.3635699,2.516200518,1.7977E+308,0.044496107,0
,150.9,253.9165259,2.404417334,1.7977E+308,0.035771381,0
,151.1,253.4744742,2.292633824,1.7977E+308,0.023120527,0
,151.3,253.4734124,2.180821396,1.7977E+308,0.006543545,0
,151.5,253.1894514,2.069027519,1.7977E+308,0.011342146,0
,151.7,253.04694,1.957224367,1.7977E+308,0.027482892,0
,151.9,252.307012,1.845460388,1.7977E+308,0.041006221,0
,152.1,252.1145772,1.73366051,1.7977E+308,0.049294713,0
,152.3,251.7182886,1.621873998,1.7977E+308,0.048858478,0
,152.5,251.4010453,1.510082303,1.7977E+308,0.042751169,0
,152.7,251.0721532,1.398291372,1.7977E+308,0.039261278,0
,152.9,250.5327508,1.286514245,1.7977E+308,0.037080097,0
,153.1,250.6040779,1.174697071,1.7977E+308,0.031409024,0
,153.2,250.1718591,1.120496361,1.7977E+308,0.027919133,0
,228.5,249.5878005,0.956423252,1.7977E+308,0.000872473,0
,228.7,248.9626961,0.844651744,1.7977E+308,0.007852258,0
,228.9,248.8917415,0.7328439,1.7977E+308,0.008288495,0
,229.1,248.3881174,0.621064426,1.7977E+308,0.010905915,0
,229.3,247.8154325,0.509289481,1.7977E+308,0.005671076,0
,229.5,247.3792049,0.397505589,1.7977E+308,0.008724732,0
,229.7,246.9338247,0.285722296,1.7977E+308,0.018758175,0
,229.9,245.9908744,0.17397163,1.7977E+308,0.027046672,0
,230.1,245.2692512,0.062206451,1.7977E+308,0.02879162,0
,230.204,244.3536028,0.004123993,1.7977E+308,0.024865491,0
END,,,,,,